Workbook

Sheet File for Export
A1: Year | B1: Employer Number | C1: Employer | D1: district_contributions | E1: state_contributions | F1: total_contributions | G1: LEAID
A2: 2015 | C2: Barbour County Board of Education | D2: 72951 | E2: 1126867.8 | F2: 1199818.8 | G2: =IFERROR(VLOOKUP(C2,Match!$A$2:$B$84,2,FALSE),"") -> 5400030
A3: 2015 | C3: Berkeley County Board of Education | D3: 1783435 | E3: 27548754 | F3: 29332189 | G3: =IFERROR(VLOOKUP(C3,Match!$A$2:$B$84,2,FALSE),"") -> 5400060
A4: 2015 | C4: Boone County Board of Education | D4: 659694 | E4: 10190304 | F4: 10849998 | G4: =IFERROR(VLOOKUP(C4,Match!$A$2:$B$84,2,FALSE),"") -> 5400090
A5: 2015 | C5: Braxton County Board of Education | D5: 70962 | E5: 1096160.7 | F5: 1167122.7 | G5: =IFERROR(VLOOKUP(C5,Match!$A$2:$B$84,2,FALSE),"") -> 5400120
A6: 2015 | C6: Brooke County Board of Education | D6: 352159 | E6: 5439798.7 | F6: 5791957.7 | G6: =IFERROR(VLOOKUP(C6,Match!$A$2:$B$84,2,FALSE),"") -> 5400150
A7: 2015 | C7: Cabell County Board of Education | D7: 1022376 | E7: 15792663 | F7: 16815039 | G7: =IFERROR(VLOOKUP(C7,Match!$A$2:$B$84,2,FALSE),"") -> 5400180
A8: 2015 | C8: Calhoun County Board of Education | D8: 75551 | E8: 1167039.6 | F8: 1242590.6 | G8: =IFERROR(VLOOKUP(C8,Match!$A$2:$B$84,2,FALSE),"") -> 5400210
A9: 2015 | C9: Clay County Board of Education | D9: 129973 | E9: 2007699.2 | F9: 2137672.2 | G9: =IFERROR(VLOOKUP(C9,Match!$A$2:$B$84,2,FALSE),"") -> 5400240
A10: 2015 | C10: Doddridge County Board of Education | D10: 243417 | E10: 3760069.4 | F10: 4003486.4 | G10: =IFERROR(VLOOKUP(C10,Match!$A$2:$B$84,2,FALSE),"") -> 5400270
A11: 2015 | C11: Fayette County Board of Education | D11: 634696 | E11: 9804153.3 | F11: 10438849 | G11: =IFERROR(VLOOKUP(C11,Match!$A$2:$B$84,2,FALSE),"") -> 5400300
A12: 2015 | C12: Gilmer County Board of Education | D12: 80874 | E12: 1249256.9 | F12: 1330130.9 | G12: =IFERROR(VLOOKUP(C12,Match!$A$2:$B$84,2,FALSE),"") -> 5400330
A13: 2015 | C13: Grant County Board of Education | D13: 66550 | E13: 1028001 | F13: 1094551 | G13: =IFERROR(VLOOKUP(C13,Match!$A$2:$B$84,2,FALSE),"") -> 5400360
... A398: 2019 | C398: Mountain State Educational Services Cooperative | D398: 278138 | E398: 4318670 | F398: 4596808 | G398: =IFERROR(VLOOKUP(C398,Match!$A$2:$B$84,2,FALSE),"") -> 5400061
A399: 2020 | B399: 000100 | C399: Barbour County Board of Education | D399: 19119 | E399: 302167.56 | F399: 321286.56 | G399: =IFERROR(VLOOKUP(C399,Match!$A$2:$B$84,2,FALSE),"") -> 5400030
A400: 2020 | B400: 000200 | C400: Berkeley County Board of Education | D400: 886455 | E400: 14009865 | F400: 14896320 | G400: =IFERROR(VLOOKUP(C400,Match!$A$2:$B$84,2,FALSE),"") -> 5400060
A401: 2020 | B401: 000300 | C401: Boone County Board of Education | D401: 263280 | E401: 4160971.5 | F401: 4424251.5 | G401: =IFERROR(VLOOKUP(C401,Match!$A$2:$B$84,2,FALSE),"") -> 5400090
A402: 2020 | B402: 000400 | C402: Braxton County Board of Education | D402: 124319 | E402: 1964785.6 | F402: 2089104.6 | G402: =IFERROR(VLOOKUP(C402,Match!$A$2:$B$84,2,FALSE),"") -> 5400120
A403: 2020 | B403: 000500 | C403: Brooke County Board of Education | D403: 481888 | E403: 7615942.2 | F403: 8097830.2 | G403: =IFERROR(VLOOKUP(C403,Match!$A$2:$B$84,2,FALSE),"") -> 5400150
A404: 2020 | B404: 000600 | C404: Cabell County Board of Education | D404: 1225072 | E404: 19361505 | F404: 20586577 | G404: =IFERROR(VLOOKUP(C404,Match!$A$2:$B$84,2,FALSE),"") -> 5400180
A405: 2020 | B405: 000700 | C405: Calhoun County Board of Education | D405: 11256 | E405: 177903.61 | F405: 189159.61 | G405: =IFERROR(VLOOKUP(C405,Match!$A$2:$B$84,2,FALSE),"") -> 5400210
A406: 2020 | B406: 000800 | C406: Clay County Board of Education | D406: 98782 | E406: 1561191 | F406: 1659973 | G406: =IFERROR(VLOOKUP(C406,Match!$A$2:$B$84,2,FALSE),"") -> 5400240
A407: 2020 | B407: 000900 | C407: Doddridge County Board of Education | D407: 348052 | E407: 5500742.3 | F407: 5848794.3 | G407: =IFERROR(VLOOKUP(C407,Match!$A$2:$B$84,2,FALSE),"") -> 5400270
A408: 2020 | B408: 001000 | C408: Fayette County Board of Education | D408: 469306 | E408: 7417091.1 | F408: 7886397.1 | G408: =IFERROR(VLOOKUP(C408,Match!$A$2:$B$84,2,FALSE),"") -> 5400300
A409: 2020 | B409: 001100 | C409: Gilmer County Board of Education | D409: 13725 | E409: 216908.83 | F409: 230633.83 | G409: =IFERROR(VLOOKUP(C409,Match!$A$2:$B$84,2,FALSE),"") -> 5400330
A410: 2020 | B410: 001200 | C410: Grant County Board of Education | D410: 53158 | E410: 840134.04 | F410: 893292.04 | G410: =IFERROR(VLOOKUP(C410,Match!$A$2:$B$84,2,FALSE),"") -> 5400360
... A638: 2022 | B638: ESC006 | C638: Mountain State Educational Services Cooperative | D638: 641962 | E638: 9555669.3 | F638: 10197631 | G638: =IFERROR(VLOOKUP(C638,Match!$A$2:$B$84,2,FALSE),"") -> 5400061

Sheet GASB Files -->

Sheet Raw Data & Formula Checks
A1: Year | B1: Employer Number | C1: Employer | D1: Employer Contributions | E1: State Payment On Behalf | F1: Total Contributions
A2: 2015 | C2: Barbour County Board of Education | D2: 72951 | E2: 5762 | F2: 78713
A3: 2015 | C3: Berkeley County Board of Education | D3: 1783435 | E3: 140876 | F3: 1924311
A4: 2015 | C4: Boone County Board of Education | D4: 659694 | E4: 52110 | F4: 711804
A5: 2015 | C5: Braxton County Board of Education | D5: 70962 | E5: 5606 | F5: 76568
A6: 2015 | C6: Brooke County Board of Education | D6: 352159 | E6: 27817 | F6: 379976
A7: 2015 | C7: Cabell County Board of Education | D7: 1022376 | E7: 80759 | F7: 1103135
A8: 2015 | C8: Calhoun County Board of Education | D8: 75551 | E8: 5968 | F8: 81519
A9: 2015 | C9: Clay County Board of Education | D9: 129973 | E9: 10267 | F9: 140240
A10: 2015 | C10: Doddridge County Board of Education | D10: 243417 | E10: 19228 | F10: 262645
A11: 2015 | C11: Fayette County Board of Education | D11: 634696 | E11: 50135 | F11: 684831
A12: 2015 | C12: Gilmer County Board of Education | D12: 80874 | E12: 6388 | F12: 87262
A13: 2015 | C13: Grant County Board of Education | D13: 66550 | E13: 5257 | F13: 71807
... A408: 2019 | C408: State of WV Special Funding - ARC Contributions | D408: 306319491 | E408: 34168665 | F408: 340488156
A409: 2020 | B409: 000100 | C409: Barbour County Board of Education | D409: 19119 | E409: 2316 | F409: 21435
A410: 2020 | B410: 000200 | C410: Berkeley County Board of Education | D410: 886455 | E410: 107370 | F410: 993825
A411: 2020 | B411: 000300 | C411: Boone County Board of Education | D411: 263280 | E411: 31889 | F411: 295169
A412: 2020 | B412: 000400 | C412: Braxton County Board of Education | D412: 124319 | E412: 15058 | F412: 139377
A413: 2020 | B413: 000500 | C413: Brooke County Board of Education | D413: 481888 | E413: 58368 | F413: 540256
A414: 2020 | B414: 000600 | C414: Cabell County Board of Education | D414: 1225072 | E414: 148385 | F414: 1373457
A415: 2020 | B415: 000700 | C415: Calhoun County Board of Education | D415: 11256 | E415: 1364 | F415: 12620
A416: 2020 | B416: 000800 | C416: Clay County Board of Education | D416: 98782 | E416: 11965 | F416: 110747
A417: 2020 | B417: 000900 | C417: Doddridge County Board of Education | D417: 348052 | E417: 42157 | F417: 390209
A418: 2020 | B418: 001000 | C418: Fayette County Board of Education | D418: 469306 | E418: 56844 | F418: 526150
A419: 2020 | B419: 001100 | C419: Gilmer County Board of Education | D419: 13725 | E419: 1662 | F419: 15387
A420: 2020 | B420: 001200 | C420: Grant County Board of Education | D420: 53158 | E420: 6439 | F420: 59597
... A490: 2020 | B490: wvARC | C490: State of WV Special Funding - ARC Contributions | D490: 283332231 | E490: 34318062 | F490: 317650293
A491: 2021 | B491: 000100 | C491: Barbour County Board of Education | D491: 106320
A492: 2021 | B492: 000200 | C492: Berkeley County Board of Education | D492: 1303866
A493: 2021 | B493: 000300 | C493: Boone County Board of Education | D493: 236486
A494: 2021 | B494: 000400 | C494: Braxton County Board of Education | D494: 100618
A495: 2021 | B495: 000500 | C495: Brooke County Board of Education | D495: 290005
A496: 2021 | B496: 000600 | C496: Cabell County Board of Education | D496: 1072625
A497: 2021 | B497: 000700 | C497: Calhoun County Board of Education | D497: 19698
A498: 2021 | B498: 000800 | C498: Clay County Board of Education | D498: 134848
A499: 2021 | B499: 000900 | C499: Doddridge County Board of Education | D499: 332230
A500: 2021 | B500: 001000 | C500: Fayette County Board of Education | D500: 515555
A501: 2021 | B501: 001100 | C501: Gilmer County Board of Education | D501: 31609
A502: 2021 | B502: 001200 | C502: Grant County Board of Education | D502: 36969
... A573: 2021 | B573: wvSAF | C573: State of WV Special Funding - SAF | D573: 101022149
...

Sheet Edited File w State Contri
A1: Year | B1: Employer Number | C1: Employer | D1: district_contributions | E1: State Payment On Behalf | F1: Total Contributions (no state) | H1: prop | I1: state_contributions | J1: total_contributions | L1: Year | M1: Employer Number | N1: Employer | O1: Employer Contributions | P1: State Payment On Behalf | Q1: Total Contributions
A2: 2015 | C2: Barbour County Board of Education | D2: 72951 | E2: 5762 | F2: 78713 | G2: {=_xlfn.IFS(A2=$E$640,F2/$F$640,A2=$E$641,F2/$F$641,A2=$E$641,F2/$F$641,A2=$E$642,F2/$F$642,A2=$E$643,F2/$F$643,A2=$E$644,F2/$F$644,A2=$E$645,F2/$F$645,A2=$E$646,F2/$F$646,A2=$E$647,F2/$F$647)} -> 0.0024454159 | H2: {=_xlfn.IFS(A2=$P$24,G2*$Q$24,A2=$P$25,G2*$Q$25,A2=$P$26,G2*$Q$26,A2=$P$27,G2*$Q$27,A2=$P$28,G2*$Q$28,A2=$P$29,G2*$Q$29,A2=$P$30,G2*$Q$30,A2=$P$31,G2*$Q$31)} -> 1121105.8 | I2: =SUM(H2,E2) -> 1126867.8 | J2: =SUM(I2,D2) -> 1199818.8 | L2: 2015 | N2: West Virginia - SAF | O2: 108729623 | P2: 8588694 | Q2: 117318317
A3: 2015 | C3: Berkeley County Board of Education | D3: 1783435 | E3: 140876 | F3: 1924311 | G3: {=_xlfn.IFS(A3=$E$640,F3/$F$640,A3=$E$641,F3/$F$641,A3=$E$641,F3/$F$641,A3=$E$642,F3/$F$642,A3=$E$643,F3/$F$643,A3=$E$644,F3/$F$644,A3=$E$645,F3/$F$645,A3=$E$646,F3/$F$646,A3=$E$647,F3/$F$647)} -> 0.059783526 | H3: {=_xlfn.IFS(A3=$P$24,G3*$Q$24,A3=$P$25,G3*$Q$25,A3=$P$26,G3*$Q$26,A3=$P$27,G3*$Q$27,A3=$P$28,G3*$Q$28,A3=$P$29,G3*$Q$29,A3=$P$30,G3*$Q$30,A3=$P$31,G3*$Q$31)} -> 27407878 | I3: =SUM(H3,E3) -> 27548754 | J3: =SUM(I3,D3) -> 29332189 | L3: 2016 | N3: West Virginia - SAF | O3: 102803167 | P3: 9416254 | Q3: 112219421
A4: 2015 | C4: Boone County Board of Education | D4: 659694 | E4: 52110 | F4: 711804 | G4: {=_xlfn.IFS(A4=$E$640,F4/$F$640,A4=$E$641,F4/$F$641,A4=$E$641,F4/$F$641,A4=$E$642,F4/$F$642,A4=$E$643,F4/$F$643,A4=$E$644,F4/$F$644,A4=$E$645,F4/$F$645,A4=$E$646,F4/$F$646,A4=$E$647,F4/$F$647)} -> 0.022113969 | H4: {=_xlfn.IFS(A4=$P$24,G4*$Q$24,A4=$P$25,G4*$Q$25,A4=$P$26,G4*$Q$26,A4=$P$27,G4*$Q$27,A4=$P$28,G4*$Q$28,A4=$P$29,G4*$Q$29,A4=$P$30,G4*$Q$30,A4=$P$31,G4*$Q$31)} -> 10138194 | I4: =SUM(H4,E4) -> 10190304 | J4: =SUM(I4,D4) -> 10849998 | L4: 2017 | N4: State of WV Special Funding - SAF | O4: 99335705 | P4: 8991362 | Q4: 108327067
A5: 2015 | C5: Braxton County Board of Education | D5: 70962 | E5: 5606 | F5: 76568 | G5: {=_xlfn.IFS(A5=$E$640,F5/$F$640,A5=$E$641,F5/$F$641,A5=$E$641,F5/$F$641,A5=$E$642,F5/$F$642,A5=$E$643,F5/$F$643,A5=$E$644,F5/$F$644,A5=$E$645,F5/$F$645,A5=$E$646,F5/$F$646,A5=$E$647,F5/$F$647)} -> 0.0023787761 | H5: {=_xlfn.IFS(A5=$P$24,G5*$Q$24,A5=$P$25,G5*$Q$25,A5=$P$26,G5*$Q$26,A5=$P$27,G5*$Q$27,A5=$P$28,G5*$Q$28,A5=$P$29,G5*$Q$29,A5=$P$30,G5*$Q$30,A5=$P$31,G5*$Q$31)} -> 1090554.7 | I5: =SUM(H5,E5) -> 1096160.7 | J5: =SUM(I5,D5) -> 1167122.7 | L5: 2018 | N5: State of WV Special Funding - SAF | O5: 96207630 | P5: 6077903 | Q5: 102285533
A6: 2015 | C6: Brooke County Board of Education | D6: 352159 | E6: 27817 | F6: 379976 | G6: {=_xlfn.IFS(A6=$E$640,F6/$F$640,A6=$E$641,F6/$F$641,A6=$E$641,F6/$F$641,A6=$E$642,F6/$F$642,A6=$E$643,F6/$F$643,A6=$E$644,F6/$F$644,A6=$E$645,F6/$F$645,A6=$E$646,F6/$F$646,A6=$E$647,F6/$F$647)} -> 0.011804903 | H6: {=_xlfn.IFS(A6=$P$24,G6*$Q$24,A6=$P$25,G6*$Q$25,A6=$P$26,G6*$Q$26,A6=$P$27,G6*$Q$27,A6=$P$28,G6*$Q$28,A6=$P$29,G6*$Q$29,A6=$P$30,G6*$Q$30,A6=$P$31,G6*$Q$31)} -> 5411981.7 | I6: =SUM(H6,E6) -> 5439798.7 | J6: =SUM(I6,D6) -> 5791957.7 | L6: 2019 | N6: State of WV Special Funding - SAF | O6: 97748005 | P6: 10903385 | Q6: 108651390
A7: 2015 | C7: Cabell County Board of Education | D7: 1022376 | E7: 80759 | F7: 1103135 | G7: {=_xlfn.IFS(A7=$E$640,F7/$F$640,A7=$E$641,F7/$F$641,A7=$E$641,F7/$F$641,A7=$E$642,F7/$F$642,A7=$E$643,F7/$F$643,A7=$E$644,F7/$F$644,A7=$E$645,F7/$F$645,A7=$E$646,F7/$F$646,A7=$E$647,F7/$F$647)} -> 0.034271643 | H7: {=_xlfn.IFS(A7=$P$24,G7*$Q$24,A7=$P$25,G7*$Q$25,A7=$P$26,G7*$Q$26,A7=$P$27,G7*$Q$27,A7=$P$28,G7*$Q$28,A7=$P$29,G7*$Q$29,A7=$P$30,G7*$Q$30,A7=$P$31,G7*$Q$31)} -> 15711904 | I7: =SUM(H7,E7) -> 15792663 | J7: =SUM(I7,D7) -> 16815039 | L7: 2020 | M7: wvSAF | N7: State of WV Special Funding - SAF | O7: 102793436 | P7: 12450655 | Q7: 115244091
A8: 2015 | C8: Calhoun County Board of Education | D8: 75551 | E8: 5968 | F8: 81519 | G8: {=_xlfn.IFS(A8=$E$640,F8/$F$640,A8=$E$641,F8/$F$641,A8=$E$641,F8/$F$641,A8=$E$642,F8/$F$642,A8=$E$643,F8/$F$643,A8=$E$644,F8/$F$644,A8=$E$645,F8/$F$645,A8=$E$646,F8/$F$646,A8=$E$647,F8/$F$647)} -> 0.0025325913 | H8: {=_xlfn.IFS(A8=$P$24,G8*$Q$24,A8=$P$25,G8*$Q$25,A8=$P$26,G8*$Q$26,A8=$P$27,G8*$Q$27,A8=$P$28,G8*$Q$28,A8=$P$29,G8*$Q$29,A8=$P$30,G8*$Q$30,A8=$P$31,G8*$Q$31)} -> 1161071.6 | I8: =SUM(H8,E8) -> 1167039.6 | J8: =SUM(I8,D8) -> 1242590.6 | L8: 2021 | M8: wvSAF | N8: State of WV Special Funding - SAF | O8: 101022149 | Q8: =O8 -> 101022149
A9: 2015 | C9: Clay County Board of Education | D9: 129973 | E9: 10267 | F9: 140240 | G9: {=_xlfn.IFS(A9=$E$640,F9/$F$640,A9=$E$641,F9/$F$641,A9=$E$641,F9/$F$641,A9=$E$642,F9/$F$642,A9=$E$643,F9/$F$643,A9=$E$644,F9/$F$644,A9=$E$645,F9/$F$645,A9=$E$646,F9/$F$646,A9=$E$647,F9/$F$647)} -> 0.0043569058 | H9: {=_xlfn.IFS(A9=$P$24,G9*$Q$24,A9=$P$25,G9*$Q$25,A9=$P$26,G9*$Q$26,A9=$P$27,G9*$Q$27,A9=$P$28,G9*$Q$28,A9=$P$29,G9*$Q$29,A9=$P$30,G9*$Q$30,A9=$P$31,G9*$Q$31)} -> 1997432.2 | I9: =SUM(H9,E9) -> 2007699.2 | J9: =SUM(I9,D9) -> 2137672.2 | L9: 2022 | M9: wvSAF | N9: State of WV Special Funding - SAF | O9: 100085768 | P9: 14687590 | Q9: 114773358
A10: 2015 | C10: Doddridge County Board of Education | D10: 243417 | E10: 19228 | F10: 262645 | G10: {=_xlfn.IFS(A10=$E$640,F10/$F$640,A10=$E$641,F10/$F$641,A10=$E$641,F10/$F$641,A10=$E$642,F10/$F$642,A10=$E$643,F10/$F$643,A10=$E$644,F10/$F$644,A10=$E$645,F10/$F$645,A10=$E$646,F10/$F$646,A10=$E$647,F10/$F$647)} -> 0.0081597227 | H10: {=_xlfn.IFS(A10=$P$24,G10*$Q$24,A10=$P$25,G10*$Q$25,A10=$P$26,G10*$Q$26,A10=$P$27,G10*$Q$27,A10=$P$28,G10*$Q$28,A10=$P$29,G10*$Q$29,A10=$P$30,G10*$Q$30,A10=$P$31,G10*$Q$31)} -> 3740841.4 | I10: =SUM(H10,E10) -> 3760069.4 | J10: =SUM(I10,D10) -> 4003486.4 | L10: 2023 | M10: wvSAF | N10: State of WV Special Funding - SAF | O10: 101255002 | P10: 10144721 | Q10: 111399723
A11: 2015 | C11: Fayette County Board of Education | D11: 634696 | E11: 50135 | F11: 684831 | G11: {=_xlfn.IFS(A11=$E$640,F11/$F$640,A11=$E$641,F11/$F$641,A11=$E$641,F11/$F$641,A11=$E$642,F11/$F$642,A11=$E$643,F11/$F$643,A11=$E$644,F11/$F$644,A11=$E$645,F11/$F$645,A11=$E$646,F11/$F$646,A11=$E$647,F11/$F$647)} -> 0.021275985 | H11: {=_xlfn.IFS(A11=$P$24,G11*$Q$24,A11=$P$25,G11*$Q$25,A11=$P$26,G11*$Q$26,A11=$P$27,G11*$Q$27,A11=$P$28,G11*$Q$28,A11=$P$29,G11*$Q$29,A11=$P$30,G11*$Q$30,A11=$P$31,G11*$Q$31)} -> 9754018.3 | I11: =SUM(H11,E11) -> 9804153.3 | J11: =SUM(I11,D11) -> 10438849
A12: 2015 | C12: Gilmer County Board of Education | D12: 80874 | E12: 6388 | F12: 87262 | G12: {=_xlfn.IFS(A12=$E$640,F12/$F$640,A12=$E$641,F12/$F$641,A12=$E$641,F12/$F$641,A12=$E$642,F12/$F$642,A12=$E$643,F12/$F$643,A12=$E$644,F12/$F$644,A12=$E$645,F12/$F$645,A12=$E$646,F12/$F$646,A12=$E$647,F12/$F$647)} -> 0.0027110119 | H12: {=_xlfn.IFS(A12=$P$24,G12*$Q$24,A12=$P$25,G12*$Q$25,A12=$P$26,G12*$Q$26,A12=$P$27,G12*$Q$27,A12=$P$28,G12*$Q$28,A12=$P$29,G12*$Q$29,A12=$P$30,G12*$Q$30,A12=$P$31,G12*$Q$31)} -> 1242868.9 | I12: =SUM(H12,E12) -> 1249256.9 | J12: =SUM(I12,D12) -> 1330130.9
A13: 2015 | C13: Grant County Board of Education | D13: 66550 | E13: 5257 | F13: 71807 | G13: {=_xlfn.IFS(A13=$E$640,F13/$F$640,A13=$E$641,F13/$F$641,A13=$E$641,F13/$F$641,A13=$E$642,F13/$F$642,A13=$E$643,F13/$F$643,A13=$E$644,F13/$F$644,A13=$E$645,F13/$F$645,A13=$E$646,F13/$F$646,A13=$E$647,F13/$F$647)} -> 0.0022308638 | H13: {=_xlfn.IFS(A13=$P$24,G13*$Q$24,A13=$P$25,G13*$Q$25,A13=$P$26,G13*$Q$26,A13=$P$27,G13*$Q$27,A13=$P$28,G13*$Q$28,A13=$P$29,G13*$Q$29,A13=$P$30,G13*$Q$30,A13=$P$31,G13*$Q$31)} -> 1022744 | I13: =SUM(H13,E13) -> 1028001 | J13: =SUM(I13,D13) -> 1094551 | L13: 2015 | N13: West Virginia - ARC | O13: 316159828 | P13: 24973874 | Q13: 341133702
A14: 2015 | C14: Greenbrier County Board of Education | D14: 400447 | E14: 31632 | F14: 432079 | G14: {=_xlfn.IFS(A14=$E$640,F14/$F$640,A14=$E$641,F14/$F$641,A14=$E$641,F14/$F$641,A14=$E$642,F14/$F$642,A14=$E$643,F14/$F$643,A14=$E$644,F14/$F$644,A14=$E$645,F14/$F$645,A14=$E$646,F14/$F$646,A14=$E$647,F14/$F$647)} -> 0.013423613 | H14: {=_xlfn.IFS(A14=$P$24,G14*$Q$24,A14=$P$25,G14*$Q$25,A14=$P$26,G14*$Q$26,A14=$P$27,G14*$Q$27,A14=$P$28,G14*$Q$28,A14=$P$29,G14*$Q$29,A14=$P$30,G14*$Q$30,A14=$P$31,G14*$Q$31)} -> 6154082.5 | I14: =SUM(H14,E14) -> 6185714.5 | J14: =SUM(I14,D14) -> 6586161.5 | L14: 2016 | N14: West Virginia - ARC | O14: 254218385 | P14: 23285124 | Q14: 277503509
A15: 2015 | C15: Hampshire County Board of Education | D15: 196048 | E15: 15486 | F15: 211534 | G15: {=_xlfn.IFS(A15=$E$640,F15/$F$640,A15=$E$641,F15/$F$641,A15=$E$641,F15/$F$641,A15=$E$642,F15/$F$642,A15=$E$643,F15/$F$643,A15=$E$644,F15/$F$644,A15=$E$645,F15/$F$645,A15=$E$646,F15/$F$646,A15=$E$647,F15/$F$647)} -> 0.0065718319 | H15: {=_xlfn.IFS(A15=$P$24,G15*$Q$24,A15=$P$25,G15*$Q$25,A15=$P$26,G15*$Q$26,A15=$P$27,G15*$Q$27,A15=$P$28,G15*$Q$28,A15=$P$29,G15*$Q$29,A15=$P$30,G15*$Q$30,A15=$P$31,G15*$Q$31)} -> 3012869.6 | I15: =SUM(H15,E15) -> 3028355.6 | J15: =SUM(I15,D15) -> 3224403.6 | L15: 2017 | N15: State of WV Special Funding - ARC Contributions | O15: 285068483 | P15: 25802944 | Q15: 310871427
A16: 2015 | C16: Hancock County Board of Education | D16: 458098 | E16: 36186 | F16: 494284 | G16: {=_xlfn.IFS(A16=$E$640,F16/$F$640,A16=$E$641,F16/$F$641,A16=$E$641,F16/$F$641,A16=$E$642,F16/$F$642,A16=$E$643,F16/$F$643,A16=$E$644,F16/$F$644,A16=$E$645,F16/$F$645,A16=$E$646,F16/$F$646,A16=$E$647,F16/$F$647)} -> 0.015356167 | H16: {=_xlfn.IFS(A16=$P$24,G16*$Q$24,A16=$P$25,G16*$Q$25,A16=$P$26,G16*$Q$26,A16=$P$27,G16*$Q$27,A16=$P$28,G16*$Q$28,A16=$P$29,G16*$Q$29,A16=$P$30,G16*$Q$30,A16=$P$31,G16*$Q$31)} -> 7040065.6 | I16: =SUM(H16,E16) -> 7076251.6 | J16: =SUM(I16,D16) -> 7534349.6 | L16: 2018 | N16: State of WV Special Funding - ARC Contributions | O16: 320214422 | P16: 20229500 | Q16: 340443922
A17: 2015 | C17: Hardy County Board of Education | D17: 41192 | E17: 3254 | F17: 44446 | G17: {=_xlfn.IFS(A17=$E$640,F17/$F$640,A17=$E$641,F17/$F$641,A17=$E$641,F17/$F$641,A17=$E$642,F17/$F$642,A17=$E$643,F17/$F$643,A17=$E$644,F17/$F$644,A17=$E$645,F17/$F$645,A17=$E$646,F17/$F$646,A17=$E$647,F17/$F$647)} -> 0.001380826 | H17: {=_xlfn.IFS(A17=$P$24,G17*$Q$24,A17=$P$25,G17*$Q$25,A17=$P$26,G17*$Q$26,A17=$P$27,G17*$Q$27,A17=$P$28,G17*$Q$28,A17=$P$29,G17*$Q$29,A17=$P$30,G17*$Q$30,A17=$P$31,G17*$Q$31)} -> 633042.45 | I17: =SUM(H17,E17) -> 636296.45 | J17: =SUM(I17,D17) -> 677488.45 | L17: 2019 | N17: State of WV Special Funding - ARC Contributions | O17: 306319491 | P17: 34168665 | Q17: 340488156
A18: 2015 | C18: Harrison County Board of Education | D18: 1352473 | E18: 106834 | F18: 1459307 | G18: {=_xlfn.IFS(A18=$E$640,F18/$F$640,A18=$E$641,F18/$F$641,A18=$E$641,F18/$F$641,A18=$E$642,F18/$F$642,A18=$E$643,F18/$F$643,A18=$E$644,F18/$F$644,A18=$E$645,F18/$F$645,A18=$E$646,F18/$F$646,A18=$E$647,F18/$F$647)} -> 0.045337016 | H18: {=_xlfn.IFS(A18=$P$24,G18*$Q$24,A18=$P$25,G18*$Q$25,A18=$P$26,G18*$Q$26,A18=$P$27,G18*$Q$27,A18=$P$28,G18*$Q$28,A18=$P$29,G18*$Q$29,A18=$P$30,G18*$Q$30,A18=$P$31,G18*$Q$31)} -> 20784846 | I18: =SUM(H18,E18) -> 20891680 | J18: =SUM(I18,D18) -> 22244153 | L18: 2020 | M18: wvARC | N18: State of WV Special Funding - ARC Contributions | O18: 283332231 | P18: 34318062 | Q18: 317650293
A19: 2015 | C19: Jackson County Board of Education | D19: 503546 | E19: 39776 | F19: 543322 | G19: {=_xlfn.IFS(A19=$E$640,F19/$F$640,A19=$E$641,F19/$F$641,A19=$E$641,F19/$F$641,A19=$E$642,F19/$F$642,A19=$E$643,F19/$F$643,A19=$E$644,F19/$F$644,A19=$E$645,F19/$F$645,A19=$E$646,F19/$F$646,A19=$E$647,F19/$F$647)} -> 0.016879655 | H19: {=_xlfn.IFS(A19=$P$24,G19*$Q$24,A19=$P$25,G19*$Q$25,A19=$P$26,G19*$Q$26,A19=$P$27,G19*$Q$27,A19=$P$28,G19*$Q$28,A19=$P$29,G19*$Q$29,A19=$P$30,G19*$Q$30,A19=$P$31,G19*$Q$31)} -> 7738511.7 | I19: =SUM(H19,E19) -> 7778287.7 | J19: =SUM(I19,D19) -> 8281833.7 | L19: 2021 | M19: wvARC | N19: State of WV Special Funding - ARC Contributions | O19: 288360024 | Q19: =O19 -> 288360024
A20: 2015 | C20: Jefferson County Board of Education | D20: 1024564 | E20: 80932 | F20: 1105496 | G20: {=_xlfn.IFS(A20=$E$640,F20/$F$640,A20=$E$641,F20/$F$641,A20=$E$641,F20/$F$641,A20=$E$642,F20/$F$642,A20=$E$643,F20/$F$643,A20=$E$644,F20/$F$644,A20=$E$645,F20/$F$645,A20=$E$646,F20/$F$646,A20=$E$647,F20/$F$647)} -> 0.034344994 | H20: {=_xlfn.IFS(A20=$P$24,G20*$Q$24,A20=$P$25,G20*$Q$25,A20=$P$26,G20*$Q$26,A20=$P$27,G20*$Q$27,A20=$P$28,G20*$Q$28,A20=$P$29,G20*$Q$29,A20=$P$30,G20*$Q$30,A20=$P$31,G20*$Q$31)} -> 15745532 | I20: =SUM(H20,E20) -> 15826464 | J20: =SUM(I20,D20) -> 16851028 | L20: 2022 | M20: wvARC | N20: State of WV Special Funding - ARC Contributions | O20: 281632070 | P20: 51731299 | Q20: 333363369
A21: 2015 | C21: Kanawha County Board of Education | D21: 1837706 | E21: 145163 | F21: 1982869 | G21: {=_xlfn.IFS(A21=$E$640,F21/$F$640,A21=$E$641,F21/$F$641,A21=$E$641,F21/$F$641,A21=$E$642,F21/$F$642,A21=$E$643,F21/$F$643,A21=$E$644,F21/$F$644,A21=$E$645,F21/$F$645,A21=$E$646,F21/$F$646,A21=$E$647,F21/$F$647)} -> 0.061602777 | H21: {=_xlfn.IFS(A21=$P$24,G21*$Q$24,A21=$P$25,G21*$Q$25,A21=$P$26,G21*$Q$26,A21=$P$27,G21*$Q$27,A21=$P$28,G21*$Q$28,A21=$P$29,G21*$Q$29,A21=$P$30,G21*$Q$30,A21=$P$31,G21*$Q$31)} -> 28241917 | I21: =SUM(H21,E21) -> 28387080 | J21: =SUM(I21,D21) -> 30224786 | L21: 2023 | M21: wvARC | N21: State of WV Special Funding - ARC Contributions | O21: 271978964 | P21: 31791932 | Q21: 303770896
A22: 2015 | C22: Lewis County Board of Education | D22: 167516 | E22: 13232 | F22: 180748 | G22: {=_xlfn.IFS(A22=$E$640,F22/$F$640,A22=$E$641,F22/$F$641,A22=$E$641,F22/$F$641,A22=$E$642,F22/$F$642,A22=$E$643,F22/$F$643,A22=$E$644,F22/$F$644,A22=$E$645,F22/$F$645,A22=$E$646,F22/$F$646,A22=$E$647,F22/$F$647)} -> 0.0056153879 | H22: {=_xlfn.IFS(A22=$P$24,G22*$Q$24,A22=$P$25,G22*$Q$25,A22=$P$26,G22*$Q$26,A22=$P$27,G22*$Q$27,A22=$P$28,G22*$Q$28,A22=$P$29,G22*$Q$29,A22=$P$30,G22*$Q$30,A22=$P$31,G22*$Q$31)} -> 2574385.9 | I22: =SUM(H22,E22) -> 2587617.9 | J22: =SUM(I22,D22) -> 2755133.9
A23: 2015 | C23: Lincoln County Board of Education | D23: 247929 | E23: 19584 | F23: 267513 | G23: {=_xlfn.IFS(A23=$E$640,F23/$F$640,A23=$E$641,F23/$F$641,A23=$E$641,F23/$F$641,A23=$E$642,F23/$F$642,A23=$E$643,F23/$F$643,A23=$E$644,F23/$F$644,A23=$E$645,F23/$F$645,A23=$E$646,F23/$F$646,A23=$E$647,F23/$F$647)} -> 0.0083109593 | H23: {=_xlfn.IFS(A23=$P$24,G23*$Q$24,A23=$P$25,G23*$Q$25,A23=$P$26,G23*$Q$26,A23=$P$27,G23*$Q$27,A23=$P$28,G23*$Q$28,A23=$P$29,G23*$Q$29,A23=$P$30,G23*$Q$30,A23=$P$31,G23*$Q$31)} -> 3810176.1 | I23: =SUM(H23,E23) -> 3829760.1 | J23: =SUM(I23,D23) -> 4077689.1 | N23: State Contribution Check
A24: 2015 | C24: Logan County Board of Education | D24: 456258 | E24: 36040 | F24: 492298 | G24: {=_xlfn.IFS(A24=$E$640,F24/$F$640,A24=$E$641,F24/$F$641,A24=$E$641,F24/$F$641,A24=$E$642,F24/$F$642,A24=$E$643,F24/$F$643,A24=$E$644,F24/$F$644,A24=$E$645,F24/$F$645,A24=$E$646,F24/$F$646,A24=$E$647,F24/$F$647)} -> 0.015294467 | H24: {=_xlfn.IFS(A24=$P$24,G24*$Q$24,A24=$P$25,G24*$Q$25,A24=$P$26,G24*$Q$26,A24=$P$27,G24*$Q$27,A24=$P$28,G24*$Q$28,A24=$P$29,G24*$Q$29,A24=$P$30,G24*$Q$30,A24=$P$31,G24*$Q$31)} -> 7011779.1 | I24: =SUM(H24,E24) -> 7047819.1 | J24: =SUM(I24,D24) -> 7504077.1 | N24: 2015 | O24: =SUMIF($A$2:$A$638,N24,$H$2:$H$638) -> 458452019 | P24: 2015 | Q24: =SUM(Q2,Q13) -> 458452019 | R24: =O24=Q24 -> TRUE
A25: 2015 | C25: Marion County Board of Education | D25: 639563 | E25: 50520 | F25: 690083 | G25: {=_xlfn.IFS(A25=$E$640,F25/$F$640,A25=$E$641,F25/$F$641,A25=$E$641,F25/$F$641,A25=$E$642,F25/$F$642,A25=$E$643,F25/$F$643,A25=$E$644,F25/$F$644,A25=$E$645,F25/$F$645,A25=$E$646,F25/$F$646,A25=$E$647,F25/$F$647)} -> 0.021439151 | H25: {=_xlfn.IFS(A25=$P$24,G25*$Q$24,A25=$P$25,G25*$Q$25,A25=$P$26,G25*$Q$26,A25=$P$27,G25*$Q$27,A25=$P$28,G25*$Q$28,A25=$P$29,G25*$Q$29,A25=$P$30,G25*$Q$30,A25=$P$31,G25*$Q$31)} -> 9828822.3 | I25: =SUM(H25,E25) -> 9879342.3 | J25: =SUM(I25,D25) -> 10518905 | N25: 2016 | O25: =SUMIF($A$2:$A$638,N25,$H$2:$H$638) -> 3.8972293e+08 | P25: 2016 | Q25: =SUM(Q3,Q14) -> 389722930 | R25: =O25=Q25 -> TRUE
A26: 2015 | C26: Marshall County Board of Education | D26: 690182 | E26: 54518 | F26: 744700 | G26: {=_xlfn.IFS(A26=$E$640,F26/$F$640,A26=$E$641,F26/$F$641,A26=$E$641,F26/$F$641,A26=$E$642,F26/$F$642,A26=$E$643,F26/$F$643,A26=$E$644,F26/$F$644,A26=$E$645,F26/$F$645,A26=$E$646,F26/$F$646,A26=$E$647,F26/$F$647)} -> 0.023135965 | H26: {=_xlfn.IFS(A26=$P$24,G26*$Q$24,A26=$P$25,G26*$Q$25,A26=$P$26,G26*$Q$26,A26=$P$27,G26*$Q$27,A26=$P$28,G26*$Q$28,A26=$P$29,G26*$Q$29,A26=$P$30,G26*$Q$30,A26=$P$31,G26*$Q$31)} -> 10606730 | I26: =SUM(H26,E26) -> 10661248 | J26: =SUM(I26,D26) -> 11351430 | N26: 2017 | O26: =SUMIF($A$2:$A$638,N26,$H$2:$H$638) -> 419198494 | P26: 2017 | Q26: =SUM(Q4,Q15) -> 419198494 | R26: =O26=Q26 -> TRUE
A27: 2015 | C27: Mason County Board of Education | D27: 299203 | E27: 23634 | F27: 322837 | G27: {=_xlfn.IFS(A27=$E$640,F27/$F$640,A27=$E$641,F27/$F$641,A27=$E$641,F27/$F$641,A27=$E$642,F27/$F$642,A27=$E$643,F27/$F$643,A27=$E$644,F27/$F$644,A27=$E$645,F27/$F$645,A27=$E$646,F27/$F$646,A27=$E$647,F27/$F$647)} -> 0.010029737 | H27: {=_xlfn.IFS(A27=$P$24,G27*$Q$24,A27=$P$25,G27*$Q$25,A27=$P$26,G27*$Q$26,A27=$P$27,G27*$Q$27,A27=$P$28,G27*$Q$28,A27=$P$29,G27*$Q$29,A27=$P$30,G27*$Q$30,A27=$P$31,G27*$Q$31)} -> 4598153.4 | I27: =SUM(H27,E27) -> 4621787.4 | J27: =SUM(I27,D27) -> 4920990.4 | N27: 2018 | O27: =SUMIF($A$2:$A$638,N27,$H$2:$H$638) -> 4.4272946e+08 | P27: 2018 | Q27: =SUM(Q5,Q16) -> 442729455 | R27: =O27=Q27 -> TRUE
A28: 2015 | C28: McDowell County Board of Education | D28: 461646 | E28: 36466 | F28: 498112 | G28: {=_xlfn.IFS(A28=$E$640,F28/$F$640,A28=$E$641,F28/$F$641,A28=$E$641,F28/$F$641,A28=$E$642,F28/$F$642,A28=$E$643,F28/$F$643,A28=$E$644,F28/$F$644,A28=$E$645,F28/$F$645,A28=$E$646,F28/$F$646,A28=$E$647,F28/$F$647)} -> 0.015475093 | H28: {=_xlfn.IFS(A28=$P$24,G28*$Q$24,A28=$P$25,G28*$Q$25,A28=$P$26,G28*$Q$26,A28=$P$27,G28*$Q$27,A28=$P$28,G28*$Q$28,A28=$P$29,G28*$Q$29,A28=$P$30,G28*$Q$30,A28=$P$31,G28*$Q$31)} -> 7094587.6 | I28: =SUM(H28,E28) -> 7131053.6 | J28: =SUM(I28,D28) -> 7592699.6 | N28: 2019 | O28: =SUMIF($A$2:$A$638,N28,$H$2:$H$638) -> 449139546 | P28: 2019 | Q28: =SUM(Q6,Q17) -> 449139546 | R28: =O28=Q28 -> TRUE
A29: 2015 | C29: Mercer County Board of Education | D29: 764534 | E29: 60392 | F29: 824926 | G29: {=_xlfn.IFS(A29=$E$640,F29/$F$640,A29=$E$641,F29/$F$641,A29=$E$641,F29/$F$641,A29=$E$642,F29/$F$642,A29=$E$643,F29/$F$643,A29=$E$644,F29/$F$644,A29=$E$645,F29/$F$645,A29=$E$646,F29/$F$646,A29=$E$647,F29/$F$647)} -> 0.025628386 | H29: {=_xlfn.IFS(A29=$P$24,G29*$Q$24,A29=$P$25,G29*$Q$25,A29=$P$26,G29*$Q$26,A29=$P$27,G29*$Q$27,A29=$P$28,G29*$Q$28,A29=$P$29,G29*$Q$29,A29=$P$30,G29*$Q$30,A29=$P$31,G29*$Q$31)} -> 11749385 | I29: =SUM(H29,E29) -> 11809777 | J29: =SUM(I29,D29) -> 12574311 | N29: 2020 | O29: =SUMIF($A$2:$A$638,N29,$H$2:$H$638) -> 4.3289438e+08 | P29: 2020 | Q29: =SUM(Q7,Q18) -> 432894384 | R29: =O29=Q29 -> TRUE
A30: 2015 | C30: Mineral County Board of Education | D30: 395816 | E30: 31266 | F30: 427082 | G30: {=_xlfn.IFS(A30=$E$640,F30/$F$640,A30=$E$641,F30/$F$641,A30=$E$641,F30/$F$641,A30=$E$642,F30/$F$642,A30=$E$643,F30/$F$643,A30=$E$644,F30/$F$644,A30=$E$645,F30/$F$645,A30=$E$646,F30/$F$646,A30=$E$647,F30/$F$647)} -> 0.013268369 | H30: {=_xlfn.IFS(A30=$P$24,G30*$Q$24,A30=$P$25,G30*$Q$25,A30=$P$26,G30*$Q$26,A30=$P$27,G30*$Q$27,A30=$P$28,G30*$Q$28,A30=$P$29,G30*$Q$29,A30=$P$30,G30*$Q$30,A30=$P$31,G30*$Q$31)} -> 6082910.4 | I30: =SUM(H30,E30) -> 6114176.4 | J30: =SUM(I30,D30) -> 6509992.4 | N30: 2021 | O30: =SUMIF($A$2:$A$638,N30,$H$2:$H$638) -> 389382173 | P30: 2021 | Q30: =SUM(Q8,Q19) -> 389382173 | R30: =O30=Q30 -> TRUE
A31: 2015 | C31: Mingo County Board of Education | D31: 285140 | E31: 22524 | F31: 307664 | G31: {=_xlfn.IFS(A31=$E$640,F31/$F$640,A31=$E$641,F31/$F$641,A31=$E$641,F31/$F$641,A31=$E$642,F31/$F$642,A31=$E$643,F31/$F$643,A31=$E$644,F31/$F$644,A31=$E$645,F31/$F$645,A31=$E$646,F31/$F$646,A31=$E$647,F31/$F$647)} -> 0.0095583504 | H31: {=_xlfn.IFS(A31=$P$24,G31*$Q$24,A31=$P$25,G31*$Q$25,A31=$P$26,G31*$Q$26,A31=$P$27,G31*$Q$27,A31=$P$28,G31*$Q$28,A31=$P$29,G31*$Q$29,A31=$P$30,G31*$Q$30,A31=$P$31,G31*$Q$31)} -> 4382045 | I31: =SUM(H31,E31) -> 4404569 | J31: =SUM(I31,D31) -> 4689709 | N31: 2022 | O31: =SUMIF($A$2:$A$638,N31,$H$2:$H$638) -> 448136727 | P31: 2022 | Q31: =SUM(Q9,Q20) -> 448136727 | R31: =O31=Q31 -> TRUE
A32: 2015 | C32: Monongalia County Board of Education | D32: 1308604 | E32: 103368 | F32: 1411972 | G32: {=_xlfn.IFS(A32=$E$640,F32/$F$640,A32=$E$641,F32/$F$641,A32=$E$641,F32/$F$641,A32=$E$642,F32/$F$642,A32=$E$643,F32/$F$643,A32=$E$644,F32/$F$644,A32=$E$645,F32/$F$645,A32=$E$646,F32/$F$646,A32=$E$647,F32/$F$647)} -> 0.043866436 | H32: {=_xlfn.IFS(A32=$P$24,G32*$Q$24,A32=$P$25,G32*$Q$25,A32=$P$26,G32*$Q$26,A32=$P$27,G32*$Q$27,A32=$P$28,G32*$Q$28,A32=$P$29,G32*$Q$29,A32=$P$30,G32*$Q$30,A32=$P$31,G32*$Q$31)} -> 20110656 | I32: =SUM(H32,E32) -> 20214024 | J32: =SUM(I32,D32) -> 21522628
A33: 2015 | C33: Monroe County Board of Education | D33: 125414 | E33: 9906 | F33: 135320 | G33: {=_xlfn.IFS(A33=$E$640,F33/$F$640,A33=$E$641,F33/$F$641,A33=$E$641,F33/$F$641,A33=$E$642,F33/$F$642,A33=$E$643,F33/$F$643,A33=$E$644,F33/$F$644,A33=$E$645,F33/$F$645,A33=$E$646,F33/$F$646,A33=$E$647,F33/$F$647)} -> 0.0042040537 | H33: {=_xlfn.IFS(A33=$P$24,G33*$Q$24,A33=$P$25,G33*$Q$25,A33=$P$26,G33*$Q$26,A33=$P$27,G33*$Q$27,A33=$P$28,G33*$Q$28,A33=$P$29,G33*$Q$29,A33=$P$30,G33*$Q$30,A33=$P$31,G33*$Q$31)} -> 1927356.9 | I33: =SUM(H33,E33) -> 1937262.9 | J33: =SUM(I33,D33) -> 2062676.9
A34: 2015 | C34: Morgan County Board of Education | D34: 128245 | E34: 10130 | F34: 138375 | G34: {=_xlfn.IFS(A34=$E$640,F34/$F$640,A34=$E$641,F34/$F$641,A34=$E$641,F34/$F$641,A34=$E$642,F34/$F$642,A34=$E$643,F34/$F$643,A34=$E$644,F34/$F$644,A34=$E$645,F34/$F$645,A34=$E$646,F34/$F$646,A34=$E$647,F34/$F$647)} -> 0.0042989649 | H34: {=_xlfn.IFS(A34=$P$24,G34*$Q$24,A34=$P$25,G34*$Q$25,A34=$P$26,G34*$Q$26,A34=$P$27,G34*$Q$27,A34=$P$28,G34*$Q$28,A34=$P$29,G34*$Q$29,A34=$P$30,G34*$Q$30,A34=$P$31,G34*$Q$31)} -> 1970869.1 | I34: =SUM(H34,E34) -> 1980999.1 | J34: =SUM(I34,D34) -> 2109244.1
A35: 2015 | C35: Nicholas County Board of Education | D35: 279542 | E35: 22081 | F35: 301623 | G35: {=_xlfn.IFS(A35=$E$640,F35/$F$640,A35=$E$641,F35/$F$641,A35=$E$641,F35/$F$641,A35=$E$642,F35/$F$642,A35=$E$643,F35/$F$643,A35=$E$644,F35/$F$644,A35=$E$645,F35/$F$645,A35=$E$646,F35/$F$646,A35=$E$647,F35/$F$647)} -> 0.0093706716 | H35: {=_xlfn.IFS(A35=$P$24,G35*$Q$24,A35=$P$25,G35*$Q$25,A35=$P$26,G35*$Q$26,A35=$P$27,G35*$Q$27,A35=$P$28,G35*$Q$28,A35=$P$29,G35*$Q$29,A35=$P$30,G35*$Q$30,A35=$P$31,G35*$Q$31)} -> 4296003.3 | I35: =SUM(H35,E35) -> 4318084.3 | J35: =SUM(I35,D35) -> 4597626.3
A36: 2015 | C36: Ohio County Board of Education | D36: 580235 | E36: 45833 | F36: 626068 | G36: {=_xlfn.IFS(A36=$E$640,F36/$F$640,A36=$E$641,F36/$F$641,A36=$E$641,F36/$F$641,A36=$E$642,F36/$F$642,A36=$E$643,F36/$F$643,A36=$E$644,F36/$F$644,A36=$E$645,F36/$F$645,A36=$E$646,F36/$F$646,A36=$E$647,F36/$F$647)} -> 0.019450366 | H36: {=_xlfn.IFS(A36=$P$24,G36*$Q$24,A36=$P$25,G36*$Q$25,A36=$P$26,G36*$Q$26,A36=$P$27,G36*$Q$27,A36=$P$28,G36*$Q$28,A36=$P$29,G36*$Q$29,A36=$P$30,G36*$Q$30,A36=$P$31,G36*$Q$31)} -> 8917059.4 | I36: =SUM(H36,E36) -> 8962892.4 | J36: =SUM(I36,D36) -> 9543127.4
A37: 2015 | C37: Pendleton County Board of Education | D37: 45161 | E37: 3567 | F37: 48728 | G37: {=_xlfn.IFS(A37=$E$640,F37/$F$640,A37=$E$641,F37/$F$641,A37=$E$641,F37/$F$641,A37=$E$642,F37/$F$642,A37=$E$643,F37/$F$643,A37=$E$644,F37/$F$644,A37=$E$645,F37/$F$645,A37=$E$646,F37/$F$646,A37=$E$647,F37/$F$647)} -> 0.001513857 | H37: {=_xlfn.IFS(A37=$P$24,G37*$Q$24,A37=$P$25,G37*$Q$25,A37=$P$26,G37*$Q$26,A37=$P$27,G37*$Q$27,A37=$P$28,G37*$Q$28,A37=$P$29,G37*$Q$29,A37=$P$30,G37*$Q$30,A37=$P$31,G37*$Q$31)} -> 694030.79 | I37: =SUM(H37,E37) -> 697597.79 | J37: =SUM(I37,D37) -> 742758.79
A38: 2015 | C38: Pleasants County Board of Education | D38: 191654 | E38: 15139 | F38: 206793 | G38: {=_xlfn.IFS(A38=$E$640,F38/$F$640,A38=$E$641,F38/$F$641,A38=$E$641,F38/$F$641,A38=$E$642,F38/$F$642,A38=$E$643,F38/$F$643,A38=$E$644,F38/$F$644,A38=$E$645,F38/$F$645,A38=$E$646,F38/$F$646,A38=$E$647,F38/$F$647)} -> 0.0064245409 | H38: {=_xlfn.IFS(A38=$P$24,G38*$Q$24,A38=$P$25,G38*$Q$25,A38=$P$26,G38*$Q$26,A38=$P$27,G38*$Q$27,A38=$P$28,G38*$Q$28,A38=$P$29,G38*$Q$29,A38=$P$30,G38*$Q$30,A38=$P$31,G38*$Q$31)} -> 2945343.7 | I38: =SUM(H38,E38) -> 2960482.7 | J38: =SUM(I38,D38) -> 3152136.7
A39: 2015 | C39: Pocahontas County Board of Education | D39: 49077 | E39: 3877 | F39: 52954 | G39: {=_xlfn.IFS(A39=$E$640,F39/$F$640,A39=$E$641,F39/$F$641,A39=$E$641,F39/$F$641,A39=$E$642,F39/$F$642,A39=$E$643,F39/$F$643,A39=$E$644,F39/$F$644,A39=$E$645,F39/$F$645,A39=$E$646,F39/$F$646,A39=$E$647,F39/$F$647)} -> 0.0016451482 | H39: {=_xlfn.IFS(A39=$P$24,G39*$Q$24,A39=$P$25,G39*$Q$25,A39=$P$26,G39*$Q$26,A39=$P$27,G39*$Q$27,A39=$P$28,G39*$Q$28,A39=$P$29,G39*$Q$29,A39=$P$30,G39*$Q$30,A39=$P$31,G39*$Q$31)} -> 754221.53 | I39: =SUM(H39,E39) -> 758098.53 | J39: =SUM(I39,D39) -> 807175.53
A40: 2015 | C40: Preston County Board of Education | D40: 58950 | E40: 4657 | F40: 63607 | G40: {=_xlfn.IFS(A40=$E$640,F40/$F$640,A40=$E$641,F40/$F$641,A40=$E$641,F40/$F$641,A40=$E$642,F40/$F$642,A40=$E$643,F40/$F$643,A40=$E$644,F40/$F$644,A40=$E$645,F40/$F$645,A40=$E$646,F40/$F$646,A40=$E$647,F40/$F$647)} -> 0.0019761103 | H40: {=_xlfn.IFS(A40=$P$24,G40*$Q$24,A40=$P$25,G40*$Q$25,A40=$P$26,G40*$Q$26,A40=$P$27,G40*$Q$27,A40=$P$28,G40*$Q$28,A40=$P$29,G40*$Q$29,A40=$P$30,G40*$Q$30,A40=$P$31,G40*$Q$31)} -> 905951.75 | I40: =SUM(H40,E40) -> 910608.75 | J40: =SUM(I40,D40) -> 969558.75
...

Sheet NCES Match -->

Sheet Match
A1: District Name | B1: LEAID
A2: Barbour County Board of Education | B2: 5400030
A3: Eastern Panhandle Intructional Cooperative | B3: 5400058
A4: Southern Educational Services Cooperative | B4: 5400059
A5: Berkeley County Board of Education | B5: 5400060
A6: Mountain State Educational Services Cooperative | B6: 5400061
A7: Boone County Board of Education | B7: 5400090
A8: Braxton County Board of Education | B8: 5400120
A9: Brooke County Board of Education | B9: 5400150
A10: Cabell County Board of Education | B10: 5400180
A11: Calhoun County Board of Education | B11: 5400210
A12: Clay County Board of Education | B12: 5400240
A13: Doddridge County Board of Education | B13: 5400270
... A60: Wyoming County Board of Education | B60: 5401650
A61: Blue Ridge Community and Technical College
A62: Bluefield State College
A63: Bridge Valley Community & Technical College
A64: Concord University
A65: Fairmont State University
A66: Glenville State College
A67: Marshall University
A68: Marshall University Research Corp
A69: Mountwest Community and Technical College
A70: New River Community and Technical College
A71: Pierpont Community & Technical College
A72: River Valley Child Development Services
... A84: West Virginia University at Parkersburg
