Workbook

Sheet Summary
A1: LEAID | B1: Year | C1: State | D1: state_abv | E1: plan | F1: employer_number | G1: district_name | H1: peers_district_contributions | I1: psrs_district_contributions | J1: LEAID_match | K1: count
A2: =J2 -> 2922980 | B2: 2015 | C2: Missouri | D2: MO | E2: Public Education Employee Retirement System of Missouri | F2: 1 | G2: Adair Co. R-1 Schools | H2: 26384 | I2: 190567 | J2: =IFERROR(VLOOKUP(G2,'LEAID Match'!$A$2:$B$526,2,FALSE),"") -> 2922980 | K2: =COUNTIF($J$2:$J$4295,J2) -> 8
A3: =J3 -> 2922980 | B3: 2016 | C3: Missouri | D3: MO | E3: Public Education Employee Retirement System of Missouri | F3: 1 | G3: Adair Co. R-1 Schools | H3: 28983 | I3: 184107 | J3: =IFERROR(VLOOKUP(G3,'LEAID Match'!$A$2:$B$526,2,FALSE),"") -> 2922980 | K3: =COUNTIF($J$2:$J$4295,J3) -> 8
A4: =J4 -> 2922980 | B4: 2017 | C4: Missouri | D4: MO | E4: Public Education Employee Retirement System of Missouri | F4: 1 | G4: Adair Co. R-1 Schools | H4: 28306 | I4: 172583 | J4: =IFERROR(VLOOKUP(G4,'LEAID Match'!$A$2:$B$526,2,FALSE),"") -> 2922980 | K4: =COUNTIF($J$2:$J$4295,J4) -> 8
A5: =J5 -> 2922980 | B5: 2018 | C5: Missouri | D5: MO | E5: Public Education Employee Retirement System of Missouri | F5: 1 | G5: Adair Co. R-1 Schools | H5: 28400 | I5: 184671 | J5: =IFERROR(VLOOKUP(G5,'LEAID Match'!$A$2:$B$526,2,FALSE),"") -> 2922980 | K5: =COUNTIF($J$2:$J$4295,J5) -> 8
A6: =J6 -> 2922980 | B6: 2019 | C6: Missouri | D6: MO | E6: Public Education Employee Retirement System of Missouri | F6: 1 | G6: Adair Co. R-1 Schools | H6: 30289 | I6: 179422 | J6: =IFERROR(VLOOKUP(G6,'LEAID Match'!$A$2:$B$526,2,FALSE),"") -> 2922980 | K6: =COUNTIF($J$2:$J$4295,J6) -> 8
A7: =J7 -> 2922980 | B7: 2020 | C7: Missouri | D7: MO | E7: Public Education Employee Retirement System of Missouri | F7: 1 | G7: Adair Co. R-1 Schools | H7: 29091 | I7: 180074 | J7: =IFERROR(VLOOKUP(G7,'LEAID Match'!$A$2:$B$526,2,FALSE),"") -> 2922980 | K7: =COUNTIF($J$2:$J$4295,J7) -> 8
A8: =J8 -> 2922980 | B8: 2021 | C8: Missouri | D8: MO | E8: Public Education Employee Retirement System of Missouri | F8: 1 | G8: Adair Co. R-1 Schools | H8: 30013 | I8: 174971 | J8: =IFERROR(VLOOKUP(G8,'LEAID Match'!$A$2:$B$526,2,FALSE),"") -> 2922980 | K8: =COUNTIF($J$2:$J$4295,J8) -> 8
A9: =J9 -> 2922980 | B9: 2022 | C9: Missouri | D9: MO | E9: Public Education Employee Retirement System of Missouri | F9: 1 | G9: Adair Co. R-1 Schools | H9: 29054 | I9: 189158 | J9: =IFERROR(VLOOKUP(G9,'LEAID Match'!$A$2:$B$526,2,FALSE),"") -> 2922980 | K9: =COUNTIF($J$2:$J$4295,J9) -> 8
A10: =J10 -> 2905790 | B10: 2015 | C10: Missouri | D10: MO | E10: Public Education Employee Retirement System of Missouri | F10: 2 | G10: Adair County R-II Schools | H10: 19636 | I10: 154138 | J10: =IFERROR(VLOOKUP(G10,'LEAID Match'!$A$2:$B$526,2,FALSE),"") -> 2905790 | K10: =COUNTIF($J$2:$J$4295,J10) -> 8
A11: =J11 -> 2905790 | B11: 2016 | C11: Missouri | D11: MO | E11: Public Education Employee Retirement System of Missouri | F11: 2 | G11: Adair County R-II Schools | H11: 19230 | I11: 157907 | J11: =IFERROR(VLOOKUP(G11,'LEAID Match'!$A$2:$B$526,2,FALSE),"") -> 2905790 | K11: =COUNTIF($J$2:$J$4295,J11) -> 8
A12: =J12 -> 2905790 | B12: 2017 | C12: Missouri | D12: MO | E12: Public Education Employee Retirement System of Missouri | F12: 2 | G12: Adair County R-II Schools | H12: 20124 | I12: 159244 | J12: =IFERROR(VLOOKUP(G12,'LEAID Match'!$A$2:$B$526,2,FALSE),"") -> 2905790 | K12: =COUNTIF($J$2:$J$4295,J12) -> 8
A13: =J13 -> 2905790 | B13: 2018 | C13: Missouri | D13: MO | E13: Public Education Employee Retirement System of Missouri | F13: 2 | G13: Adair County R-II Schools | H13: 20012 | I13: 154375 | J13: =IFERROR(VLOOKUP(G13,'LEAID Match'!$A$2:$B$526,2,FALSE),"") -> 2905790 | K13: =COUNTIF($J$2:$J$4295,J13) -> 8
... A810: =J810 -> 2919320 | B810: 2015 | C810: Missouri | D810: MO | E810: Public Education Employee Retirement System of Missouri | F810: 149 | G810: Luray 33 Public Schools | H810: 9106 | I810: 33278 | J810: =IFERROR(VLOOKUP(G810,'LEAID Match'!$A$2:$B$526,2,FALSE),"") -> 2919320 | K810: =COUNTIF($J$2:$J$4295,J810) -> 8
A811: =J811 -> 2919320 | B811: 2016 | C811: Missouri | D811: MO | E811: Public Education Employee Retirement System of Missouri | F811: 149 | G811: Luray 33 Public Schools | J811: =IFERROR(VLOOKUP(G811,'LEAID Match'!$A$2:$B$526,2,FALSE),"") -> 2919320 | K811: =COUNTIF($J$2:$J$4295,J811) -> 8
A812: =J812 -> 2919320 | B812: 2017 | C812: Missouri | D812: MO | E812: Public Education Employee Retirement System of Missouri | F812: 149 | G812: Luray 33 Public Schools | J812: =IFERROR(VLOOKUP(G812,'LEAID Match'!$A$2:$B$526,2,FALSE),"") -> 2919320 | K812: =COUNTIF($J$2:$J$4295,J812) -> 8
A813: =J813 -> 2919320 | B813: 2018 | C813: Missouri | D813: MO | E813: Public Education Employee Retirement System of Missouri | F813: 149 | G813: Luray 33 Public Schools | J813: =IFERROR(VLOOKUP(G813,'LEAID Match'!$A$2:$B$526,2,FALSE),"") -> 2919320 | K813: =COUNTIF($J$2:$J$4295,J813) -> 8
A814: =J814 -> 2919320 | B814: 2019 | C814: Missouri | D814: MO | E814: Public Education Employee Retirement System of Missouri | F814: 149 | G814: Luray 33 Public Schools | J814: =IFERROR(VLOOKUP(G814,'LEAID Match'!$A$2:$B$526,2,FALSE),"") -> 2919320 | K814: =COUNTIF($J$2:$J$4295,J814) -> 8
A815: =J815 -> 2919320 | B815: 2020 | C815: Missouri | D815: MO | E815: Public Education Employee Retirement System of Missouri | F815: 149 | G815: Luray 33 Public Schools | J815: =IFERROR(VLOOKUP(G815,'LEAID Match'!$A$2:$B$526,2,FALSE),"") -> 2919320 | K815: =COUNTIF($J$2:$J$4295,J815) -> 8
A816: =J816 -> 2919320 | B816: 2021 | C816: Missouri | D816: MO | E816: Public Education Employee Retirement System of Missouri | F816: 149 | G816: Luray 33 Public Schools | J816: =IFERROR(VLOOKUP(G816,'LEAID Match'!$A$2:$B$526,2,FALSE),"") -> 2919320 | K816: =COUNTIF($J$2:$J$4295,J816) -> 8
A817: =J817 -> 2919320 | B817: 2022 | C817: Missouri | D817: MO | E817: Public Education Employee Retirement System of Missouri | F817: 149 | G817: Luray 33 Public Schools | J817: =IFERROR(VLOOKUP(G817,'LEAID Match'!$A$2:$B$526,2,FALSE),"") -> 2919320 | K817: =COUNTIF($J$2:$J$4295,J817) -> 8
A818: =J818 -> 2916450 | B818: 2015 | C818: Missouri | D818: MO | E818: Public Education Employee Retirement System of Missouri | F818: 151 | G818: Kearney R-1 Schools | H818: 249869 | I818: 2479116 | J818: =IFERROR(VLOOKUP(G818,'LEAID Match'!$A$2:$B$526,2,FALSE),"") -> 2916450 | K818: =COUNTIF($J$2:$J$4295,J818) -> 8
A819: =J819 -> 2916450 | B819: 2016 | C819: Missouri | D819: MO | E819: Public Education Employee Retirement System of Missouri | F819: 151 | G819: Kearney R-1 Schools | H819: 270497 | I819: 2491163 | J819: =IFERROR(VLOOKUP(G819,'LEAID Match'!$A$2:$B$526,2,FALSE),"") -> 2916450 | K819: =COUNTIF($J$2:$J$4295,J819) -> 8
A820: =J820 -> 2916450 | B820: 2017 | C820: Missouri | D820: MO | E820: Public Education Employee Retirement System of Missouri | F820: 151 | G820: Kearney R-1 Schools | H820: 292279 | I820: 2565384 | J820: =IFERROR(VLOOKUP(G820,'LEAID Match'!$A$2:$B$526,2,FALSE),"") -> 2916450 | K820: =COUNTIF($J$2:$J$4295,J820) -> 8
A821: =J821 -> 2916450 | B821: 2018 | C821: Missouri | D821: MO | E821: Public Education Employee Retirement System of Missouri | F821: 151 | G821: Kearney R-1 Schools | H821: 303258 | I821: 2562167 | J821: =IFERROR(VLOOKUP(G821,'LEAID Match'!$A$2:$B$526,2,FALSE),"") -> 2916450 | K821: =COUNTIF($J$2:$J$4295,J821) -> 8
A822: =J822 -> 2916450 | B822: 2019 | C822: Missouri | D822: MO | E822: Public Education Employee Retirement System of Missouri | F822: 151 | G822: Kearney R-1 Schools | H822: 324773 | I822: 2659388 | J822: =IFERROR(VLOOKUP(G822,'LEAID Match'!$A$2:$B$526,2,FALSE),"") -> 2916450 | K822: =COUNTIF($J$2:$J$4295,J822) -> 8
A823: =J823 -> 2916450 | B823: 2020 | C823: Missouri | D823: MO | E823: Public Education Employee Retirement System of Missouri | F823: 151 | G823: Kearney R-1 Schools | H823: 354340 | I823: 2740625 | J823: =IFERROR(VLOOKUP(G823,'LEAID Match'!$A$2:$B$526,2,FALSE),"") -> 2916450 | K823: =COUNTIF($J$2:$J$4295,J823) -> 8
A824: =J824 -> 2916450 | B824: 2021 | C824: Missouri | D824: MO | E824: Public Education Employee Retirement System of Missouri | F824: 151 | G824: Kearney R-1 Schools | H824: 356137 | I824: 2780541 | J824: =IFERROR(VLOOKUP(G824,'LEAID Match'!$A$2:$B$526,2,FALSE),"") -> 2916450 | K824: =COUNTIF($J$2:$J$4295,J824) -> 8
A825: =J825 -> 2916450 | B825: 2022 | C825: Missouri | D825: MO | E825: Public Education Employee Retirement System of Missouri | F825: 151 | G825: Kearney R-1 Schools | H825: 383887 | I825: 2831072 | J825: =IFERROR(VLOOKUP(G825,'LEAID Match'!$A$2:$B$526,2,FALSE),"") -> 2916450 | K825: =COUNTIF($J$2:$J$4295,J825) -> 8
A826: =J826 -> 2928410 | B826: 2015 | C826: Missouri | D826: MO | E826: Public Education Employee Retirement System of Missouri | F826: 152 | G826: Smithville R-II Schools | H826: 199483 | I826: 1678978 | J826: =IFERROR(VLOOKUP(G826,'LEAID Match'!$A$2:$B$526,2,FALSE),"") -> 2928410 | K826: =COUNTIF($J$2:$J$4295,J826) -> 8
A827: =J827 -> 2928410 | B827: 2016 | C827: Missouri | D827: MO | E827: Public Education Employee Retirement System of Missouri | F827: 152 | G827: Smithville R-II Schools | H827: 218287 | I827: 1768415 | J827: =IFERROR(VLOOKUP(G827,'LEAID Match'!$A$2:$B$526,2,FALSE),"") -> 2928410 | K827: =COUNTIF($J$2:$J$4295,J827) -> 8
A828: =J828 -> 2928410 | B828: 2017 | C828: Missouri | D828: MO | E828: Public Education Employee Retirement System of Missouri | F828: 152 | G828: Smithville R-II Schools | H828: 225707 | I828: 1817156 | J828: =IFERROR(VLOOKUP(G828,'LEAID Match'!$A$2:$B$526,2,FALSE),"") -> 2928410 | K828: =COUNTIF($J$2:$J$4295,J828) -> 8
A829: =J829 -> 2928410 | B829: 2018 | C829: Missouri | D829: MO | E829: Public Education Employee Retirement System of Missouri | F829: 152 | G829: Smithville R-II Schools | H829: 247614 | I829: 1873954 | J829: =IFERROR(VLOOKUP(G829,'LEAID Match'!$A$2:$B$526,2,FALSE),"") -> 2928410 | K829: =COUNTIF($J$2:$J$4295,J829) -> 8
... A3626: =J3626 -> 2913020 | B3626: 2015 | C3626: Missouri | D3626: MO | E3626: Public Education Employee Retirement System of Missouri | F3626: 603 | G3626: Gorin R-III Schools | H3626: 5685 | I3626: 45956 | J3626: =IFERROR(VLOOKUP(G3626,'LEAID Match'!$A$2:$B$526,2,FALSE),"") -> 2913020 | K3626: =COUNTIF($J$2:$J$4295,J3626) -> 8
A3627: =J3627 -> 2913020 | B3627: 2016 | C3627: Missouri | D3627: MO | E3627: Public Education Employee Retirement System of Missouri | F3627: 603 | G3627: Gorin R-III Schools | H3627: 0 | J3627: =IFERROR(VLOOKUP(G3627,'LEAID Match'!$A$2:$B$526,2,FALSE),"") -> 2913020 | K3627: =COUNTIF($J$2:$J$4295,J3627) -> 8
A3628: =J3628 -> 2913020 | B3628: 2017 | C3628: Missouri | D3628: MO | E3628: Public Education Employee Retirement System of Missouri | F3628: 603 | G3628: Gorin R-III Schools | H3628: - | J3628: =IFERROR(VLOOKUP(G3628,'LEAID Match'!$A$2:$B$526,2,FALSE),"") -> 2913020 | K3628: =COUNTIF($J$2:$J$4295,J3628) -> 8
A3629: =J3629 -> 2913020 | B3629: 2018 | C3629: Missouri | D3629: MO | E3629: Public Education Employee Retirement System of Missouri | F3629: 603 | G3629: Gorin R-III Schools | H3629: - | J3629: =IFERROR(VLOOKUP(G3629,'LEAID Match'!$A$2:$B$526,2,FALSE),"") -> 2913020 | K3629: =COUNTIF($J$2:$J$4295,J3629) -> 8
A3630: =J3630 -> 2913020 | B3630: 2019 | C3630: Missouri | D3630: MO | E3630: Public Education Employee Retirement System of Missouri | F3630: 603 | G3630: Gorin R-III Schools | J3630: =IFERROR(VLOOKUP(G3630,'LEAID Match'!$A$2:$B$526,2,FALSE),"") -> 2913020 | K3630: =COUNTIF($J$2:$J$4295,J3630) -> 8
A3631: =J3631 -> 2913020 | B3631: 2020 | C3631: Missouri | D3631: MO | E3631: Public Education Employee Retirement System of Missouri | F3631: 603 | G3631: Gorin R-III Schools | J3631: =IFERROR(VLOOKUP(G3631,'LEAID Match'!$A$2:$B$526,2,FALSE),"") -> 2913020 | K3631: =COUNTIF($J$2:$J$4295,J3631) -> 8
A3632: =J3632 -> 2913020 | B3632: 2021 | C3632: Missouri | D3632: MO | E3632: Public Education Employee Retirement System of Missouri | F3632: 603 | G3632: Gorin R-III Schools | J3632: =IFERROR(VLOOKUP(G3632,'LEAID Match'!$A$2:$B$526,2,FALSE),"") -> 2913020 | K3632: =COUNTIF($J$2:$J$4295,J3632) -> 8
...

Sheet GASB Data -->

Sheet 2015
A1: Year | B1: employer_number | C1: district_name | D1: district_contributions | E1: district_contributions
A2: 2015 | B2: 1 | C2: Adair Co. R-1 Schools | D2: 26384 | E2: 190567
A3: 2015 | B3: 2 | C3: Adair County R-II Schools | D3: 19636 | E3: 154138
A4: 2015 | B4: 3 | C4: Kirksville R-3 School District | D4: 289723 | E4: 1807287
A5: 2015 | B5: 4 | C5: Savannah R-III Schools | D5: 165016 | E5: 1392047
A6: 2015 | B6: 5 | C6: North Andrew Co. R-VI Schools | D6: 26564 | E6: 259917
A7: 2015 | B7: 6 | C7: Avenue City R-IX Schools | D7: 14040 | E7: 104151
A8: 2015 | B8: 8 | C8: Tarkio R-I Schools | D8: 46642 | E8: 328014
A9: 2015 | B9: 9 | C9: Rock Port R-II Schools | D9: 32781 | E9: 282745
A10: 2015 | B10: 10 | C10: Fairfax R-III Schools | D10: 11391 | E10: 143192
A11: 2015 | B11: 12 | C11: Van-Far R-I Schools | D11: 65500 | E11: 412520
A12: 2015 | B12: 14 | C12: Community R-VI Schools | D12: 32519 | E12: 212360
A13: 2015 | B13: 15 | C13: Mexico Public Schools | D13: 256131 | E13: 1536970
... A518: 2015 | B518: 699 | C518: Portageville Schools | D518: 34194 | E518: 490528
A519: 2015 | B519: 701 | C519: MO State Teachers Association | E519: 158691
A520: 2015 | B520: 702 | C520: MO High School Act. Assoc. | E520: 120853
A521: 2015 | B521: 704 | C521: Dept. of Elem. & Secondary Ed. | E521: 116774
A522: 2015 | B522: 708 | C522: Division .of Youth Services | E522: 10434
A523: 2015 | B523: 711 | C523: Coop. Sch. Dist. of St. Louis | D523: 211523 | E523: 183052
A524: 2015 | B524: 714 | C524: Missouri Council of School Administrators | D524: 30894
A525: 2015 | B525: 750 | C525: Pemiscot Co. Special Schools | D525: 77528 | E525: 374684
A526: 2015 | B526: 801 | C526: Three Rivers Community College | D526: 123519 | E526: 1275237
A527: 2015 | B527: 802 | C527: East Central College | D527: 217873 | E527: 1209650
A528: 2015 | B528: 803 | C528: Metropolitan Community College | D528: 2123413 | E528: 4159289
A529: 2015 | B529: 805 | C529: Jefferson College | D529: 434618 | E529: 1704191
A530: 2015 | B530: 806 | C530: Crowder College | D530: 245367 | E530: 2003943
A531: 2015 | B531: 807 | C531: State Fair Community College | D531: 180322 | E531: 1563698
A532: 2015 | B532: 808 | C532: Moberly Area Community College | D532: 271340 | E532: 1322280
A533: 2015 | B533: 809 | C533: Mineral Area Community College | D533: 234094 | E533: 1271402
A534: 2015 | B534: 810 | C534: St. Louis Community College | E534: 8934195
A535: 2015 | B535: 811 | C535: North Central Missouri College | D535: 237330 | E535: 531454
A536: 2015 | B536: 812 | C536: St. Charles Comm. College | D536: 736516 | E536: 2085438
A537: 2015 | B537: 813 | C537: Ozarks Technical Comm. College | D537: 575577 | E537: 3447038
E539: =SUM(E2:E537) -> 656578129

Sheet 2016
A1: Year | B1: employer_number | C1: district_name | D1: district_contributions
A2: 2016 | B2: 1 | C2: Adair Co. R-1 Schools | D2: 28983 | E2: 184107 | O2: 0.000274
A3: 2016 | B3: 2 | C3: Adair County R-II Schools | D3: 19230 | E3: 157907 | O3: 0.000182
A4: 2016 | B4: 3 | C4: Kirksville R-3 School District | D4: 300832 | E4: 1837911 | O4: 0.00284
A5: 2016 | B5: 4 | C5: Savannah R-III Schools | D5: 174875 | E5: 1416674 | O5: 0.001651
A6: 2016 | B6: 5 | C6: North Andrew Co. R-VI Schools | D6: 27278 | E6: 272392 | O6: 0.000257
A7: 2016 | B7: 6 | C7: Avenue City R-IX Schools | D7: 19694 | E7: 101579 | O7: 0.000186
A8: 2016 | B8: 8 | C8: Tarkio R-I Schools | D8: 44842 | E8: 351285 | O8: 0.000423
A9: 2016 | B9: 9 | C9: Rock Port R-II Schools | D9: 32447 | E9: 296418 | O9: 0.000306
A10: 2016 | B10: 10 | C10: Fairfax R-III Schools | D10: 11194 | E10: 144360 | O10: 0.000106
A11: 2016 | B11: 12 | C11: Van-Far R-I Schools | D11: 63385 | E11: 414142 | O11: 0.000598
A12: 2016 | B12: 14 | C12: Community R-VI Schools | D12: 36821 | E12: 216421 | O12: 0.000348
A13: 2016 | B13: 15 | C13: Mexico Public Schools | D13: 270051 | E13: 1600561 | O13: 0.002549
... A45: 2016 | B45: 64 | C45: Mid-Buchanan Co R-V Schools | D45: 56139 | E45: 459925 | O45: 0.00053
A46: 2016 | B46: 65 | C46: East Buchanan Co C-1 Schools | D46: 55572 | E46: 520966
A47: 2016 | B47: 66 | C47: St. Joseph Public Schools | D47: 1527584 | E47: 8297465
A48: 2016 | B48: 67 | C48: Poplar Bluff R-I Schools | D48: 463057 | E48: 3155808
A49: 2016 | B49: 68 | C49: Neelyville R-IV Schools | D49: 50201 | E49: 423466
A50: 2016 | B50: 69 | C50: Twin Rivers R-X Schools | D50: 108774 | E50: 616289
A51: 2016 | B51: 74 | C51: Breckenridge R-1 Schools | D51: 15138 | E51: 87660
A52: 2016 | B52: 75 | C52: Hamilton R-II Schools | D52: 57509 | E52: 479448
A53: 2016 | B53: 76 | C53: New York R-IV Schools | D53: 2462 | E53: 37610
A54: 2016 | B54: 77 | C54: Cowgill R-VI Schools | D54: 5372 | E54: 38650
A55: 2016 | B55: 78 | C55: Polo R-VII Schools | D55: 36058 | E55: 299666
A56: 2016 | B56: 79 | C56: Mirabile C-1 Schools | D56: 5261 | E56: 44880
A57: 2016 | B57: 80 | C57: Braymer C-4 Schools | D57: 23888 | E57: 199863
... A102: 2016 | B102: 144 | C102: Clark Co. R-I Schools | D102: 74964 | E102: 674972
A103: 2016 | B103: 149 | C103: Luray 33 Public Schools
A104: 2016 | B104: 151 | C104: Kearney R-1 Schools | D104: 270497 | E104: 2491163
A105: 2016 | B105: 152 | C105: Smithville R-II Schools | D105: 218287 | E105: 1768415
A106: 2016 | B106: 154 | C106: Excelsior Springs 40 Schools | D106: 288084 | E106: 1900812
A107: 2016 | B107: 155 | C107: Liberty Public Schools | D107: 1598344 | E107: 8529254
A108: 2016 | B108: 156 | C108: North Kansas City Schools | D108: 3009720 | E108: 15501055
A109: 2016 | B109: 165 | C109: Missouri City Public Schools | D109: 3359 | E109: 20305
A110: 2016 | B110: 167 | C110: Cameron R-I Schools | D110: 132305 | E110: 1144623
A111: 2016 | B111: 168 | C111: Lathrop R-II Schools | D111: 77832 | E111: 693918
A112: 2016 | B112: 169 | C112: Clinton Co. R-III Schools | D112: 34495 | E112: 501722
A113: 2016 | B113: 170 | C113: Cole County R-I Schools | D113: 50562 | E113: 372585
A114: 2016 | B114: 171 | C114: Cole Co. R-II Schools | D114: 76005 | E114: 649308
A115: 2016 | B115: 173 | C115: Cole Co. R-V Schools | D115: 42082 | E115: 392257
...

Sheet 2017
A1: Year | B1: employer_number | C1: district_name | D1: district_contributions
A2: 2017 | B2: 1 | C2: Adair Co. R-1 Schools | D2: 28306 | E2: 172583
A3: 2017 | B3: 2 | C3: Adair County R-II Schools | D3: 20124 | E3: 159244
A4: 2017 | B4: 3 | C4: Kirksville R-3 School District | D4: 295371 | E4: 1831402
A5: 2017 | B5: 4 | C5: Savannah R-III Schools | D5: 192455 | E5: 1480018
A6: 2017 | B6: 5 | C6: North Andrew Co. R-VI Schools | D6: 32087 | E6: 271813
A7: 2017 | B7: 6 | C7: Avenue City R-IX Schools | D7: 21011 | E7: 108409
A8: 2017 | B8: 8 | C8: Tarkio R-I Schools | D8: 41860 | E8: 338978
A9: 2017 | B9: 9 | C9: Rock Port R-II Schools | D9: 35107 | E9: 299436
A10: 2017 | B10: 10 | C10: Fairfax R-III Schools | D10: 10380 | E10: 144831
A11: 2017 | B11: 12 | C11: Van-Far R-I Schools | D11: 60887 | E11: 392581
A12: 2017 | B12: 14 | C12: Community R-VI Schools | D12: 35536 | E12: 218020
A13: 2017 | B13: 15 | C13: Mexico Public Schools | D13: 269163 | E13: 1592178
... A102: 2017 | B102: 144 | C102: Clark Co. R-I Schools | D102: 82934 | E102: 686909
A103: 2017 | B103: 149 | C103: Luray 33 Public Schools
A104: 2017 | B104: 151 | C104: Kearney R-1 Schools | D104: 292279 | E104: 2565384
A105: 2017 | B105: 152 | C105: Smithville R-II Schools | D105: 225707 | E105: 1817156
A106: 2017 | B106: 154 | C106: Excelsior Springs 40 Schools | D106: 295949 | E106: 1954845
A107: 2017 | B107: 155 | C107: Liberty Public Schools | D107: 1713938 | E107: 8837739
A108: 2017 | B108: 156 | C108: North Kansas City Schools | D108: 3138926 | E108: 15992950
A109: 2017 | B109: 165 | C109: Missouri City Public Schools | D109: 3776 | E109: 20988
A110: 2017 | B110: 167 | C110: Cameron R-I Schools | D110: 147264 | E110: 1115040
A111: 2017 | B111: 168 | C111: Lathrop R-II Schools | D111: 78928 | E111: 711392
A112: 2017 | B112: 169 | C112: Clinton Co. R-III Schools | D112: 27229 | E112: 496130
A113: 2017 | B113: 170 | C113: Cole County R-I Schools | D113: 48091 | E113: 364926
A114: 2017 | B114: 171 | C114: Cole Co. R-II Schools | D114: 80623 | E114: 698695
A115: 2017 | B115: 173 | C115: Cole Co. R-V Schools | D115: 42268 | E115: 384035
... A454: 2017 | B454: 602 | C454: Scotland Co. R-I Schools | D454: 72663 | E454: 406258
A455: 2017 | B455: 603 | C455: Gorin R-III Schools
A456: 2017 | B456: 607 | C456: Scott City R-I Schools | D456: 64893 | E456: 613611
A457: 2017 | B457: 608 | C457: Chaffee R-II Schools | D457: 44922 | E457: 371123
A458: 2017 | B458: 609 | C458: Oran R-III Schools | D458: 19067 | E458: 225163
A459: 2017 | B459: 610 | C459: Scott Co. R-IV Schools | D459: 64295 | E459: 581596
A460: 2017 | B460: 611 | C460: Scott County Central Schools | D460: 29924 | E460: 283115
A461: 2017 | B461: 612 | C461: Sikeston R-VI Schools | D461: 300776 | E461: 2386075
A462: 2017 | B462: 613 | C462: Kelso C-7 Schools | D462: 10777 | E462: 93336
A463: 2017 | B463: 614 | C463: Eminence R-I Schools | D463: 32767 | E463: 168294
A464: 2017 | B464: 615 | C464: Winona R-III Schools | D464: 53239 | E464: 293091
A465: 2017 | B465: 617 | C465: Shelby Co. R-IV Schools | D465: 87361 | E465: 466874
A466: 2017 | B466: 618 | C466: Shelby Co. C-1 Schools | D466: 31479 | E466: 235898
...

Sheet 2018
A1: Year | B1: employer_number | C1: district_name | D1: district_contributions
A2: 2018 | B2: 1 | C2: Adair Co. R-1 Schools | D2: 28400 | E2: 184671 | O2: 0.000249
A3: 2018 | B3: 2 | C3: Adair County R-II Schools | D3: 20012 | E3: 154375 | O3: 0.000175
A4: 2018 | B4: 3 | C4: Kirksville R-3 School District | D4: 295540 | E4: 1853665 | O4: 0.002589
A5: 2018 | B5: 4 | C5: Savannah R-III Schools | D5: 197416 | E5: 1512868 | O5: 0.00173
A6: 2018 | B6: 5 | C6: North Andrew Co. R-VI Schools | D6: 33492 | E6: 287232 | O6: 0.000293
A7: 2018 | B7: 6 | C7: Avenue City R-IX Schools | D7: 21441 | E7: 109816 | O7: 0.000188
A8: 2018 | B8: 8 | C8: Tarkio R-I Schools | D8: 42920 | E8: 354304 | O8: 0.000376
A9: 2018 | B9: 9 | C9: Rock Port R-II Schools | D9: 35689 | E9: 295393 | O9: 0.000313
A10: 2018 | B10: 10 | C10: Fairfax R-III Schools | D10: 9834 | E10: 149095 | O10: 8.6e-05
A11: 2018 | B11: 12 | C11: Van-Far R-I Schools | D11: 60896 | E11: 371846 | O11: 0.000534
A12: 2018 | B12: 14 | C12: Community R-VI Schools | D12: 30757 | E12: 247535 | O12: 0.000269
A13: 2018 | B13: 15 | C13: Mexico Public Schools | D13: 267724 | E13: 1579509 | O13: 0.002346
... A45: 2018 | B45: 64 | C45: Mid-Buchanan Co R-V Schools | D45: 59056 | E45: 483236 | O45: 0.000517
A46: 2018 | B46: 65 | C46: East Buchanan Co C-1 Schools | D46: 55774 | E46: 519363
A47: 2018 | B47: 66 | C47: St. Joseph Public Schools | D47: 1626948 | E47: 8658685
A48: 2018 | B48: 67 | C48: Poplar Bluff R-I Schools | D48: 557902 | E48: 3245858
A49: 2018 | B49: 68 | C49: Neelyville R-IV Schools | D49: 51830 | E49: 441578
A50: 2018 | B50: 69 | C50: Twin Rivers R-X Schools | D50: 110181 | E50: 629863
A51: 2018 | B51: 74 | C51: Breckenridge R-1 Schools | D51: 22305 | E51: 69391
A52: 2018 | B52: 75 | C52: Hamilton R-II Schools | D52: 57505 | E52: 501921
A53: 2018 | B53: 76 | C53: New York R-IV Schools | D53: 1674 | E53: 28269
A54: 2018 | B54: 77 | C54: Cowgill R-VI Schools | D54: 7854 | E54: 38958
A55: 2018 | B55: 78 | C55: Polo R-VII Schools | D55: 42080 | E55: 295920
A56: 2018 | B56: 79 | C56: Mirabile C-1 Schools | D56: 6705 | E56: 41481
A57: 2018 | B57: 80 | C57: Braymer C-4 Schools | D57: 31960 | E57: 221077
... A102: 2018 | B102: 144 | C102: Clark Co. R-I Schools | D102: 90998 | E102: 720997
A103: 2018 | B103: 149 | C103: Luray 33 Public Schools
A104: 2018 | B104: 151 | C104: Kearney R-1 Schools | D104: 303258 | E104: 2562167
A105: 2018 | B105: 152 | C105: Smithville R-II Schools | D105: 247614 | E105: 1873954
A106: 2018 | B106: 154 | C106: Excelsior Springs 40 Schools | D106: 297781 | E106: 1972563
A107: 2018 | B107: 155 | C107: Liberty Public Schools | D107: 1779755 | E107: 9263860
A108: 2018 | B108: 156 | C108: North Kansas City Schools | D108: 3225423 | E108: 16434928
A109: 2018 | B109: 165 | C109: Missouri City Public Schools | D109: 2985 | E109: 23925
A110: 2018 | B110: 167 | C110: Cameron R-I Schools | D110: 149330 | E110: 1152808
A111: 2018 | B111: 168 | C111: Lathrop R-II Schools | D111: 82871 | E111: 724795
A112: 2018 | B112: 169 | C112: Clinton Co. R-III Schools | D112: 25680 | E112: 482144
A113: 2018 | B113: 170 | C113: Cole County R-I Schools | D113: 49527 | E113: 374041
A114: 2018 | B114: 171 | C114: Cole Co. R-II Schools | D114: 83538 | E114: 707882
A115: 2018 | B115: 173 | C115: Cole Co. R-V Schools | D115: 41497 | E115: 347951
...

Sheet 2019
A1: Year | B1: employer_number | C1: district_name | D1: district_contributions
A2: 2019 | B2: 1 | C2: Adair Co. R-1 Schools | D2: 30289 | E2: 179422
A3: 2019 | B3: 2 | C3: Adair County R-II Schools | D3: 22656 | E3: 156588
A4: 2019 | B4: 3 | C4: Kirksville R-3 School District | D4: 307005 | E4: 1863607
A5: 2019 | B5: 4 | C5: Savannah R-III Schools | D5: 198348 | E5: 1543846
A6: 2019 | B6: 5 | C6: North Andrew Co. R-VI Schools | D6: 34194 | E6: 300473
A7: 2019 | B7: 6 | C7: Avenue City R-IX Schools | D7: 21179 | E7: 112395
A8: 2019 | B8: 8 | C8: Tarkio R-I Schools | D8: 45281 | E8: 364657
A9: 2019 | B9: 9 | C9: Rock Port R-II Schools | D9: 35998 | E9: 288268
A10: 2019 | B10: 10 | C10: Fairfax R-III Schools | D10: 12636 | E10: 145082
A11: 2019 | B11: 12 | C11: Van-Far R-I Schools | D11: 62624 | E11: 379868
A12: 2019 | B12: 14 | C12: Community R-VI Schools | D12: 35687 | E12: 272493
A13: 2019 | B13: 15 | C13: Mexico Public Schools | D13: 278435 | E13: 1668819
... A102: 2019 | B102: 144 | C102: Clark Co. R-I Schools | D102: 103640 | E102: 741601
A103: 2019 | B103: 149 | C103: Luray 33 Public Schools
A104: 2019 | B104: 151 | C104: Kearney R-1 Schools | D104: 324773 | E104: 2659388
A105: 2019 | B105: 152 | C105: Smithville R-II Schools | D105: 270823 | E105: 1997568
A106: 2019 | B106: 154 | C106: Excelsior Springs 40 Schools | D106: 309680 | E106: 2018260
A107: 2019 | B107: 155 | C107: Liberty Public Schools | D107: 1853199 | E107: 9743579
A108: 2019 | B108: 156 | C108: North Kansas City Schools | D108: 3441193 | E108: 16936255
A109: 2019 | B109: 165 | C109: Missouri City Public Schools | D109: 3884 | E109: 22281
A110: 2019 | B110: 167 | C110: Cameron R-I Schools | D110: 156066 | E110: 1199911
A111: 2019 | B111: 168 | C111: Lathrop R-II Schools | D111: 82229 | E111: 724724
A112: 2019 | B112: 169 | C112: Clinton Co. R-III Schools | D112: 29774 | E112: 515998
A113: 2019 | B113: 170 | C113: Cole County R-I Schools | D113: 57992 | E113: 376630
A114: 2019 | B114: 171 | C114: Cole Co. R-II Schools | D114: 85297 | E114: 730557
A115: 2019 | B115: 173 | C115: Cole Co. R-V Schools | D115: 40553 | E115: 341959
... A454: 2019 | B454: 602 | C454: Scotland Co. R-I Schools | D454: 78842 | E454: 440134
A455: 2019 | B455: 603 | C455: Gorin R-III Schools
A456: 2019 | B456: 607 | C456: Scott City R-I Schools | D456: 66873 | E456: 590100
A457: 2019 | B457: 608 | C457: Chaffee R-II Schools | D457: 52144 | E457: 409489
A458: 2019 | B458: 609 | C458: Oran R-III Schools | D458: 16908 | E458: 229981
A459: 2019 | B459: 610 | C459: Scott Co. R-IV Schools | D459: 66499 | E459: 607367
A460: 2019 | B460: 611 | C460: Scott County Central Schools | D460: 30550 | E460: 238919
A461: 2019 | B461: 612 | C461: Sikeston R-VI Schools | D461: 303755 | E461: 2439190
A462: 2019 | B462: 613 | C462: Kelso C-7 Schools | D462: 16551 | E462: 105355
A463: 2019 | B463: 614 | C463: Eminence R-I Schools | D463: 37848 | E463: 173415
A464: 2019 | B464: 615 | C464: Winona R-III Schools | D464: 45876 | E464: 296098
A465: 2019 | B465: 617 | C465: Shelby Co. R-IV Schools | D465: 89386 | E465: 482291
A466: 2019 | B466: 618 | C466: Shelby Co. C-1 Schools | D466: 36039 | E466: 260897
...

Sheet 2020
A1: Year | B1: employer_number | C1: district_name | D1: district_contributions
A2: 2020 | B2: 1 | C2: Adair Co. R-1 Schools | D2: 29091 | E2: 180074
A3: 2020 | B3: 2 | C3: Adair County R-II Schools | D3: 21510 | E3: 166807
A4: 2020 | B4: 3 | C4: Kirksville R-3 School District | D4: 309258 | E4: 1863479
A5: 2020 | B5: 4 | C5: Savannah R-III Schools | D5: 189961 | E5: 1488889
A6: 2020 | B6: 5 | C6: North Andrew Co. R-VI Schools | D6: 37261 | E6: 301204
A7: 2020 | B7: 6 | C7: Avenue City R-IX Schools | D7: 19113 | E7: 116946
A8: 2020 | B8: 8 | C8: Tarkio R-I Schools | D8: 44848 | E8: 358330
A9: 2020 | B9: 9 | C9: Rock Port R-II Schools | D9: 36740 | E9: 289537
A10: 2020 | B10: 10 | C10: Fairfax R-III Schools | D10: 11166 | E10: 149210
A11: 2020 | B11: 12 | C11: Van-Far R-I Schools | D11: 66271 | E11: 367494
A12: 2020 | B12: 14 | C12: Community R-VI Schools | D12: 36153 | E12: 279421
A13: 2020 | B13: 15 | C13: Mexico Public Schools | D13: 295995 | E13: 1685144
... A102: 2020 | B102: 144 | C102: Clark Co. R-I Schools | D102: 99165 | E102: 750149
A103: 2020 | B103: 149 | C103: Luray 33 Public Schools
A104: 2020 | B104: 151 | C104: Kearney R-1 Schools | D104: 354340 | E104: 2740625
A105: 2020 | B105: 152 | C105: Smithville R-II Schools | D105: 269163 | E105: 1929395
A106: 2020 | B106: 154 | C106: Excelsior Springs 40 Schools | D106: 336196 | E106: 2019235
A107: 2020 | B107: 155 | C107: Liberty Public Schools | D107: 1968163 | E107: 10263578
A108: 2020 | B108: 156 | C108: North Kansas City Schools | D108: 3482176 | E108: 17536934
A109: 2020 | B109: 165 | C109: Missouri City Public Schools | D109: 4393 | E109: 25144
A110: 2020 | B110: 167 | C110: Cameron R-I Schools | D110: 157384 | E110: 1237291
A111: 2020 | B111: 168 | C111: Lathrop R-II Schools | D111: 85387 | E111: 733600
A112: 2020 | B112: 169 | C112: Clinton Co. R-III Schools | D112: 32144 | E112: 526865
A113: 2020 | B113: 170 | C113: Cole County R-I Schools | D113: 56633 | E113: 386832
A114: 2020 | B114: 171 | C114: Cole Co. R-II Schools | D114: 90592 | E114: 737716
A115: 2020 | B115: 173 | C115: Cole Co. R-V Schools | D115: 40867 | E115: 362781
... A454: 2020 | B454: 602 | C454: Scotland Co. R-I Schools | D454: 80347 | E454: 468347
A455: 2020 | B455: 603 | C455: Gorin R-III Schools
A456: 2020 | B456: 607 | C456: Scott City R-I Schools | D456: 70564 | E456: 592064
A457: 2020 | B457: 608 | C457: Chaffee R-II Schools | D457: 51797 | E457: 403895
A458: 2020 | B458: 609 | C458: Oran R-III Schools | D458: 17278 | E458: 225534
A459: 2020 | B459: 610 | C459: Scott Co. R-IV Schools | D459: 73588 | E459: 608658
A460: 2020 | B460: 611 | C460: Scott County Central Schools | D460: 25733 | E460: 239036
A461: 2020 | B461: 612 | C461: Sikeston R-VI Schools | D461: 325009 | E461: 2482499
A462: 2020 | B462: 613 | C462: Kelso C-7 Schools | D462: 15192 | E462: 114705
A463: 2020 | B463: 614 | C463: Eminence R-I Schools | D463: 42270 | E463: 178091
A464: 2020 | B464: 615 | C464: Winona R-III Schools | D464: 48488 | E464: 302890
A465: 2020 | B465: 617 | C465: Shelby Co. R-IV Schools | D465: 97437 | E465: 477385
A466: 2020 | B466: 618 | C466: Shelby Co. C-1 Schools | D466: 43105 | E466: 270027
...

Sheet 2021
A1: Year | B1: employer_number | C1: district_name | D1: district_contributions
A2: 2021 | B2: 1 | C2: Adair Co. R-1 Schools | D2: 30013 | E2: 174971
A3: 2021 | B3: 2 | C3: Adair County R-II Schools | D3: 20956 | E3: 174180
A4: 2021 | B4: 3 | C4: Kirksville R-3 School District | D4: 314070 | E4: 1859047
A5: 2021 | B5: 4 | C5: Savannah R-III Schools | D5: 210270 | E5: 1492172
A6: 2021 | B6: 5 | C6: North Andrew Co. R-VI Schools | D6: 37537 | E6: 299902
A7: 2021 | B7: 6 | C7: Avenue City R-IX Schools | D7: 22356 | E7: 117751
A8: 2021 | B8: 8 | C8: Tarkio R-I Schools | D8: 45189 | E8: 344596
A9: 2021 | B9: 9 | C9: Rock Port R-II Schools | D9: 36988 | E9: 275102
A10: 2021 | B10: 10 | C10: Fairfax R-III Schools | D10: 8845 | E10: 154570
A11: 2021 | B11: 12 | C11: Van-Far R-I Schools | D11: 65695 | E11: 406109
A12: 2021 | B12: 14 | C12: Community R-VI Schools | D12: 40174 | E12: 285003
A13: 2021 | B13: 15 | C13: Mexico Public Schools | D13: 329290 | E13: 1802571
... A102: 2021 | B102: 144 | C102: Clark Co. R-I Schools | D102: 103687 | E102: 736956
A103: 2021 | B103: 149 | C103: Luray 33 Public Schools
A104: 2021 | B104: 151 | C104: Kearney R-1 Schools | D104: 356137 | E104: 2780541
A105: 2021 | B105: 152 | C105: Smithville R-II Schools | D105: 283386 | E105: 1978702
A106: 2021 | B106: 154 | C106: Excelsior Springs 40 Schools | D106: 362139 | E106: 2088553
A107: 2021 | B107: 155 | C107: Liberty Public Schools | D107: 2045006 | E107: 10563679
A108: 2021 | B108: 156 | C108: North Kansas City Schools | D108: 3533261 | E108: 17950552
A109: 2021 | B109: 165 | C109: Missouri City Public Schools | D109: 5088 | E109: 25916
A110: 2021 | B110: 167 | C110: Cameron R-I Schools | D110: 155082 | E110: 1269695
A111: 2021 | B111: 168 | C111: Lathrop R-II Schools | D111: 91069 | E111: 760105
A112: 2021 | B112: 169 | C112: Clinton Co. R-III Schools | D112: 34462 | E112: 558139
A113: 2021 | B113: 170 | C113: Cole County R-I Schools | D113: 62455 | E113: 420381
A114: 2021 | B114: 171 | C114: Cole Co. R-II Schools | D114: 94920 | E114: 799295
A115: 2021 | B115: 173 | C115: Cole Co. R-V Schools | D115: 42854 | E115: 389653
... A454: 2021 | B454: 602 | C454: Scotland Co. R-I Schools | D454: 91032 | E454: 480040
A455: 2021 | B455: 603 | C455: Gorin R-III Schools
A456: 2021 | B456: 607 | C456: Scott City R-I Schools | D456: 83148 | E456: 637706
A457: 2021 | B457: 608 | C457: Chaffee R-II Schools | D457: 46920 | E457: 417074
A458: 2021 | B458: 609 | C458: Oran R-III Schools | D458: 19738 | E458: 242537
A459: 2021 | B459: 610 | C459: Scott Co. R-IV Schools | D459: 66637 | E459: 635055
A460: 2021 | B460: 611 | C460: Scott County Central Schools | D460: 27826 | E460: 250989
A461: 2021 | B461: 612 | C461: Sikeston R-VI Schools | D461: 352955 | E461: 2565248
A462: 2021 | B462: 613 | C462: Kelso C-7 Schools | D462: 15549 | E462: 117458
A463: 2021 | B463: 614 | C463: Eminence R-I Schools | D463: 47785 | E463: 195919
A464: 2021 | B464: 615 | C464: Winona R-III Schools | D464: 54973 | E464: 320093
A465: 2021 | B465: 617 | C465: Shelby Co. R-IV Schools | D465: 114549 | E465: 506947
A466: 2021 | B466: 618 | C466: Shelby Co. C-1 Schools | D466: 44077 | E466: 264089
...

Sheet 2022
A1: Year | B1: employer_number | C1: district_name | D1: district_contributions
A2: 2022 | B2: 1 | C2: Adair Co. R-1 Schools | D2: 29054 | E2: 189158
A3: 2022 | B3: 2 | C3: Adair County R-II Schools | D3: 34111 | E3: 202011
A4: 2022 | B4: 3 | C4: Kirksville R-3 School District | D4: 336495 | E4: 1945961
A5: 2022 | B5: 4 | C5: Savannah R-III Schools | D5: 206486 | E5: 1551488
A6: 2022 | B6: 5 | C6: North Andrew Co. R-VI Schools | D6: 35181 | E6: 292135
A7: 2022 | B7: 6 | C7: Avenue City R-IX Schools | D7: 23363 | E7: 126344
A8: 2022 | B8: 8 | C8: Tarkio R-I Schools | D8: 39507 | E8: 348428
A9: 2022 | B9: 9 | C9: Rock Port R-II Schools | D9: 40695 | E9: 290422
A10: 2022 | B10: 10 | C10: Fairfax R-III Schools | D10: 9667 | E10: 159187
A11: 2022 | B11: 12 | C11: Van-Far R-I Schools | D11: 68774 | E11: 418255
A12: 2022 | B12: 14 | C12: Community R-VI Schools | D12: 42787 | E12: 286902
A13: 2022 | B13: 15 | C13: Mexico Public Schools | D13: 349170 | E13: 1837307
... A102: 2022 | B102: 144 | C102: Clark Co. R-I Schools | D102: 126792 | E102: 740373
A103: 2022 | B103: 149 | C103: Luray 33 Public Schools
A104: 2022 | B104: 151 | C104: Kearney R-1 Schools | D104: 383887 | E104: 2831072
A105: 2022 | B105: 152 | C105: Smithville R-II Schools | D105: 292085 | E105: 1961928
A106: 2022 | B106: 154 | C106: Excelsior Springs 40 Schools | D106: 369907 | E106: 2221287
A107: 2022 | B107: 155 | C107: Liberty Public Schools | D107: 2141297 | E107: 10732066
A108: 2022 | B108: 156 | C108: North Kansas City Schools | D108: 3946708 | E108: 19022640
A109: 2022 | B109: 165 | C109: Missouri City Public Schools | D109: 8498 | E109: 25110
A110: 2022 | B110: 167 | C110: Cameron R-I Schools | D110: 187169 | E110: 1314449
A111: 2022 | B111: 168 | C111: Lathrop R-II Schools | D111: 115722 | E111: 818490
A112: 2022 | B112: 169 | C112: Clinton Co. R-III Schools | D112: 33020 | E112: 556090
A113: 2022 | B113: 170 | C113: Cole County R-I Schools | D113: 63187 | E113: 437206
A114: 2022 | B114: 171 | C114: Cole Co. R-II Schools | D114: 111221 | E114: 811001
A115: 2022 | B115: 173 | C115: Cole Co. R-V Schools | D115: 41915 | E115: 389118
... A454: 2022 | B454: 602 | C454: Scotland Co. R-I Schools | D454: 91306 | E454: 489359
A455: 2022 | B455: 603 | C455: Gorin R-III Schools
A456: 2022 | B456: 607 | C456: Scott City R-I Schools | D456: 94598 | E456: 658404
A457: 2022 | B457: 608 | C457: Chaffee R-II Schools | D457: 53503 | E457: 432880
A458: 2022 | B458: 609 | C458: Oran R-III Schools | D458: 16965 | E458: 239805
A459: 2022 | B459: 610 | C459: Scott Co. R-IV Schools | D459: 70903 | E459: 673444
A460: 2022 | B460: 611 | C460: Scott County Central Schools | D460: 32451 | E460: 262528
A461: 2022 | B461: 612 | C461: Sikeston R-VI Schools | D461: 393533 | E461: 2572920
A462: 2022 | B462: 613 | C462: Kelso C-7 Schools | D462: 19336 | E462: 112535
A463: 2022 | B463: 614 | C463: Eminence R-I Schools | D463: 48963 | E463: 191867
A464: 2022 | B464: 615 | C464: Winona R-III Schools | D464: 58635 | E464: 366362
A465: 2022 | B465: 617 | C465: Shelby Co. R-IV Schools | D465: 114996 | E465: 529870
A466: 2022 | B466: 618 | C466: Shelby Co. C-1 Schools | D466: 47057 | E466: 278081
...

Sheet NCES Data -->

Sheet LEAID Match
A1: district_name | B1: LEAID
A2: Maries Co. R-II Schools | B2: 2900001
A3: South Harrison Co. R-2 Schools | B3: 2900002
A4: Portageville Schools | B4: 2900003
A5: New Madrid Co. R-I Schools | B5: 2900004
A6: State Fair Community College | B6: 2900005
A7: Jefferson College | B7: 2900006
A8: Crowder College | B8: 2900007
A9: Ozarks Technical Comm. College | B9: 2900008
A10: Division of Youth Services | B10: 2900009
A11: Columbia Public Schools | B11: 2901000
A12: Adrian R-III Schools | B12: 2902850
A13: Advance R-IV Schools | B13: 2902880
... A432: Southwest R-V Schools | B432: 2928710
A433: SW Livingston Co. R-1 Schools
A434: Sparta R-III Schools | B434: 2928740
A435: Spickard R-II Schools | B435: 2928770
A436: Spokane R-VII Schools | B436: 2928800
A437: Springfield R-XII Schools | B437: 2928860
A438: St. Charles Co. R-VI Schools | B438: 2928920
A439: Francis Howell R-III Schools | B439: 2928950
A440: St. Clair R-XIII Schools | B440: 2929100
A441: St. Elizabeth R-IV Schools | B441: 2929130
A442: Central R-III Schools | B442: 2929170
A443: St. James R-I Schools | B443: 2929250
A444: Coop. Sch. Dist. of St. Louis
A445: St. Louis Public Schools | B445: 2929280
A446: Ste. Genevieve R-II Schools | B446: 2929370
A447: Steelville R-III Schools | B447: 2929430
A448: Stewartsville C-2 Schools | B448: 2929490
A449: Stockton R-I Schools | B449: 2929520
A450: Morgan Co. R-I Schools | B450: 2929610
A451: Strafford R-VI Schools | B451: 2929640
A452: Strasburg C-3 Schools | B452: 2929670
A453: Sturgeon R-V Schools | B453: 2929700
A454: Success R-VI Schools | B454: 2929730
A455: Sullivan C-2 Schools | B455: 2929760
A456: Summersville R-II Schools | B456: 2929810
... A511: Zalma R-V Schools | B511: 2932490
A512: Boone County R-IV Schools
...
