Workbook

Sheet Final Data
A1: LEAID | B1: Year | C1: employer_code | D1: original_employer_name | E1: standardized_employer_name | F1: employer_contributions | G1: state_contributions | H1: LEAID
B2: 2015 | C2: 4010 | D2: DEPARTMENT OF ADMIN SERVICE | E2: DEPARTMENT OF ADMIN SERVICE | F2: 6542.85 | H2: =IFERROR(VLOOKUP(E2,'GASB Match'!$A$2:$B$240,2,FALSE),"")
B3: 2016 | C3: 4010 | D3: DEPARTMENT OF ADMIN SERVICE | E3: DEPARTMENT OF ADMIN SERVICE | F3: 10068.75 | H3: =IFERROR(VLOOKUP(E3,'GASB Match'!$A$2:$B$240,2,FALSE),"")
B4: 2017 | C4: 4010 | D4: DEPARTMENT OF ADMIN SERVICE | E4: DEPARTMENT OF ADMIN SERVICE | F4: 26928 | H4: =IFERROR(VLOOKUP(E4,'GASB Match'!$A$2:$B$240,2,FALSE),"")
B5: 2018 | C5: 4010 | D5: DEPARTMENT OF ADMIN SERVICE | E5: DEPARTMENT OF ADMIN SERVICE | F5: 48505 | H5: =IFERROR(VLOOKUP(E5,'GASB Match'!$A$2:$B$240,2,FALSE),"")
B6: 2019 | C6: 4010 | D6: DEPARTMENT OF ADMIN SERVICE | E6: DEPARTMENT OF ADMIN SERVICE | F6: 54920 | H6: =IFERROR(VLOOKUP(E6,'GASB Match'!$A$2:$B$240,2,FALSE),"")
B7: 2020 | C7: 4010 | D7: DEPARTMENT OF ADMIN SERVICE | E7: DEPARTMENT OF ADMIN SERVICE | F7: 63308 | H7: =IFERROR(VLOOKUP(E7,'GASB Match'!$A$2:$B$240,2,FALSE),"")
B8: 2021 | C8: 4010 | D8: DEPARTMENT OF ADMIN SERVICE | E8: DEPARTMENT OF ADMIN SERVICE | F8: 66819 | H8: =IFERROR(VLOOKUP(E8,'GASB Match'!$A$2:$B$240,2,FALSE),"")
B9: 2022 | C9: 4010 | D9: DEPARTMENT OF ADMIN SERVICE | E9: DEPARTMENT OF ADMIN SERVICE | F9: 82013 | H9: =IFERROR(VLOOKUP(E9,'GASB Match'!$A$2:$B$240,2,FALSE),"")
B10: 2023 | C10: 4010 | D10: DEPARTMENT OF ADMIN SERVICE | E10: DEPARTMENT OF ADMIN SERVICE | F10: 92730 | H10: =IFERROR(VLOOKUP(E10,'GASB Match'!$A$2:$B$240,2,FALSE),"")
B11: 2015 | C11: 4020 | D11: GEORGIA DEPARTMENT OF AGRICULTURE | E11: GEORGIA DEPARTMENT OF AGRICULTURE | H11: =IFERROR(VLOOKUP(E11,'GASB Match'!$A$2:$B$240,2,FALSE),"")
B12: 2016 | C12: 4020 | D12: GEORGIA DEPARTMENT OF AGRICULTURE | E12: GEORGIA DEPARTMENT OF AGRICULTURE | F12: 2779.67 | H12: =IFERROR(VLOOKUP(E12,'GASB Match'!$A$2:$B$240,2,FALSE),"")
B13: 2017 | C13: 4020 | D13: GEORGIA DEPARTMENT OF AGRICULTURE | E13: GEORGIA DEPARTMENT OF AGRICULTURE | F13: 7863 | H13: =IFERROR(VLOOKUP(E13,'GASB Match'!$A$2:$B$240,2,FALSE),"")
B14: 2018 | C14: 4020 | D14: GEORGIA DEPARTMENT OF AGRICULTURE | E14: GEORGIA DEPARTMENT OF AGRICULTURE | F14: 10451 | H14: =IFERROR(VLOOKUP(E14,'GASB Match'!$A$2:$B$240,2,FALSE),"")
B15: 2019 | C15: 4020 | D15: GEORGIA DEPARTMENT OF AGRICULTURE | E15: GEORGIA DEPARTMENT OF AGRICULTURE | F15: 28999 | H15: =IFERROR(VLOOKUP(E15,'GASB Match'!$A$2:$B$240,2,FALSE),"")
B16: 2020 | C16: 4020 | D16: GEORGIA DEPARTMENT OF AGRICULTURE | E16: GEORGIA DEPARTMENT OF AGRICULTURE | F16: 32834 | H16: =IFERROR(VLOOKUP(E16,'GASB Match'!$A$2:$B$240,2,FALSE),"")
B17: 2021 | C17: 4020 | D17: GEORGIA DEPARTMENT OF AGRICULTURE | E17: GEORGIA DEPARTMENT OF AGRICULTURE | F17: 30377 | H17: =IFERROR(VLOOKUP(E17,'GASB Match'!$A$2:$B$240,2,FALSE),"")
B18: 2022 | C18: 4020 | D18: GEORGIA DEPARTMENT OF AGRICULTURE | E18: GEORGIA DEPARTMENT OF AGRICULTURE | F18: 30294 | H18: =IFERROR(VLOOKUP(E18,'GASB Match'!$A$2:$B$240,2,FALSE),"")
B19: 2023 | C19: 4020 | D19: GEORGIA DEPARTMENT OF AGRICULTURE | E19: GEORGIA DEPARTMENT OF AGRICULTURE | F19: 23356 | H19: =IFERROR(VLOOKUP(E19,'GASB Match'!$A$2:$B$240,2,FALSE),"")
B20: 2015 | C20: 4040 | D20: GEORGIA DEPARTMENT OF AUDITS | E20: GEORGIA DEPARTMENT OF AUDITS | F20: 9704.27 | H20: =IFERROR(VLOOKUP(E20,'GASB Match'!$A$2:$B$240,2,FALSE),"")
B21: 2016 | C21: 4040 | D21: GEORGIA DEPARTMENT OF AUDITS | E21: GEORGIA DEPARTMENT OF AUDITS | F21: 23667.52 | H21: =IFERROR(VLOOKUP(E21,'GASB Match'!$A$2:$B$240,2,FALSE),"")
B22: 2017 | C22: 4040 | D22: GEORGIA DEPARTMENT OF AUDITS | E22: GEORGIA DEPARTMENT OF AUDITS | F22: 14228 | H22: =IFERROR(VLOOKUP(E22,'GASB Match'!$A$2:$B$240,2,FALSE),"")
B23: 2018 | C23: 4040 | D23: GEORGIA DEPARTMENT OF AUDITS | E23: GEORGIA DEPARTMENT OF AUDITS | F23: 9803 | H23: =IFERROR(VLOOKUP(E23,'GASB Match'!$A$2:$B$240,2,FALSE),"")
... B66: 2023 | C66: 4220 | D66: GOVERNORS OFFICE OF PLANNING AND BUDGET | E66: GOVERNORS OFFICE OF PLANNING AND BUDGET | F66: 263497 | H66: =IFERROR(VLOOKUP(E66,'GASB Match'!$A$2:$B$240,2,FALSE),"")
A67: 1300027 | B67: 2015 | C67: 4270 | D67: DEPARTMENT OF HUMAN SERVICES | E67: DEPARTMENT OF HUMAN SERVICES | F67: 30903.98 | H67: =IFERROR(VLOOKUP(E67,'GASB Match'!$A$2:$B$240,2,FALSE),"") -> 1300027
A68: 1300027 | B68: 2016 | C68: 4270 | D68: DEPARTMENT OF HUMAN SERVICES | E68: DEPARTMENT OF HUMAN SERVICES | F68: 41851.7 | H68: =IFERROR(VLOOKUP(E68,'GASB Match'!$A$2:$B$240,2,FALSE),"") -> 1300027
A69: 1300027 | B69: 2017 | C69: 4270 | D69: DEPARTMENT OF HUMAN SERVICES | E69: DEPARTMENT OF HUMAN SERVICES | F69: 73617 | H69: =IFERROR(VLOOKUP(E69,'GASB Match'!$A$2:$B$240,2,FALSE),"") -> 1300027
A70: 1300027 | B70: 2018 | C70: 4270 | D70: DEPARTMENT OF HUMAN SERVICES | E70: DEPARTMENT OF HUMAN SERVICES | F70: 100104 | H70: =IFERROR(VLOOKUP(E70,'GASB Match'!$A$2:$B$240,2,FALSE),"") -> 1300027
A71: 1300027 | B71: 2019 | C71: 4270 | D71: DEPARTMENT OF HUMAN SERVICES | E71: DEPARTMENT OF HUMAN SERVICES | F71: 102528 | H71: =IFERROR(VLOOKUP(E71,'GASB Match'!$A$2:$B$240,2,FALSE),"") -> 1300027
A72: 1300027 | B72: 2020 | C72: 4270 | D72: DEPARTMENT OF HUMAN SERVICES | E72: DEPARTMENT OF HUMAN SERVICES | F72: 116495 | H72: =IFERROR(VLOOKUP(E72,'GASB Match'!$A$2:$B$240,2,FALSE),"") -> 1300027
A73: 1300027 | B73: 2021 | C73: 4270 | D73: DEPARTMENT OF HUMAN SERVICES | E73: DEPARTMENT OF HUMAN SERVICES | F73: 114946 | H73: =IFERROR(VLOOKUP(E73,'GASB Match'!$A$2:$B$240,2,FALSE),"") -> 1300027
A74: 1300027 | B74: 2022 | C74: 4270 | D74: DEPARTMENT OF HUMAN SERVICES | E74: DEPARTMENT OF HUMAN SERVICES | F74: 35636 | H74: =IFERROR(VLOOKUP(E74,'GASB Match'!$A$2:$B$240,2,FALSE),"") -> 1300027
A75: 1300027 | B75: 2023 | C75: 4270 | D75: DEPARTMENT OF HUMAN SERVICES | E75: DEPARTMENT OF HUMAN SERVICES | F75: 41802 | H75: =IFERROR(VLOOKUP(E75,'GASB Match'!$A$2:$B$240,2,FALSE),"") -> 1300027
B76: 2016 | C76: 4290 | D76: GEORGIA DEPARTMENT OF ECONOMIC DEVELOPMENT | E76: GEORGIA DEPARTMENT OF ECONOMIC DEVELOPMENT | F76: 11523.03 | H76: =IFERROR(VLOOKUP(E76,'GASB Match'!$A$2:$B$240,2,FALSE),"")
B77: 2017 | C77: 4290 | D77: GEORGIA DEPARTMENT OF ECONOMIC DEVELOPMENT | E77: GEORGIA DEPARTMENT OF ECONOMIC DEVELOPMENT | F77: 14701 | H77: =IFERROR(VLOOKUP(E77,'GASB Match'!$A$2:$B$240,2,FALSE),"")
B78: 2018 | C78: 4290 | D78: GEORGIA DEPARTMENT OF ECONOMIC DEVELOPMENT | E78: GEORGIA DEPARTMENT OF ECONOMIC DEVELOPMENT | F78: 25264 | H78: =IFERROR(VLOOKUP(E78,'GASB Match'!$A$2:$B$240,2,FALSE),"")
B79: 2019 | C79: 4290 | D79: GEORGIA DEPARTMENT OF ECONOMIC DEVELOPMENT | E79: GEORGIA DEPARTMENT OF ECONOMIC DEVELOPMENT | F79: 49116 | H79: =IFERROR(VLOOKUP(E79,'GASB Match'!$A$2:$B$240,2,FALSE),"")
B80: 2020 | C80: 4290 | D80: GEORGIA DEPARTMENT OF ECONOMIC DEVELOPMENT | E80: GEORGIA DEPARTMENT OF ECONOMIC DEVELOPMENT | F80: 40136 | H80: =IFERROR(VLOOKUP(E80,'GASB Match'!$A$2:$B$240,2,FALSE),"")
B81: 2021 | C81: 4290 | D81: GEORGIA DEPARTMENT OF ECONOMIC DEVELOPMENT | E81: GEORGIA DEPARTMENT OF ECONOMIC DEVELOPMENT | F81: 27265 | H81: =IFERROR(VLOOKUP(E81,'GASB Match'!$A$2:$B$240,2,FALSE),"")
B82: 2022 | C82: 4290 | D82: GEORGIA DEPARTMENT OF ECONOMIC DEVELOPMENT | E82: GEORGIA DEPARTMENT OF ECONOMIC DEVELOPMENT | F82: 13124 | H82: =IFERROR(VLOOKUP(E82,'GASB Match'!$A$2:$B$240,2,FALSE),"")
...

Sheet GASB Match
A1: Districts | B1: LEAID
A2: HENRY CO SCHOOLS | B2: 1302820 | C2: =COUNTIF($B$2:$B$240,B2) -> 1
A3: HOUSTON CO SCHOOLS | B3: 1302880 | C3: =COUNTIF($B$2:$B$240,B3) -> 1
A4: ROCKDALE CO SCHOOLS | B4: 1304410 | C4: =COUNTIF($B$2:$B$240,B4) -> 1
A5: ROME CITY SCHOOLS | B5: 1304440 | C5: =COUNTIF($B$2:$B$240,B5) -> 1
A6: TROUP CO SCHOOLS | B6: 1300001 | C6: =COUNTIF($B$2:$B$240,B6) -> 1
A7: NORTHWEST GEORGIA RESA | B7: 1300006 | C7: =COUNTIF($B$2:$B$240,B7) -> 1
A8: NORTH GEORGIA RESA | B8: 1300007 | C8: =COUNTIF($B$2:$B$240,B8) -> 1
A9: PIONEER RESA | B9: 1300008 | C9: =COUNTIF($B$2:$B$240,B9) -> 1
A10: METRO RESA | B10: 1300009 | C10: =COUNTIF($B$2:$B$240,B10) -> 1
A11: NORTHEAST GEORGIA RESA | B11: 1300010 | C11: =COUNTIF($B$2:$B$240,B11) -> 1
A12: WEST GEORGIA RESA | B12: 1300011 | C12: =COUNTIF($B$2:$B$240,B12) -> 1
A13: GRIFFIN RESA | B13: 1300012 | C13: =COUNTIF($B$2:$B$240,B13) -> 1
... A240: IVY PREPARATORY ACAD. | B240: 1300215 | C240: =COUNTIF($B$2:$B$240,B240) -> 1
