Workbook

Sheet Final Data
A1: LEAID | B1: Year | C1: state | D1: state_abv | E1: plan | F1: district_name2 | G1: employer_code | H1: district_name | I1: district_contributions | J1: State Contributions
A2: 2733840 | B2: 2015 | C2: Minnesota | D2: MN | E2: Minnesota Teacher's Retirement Association | H2: St Paul - ISD #625 | I2: 31316000 | J2: 15665000
A3: 2733840 | B3: 2016 | C3: Minnesota | D3: MN | E3: Minnesota Teacher's Retirement Association | H3: St Paul - ISD #625 | I3: 34139000 | J3: 15665000
A4: 2733840 | B4: 2017 | C4: Minnesota | D4: MN | E4: Minnesota Teacher's Retirement Association | H4: St Paul - ISD #625 | I4: 35251000 | J4: 15665000
A5: 2733840 | B5: 2018 | C5: Minnesota | D5: MN | E5: Minnesota Teacher's Retirement Association | H5: St Paul - ISD #625 | I5: 39070000 | J5: 15665000
A6: 2733840 | B6: 2019 | C6: Minnesota | D6: MN | E6: Minnesota Teacher's Retirement Association | H6: St Paul - ISD #625 | I6: 26046000 | J6: 10665000
A7: 2733840 | B7: 2020 | C7: Minnesota | D7: MN | E7: Minnesota Teacher's Retirement Association | H7: St Paul - ISD #625 | I7: 26563000 | J7: 10665000
A8: 2733840 | B8: 2021 | C8: Minnesota | D8: MN | E8: Minnesota Teacher's Retirement Association | H8: St Paul - ISD #625 | I8: 27685000 | J8: 10665000
A9: 2733840 | B9: 2022 | C9: Minnesota | D9: MN | E9: Minnesota Teacher's Retirement Association | H9: St Paul - ISD #625 | I9: 28544000 | J9: 10665000
A10: 0 | B10: 2015 | C10: Minnesota | D10: MN | E10: Minnesota Teacher's Retirement Association | F10: City of Minneapolis | G10: CITY | H10: City of Minneapolis | I10: 2250000
A11: 0 | B11: 2016 | C11: Minnesota | D11: MN | E11: Minnesota Teacher's Retirement Association | F11: City of Minneapolis | G11: CITY | H11: City of Minneapolis | I11: 2250000
A12: 0 | B12: 2017 | C12: Minnesota | D12: MN | E12: Minnesota Teacher's Retirement Association | F12: City of Minneapolis | G12: CITY | H12: City of Minneapolis | I12: 2250000
A13: 0 | B13: 2018 | C13: Minnesota | D13: MN | E13: Minnesota Teacher's Retirement Association | F13: City of Minneapolis | G13: CITY | H13: City of Minneapolis | I13: 2250000
A14: 0 | B14: 2019 | C14: Minnesota | D14: MN | E14: Minnesota Teacher's Retirement Association | F14: City of Minneapolis | G14: CITY | H14: City of Minneapolis | I14: 2250000
A15: 0 | B15: 2020 | C15: Minnesota | D15: MN | E15: Minnesota Teacher's Retirement Association | F15: City of Minneapolis | G15: CITY | H15: City of Minneapolis | I15: 2250000
A16: 0 | B16: 2021 | C16: Minnesota | D16: MN | E16: Minnesota Teacher's Retirement Association | F16: City of Minneapolis | G16: CITY | H16: City of Minneapolis | I16: 2250000
A17: 0 | B17: 2022 | C17: Minnesota | D17: MN | E17: Minnesota Teacher's Retirement Association | F17: City of Minneapolis | G17: CITY | H17: City of Minneapolis | I17: 2250000
A18: 2721240 | B18: 2015 | C18: Minnesota | D18: MN | E18: Minnesota Teacher's Retirement Association | F18: Msp School District | G18: MSPSD | H18: Msp School District | I18: 2250000
A19: 2721240 | B19: 2016 | C19: Minnesota | D19: MN | E19: Minnesota Teacher's Retirement Association | F19: Msp School District | G19: MSPSD | H19: Msp School District | I19: 2250000
A20: 2721240 | B20: 2017 | C20: Minnesota | D20: MN | E20: Minnesota Teacher's Retirement Association | F20: Msp School District | G20: MSPSD | H20: Msp School District | I20: 2250000
A21: 2721240 | B21: 2018 | C21: Minnesota | D21: MN | E21: Minnesota Teacher's Retirement Association | F21: Msp School District | G21: MSPSD | H21: Msp School District | I21: 2250000
... A25: 2721240 | B25: 2022 | C25: Minnesota | D25: MN | E25: Minnesota Teacher's Retirement Association | F25: Msp School District | G25: MSPSD | H25: Msp School District | I25: 2250000
A26: 2702760 | B26: 2015 | C26: Minnesota | D26: MN | E26: Minnesota Teacher's Retirement Association | F26: Aitkin - ISD #1 | G26: 00001 | H26: Aitkin - ISD #1 | I26: 378937 | J26: {=_xlfn.IFS(B26=2015,K26*$H$4790,B26=2016,K26*$H$4791,B26=2017,K26*$H$4792,B26=2018,K26*$H$4793,B26=2019,K26*$H$4794,B26=2020,K26*$H$4795,B26=2021,K26*$H$4796,B26=2022,K26*$H$4797)} -> 41448.428 | K26: {=_xlfn.IFS(B26=2015,I26/$I$4810,B26=2016,I26/$I$4811,B26=2017,I26/$I$4812,B26=2018,I26/$I$4813,B26=2019,I26/$I$4814,B26=2020,I26/$I$4815,B26=2021,I26/$I$4816,B26=2022,I26/$I$4817)} -> 0.0011175875
A27: 2702760 | B27: 2016 | C27: Minnesota | D27: MN | E27: Minnesota Teacher's Retirement Association | F27: Aitkin - ISD #1 | G27: 00001 | H27: Aitkin - ISD #1 | I27: 388846 | J27: {=_xlfn.IFS(B27=2015,K27*$H$4790,B27=2016,K27*$H$4791,B27=2017,K27*$H$4792,B27=2018,K27*$H$4793,B27=2019,K27*$H$4794,B27=2020,K27*$H$4795,B27=2021,K27*$H$4796,B27=2022,K27*$H$4797)} -> 34095.056 | K27: {=_xlfn.IFS(B27=2015,I27/$I$4810,B27=2016,I27/$I$4811,B27=2017,I27/$I$4812,B27=2018,I27/$I$4813,B27=2019,I27/$I$4814,B27=2020,I27/$I$4815,B27=2021,I27/$I$4816,B27=2022,I27/$I$4817)} -> 0.001096748
A28: 2702760 | B28: 2017 | C28: Minnesota | D28: MN | E28: Minnesota Teacher's Retirement Association | F28: Aitkin - ISD #1 | G28: 00001 | H28: Aitkin - ISD #1 | I28: 422156 | J28: {=_xlfn.IFS(B28=2015,K28*$H$4790,B28=2016,K28*$H$4791,B28=2017,K28*$H$4792,B28=2018,K28*$H$4793,B28=2019,K28*$H$4794,B28=2020,K28*$H$4795,B28=2021,K28*$H$4796,B28=2022,K28*$H$4797)} -> 35648.244 | K28: {=_xlfn.IFS(B28=2015,I28/$I$4810,B28=2016,I28/$I$4811,B28=2017,I28/$I$4812,B28=2018,I28/$I$4813,B28=2019,I28/$I$4814,B28=2020,I28/$I$4815,B28=2021,I28/$I$4816,B28=2022,I28/$I$4817)} -> 0.00114671
A29: 2702760 | B29: 2018 | C29: Minnesota | D29: MN | E29: Minnesota Teacher's Retirement Association | F29: Aitkin - ISD #1 | G29: 00001 | H29: Aitkin - ISD #1 | I29: 430646 | J29: {=_xlfn.IFS(B29=2015,K29*$H$4790,B29=2016,K29*$H$4791,B29=2017,K29*$H$4792,B29=2018,K29*$H$4793,B29=2019,K29*$H$4794,B29=2020,K29*$H$4795,B29=2021,K29*$H$4796,B29=2022,K29*$H$4797)} -> 35344.196 | K29: {=_xlfn.IFS(B29=2015,I29/$I$4810,B29=2016,I29/$I$4811,B29=2017,I29/$I$4812,B29=2018,I29/$I$4813,B29=2019,I29/$I$4814,B29=2020,I29/$I$4815,B29=2021,I29/$I$4816,B29=2022,I29/$I$4817)} -> 0.0011369296
A30: 2702760 | B30: 2019 | C30: Minnesota | D30: MN | E30: Minnesota Teacher's Retirement Association | F30: Aitkin - ISD #1 | G30: 00001 | H30: Aitkin - ISD #1 | I30: 430556 | J30: {=_xlfn.IFS(B30=2015,K30*$H$4790,B30=2016,K30*$H$4791,B30=2017,K30*$H$4792,B30=2018,K30*$H$4793,B30=2019,K30*$H$4794,B30=2020,K30*$H$4795,B30=2021,K30*$H$4796,B30=2022,K30*$H$4797)} -> 33285.241 | K30: {=_xlfn.IFS(B30=2015,I30/$I$4810,B30=2016,I30/$I$4811,B30=2017,I30/$I$4812,B30=2018,I30/$I$4813,B30=2019,I30/$I$4814,B30=2020,I30/$I$4815,B30=2021,I30/$I$4816,B30=2022,I30/$I$4817)} -> 0.0010706984
A31: 2702760 | B31: 2020 | C31: Minnesota | D31: MN | E31: Minnesota Teacher's Retirement Association | F31: Aitkin - ISD #1 | G31: 00001 | H31: Aitkin - ISD #1 | I31: 465244 | J31: {=_xlfn.IFS(B31=2015,K31*$H$4790,B31=2016,K31*$H$4791,B31=2017,K31*$H$4792,B31=2018,K31*$H$4793,B31=2019,K31*$H$4794,B31=2020,K31*$H$4795,B31=2021,K31*$H$4796,B31=2022,K31*$H$4797)} -> 34058.456 | K31: {=_xlfn.IFS(B31=2015,I31/$I$4810,B31=2016,I31/$I$4811,B31=2017,I31/$I$4812,B31=2018,I31/$I$4813,B31=2019,I31/$I$4814,B31=2020,I31/$I$4815,B31=2021,I31/$I$4816,B31=2022,I31/$I$4817)} -> 0.0010955707
A32: 2702760 | B32: 2021 | C32: Minnesota | D32: MN | E32: Minnesota Teacher's Retirement Association | F32: Aitkin - ISD #1 | G32: 00001 | H32: Aitkin - ISD #1 | I32: 494582 | J32: {=_xlfn.IFS(B32=2015,K32*$H$4790,B32=2016,K32*$H$4791,B32=2017,K32*$H$4792,B32=2018,K32*$H$4793,B32=2019,K32*$H$4794,B32=2020,K32*$H$4795,B32=2021,K32*$H$4796,B32=2022,K32*$H$4797)} -> 36751.731 | K32: {=_xlfn.IFS(B32=2015,I32/$I$4810,B32=2016,I32/$I$4811,B32=2017,I32/$I$4812,B32=2018,I32/$I$4813,B32=2019,I32/$I$4814,B32=2020,I32/$I$4815,B32=2021,I32/$I$4816,B32=2022,I32/$I$4817)} -> 0.001102329
A33: 2702760 | B33: 2022 | C33: Minnesota | D33: MN | E33: Minnesota Teacher's Retirement Association | F33: Aitkin - ISD #1 | G33: 00001 | H33: Aitkin - ISD #1 | I33: 505855 | J33: {=_xlfn.IFS(B33=2015,K33*$H$4790,B33=2016,K33*$H$4791,B33=2017,K33*$H$4792,B33=2018,K33*$H$4793,B33=2019,K33*$H$4794,B33=2020,K33*$H$4795,B33=2021,K33*$H$4796,B33=2022,K33*$H$4797)} -> 32770.234 | K33: {=_xlfn.IFS(B33=2015,I33/$I$4810,B33=2016,I33/$I$4811,B33=2017,I33/$I$4812,B33=2018,I33/$I$4813,B33=2019,I33/$I$4814,B33=2020,I33/$I$4815,B33=2021,I33/$I$4816,B33=2022,I33/$I$4817)} -> 0.0010540205
A34: 2714010 | B34: 2015 | C34: Minnesota | D34: MN | E34: Minnesota Teacher's Retirement Association | F34: Hill City - ISD #2 | G34: 00002 | H34: Hill City - ISD #2 | I34: 128202 | J34: {=_xlfn.IFS(B34=2015,K34*$H$4790,B34=2016,K34*$H$4791,B34=2017,K34*$H$4792,B34=2018,K34*$H$4793,B34=2019,K34*$H$4794,B34=2020,K34*$H$4795,B34=2021,K34*$H$4796,B34=2022,K34*$H$4797)} -> 14022.836 | K34: {=_xlfn.IFS(B34=2015,I34/$I$4810,B34=2016,I34/$I$4811,B34=2017,I34/$I$4812,B34=2018,I34/$I$4813,B34=2019,I34/$I$4814,B34=2020,I34/$I$4815,B34=2021,I34/$I$4816,B34=2022,I34/$I$4817)} -> 0.00037810231
A35: 2714010 | B35: 2016 | C35: Minnesota | D35: MN | E35: Minnesota Teacher's Retirement Association | F35: Hill City - ISD #2 | G35: 00002 | H35: Hill City - ISD #2 | I35: 129584 | J35: {=_xlfn.IFS(B35=2015,K35*$H$4790,B35=2016,K35*$H$4791,B35=2017,K35*$H$4792,B35=2018,K35*$H$4793,B35=2019,K35*$H$4794,B35=2020,K35*$H$4795,B35=2021,K35*$H$4796,B35=2022,K35*$H$4797)} -> 11362.271 | K35: {=_xlfn.IFS(B35=2015,I35/$I$4810,B35=2016,I35/$I$4811,B35=2017,I35/$I$4812,B35=2018,I35/$I$4813,B35=2019,I35/$I$4814,B35=2020,I35/$I$4815,B35=2021,I35/$I$4816,B35=2022,I35/$I$4817)} -> 0.0003654943
A36: 2714010 | B36: 2017 | C36: Minnesota | D36: MN | E36: Minnesota Teacher's Retirement Association | F36: Hill City - ISD #2 | G36: 00002 | H36: Hill City - ISD #2 | I36: 136806 | J36: {=_xlfn.IFS(B36=2015,K36*$H$4790,B36=2016,K36*$H$4791,B36=2017,K36*$H$4792,B36=2018,K36*$H$4793,B36=2019,K36*$H$4794,B36=2020,K36*$H$4795,B36=2021,K36*$H$4796,B36=2022,K36*$H$4797)} -> 11552.349 | K36: {=_xlfn.IFS(B36=2015,I36/$I$4810,B36=2016,I36/$I$4811,B36=2017,I36/$I$4812,B36=2018,I36/$I$4813,B36=2019,I36/$I$4814,B36=2020,I36/$I$4815,B36=2021,I36/$I$4816,B36=2022,I36/$I$4817)} -> 0.00037160862
A37: 2714010 | B37: 2018 | C37: Minnesota | D37: MN | E37: Minnesota Teacher's Retirement Association | F37: Hill City - ISD #2 | G37: 00002 | H37: Hill City - ISD #2 | I37: 143777 | J37: {=_xlfn.IFS(B37=2015,K37*$H$4790,B37=2016,K37*$H$4791,B37=2017,K37*$H$4792,B37=2018,K37*$H$4793,B37=2019,K37*$H$4794,B37=2020,K37*$H$4795,B37=2021,K37*$H$4796,B37=2022,K37*$H$4797)} -> 11800.139 | K37: {=_xlfn.IFS(B37=2015,I37/$I$4810,B37=2016,I37/$I$4811,B37=2017,I37/$I$4812,B37=2018,I37/$I$4813,B37=2019,I37/$I$4814,B37=2020,I37/$I$4815,B37=2021,I37/$I$4816,B37=2022,I37/$I$4817)} -> 0.00037957934
... A4786: 2721240 | B4786: 2022 | C4786: Minnesota | D4786: MN | E4786: Minnesota Teacher's Retirement Association | F4786: Minneapolis - Special School Dist #1 | G4786: S0001 | H4786: Minneapolis - Special School Dist #1 | I4786: 32663945 | J4786: {=_xlfn.IFS(B4786=2015,K4786*$H$4790,B4786=2016,K4786*$H$4791,B4786=2017,K4786*$H$4792,B4786=2018,K4786*$H$4793,B4786=2019,K4786*$H$4794,B4786=2020,K4786*$H$4795,B4786=2021,K4786*$H$4796,B4786=2022,K4786*$H$4797)} -> 2116031.5 | K4786: {=_xlfn.IFS(B4786=2015,I4786/$I$4810,B4786=2016,I4786/$I$4811,B4786=2017,I4786/$I$4812,B4786=2018,I4786/$I$4813,B4786=2019,I4786/$I$4814,B4786=2020,I4786/$I$4815,B4786=2021,I4786/$I$4816,B4786=2022,I4786/$I$4817)} -> 0.068059953
J4789: Check - State Contributions | L4789: Check - Proportions
G4790: 2015 | H4790: 37087411 | I4790: 2015 | J4790: =SUMIF($B$26:$B$4786,I4790,$J$26:$J$4786) -> 37087411 | K4790: =H4790=J4790 -> TRUE | L4790: 2015 | M4790: =SUMIF(B26:B4786,L4790,K26:K4786) -> 1
G4791: 2016 | H4791: 31087410 | I4791: 2016 | J4791: =SUMIF($B$26:$B$4786,I4791,$J$26:$J$4786) -> 31087410 | K4791: =H4791=J4791 -> TRUE | L4791: 2016 | M4791: =SUMIF(B27:B4787,L4791,K27:K4787) -> 1
G4792: 2017 | H4792: 31087410 | I4792: 2017 | J4792: =SUMIF($B$26:$B$4786,I4792,$J$26:$J$4786) -> 31087410 | K4792: =H4792=J4792 -> TRUE | L4792: 2017 | M4792: =SUMIF(B28:B4788,L4792,K28:K4788) -> 1
G4793: 2018 | H4793: 31087410 | I4793: 2018 | J4793: =SUMIF($B$26:$B$4786,I4793,$J$26:$J$4786) -> 31087410 | K4793: =H4793=J4793 -> TRUE | L4793: 2018 | M4793: =SUMIF(B29:B4789,L4793,K29:K4789) -> 1
...

Sheet NCES LEAIDs
A1: district | B1: LEAID | C1: count
A2: Mountain Iron-Buhl - ISD #712 | B2: =VLOOKUP(A2,'Old Data'!$A$2:$B$530,2,FALSE) -> 2700001 | C2: =COUNTIF($B$2:$B$592,B2) -> 1
A3: United South Central - ISD #2134 | B3: =VLOOKUP(A3,'Old Data'!$A$2:$B$530,2,FALSE) -> 2700005 | C3: =COUNTIF($B$2:$B$592,B3) -> 1
A4: Maple River - ISD #2135 | B4: =VLOOKUP(A4,'Old Data'!$A$2:$B$530,2,FALSE) -> 2700006 | C4: =COUNTIF($B$2:$B$592,B4) -> 1
A5: Kingsland - ISD #2137 | B5: =VLOOKUP(A5,'Old Data'!$A$2:$B$530,2,FALSE) -> 2700007 | C5: =COUNTIF($B$2:$B$592,B5) -> 1
A6: St Louis County Schools - ISD # 2142 | B6: =VLOOKUP(A6,'Old Data'!$A$2:$B$530,2,FALSE) -> 2700008 | C6: =COUNTIF($B$2:$B$592,B6) -> 1
A7: Waterville-Elysian-Morristown ISD #2143 | B7: =VLOOKUP(A7,'Old Data'!$A$2:$B$530,2,FALSE) -> 2700013 | C7: =COUNTIF($B$2:$B$592,B7) -> 1
A8: Freshwater Education Dist # 6004 | B8: =VLOOKUP(A8,'Old Data'!$A$2:$B$530,2,FALSE) -> 2700014 | C8: =COUNTIF($B$2:$B$592,B8) -> 1
A9: St. Croix River Education District | B9: =VLOOKUP(A9,'Old Data'!$A$2:$B$530,2,FALSE) -> 2700015 | C9: =COUNTIF($B$2:$B$592,B9) -> 1
A10: Runestone Area Education Dist # 6014 | B10: =VLOOKUP(A10,'Old Data'!$A$2:$B$530,2,FALSE) -> 2700016 | C10: =COUNTIF($B$2:$B$592,B10) -> 1
A11: Chisago Lakes Area - ISD #2144 | B11: =VLOOKUP(A11,'Old Data'!$A$2:$B$530,2,FALSE) -> 2700017 | C11: =COUNTIF($B$2:$B$592,B11) -> 1
A12: Minnewaska Area - ISD #2149 | B12: =VLOOKUP(A12,'Old Data'!$A$2:$B$530,2,FALSE) -> 2700019 | C12: =COUNTIF($B$2:$B$592,B12) -> 1
A13: Eveleth-Gilbert - ISD #2154 | B13: =VLOOKUP(A13,'Old Data'!$A$2:$B$530,2,FALSE) -> 2700021 | C13: =COUNTIF($B$2:$B$592,B13) -> 1
A14: Wadena-Deer Creek - ISD #2155 | B14: =VLOOKUP(A14,'Old Data'!$A$2:$B$530,2,FALSE) -> 2700022 | C14: =COUNTIF($B$2:$B$592,B14) -> 1
A15: Buffalo Lake-Hector - ISD #2159 | B15: 2700023 | C15: =COUNTIF($B$2:$B$592,B15) -> 1
A16: Warren-Alvarado-Oslo - ISD #2176 | B16: =VLOOKUP(A16,'Old Data'!$A$2:$B$530,2,FALSE) -> 2700024 | C16: =COUNTIF($B$2:$B$592,B16) -> 1
A17: Interm School District #287 | B17: =VLOOKUP(A17,'Old Data'!$A$2:$B$530,2,FALSE) -> 2700025 | C17: =COUNTIF($B$2:$B$592,B17) -> 1
A18: Interm School District #917 | B18: =VLOOKUP(A18,'Old Data'!$A$2:$B$530,2,FALSE) -> 2700026 | C18: =COUNTIF($B$2:$B$592,B18) -> 1
A19: Cedar-Riverside Community School | B19: =VLOOKUP(A19,'Old Data'!$A$2:$B$530,2,FALSE) -> 2700027 | C19: =COUNTIF($B$2:$B$592,B19) -> 1
A20: Metro Deaf School | B20: =VLOOKUP(A20,'Old Data'!$A$2:$B$530,2,FALSE) -> 2700028 | C20: =COUNTIF($B$2:$B$592,B20) -> 1
A21: East Range Academy of Tech and Science | B21: 2700034 | C21: =COUNTIF($B$2:$B$592,B21) -> 1
A22: Wright Technical Ctr #966 | B22: =VLOOKUP(A22,'Old Data'!$A$2:$B$530,2,FALSE) -> 2700036 | C22: =COUNTIF($B$2:$B$592,B22) -> 1
A23: Pine to Prairie Coop Ctr #985 | B23: 2700038 | C23: =COUNTIF($B$2:$B$592,B23) -> 1
A24: Northwest Reg lntrdst Council #382 | B24: 2700039 | C24: =COUNTIF($B$2:$B$592,B24) -> 1
A25: Lake Agassiz Spec Ed Coop #397 | B25: =VLOOKUP(A25,'Old Data'!$A$2:$B$530,2,FALSE) -> 2700040 | C25: =COUNTIF($B$2:$B$592,B25) -> 1
A26: Midwest Spec Ed Coop #398 | B26: 2700041 | C26: =COUNTIF($B$2:$B$592,B26) -> 1
A27: Fergus Falls - ISD #544 | B27: 2711880 | C27: =COUNTIF($B$2:$B$592,B27) -> 1
A28: Fergus Falls Spec Ed Coop #935 | B28: 2700043 | C28: =COUNTIF($B$2:$B$592,B28) -> 1
A29: Meeker & Wright Spec Ed Coop #938 | B29: =VLOOKUP(A29,'Old Data'!$A$2:$B$530,2,FALSE) -> 2700045 | C29: =COUNTIF($B$2:$B$592,B29) -> 1
A30: Southern Plains #915 | B30: =VLOOKUP(A30,'Old Data'!$A$2:$B$530,2,FALSE) -> 2700046 | C30: =COUNTIF($B$2:$B$592,B30) -> 1
A31: MN Valley Coop Ctr #978 | B31: 2700047 | C31: =COUNTIF($B$2:$B$592,B31) -> 1
A32: Area Special Educ Coop #997 | B32: 2700050 | C32: =COUNTIF($B$2:$B$592,B32) -> 1
A33: Bemidji Reg Interdist Council #998 | B33: 2700051 | C33: =COUNTIF($B$2:$B$592,B33) -> 1
A34: Zumbro Education District #6012 | B34: =VLOOKUP(A34,'Old Data'!$A$2:$B$530,2,FALSE) -> 2700054 | C34: =COUNTIF($B$2:$B$592,B34) -> 1
A35: Hiawatha Valley Ed Dist # 6013 | B35: =VLOOKUP(A35,'Old Data'!$A$2:$B$530,2,FALSE) -> 2700055 | C35: =COUNTIF($B$2:$B$592,B35) -> 1
A36: MN Valley Educ Dist # 6027 | B36: =VLOOKUP(A36,'Old Data'!$A$2:$B$530,2,FALSE) -> 2700063 | C36: =COUNTIF($B$2:$B$592,B36) -> 1
A37: Benton-Stearns Educ Dist # 6383 | B37: =VLOOKUP(A37,'Old Data'!$A$2:$B$530,2,FALSE) -> 2700071 | C37: =COUNTIF($B$2:$B$592,B37) -> 1
A38: Midstate Educational Dist # 6979 | B38: =VLOOKUP(A38,'Old Data'!$A$2:$B$530,2,FALSE) -> 2700073 | C38: =COUNTIF($B$2:$B$592,B38) -> 1
A39: Southeast Service Coop #921 | B39: 2700079 | C39: =COUNTIF($B$2:$B$592,B39) -> 1
A40: South Central Serv Coop #922 | B40: 2700080 | C40: =COUNTIF($B$2:$B$592,B40) -> 1
...

Sheet Old Data
A2: MN International Middle School | B2: 2700189
A3: BOLD - ISD #2534 | B3: 2705660
A4: East Metro Integration District | B4: 2700411
A5: Duluth Edison Charter School | B5: 2700133
A6: NE Metro Interm School Dist #916 | B6: 2702264
A7: Lakes Country Serv Coop #926 | B7: 2700083
A8: SW/W Central Service Cooperative #991 | B8: 2700086
A9: St Paul - ISD #625 | B9: 2733840
A10: South Washington County - ISD #833 | B10: 2700146
A11: West St Paul - ISD #197 | B11: 2742270
A12: Twin Cities International Elem. School | B12: 2700188
A13: Southwest Metro Educational Cooperative | B13: 2700387
... A530: Pillager - ISD #116 | B530: 2728350
