Workbook

Sheet Project Coverage -->

Sheet District Coverage by State
B2: State | C2: Google # Districts | D2: Our Data # Districts | E2: Coverage
B3: Alabama | C3: 140 | D3: 134 | E3: =D3/C3 -> 0.95714286 | F3: 1
B4: Alaska | C4: 54 | D4: 52 | E4: =D4/C4 -> 0.96296296 | F4: 1
B5: Arizona | C5: 307 | D5: 295 | E5: =D5/C5 -> 0.96091205 | F5: 1
B6: Arkansas | C6: 258 | D6: 246 | E6: =D6/C6 -> 0.95348837 | F6: 1
B7: California | C7: 977 | D7: 967 | E7: =D7/C7 -> 0.98976459 | F7: 1
B8: Connecticut | C8: 190 | D8: 181 | E8: =D8/C8 -> 0.95263158 | F8: 1
B9: DC | C9: 1 | D9: 1 | E9: =D9/C9 -> 1 | F9: 1
B10: Delaware | C10: 19 | D10: 19 | E10: =D10/C10 -> 1 | F10: 1
B11: Florida | C11: 71 | D11: 66 | E11: =D11/C11 -> 0.92957746 | F11: 1
B12: Georgia | C12: 194 | D12: 189 | E12: =D12/C12 -> 0.9742268 | F12: 1
B13: Hawaii | C13: 1 | D13: 1 | E13: =D13/C13 -> 1 | F13: 1
B14: Idaho | C14: 166 | D14: 151 | E14: =D14/C14 -> 0.90963855 | F14: 1
... B50: Wyoming | C50: 48 | D50: 47 | E50: =D50/C50 -> 0.97916667 | F50: 1
B52: Total | C52: =SUM(C3:C50) -> 13819 | D52: =SUM(D3:D50) -> 13099 | E52: =D52/C52 -> 0.94789782
B54: State Count | C54: =COUNT(F3:F50) -> 48

Sheet Contribution Sum by State -->

Sheet Summary
B2: State | C2: Party Affiliation | D2: Total Contribution % (2022) | E2: Total Contribution % Percentage Point Change | F2: Right to Work vs. Non-Right to Work | G2: Teachers' Union Strength
B3: Alabama | C3: Republican | D3: 6.93 | E3: 0 | F3: =IFERROR(VLOOKUP(B3,'Employment Type'!$A$2:$B$52,2,FALSE),"") -> Right-to-Work | G3: =IFERROR(VLOOKUP(B3,'Teachers'' Union Strength'!$A$2:$B$52,2,FALSE),"") -> 20
B4: Alaska | C4: Republican | D4: 5.96 | E4: 1.1 | F4: =IFERROR(VLOOKUP(B4,'Employment Type'!$A$2:$B$52,2,FALSE),"") -> Non-Right-to-Work | G4: =IFERROR(VLOOKUP(B4,'Teachers'' Union Strength'!$A$2:$B$52,2,FALSE),"") -> 15
B5: Arizona | C5: Democrat | D5: 6.38 | E5: 0.8 | F5: =IFERROR(VLOOKUP(B5,'Employment Type'!$A$2:$B$52,2,FALSE),"") -> Right-to-Work | G5: =IFERROR(VLOOKUP(B5,'Teachers'' Union Strength'!$A$2:$B$52,2,FALSE),"") -> 51
B6: Arkansas | C6: Republican | D6: 9.04 | E6: 0.2 | F6: =IFERROR(VLOOKUP(B6,'Employment Type'!$A$2:$B$52,2,FALSE),"") -> Right-to-Work | G6: =IFERROR(VLOOKUP(B6,'Teachers'' Union Strength'!$A$2:$B$52,2,FALSE),"") -> 48
B7: California | C7: Democrat | D7: 14.22 | E7: 6.9 | F7: =IFERROR(VLOOKUP(B7,'Employment Type'!$A$2:$B$52,2,FALSE),"") -> Non-Right-to-Work | G7: =IFERROR(VLOOKUP(B7,'Teachers'' Union Strength'!$A$2:$B$52,2,FALSE),"") -> 6
B8: Connecticut | C8: Democrat | D8: 21.45 | E8: 8.2 | F8: =IFERROR(VLOOKUP(B8,'Employment Type'!$A$2:$B$52,2,FALSE),"") -> Non-Right-to-Work | G8: =IFERROR(VLOOKUP(B8,'Teachers'' Union Strength'!$A$2:$B$52,2,FALSE),"") -> 17
B9: Delaware | C9: Democrat | D9: 11.55 | E9: 0.1 | F9: =IFERROR(VLOOKUP(B9,'Employment Type'!$A$2:$B$52,2,FALSE),"") -> Non-Right-to-Work | G9: =IFERROR(VLOOKUP(B9,'Teachers'' Union Strength'!$A$2:$B$52,2,FALSE),"") -> 19
B10: District of Columbia | C10: Democrat | D10: 7.58 | E10: 2.1 | F10: Non-Right-to-Work | G10: =IFERROR(VLOOKUP(B10,'Teachers'' Union Strength'!$A$2:$B$52,2,FALSE),"") -> 33
B11: Florida | C11: Republican | D11: 4.65 | E11: 1.14 | F11: =IFERROR(VLOOKUP(B11,'Employment Type'!$A$2:$B$52,2,FALSE),"") -> Right-to-Work | G11: =IFERROR(VLOOKUP(B11,'Teachers'' Union Strength'!$A$2:$B$52,2,FALSE),"") -> 50
B12: Georgia | C12: Republican | D12: 9.68 | E12: 2.3 | F12: =IFERROR(VLOOKUP(B12,'Employment Type'!$A$2:$B$52,2,FALSE),"") -> Right-to-Work | G12: =IFERROR(VLOOKUP(B12,'Teachers'' Union Strength'!$A$2:$B$52,2,FALSE),"") -> 45
B13: Hawaii | C13: Democrat | D13: 17.65 | E13: 3.7 | F13: =IFERROR(VLOOKUP(B13,'Employment Type'!$A$2:$B$52,2,FALSE),"") -> Non-Right-to-Work | G13: =IFERROR(VLOOKUP(B13,'Teachers'' Union Strength'!$A$2:$B$52,2,FALSE),"") -> 1
B14: Idaho | C14: Republican | D14: 13.16 | E14: 2.8 | F14: =IFERROR(VLOOKUP(B14,'Employment Type'!$A$2:$B$52,2,FALSE),"") -> Right-to-Work | G14: =IFERROR(VLOOKUP(B14,'Teachers'' Union Strength'!$A$2:$B$52,2,FALSE),"") -> 36
B15: Illinois | C15: Democrat | D15: 22.66 | E15: 5.8 | F15: =IFERROR(VLOOKUP(B15,'Employment Type'!$A$2:$B$52,2,FALSE),"") -> Non-Right-to-Work | G15: =IFERROR(VLOOKUP(B15,'Teachers'' Union Strength'!$A$2:$B$52,2,FALSE),"") -> 8
B16: Indiana | C16: Democrat | D16: 18.8 | E16: 4.8 | F16: =IFERROR(VLOOKUP(B16,'Employment Type'!$A$2:$B$52,2,FALSE),"") -> Right-to-Work | G16: =IFERROR(VLOOKUP(B16,'Teachers'' Union Strength'!$A$2:$B$52,2,FALSE),"") -> 31
B17: Iowa | C17: Democrat | D17: 5.64 | E17: 0.2 | F17: =IFERROR(VLOOKUP(B17,'Employment Type'!$A$2:$B$52,2,FALSE),"") -> Right-to-Work | G17: =IFERROR(VLOOKUP(B17,'Teachers'' Union Strength'!$A$2:$B$52,2,FALSE),"") -> 27
B18: Kansas | C18: Democrat | D18: 7.59 | E18: 1.3 | F18: =IFERROR(VLOOKUP(B18,'Employment Type'!$A$2:$B$52,2,FALSE),"") -> Right-to-Work | G18: =IFERROR(VLOOKUP(B18,'Teachers'' Union Strength'!$A$2:$B$52,2,FALSE),"") -> 32
B19: Kentucky | C19: Democrat | D19: 17.06 | E19: 9.8 | F19: =IFERROR(VLOOKUP(B19,'Employment Type'!$A$2:$B$52,2,FALSE),"") -> Right-to-Work | G19: =IFERROR(VLOOKUP(B19,'Teachers'' Union Strength'!$A$2:$B$52,2,FALSE),"") -> 28
B20: Louisiana | C20: Republican | D20: 12.81 | E20: -2.1 | F20: =IFERROR(VLOOKUP(B20,'Employment Type'!$A$2:$B$52,2,FALSE),"") -> Right-to-Work | G20: =IFERROR(VLOOKUP(B20,'Teachers'' Union Strength'!$A$2:$B$52,2,FALSE),"") -> 42
B21: Maine | C21: Democrat | D21: 8.73 | E21: 1.1 | F21: =IFERROR(VLOOKUP(B21,'Employment Type'!$A$2:$B$52,2,FALSE),"") -> Non-Right-to-Work | G21: =IFERROR(VLOOKUP(B21,'Teachers'' Union Strength'!$A$2:$B$52,2,FALSE),"") -> 22
B22: Maryland | C22: Democrat | D22: 9.63 | E22: -2.55 | F22: =IFERROR(VLOOKUP(B22,'Employment Type'!$A$2:$B$52,2,FALSE),"") -> Non-Right-to-Work | G22: =IFERROR(VLOOKUP(B22,'Teachers'' Union Strength'!$A$2:$B$52,2,FALSE),"") -> 23
... B50: Wyoming | C50: Republican | D50: 9.35 | E50: 0.6 | F50: =IFERROR(VLOOKUP(B50,'Employment Type'!$A$2:$B$52,2,FALSE),"") -> Right-to-Work | G50: =IFERROR(VLOOKUP(B50,'Teachers'' Union Strength'!$A$2:$B$52,2,FALSE),"") -> 29
C52: Party Affiliation | D52: Avg Total Contribution % (2022) | E52: Average Percentage Point Change in Total Contribution %
C53: Democrat | D53: =AVERAGEIF($C$3:$C$50,$C53,$D$3:$D$50) -> 11.569167 | E53: =AVERAGEIF($C$3:$C$50,$C53,$E$3:$E$50) -> 3.0558333
C54: Republican | D54: =AVERAGEIF($C$3:$C$50,$C54,$D$3:$D$50) -> 9.1079167 | E54: =AVERAGEIF($C$3:$C$50,$C54,$E$3:$E$50) -> 0.55958333
C56: Right to Work vs. Non-Right to Work | D56: Avg Total Contribution % (2022) | E56: Average Percentage Point Change in Total Contribution %
C57: Non-Right-to-Work | D57: =AVERAGEIF($F$3:$F$50,C57,$D$3:$D$50) -> 11.36913 | E57: =AVERAGEIF($F$3:$F$50,C57,$E$3:$E$50) -> 2.873913
C58: Right-to-Work | D58: =AVERAGEIF($F$3:$F$50,C58,$D$3:$D$50) -> 9.3904 | E58: =AVERAGEIF($F$3:$F$50,C58,$E$3:$E$50) -> 0.8268
C60: Count by Party
C61: Democrat | D61: =COUNTIF($C$3:$C$50,$C53) -> 24
C62: Republican | D62: =COUNTIF($C$3:$C$50,$C54) -> 24

Sheet Teachers' Union Strength
A1: State | B1: Rank
A2: Hawaii | B2: 1 | D2: https://fordhaminstitute.org/national/research/how-strong-are-us-teacher-unions-state-state-comparison
A3: Oregon | B3: 2
A4: Montana | B4: 3
A5: Pennsylvania | B5: 4
A6: Rhode Island | B6: 5
A7: California | B7: 6
A8: New Jersey | B8: 7
A9: Illinois | B9: 8
A10: New York | B10: 9
A11: Washington | B11: 10
A12: Vermont | B12: 11
A13: Ohio | B13: 12
A14: West Virginia | B14: 13
... A52: Arizona | B52: 51

Sheet Employment Type
A1: State | B1: Right-to-Work Status
A2: Alabama | B2: Right-to-Work
A3: Alaska | B3: Non-Right-to-Work
A4: Arizona | B4: Right-to-Work
A5: Arkansas | B5: Right-to-Work
A6: California | B6: Non-Right-to-Work
A7: Colorado | B7: Right-to-Work
A8: Connecticut | B8: Non-Right-to-Work
A9: Delaware | B9: Non-Right-to-Work
A10: Florida | B10: Right-to-Work
A11: Georgia | B11: Right-to-Work
A12: Hawaii | B12: Non-Right-to-Work
... A52: District of Columbia | B52: Non-Right-to-Work

Sheet State-by-State Results -->

Sheet Northeast -->

Sheet Connecticut
B2: District Contributions
B3: Year | C3: Unweighted | D3: Weighted
B4: 2015 | C4: 0.13208681 | D4: 0.1287644 | F4: 100
B5: 2016 | C5: 0.12610712 | D5: 0.125173
B6: 2017 | C6: 0.12778236 | D6: 0.1278719
B7: 2018 | C7: 0.15323228 | D7: 0.1539446
B8: 2019 | C8: 0.16065901 | D8: 0.153682
B9: 2020 | C9: 0.20024635 | D9: 0.1439347
B10: 2021 | C10: 0.19654706 | D10: 0.1429204
B11: 2022 | C11: 0.21449842 | D11: 0.1548927
B13: Change | C13: =C11-C4 -> 0.08241161 | D13: =D11-D4 -> 0.0261283
C15: =C11-C4 -> 0.08241161 | D15: =D11-D4 -> 0.0261283
C17: =C4*$F$4 -> 13.208681 | D17: =D4*$F$4 -> 12.87644
C18: =C5*$F$4 -> 12.610712 | D18: =D5*$F$4 -> 12.5173
C19: =C6*$F$4 -> 12.778236 | D19: =D6*$F$4 -> 12.78719
C20: =C7*$F$4 -> 15.323228 | D20: =D7*$F$4 -> 15.39446
C21: =C8*$F$4 -> 16.065901 | D21: =D8*$F$4 -> 15.3682
C22: =C9*$F$4 -> 20.024635 | D22: =D9*$F$4 -> 14.39347
C23: =C10*$F$4 -> 19.654706 | D23: =D10*$F$4 -> 14.29204
C24: =C11*$F$4 -> 21.449842 | D24: =D11*$F$4 -> 15.48927

Sheet Delaware
B2: Total Contributions | F2: District Contributions | J2: State Contributions
B3: Year | C3: Unweighted | D3: Weighted | F3: Year | G3: Unweighted | H3: Weighted | J3: Year | K3: Unweighted | L3: Weighted
B4: 2015 | C4: 0.11450507 | D4: 0.1201562 | F4: 2015 | G4: 0.04139538 | H4: 0.0432022 | J4: 2015 | K4: 0.07220464 | L4: 0.0766823 | N4: 100
B5: 2016 | C5: 0.12376694 | D5: 0.1295683 | F5: 2016 | G5: 0.04066339 | H5: 0.0425694 | J5: 2016 | K5: 0.08274628 | L5: 0.085921
B6: 2017 | C6: 0.10418892 | D6: 0.1078266 | F6: 2017 | G6: 0.04083831 | H6: 0.0422642 | J6: 2017 | K6: 0.0633506 | L6: 0.0655625
B7: 2018 | C7: 0.06696059 | D7: 0.0697379 | F7: 2018 | G7: 0.04538184 | H7: 0.0472642 | J7: 2018 | K7: 0.02157876 | L7: 0.0224738
B8: 2019 | C8: 0.09663232 | D8: 0.1002276 | F8: 2019 | G8: 0.05342232 | H8: 0.0554099 | J8: 2019 | K8: 0.04321001 | L8: 0.0448177
B9: 2020 | C9: 0.06884031 | D9: 0.0713628 | F9: 2020 | G9: 0.05709798 | H9: 0.0591902 | J9: 2020 | K9: 0.01174233 | L9: 0.0121726
B10: 2021 | C10: 0.05998683 | D10: 0.0620294 | F10: 2021 | G10: 0.05998683 | H10: 0.0620294 | J10: 2021 | K10: 0 | L10: 0
B11: 2022 | C11: 0.11548557 | D11: 0.1161366 | F11: 2022 | G11: 0.05827416 | H11: 0.0596348 | J11: 2022 | K11: 0.05847272 | L11: 0.0602201
B13: Change | C13: =C11-C4 -> 0.0009805 | D13: =D11-D4 -> -0.0040196 | F13: Change | G13: =G11-G4 -> 0.01687878 | H13: =H11-H4 -> 0.0164326 | J13: Change | K13: =K11-K4 -> -0.01373192 | L13: =L11-L4 -> -0.0164622
C17: =C4*$N$4 -> 11.450507 | D17: =D4*$N$4 -> 12.01562 | G17: =G4*$N$4 -> 4.139538 | H17: =H4*$N$4 -> 4.32022 | K17: =K4*$N$4 -> 7.220464 | L17: =L4*$N$4 -> 7.66823
C18: =C5*$N$4 -> 12.376694 | D18: =D5*$N$4 -> 12.95683 | G18: =G5*$N$4 -> 4.066339 | H18: =H5*$N$4 -> 4.25694 | K18: =K5*$N$4 -> 8.274628 | L18: =L5*$N$4 -> 8.5921
C19: =C6*$N$4 -> 10.418892 | D19: =D6*$N$4 -> 10.78266 | G19: =G6*$N$4 -> 4.083831 | H19: =H6*$N$4 -> 4.22642 | K19: =K6*$N$4 -> 6.33506 | L19: =L6*$N$4 -> 6.55625
C20: =C7*$N$4 -> 6.696059 | D20: =D7*$N$4 -> 6.97379 | G20: =G7*$N$4 -> 4.538184 | H20: =H7*$N$4 -> 4.72642 | K20: =K7*$N$4 -> 2.157876 | L20: =L7*$N$4 -> 2.24738
C21: =C8*$N$4 -> 9.663232 | D21: =D8*$N$4 -> 10.02276 | G21: =G8*$N$4 -> 5.342232 | H21: =H8*$N$4 -> 5.54099 | K21: =K8*$N$4 -> 4.321001 | L21: =L8*$N$4 -> 4.48177
C22: =C9*$N$4 -> 6.884031 | D22: =D9*$N$4 -> 7.13628 | G22: =G9*$N$4 -> 5.709798 | H22: =H9*$N$4 -> 5.91902 | K22: =K9*$N$4 -> 1.174233 | L22: =L9*$N$4 -> 1.21726
C23: =C10*$N$4 -> 5.998683 | D23: =D10*$N$4 -> 6.20294 | G23: =G10*$N$4 -> 5.998683 | H23: =H10*$N$4 -> 6.20294 | K23: =K10*$N$4 -> 0 | L23: =L10*$N$4 -> 0
C24: =C11*$N$4 -> 11.548557 | D24: =D11*$N$4 -> 11.61366 | G24: =G11*$N$4 -> 5.827416 | H24: =H11*$N$4 -> 5.96348 | K24: =K11*$N$4 -> 5.847272 | L24: =L11*$N$4 -> 6.02201

Sheet Maine
B2: Total Contributions | F2: District Contributions | J2: State Contributions
B3: Year | C3: Unweighted | D3: Weighted | F3: Year | G3: Unweighted | H3: Weighted | J3: Year | K3: Unweighted | L3: Weighted
B4: 2015 | C4: 0.07626834 | D4: 0.0752497 | F4: 2015 | G4: 0.0038003 | H4: 0.0037814 | J4: 2015 | K4: 0.0724874 | L4: 0.0715178 | N4: 100
B5: 2016 | C5: 0.0652517 | D5: 0.0612083 | F5: 2016 | G5: 0.00326675 | H5: 0.0030813 | J5: 2016 | K5: 0.06198997 | L5: 0.0581492
B6: 2017 | C6: 0.06295209 | D6: 0.0608779 | F6: 2017 | G6: 0.00314467 | H6: 0.003058 | J6: 2017 | K6: 0.05981506 | L6: 0.0578442
B7: 2018 | C7: 0.07290516 | D7: 0.066586 | F7: 2018 | G7: 0.003434 | H7: 0.0031638 | J7: 2018 | K7: 0.06947567 | L7: 0.063446
B8: 2019 | C8: 0.06737731 | D8: 0.0654423 | F8: 2019 | G8: 0.00302428 | H8: 0.0029831 | J8: 2019 | K8: 0.06436588 | L8: 0.0624898
B9: 2020 | C9: 0.08817983 | D9: 0.0779967 | F9: 2020 | G9: 0.0038053 | H9: 0.0034391 | J9: 2020 | K9: 0.08438359 | L9: 0.0746029
B10: 2021 | C10: 0.08153943 | D10: 0.0728744 | F10: 2021 | G10: 0.00458607 | H10: 0.0040988 | J10: 2021 | K10: 0.0769664 | L10: 0.0688172
B11: 2022 | C11: 0.08726209 | D11: 0.0840687 | F11: 2022 | G11: 0.00565423 | H11: 0.0054012 | J11: 2022 | K11: 0.08161298 | L11: 0.0786945
B13: Change | C13: =C11-C4 -> 0.01099375 | D13: =D11-D4 -> 0.008819 | F13: Change | G13: =G11-G4 -> 0.00185393 | H13: =H11-H4 -> 0.0016198 | J13: Change | K13: =K11-K4 -> 0.00912558 | L13: =L11-L4 -> 0.0071767
C17: =C4*$N$4 -> 7.626834 | D17: =D4*$N$4 -> 7.52497 | G17: =G4*$N$4 -> 0.38003 | H17: =H4*$N$4 -> 0.37814 | K17: =K4*$N$4 -> 7.24874 | L17: =L4*$N$4 -> 7.15178
C18: =C5*$N$4 -> 6.52517 | D18: =D5*$N$4 -> 6.12083 | G18: =G5*$N$4 -> 0.326675 | H18: =H5*$N$4 -> 0.30813 | K18: =K5*$N$4 -> 6.198997 | L18: =L5*$N$4 -> 5.81492
C19: =C6*$N$4 -> 6.295209 | D19: =D6*$N$4 -> 6.08779 | G19: =G6*$N$4 -> 0.314467 | H19: =H6*$N$4 -> 0.3058 | K19: =K6*$N$4 -> 5.981506 | L19: =L6*$N$4 -> 5.78442
C20: =C7*$N$4 -> 7.290516 | D20: =D7*$N$4 -> 6.6586 | G20: =G7*$N$4 -> 0.3434 | H20: =H7*$N$4 -> 0.31638 | K20: =K7*$N$4 -> 6.947567 | L20: =L7*$N$4 -> 6.3446
C21: =C8*$N$4 -> 6.737731 | D21: =D8*$N$4 -> 6.54423 | G21: =G8*$N$4 -> 0.302428 | H21: =H8*$N$4 -> 0.29831 | K21: =K8*$N$4 -> 6.436588 | L21: =L8*$N$4 -> 6.24898
C22: =C9*$N$4 -> 8.817983 | D22: =D9*$N$4 -> 7.79967 | G22: =G9*$N$4 -> 0.38053 | H22: =H9*$N$4 -> 0.34391 | K22: =K9*$N$4 -> 8.438359 | L22: =L9*$N$4 -> 7.46029
C23: =C10*$N$4 -> 8.153943 | D23: =D10*$N$4 -> 7.28744 | G23: =G10*$N$4 -> 0.458607 | H23: =H10*$N$4 -> 0.40988 | K23: =K10*$N$4 -> 7.69664 | L23: =L10*$N$4 -> 6.88172
C24: =C11*$N$4 -> 8.726209 | D24: =D11*$N$4 -> 8.40687 | G24: =G11*$N$4 -> 0.565423 | H24: =H11*$N$4 -> 0.54012 | K24: =K11*$N$4 -> 8.161298 | L24: =L11*$N$4 -> 7.86945

Sheet Maryland
B2: Total Contributions | F2: District Contributions | J2: State Contributions
B3: Year | C3: Unweighted | D3: Weighted | F3: Year | G3: Unweighted | H3: Weighted | J3: Year | K3: Unweighted | L3: Weighted
B4: 2015 | C4: 0.12191679 | D4: 0.0939723 | F4: 2015 | G4: 0.00756993 | H4: 0.0063368 | J4: 2015 | K4: 0.11979195 | L4: 0.0990627 | N4: 100
B5: 2016 | C5: 0.10794004 | D5: 0.0840029 | F5: 2016 | G5: 0.0067582 | H5: 0.0057613 | J5: 2016 | K5: 0.10600002 | L5: 0.0877647
B6: 2017 | C6: 0.10642183 | D6: 0.0808419 | F6: 2017 | G6: 0.00631842 | H6: 0.0052933 | J6: 2017 | K6: 0.10487024 | L6: 0.08467
B7: 2018 | C7: 0.10511845 | D7: 0.080339 | F7: 2018 | G7: 0.00679754 | H7: 0.0056818 | J7: 2018 | K7: 0.10300286 | L7: 0.0830223
B8: 2019 | C8: 0.10530973 | D8: 0.0808104 | F8: 2019 | G8: 0.00710032 | H8: 0.0059563 | J8: 2019 | K8: 0.10288605 | L8: 0.0829884
B9: 2020 | C9: 0.10521709 | D9: 0.0807024 | F9: 2020 | G9: 0.00720224 | H9: 0.0058798 | J9: 2020 | K9: 0.10268223 | L9: 0.0827863
B10: 2021 | C10: 0.10489286 | D10: 0.0816275 | F10: 2021 | G10: 0.00802773 | H10: 0.0080695 | J10: 2021 | K10: 0.10186003 | L10: 0.0838053
B11: 2022 | C11: 0.09639311 | D11: 0.0823539 | F11: 2022 | G11: 0.0070633 | H11: 0.0076304 | J11: 2022 | K11: 0.09391996 | L11: 0.0843493
B13: Change | C13: =C11-C4 -> -0.02552368 | D13: =D11-D4 -> -0.0116184 | F13: Change | G13: =G11-G4 -> -0.00050663 | H13: =H11-H4 -> 0.0012936 | J13: Change | K13: =K11-K4 -> -0.02587199 | L13: =L11-L4 -> -0.0147134
C17: =C4*$N$4 -> 12.191679 | D17: =D4*$N$4 -> 9.39723 | G17: =G4*$N$4 -> 0.756993 | H17: =H4*$N$4 -> 0.63368 | K17: =K4*$N$4 -> 11.979195 | L17: =L4*$N$4 -> 9.90627
C18: =C5*$N$4 -> 10.794004 | D18: =D5*$N$4 -> 8.40029 | G18: =G5*$N$4 -> 0.67582 | H18: =H5*$N$4 -> 0.57613 | K18: =K5*$N$4 -> 10.600002 | L18: =L5*$N$4 -> 8.77647
C19: =C6*$N$4 -> 10.642183 | D19: =D6*$N$4 -> 8.08419 | G19: =G6*$N$4 -> 0.631842 | H19: =H6*$N$4 -> 0.52933 | K19: =K6*$N$4 -> 10.487024 | L19: =L6*$N$4 -> 8.467
C20: =C7*$N$4 -> 10.511845 | D20: =D7*$N$4 -> 8.0339 | G20: =G7*$N$4 -> 0.679754 | H20: =H7*$N$4 -> 0.56818 | K20: =K7*$N$4 -> 10.300286 | L20: =L7*$N$4 -> 8.30223
C21: =C8*$N$4 -> 10.530973 | D21: =D8*$N$4 -> 8.08104 | G21: =G8*$N$4 -> 0.710032 | H21: =H8*$N$4 -> 0.59563 | K21: =K8*$N$4 -> 10.288605 | L21: =L8*$N$4 -> 8.29884
C22: =C9*$N$4 -> 10.521709 | D22: =D9*$N$4 -> 8.07024 | G22: =G9*$N$4 -> 0.720224 | H22: =H9*$N$4 -> 0.58798 | K22: =K9*$N$4 -> 10.268223 | L22: =L9*$N$4 -> 8.27863
C23: =C10*$N$4 -> 10.489286 | D23: =D10*$N$4 -> 8.16275 | G23: =G10*$N$4 -> 0.802773 | H23: =H10*$N$4 -> 0.80695 | K23: =K10*$N$4 -> 10.186003 | L23: =L10*$N$4 -> 8.38053
C24: =C11*$N$4 -> 9.639311 | D24: =D11*$N$4 -> 8.23539 | G24: =G11*$N$4 -> 0.70633 | H24: =H11*$N$4 -> 0.76304 | K24: =K11*$N$4 -> 9.391996 | L24: =L11*$N$4 -> 8.43493

Sheet Massachusetts
B2: State Contributions
B3: Year | C3: Unweighted | D3: Weighted
B4: 2015 | C4: 0.08507181 | D4: 0.0900083 | F4: 100
B5: 2016 | C5: 0.09825101 | D5: 0.0998395
B6: 2017 | C6: 0.10257865 | D6: 0.1046099
B7: 2018 | C7: 0.10525142 | D7: 0.1074113
B8: 2019 | C8: 0.10979559 | D8: 0.1122412
B9: 2020 | C9: 0.12135311 | D9: 0.1147004
B10: 2021 | C10: 0.12357131 | D10: 0.1232467
B11: 2022 | C11: 0.13434747 | D11: 0.1355867
B13: Change | C13: =C11-C4 -> 0.04927566 | D13: =D11-D4 -> 0.0455784
C15: =C11-C4 -> 0.04927566 | D15: =D11-D4 -> 0.0455784
C17: =C4*$F$4 -> 8.507181 | D17: =D4*$F$4 -> 9.00083
C18: =C5*$F$4 -> 9.825101 | D18: =D5*$F$4 -> 9.98395
C19: =C6*$F$4 -> 10.257865 | D19: =D6*$F$4 -> 10.46099
C20: =C7*$F$4 -> 10.525142 | D20: =D7*$F$4 -> 10.74113
C21: =C8*$F$4 -> 10.979559 | D21: =D8*$F$4 -> 11.22412
C22: =C9*$F$4 -> 12.135311 | D22: =D9*$F$4 -> 11.47004
C23: =C10*$F$4 -> 12.357131 | D23: =D10*$F$4 -> 12.32467
C24: =C11*$F$4 -> 13.434747 | D24: =D11*$F$4 -> 13.55867

Sheet New Hampshire
B2: District Contributions
B3: Year | C3: Unweighted | D3: Weighted
B4: 2015 | C4: 0.05073431 | D4: 0.055803 | F4: 100
B5: 2016 | C5: 0.0534939 | D5: 0.0583345
B6: 2017 | C6: 0.05366845 | D6: 0.0582384
B7: 2018 | C7: 0.06352617 | D7: 0.0686667
B8: 2019 | C8: 0.06365713 | D8: 0.0684367
B9: 2020 | C9: 0.06516239 | D9: 0.0698521
B10: 2021 | C10: 0.06499079 | D10: 0.0700566
B11: 2022 | C11: 0.06918567 | D11: 0.0779569
B13: Change | C13: =C11-C4 -> 0.01845136 | D13: =D11-D4 -> 0.0221539
C15: =C11-C4 -> 0.01845136 | D15: =D11-D4 -> 0.0221539
C17: =C4*$F$4 -> 5.073431 | D17: =D4*$F$4 -> 5.5803
C18: =C5*$F$4 -> 5.34939 | D18: =D5*$F$4 -> 5.83345
C19: =C6*$F$4 -> 5.366845 | D19: =D6*$F$4 -> 5.82384
C20: =C7*$F$4 -> 6.352617 | D20: =D7*$F$4 -> 6.86667
C21: =C8*$F$4 -> 6.365713 | D21: =D8*$F$4 -> 6.84367
C22: =C9*$F$4 -> 6.516239 | D22: =D9*$F$4 -> 6.98521
C23: =C10*$F$4 -> 6.499079 | D23: =D10*$F$4 -> 7.00566
C24: =C11*$F$4 -> 6.918567 | D24: =D11*$F$4 -> 7.79569

Sheet New Jersey
B2: State Contributions
B3: Year | C3: Unweighted | D3: Weighted
B4: 2015 | C4: 0.02540558 | D4: 0.0268373 | F4: 100
B5: 2016 | C5: 0.03593427 | D5: 0.0385086
B6: 2017 | C6: 0.04925047 | D6: 0.0521654
B7: 2018 | C7: 0.06430968 | D7: 0.067096
B8: 2019 | C8: 0.08191639 | D8: 0.0843074
B9: 2020 | C9: 0.09116146 | D9: 0.0926688
B10: 2021 | C10: 0.11226316 | D10: 0.1127097
B11: 2022 | C11: 0.1419324 | D11: 0.1382872
B13: Change | C13: =C11-C4 -> 0.11652682 | D13: =D11-D4 -> 0.1114499
C15: =C11-C4 -> 0.11652682 | D15: =D11-D4 -> 0.1114499
C17: =C4*$F$4 -> 2.540558 | D17: =D4*$F$4 -> 2.68373
C18: =C5*$F$4 -> 3.593427 | D18: =D5*$F$4 -> 3.85086
C19: =C6*$F$4 -> 4.925047 | D19: =D6*$F$4 -> 5.21654
C20: =C7*$F$4 -> 6.430968 | D20: =D7*$F$4 -> 6.7096
C21: =C8*$F$4 -> 8.191639 | D21: =D8*$F$4 -> 8.43074
C22: =C9*$F$4 -> 9.116146 | D22: =D9*$F$4 -> 9.26688
C23: =C10*$F$4 -> 11.226316 | D23: =D10*$F$4 -> 11.27097
C24: =C11*$F$4 -> 14.19324 | D24: =D11*$F$4 -> 13.82872

Sheet New York
B2: District Contributions
B3: Year | C3: Unweighted | D3: Weighted
B4: 2015 | C4: 0.08854652 | D4: 0.0911024 | F4: 100
B5: 2016 | C5: 0.06835605 | D5: 0.0714299
B6: 2017 | C6: 0.06070511 | D6: 0.0635979
B7: 2018 | C7: 0.05093192 | D7: 0.0537156
B8: 2019 | C8: 0.05448018 | D8: 0.0575421
B9: 2020 | C9: 0.04610654 | D9: 0.0489858
B10: 2021 | C10: 0.04946905 | D10: 0.0523782
B11: 2022 | C11: 0.0500707 | D11: 0.0531306
B13: Change | C13: =C11-C4 -> -0.03847582 | D13: =D11-D4 -> -0.0379718
C15: =C11-C4 -> -0.03847582 | D15: =D11-D4 -> -0.0379718
C17: =C4*$F$4 -> 8.854652 | D17: =D4*$F$4 -> 9.11024
C18: =C5*$F$4 -> 6.835605 | D18: =D5*$F$4 -> 7.14299
C19: =C6*$F$4 -> 6.070511 | D19: =D6*$F$4 -> 6.35979
C20: =C7*$F$4 -> 5.093192 | D20: =D7*$F$4 -> 5.37156
C21: =C8*$F$4 -> 5.448018 | D21: =D8*$F$4 -> 5.75421
C22: =C9*$F$4 -> 4.610654 | D22: =D9*$F$4 -> 4.89858
C23: =C10*$F$4 -> 4.946905 | D23: =D10*$F$4 -> 5.23782
C24: =C11*$F$4 -> 5.00707 | D24: =D11*$F$4 -> 5.31306

Sheet Rhode Island
B2: Total Contributions | F2: District Contributions | J2: State Contributions
B3: Year | C3: Unweighted | D3: Weighted | F3: Year | G3: Unweighted | H3: Weighted | J3: Year | K3: Unweighted | L3: Weighted
B4: 2015 | C4: 0.12356643 | D4: 0.1274953 | F4: 2015 | G4: 0.07516138 | H4: 0.0777905 | J4: 2015 | K4: 0.04832999 | L4: 0.0497035 | N4: 100
B5: 2016 | C5: 0.1250552 | D5: 0.1290887 | F5: 2016 | G5: 0.07605468 | H5: 0.0787256 | J5: 2016 | K5: 0.04893175 | L5: 0.0503618
B6: 2017 | C6: 0.12974476 | D6: 0.1305796 | F6: 2017 | G6: 0.07613785 | H6: 0.0766643 | J6: 2017 | K6: 0.05358487 | L6: 0.0539141
B7: 2018 | C7: 0.16340963 | D7: 0.1500163 | F7: 2018 | G7: 0.08199638 | H7: 0.0769154 | J7: 2018 | K7: 0.08152852 | L7: 0.0735044
B8: 2019 | C8: 0.12507937 | D8: 0.1305612 | F8: 2019 | G8: 0.07385871 | H8: 0.0771412 | J8: 2019 | K8: 0.05126528 | L8: 0.0538069
B9: 2020 | C9: 0.12026328 | D9: 0.1270425 | F9: 2020 | G9: 0.06873501 | H9: 0.0726298 | J9: 2020 | K9: 0.0515035 | L9: 0.0544115
B10: 2021 | C10: 0.1288373 | D10: 0.1346276 | F10: 2021 | G10: 0.07401956 | H10: 0.0776659 | J10: 2021 | K10: 0.05486235 | L10: 0.0573392
B11: 2022 | C11: 0.12667805 | D11: 0.1326994 | F11: 2022 | G11: 0.07286437 | H11: 0.0766191 | J11: 2022 | K11: 0.0538583 | L11: 0.0564398
B13: Change | C13: =C11-C4 -> 0.00311162 | D13: =D11-D4 -> 0.0052041 | F13: Change | G13: =G11-G4 -> -0.00229701 | H13: =H11-H4 -> -0.0011714 | J13: Change | K13: =K11-K4 -> 0.00552831 | L13: =L11-L4 -> 0.0067363
C17: =C4*$N$4 -> 12.356643 | D17: =D4*$N$4 -> 12.74953 | G17: =G4*$N$4 -> 7.516138 | H17: =H4*$N$4 -> 7.77905 | K17: =K4*$N$4 -> 4.832999 | L17: =L4*$N$4 -> 4.97035
C18: =C5*$N$4 -> 12.50552 | D18: =D5*$N$4 -> 12.90887 | G18: =G5*$N$4 -> 7.605468 | H18: =H5*$N$4 -> 7.87256 | K18: =K5*$N$4 -> 4.893175 | L18: =L5*$N$4 -> 5.03618
C19: =C6*$N$4 -> 12.974476 | D19: =D6*$N$4 -> 13.05796 | G19: =G6*$N$4 -> 7.613785 | H19: =H6*$N$4 -> 7.66643 | K19: =K6*$N$4 -> 5.358487 | L19: =L6*$N$4 -> 5.39141
C20: =C7*$N$4 -> 16.340963 | D20: =D7*$N$4 -> 15.00163 | G20: =G7*$N$4 -> 8.199638 | H20: =H7*$N$4 -> 7.69154 | K20: =K7*$N$4 -> 8.152852 | L20: =L7*$N$4 -> 7.35044
C21: =C8*$N$4 -> 12.507937 | D21: =D8*$N$4 -> 13.05612 | G21: =G8*$N$4 -> 7.385871 | H21: =H8*$N$4 -> 7.71412 | K21: =K8*$N$4 -> 5.126528 | L21: =L8*$N$4 -> 5.38069
C22: =C9*$N$4 -> 12.026328 | D22: =D9*$N$4 -> 12.70425 | G22: =G9*$N$4 -> 6.873501 | H22: =H9*$N$4 -> 7.26298 | K22: =K9*$N$4 -> 5.15035 | L22: =L9*$N$4 -> 5.44115
C23: =C10*$N$4 -> 12.88373 | D23: =D10*$N$4 -> 13.46276 | G23: =G10*$N$4 -> 7.401956 | H23: =H10*$N$4 -> 7.76659 | K23: =K10*$N$4 -> 5.486235 | L23: =L10*$N$4 -> 5.73392
C24: =C11*$N$4 -> 12.667805 | D24: =D11*$N$4 -> 13.26994 | G24: =G11*$N$4 -> 7.286437 | H24: =H11*$N$4 -> 7.66191 | K24: =K11*$N$4 -> 5.38583 | L24: =L11*$N$4 -> 5.64398

Sheet Vermont
B2: State Contributions
B3: Year | C3: Unweighted | D3: Weighted
B4: 2015 | C4: 0.06554287 | D4: 0.0621013 | F4: 100
B5: 2016 | C5: 0.06082267 | D5: 0.0586576
B6: 2017 | C6: 0.06456119 | D6: 0.0616446
B7: 2018 | C7: 0.08705083 | D7: 0.0840454
B8: 2019 | C8: 0.08613007 | D8: 0.0847213
B9: 2020 | C9: 0.09019362 | D9: 0.0858054
B10: 2021 | C10: 0.08913945 | D10: 0.0885445
B11: 2022 | C11: 0.19493289 | D11: 0.1730205
B13: Change | C13: =C11-C4 -> 0.12939002 | D13: =D11-D4 -> 0.1109192
C15: =C11-C4 -> 0.12939002 | D15: =D11-D4 -> 0.1109192
C17: =C4*$F$4 -> 6.554287 | D17: =D4*$F$4 -> 6.21013
C18: =C5*$F$4 -> 6.082267 | D18: =D5*$F$4 -> 5.86576
C19: =C6*$F$4 -> 6.456119 | D19: =D6*$F$4 -> 6.16446
C20: =C7*$F$4 -> 8.705083 | D20: =D7*$F$4 -> 8.40454
C21: =C8*$F$4 -> 8.613007 | D21: =D8*$F$4 -> 8.47213
C22: =C9*$F$4 -> 9.019362 | D22: =D9*$F$4 -> 8.58054
C23: =C10*$F$4 -> 8.913945 | D23: =D10*$F$4 -> 8.85445
C24: =C11*$F$4 -> 19.493289 | D24: =D11*$F$4 -> 17.30205

Sheet Midwest -->

Sheet Illinois
B2: Total Contributions | F2: District Contributions | J2: State Contributions
B3: Year | C3: Unweighted | D3: Weighted | F3: Year | G3: Unweighted | H3: Weighted | J3: Year | K3: Unweighted | L3: Weighted
B4: 2015 | C4: 0.16814373 | D4: 0.1561264 | F4: 2015 | G4: 0.0061695 | H4: 0.0304612 | J4: 2015 | K4: 0.16196983 | L4: 0.1256263 | N4: 100
B5: 2016 | C5: 0.17604271 | D5: 0.1355382 | F5: 2016 | G5: 0.00607049 | H5: 0.0336907 | J5: 2016 | K5: 0.17015472 | L5: 0.1311705
B6: 2017 | C6: 0.16497501 | D6: 0.1325912 | F6: 2017 | G6: 0.00551778 | H6: 0.0328893 | J6: 2017 | K6: 0.15965749 | L6: 0.1284967
B7: 2018 | C7: 0.17641711 | D7: 0.1532589 | F7: 2018 | G7: 0.00268732 | H7: 0.0224414 | J7: 2018 | K7: 0.17387991 | L7: 0.1511943
B8: 2019 | C8: 0.1819229 | D8: 0.1624984 | F8: 2019 | G8: 0.00267216 | H8: 0.0229634 | J8: 2019 | K8: 0.17940328 | L8: 0.1603861
B9: 2020 | C9: 0.19200859 | D9: 0.1670837 | F9: 2020 | G9: 0.00257388 | H9: 0.0227414 | J9: 2020 | K9: 0.18958509 | L9: 0.1650892
B10: 2021 | C10: 0.21245094 | D10: 0.1716887 | F10: 2021 | G10: 0.00265667 | H10: 0.0227249 | J10: 2021 | K10: 0.20994107 | L10: 0.1697552
B11: 2022 | C11: 0.22657557 | D11: 0.1885285 | F11: 2022 | G11: 0.00273438 | H11: 0.0243432 | J11: 2022 | K11: 0.22398624 | L11: 0.1864579
B13: Change | C13: =C11-C4 -> 0.05843184 | D13: =D11-D4 -> 0.0324021 | F13: Change | G13: =G11-G4 -> -0.00343512 | H13: =H11-H4 -> -0.006118 | J13: Change | K13: =K11-K4 -> 0.06201641 | L13: =L11-L4 -> 0.0608316
B15: Weights based on NCES variables TCURINST / E17 / E08 / E09 / V40
C17: =C4*$N$4 -> 16.814373 | D17: =D4*$N$4 -> 15.61264 | K17: =K4*$N$4 -> 16.196983 | L17: =L4*$N$4 -> 12.56263
C18: =C5*$N$4 -> 17.604271 | D18: =D5*$N$4 -> 13.55382 | K18: =K5*$N$4 -> 17.015472 | L18: =L5*$N$4 -> 13.11705
C19: =C6*$N$4 -> 16.497501 | D19: =D6*$N$4 -> 13.25912 | K19: =K6*$N$4 -> 15.965749 | L19: =L6*$N$4 -> 12.84967
C20: =C7*$N$4 -> 17.641711 | D20: =D7*$N$4 -> 15.32589 | K20: =K7*$N$4 -> 17.387991 | L20: =L7*$N$4 -> 15.11943
C21: =C8*$N$4 -> 18.19229 | D21: =D8*$N$4 -> 16.24984 | K21: =K8*$N$4 -> 17.940328 | L21: =L8*$N$4 -> 16.03861
C22: =C9*$N$4 -> 19.200859 | D22: =D9*$N$4 -> 16.70837 | K22: =K9*$N$4 -> 18.958509 | L22: =L9*$N$4 -> 16.50892
C23: =C10*$N$4 -> 21.245094 | D23: =D10*$N$4 -> 17.16887 | K23: =K10*$N$4 -> 20.994107 | L23: =L10*$N$4 -> 16.97552
C24: =C11*$N$4 -> 22.657557 | D24: =D11*$N$4 -> 18.85285 | K24: =K11*$N$4 -> 22.398624 | L24: =L11*$N$4 -> 18.64579

Sheet Indiana
B2: Total Contributions | F2: District Contributions | J2: State Contributions
B3: Year | C3: Unweighted | D3: Weighted | F3: Year | G3: Unweighted | H3: Weighted | J3: Year | K3: Unweighted | L3: Weighted
B4: 2015 | C4: 0.13988968 | D4: 0.1436581 | F4: 2015 | G4: 0.028005 | H4: 0.028542 | J4: 2015 | K4: 0.11192621 | L4: 0.1154393 | N4: 100
B5: 2016 | C5: 0.14190878 | D5: 0.1457521 | F5: 2016 | G5: 0.02825437 | H5: 0.0288284 | J5: 2016 | K5: 0.11371208 | L5: 0.1172375
B6: 2017 | C6: 0.13725278 | D6: 0.1423267 | F6: 2017 | G6: 0.02883345 | H6: 0.0295507 | J6: 2017 | K6: 0.10845543 | L6: 0.1129941
B7: 2018 | C7: 0.1426787 | D7: 0.1432836 | F7: 2018 | G7: 0.02908744 | H7: 0.0297919 | J7: 2018 | K7: 0.11354829 | L7: 0.1137826
B8: 2019 | C8: 0.1002905 | D8: 0.1048215 | F8: 2019 | G8: 0.02956979 | H8: 0.0301529 | J8: 2019 | K8: 0.07061923 | L8: 0.0738097
B9: 2020 | C9: 0.13713024 | D9: 0.1362667 | F9: 2020 | G9: 0.02195924 | H9: 0.0229352 | J9: 2020 | K9: 0.11512491 | L9: 0.1136684
B10: 2021 | C10: 0.23168597 | D10: 0.2198959 | F10: 2021 | G10: 0.02492634 | H10: 0.0259644 | J10: 2021 | K10: 0.20648746 | L10: 0.1937441
B11: 2022 | C11: 0.18811658 | D11: 0.1817413 | F11: 2022 | G11: 0.02216914 | H11: 0.0231951 | J11: 2022 | K11: 0.16576574 | L11: 0.1585382
B13: Change | C13: =C11-C4 -> 0.0482269 | D13: =D11-D4 -> 0.0380832 | F13: Change | G13: =G11-G4 -> -0.00583586 | H13: =H11-H4 -> -0.0053469 | J13: Change | K13: =K11-K4 -> 0.05383953 | L13: =L11-L4 -> 0.0430989
B15: Weights based on NCES variables TCURINST / E17 / E08 / E09 / V40
C17: =C4*$N$4 -> 13.988968 | D17: =D4*$N$4 -> 14.36581 | G17: =G4*$N$4 -> 2.8005 | H17: =H4*$N$4 -> 2.8542 | K17: =K4*$N$4 -> 11.192621 | L17: =L4*$N$4 -> 11.54393
C18: =C5*$N$4 -> 14.190878 | D18: =D5*$N$4 -> 14.57521 | G18: =G5*$N$4 -> 2.825437 | H18: =H5*$N$4 -> 2.88284 | K18: =K5*$N$4 -> 11.371208 | L18: =L5*$N$4 -> 11.72375
C19: =C6*$N$4 -> 13.725278 | D19: =D6*$N$4 -> 14.23267 | G19: =G6*$N$4 -> 2.883345 | H19: =H6*$N$4 -> 2.95507 | K19: =K6*$N$4 -> 10.845543 | L19: =L6*$N$4 -> 11.29941
C20: =C7*$N$4 -> 14.26787 | D20: =D7*$N$4 -> 14.32836 | G20: =G7*$N$4 -> 2.908744 | H20: =H7*$N$4 -> 2.97919 | K20: =K7*$N$4 -> 11.354829 | L20: =L7*$N$4 -> 11.37826
C21: =C8*$N$4 -> 10.02905 | D21: =D8*$N$4 -> 10.48215 | G21: =G8*$N$4 -> 2.956979 | H21: =H8*$N$4 -> 3.01529 | K21: =K8*$N$4 -> 7.061923 | L21: =L8*$N$4 -> 7.38097
C22: =C9*$N$4 -> 13.713024 | D22: =D9*$N$4 -> 13.62667 | G22: =G9*$N$4 -> 2.195924 | H22: =H9*$N$4 -> 2.29352 | K22: =K9*$N$4 -> 11.512491 | L22: =L9*$N$4 -> 11.36684
C23: =C10*$N$4 -> 23.168597 | D23: =D10*$N$4 -> 21.98959 | G23: =G10*$N$4 -> 2.492634 | H23: =H10*$N$4 -> 2.59644 | K23: =K10*$N$4 -> 20.648746 | L23: =L10*$N$4 -> 19.37441
C24: =C11*$N$4 -> 18.811658 | D24: =D11*$N$4 -> 18.17413 | G24: =G11*$N$4 -> 2.216914 | H24: =H11*$N$4 -> 2.31951 | K24: =K11*$N$4 -> 16.576574 | L24: =L11*$N$4 -> 15.85382

Sheet Iowa
B2: District Contributions
B3: Year | C3: Unweighted | D3: Weighted
B4: 2015 | C4: 0.05479209 | D4: 0.0557985 | F4: 100
B5: 2016 | C5: 0.05504467 | D5: 0.0562974
B6: 2017 | C6: 0.05528126 | D6: 0.0567144
B7: 2018 | C7: 0.05504574 | D7: 0.0563314
B8: 2019 | C8: 0.05844296 | D8: 0.0590211
B9: 2020 | C9: 0.05891251 | D9: 0.0596
B10: 2021 | C10: 0.05767503 | D10: 0.0584794
B11: 2022 | C11: 0.0564209 | D11: 0.0575016
B13: Change | C13: =C11-C4 -> 0.00162881 | D13: =D11-D4 -> 0.0017031
C17: =C4*$F$4 -> 5.479209 | D17: =D4*$F$4 -> 5.57985
C18: =C5*$F$4 -> 5.504467 | D18: =D5*$F$4 -> 5.62974
C19: =C6*$F$4 -> 5.528126 | D19: =D6*$F$4 -> 5.67144
C20: =C7*$F$4 -> 5.504574 | D20: =D7*$F$4 -> 5.63314
C21: =C8*$F$4 -> 5.844296 | D21: =D8*$F$4 -> 5.90211
C22: =C9*$F$4 -> 5.891251 | D22: =D9*$F$4 -> 5.96
C23: =C10*$F$4 -> 5.767503 | D23: =D10*$F$4 -> 5.84794
C24: =C11*$F$4 -> 5.64209 | D24: =D11*$F$4 -> 5.75016
D47: .

Sheet Kansas
B2: Total Contributions | F2: District Contributions | J2: State Contributions
B3: Year | C3: Unweighted | D3: Weighted | F3: Year | G3: Unweighted | H3: Weighted | J3: Year | K3: Unweighted | L3: Weighted
B4: 2015 | C4: 0.06322887 | D4: 0.070577 | F4: 2015 | G4: 0.05434183 | H4: 0.0604495 | J4: 2015 | K4: 0.00877142 | L4: 0.0100222 | N4: 100
B5: 2016 | C5: 0.21208483 | D5: 0.1984939 | F5: 2016 | G5: 0.05914684 | H5: 0.0659115 | J5: 2016 | K5: 0.14957779 | L5: 0.1134639
B6: 2017 | C6: 0.06918356 | D6: 0.077514 | F6: 2017 | G6: 0.05975215 | H6: 0.0667062 | J6: 2017 | K6: 0.00935449 | L6: 0.0108001
B7: 2018 | C7: 0.07532097 | D7: 0.0844763 | F7: 2018 | G7: 0.06534752 | H7: 0.0725757 | J7: 2018 | K7: 0.00993297 | L7: 0.0117047
B8: 2019 | C8: 0.08135408 | D8: 0.0919459 | F8: 2019 | G8: 0.07049098 | H8: 0.0785626 | J8: 2019 | K8: 0.01080436 | L8: 0.012946
B9: 2020 | C9: 0.08493189 | D9: 0.0941657 | F9: 2020 | G9: 0.07369922 | H9: 0.0807659 | J9: 2020 | K9: 0.01122697 | L9: 0.0133296
B10: 2021 | C10: 0.0815433 | D10: 0.0916709 | F10: 2021 | G10: 0.07085075 | H10: 0.078586 | J10: 2021 | K10: 0.010659 | L10: 0.0128386
B11: 2022 | C11: 0.0759174 | D11: 0.085855 | F11: 2022 | G11: 0.06673515 | H11: 0.0742007 | J11: 2022 | K11: 0.00914964 | L11: 0.011187
B13: Change | C13: =C11-C4 -> 0.01268853 | D13: =D11-D4 -> 0.015278 | F13: Change | G13: =G11-G4 -> 0.01239332 | H13: =H11-H4 -> 0.0137512 | J13: Change | K13: =K11-K4 -> 0.00037822 | L13: =L11-L4 -> 0.0011648
C17: =C4*$N$4 -> 6.322887 | D17: =D4*$N$4 -> 7.0577 | G17: =G4*$N$4 -> 5.434183 | H17: =H4*$N$4 -> 6.04495 | K17: =K4*$N$4 -> 0.877142 | L17: =L4*$N$4 -> 1.00222
C18: =C5*$N$4 -> 21.208483 | D18: =D5*$N$4 -> 19.84939 | G18: =G5*$N$4 -> 5.914684 | H18: =H5*$N$4 -> 6.59115 | K18: =K5*$N$4 -> 14.957779 | L18: =L5*$N$4 -> 11.34639
C19: =C6*$N$4 -> 6.918356 | D19: =D6*$N$4 -> 7.7514 | G19: =G6*$N$4 -> 5.975215 | H19: =H6*$N$4 -> 6.67062 | K19: =K6*$N$4 -> 0.935449 | L19: =L6*$N$4 -> 1.08001
C20: =C7*$N$4 -> 7.532097 | D20: =D7*$N$4 -> 8.44763 | G20: =G7*$N$4 -> 6.534752 | H20: =H7*$N$4 -> 7.25757 | K20: =K7*$N$4 -> 0.993297 | L20: =L7*$N$4 -> 1.17047
C21: =C8*$N$4 -> 8.135408 | D21: =D8*$N$4 -> 9.19459 | G21: =G8*$N$4 -> 7.049098 | H21: =H8*$N$4 -> 7.85626 | K21: =K8*$N$4 -> 1.080436 | L21: =L8*$N$4 -> 1.2946
C22: =C9*$N$4 -> 8.493189 | D22: =D9*$N$4 -> 9.41657 | G22: =G9*$N$4 -> 7.369922 | H22: =H9*$N$4 -> 8.07659 | K22: =K9*$N$4 -> 1.122697 | L22: =L9*$N$4 -> 1.33296
C23: =C10*$N$4 -> 8.15433 | D23: =D10*$N$4 -> 9.16709 | G23: =G10*$N$4 -> 7.085075 | H23: =H10*$N$4 -> 7.8586 | K23: =K10*$N$4 -> 1.0659 | L23: =L10*$N$4 -> 1.28386
C24: =C11*$N$4 -> 7.59174 | D24: =D11*$N$4 -> 8.5855 | G24: =G11*$N$4 -> 6.673515 | H24: =H11*$N$4 -> 7.42007 | K24: =K11*$N$4 -> 0.914964 | L24: =L11*$N$4 -> 1.1187

Sheet Michigan
B2: District Contributions
B3: Year | C3: Unweighted | D3: Weighted
B4: 2015 | C4: 0.11014194 | D4: 0.1178567 | F4: 100
B5: 2016 | C5: 0.12733503 | D5: 0.1352483
B6: 2017 | C6: 0.13116584 | D6: 0.1388395
B7: 2018 | C7: 0.14723549 | D7: 0.1549729
B8: 2019 | C8: 0.14152448 | D8: 0.1491797
B9: 2020 | C9: 0.14392774 | D9: 0.1517913
B10: 2021 | C10: 0.18158369 | D10: 0.159114
B11: 2022 | C11: 0.15964795 | D11: 0.1628748
B13: Change | C13: =C11-C4 -> 0.04950601 | D13: =D11-D4 -> 0.0450181
C17: =C4*$F$4 -> 11.014194 | D17: =D4*$F$4 -> 11.78567
C18: =C5*$F$4 -> 12.733503 | D18: =D5*$F$4 -> 13.52483
C19: =C6*$F$4 -> 13.116584 | D19: =D6*$F$4 -> 13.88395
C20: =C7*$F$4 -> 14.723549 | D20: =D7*$F$4 -> 15.49729
C21: =C8*$F$4 -> 14.152448 | D21: =D8*$F$4 -> 14.91797
C22: =C9*$F$4 -> 14.392774 | D22: =D9*$F$4 -> 15.17913
C23: =C10*$F$4 -> 18.158369 | D23: =D10*$F$4 -> 15.9114
C24: =C11*$F$4 -> 15.964795 | D24: =D11*$F$4 -> 16.28748
D47: .

Sheet Minnesota
B2: Total Contributions | F2: District Contributions | J2: State Contributions
B3: Year | C3: Unweighted | D3: Weighted | F3: Year | G3: Unweighted | H3: Weighted | J3: Year | K3: Unweighted | L3: Weighted
B4: 2015 | C4: 0.04728569 | D4: 0.0462485 | F4: 2015 | G4: 0.04264504 | H4: 0.0418113 | J4: 2015 | K4: 0.00412251 | L4: 0.0043997 | N4: 100
B5: 2016 | C5: 0.0459634 | D5: 0.0450734 | F5: 2016 | G5: 0.04226005 | H5: 0.0414554 | J5: 2016 | K5: 0.00317202 | L5: 0.0036052
B6: 2017 | C6: 0.04622287 | D6: 0.0452997 | F6: 2017 | G6: 0.04262279 | H6: 0.0417723 | J6: 2017 | K6: 0.00331033 | L6: 0.003512
B7: 2018 | C7: 0.04562357 | D7: 0.0450129 | F7: 2018 | G7: 0.0421604 | H7: 0.0415854 | J7: 2018 | K7: 0.00285842 | L7: 0.0034126
B8: 2019 | C8: 0.04654335 | D8: 0.0458013 | F8: 2019 | G8: 0.04319667 | H8: 0.0424754 | J8: 2019 | K8: 0.00294696 | L8: 0.0033114
B9: 2020 | C9: 0.04774899 | D9: 0.046899 | F9: 2020 | G9: 0.04448176 | H9: 0.0436396 | J9: 2020 | K9: 0.00283201 | L9: 0.0032454
B10: 2021 | C10: 0.04929569 | D10: 0.0477652 | F10: 2021 | G10: 0.04587973 | H10: 0.0444087 | J10: 2021 | K10: 0.00324592 | L10: 0.0033428
B11: 2022 | C11: 0.04936428 | D11: 0.0479932 | F11: 2022 | G11: 0.04634797 | H11: 0.0449556 | J11: 2022 | K11: 0.00295457 | L11: 0.0030044
B13: Change | C13: =C11-C4 -> 0.00207859 | D13: =D11-D4 -> 0.0017447 | F13: Change | G13: =G11-G4 -> 0.00370293 | H13: =H11-H4 -> 0.0031443 | J13: Change | K13: =K11-K4 -> -0.00116794 | L13: =L11-L4 -> -0.0013953
B15: Weights based on NCES variables TCURINST / E17 / E08 / E09 / V40
C17: =C4*$N$4 -> 4.728569 | D17: =D4*$N$4 -> 4.62485 | G17: =G4*$N$4 -> 4.264504 | H17: =H4*$N$4 -> 4.18113 | K17: =K4*$N$4 -> 0.412251 | L17: =L4*$N$4 -> 0.43997
C18: =C5*$N$4 -> 4.59634 | D18: =D5*$N$4 -> 4.50734 | G18: =G5*$N$4 -> 4.226005 | H18: =H5*$N$4 -> 4.14554 | K18: =K5*$N$4 -> 0.317202 | L18: =L5*$N$4 -> 0.36052
C19: =C6*$N$4 -> 4.622287 | D19: =D6*$N$4 -> 4.52997 | G19: =G6*$N$4 -> 4.262279 | H19: =H6*$N$4 -> 4.17723 | K19: =K6*$N$4 -> 0.331033 | L19: =L6*$N$4 -> 0.3512
C20: =C7*$N$4 -> 4.562357 | D20: =D7*$N$4 -> 4.50129 | G20: =G7*$N$4 -> 4.21604 | H20: =H7*$N$4 -> 4.15854 | K20: =K7*$N$4 -> 0.285842 | L20: =L7*$N$4 -> 0.34126
C21: =C8*$N$4 -> 4.654335 | D21: =D8*$N$4 -> 4.58013 | G21: =G8*$N$4 -> 4.319667 | H21: =H8*$N$4 -> 4.24754 | K21: =K8*$N$4 -> 0.294696 | L21: =L8*$N$4 -> 0.33114
C22: =C9*$N$4 -> 4.774899 | D22: =D9*$N$4 -> 4.6899 | G22: =G9*$N$4 -> 4.448176 | H22: =H9*$N$4 -> 4.36396 | K22: =K9*$N$4 -> 0.283201 | L22: =L9*$N$4 -> 0.32454
C23: =C10*$N$4 -> 4.929569 | D23: =D10*$N$4 -> 4.77652 | G23: =G10*$N$4 -> 4.587973 | H23: =H10*$N$4 -> 4.44087 | K23: =K10*$N$4 -> 0.324592 | L23: =L10*$N$4 -> 0.33428
C24: =C11*$N$4 -> 4.936428 | D24: =D11*$N$4 -> 4.79932 | G24: =G11*$N$4 -> 4.634797 | H24: =H11*$N$4 -> 4.49556 | K24: =K11*$N$4 -> 0.295457 | L24: =L11*$N$4 -> 0.30044

Sheet Missouri
B2: District Contributions
B3: Year | C3: Unweighted | D3: Weighted
B4: 2015 | C4: 0.10047946 | D4: 0.1028135 | F4: 100
B5: 2016 | C5: 0.10017886 | D5: 0.1026857
B6: 2017 | C6: 0.09966694 | D6: 0.1024313
B7: 2018 | C7: 0.09730414 | D7: 0.1006507
B8: 2019 | C8: 0.09851989 | D8: 0.1023585
B9: 2020 | C9: 0.09930367 | D9: 0.1030774
B10: 2021 | C10: 0.09816642 | D10: 0.1030309
B11: 2022 | C11: 0.09566376 | D11: 0.1011053
B13: Change | C13: =C11-C4 -> -0.0048157 | D13: =D11-D4 -> -0.0017082
C17: =C4*$F$4 -> 10.047946 | D17: =D4*$F$4 -> 10.28135
C18: =C5*$F$4 -> 10.017886 | D18: =D5*$F$4 -> 10.26857
C19: =C6*$F$4 -> 9.966694 | D19: =D6*$F$4 -> 10.24313
C20: =C7*$F$4 -> 9.730414 | D20: =D7*$F$4 -> 10.06507
C21: =C8*$F$4 -> 9.851989 | D21: =D8*$F$4 -> 10.23585
C22: =C9*$F$4 -> 9.930367 | D22: =D9*$F$4 -> 10.30774
C23: =C10*$F$4 -> 9.816642 | D23: =D10*$F$4 -> 10.30309
C24: =C11*$F$4 -> 9.566376 | D24: =D11*$F$4 -> 10.11053
D47: .

Sheet Nebraska
B2: Total Contributions | F2: State Contributions | J2: District Contributions
B3: Year | C3: Unweighted | D3: Weighted | F3: Year | G3: Unweighted | H3: Weighted | J3: Year | K3: Unweighted | L3: Weighted
B4: 2015 | C4: 0.05293791 | D4: 0.0561536 | F4: 2015 | G4: 0.00018958 | H4: 0.000809 | J4: 2015 | K4: 0.0527485 | L4: 0.0553481 | N4: 100
B5: 2016 | C5: 0.05435912 | D5: 0.0572609 | F5: 2016 | G5: 0.00019235 | H5: 0.0008087 | J5: 2016 | K5: 0.05416702 | L5: 0.0564556
B6: 2017 | C6: 0.05431354 | D6: 0.0572261 | F6: 2017 | G6: 0.00019197 | H6: 0.0008056 | J6: 2017 | K6: 0.0541218 | L6: 0.0564238
B7: 2018 | C7: 0.05582571 | D7: 0.05876 | F7: 2018 | G7: 0.00019682 | H7: 0.0008227 | J7: 2018 | K7: 0.05562913 | L7: 0.0579406
B8: 2019 | C8: 0.05535695 | D8: 0.0582983 | F8: 2019 | G8: 0.00019523 | H8: 0.0008135 | J8: 2019 | K8: 0.05516199 | L8: 0.057488
B9: 2020 | C9: 0.05566634 | D9: 0.0583243 | F9: 2020 | G9: 0.00019521 | H9: 0.0008126 | J9: 2020 | K9: 0.0554714 | L9: 0.0575148
B10: 2021 | C10: 0.05525155 | D10: 0.0576658 | F10: 2021 | G10: 0.00019365 | H10: 0.0008057 | J10: 2021 | K10: 0.05505831 | L10: 0.0568646
B11: 2022 | C11: 0.05403793 | D11: 0.0565204 | F11: 2022 | G11: 0.00019066 | H11: 0.0007913 | J11: 2022 | K11: 0.05384784 | L11: 0.0557349
B13: Change | C13: =C11-C4 -> 0.00110002 | D13: =D11-D4 -> 0.0003668 | F13: Change | G13: =G11-G4 -> 1.08e-06 | H13: =H11-H4 -> -1.77e-05 | J13: Change | K13: =K11-K4 -> 0.00109934 | L13: =L11-L4 -> 0.0003868
C17: =C4*$N$4 -> 5.293791 | D17: =D4*$N$4 -> 5.61536 | G17: =G4*$N$4 -> 0.018958 | H17: =H4*$N$4 -> 0.0809 | K17: =K4*$N$4 -> 5.27485 | L17: =L4*$N$4 -> 5.53481
C18: =C5*$N$4 -> 5.435912 | D18: =D5*$N$4 -> 5.72609 | G18: =G5*$N$4 -> 0.019235 | H18: =H5*$N$4 -> 0.08087 | K18: =K5*$N$4 -> 5.416702 | L18: =L5*$N$4 -> 5.64556
C19: =C6*$N$4 -> 5.431354 | D19: =D6*$N$4 -> 5.72261 | G19: =G6*$N$4 -> 0.019197 | H19: =H6*$N$4 -> 0.08056 | K19: =K6*$N$4 -> 5.41218 | L19: =L6*$N$4 -> 5.64238
C20: =C7*$N$4 -> 5.582571 | D20: =D7*$N$4 -> 5.876 | G20: =G7*$N$4 -> 0.019682 | H20: =H7*$N$4 -> 0.08227 | K20: =K7*$N$4 -> 5.562913 | L20: =L7*$N$4 -> 5.79406
C21: =C8*$N$4 -> 5.535695 | D21: =D8*$N$4 -> 5.82983 | G21: =G8*$N$4 -> 0.019523 | H21: =H8*$N$4 -> 0.08135 | K21: =K8*$N$4 -> 5.516199 | L21: =L8*$N$4 -> 5.7488
C22: =C9*$N$4 -> 5.566634 | D22: =D9*$N$4 -> 5.83243 | G22: =G9*$N$4 -> 0.019521 | H22: =H9*$N$4 -> 0.08126 | K22: =K9*$N$4 -> 5.54714 | L22: =L9*$N$4 -> 5.75148
C23: =C10*$N$4 -> 5.525155 | D23: =D10*$N$4 -> 5.76658 | G23: =G10*$N$4 -> 0.019365 | H23: =H10*$N$4 -> 0.08057 | K23: =K10*$N$4 -> 5.505831 | L23: =L10*$N$4 -> 5.68646
C24: =C11*$N$4 -> 5.403793 | D24: =D11*$N$4 -> 5.65204 | G24: =G11*$N$4 -> 0.019066 | H24: =H11*$N$4 -> 0.07913 | K24: =K11*$N$4 -> 5.384784 | L24: =L11*$N$4 -> 5.57349
G45: .

Sheet North Dakota
B2: Total Contributions | F2: State Contributions | J2: District Contributions
B3: Year | C3: Unweighted | D3: Weighted | F3: Year | G3: Unweighted | H3: Weighted | J3: Year | K3: Unweighted | L3: Weighted
B4: 2015 | C4: 0.08677356 | D4: 0.0762194 | F4: 2015 | G4: 0.00192021 | H4: 0.0016851 | J4: 2015 | K4: 0.08485715 | L4: 0.0745344 | N4: 100
B5: 2016 | C5: 0.08932875 | D5: 0.0782673 | F5: 2016 | G5: 0.00291837 | H5: 0.0023999 | J5: 2016 | K5: 0.08640415 | L5: 0.075697
B6: 2017 | C6: 0.08971274 | D6: 0.0778396 | F6: 2017 | G6: 0.00280484 | H6: 0.0022861 | J6: 2017 | K6: 0.08690071 | L6: 0.0753962
B7: 2018 | C7: 0.088921 | D7: 0.0769979 | F7: 2018 | G7: 0.00236658 | H7: 0.0020026 | J7: 2018 | K7: 0.0865506 | L7: 0.0748618
B8: 2019 | C8: 0.08819005 | D8: 0.0762852 | F8: 2019 | G8: 0.00200264 | H8: 0.0017444 | J8: 2019 | K8: 0.08618442 | L8: 0.0744072
B9: 2020 | C9: 0.08786616 | D9: 0.076091 | F9: 2020 | G9: 0.00214926 | H9: 0.0018505 | J9: 2020 | K9: 0.08571399 | L9: 0.0741152
B10: 2021 | C10: 0.08761234 | D10: 0.0757765 | F10: 2021 | G10: 0.00232519 | H10: 0.0019488 | J10: 2021 | K10: 0.08527805 | L10: 0.0736485
B11: 2022 | C11: 0.08416038 | D11: 0.0738544 | F11: 2022 | G11: 0.00168644 | H11: 0.0015372 | J11: 2022 | K11: 0.08246561 | L11: 0.0721196
B13: Change | C13: =C11-C4 -> -0.00261318 | D13: =D11-D4 -> -0.002365 | F13: Change | G13: =G11-G4 -> -0.00023377 | H13: =H11-H4 -> -0.0001479 | J13: Change | K13: =K11-K4 -> -0.00239154 | L13: =L11-L4 -> -0.0024148
C17: =C4*$N$4 -> 8.677356 | D17: =D4*$N$4 -> 7.62194 | G17: =G4*$N$4 -> 0.192021 | H17: =H4*$N$4 -> 0.16851 | K17: =K4*$N$4 -> 8.485715 | L17: =L4*$N$4 -> 7.45344
C18: =C5*$N$4 -> 8.932875 | D18: =D5*$N$4 -> 7.82673 | G18: =G5*$N$4 -> 0.291837 | H18: =H5*$N$4 -> 0.23999 | K18: =K5*$N$4 -> 8.640415 | L18: =L5*$N$4 -> 7.5697
C19: =C6*$N$4 -> 8.971274 | D19: =D6*$N$4 -> 7.78396 | G19: =G6*$N$4 -> 0.280484 | H19: =H6*$N$4 -> 0.22861 | K19: =K6*$N$4 -> 8.690071 | L19: =L6*$N$4 -> 7.53962
C20: =C7*$N$4 -> 8.8921 | D20: =D7*$N$4 -> 7.69979 | G20: =G7*$N$4 -> 0.236658 | H20: =H7*$N$4 -> 0.20026 | K20: =K7*$N$4 -> 8.65506 | L20: =L7*$N$4 -> 7.48618
C21: =C8*$N$4 -> 8.819005 | D21: =D8*$N$4 -> 7.62852 | G21: =G8*$N$4 -> 0.200264 | H21: =H8*$N$4 -> 0.17444 | K21: =K8*$N$4 -> 8.618442 | L21: =L8*$N$4 -> 7.44072
C22: =C9*$N$4 -> 8.786616 | D22: =D9*$N$4 -> 7.6091 | G22: =G9*$N$4 -> 0.214926 | H22: =H9*$N$4 -> 0.18505 | K22: =K9*$N$4 -> 8.571399 | L22: =L9*$N$4 -> 7.41152
C23: =C10*$N$4 -> 8.761234 | D23: =D10*$N$4 -> 7.57765 | G23: =G10*$N$4 -> 0.232519 | H23: =H10*$N$4 -> 0.19488 | K23: =K10*$N$4 -> 8.527805 | L23: =L10*$N$4 -> 7.36485
C24: =C11*$N$4 -> 8.416038 | D24: =D11*$N$4 -> 7.38544 | G24: =G11*$N$4 -> 0.168644 | H24: =H11*$N$4 -> 0.15372 | K24: =K11*$N$4 -> 8.246561 | L24: =L11*$N$4 -> 7.21196

Sheet Ohio
B2: District Contributions
B3: Year | C3: Unweighted | D3: Weighted
B4: 2015 | C4: 0.0751146 | D4: 0.0796096 | F4: 100
B5: 2016 | C5: 0.0749063 | D5: 0.0774957
B6: 2017 | C6: 0.07276015 | D6: 0.0776013
B7: 2018 | C7: 0.0729271 | D7: 0.078068
B8: 2019 | C8: 0.0725302 | D8: 0.0778446
B9: 2020 | C9: 0.07747382 | D9: 0.0781347
B10: 2021 | C10: 0.0722673 | D10: 0.0776412
B11: 2022 | C11: 0.0705254 | D11: 0.0766208
B13: Change | C13: =C11-C4 -> -0.0045892 | D13: =D11-D4 -> -0.0029888
C17: =C4*$F$4 -> 7.51146 | D17: =D4*$F$4 -> 7.96096
C18: =C5*$F$4 -> 7.49063 | D18: =D5*$F$4 -> 7.74957
C19: =C6*$F$4 -> 7.276015 | D19: =D6*$F$4 -> 7.76013
C20: =C7*$F$4 -> 7.29271 | D20: =D7*$F$4 -> 7.8068
C21: =C8*$F$4 -> 7.25302 | D21: =D8*$F$4 -> 7.78446
C22: =C9*$F$4 -> 7.747382 | D22: =D9*$F$4 -> 7.81347
C23: =C10*$F$4 -> 7.22673 | D23: =D10*$F$4 -> 7.76412
C24: =C11*$F$4 -> 7.05254 | D24: =D11*$F$4 -> 7.66208
D47: .

Sheet South Dakota
B2: Total Contributions | F2: State Contributions | J2: District Contributions
B3: Year | C3: Unweighted | D3: Weighted | F3: Year | G3: Unweighted | H3: Weighted | J3: Year | K3: Unweighted | L3: Weighted
B4: 2015 | C4: 0.0515743 | D4: 0.0536974 | F4: 2015 | G4: 0.01880254 | H4: 0.0194819 | J4: 2015 | K4: 0.03275887 | L4: 0.0342713 | N4: 100
B5: 2016 | C5: 0.05133974 | D5: 0.0535083 | F5: 2016 | G5: 0.01873476 | H5: 0.019436 | J5: 2016 | K5: 0.0325915 | L5: 0.0341258
B6: 2017 | C6: 0.05028154 | D6: 0.0527633 | F6: 2017 | G6: 0.01769379 | H6: 0.0185371 | J6: 2017 | K6: 0.03258019 | L6: 0.0342758
B7: 2018 | C7: 0.05021667 | D7: 0.052688 | F7: 2018 | G7: 0.01726842 | H7: 0.0181377 | J7: 2018 | K7: 0.03294251 | L7: 0.0346479
B8: 2019 | C8: 0.05034222 | D8: 0.0526952 | F8: 2019 | G8: 0.01719292 | H8: 0.0180393 | J8: 2019 | K8: 0.0331442 | L8: 0.0347525
B9: 2020 | C9: 0.0506752 | D9: 0.0534482 | F9: 2020 | G9: 0.01724625 | H9: 0.0182411 | J9: 2020 | K9: 0.03342115 | L9: 0.0353015
B10: 2021 | C10: 0.04966089 | D10: 0.0520436 | F10: 2021 | G10: 0.01665207 | H10: 0.0175382 | J10: 2021 | K10: 0.03300516 | L10: 0.0345952
B11: 2022 | C11: 0.04864232 | D11: 0.0513816 | F11: 2022 | G11: 0.01645479 | H11: 0.0174015 | J11: 2022 | K11: 0.03218238 | L11: 0.0340227
B13: Change | C13: =C11-C4 -> -0.00293198 | D13: =D11-D4 -> -0.0023158 | F13: Change | G13: =G11-G4 -> -0.00234775 | H13: =H11-H4 -> -0.0020804 | J13: Change | K13: =K11-K4 -> -0.00057649 | L13: =L11-L4 -> -0.0002486
C17: =C4*$N$4 -> 5.15743 | D17: =D4*$N$4 -> 5.36974 | G17: =G4*$N$4 -> 1.880254 | H17: =H4*$N$4 -> 1.94819 | K17: =K4*$N$4 -> 3.275887 | L17: =L4*$N$4 -> 3.42713
C18: =C5*$N$4 -> 5.133974 | D18: =D5*$N$4 -> 5.35083 | G18: =G5*$N$4 -> 1.873476 | H18: =H5*$N$4 -> 1.9436 | K18: =K5*$N$4 -> 3.25915 | L18: =L5*$N$4 -> 3.41258
C19: =C6*$N$4 -> 5.028154 | D19: =D6*$N$4 -> 5.27633 | G19: =G6*$N$4 -> 1.769379 | H19: =H6*$N$4 -> 1.85371 | K19: =K6*$N$4 -> 3.258019 | L19: =L6*$N$4 -> 3.42758
C20: =C7*$N$4 -> 5.021667 | D20: =D7*$N$4 -> 5.2688 | G20: =G7*$N$4 -> 1.726842 | H20: =H7*$N$4 -> 1.81377 | K20: =K7*$N$4 -> 3.294251 | L20: =L7*$N$4 -> 3.46479
C21: =C8*$N$4 -> 5.034222 | D21: =D8*$N$4 -> 5.26952 | G21: =G8*$N$4 -> 1.719292 | H21: =H8*$N$4 -> 1.80393 | K21: =K8*$N$4 -> 3.31442 | L21: =L8*$N$4 -> 3.47525
C22: =C9*$N$4 -> 5.06752 | D22: =D9*$N$4 -> 5.34482 | G22: =G9*$N$4 -> 1.724625 | H22: =H9*$N$4 -> 1.82411 | K22: =K9*$N$4 -> 3.342115 | L22: =L9*$N$4 -> 3.53015
C23: =C10*$N$4 -> 4.966089 | D23: =D10*$N$4 -> 5.20436 | G23: =G10*$N$4 -> 1.665207 | H23: =H10*$N$4 -> 1.75382 | K23: =K10*$N$4 -> 3.300516 | L23: =L10*$N$4 -> 3.45952
C24: =C11*$N$4 -> 4.864232 | D24: =D11*$N$4 -> 5.13816 | G24: =G11*$N$4 -> 1.645479 | H24: =H11*$N$4 -> 1.74015 | K24: =K11*$N$4 -> 3.218238 | L24: =L11*$N$4 -> 3.40227
C44: .

Sheet Wisconsin
B2: District Contributions
B3: Year | C3: Unweighted | D3: Weighted
B4: 2015 | C4: 0.03394837 | D4: 0.0352124 | F4: 100
B5: 2016 | C5: 0.03442225 | D5: 0.0355415
B6: 2017 | C6: 0.03387922 | D6: 0.0347522
B7: 2018 | C7: 0.03357828 | D7: 0.0344452
B8: 2019 | C8: 0.03349467 | D8: 0.0343312
B9: 2020 | C9: 0.0340934 | D9: 0.0348242
B10: 2021 | C10: 0.03392871 | D10: 0.0346243
B11: 2022 | C11: 0.03280834 | D11: 0.03375
B13: Change | C13: =C11-C4 -> -0.00114003 | D13: =D11-D4 -> -0.0014624
C17: =C4*$F$4 -> 3.394837 | D17: =D4*$F$4 -> 3.52124
C18: =C5*$F$4 -> 3.442225 | D18: =D5*$F$4 -> 3.55415
C19: =C6*$F$4 -> 3.387922 | D19: =D6*$F$4 -> 3.47522
C20: =C7*$F$4 -> 3.357828 | D20: =D7*$F$4 -> 3.44452
C21: =C8*$F$4 -> 3.349467 | D21: =D8*$F$4 -> 3.43312
C22: =C9*$F$4 -> 3.40934 | D22: =D9*$F$4 -> 3.48242
C23: =C10*$F$4 -> 3.392871 | D23: =D10*$F$4 -> 3.46243
C24: =C11*$F$4 -> 3.280834 | D24: =D11*$F$4 -> 3.375
D47: .

Sheet Southeast -->

Sheet Alabama
B2: District Contributions
B3: Year | C3: Unweighted | D3: Weighted
B4: 2015 | C4: 0.06315704 | D4: 0.0635381 | F4: 100
B5: 2016 | C5: 0.06357529 | D5: 0.0637948
B6: 2017 | C6: 0.06429573 | D6: 0.0645808
B7: 2018 | C7: 0.06452507 | D7: 0.0648684
B8: 2019 | C8: 0.06820341 | D8: 0.0689258
B9: 2020 | C9: 0.06613347 | D9: 0.0668065
B10: 2021 | C10: 0.0657284 | D10: 0.0662333
B11: 2022 | C11: 0.06286546 | D11: 0.0636966
B13: Change | C13: =C11-C4 -> -0.00029158 | D13: =D11-D4 -> 0.0001585
C15: =C11-C4 -> -0.00029158 | D15: =D11-D4 -> 0.0001585
C17: =C4*$F$4 -> 6.315704 | D17: =D4*$F$4 -> 6.35381
C18: =C5*$F$4 -> 6.357529 | D18: =D5*$F$4 -> 6.37948
C19: =C6*$F$4 -> 6.429573 | D19: =D6*$F$4 -> 6.45808
C20: =C7*$F$4 -> 6.452507 | D20: =D7*$F$4 -> 6.48684
C21: =C8*$F$4 -> 6.820341 | D21: =D8*$F$4 -> 6.89258
C22: =C9*$F$4 -> 6.613347 | D22: =D9*$F$4 -> 6.68065
C23: =C10*$F$4 -> 6.57284 | D23: =D10*$F$4 -> 6.62333
C24: =C11*$F$4 -> 6.286546 | D24: =D11*$F$4 -> 6.36966

Sheet Arkansas
B2: District Contributions
B3: Year | C3: Unweighted | D3: Weighted
B4: 2015 | C4: 0.08889512 | D4: 0.0914742 | F4: 100
B5: 2016 | C5: 0.0881832 | D5: 0.0907629
B6: 2017 | C6: 0.08842632 | D6: 0.0904645
B7: 2018 | C7: 0.08862008 | D7: 0.0906972
B8: 2019 | C8: 0.08835793 | D8: 0.0904611
B9: 2020 | C9: 0.09190867 | D9: 0.093801
B10: 2021 | C10: 0.09205051 | D10: 0.0938673
B11: 2022 | C11: 0.09043497 | D11: 0.0924078
B13: Change | C13: =C11-C4 -> 0.00153985 | D13: =D11-D4 -> 0.0009336
C15: =C11-C4 -> 0.00153985 | D15: =D11-D4 -> 0.0009336
C17: =C4*$F$4 -> 8.889512 | D17: =D4*$F$4 -> 9.14742
C18: =C5*$F$4 -> 8.81832 | D18: =D5*$F$4 -> 9.07629
C19: =C6*$F$4 -> 8.842632 | D19: =D6*$F$4 -> 9.04645
C20: =C7*$F$4 -> 8.862008 | D20: =D7*$F$4 -> 9.06972
C21: =C8*$F$4 -> 8.835793 | D21: =D8*$F$4 -> 9.04611
C22: =C9*$F$4 -> 9.190867 | D22: =D9*$F$4 -> 9.3801
C23: =C10*$F$4 -> 9.205051 | D23: =D10*$F$4 -> 9.38673
C24: =C11*$F$4 -> 9.043497 | D24: =D11*$F$4 -> 9.24078

Sheet DC
B2: District Contributions
B3: Year | C3: Unweighted | D3: Weighted
B4: 2015 | C4: 0.05456519 | D4: 0.0545652 | F4: 100
B5: 2016 | C5: 0.06052263 | D5: 0.0605226
B6: 2017 | C6: 0.07322934 | D6: 0.0732293
B7: 2018 | C7: 0.07365099 | D7: 0.073651
B8: 2019 | C8: 0.06604423 | D8: 0.0660442
B9: 2020 | C9: 0.06736147 | D9: 0.0673615
B10: 2021 | C10: 0.07732438 | D10: 0.0773244
B11: 2022 | C11: 0.07581788 | D11: 0.0758179
B13: Change | C13: =C11-C4 -> 0.02125269 | D13: =D11-D4 -> 0.0212527
C15: =C11-C4 -> 0.02125269 | D15: =D11-D4 -> 0.0212527
C17: =C4*$F$4 -> 5.456519 | D17: =D4*$F$4 -> 5.45652
C18: =C5*$F$4 -> 6.052263 | D18: =D5*$F$4 -> 6.05226
C19: =C6*$F$4 -> 7.322934 | D19: =D6*$F$4 -> 7.32293
C20: =C7*$F$4 -> 7.365099 | D20: =D7*$F$4 -> 7.3651
C21: =C8*$F$4 -> 6.604423 | D21: =D8*$F$4 -> 6.60442
C22: =C9*$F$4 -> 6.736147 | D22: =D9*$F$4 -> 6.73615
C23: =C10*$F$4 -> 7.732438 | D23: =D10*$F$4 -> 7.73244
C24: =C11*$F$4 -> 7.581788 | D24: =D11*$F$4 -> 7.58179

Sheet Florida
B2: District Contributions
B3: Year | C3: Unweighted | D3: Weighted
B4: 2015 | C4: 0.03510013 | D4: 0.033827 | F4: 100
B5: 2016 | C5: 0.03221428 | D5: 0.0308566
B6: 2017 | C6: 0.03314811 | D6: 0.0319722
B7: 2018 | C7: 0.03488457 | D7: 0.0336022
B8: 2019 | C8: 0.03567385 | D8: 0.0346618
B9: 2020 | C9: 0.03695376 | D9: 0.0360541
B10: 2021 | C10: 0.04490636 | D10: 0.0431536
B11: 2022 | C11: 0.04650193 | D11: 0.0441357
B13: Change | C13: =C11-C4 -> 0.0114018 | D13: =D11-D4 -> 0.0103087
C15: =C11-C4 -> 0.0114018 | D15: =D11-D4 -> 0.0103087
C17: =C4*$F$4 -> 3.510013 | D17: =D4*$F$4 -> 3.3827
C18: =C5*$F$4 -> 3.221428 | D18: =D5*$F$4 -> 3.08566
C19: =C6*$F$4 -> 3.314811 | D19: =D6*$F$4 -> 3.19722
C20: =C7*$F$4 -> 3.488457 | D20: =D7*$F$4 -> 3.36022
C21: =C8*$F$4 -> 3.567385 | D21: =D8*$F$4 -> 3.46618
C22: =C9*$F$4 -> 3.695376 | D22: =D9*$F$4 -> 3.60541
C23: =C10*$F$4 -> 4.490636 | D23: =D10*$F$4 -> 4.31536
C24: =C11*$F$4 -> 4.650193 | D24: =D11*$F$4 -> 4.41357

Sheet Georgia
B2: Total Contributions | F2: State Contributions | J2: District Contributions
B3: Year | C3: Unweighted | D3: Weighted | F3: Year | G3: Unweighted | H3: Weighted | J3: Year | K3: Unweighted | L3: Weighted
B4: 2015 | C4: 0.07351306 | D4: 0.0747609 | F4: 2015 | G4: 0.00075267 | H4: 0.0004755 | J4: 2015 | K4: 0.07294242 | L4: 0.0742939 | N4: 100
B5: 2016 | C5: 0.07799944 | D5: 0.0808749 | F5: 2016 | G5: 0.00086058 | H5: 0.0005155 | J5: 2016 | K5: 0.07736427 | L5: 0.0803678
B6: 2017 | C6: 0.07693979 | D6: 0.0798613 | F6: 2017 | G6: 0.0006653 | H6: 0.0003794 | J6: 2017 | K6: 0.07643646 | L6: 0.0794838
B7: 2018 | C7: 0.09068497 | D7: 0.0912274 | F7: 2018 | G7: 0.00057822 | H7: 0.0002684 | J7: 2018 | K7: 0.09023458 | L7: 0.0909634
B8: 2019 | C8: 0.10882997 | D8: 0.1094022 | F8: 2019 | G8: 0.0007196 | H8: 0.0003248 | J8: 2019 | K8: 0.10828119 | L8: 0.1090505
B9: 2020 | C9: 0.11139381 | D9: 0.1110172 | F9: 2020 | G9: 0.00075445 | H9: 0.0003304 | J9: 2020 | K9: 0.11080108 | L9: 0.1106385
B10: 2021 | C10: 0.0992534 | D10: 0.1018419 | F10: 2021 | G10: 0.00068548 | H10: 0.0002937 | J10: 2021 | K10: 0.09872329 | L10: 0.1015202
B11: 2022 | C11: 0.09684463 | D11: 0.0991486 | F11: 2022 | G11: 0.00067832 | H11: 0.0002867 | J11: 2022 | K11: 0.0963272 | L11: 0.0988433
B13: Change | C13: =C11-C4 -> 0.02333157 | D13: =D11-D4 -> 0.0243877 | F13: Change | G13: =G11-G4 -> -7.435e-05 | H13: =H11-H4 -> -0.0001888 | J13: Change | K13: =K11-K4 -> 0.02338478 | L13: =L11-L4 -> 0.0245494
C17: =C4*$N$4 -> 7.351306 | D17: =D4*$N$4 -> 7.47609 | G17: =G4*$N$4 -> 0.075267 | H17: =H4*$N$4 -> 0.04755 | K17: =K4*$N$4 -> 7.294242 | L17: =L4*$N$4 -> 7.42939
C18: =C5*$N$4 -> 7.799944 | D18: =D5*$N$4 -> 8.08749 | G18: =G5*$N$4 -> 0.086058 | H18: =H5*$N$4 -> 0.05155 | K18: =K5*$N$4 -> 7.736427 | L18: =L5*$N$4 -> 8.03678
C19: =C6*$N$4 -> 7.693979 | D19: =D6*$N$4 -> 7.98613 | G19: =G6*$N$4 -> 0.06653 | H19: =H6*$N$4 -> 0.03794 | K19: =K6*$N$4 -> 7.643646 | L19: =L6*$N$4 -> 7.94838
C20: =C7*$N$4 -> 9.068497 | D20: =D7*$N$4 -> 9.12274 | G20: =G7*$N$4 -> 0.057822 | H20: =H7*$N$4 -> 0.02684 | K20: =K7*$N$4 -> 9.023458 | L20: =L7*$N$4 -> 9.09634
C21: =C8*$N$4 -> 10.882997 | D21: =D8*$N$4 -> 10.94022 | G21: =G8*$N$4 -> 0.07196 | H21: =H8*$N$4 -> 0.03248 | K21: =K8*$N$4 -> 10.828119 | L21: =L8*$N$4 -> 10.90505
C22: =C9*$N$4 -> 11.139381 | D22: =D9*$N$4 -> 11.10172 | G22: =G9*$N$4 -> 0.075445 | H22: =H9*$N$4 -> 0.03304 | K22: =K9*$N$4 -> 11.080108 | L22: =L9*$N$4 -> 11.06385
C23: =C10*$N$4 -> 9.92534 | D23: =D10*$N$4 -> 10.18419 | G23: =G10*$N$4 -> 0.068548 | H23: =H10*$N$4 -> 0.02937 | K23: =K10*$N$4 -> 9.872329 | L23: =L10*$N$4 -> 10.15202
C24: =C11*$N$4 -> 9.684463 | D24: =D11*$N$4 -> 9.91486 | G24: =G11*$N$4 -> 0.067832 | H24: =H11*$N$4 -> 0.02867 | K24: =K11*$N$4 -> 9.63272 | L24: =L11*$N$4 -> 9.88433

Sheet Kentucky
B2: State Contributions
B3: Year | C3: Unweighted | D3: Weighted
B4: 2015 | C4: 0.07283846 | D4: 0.0807319 | F4: 100
B5: 2016 | C5: 0.07182352 | D5: 0.0796521
B6: 2017 | C6: 0.13659243 | D6: 0.1425479
B7: 2018 | C7: 0.12343083 | D7: 0.1306192
B8: 2019 | C8: 0.13058971 | D8: 0.1373529
B9: 2020 | C9: 0.12622493 | D9: 0.1333899
B10: 2021 | C10: 0.12468728 | D10: 0.1326839
B11: 2022 | C11: 0.17063665 | D11: 0.1743614
B13: Change | C13: =C11-C4 -> 0.09779819 | D13: =D11-D4 -> 0.0936295
C17: =C4*$F$4 -> 7.283846 | D17: =D4*$F$4 -> 8.07319
C18: =C5*$F$4 -> 7.182352 | D18: =D5*$F$4 -> 7.96521
C19: =C6*$F$4 -> 13.659243 | D19: =D6*$F$4 -> 14.25479
C20: =C7*$F$4 -> 12.343083 | D20: =D7*$F$4 -> 13.06192
C21: =C8*$F$4 -> 13.058971 | D21: =D8*$F$4 -> 13.73529
C22: =C9*$F$4 -> 12.622493 | D22: =D9*$F$4 -> 13.33899
C23: =C10*$F$4 -> 12.468728 | D23: =D10*$F$4 -> 13.26839
C24: =C11*$F$4 -> 17.063665 | D24: =D11*$F$4 -> 17.43614

Sheet Louisiana
B2: Total Contributions | F2: State Contributions | J2: District Contributions
B3: Year | C3: Unweighted | D3: Weighted | F3: Year | G3: Unweighted | H3: Weighted | J3: Year | K3: Unweighted | L3: Weighted
B4: 2015 | C4: 0.14936118 | D4: 0.151938 | F4: 2015 | G4: 0.00445606 | H4: 0.0045396 | J4: 2015 | K4: 0.14489875 | L4: 0.1473645 | N4: 100
B5: 2016 | C5: 0.14242312 | D5: 0.1446668 | F5: 2016 | G5: 0.00454781 | H5: 0.0046195 | J5: 2016 | K5: 0.13787531 | L5: 0.1400474
B6: 2017 | C6: 0.13569374 | D6: 0.1388264 | F6: 2017 | G6: 0.00453033 | H6: 0.0046349 | J6: 2017 | K6: 0.13116342 | L6: 0.1341915
B7: 2018 | C7: 0.14240843 | D7: 0.1463218 | F7: 2018 | G7: 0.00453884 | H7: 0.0046718 | J7: 2018 | K7: 0.13786797 | L7: 0.1416406
B8: 2019 | C8: 0.13914293 | D8: 0.1431544 | F8: 2019 | G8: 0.00451913 | H8: 0.0046535 | J8: 2019 | K8: 0.13462245 | L8: 0.1384934
B9: 2020 | C9: 0.13802801 | D9: 0.1427432 | F9: 2020 | G9: 0.0047035 | H9: 0.0048581 | J9: 2020 | K9: 0.13332407 | L9: 0.1378825
B10: 2021 | C10: 0.13163944 | D10: 0.1364186 | F10: 2021 | G10: 0.00442742 | H10: 0.0045862 | J10: 2021 | K10: 0.12721154 | L10: 0.1318299
B11: 2022 | C11: 0.12819894 | D11: 0.1324079 | F11: 2022 | G11: 0.00442005 | H11: 0.0045561 | J11: 2022 | K11: 0.12377828 | L11: 0.1278486
B13: Change | C13: =C11-C4 -> -0.02116224 | D13: =D11-D4 -> -0.0195301 | F13: Change | G13: =G11-G4 -> -3.601e-05 | H13: =H11-H4 -> 1.65e-05 | J13: Change | K13: =K11-K4 -> -0.02112047 | L13: =L11-L4 -> -0.0195159
C17: =C4*$N$4 -> 14.936118 | D17: =D4*$N$4 -> 15.1938 | G17: =G4*$N$4 -> 0.445606 | H17: =H4*$N$4 -> 0.45396 | K17: =K4*$N$4 -> 14.489875 | L17: =L4*$N$4 -> 14.73645
C18: =C5*$N$4 -> 14.242312 | D18: =D5*$N$4 -> 14.46668 | G18: =G5*$N$4 -> 0.454781 | H18: =H5*$N$4 -> 0.46195 | K18: =K5*$N$4 -> 13.787531 | L18: =L5*$N$4 -> 14.00474
C19: =C6*$N$4 -> 13.569374 | D19: =D6*$N$4 -> 13.88264 | G19: =G6*$N$4 -> 0.453033 | H19: =H6*$N$4 -> 0.46349 | K19: =K6*$N$4 -> 13.116342 | L19: =L6*$N$4 -> 13.41915
C20: =C7*$N$4 -> 14.240843 | D20: =D7*$N$4 -> 14.63218 | G20: =G7*$N$4 -> 0.453884 | H20: =H7*$N$4 -> 0.46718 | K20: =K7*$N$4 -> 13.786797 | L20: =L7*$N$4 -> 14.16406
C21: =C8*$N$4 -> 13.914293 | D21: =D8*$N$4 -> 14.31544 | G21: =G8*$N$4 -> 0.451913 | H21: =H8*$N$4 -> 0.46535 | K21: =K8*$N$4 -> 13.462245 | L21: =L8*$N$4 -> 13.84934
C22: =C9*$N$4 -> 13.802801 | D22: =D9*$N$4 -> 14.27432 | G22: =G9*$N$4 -> 0.47035 | H22: =H9*$N$4 -> 0.48581 | K22: =K9*$N$4 -> 13.332407 | L22: =L9*$N$4 -> 13.78825
C23: =C10*$N$4 -> 13.163944 | D23: =D10*$N$4 -> 13.64186 | G23: =G10*$N$4 -> 0.442742 | H23: =H10*$N$4 -> 0.45862 | K23: =K10*$N$4 -> 12.721154 | L23: =L10*$N$4 -> 13.18299
