Workbook

Sheet GASB 67 Data
A1: CENSUSID | B1: Year of Reporting | C1: plan_idx | D1: unique_id | E1: Month of Reporting | F1: State Name | G1: Plan Name | H1: Plan Abbreviation | I1: Available? | J1: Service Cost | K1: Interest Cost | L1: Changes in Benefit Terms | M1: Expected vs Actual Experience | N1: Assumption Changes | O1: Benefit Payments (including Refunds if combined) | P1: Refunds | Q1: Net Change in TPL | R1: TPL boy | S1: TPL eoy | T1: Employer Contribs | U1: Non-Employer/State Contributions | V1: Member Contributions | W1: Net Inv Inc | X1: Transfers Among Employers | Y1: Administrative Expenses | Z1: Other (+ = improves) | AA1: Net Change in FNP | AB1: FNP boy | AC1: FNP eoy | AD1: NPL eoy | AE1: NPL boy | AF1: Net Changes to NPL | AG1: Covered Employee Payroll | AH1: State Contributions as a % of Payroll | AI1: Check | AJ1: Imputed Flag | AK1: Discount Rate Previous Year | AL1: Discount Rate (current year) | AM1: Expected Rate of Return | AN1: Prior Year's Expected Rate of Return | AO1: State/Local Plan | AP1: Discount - Expected | AQ1: Muni Rate | AR1: Exhaustion | AS1: NPL - 1% | AT1: NPL + 1% | AU1: Exact Source | AV1: Link to Exact Source | BB1: Stated Funding Ratio | BD1: Duration Calculation | BF1: Dur(-) | BG1: Dur(+) | BH1: Dur | BI1: Conv/2 | BJ1: Rounded Duration | BK1: Treas Zero boy | BL1: Adj boy | BM1: TPL * boy | BN1: NPL * boy | BP1: Treas Zero eoy | BQ1: Adj eoy | BR1: TPL * eoy | BS1: NPL * eoy | BU1: SC Duration | BV1: SC Adj | BW1: Service Cost * | BX1: Interest Cost * | BY1: Interest on NPL* | BZ1: SC Orig + IC Orig | CA1: SC + IntNPLAdj | CC1: TPL* | CE1: FNP / TPL | CF1: FNP / TPL*
A2: 5000000015801 | B2: 2015 | C2: 39 | D2: plan134_y2021 | E2: 6 | F2: California | G2: California State Teachers Retirement System | H2: CalSTRS | I2: TRUE | J2: 5556000 | K2: 18556000 | M2: -1312000 | O2: 12565000 | Q2: 10235000 | R2: 248911000 | S2: 259146000 | T2: 2678000 | U2: 1426000 | V2: 2510000 | W2: 7612000 | Y2: 145000 | Z2: 10000 | AA2: 1510000 | AB2: 190312000 | AC2: 191822000 | AD2: 67324000 | AE2: 58599000 | AF2: 8725000 | AG2: 32026000 | AH2: 0.083619559 | AI2: TRUE | AJ2: =AA2-Q2+AF2 -> 0 | AK2: 0.076 | AL2: 0.076 | AM2: 0.076 | AN2: 0.075 | AO2: 1 | AP2: 0 | AS2: 101654000 | AT2: 38793000 | AU2: p75 of CAFR | AV2: https://www.calstrs.com/sites/main/files/file-attachments/cafr2015.pdf | BB2: =AC2/S2 -> 0.74020822 | BD2: =AS2-AD2 -> 34330000 | BE2: =AT2-AD2 -> -28531000 | BF2: =BD2/S2*100 -> 13.247359 | BG2: =BE2/S2*100 -> -11.009624 | BH2: =(BD2-BE2)/(2*S2)*100 -> 12.128491 | BI2: =(BD2+BE2)/(2*S2*(0.01^2)) -> 111.88674 | BJ2: =ROUND(BH2,0) -> 12 | BK2: =IF($BJ2<=30,IF($B2=2015,VLOOKUP($BJ2,'Treasury Yields'!$C$5:$N$34,$E2,FALSE)/100,IF($B2=2016,VLOOKUP($BJ2,'Treasury Yields'!$C$40:$N$69,$E2,FALSE)/100,IF($B2=2017,VLOOKUP($BJ2,'Treasury Yields'!$C$75:$N$104,$E2,FALSE)/100,IF($B2=2018,VLOOKUP($BJ2,'Treasury Yields'!$C$110:$N$139,$E2,FALSE)/100,IF($B2=2019,VLOOKUP($BJ2,'Treasury Yields'!$C$145:$N$174,$E2,FALSE)/100,IF($B2=2020,VLOOKUP($BJ2,'Treasury Yields'!$C$180:$N$209,$E2,FALSE)/100,IF($B2=2021,VLOOKUP($BJ2,'Treasury Yields'!$C$215:$N$244,$E2,FALSE)/100,IF($B2=2022,VLOOKUP($BJ2,'Treasury Yields'!$C$250:$N$279,$E2,FALSE)/100)))))))),0) -> 0.029186 | BL2: =1+BH2*(AL2-BK2)+(AL2-BK2)^2 -> 1.5699747 | BM2: =BL2*R2 -> 3.9078398e+08 | BN2: =BM2-AB2 -> 2.0047198e+08 | BP2: =IF($BJ2<=30,IF($B2=2015,VLOOKUP($BJ2,'Treasury Yields'!$C$40:$N$69,$E2,FALSE)/100,IF($B2=2016,VLOOKUP($BJ2,'Treasury Yields'!$C$75:$N$104,$E2,FALSE)/100,IF($B2=2017,VLOOKUP($BJ2,'Treasury Yields'!$C$110:$N$139,$E2,FALSE)/100,IF($B2=2018,VLOOKUP($BJ2,'Treasury Yields'!$C$145:$N$174,$E2,FALSE)/100,IF($B2=2019,VLOOKUP($BJ2,'Treasury Yields'!$C$180:$N$209,$E2,FALSE)/100,IF($B2=2020,VLOOKUP($BJ2,'Treasury Yields'!$C$215:$N$244,$E2,FALSE)/100,IF($B2=2021,VLOOKUP($BJ2,'Treasury Yields'!$C$250:$N$279,$E2,FALSE)/100,IF($B2=2022,VLOOKUP($BJ2,'Treasury Yields'!$C$285:$N$314,$E2,FALSE)/100)))))))),0) -> 0.027046 | BQ2: =1+BH2*(AN2-BP2)+(AN2-BP2)^2 -> 1.5839093 | BR2: =BQ2*S2 -> 4.1046375e+08 | BS2: =BR2-AC2 -> 2.1864175e+08 | BT2: 3 | BU2: =IF(BJ2="","",ROUND(BJ2+$BT$2,0)) -> 15 | BV2: =1+(BH2+BU2)*(AN2-BK2)+(AN2-BK2)^2*BI2 -> 2.4777063 | BW2: =BV2*J2 -> 13766136 | BX2: =(BM2+BW2-O2)*BK2 -> 11440478 | BY2: =BK2*(BN2+BW2-O2) -> 5886031.7 | BZ2: =SUM(J2:K2) -> 24112000 | CA2: =SUM(BW2+BY2) -> 19652168 | CC2: =BR2 -> 4.1046375e+08 | CD2: =F2 -> California | CE2: =BB2 -> 0.74020822 | CF2: =AC2/CC2 -> 0.46732994
A3: 5000000015801 | B3: 2016 | C3: 39 | D3: plan134_y2021 | E3: 6 | F3: California | G3: California State Teachers Retirement System | H3: CalSTRS | I3: TRUE | J3: 5874000 | K3: 19332000 | M3: -1209000 | O3: 13149000 | Q3: 10848000 | R3: 259146000 | S3: 269994000 | T3: 3391000 | U3: 1940000 | V3: 2957000 | W3: 2305000 | Y3: 1800000 | Z3: 15000 | AA3: -2709000 | AB3: 191822000 | AC3: 189113000 | AD3: 80881000 | AE3: 67324000 | AF3: 13557000 | AG3: 31910000 | AH3: 0.10626763 | AI3: TRUE | AK3: 0.076 | AL3: 0.076 | AM3: 0.076 | AN3: 0.076 | AO3: 1 | AP3: 0 | AS3: 116406000 | AT3: 51376000 | AU3: p80 of CAFR | AV3: https://www.calstrs.com/sites/main/files/file-attachments/cafr2016.pdf | BB3: =AC3/S3 -> 0.70043408 | BD3: =AS3-AD3 -> 35525000 | BE3: =AT3-AD3 -> -29505000 | BF3: =BD3/S3*100 -> 13.1577 | BG3: =BE3/S3*100 -> -10.928021 | BH3: =(BD3-BE3)/(2*S3)*100 -> 12.04286 | BI3: =(BD3+BE3)/(2*S3*(0.01^2)) -> 111.48396 | BJ3: =ROUND(BH3,0) -> 12 | BK3: =IF($BJ3<=30,IF($B3=2015,VLOOKUP($BJ3,'Treasury Yields'!$C$5:$N$34,$E3,FALSE)/100,IF($B3=2016,VLOOKUP($BJ3,'Treasury Yields'!$C$40:$N$69,$E3,FALSE)/100,IF($B3=2017,VLOOKUP($BJ3,'Treasury Yields'!$C$75:$N$104,$E3,FALSE)/100,IF($B3=2018,VLOOKUP($BJ3,'Treasury Yields'!$C$110:$N$139,$E3,FALSE)/100,IF($B3=2019,VLOOKUP($BJ3,'Treasury Yields'!$C$145:$N$174,$E3,FALSE)/100,IF($B3=2020,VLOOKUP($BJ3,'Treasury Yields'!$C$180:$N$209,$E3,FALSE)/100,IF($B3=2021,VLOOKUP($BJ3,'Treasury Yields'!$C$215:$N$244,$E3,FALSE)/100,IF($B3=2022,VLOOKUP($BJ3,'Treasury Yields'!$C$250:$N$279,$E3,FALSE)/100)))))))),0) -> 0.027046 | BL3: =1+BH3*(AL3-BK3)+(AL3-BK3)^2 -> 1.5919427 | BM3: =BL3*R3 -> 4.1254558e+08 | BN3: =BM3-AB3 -> 2.2072358e+08 | BP3: =IF($BJ3<=30,IF($B3=2015,VLOOKUP($BJ3,'Treasury Yields'!$C$40:$N$69,$E3,FALSE)/100,IF($B3=2016,VLOOKUP($BJ3,'Treasury Yields'!$C$75:$N$104,$E3,FALSE)/100,IF($B3=2017,VLOOKUP($BJ3,'Treasury Yields'!$C$110:$N$139,$E3,FALSE)/100,IF($B3=2018,VLOOKUP($BJ3,'Treasury Yields'!$C$145:$N$174,$E3,FALSE)/100,IF($B3=2019,VLOOKUP($BJ3,'Treasury Yields'!$C$180:$N$209,$E3,FALSE)/100,IF($B3=2020,VLOOKUP($BJ3,'Treasury Yields'!$C$215:$N$244,$E3,FALSE)/100,IF($B3=2021,VLOOKUP($BJ3,'Treasury Yields'!$C$250:$N$279,$E3,FALSE)/100,IF($B3=2022,VLOOKUP($BJ3,'Treasury Yields'!$C$285:$N$314,$E3,FALSE)/100)))))))),0) -> 0.017546 | BQ3: =1+BH3*(AN3-BP3)+(AN3-BP3)^2 -> 1.7073702 | BR3: =BQ3*S3 -> 4.6097972e+08 | BS3: =BR3-AC3 -> 2.7186672e+08 | BU3: =IF(BJ3="","",ROUND(BJ3+$BT$2,0)) -> 15 | BV3: =1+(BH3+BU3)*(AN3-BK3)+(AN3-BK3)^2*BI3 -> 2.5910268 | BW3: =BV3*J3 -> 15219692 | BX3: =(BM3+BW3-O3)*BK3 -> 11213712 | BY3: =BK3*(BN3+BW3-O3) -> 6025693.8 | BZ3: =SUM(J3:K3) -> 25206000 | CA3: =SUM(BW3+BY3) -> 21245385 | CC3: =BR3 -> 4.6097972e+08 | CD3: =F3 -> California | CE3: =BB3 -> 0.70043408 | CF3: =AC3/CC3 -> 0.41024148
A4: 5000000015801 | B4: 2017 | C4: 39 | D4: plan134_y2021 | E4: 6 | F4: California | G4: California State Teachers Retirement System | H4: CalSTRS | I4: TRUE | J4: 6064000 | K4: 20227000 | M4: 399000 | N4: 19988000 | O4: 13903000 | Q4: 32775000 | R4: 269994000 | S4: 302769000 | T4: 4173000 | U4: 2478000 | V4: 3441000 | W4: 25165000 | Y4: 182000 | Z4: 10000 | AA4: 21176000 | AB4: 189113000 | AC4: 210289000 | AD4: 92480000 | AE4: 80881000 | AF4: 11599000 | AG4: 34126000 | AH4: 0.12228213 | AI4: TRUE | AK4: 0.076 | AL4: 0.071 | AM4: 0.071 | AN4: 0.076 | AO4: 1 | AP4: 0 | AS4: 135790000 | AT4: 57331000 | AU4: p88 of CAFR | AV4: https://www.calstrs.com/sites/main/files/file-attachments/cafr2017.pdf | BB4: =AC4/S4 -> 0.69455261 | BD4: =AS4-AD4 -> 43310000 | BE4: =AT4-AD4 -> -35149000 | BF4: =BD4/S4*100 -> 14.304635 | BG4: =BE4/S4*100 -> -11.609181 | BH4: =(BD4-BE4)/(2*S4)*100 -> 12.956908 | BI4: =(BD4+BE4)/(2*S4*(0.01^2)) -> 134.77271 | BJ4: =ROUND(BH4,0) -> 13 | BK4: =IF($BJ4<=30,IF($B4=2015,VLOOKUP($BJ4,'Treasury Yields'!$C$5:$N$34,$E4,FALSE)/100,IF($B4=2016,VLOOKUP($BJ4,'Treasury Yields'!$C$40:$N$69,$E4,FALSE)/100,IF($B4=2017,VLOOKUP($BJ4,'Treasury Yields'!$C$75:$N$104,$E4,FALSE)/100,IF($B4=2018,VLOOKUP($BJ4,'Treasury Yields'!$C$110:$N$139,$E4,FALSE)/100,IF($B4=2019,VLOOKUP($BJ4,'Treasury Yields'!$C$145:$N$174,$E4,FALSE)/100,IF($B4=2020,VLOOKUP($BJ4,'Treasury Yields'!$C$180:$N$209,$E4,FALSE)/100,IF($B4=2021,VLOOKUP($BJ4,'Treasury Yields'!$C$215:$N$244,$E4,FALSE)/100,IF($B4=2022,VLOOKUP($BJ4,'Treasury Yields'!$C$250:$N$279,$E4,FALSE)/100)))))))),0) -> 0.018144 | BL4: =1+BH4*(AL4-BK4)+(AL4-BK4)^2 -> 1.6876441 | BM4: =BL4*R4 -> 4.5565377e+08 | BN4: =BM4-AB4 -> 2.6654077e+08 | BP4: =IF($BJ4<=30,IF($B4=2015,VLOOKUP($BJ4,'Treasury Yields'!$C$40:$N$69,$E4,FALSE)/100,IF($B4=2016,VLOOKUP($BJ4,'Treasury Yields'!$C$75:$N$104,$E4,FALSE)/100,IF($B4=2017,VLOOKUP($BJ4,'Treasury Yields'!$C$110:$N$139,$E4,FALSE)/100,IF($B4=2018,VLOOKUP($BJ4,'Treasury Yields'!$C$145:$N$174,$E4,FALSE)/100,IF($B4=2019,VLOOKUP($BJ4,'Treasury Yields'!$C$180:$N$209,$E4,FALSE)/100,IF($B4=2020,VLOOKUP($BJ4,'Treasury Yields'!$C$215:$N$244,$E4,FALSE)/100,IF($B4=2021,VLOOKUP($BJ4,'Treasury Yields'!$C$250:$N$279,$E4,FALSE)/100,IF($B4=2022,VLOOKUP($BJ4,'Treasury Yields'!$C$285:$N$314,$E4,FALSE)/100)))))))),0) -> 0.0258664 | BQ4: =1+BH4*(AN4-BP4)+(AN4-BP4)^2 -> 1.6520898 | BR4: =BQ4*S4 -> 5.0020158e+08 | BS4: =BR4-AC4 -> 2.8991258e+08 | BU4: =IF(BJ4="","",ROUND(BJ4+$BT$2,0)) -> 16 | BV4: =1+(BH4+BU4)*(AN4-BK4)+(AN4-BK4)^2*BI4 -> 3.1264578 | BW4: =BV4*J4 -> 18958840 | BX4: =(BM4+BW4-O4)*BK4 -> 8359115.2 | BY4: =BK4*(BN4+BW4-O4) -> 4927849 | BZ4: =SUM(J4:K4) -> 26291000 | CA4: =SUM(BW4+BY4) -> 23886689 | CC4: =BR4 -> 5.0020158e+08 | CD4: =F4 -> California | CE4: =BB4 -> 0.69455261 | CF4: =AC4/CC4 -> 0.42040851
A5: 5000000015801 | B5: 2018 | C5: 39 | D5: plan134_y2021 | E5: 6 | F5: California | G5: California State Teachers Retirement System | H5: CalSTRS | I5: TRUE | J5: 7142000 | K5: 21496000 | M5: -94000 | N5: 0 | O5: 14537000 | Q5: 14007000 | R5: 302769000 | S5: 316776000 | T5: 4867000 | U5: 2797000 | V5: 3496000 | W5: 18674000 | Y5: 216000 | Z5: 2000 | AA5: 15091000 | AB5: 210289000 | AC5: 224869000 | AD5: 91907000 | AE5: 92480000 | AF5: -573000 | AG5: 34753000 | AH5: 0.14004546 | AI5: TRUE | AK5: 0.071 | AL5: 0.071 | AM5: 0.071 | AN5: 0.071 | AO5: 1 | AP5: 0 | AS5: 134633000 | AT5: 56483000 | AU5: p94 of CAFR | AV5: https://www.calstrs.com/sites/main/files/file-attachments/cafr2018.pdf | BB5: =AC5/S5 -> 0.70986754 | BD5: =AS5-AD5 -> 42726000 | BE5: =AT5-AD5 -> -35424000 | BF5: =BD5/S5*100 -> 13.487764 | BG5: =BE5/S5*100 -> -11.182665 | BH5: =(BD5-BE5)/(2*S5)*100 -> 12.335215 | BI5: =(BD5+BE5)/(2*S5*(0.01^2)) -> 115.25494 | BJ5: =ROUND(BH5,0) -> 12 | BK5: =IF($BJ5<=30,IF($B5=2015,VLOOKUP($BJ5,'Treasury Yields'!$C$5:$N$34,$E5,FALSE)/100,IF($B5=2016,VLOOKUP($BJ5,'Treasury Yields'!$C$40:$N$69,$E5,FALSE)/100,IF($B5=2017,VLOOKUP($BJ5,'Treasury Yields'!$C$75:$N$104,$E5,FALSE)/100,IF($B5=2018,VLOOKUP($BJ5,'Treasury Yields'!$C$110:$N$139,$E5,FALSE)/100,IF($B5=2019,VLOOKUP($BJ5,'Treasury Yields'!$C$145:$N$174,$E5,FALSE)/100,IF($B5=2020,VLOOKUP($BJ5,'Treasury Yields'!$C$180:$N$209,$E5,FALSE)/100,IF($B5=2021,VLOOKUP($BJ5,'Treasury Yields'!$C$215:$N$244,$E5,FALSE)/100,IF($B5=2022,VLOOKUP($BJ5,'Treasury Yields'!$C$250:$N$279,$E5,FALSE)/100)))))))),0) -> 0.0254676 | BL5: =1+BH5*(AL5-BK5)+(AL5-BK5)^2 -> 1.5637251 | BM5: =BL5*R5 -> 4.7344749e+08 | BN5: =BM5-AB5 -> 2.6315849e+08 | BP5: =IF($BJ5<=30,IF($B5=2015,VLOOKUP($BJ5,'Treasury Yields'!$C$40:$N$69,$E5,FALSE)/100,IF($B5=2016,VLOOKUP($BJ5,'Treasury Yields'!$C$75:$N$104,$E5,FALSE)/100,IF($B5=2017,VLOOKUP($BJ5,'Treasury Yields'!$C$110:$N$139,$E5,FALSE)/100,IF($B5=2018,VLOOKUP($BJ5,'Treasury Yields'!$C$145:$N$174,$E5,FALSE)/100,IF($B5=2019,VLOOKUP($BJ5,'Treasury Yields'!$C$180:$N$209,$E5,FALSE)/100,IF($B5=2020,VLOOKUP($BJ5,'Treasury Yields'!$C$215:$N$244,$E5,FALSE)/100,IF($B5=2021,VLOOKUP($BJ5,'Treasury Yields'!$C$250:$N$279,$E5,FALSE)/100,IF($B5=2022,VLOOKUP($BJ5,'Treasury Yields'!$C$285:$N$314,$E5,FALSE)/100)))))))),0) -> 0.028906473 | BQ5: =1+BH5*(AN5-BP5)+(AN5-BP5)^2 -> 1.5210046 | BR5: =BQ5*S5 -> 4.8181774e+08 | BS5: =BR5-AC5 -> 2.5694874e+08 | BU5: =IF(BJ5="","",ROUND(BJ5+$BT$2,0)) -> 15 | BV5: =1+(BH5+BU5)*(AN5-BK5)+(AN5-BK5)^2*BI5 -> 2.4835844 | BW5: =BV5*J5 -> 17737760 | BX5: =(BM5+BW5-O5)*BK5 -> 12139087 | BY5: =BK5*(BN5+BW5-O5) -> 6783531 | BZ5: =SUM(J5:K5) -> 28638000 | CA5: =SUM(BW5+BY5) -> 24521291 | CC5: =BR5 -> 4.8181774e+08 | CD5: =F5 -> California | CE5: =BB5 -> 0.70986754 | CF5: =AC5/CC5 -> 0.46670967
A6: 5000000015801 | B6: 2019 | C6: 39 | D6: plan134_y2021 | E6: 6 | F6: California | G6: California State Teachers Retirement System | H6: CalSTRS | I6: TRUE | J6: 7055000 | K6: 22458000 | L6: 32000 | M6: -1847000 | N6: 0 | O6: 15296000 | Q6: 12402000 | R6: 316776000 | S6: 329178000 | T6: 5644000 | U6: 5335000 | V6: 3648000 | W6: 14898000 | Y6: 254000 | Z6: 4000 | AA6: 13993000 | AB6: 224869000 | AC6: 238862000 | AD6: 90316000 | AE6: 91907000 | AF6: -1591000 | AG6: 35805000 | AH6: 0.15763162 | AI6: TRUE | AK6: 0.071 | AL6: 0.071 | AM6: 0.071 | AN6: 0.071 | AO6: 1 | AP6: 0 | AS6: 134488000 | AT6: 53689000 | AU6: p86 of CAFR | AV6: https://www.calstrs.com/sites/main/files/file-attachments/cafr2019.pdf | BB6: =AC6/S6 -> 0.72563173 | BD6: =AS6-AD6 -> 44172000 | BE6: =AT6-AD6 -> -36627000 | BF6: =BD6/S6*100 -> 13.41888 | BG6: =BE6/S6*100 -> -11.126807 | BH6: =(BD6-BE6)/(2*S6)*100 -> 12.272843 | BI6: =(BD6+BE6)/(2*S6*(0.01^2)) -> 114.60365 | BJ6: =ROUND(BH6,0) -> 12 | BK6: =IF($BJ6<=30,IF($B6=2015,VLOOKUP($BJ6,'Treasury Yields'!$C$5:$N$34,$E6,FALSE)/100,IF($B6=2016,VLOOKUP($BJ6,'Treasury Yields'!$C$40:$N$69,$E6,FALSE)/100,IF($B6=2017,VLOOKUP($BJ6,'Treasury Yields'!$C$75:$N$104,$E6,FALSE)/100,IF($B6=2018,VLOOKUP($BJ6,'Treasury Yields'!$C$110:$N$139,$E6,FALSE)/100,IF($B6=2019,VLOOKUP($BJ6,'Treasury Yields'!$C$145:$N$174,$E6,FALSE)/100,IF($B6=2020,VLOOKUP($BJ6,'Treasury Yields'!$C$180:$N$209,$E6,FALSE)/100,IF($B6=2021,VLOOKUP($BJ6,'Treasury Yields'!$C$215:$N$244,$E6,FALSE)/100,IF($B6=2022,VLOOKUP($BJ6,'Treasury Yields'!$C$250:$N$279,$E6,FALSE)/100)))))))),0) -> 0.028906473 | BL6: =1+BH6*(AL6-BK6)+(AL6-BK6)^2 -> 1.5183791 | BM6: =BL6*R6 -> 4.8098607e+08 | BN6: =BM6-AB6 -> 2.5611707e+08 | BP6: =IF($BJ6<=30,IF($B6=2015,VLOOKUP($BJ6,'Treasury Yields'!$C$40:$N$69,$E6,FALSE)/100,IF($B6=2016,VLOOKUP($BJ6,'Treasury Yields'!$C$75:$N$104,$E6,FALSE)/100,IF($B6=2017,VLOOKUP($BJ6,'Treasury Yields'!$C$110:$N$139,$E6,FALSE)/100,IF($B6=2018,VLOOKUP($BJ6,'Treasury Yields'!$C$145:$N$174,$E6,FALSE)/100,IF($B6=2019,VLOOKUP($BJ6,'Treasury Yields'!$C$180:$N$209,$E6,FALSE)/100,IF($B6=2020,VLOOKUP($BJ6,'Treasury Yields'!$C$215:$N$244,$E6,FALSE)/100,IF($B6=2021,VLOOKUP($BJ6,'Treasury Yields'!$C$250:$N$279,$E6,FALSE)/100,IF($B6=2022,VLOOKUP($BJ6,'Treasury Yields'!$C$285:$N$314,$E6,FALSE)/100)))))))),0) -> 0.022184 | BQ6: =1+BH6*(AN6-BP6)+(AN6-BP6)^2 -> 1.6014941 | BR6: =BQ6*S6 -> 5.2717663e+08 | BS6: =BR6-AC6 -> 2.8831463e+08 | BU6: =IF(BJ6="","",ROUND(BJ6+$BT$2,0)) -> 15 | BV6: =1+(BH6+BU6)*(AN6-BK6)+(AN6-BK6)^2*BI6 -> 2.3510724 | BW6: =BV6*J6 -> 16586816 | BX6: =(BM6+BW6-O6)*BK6 -> 13940924 | BY6: =BK6*(BN6+BW6-O6) -> 7440753.9 | BZ6: =SUM(J6:K6) -> 29513000 | CA6: =SUM(BW6+BY6) -> 24027570 | CC6: =BR6 -> 5.2717663e+08 | CD6: =F6 -> California | CE6: =BB6 -> 0.72563173 | CF6: =AC6/CC6 -> 0.45309672
A7: 5000000015801 | B7: 2020 | C7: 39 | D7: plan134_y2021 | E7: 6 | F7: California | G7: California State Teachers Retirement System | H7: CalSTRS | I7: TRUE | J7: 7340000 | K7: 23334000 | M7: -963000 | N7: 1029000 | O7: 16025000 | Q7: 14715000 | R7: 329178000 | S7: 343893000 | T7: 6080000 | U7: 4447000 | V7: 3735000 | W7: 10103000 | Y7: 219000 | Z7: 5000 | AA7: 8122000 | AB7: 238862000 | AC7: 246984000 | AD7: 96909000 | AE7: 90316000 | AF7: 6593000 | AG7: 36668000 | AH7: 0.16581215 | AI7: TRUE | AK7: 0.071 | AL7: 0.071 | AM7: 0.071 | AN7: 0.071 | AO7: 1 | AP7: 0 | AS7: 146416000 | AT7: 56034000 | AU7: p83 of CAFR | AV7: https://www.calstrs.com/sites/main/files/file-attachments/cafr2020.pdf | BB7: =AC7/S7 -> 0.71820014 | BD7: =AS7-AD7 -> 49507000 | BE7: =AT7-AD7 -> -40875000 | BF7: =BD7/S7*100 -> 14.396048 | BG7: =BE7/S7*100 -> -11.885965 | BH7: =(BD7-BE7)/(2*S7)*100 -> 13.141006 | BI7: =(BD7+BE7)/(2*S7*(0.01^2)) -> 125.50415 | BJ7: =ROUND(BH7,0) -> 13 | BK7: =IF($BJ7<=30,IF($B7=2015,VLOOKUP($BJ7,'Treasury Yields'!$C$5:$N$34,$E7,FALSE)/100,IF($B7=2016,VLOOKUP($BJ7,'Treasury Yields'!$C$40:$N$69,$E7,FALSE)/100,IF($B7=2017,VLOOKUP($BJ7,'Treasury Yields'!$C$75:$N$104,$E7,FALSE)/100,IF($B7=2018,VLOOKUP($BJ7,'Treasury Yields'!$C$110:$N$139,$E7,FALSE)/100,IF($B7=2019,VLOOKUP($BJ7,'Treasury Yields'!$C$145:$N$174,$E7,FALSE)/100,IF($B7=2020,VLOOKUP($BJ7,'Treasury Yields'!$C$180:$N$209,$E7,FALSE)/100,IF($B7=2021,VLOOKUP($BJ7,'Treasury Yields'!$C$215:$N$244,$E7,FALSE)/100,IF($B7=2022,VLOOKUP($BJ7,'Treasury Yields'!$C$250:$N$279,$E7,FALSE)/100)))))))),0) -> 0.022646 | BL7: =1+BH7*(AL7-BK7)+(AL7-BK7)^2 -> 1.6377583 | BM7: =BL7*R7 -> 5.3911401e+08 | BN7: =BM7-AB7 -> 3.0025201e+08 | BP7: =IF($BJ7<=30,IF($B7=2015,VLOOKUP($BJ7,'Treasury Yields'!$C$40:$N$69,$E7,FALSE)/100,IF($B7=2016,VLOOKUP($BJ7,'Treasury Yields'!$C$75:$N$104,$E7,FALSE)/100,IF($B7=2017,VLOOKUP($BJ7,'Treasury Yields'!$C$110:$N$139,$E7,FALSE)/100,IF($B7=2018,VLOOKUP($BJ7,'Treasury Yields'!$C$145:$N$174,$E7,FALSE)/100,IF($B7=2019,VLOOKUP($BJ7,'Treasury Yields'!$C$180:$N$209,$E7,FALSE)/100,IF($B7=2020,VLOOKUP($BJ7,'Treasury Yields'!$C$215:$N$244,$E7,FALSE)/100,IF($B7=2021,VLOOKUP($BJ7,'Treasury Yields'!$C$250:$N$279,$E7,FALSE)/100,IF($B7=2022,VLOOKUP($BJ7,'Treasury Yields'!$C$285:$N$314,$E7,FALSE)/100)))))))),0) -> 0.012827818 | BQ7: =1+BH7*(AN7-BP7)+(AN7-BP7)^2 -> 1.767825 | BR7: =BQ7*S7 -> 6.0794264e+08 | BS7: =BR7-AC7 -> 3.6095864e+08 | BU7: =IF(BJ7="","",ROUND(BJ7+$BT$2,0)) -> 16 | BV7: =1+(BH7+BU7)*(AN7-BK7)+(AN7-BK7)^2*BI7 -> 2.7025266 | BW7: =BV7*J7 -> 19836546 | BX7: =(BM7+BW7-O7)*BK7 -> 12295092 | BY7: =BK7*(BN7+BW7-O7) -> 6885823.2 | BZ7: =SUM(J7:K7) -> 30674000 | CA7: =SUM(BW7+BY7) -> 26722369 | CC7: =BR7 -> 6.0794264e+08 | CD7: =F7 -> California | CE7: =BB7 -> 0.71820014 | CF7: =AC7/CC7 -> 0.40626201
A8: 5000000015801 | B8: 2021 | C8: 39 | D8: plan134_y2021 | E8: 6 | F8: California | G8: California State Teachers Retirement System | H8: CalSTRS | I8: TRUE | J8: 7612000 | K8: 24373000 | M8: -3369000 | O8: 16708000 | Q8: 11908000 | R8: 343893000 | S8: 355801000 | T8: 5758000 | U8: 3731000 | V8: 3743000 | W8: 67039000 | Y8: 252000 | Z8: 2000 | AA8: 63309000 | AB8: 246984000 | AC8: 310293000 | AD8: 45508000 | AE8: 96909000 | AF8: -51401000 | AG8: 36737000 | AI8: TRUE | AK8: 0.071 | AL8: 0.071 | AM8: 0.071 | AN8: 0.071 | AS8: 92638000 | AT8: 6391000 | BB8: =AC8/S8 -> 0.87209704 | BD8: =AS8-AD8 -> 47130000 | BE8: =AT8-AD8 -> -39117000 | BF8: =BD8/S8*100 -> 13.246169 | BG8: =BE8/S8*100 -> -10.994067 | BH8: =(BD8-BE8)/(2*S8)*100 -> 12.120118 | BI8: =(BD8+BE8)/(2*S8*(0.01^2)) -> 112.60508 | BJ8: =ROUND(BH8,0) -> 12 | BK8: =IF($BJ8<=30,IF($B8=2015,VLOOKUP($BJ8,'Treasury Yields'!$C$5:$N$34,$E8,FALSE)/100,IF($B8=2016,VLOOKUP($BJ8,'Treasury Yields'!$C$40:$N$69,$E8,FALSE)/100,IF($B8=2017,VLOOKUP($BJ8,'Treasury Yields'!$C$75:$N$104,$E8,FALSE)/100,IF($B8=2018,VLOOKUP($BJ8,'Treasury Yields'!$C$110:$N$139,$E8,FALSE)/100,IF($B8=2019,VLOOKUP($BJ8,'Treasury Yields'!$C$145:$N$174,$E8,FALSE)/100,IF($B8=2020,VLOOKUP($BJ8,'Treasury Yields'!$C$180:$N$209,$E8,FALSE)/100,IF($B8=2021,VLOOKUP($BJ8,'Treasury Yields'!$C$215:$N$244,$E8,FALSE)/100,IF($B8=2022,VLOOKUP($BJ8,'Treasury Yields'!$C$250:$N$279,$E8,FALSE)/100)))))))),0) -> 0.013689455 | BL8: =1+BH8*(AL8-BK8)+(AL8-BK8)^2 -> 1.6978951 | BM8: =BL8*R8 -> 5.8389422e+08 | BN8: =BM8-AB8 -> 3.3691022e+08 | BP8: =IF($BJ8<=30,IF($B8=2015,VLOOKUP($BJ8,'Treasury Yields'!$C$40:$N$69,$E8,FALSE)/100,IF($B8=2016,VLOOKUP($BJ8,'Treasury Yields'!$C$75:$N$104,$E8,FALSE)/100,IF($B8=2017,VLOOKUP($BJ8,'Treasury Yields'!$C$110:$N$139,$E8,FALSE)/100,IF($B8=2018,VLOOKUP($BJ8,'Treasury Yields'!$C$145:$N$174,$E8,FALSE)/100,IF($B8=2019,VLOOKUP($BJ8,'Treasury Yields'!$C$180:$N$209,$E8,FALSE)/100,IF($B8=2020,VLOOKUP($BJ8,'Treasury Yields'!$C$215:$N$244,$E8,FALSE)/100,IF($B8=2021,VLOOKUP($BJ8,'Treasury Yields'!$C$250:$N$279,$E8,FALSE)/100,IF($B8=2022,VLOOKUP($BJ8,'Treasury Yields'!$C$285:$N$314,$E8,FALSE)/100)))))))),0) -> 0.021085818 | BQ8: =1+BH8*(AN8-BP8)+(AN8-BP8)^2 -> 1.6074572 | BR8: =BQ8*S8 -> 5.7193487e+08 | BS8: =BR8-AC8 -> 2.6164187e+08 | BU8: =IF(BJ8="","",ROUND(BJ8+$BT$2,0)) -> 15 | BV8: =1+(BH8+BU8)*(AN8-BK8)+(AN8-BK8)^2*BI8 -> 2.92412 | BW8: =BV8*J8 -> 22258401 | BX8: =(BM8+BW8-O8)*BK8 -> 8069175.4 | BY8: =BK8*(BN8+BW8-O8) -> 4688099.2 | BZ8: =SUM(J8:K8) -> 31985000 | CA8: =SUM(BW8+BY8) -> 26946500 | CC8: =BR8 -> 5.7193487e+08 | CD8: =F8 -> California | CE8: =BB8 -> 0.87209704 | CF8: =AC8/CC8 -> 0.54253205
A9: 5000000015801 | B9: 2022 | C9: 39 | D9: plan134_y2021 | E9: 6 | F9: California | G9: California State Teachers Retirement System | H9: CalSTRS | I9: TRUE | J9: 7675000 | K9: 25196000 | L9: 70000 | M9: -1673000 | N9: 0 | O9: 17527000 | Q9: 13741000 | R9: 355801000 | S9: 369542000 | T9: 6521000 | U9: 4280000 | V9: 4068000 | W9: -7390000 | Y9: 191000 | Z9: 5000 | AA9: -10237000 | AB9: 310293000 | AC9: 300056000 | AD9: 69486000 | AE9: 45508000 | AF9: 23978000 | AG9: 40103000 | AI9: TRUE | AK9: 0.071 | AL9: 0.071 | AM9: 0.071 | AN9: 0.071 | AS9: 118013000 | AT9: 29194000 | AU9: p78 of CAFR | AV9: https://www.calstrs.com/files/621ec3ae1/ACFR2021-22.pdf | BB9: =AC9/S9 -> 0.81196725 | BD9: =AS9-AD9 -> 48527000 | BE9: =AT9-AD9 -> -40292000 | BF9: =BD9/S9*100 -> 13.13166 | BG9: =BE9/S9*100 -> -10.903226 | BH9: =(BD9-BE9)/(2*S9)*100 -> 12.017443 | BI9: =(BD9+BE9)/(2*S9*(0.01^2)) -> 111.42171 | BJ9: =ROUND(BH9,0) -> 12 | BK9: =IF($BJ9<=30,IF($B9=2015,VLOOKUP($BJ9,'Treasury Yields'!$C$5:$N$34,$E9,FALSE)/100,IF($B9=2016,VLOOKUP($BJ9,'Treasury Yields'!$C$40:$N$69,$E9,FALSE)/100,IF($B9=2017,VLOOKUP($BJ9,'Treasury Yields'!$C$75:$N$104,$E9,FALSE)/100,IF($B9=2018,VLOOKUP($BJ9,'Treasury Yields'!$C$110:$N$139,$E9,FALSE)/100,IF($B9=2019,VLOOKUP($BJ9,'Treasury Yields'!$C$145:$N$174,$E9,FALSE)/100,IF($B9=2020,VLOOKUP($BJ9,'Treasury Yields'!$C$180:$N$209,$E9,FALSE)/100,IF($B9=2021,VLOOKUP($BJ9,'Treasury Yields'!$C$215:$N$244,$E9,FALSE)/100,IF($B9=2022,VLOOKUP($BJ9,'Treasury Yields'!$C$250:$N$279,$E9,FALSE)/100)))))))),0) -> 0.021085818 | BL9: =1+BH9*(AL9-BK9)+(AL9-BK9)^2 -> 1.6023323 | BM9: =BL9*R9 -> 5.7011142e+08 | BN9: =BM9-AB9 -> 2.5981842e+08 | BP9: =IF($BJ9<=30,IF($B9=2015,VLOOKUP($BJ9,'Treasury Yields'!$C$40:$N$69,$E9,FALSE)/100,IF($B9=2016,VLOOKUP($BJ9,'Treasury Yields'!$C$75:$N$104,$E9,FALSE)/100,IF($B9=2017,VLOOKUP($BJ9,'Treasury Yields'!$C$110:$N$139,$E9,FALSE)/100,IF($B9=2018,VLOOKUP($BJ9,'Treasury Yields'!$C$145:$N$174,$E9,FALSE)/100,IF($B9=2019,VLOOKUP($BJ9,'Treasury Yields'!$C$180:$N$209,$E9,FALSE)/100,IF($B9=2020,VLOOKUP($BJ9,'Treasury Yields'!$C$215:$N$244,$E9,FALSE)/100,IF($B9=2021,VLOOKUP($BJ9,'Treasury Yields'!$C$250:$N$279,$E9,FALSE)/100,IF($B9=2022,VLOOKUP($BJ9,'Treasury Yields'!$C$285:$N$314,$E9,FALSE)/100)))))))),0) -> 0.032402273 | BQ9: =1+BH9*(AN9-BP9)+(AN9-BP9)^2 -> 1.4653358 | BR9: =BQ9*S9 -> 5.4150311e+08 | BS9: =BR9-AC9 -> 2.4144711e+08 | BU9: =IF(BJ9="","",ROUND(BJ9+$BT$2,0)) -> 15 | BV9: =1+(BH9+BU9)*(AN9-BK9)+(AN9-BK9)^2*BI9 -> 2.6261525 | BW9: =BV9*J9 -> 20155720 | BX9: =(BM9+BW9-O9)*BK9 -> 12076695 | BY9: =BK9*(BN9+BW9-O9) -> 5533912.8 | BZ9: =SUM(J9:K9) -> 32871000 | CA9: =SUM(BW9+BY9) -> 25689633 | CC9: =BR9 -> 5.4150311e+08 | CD9: =F9 -> California | CE9: =BB9 -> 0.81196725 | CF9: =AC9/CC9 -> 0.55411685
A10: 44000000011101 | B10: 2015 | C10: 569 | D10: plan314_y2021 | E10: 8 | F10: Texas | G10: Teachers Retirement System of Texas | H10: TRS | I10: TRUE | J10: 4225449 | K10: 12555646 | M10: -1588619 | N10: -1474724 | O10: 8935112 | P10: 391341 | Q10: 4391299 | R10: 159496076 | S10: 163887375 | T10: 1377973 | U10: 1591483 | V10: 2576024 | W10: -412759 | Y10: 35557 | Z10: -11248 | AA10: -4240537 | AB10: 132779243 | AC10: 128538706 | AD10: 35348669 | AE10: 26716833 | AF10: 8631836 | AG10: 38448124 | AH10: 0.035839798 | AI10: TRUE | AK10: 0.08 | AL10: 0.08 | AM10: 0.08 | AN10: 0.08 | AO10: 1 | AP10: 0 | AS10: 55384702 | AT10: 18659899 | BB10: =AC10/S10 -> 0.78431121 | BD10: =AS10-AD10 -> 20036033 | BE10: =AT10-AD10 -> -16688770 | BF10: =BD10/S10*100 -> 12.225489 | BG10: =BE10/S10*100 -> -10.183072 | BH10: =(BD10-BE10)/(2*S10)*100 -> 11.204281 | BI10: =(BD10+BE10)/(2*S10*(0.01^2)) -> 102.12082 | BJ10: =ROUND(BH10,0) -> 11 | BK10: =IF($BJ10<=30,IF($B10=2015,VLOOKUP($BJ10,'Treasury Yields'!$C$5:$N$34,$E10,FALSE)/100,IF($B10=2016,VLOOKUP($BJ10,'Treasury Yields'!$C$40:$N$69,$E10,FALSE)/100,IF($B10=2017,VLOOKUP($BJ10,'Treasury Yields'!$C$75:$N$104,$E10,FALSE)/100,IF($B10=2018,VLOOKUP($BJ10,'Treasury Yields'!$C$110:$N$139,$E10,FALSE)/100,IF($B10=2019,VLOOKUP($BJ10,'Treasury Yields'!$C$145:$N$174,$E10,FALSE)/100,IF($B10=2020,VLOOKUP($BJ10,'Treasury Yields'!$C$180:$N$209,$E10,FALSE)/100,IF($B10=2021,VLOOKUP($BJ10,'Treasury Yields'!$C$215:$N$244,$E10,FALSE)/100,IF($B10=2022,VLOOKUP($BJ10,'Treasury Yields'!$C$250:$N$279,$E10,FALSE)/100)))))))),0) -> 0.024838 | BL10: =1+BH10*(AL10-BK10)+(AL10-BK10)^2 -> 1.6210934 | BM10: =BL10*R10 -> 2.5855803e+08 | BN10: =BM10-AB10 -> 1.2577879e+08 | BP10: =IF($BJ10<=30,IF($B10=2015,VLOOKUP($BJ10,'Treasury Yields'!$C$40:$N$69,$E10,FALSE)/100,IF($B10=2016,VLOOKUP($BJ10,'Treasury Yields'!$C$75:$N$104,$E10,FALSE)/100,IF($B10=2017,VLOOKUP($BJ10,'Treasury Yields'!$C$110:$N$139,$E10,FALSE)/100,IF($B10=2018,VLOOKUP($BJ10,'Treasury Yields'!$C$145:$N$174,$E10,FALSE)/100,IF($B10=2019,VLOOKUP($BJ10,'Treasury Yields'!$C$180:$N$209,$E10,FALSE)/100,IF($B10=2020,VLOOKUP($BJ10,'Treasury Yields'!$C$215:$N$244,$E10,FALSE)/100,IF($B10=2021,VLOOKUP($BJ10,'Treasury Yields'!$C$250:$N$279,$E10,FALSE)/100,IF($B10=2022,VLOOKUP($BJ10,'Treasury Yields'!$C$285:$N$314,$E10,FALSE)/100)))))))),0) -> 0.024838 | BQ10: =1+BH10*(AN10-BP10)+(AN10-BP10)^2 -> 1.6210934 | BR10: =BQ10*S10 -> 2.6567674e+08 | BS10: =BR10-AC10 -> 1.3713803e+08 | BU10: =IF(BJ10="","",ROUND(BJ10+$BT$2,0)) -> 14 | BV10: =1+(BH10+BU10)*(AN10-BK10)+(AN10-BK10)^2*BI10 -> 2.7010565 | BW10: =BV10*J10 -> 11413176 | BX10: =(BM10+BW10-O10)*BK10 -> 6483614.6 | BY10: =BK10*(BN10+BW10-O10) -> 3185643.7 | BZ10: =SUM(J10:K10) -> 16781095 | CA10: =SUM(BW10+BY10) -> 14598820 | CC10: =BR10 -> 2.6567674e+08 | CD10: =F10 -> Texas | CE10: =BB10 -> 0.78431121 | CF10: =AC10/CC10 -> 0.48381619
A11: 44000000011101 | B11: 2016 | C11: 569 | D11: plan314_y2021 | E11: 8 | F11: Texas | G11: Teachers Retirement System of Texas | H11: TRS | I11: TRUE | J11: 4392077 | K11: 12896571 | M11: 373669 | O11: 9379123 | P11: 373419 | Q11: 7909775 | R11: 163887375 | S11: 171797150 | T11: 1483390 | U11: 1675631 | V11: 2943669 | W11: 9193281 | Y11: 44403 | Z11: -29095 | AA11: 5469931 | AB11: 128538706 | AC11: 134008637 | AD11: 37788513 | AE11: 35348669 | AF11: 2439844 | AG11: 40742826 | AH11: 0.036408618 | AI11: TRUE | AK11: 0.08 | AL11: 0.08 | AM11: 0.08 | AN11: 0.08 | AO11: 1 | AP11: 0 | AS11: 58483889 | AT11: 20234651 | AU11: p88 of CAFR | AV11: https://www.trs.texas.gov/TRS%20Documents/cafr_2016.pdf | BB11: =AC11/S11 -> 0.78003993 | BD11: =AS11-AD11 -> 20695376 | BE11: =AT11-AD11 -> -17553862 | BF11: =BD11/S11*100 -> 12.046402 | BG11: =BE11/S11*100 -> -10.217784 | BH11: =(BD11-BE11)/(2*S11)*100 -> 11.132093 | BI11: =(BD11+BE11)/(2*S11*(0.01^2)) -> 91.430911 | BJ11: =ROUND(BH11,0) -> 11 | BK11: =IF($BJ11<=30,IF($B11=2015,VLOOKUP($BJ11,'Treasury Yields'!$C$5:$N$34,$E11,FALSE)/100,IF($B11=2016,VLOOKUP($BJ11,'Treasury Yields'!$C$40:$N$69,$E11,FALSE)/100,IF($B11=2017,VLOOKUP($BJ11,'Treasury Yields'!$C$75:$N$104,$E11,FALSE)/100,IF($B11=2018,VLOOKUP($BJ11,'Treasury Yields'!$C$110:$N$139,$E11,FALSE)/100,IF($B11=2019,VLOOKUP($BJ11,'Treasury Yields'!$C$145:$N$174,$E11,FALSE)/100,IF($B11=2020,VLOOKUP($BJ11,'Treasury Yields'!$C$180:$N$209,$E11,FALSE)/100,IF($B11=2021,VLOOKUP($BJ11,'Treasury Yields'!$C$215:$N$244,$E11,FALSE)/100,IF($B11=2022,VLOOKUP($BJ11,'Treasury Yields'!$C$250:$N$279,$E11,FALSE)/100)))))))),0) -> 0.024838 | BL11: =1+BH11*(AL11-BK11)+(AL11-BK11)^2 -> 1.6171114 | BM11: =BL11*R11 -> 2.6502414e+08 | BN11: =BM11-AB11 -> 1.3648543e+08 | BP11: =IF($BJ11<=30,IF($B11=2015,VLOOKUP($BJ11,'Treasury Yields'!$C$40:$N$69,$E11,FALSE)/100,IF($B11=2016,VLOOKUP($BJ11,'Treasury Yields'!$C$75:$N$104,$E11,FALSE)/100,IF($B11=2017,VLOOKUP($BJ11,'Treasury Yields'!$C$110:$N$139,$E11,FALSE)/100,IF($B11=2018,VLOOKUP($BJ11,'Treasury Yields'!$C$145:$N$174,$E11,FALSE)/100,IF($B11=2019,VLOOKUP($BJ11,'Treasury Yields'!$C$180:$N$209,$E11,FALSE)/100,IF($B11=2020,VLOOKUP($BJ11,'Treasury Yields'!$C$215:$N$244,$E11,FALSE)/100,IF($B11=2021,VLOOKUP($BJ11,'Treasury Yields'!$C$250:$N$279,$E11,FALSE)/100,IF($B11=2022,VLOOKUP($BJ11,'Treasury Yields'!$C$285:$N$314,$E11,FALSE)/100)))))))),0) -> 0.017736 | BQ11: =1+BH11*(AN11-BP11)+(AN11-BP11)^2 -> 1.6970055 | BR11: =BQ11*S11 -> 2.915407e+08 | BS11: =BR11-AC11 -> 1.5753206e+08 | BU11: =IF(BJ11="","",ROUND(BJ11+$BT$2,0)) -> 14 | BV11: =1+(BH11+BU11)*(AN11-BK11)+(AN11-BK11)^2*BI11 -> 2.6645467 | BW11: =BV11*J11 -> 11702894 | BX11: =(BM11+BW11-O11)*BK11 -> 6640387.4 | BY11: =BK11*(BN11+BW11-O11) -> 3447743 | BZ11: =SUM(J11:K11) -> 17288648 | CA11: =SUM(BW11+BY11) -> 15150637 | CC11: =BR11 -> 2.915407e+08 | CD11: =F11 -> Texas | CE11: =BB11 -> 0.78003993 | CF11: =AC11/CC11 -> 0.4596567
A12: 44000000011101 | B12: 2017 | C12: 569 | D12: plan314_y2021 | E12: 8 | F12: Texas | G12: Teachers Retirement System of Texas | H12: TRS | I12: TRUE | J12: 4489046 | K12: 13515486 | M12: -969831 | N12: 700880 | O12: 9775775 | P12: 420421 | Q12: 7539385 | R12: 171797150 | S12: 179336535 | T12: 1588309 | U12: 1697963 | V12: 3242556 | W12: 17079807 | Y12: 44190 | Z12: -14964 | AA12: 13353285 | AB12: 134008637 | AC12: 147361922 | AD12: 31974613 | AE12: 37788513 | AF12: -5813900 | AG12: 42111120 | AH12: 0.037717092 | AI12: TRUE | AJ12: 1 | AK12: 0.08 | AL12: 0.08 | AM12: 0.08 | AN12: 0.08 | AO12: 1 | AP12: 0 | AS12: 53902880 | AT12: 13715772 | AU12: p94 of CAFR | AV12: https://www.trs.texas.gov/TRS%20Documents/cafr_2017.pdf | BB12: =AC12/S12 -> 0.82170608 | BD12: =AS12-AD12 -> 21928267 | BE12: =AT12-AD12 -> -18258841 | BF12: =BD12/S12*100 -> 12.22744 | BG12: =BE12/S12*100 -> -10.181328 | BH12: =(BD12-BE12)/(2*S12)*100 -> 11.204384 | BI12: =(BD12+BE12)/(2*S12*(0.01^2)) -> 102.30559 | BJ12: =ROUND(BH12,0) -> 11 | BK12: =IF($BJ12<=30,IF($B12=2015,VLOOKUP($BJ12,'Treasury Yields'!$C$5:$N$34,$E12,FALSE)/100,IF($B12=2016,VLOOKUP($BJ12,'Treasury Yields'!$C$40:$N$69,$E12,FALSE)/100,IF($B12=2017,VLOOKUP($BJ12,'Treasury Yields'!$C$75:$N$104,$E12,FALSE)/100,IF($B12=2018,VLOOKUP($BJ12,'Treasury Yields'!$C$110:$N$139,$E12,FALSE)/100,IF($B12=2019,VLOOKUP($BJ12,'Treasury Yields'!$C$145:$N$174,$E12,FALSE)/100,IF($B12=2020,VLOOKUP($BJ12,'Treasury Yields'!$C$180:$N$209,$E12,FALSE)/100,IF($B12=2021,VLOOKUP($BJ12,'Treasury Yields'!$C$215:$N$244,$E12,FALSE)/100,IF($B12=2022,VLOOKUP($BJ12,'Treasury Yields'!$C$250:$N$279,$E12,FALSE)/100)))))))),0) -> 0.017736 | BL12: =1+BH12*(AL12-BK12)+(AL12-BK12)^2 -> 1.7015066 | BM12: =BL12*R12 -> 2.9231398e+08 | BN12: =BM12-AB12 -> 1.5830534e+08 | BP12: =IF($BJ12<=30,IF($B12=2015,VLOOKUP($BJ12,'Treasury Yields'!$C$40:$N$69,$E12,FALSE)/100,IF($B12=2016,VLOOKUP($BJ12,'Treasury Yields'!$C$75:$N$104,$E12,FALSE)/100,IF($B12=2017,VLOOKUP($BJ12,'Treasury Yields'!$C$110:$N$139,$E12,FALSE)/100,IF($B12=2018,VLOOKUP($BJ12,'Treasury Yields'!$C$145:$N$174,$E12,FALSE)/100,IF($B12=2019,VLOOKUP($BJ12,'Treasury Yields'!$C$180:$N$209,$E12,FALSE)/100,IF($B12=2020,VLOOKUP($BJ12,'Treasury Yields'!$C$215:$N$244,$E12,FALSE)/100,IF($B12=2021,VLOOKUP($BJ12,'Treasury Yields'!$C$250:$N$279,$E12,FALSE)/100,IF($B12=2022,VLOOKUP($BJ12,'Treasury Yields'!$C$285:$N$314,$E12,FALSE)/100)))))))),0) -> 0.0229824 | BQ12: =1+BH12*(AN12-BP12)+(AN12-BP12)^2 -> 1.6420981 | BR12: =BQ12*S12 -> 2.9448818e+08 | BS12: =BR12-AC12 -> 1.4712626e+08 | BU12: =IF(BJ12="","",ROUND(BJ12+$BT$2,0)) -> 14 | BV12: =1+(BH12+BU12)*(AN12-BK12)+(AN12-BK12)^2*BI12 -> 2.9659447 | BW12: =BV12*J12 -> 13314262 | BX12: =(BM12+BW12-O12)*BK12 -> 5247239.3 | BY12: =BK12*(BN12+BW12-O12) -> 2870462.2 | BZ12: =SUM(J12:K12) -> 18004532 | CA12: =SUM(BW12+BY12) -> 16184724 | CC12: =BR12 -> 2.9448818e+08 | CD12: =F12 -> Texas | CE12: =BB12 -> 0.82170608 | CF12: =AC12/CC12 -> 0.50040012
A13: 44000000011101 | B13: 2018 | C13: 569 | D13: plan314_y2021 | E13: 8 | F13: Texas | G13: Teachers Retirement System of Texas | H13: TRS | I13: TRUE | J13: 4654171 | K13: 14109277 | M13: 0 | N13: 22106679 | O13: 10172997 | P13: 422336 | Q13: 30274794 | R13: 179336535 | S13: 209611329 | T13: 1671257 | U13: 1715785 | V13: 3360773 | W13: 11242814 | Y13: 64926 | Z13: -123390 | AA13: 7206980 | AB13: 147361922 | AC13: 154568902 | AD13: 55042427 | AE13: 31974613 | AF13: 23067814 | AG13: 43646405 | AH13: 0.038290828 | AI13: TRUE | AJ13: 1 | AK13: 0.08 | AL13: 0.06907 | AM13: 0.0725 | AN13: 0.08 | AO13: 1 | AP13: 0.00343 | AS13: 83072221 | AT13: 32350646 | AU13: p82 of CAFR | AV13: https://www.trs.texas.gov/TRS%20Documents/cafr_2018.pdf | BB13: =AC13/S13 -> 0.73740719 | BD13: =AS13-AD13 -> 28029794 | BE13: =AT13-AD13 -> -22691781 | BF13: =BD13/S13*100 -> 13.372271 | BG13: =BE13/S13*100 -> -10.825646 | BH13: =(BD13-BE13)/(2*S13)*100 -> 12.098958 | BI13: =(BD13+BE13)/(2*S13*(0.01^2)) -> 127.33121 | BJ13: =ROUND(BH13,0) -> 12 | BK13: =IF($BJ13<=30,IF($B13=2015,VLOOKUP($BJ13,'Treasury Yields'!$C$5:$N$34,$E13,FALSE)/100,IF($B13=2016,VLOOKUP($BJ13,'Treasury Yields'!$C$40:$N$69,$E13,FALSE)/100,IF($B13=2017,VLOOKUP($BJ13,'Treasury Yields'!$C$75:$N$104,$E13,FALSE)/100,IF($B13=2018,VLOOKUP($BJ13,'Treasury Yields'!$C$110:$N$139,$E13,FALSE)/100,IF($B13=2019,VLOOKUP($BJ13,'Treasury Yields'!$C$145:$N$174,$E13,FALSE)/100,IF($B13=2020,VLOOKUP($BJ13,'Treasury Yields'!$C$180:$N$209,$E13,FALSE)/100,IF($B13=2021,VLOOKUP($BJ13,'Treasury Yields'!$C$215:$N$244,$E13,FALSE)/100,IF($B13=2022,VLOOKUP($BJ13,'Treasury Yields'!$C$250:$N$279,$E13,FALSE)/100)))))))),0) -> 0.0233448 | BL13: =1+BH13*(AL13-BK13)+(AL13-BK13)^2 -> 1.5553181 | BM13: =BL13*R13 -> 2.7892536e+08 | BN13: =BM13-AB13 -> 1.3156343e+08 | BP13: =IF($BJ13<=30,IF($B13=2015,VLOOKUP($BJ13,'Treasury Yields'!$C$40:$N$69,$E13,FALSE)/100,IF($B13=2016,VLOOKUP($BJ13,'Treasury Yields'!$C$75:$N$104,$E13,FALSE)/100,IF($B13=2017,VLOOKUP($BJ13,'Treasury Yields'!$C$110:$N$139,$E13,FALSE)/100,IF($B13=2018,VLOOKUP($BJ13,'Treasury Yields'!$C$145:$N$174,$E13,FALSE)/100,IF($B13=2019,VLOOKUP($BJ13,'Treasury Yields'!$C$180:$N$209,$E13,FALSE)/100,IF($B13=2020,VLOOKUP($BJ13,'Treasury Yields'!$C$215:$N$244,$E13,FALSE)/100,IF($B13=2021,VLOOKUP($BJ13,'Treasury Yields'!$C$250:$N$279,$E13,FALSE)/100,IF($B13=2022,VLOOKUP($BJ13,'Treasury Yields'!$C$285:$N$314,$E13,FALSE)/100)))))))),0) -> 0.028935352 | BQ13: =1+BH13*(AN13-BP13)+(AN13-BP13)^2 -> 1.6204366 | BR13: =BQ13*S13 -> 3.3966188e+08 | BS13: =BR13-AC13 -> 1.8509298e+08 | BU13: =IF(BJ13="","",ROUND(BJ13+$BT$2,0)) -> 15 | BV13: =1+(BH13+BU13)*(AN13-BK13)+(AN13-BK13)^2*BI13 -> 2.9440061 | BW13: =BV13*J13 -> 13701908 | BX13: =(BM13+BW13-O13)*BK13 -> 6593838.4 | BY13: =BK13*(BN13+BW13-O13) -> 3153703.8 | BZ13: =SUM(J13:K13) -> 18763448 | CA13: =SUM(BW13+BY13) -> 16855612 | CC13: =BR13 -> 3.3966188e+08 | CD13: =F13 -> Texas | CE13: =BB13 -> 0.73740719 | CF13: =AC13/CC13 -> 0.45506697
A14: 44000000011101 | B14: 2019 | C14: 569 | D14: plan314_y2021 | E14: 8 | F14: Texas | G14: Teachers Retirement System of Texas | H14: TRS | I14: TRUE | J14: 5642075 | K14: 14267256 | M14: -982694 | N14: -7425279 | O14: 11253729 | P14: 486461 | Q14: 349996 | R14: 209611329 | S14: 209961325 | T14: 1761822 | U14: 1737852 | V14: 3482870 | W14: 7669029 | Y14: 60486 | Z14: 558400 | AA14: 3409297 | AB14: 154568902 | AC14: 157978199 | AD14: 51983126 | AE14: 55042427 | AF14: -3059301 | AG14: 45232074 | AH14: 0.038950723 | AI14: TRUE | AK14: 0.06907 | AL14: 0.0725 | AM14: 0.0725 | AN14: 0.0725 | AO14: 1 | AP14: 0 | AQ14: 0.0263 | AS14: 79905617 | AT14: 29360519 | AU14: p80 of CAFR | AV14: https://www.trs.texas.gov/TRS%20Documents/cafr_2019.pdf | BB14: =AC14/S14 -> 0.75241571 | BD14: =AS14-AD14 -> 27922491 | BE14: =AT14-AD14 -> -22622607 | BF14: =BD14/S14*100 -> 13.298873 | BG14: =BE14/S14*100 -> -10.774654 | BH14: =(BD14-BE14)/(2*S14)*100 -> 12.036764 | BI14: =(BD14+BE14)/(2*S14*(0.01^2)) -> 126.21096 | BJ14: =ROUND(BH14,0) -> 12 | BK14: =IF($BJ14<=30,IF($B14=2015,VLOOKUP($BJ14,'Treasury Yields'!$C$5:$N$34,$E14,FALSE)/100,IF($B14=2016,VLOOKUP($BJ14,'Treasury Yields'!$C$40:$N$69,$E14,FALSE)/100,IF($B14=2017,VLOOKUP($BJ14,'Treasury Yields'!$C$75:$N$104,$E14,FALSE)/100,IF($B14=2018,VLOOKUP($BJ14,'Treasury Yields'!$C$110:$N$139,$E14,FALSE)/100,IF($B14=2019,VLOOKUP($BJ14,'Treasury Yields'!$C$145:$N$174,$E14,FALSE)/100,IF($B14=2020,VLOOKUP($BJ14,'Treasury Yields'!$C$180:$N$209,$E14,FALSE)/100,IF($B14=2021,VLOOKUP($BJ14,'Treasury Yields'!$C$215:$N$244,$E14,FALSE)/100,IF($B14=2022,VLOOKUP($BJ14,'Treasury Yields'!$C$250:$N$279,$E14,FALSE)/100)))))))),0) -> 0.028935352 | BL14: =1+BH14*(AL14-BK14)+(AL14-BK14)^2 -> 1.5262753 | BM14: =BL14*R14 -> 3.1992459e+08 | BN14: =BM14-AB14 -> 1.6535568e+08 | BP14: =IF($BJ14<=30,IF($B14=2015,VLOOKUP($BJ14,'Treasury Yields'!$C$40:$N$69,$E14,FALSE)/100,IF($B14=2016,VLOOKUP($BJ14,'Treasury Yields'!$C$75:$N$104,$E14,FALSE)/100,IF($B14=2017,VLOOKUP($BJ14,'Treasury Yields'!$C$110:$N$139,$E14,FALSE)/100,IF($B14=2018,VLOOKUP($BJ14,'Treasury Yields'!$C$145:$N$174,$E14,FALSE)/100,IF($B14=2019,VLOOKUP($BJ14,'Treasury Yields'!$C$180:$N$209,$E14,FALSE)/100,IF($B14=2020,VLOOKUP($BJ14,'Treasury Yields'!$C$215:$N$244,$E14,FALSE)/100,IF($B14=2021,VLOOKUP($BJ14,'Treasury Yields'!$C$250:$N$279,$E14,FALSE)/100,IF($B14=2022,VLOOKUP($BJ14,'Treasury Yields'!$C$285:$N$314,$E14,FALSE)/100)))))))),0) -> 0.016946 | BQ14: =1+BH14*(AN14-BP14)+(AN14-BP14)^2 -> 1.6717766 | BR14: =BQ14*S14 -> 3.5100844e+08 | BS14: =BR14-AC14 -> 1.9303024e+08 | BU14: =IF(BJ14="","",ROUND(BJ14+$BT$2,0)) -> 15 | BV14: =1+(BH14+BU14)*(AN14-BK14)+(AN14-BK14)^2*BI14 -> 2.4173802 | BW14: =BV14*J14 -> 13639040 | BX14: =(BM14+BW14-O14)*BK14 -> 9326150.4 | BY14: =BK14*(BN14+BW14-O14) -> 4853644.8 | BZ14: =SUM(J14:K14) -> 19909331 | CA14: =SUM(BW14+BY14) -> 18492685 | CC14: =BR14 -> 3.5100844e+08 | CD14: =F14 -> Texas | CE14: =BB14 -> 0.75241571 | CF14: =AC14/CC14 -> 0.45006952
A15: 44000000011101 | B15: 2020 | C15: 569 | D15: plan314_y2021 | E15: 8 | F15: Texas | G15: Teachers Retirement System of Texas | H15: TRS | I15: TRUE | J15: 5651647 | K15: 15014048 | M15: -259157 | N15: 0 | O15: 10972292 | P15: 421366 | Q15: 9012880 | R15: 209961325 | S15: 218974205 | T15: 2016482 | U15: 2107999 | V15: 3736877 | W15: 11032131 | Y15: 67136 | Z15: -31435 | AA15: 7438046 | AB15: 157978199 | AC15: 165416245 | AD15: 53557960 | AE15: 51983126 | AF15: 1574834 | AG15: 48530876 | AH15: 0.041550497 | AI15: TRUE | AK15: 0.0725 | AL15: 0.0725 | AM15: 0.0725 | AN15: 0.0725 | AO15: 1 | AP15: 0 | AQ15: 0.0233 | AS15: 82585416 | AT15: 29973788 | AU15: p87 of CAFR | AV15: https://www.trs.texas.gov/TRS%20Documents/cafr_2020.pdf | BB15: =AC15/S15 -> 0.7554143 | BD15: =AS15-AD15 -> 29027456 | BE15: =AT15-AD15 -> -23584172 | BF15: =BD15/S15*100 -> 13.256107 | BG15: =BE15/S15*100 -> -10.770297 | BH15: =(BD15-BE15)/(2*S15)*100 -> 12.013202 | BI15: =(BD15+BE15)/(2*S15*(0.01^2)) -> 124.29053 | BJ15: =ROUND(BH15,0) -> 12 | BK15: =IF($BJ15<=30,IF($B15=2015,VLOOKUP($BJ15,'Treasury Yields'!$C$5:$N$34,$E15,FALSE)/100,IF($B15=2016,VLOOKUP($BJ15,'Treasury Yields'!$C$40:$N$69,$E15,FALSE)/100,IF($B15=2017,VLOOKUP($BJ15,'Treasury Yields'!$C$75:$N$104,$E15,FALSE)/100,IF($B15=2018,VLOOKUP($BJ15,'Treasury Yields'!$C$110:$N$139,$E15,FALSE)/100,IF($B15=2019,VLOOKUP($BJ15,'Treasury Yields'!$C$145:$N$174,$E15,FALSE)/100,IF($B15=2020,VLOOKUP($BJ15,'Treasury Yields'!$C$180:$N$209,$E15,FALSE)/100,IF($B15=2021,VLOOKUP($BJ15,'Treasury Yields'!$C$215:$N$244,$E15,FALSE)/100,IF($B15=2022,VLOOKUP($BJ15,'Treasury Yields'!$C$250:$N$279,$E15,FALSE)/100)))))))),0) -> 0.016946 | BL15: =1+BH15*(AL15-BK15)+(AL15-BK15)^2 -> 1.6704677 | BM15: =BL15*R15 -> 3.5073361e+08 | BN15: =BM15-AB15 -> 1.9275541e+08 | BP15: =IF($BJ15<=30,IF($B15=2015,VLOOKUP($BJ15,'Treasury Yields'!$C$40:$N$69,$E15,FALSE)/100,IF($B15=2016,VLOOKUP($BJ15,'Treasury Yields'!$C$75:$N$104,$E15,FALSE)/100,IF($B15=2017,VLOOKUP($BJ15,'Treasury Yields'!$C$110:$N$139,$E15,FALSE)/100,IF($B15=2018,VLOOKUP($BJ15,'Treasury Yields'!$C$145:$N$174,$E15,FALSE)/100,IF($B15=2019,VLOOKUP($BJ15,'Treasury Yields'!$C$180:$N$209,$E15,FALSE)/100,IF($B15=2020,VLOOKUP($BJ15,'Treasury Yields'!$C$215:$N$244,$E15,FALSE)/100,IF($B15=2021,VLOOKUP($BJ15,'Treasury Yields'!$C$250:$N$279,$E15,FALSE)/100,IF($B15=2022,VLOOKUP($BJ15,'Treasury Yields'!$C$285:$N$314,$E15,FALSE)/100)))))))),0) -> 0.012643048 | BQ15: =1+BH15*(AN15-BP15)+(AN15-BP15)^2 -> 1.7226565 | BR15: =BQ15*S15 -> 3.7721734e+08 | BS15: =BR15-AC15 -> 2.118011e+08 | BU15: =IF(BJ15="","",ROUND(BJ15+$BT$2,0)) -> 15 | BV15: =1+(BH15+BU15)*(AN15-BK15)+(AN15-BK15)^2*BI15 -> 2.8842827 | BW15: =BV15*J15 -> 16300948 | BX15: =(BM15+BW15-O15)*BK15 -> 6033831.1 | BY15: =BK15*(BN15+BW15-O15) -> 3356732.6 | BZ15: =SUM(J15:K15) -> 20665695 | CA15: =SUM(BW15+BY15) -> 19657680 | CC15: =BR15 -> 3.7721734e+08 | CD15: =F15 -> Texas | CE15: =BB15 -> 0.7554143 | CF15: =AC15/CC15 -> 0.43851707
A16: 44000000011101 | B16: 2021 | C16: 569 | D16: plan314_y2021 | E16: 8 | F16: Texas | G16: Teachers Retirement System of Texas | H16: TRS | I16: TRUE | J16: 5793398 | K16: 15645734 | M16: -1004527 | O16: 11686211 | P16: 449136 | Q16: 8299259 | R16: 218974205 | S16: 227273464 | T16: 2124028 | U16: 2140553 | V16: 3839244 | W16: 40512139 | Y16: 71360 | Z16: -18500 | AA16: 36390757 | AB16: 165416245 | AC16: 201807002 | AD16: 25466461 | AE16: 53557960 | AF16: -28091499 | AG16: 49860307 | AI16: TRUE | AK16: 0.0725 | AL16: 0.0725 | AM16: 0.0725 | AN16: 0.0725 | AS16: 55648260 | AT16: 979861 | BB16: =AC16/S16 -> 0.88794793 | BD16: =AS16-AD16 -> 30181799 | BE16: =AT16-AD16 -> -24486600 | BF16: =BD16/S16*100 -> 13.279949 | BG16: =BE16/S16*100 -> -10.774069 | BH16: =(BD16-BE16)/(2*S16)*100 -> 12.027009 | BI16: =(BD16+BE16)/(2*S16*(0.01^2)) -> 125.29397 | BJ16: =ROUND(BH16,0) -> 12 | BK16: =IF($BJ16<=30,IF($B16=2015,VLOOKUP($BJ16,'Treasury Yields'!$C$5:$N$34,$E16,FALSE)/100,IF($B16=2016,VLOOKUP($BJ16,'Treasury Yields'!$C$40:$N$69,$E16,FALSE)/100,IF($B16=2017,VLOOKUP($BJ16,'Treasury Yields'!$C$75:$N$104,$E16,FALSE)/100,IF($B16=2018,VLOOKUP($BJ16,'Treasury Yields'!$C$110:$N$139,$E16,FALSE)/100,IF($B16=2019,VLOOKUP($BJ16,'Treasury Yields'!$C$145:$N$174,$E16,FALSE)/100,IF($B16=2020,VLOOKUP($BJ16,'Treasury Yields'!$C$180:$N$209,$E16,FALSE)/100,IF($B16=2021,VLOOKUP($BJ16,'Treasury Yields'!$C$215:$N$244,$E16,FALSE)/100,IF($B16=2022,VLOOKUP($BJ16,'Treasury Yields'!$C$250:$N$279,$E16,FALSE)/100)))))))),0) -> 0.012643048 | BL16: =1+BH16*(AL16-BK16)+(AL16-BK16)^2 -> 1.7234829 | BM16: =BL16*R16 -> 3.7739831e+08 | BN16: =BM16-AB16 -> 2.1198206e+08 | BP16: =IF($BJ16<=30,IF($B16=2015,VLOOKUP($BJ16,'Treasury Yields'!$C$40:$N$69,$E16,FALSE)/100,IF($B16=2016,VLOOKUP($BJ16,'Treasury Yields'!$C$75:$N$104,$E16,FALSE)/100,IF($B16=2017,VLOOKUP($BJ16,'Treasury Yields'!$C$110:$N$139,$E16,FALSE)/100,IF($B16=2018,VLOOKUP($BJ16,'Treasury Yields'!$C$145:$N$174,$E16,FALSE)/100,IF($B16=2019,VLOOKUP($BJ16,'Treasury Yields'!$C$180:$N$209,$E16,FALSE)/100,IF($B16=2020,VLOOKUP($BJ16,'Treasury Yields'!$C$215:$N$244,$E16,FALSE)/100,IF($B16=2021,VLOOKUP($BJ16,'Treasury Yields'!$C$250:$N$279,$E16,FALSE)/100,IF($B16=2022,VLOOKUP($BJ16,'Treasury Yields'!$C$285:$N$314,$E16,FALSE)/100)))))))),0) -> 0.018741 | BQ16: =1+BH16*(AN16-BP16)+(AN16-BP16)^2 -> 1.64945 | BR16: =BQ16*S16 -> 3.7487621e+08 | BS16: =BR16-AC16 -> 1.7306921e+08 | BU16: =IF(BJ16="","",ROUND(BJ16+$BT$2,0)) -> 15 | BV16: =1+(BH16+BU16)*(AN16-BK16)+(AN16-BK16)^2*BI16 -> 3.0666645 | BW16: =BV16*J16 -> 17766408 | BX16: =(BM16+BW16-O16)*BK16 -> 4848337 | BY16: =BK16*(BN16+BW16-O16) -> 2756971.5 | BZ16: =SUM(J16:K16) -> 21439132 | CA16: =SUM(BW16+BY16) -> 20523379 | CC16: =BR16 -> 3.7487621e+08 | CD16: =F16 -> Texas | CE16: =BB16 -> 0.88794793 | CF16: =AC16/CC16 -> 0.53832971
A17: 44000000011101 | B17: 2022 | C17: 569 | D17: plan314_y2021 | E17: 8 | F17: Texas | G17: Teachers Retirement System of Texas | H17: TRS | I17: TRUE | J17: 6093119 | K17: 16201213 | M17: 1043774 | N17: 6651511 | O17: 13130574 | P17: 579462 | Q17: 16279582 | R17: 227273464 | S17: 243553045 | T17: 2504170 | U17: 2153483 | V17: 4213622 | W17: -13383751 | Y17: 62053 | Z17: 663179 | AA17: -17621385 | AB17: 201807002 | AC17: 184185617 | AD17: 59367428 | AE17: 25466461 | AF17: 33900967 | AG17: 52670273 | AI17: TRUE | AK17: 0.0725 | AL17: 0.07 | AM17: 0.07 | AN17: 0.0725 | AS17: 92353209 | AT17: 32630905 | AV17: https://www.trs.texas.gov/TRS%20Documents/acfr-2022.pdf | BB17: =AC17/S17 -> 0.75624436 | BD17: =AS17-AD17 -> 32985781 | BE17: =AT17-AD17 -> -26736523 | BF17: =BD17/S17*100 -> 13.543572 | BG17: =BE17/S17*100 -> -10.9777 | BH17: =(BD17-BE17)/(2*S17)*100 -> 12.260636 | BI17: =(BD17+BE17)/(2*S17*(0.01^2)) -> 128.29357 | BJ17: =ROUND(BH17,0) -> 12 | BK17: =IF($BJ17<=30,IF($B17=2015,VLOOKUP($BJ17,'Treasury Yields'!$C$5:$N$34,$E17,FALSE)/100,IF($B17=2016,VLOOKUP($BJ17,'Treasury Yields'!$C$40:$N$69,$E17,FALSE)/100,IF($B17=2017,VLOOKUP($BJ17,'Treasury Yields'!$C$75:$N$104,$E17,FALSE)/100,IF($B17=2018,VLOOKUP($BJ17,'Treasury Yields'!$C$110:$N$139,$E17,FALSE)/100,IF($B17=2019,VLOOKUP($BJ17,'Treasury Yields'!$C$145:$N$174,$E17,FALSE)/100,IF($B17=2020,VLOOKUP($BJ17,'Treasury Yields'!$C$180:$N$209,$E17,FALSE)/100,IF($B17=2021,VLOOKUP($BJ17,'Treasury Yields'!$C$215:$N$244,$E17,FALSE)/100,IF($B17=2022,VLOOKUP($BJ17,'Treasury Yields'!$C$250:$N$279,$E17,FALSE)/100)))))))),0) -> 0.018741 | BL17: =1+BH17*(AL17-BK17)+(AL17-BK17)^2 -> 1.6310954 | BM17: =BL17*R17 -> 3.7070471e+08 | BN17: =BM17-AB17 -> 1.688977e+08 | BP17: =IF($BJ17<=30,IF($B17=2015,VLOOKUP($BJ17,'Treasury Yields'!$C$40:$N$69,$E17,FALSE)/100,IF($B17=2016,VLOOKUP($BJ17,'Treasury Yields'!$C$75:$N$104,$E17,FALSE)/100,IF($B17=2017,VLOOKUP($BJ17,'Treasury Yields'!$C$110:$N$139,$E17,FALSE)/100,IF($B17=2018,VLOOKUP($BJ17,'Treasury Yields'!$C$145:$N$174,$E17,FALSE)/100,IF($B17=2019,VLOOKUP($BJ17,'Treasury Yields'!$C$180:$N$209,$E17,FALSE)/100,IF($B17=2020,VLOOKUP($BJ17,'Treasury Yields'!$C$215:$N$244,$E17,FALSE)/100,IF($B17=2021,VLOOKUP($BJ17,'Treasury Yields'!$C$250:$N$279,$E17,FALSE)/100,IF($B17=2022,VLOOKUP($BJ17,'Treasury Yields'!$C$285:$N$314,$E17,FALSE)/100)))))))),0) -> 0.031534348 | BQ17: =1+BH17*(AN17-BP17)+(AN17-BP17)^2 -> 1.5039431 | BR17: =BQ17*S17 -> 3.6628993e+08 | BS17: =BR17-AC17 -> 1.8210431e+08 | BU17: =IF(BJ17="","",ROUND(BJ17+$BT$2,0)) -> 15 | BV17: =1+(BH17+BU17)*(AN17-BK17)+(AN17-BK17)^2*BI17 -> 2.8362768 | BW17: =BV17*J17 -> 17281772 | BX17: =(BM17+BW17-O17)*BK17 -> 7025174.5 | BY17: =BK17*(BN17+BW17-O17) -> 3243109.5 | BZ17: =SUM(J17:K17) -> 22294332 | CA17: =SUM(BW17+BY17) -> 20524882 | CC17: =BR17 -> 3.6628993e+08 | CD17: =F17 -> Texas | CE17: =BB17 -> 0.75624436 | CF17: =AC17/CC17 -> 0.50284106
A18: 10000000000401 | B18: 2015 | C18: 231 | D18: plan70_y2021 | E18: 6 | F18: Florida | G18: Florida Retirement System Pension Plan | H18: FRS | I18: TRUE | J18: 2114047 | K18: 11721563 | L18: 0 | M18: 1620863 | N18: 0 | O18: 10201501 | Q18: 5254972 | R18: 156115763 | S18: 161370735 | T18: 2438085 | V18: 698304 | W18: 5523287 | Y18: 18074 | AA18: -1559898 | AB18: 150014292 | AC18: 148454394 | AD18: 12916341 | AE18: 6101471 | AF18: 6814870 | AG18: 32726034 | AH18: 0.074499861 | AI18: TRUE | AK18: 0.0765 | AL18: 0.0765 | AM18: 0.0765 | AN18: 0.0765 | AO18: 1 | AP18: 0 | AS18: 33469191 | AT18: -4186981 | BB18: =AC18/S18 -> 0.91995859 | BD18: =AS18-AD18 -> 20552850 | BE18: =AT18-AD18 -> -17103322 | BF18: =BD18/S18*100 -> 12.736417 | BG18: =BE18/S18*100 -> -10.598776 | BH18: =(BD18-BE18)/(2*S18)*100 -> 11.667596 | BI18: =(BD18+BE18)/(2*S18*(0.01^2)) -> 106.88209 | BJ18: =ROUND(BH18,0) -> 12 | BK18: =IF($BJ18<=30,IF($B18=2015,VLOOKUP($BJ18,'Treasury Yields'!$C$5:$N$34,$E18,FALSE)/100,IF($B18=2016,VLOOKUP($BJ18,'Treasury Yields'!$C$40:$N$69,$E18,FALSE)/100,IF($B18=2017,VLOOKUP($BJ18,'Treasury Yields'!$C$75:$N$104,$E18,FALSE)/100,IF($B18=2018,VLOOKUP($BJ18,'Treasury Yields'!$C$110:$N$139,$E18,FALSE)/100,IF($B18=2019,VLOOKUP($BJ18,'Treasury Yields'!$C$145:$N$174,$E18,FALSE)/100,IF($B18=2020,VLOOKUP($BJ18,'Treasury Yields'!$C$180:$N$209,$E18,FALSE)/100,IF($B18=2021,VLOOKUP($BJ18,'Treasury Yields'!$C$215:$N$244,$E18,FALSE)/100,IF($B18=2022,VLOOKUP($BJ18,'Treasury Yields'!$C$250:$N$279,$E18,FALSE)/100)))))))),0) -> 0.029186 | BL18: =1+BH18*(AL18-BK18)+(AL18-BK18)^2 -> 1.5542793 | BM18: =BL18*R18 -> 2.4264749e+08 | BN18: =BM18-AB18 -> 92633202 | BP18: =IF($BJ18<=30,IF($B18=2015,VLOOKUP($BJ18,'Treasury Yields'!$C$40:$N$69,$E18,FALSE)/100,IF($B18=2016,VLOOKUP($BJ18,'Treasury Yields'!$C$75:$N$104,$E18,FALSE)/100,IF($B18=2017,VLOOKUP($BJ18,'Treasury Yields'!$C$110:$N$139,$E18,FALSE)/100,IF($B18=2018,VLOOKUP($BJ18,'Treasury Yields'!$C$145:$N$174,$E18,FALSE)/100,IF($B18=2019,VLOOKUP($BJ18,'Treasury Yields'!$C$180:$N$209,$E18,FALSE)/100,IF($B18=2020,VLOOKUP($BJ18,'Treasury Yields'!$C$215:$N$244,$E18,FALSE)/100,IF($B18=2021,VLOOKUP($BJ18,'Treasury Yields'!$C$250:$N$279,$E18,FALSE)/100,IF($B18=2022,VLOOKUP($BJ18,'Treasury Yields'!$C$285:$N$314,$E18,FALSE)/100)))))))),0) -> 0.027046 | BQ18: =1+BH18*(AN18-BP18)+(AN18-BP18)^2 -> 1.579455 | BR18: =BQ18*S18 -> 2.5487782e+08 | BS18: =BR18-AC18 -> 1.0642342e+08 | BU18: =IF(BJ18="","",ROUND(BJ18+$BT$2,0)) -> 15 | BV18: =1+(BH18+BU18)*(AN18-BK18)+(AN18-BK18)^2*BI18 -> 2.5010185 | BW18: =BV18*J18 -> 5287270.6 | BX18: =(BM18+BW18-O18)*BK18 -> 6938483 | BY18: =BK18*(BN18+BW18-O18) -> 2560165.9 | BZ18: =SUM(J18:K18) -> 13835610 | CA18: =SUM(BW18+BY18) -> 7847436.5 | CC18: =BR18 -> 2.5487782e+08 | CD18: =F18 -> Florida | CE18: =BB18 -> 0.91995859 | CF18: =AC18/CC18 -> 0.58245318
A19: 10000000000401 | B19: 2016 | C19: 231 | D19: plan70_y2021 | E19: 6 | F19: Florida | G19: Florida Retirement System Pension Plan | H19: FRS | I19: TRUE | J19: 2132906 | K19: 12109114 | L19: 32310 | M19: 980192 | N19: 1030667 | O19: 10624925 | Q19: 5660264 | R19: 161370735 | S19: 167030999 | T19: 2438659 | V19: 710717 | W19: 820582 | Y19: 18507 | AA19: -6673473 | AB19: 148454394 | AC19: 141780921 | AD19: 25250078 | AE19: 12916341 | AF19: 12333737 | AG19: 33214217 | AH19: 0.073422143 | AI19: TRUE | AK19: 0.0765 | AL19: 0.076 | AM19: 0.076 | AN19: 0.0765 | AO19: 1 | AP19: 0 | AS19: 46487104 | AT19: 7573059 | AU19: p66 of CAFR | AV19: https://www.rol.frs.state.fl.us/forms/2015-16_CAFR.pdf | BB19: =AC19/S19 -> 0.84882999 | BD19: =AS19-AD19 -> 21237026 | BE19: =AT19-AD19 -> -17677019 | BF19: =BD19/S19*100 -> 12.714422 | BG19: =BE19/S19*100 -> -10.583077 | BH19: =(BD19-BE19)/(2*S19)*100 -> 11.648749 | BI19: =(BD19+BE19)/(2*S19*(0.01^2)) -> 106.56725 | BJ19: =ROUND(BH19,0) -> 12 | BK19: =IF($BJ19<=30,IF($B19=2015,VLOOKUP($BJ19,'Treasury Yields'!$C$5:$N$34,$E19,FALSE)/100,IF($B19=2016,VLOOKUP($BJ19,'Treasury Yields'!$C$40:$N$69,$E19,FALSE)/100,IF($B19=2017,VLOOKUP($BJ19,'Treasury Yields'!$C$75:$N$104,$E19,FALSE)/100,IF($B19=2018,VLOOKUP($BJ19,'Treasury Yields'!$C$110:$N$139,$E19,FALSE)/100,IF($B19=2019,VLOOKUP($BJ19,'Treasury Yields'!$C$145:$N$174,$E19,FALSE)/100,IF($B19=2020,VLOOKUP($BJ19,'Treasury Yields'!$C$180:$N$209,$E19,FALSE)/100,IF($B19=2021,VLOOKUP($BJ19,'Treasury Yields'!$C$215:$N$244,$E19,FALSE)/100,IF($B19=2022,VLOOKUP($BJ19,'Treasury Yields'!$C$250:$N$279,$E19,FALSE)/100)))))))),0) -> 0.027046 | BL19: =1+BH19*(AL19-BK19)+(AL19-BK19)^2 -> 1.5726494 | BM19: =BL19*R19 -> 2.5377959e+08 | BN19: =BM19-AB19 -> 1.0532519e+08 | BP19: =IF($BJ19<=30,IF($B19=2015,VLOOKUP($BJ19,'Treasury Yields'!$C$40:$N$69,$E19,FALSE)/100,IF($B19=2016,VLOOKUP($BJ19,'Treasury Yields'!$C$75:$N$104,$E19,FALSE)/100,IF($B19=2017,VLOOKUP($BJ19,'Treasury Yields'!$C$110:$N$139,$E19,FALSE)/100,IF($B19=2018,VLOOKUP($BJ19,'Treasury Yields'!$C$145:$N$174,$E19,FALSE)/100,IF($B19=2019,VLOOKUP($BJ19,'Treasury Yields'!$C$180:$N$209,$E19,FALSE)/100,IF($B19=2020,VLOOKUP($BJ19,'Treasury Yields'!$C$215:$N$244,$E19,FALSE)/100,IF($B19=2021,VLOOKUP($BJ19,'Treasury Yields'!$C$250:$N$279,$E19,FALSE)/100,IF($B19=2022,VLOOKUP($BJ19,'Treasury Yields'!$C$285:$N$314,$E19,FALSE)/100)))))))),0) -> 0.017546 | BQ19: =1+BH19*(AN19-BP19)+(AN19-BP19)^2 -> 1.6902159 | BR19: =BQ19*S19 -> 2.8231846e+08 | BS19: =BR19-AC19 -> 1.4053754e+08 | BU19: =IF(BJ19="","",ROUND(BJ19+$BT$2,0)) -> 15 | BV19: =1+(BH19+BU19)*(AN19-BK19)+(AN19-BK19)^2*BI19 -> 2.5785186 | BW19: =BV19*J19 -> 5499737.8 | BX19: =(BM19+BW19-O19)*BK19 -> 6725106.8 | BY19: =BK19*(BN19+BW19-O19) -> 2710009.3 | BZ19: =SUM(J19:K19) -> 14242020 | CA19: =SUM(BW19+BY19) -> 8209747.1 | CC19: =BR19 -> 2.8231846e+08 | CD19: =F19 -> Florida | CE19: =BB19 -> 0.84882999 | CF19: =AC19/CC19 -> 0.50220209
A20: 10000000000401 | B20: 2017 | C20: 231 | D20: plan70_y2021 | E20: 6 | F20: Florida | G20: Florida Retirement System Pension Plan | H20: FRS | I20: TRUE | J20: 2073754 | K20: 12484167 | L20: 92185 | M20: 1412462 | N20: 10398344 | O20: 9859319 | Q20: 16601593 | R20: 167030999 | S20: 183632592 | T20: 2603246 | V20: 744839 | W20: 18801917 | Y20: 18340 | AA20: 12272342 | AB20: 141780921 | AC20: 154053263 | AD20: 29579329 | AE20: 25250078 | AF20: 4329251 | AG20: 33775800 | AH20: 0.077074296 | AI20: TRUE | AK20: 0.076 | AL20: 0.071 | AM20: 0.071 | AN20: 0.076 | AO20: 1 | AP20: 0 | AS20: 53536799 | AT20: 9689140 | AU20: p71 of CAFR | AV20: https://www.rol.frs.state.fl.us/forms/2016-17_CAFR.pdf | BB20: =AC20/S20 -> 0.83892114 | BD20: =AS20-AD20 -> 23957470 | BE20: =AT20-AD20 -> -19890189 | BF20: =BD20/S20*100 -> 13.046415 | BG20: =BE20/S20*100 -> -10.831514 | BH20: =(BD20-BE20)/(2*S20)*100 -> 11.938964 | BI20: =(BD20+BE20)/(2*S20*(0.01^2)) -> 110.74507 | BJ20: =ROUND(BH20,0) -> 12 | BK20: =IF($BJ20<=30,IF($B20=2015,VLOOKUP($BJ20,'Treasury Yields'!$C$5:$N$34,$E20,FALSE)/100,IF($B20=2016,VLOOKUP($BJ20,'Treasury Yields'!$C$40:$N$69,$E20,FALSE)/100,IF($B20=2017,VLOOKUP($BJ20,'Treasury Yields'!$C$75:$N$104,$E20,FALSE)/100,IF($B20=2018,VLOOKUP($BJ20,'Treasury Yields'!$C$110:$N$139,$E20,FALSE)/100,IF($B20=2019,VLOOKUP($BJ20,'Treasury Yields'!$C$145:$N$174,$E20,FALSE)/100,IF($B20=2020,VLOOKUP($BJ20,'Treasury Yields'!$C$180:$N$209,$E20,FALSE)/100,IF($B20=2021,VLOOKUP($BJ20,'Treasury Yields'!$C$215:$N$244,$E20,FALSE)/100,IF($B20=2022,VLOOKUP($BJ20,'Treasury Yields'!$C$250:$N$279,$E20,FALSE)/100)))))))),0) -> 0.017546 | BL20: =1+BH20*(AL20-BK20)+(AL20-BK20)^2 -> 1.6410427 | BM20: =BL20*R20 -> 2.7410501e+08 | BN20: =BM20-AB20 -> 1.3232408e+08 | BP20: =IF($BJ20<=30,IF($B20=2015,VLOOKUP($BJ20,'Treasury Yields'!$C$40:$N$69,$E20,FALSE)/100,IF($B20=2016,VLOOKUP($BJ20,'Treasury Yields'!$C$75:$N$104,$E20,FALSE)/100,IF($B20=2017,VLOOKUP($BJ20,'Treasury Yields'!$C$110:$N$139,$E20,FALSE)/100,IF($B20=2018,VLOOKUP($BJ20,'Treasury Yields'!$C$145:$N$174,$E20,FALSE)/100,IF($B20=2019,VLOOKUP($BJ20,'Treasury Yields'!$C$180:$N$209,$E20,FALSE)/100,IF($B20=2020,VLOOKUP($BJ20,'Treasury Yields'!$C$215:$N$244,$E20,FALSE)/100,IF($B20=2021,VLOOKUP($BJ20,'Treasury Yields'!$C$250:$N$279,$E20,FALSE)/100,IF($B20=2022,VLOOKUP($BJ20,'Treasury Yields'!$C$285:$N$314,$E20,FALSE)/100)))))))),0) -> 0.0254676 | BQ20: =1+BH20*(AN20-BP20)+(AN20-BP20)^2 -> 1.605858 | BR20: =BQ20*S20 -> 2.9488787e+08 | BS20: =BR20-AC20 -> 1.4083461e+08 | BU20: =IF(BJ20="","",ROUND(BJ20+$BT$2,0)) -> 15 | BV20: =1+(BH20+BU20)*(AN20-BK20)+(AN20-BK20)^2*BI20 -> 2.9530917 | BW20: =BV20*J20 -> 6123985.8 | BX20: =(BM20+BW20-O20)*BK20 -> 4743906.3 | BY20: =BK20*(BN20+BW20-O20) -> 2256218.2 | BZ20: =SUM(J20:K20) -> 14557921 | CA20: =SUM(BW20+BY20) -> 8380204.1 | CC20: =BR20 -> 2.9488787e+08 | CD20: =F20 -> Florida | CE20: =BB20 -> 0.83892114 | CF20: =AC20/CC20 -> 0.52241301
A21: 10000000000401 | B21: 2018 | C21: 231 | D21: plan70_y2021 | E21: 6 | F21: Florida | G21: Florida Retirement System Pension Plan | H21: FRS | I21: TRUE | J21: 2423987 | K21: 12847930 | L21: 0 | M21: 554811 | N21: 2235654 | O21: 10377575 | Q21: 7684807 | R21: 183632592 | S21: 191317399 | T21: 2849920 | V21: 746370 | W21: 13955233 | Y21: 20178 | AA21: 7153770 | AB21: 154043111 | AC21: 161196881 | AD21: 30120518 | AE21: 29589481 | AF21: 531037 | AG21: 34675000 | AH21: 0.082189474 | AI21: TRUE | AK21: 0.071 | AL21: 0.07 | AM21: 0.07 | AN21: 0.071 | AO21: 1 | AP21: 0 | AS21: 54971209 | AT21: 9480550 | AU21: p73 of CAFR | AV21: https://www.rol.frs.state.fl.us/forms/2017-18_CAFR.pdf | BB21: =AC21/S21 -> 0.84256258 | BD21: =AS21-AD21 -> 24850691 | BE21: =AT21-AD21 -> -20639968 | BF21: =BD21/S21*100 -> 12.989248 | BG21: =BE21/S21*100 -> -10.788338 | BH21: =(BD21-BE21)/(2*S21)*100 -> 11.888793 | BI21: =(BD21+BE21)/(2*S21*(0.01^2)) -> 110.04548 | BJ21: =ROUND(BH21,0) -> 12 | BK21: =IF($BJ21<=30,IF($B21=2015,VLOOKUP($BJ21,'Treasury Yields'!$C$5:$N$34,$E21,FALSE)/100,IF($B21=2016,VLOOKUP($BJ21,'Treasury Yields'!$C$40:$N$69,$E21,FALSE)/100,IF($B21=2017,VLOOKUP($BJ21,'Treasury Yields'!$C$75:$N$104,$E21,FALSE)/100,IF($B21=2018,VLOOKUP($BJ21,'Treasury Yields'!$C$110:$N$139,$E21,FALSE)/100,IF($B21=2019,VLOOKUP($BJ21,'Treasury Yields'!$C$145:$N$174,$E21,FALSE)/100,IF($B21=2020,VLOOKUP($BJ21,'Treasury Yields'!$C$180:$N$209,$E21,FALSE)/100,IF($B21=2021,VLOOKUP($BJ21,'Treasury Yields'!$C$215:$N$244,$E21,FALSE)/100,IF($B21=2022,VLOOKUP($BJ21,'Treasury Yields'!$C$250:$N$279,$E21,FALSE)/100)))))))),0) -> 0.0254676 | BL21: =1+BH21*(AL21-BK21)+(AL21-BK21)^2 -> 1.5314196 | BM21: =BL21*R21 -> 2.8121855e+08 | BN21: =BM21-AB21 -> 1.2717544e+08 | BP21: =IF($BJ21<=30,IF($B21=2015,VLOOKUP($BJ21,'Treasury Yields'!$C$40:$N$69,$E21,FALSE)/100,IF($B21=2016,VLOOKUP($BJ21,'Treasury Yields'!$C$75:$N$104,$E21,FALSE)/100,IF($B21=2017,VLOOKUP($BJ21,'Treasury Yields'!$C$110:$N$139,$E21,FALSE)/100,IF($B21=2018,VLOOKUP($BJ21,'Treasury Yields'!$C$145:$N$174,$E21,FALSE)/100,IF($B21=2019,VLOOKUP($BJ21,'Treasury Yields'!$C$180:$N$209,$E21,FALSE)/100,IF($B21=2020,VLOOKUP($BJ21,'Treasury Yields'!$C$215:$N$244,$E21,FALSE)/100,IF($B21=2021,VLOOKUP($BJ21,'Treasury Yields'!$C$250:$N$279,$E21,FALSE)/100,IF($B21=2022,VLOOKUP($BJ21,'Treasury Yields'!$C$285:$N$314,$E21,FALSE)/100)))))))),0) -> 0.028906473 | BQ21: =1+BH21*(AN21-BP21)+(AN21-BP21)^2 -> 1.5022131 | BR21: =BQ21*S21 -> 2.873995e+08 | BS21: =BR21-AC21 -> 1.2620262e+08 | BU21: =IF(BJ21="","",ROUND(BJ21+$BT$2,0)) -> 15 | BV21: =1+(BH21+BU21)*(AN21-BK21)+(AN21-BK21)^2*BI21 -> 2.4524575 | BW21: =BV21*J21 -> 5944725.1 | BX21: =(BM21+BW21-O21)*BK21 -> 7049067.6 | BY21: =BK21*(BN21+BW21-O21) -> 3125959.3 | BZ21: =SUM(J21:K21) -> 15271917 | CA21: =SUM(BW21+BY21) -> 9070684.4 | CC21: =BR21 -> 2.873995e+08 | CD21: =F21 -> Florida | CE21: =BB21 -> 0.84256258 | CF21: =AC21/CC21 -> 0.56088086
