Workbook

Sheet Summary
A1: LEAID | B1: Year | C1: State | D1: state_abv | E1: plan_name | F1: district_name | G1: district_contributions | H1: state_contributions | I1: total_contributions | J1: LEAID Match | K1: count | L1: dc proportion
A2: 3801760 | B2: 2015 | C2: North Dakota | D2: ND | E2: North Dakota Teachers' Fund for Retirement | F2: Alexander School | G2: 120120 | H2: {=_xlfn.IFS(B2=2015,L2*$P$3,B2=2016,L2*$P$4,B2=2017,L2*$P$5,B2=2018,L2*$P$6,B2=2019,L2*$P$7,B2=2020,L2*$P$8,B2=2021,L2*$P$9,B2=2022,L2*$P$10)} -> 2715.7238 | I2: =SUM(G2:H2) -> 122835.72 | J2: =IFERROR(VLOOKUP(F2,'LEAID Match'!$A$2:$B$227,2,FALSE),"") -> 3801760 | K2: =COUNTIF($A$2:$A$1757,A2) -> 8 | L2: {=_xlfn.IFS(B2=2015,G2/$P$13,B2=2016,G2/$P$14,B2=2017,G2/$P$15,B2=2018,G2/$P$16,B2=2019,G2/$P$17,B2=2019,G2/$P$18,B2=2020,G2/$P$18,B2=2021,G2/$P$19,B2=2022,G2/$P$20)} -> 0.0015317111
A3: 3801760 | B3: 2016 | C3: North Dakota | D3: ND | E3: North Dakota Teachers' Fund for Retirement | F3: Alexander School | G3: 149793 | H3: {=_xlfn.IFS(B3=2015,L3*$P$3,B3=2016,L3*$P$4,B3=2017,L3*$P$5,B3=2018,L3*$P$6,B3=2019,L3*$P$7,B3=2020,L3*$P$8,B3=2021,L3*$P$9,B3=2022,L3*$P$10)} -> 5086.529 | I3: =SUM(G3:H3) -> 154879.53 | J3: =IFERROR(VLOOKUP(F3,'LEAID Match'!$A$2:$B$227,2,FALSE),"") -> 3801760 | K3: =COUNTIF($A$2:$A$1757,A3) -> 8 | L3: {=_xlfn.IFS(B3=2015,G3/$P$13,B3=2016,G3/$P$14,B3=2017,G3/$P$15,B3=2018,G3/$P$16,B3=2019,G3/$P$17,B3=2019,G3/$P$18,B3=2020,G3/$P$18,B3=2021,G3/$P$19,B3=2022,G3/$P$20)} -> 0.0018082222 | N3: GASB 67 State Contributions | O3: 2015 | P3: 1773000
A4: 3801760 | B4: 2017 | C4: North Dakota | D4: ND | E4: North Dakota Teachers' Fund for Retirement | F4: Alexander School | G4: 153240 | H4: {=_xlfn.IFS(B4=2015,L4*$P$3,B4=2016,L4*$P$4,B4=2017,L4*$P$5,B4=2018,L4*$P$6,B4=2019,L4*$P$7,B4=2020,L4*$P$8,B4=2021,L4*$P$9,B4=2022,L4*$P$10)} -> 4966.2097 | I4: =SUM(G4:H4) -> 158206.21 | J4: =IFERROR(VLOOKUP(F4,'LEAID Match'!$A$2:$B$227,2,FALSE),"") -> 3801760 | K4: =COUNTIF($A$2:$A$1757,A4) -> 8 | L4: {=_xlfn.IFS(B4=2015,G4/$P$13,B4=2016,G4/$P$14,B4=2017,G4/$P$15,B4=2018,G4/$P$16,B4=2019,G4/$P$17,B4=2019,G4/$P$18,B4=2020,G4/$P$18,B4=2021,G4/$P$19,B4=2022,G4/$P$20)} -> 0.0017806417 | O4: 2016 | P4: 2813000
A5: 3801760 | B5: 2018 | C5: North Dakota | D5: ND | E5: North Dakota Teachers' Fund for Retirement | F5: Alexander School | G5: 156508 | H5: {=_xlfn.IFS(B5=2015,L5*$P$3,B5=2016,L5*$P$4,B5=2017,L5*$P$5,B5=2018,L5*$P$6,B5=2019,L5*$P$7,B5=2020,L5*$P$8,B5=2021,L5*$P$9,B5=2022,L5*$P$10)} -> 4288.4739 | I5: =SUM(G5:H5) -> 160796.47 | J5: =IFERROR(VLOOKUP(F5,'LEAID Match'!$A$2:$B$227,2,FALSE),"") -> 3801760 | K5: =COUNTIF($A$2:$A$1757,A5) -> 8 | L5: {=_xlfn.IFS(B5=2015,G5/$P$13,B5=2016,G5/$P$14,B5=2017,G5/$P$15,B5=2018,G5/$P$16,B5=2019,G5/$P$17,B5=2019,G5/$P$18,B5=2020,G5/$P$18,B5=2021,G5/$P$19,B5=2022,G5/$P$20)} -> 0.0018056732 | O5: 2017 | P5: 2789000
A6: 3801760 | B6: 2019 | C6: North Dakota | D6: ND | E6: North Dakota Teachers' Fund for Retirement | F6: Alexander School | G6: 181171 | H6: {=_xlfn.IFS(B6=2015,L6*$P$3,B6=2016,L6*$P$4,B6=2017,L6*$P$5,B6=2018,L6*$P$6,B6=2019,L6*$P$7,B6=2020,L6*$P$8,B6=2021,L6*$P$9,B6=2022,L6*$P$10)} -> 4204.9472 | I6: =SUM(G6:H6) -> 185375.95 | J6: =IFERROR(VLOOKUP(F6,'LEAID Match'!$A$2:$B$227,2,FALSE),"") -> 3801760 | K6: =COUNTIF($A$2:$A$1757,A6) -> 8 | L6: {=_xlfn.IFS(B6=2015,G6/$P$13,B6=2016,G6/$P$14,B6=2017,G6/$P$15,B6=2018,G6/$P$16,B6=2019,G6/$P$17,B6=2019,G6/$P$18,B6=2020,G6/$P$18,B6=2021,G6/$P$19,B6=2022,G6/$P$20)} -> 0.0020255044 | O6: 2018 | P6: 2375000
A7: 3801760 | B7: 2020 | C7: North Dakota | D7: ND | E7: North Dakota Teachers' Fund for Retirement | F7: Alexander School | G7: 193333 | H7: {=_xlfn.IFS(B7=2015,L7*$P$3,B7=2016,L7*$P$4,B7=2017,L7*$P$5,B7=2018,L7*$P$6,B7=2019,L7*$P$7,B7=2020,L7*$P$8,B7=2021,L7*$P$9,B7=2022,L7*$P$10)} -> 4850.3418 | I7: =SUM(G7:H7) -> 198183.34 | J7: =IFERROR(VLOOKUP(F7,'LEAID Match'!$A$2:$B$227,2,FALSE),"") -> 3801760 | K7: =COUNTIF($A$2:$A$1757,A7) -> 8 | L7: {=_xlfn.IFS(B7=2015,G7/$P$13,B7=2016,G7/$P$14,B7=2017,G7/$P$15,B7=2018,G7/$P$16,B7=2019,G7/$P$17,B7=2019,G7/$P$18,B7=2020,G7/$P$18,B7=2021,G7/$P$19,B7=2022,G7/$P$20)} -> 0.0020781242 | O7: 2019 | P7: 2076000
A8: 3801760 | B8: 2021 | C8: North Dakota | D8: ND | E8: North Dakota Teachers' Fund for Retirement | F8: Alexander School | G8: 195392 | H8: {=_xlfn.IFS(B8=2015,L8*$P$3,B8=2016,L8*$P$4,B8=2017,L8*$P$5,B8=2018,L8*$P$6,B8=2019,L8*$P$7,B8=2020,L8*$P$8,B8=2021,L8*$P$9,B8=2022,L8*$P$10)} -> 5338.9483 | I8: =SUM(G8:H8) -> 200730.95 | J8: =IFERROR(VLOOKUP(F8,'LEAID Match'!$A$2:$B$227,2,FALSE),"") -> 3801760 | K8: =COUNTIF($A$2:$A$1757,A8) -> 8 | L8: {=_xlfn.IFS(B8=2015,G8/$P$13,B8=2016,G8/$P$14,B8=2017,G8/$P$15,B8=2018,G8/$P$16,B8=2019,G8/$P$17,B8=2019,G8/$P$18,B8=2020,G8/$P$18,B8=2021,G8/$P$19,B8=2022,G8/$P$20)} -> 0.0019884351 | O8: 2020 | P8: 2334000
A9: 3801760 | B9: 2022 | C9: North Dakota | D9: ND | E9: North Dakota Teachers' Fund for Retirement | F9: Alexander School | G9: 214703 | H9: {=_xlfn.IFS(B9=2015,L9*$P$3,B9=2016,L9*$P$4,B9=2017,L9*$P$5,B9=2018,L9*$P$6,B9=2019,L9*$P$7,B9=2020,L9*$P$8,B9=2021,L9*$P$9,B9=2022,L9*$P$10)} -> 4369.7563 | I9: =SUM(G9:H9) -> 219072.76 | J9: =IFERROR(VLOOKUP(F9,'LEAID Match'!$A$2:$B$227,2,FALSE),"") -> 3801760 | K9: =COUNTIF($A$2:$A$1757,A9) -> 8 | L9: {=_xlfn.IFS(B9=2015,G9/$P$13,B9=2016,G9/$P$14,B9=2017,G9/$P$15,B9=2018,G9/$P$16,B9=2019,G9/$P$17,B9=2019,G9/$P$18,B9=2020,G9/$P$18,B9=2021,G9/$P$19,B9=2022,G9/$P$20)} -> 0.0021399394 | O9: 2021 | P9: 2685000
A10: 3801950 | B10: 2015 | C10: North Dakota | D10: ND | E10: North Dakota Teachers' Fund for Retirement | F10: Anamoose School | G10: 89301 | H10: {=_xlfn.IFS(B10=2015,L10*$P$3,B10=2016,L10*$P$4,B10=2017,L10*$P$5,B10=2018,L10*$P$6,B10=2019,L10*$P$7,B10=2020,L10*$P$8,B10=2021,L10*$P$9,B10=2022,L10*$P$10)} -> 2018.9548 | I10: =SUM(G10:H10) -> 91319.955 | J10: =IFERROR(VLOOKUP(F10,'LEAID Match'!$A$2:$B$227,2,FALSE),"") -> 3801950 | K10: =COUNTIF($A$2:$A$1757,A10) -> 8 | L10: {=_xlfn.IFS(B10=2015,G10/$P$13,B10=2016,G10/$P$14,B10=2017,G10/$P$15,B10=2018,G10/$P$16,B10=2019,G10/$P$17,B10=2019,G10/$P$18,B10=2020,G10/$P$18,B10=2021,G10/$P$19,B10=2022,G10/$P$20)} -> 0.0011387224 | O10: 2022 | P10: 2042000
A11: 3801950 | B11: 2016 | C11: North Dakota | D11: ND | E11: North Dakota Teachers' Fund for Retirement | F11: Anamoose School | G11: 92042 | H11: {=_xlfn.IFS(B11=2015,L11*$P$3,B11=2016,L11*$P$4,B11=2017,L11*$P$5,B11=2018,L11*$P$6,B11=2019,L11*$P$7,B11=2020,L11*$P$8,B11=2021,L11*$P$9,B11=2022,L11*$P$10)} -> 3125.4752 | I11: =SUM(G11:H11) -> 95167.475 | J11: =IFERROR(VLOOKUP(F11,'LEAID Match'!$A$2:$B$227,2,FALSE),"") -> 3801950 | K11: =COUNTIF($A$2:$A$1757,A11) -> 8 | L11: {=_xlfn.IFS(B11=2015,G11/$P$13,B11=2016,G11/$P$14,B11=2017,G11/$P$15,B11=2018,G11/$P$16,B11=2019,G11/$P$17,B11=2019,G11/$P$18,B11=2020,G11/$P$18,B11=2021,G11/$P$19,B11=2022,G11/$P$20)} -> 0.0011110825
A12: 3801950 | B12: 2017 | C12: North Dakota | D12: ND | E12: North Dakota Teachers' Fund for Retirement | F12: Anamoose School | G12: 97427 | H12: {=_xlfn.IFS(B12=2015,L12*$P$3,B12=2016,L12*$P$4,B12=2017,L12*$P$5,B12=2018,L12*$P$6,B12=2019,L12*$P$7,B12=2020,L12*$P$8,B12=2021,L12*$P$9,B12=2022,L12*$P$10)} -> 3157.4192 | I12: =SUM(G12:H12) -> 100584.42 | J12: =IFERROR(VLOOKUP(F12,'LEAID Match'!$A$2:$B$227,2,FALSE),"") -> 3801950 | K12: =COUNTIF($A$2:$A$1757,A12) -> 8 | L12: {=_xlfn.IFS(B12=2015,G12/$P$13,B12=2016,G12/$P$14,B12=2017,G12/$P$15,B12=2018,G12/$P$16,B12=2019,G12/$P$17,B12=2019,G12/$P$18,B12=2020,G12/$P$18,B12=2021,G12/$P$19,B12=2022,G12/$P$20)} -> 0.0011320972
A13: 3801950 | B13: 2018 | C13: North Dakota | D13: ND | E13: North Dakota Teachers' Fund for Retirement | F13: Anamoose School | G13: 98506 | H13: {=_xlfn.IFS(B13=2015,L13*$P$3,B13=2016,L13*$P$4,B13=2017,L13*$P$5,B13=2018,L13*$P$6,B13=2019,L13*$P$7,B13=2020,L13*$P$8,B13=2021,L13*$P$9,B13=2022,L13*$P$10)} -> 2699.1618 | I13: =SUM(G13:H13) -> 101205.16 | J13: =IFERROR(VLOOKUP(F13,'LEAID Match'!$A$2:$B$227,2,FALSE),"") -> 3801950 | K13: =COUNTIF($A$2:$A$1757,A13) -> 8 | L13: {=_xlfn.IFS(B13=2015,G13/$P$13,B13=2016,G13/$P$14,B13=2017,G13/$P$15,B13=2018,G13/$P$16,B13=2019,G13/$P$17,B13=2019,G13/$P$18,B13=2020,G13/$P$18,B13=2021,G13/$P$19,B13=2022,G13/$P$20)} -> 0.0011364892 | N13: summed district contributions | O13: 2015 | P13: =SUMIF($B$2:$B$1757,O13,$G$2:$G$1757) -> 78422100
A14: 3801950 | B14: 2019 | C14: North Dakota | D14: ND | E14: North Dakota Teachers' Fund for Retirement | F14: Anamoose School | G14: 88156 | H14: {=_xlfn.IFS(B14=2015,L14*$P$3,B14=2016,L14*$P$4,B14=2017,L14*$P$5,B14=2018,L14*$P$6,B14=2019,L14*$P$7,B14=2020,L14*$P$8,B14=2021,L14*$P$9,B14=2022,L14*$P$10)} -> 2046.0853 | I14: =SUM(G14:H14) -> 90202.085 | J14: =IFERROR(VLOOKUP(F14,'LEAID Match'!$A$2:$B$227,2,FALSE),"") -> 3801950 | K14: =COUNTIF($A$2:$A$1757,A14) -> 8 | L14: {=_xlfn.IFS(B14=2015,G14/$P$13,B14=2016,G14/$P$14,B14=2017,G14/$P$15,B14=2018,G14/$P$16,B14=2019,G14/$P$17,B14=2019,G14/$P$18,B14=2020,G14/$P$18,B14=2021,G14/$P$19,B14=2022,G14/$P$20)} -> 0.00098559023 | O14: 2016 | P14: =SUMIF($B$2:$B$1757,O14,$G$2:$G$1757) -> 82839931
A15: 3801950 | B15: 2020 | C15: North Dakota | D15: ND | E15: North Dakota Teachers' Fund for Retirement | F15: Anamoose School | G15: 85143 | H15: {=_xlfn.IFS(B15=2015,L15*$P$3,B15=2016,L15*$P$4,B15=2017,L15*$P$5,B15=2018,L15*$P$6,B15=2019,L15*$P$7,B15=2020,L15*$P$8,B15=2021,L15*$P$9,B15=2022,L15*$P$10)} -> 2136.0691 | I15: =SUM(G15:H15) -> 87279.069 | J15: =IFERROR(VLOOKUP(F15,'LEAID Match'!$A$2:$B$227,2,FALSE),"") -> 3801950 | K15: =COUNTIF($A$2:$A$1757,A15) -> 8 | L15: {=_xlfn.IFS(B15=2015,G15/$P$13,B15=2016,G15/$P$14,B15=2017,G15/$P$15,B15=2018,G15/$P$16,B15=2019,G15/$P$17,B15=2019,G15/$P$18,B15=2020,G15/$P$18,B15=2021,G15/$P$19,B15=2022,G15/$P$20)} -> 0.00091519672 | O15: 2017 | P15: =SUMIF($B$2:$B$1757,O15,$G$2:$G$1757) -> 86058863
A16: 3801950 | B16: 2021 | C16: North Dakota | D16: ND | E16: North Dakota Teachers' Fund for Retirement | F16: Anamoose School | G16: 90105 | H16: {=_xlfn.IFS(B16=2015,L16*$P$3,B16=2016,L16*$P$4,B16=2017,L16*$P$5,B16=2018,L16*$P$6,B16=2019,L16*$P$7,B16=2020,L16*$P$8,B16=2021,L16*$P$9,B16=2022,L16*$P$10)} -> 2462.0555 | I16: =SUM(G16:H16) -> 92567.055 | J16: =IFERROR(VLOOKUP(F16,'LEAID Match'!$A$2:$B$227,2,FALSE),"") -> 3801950 | K16: =COUNTIF($A$2:$A$1757,A16) -> 8 | L16: {=_xlfn.IFS(B16=2015,G16/$P$13,B16=2016,G16/$P$14,B16=2017,G16/$P$15,B16=2018,G16/$P$16,B16=2019,G16/$P$17,B16=2019,G16/$P$18,B16=2020,G16/$P$18,B16=2021,G16/$P$19,B16=2022,G16/$P$20)} -> 0.00091696665 | O16: 2018 | P16: =SUMIF($B$2:$B$1757,O16,$G$2:$G$1757) -> 86675705
A17: 3801950 | B17: 2022 | C17: North Dakota | D17: ND | E17: North Dakota Teachers' Fund for Retirement | F17: Anamoose School | G17: 102289 | H17: {=_xlfn.IFS(B17=2015,L17*$P$3,B17=2016,L17*$P$4,B17=2017,L17*$P$5,B17=2018,L17*$P$6,B17=2019,L17*$P$7,B17=2020,L17*$P$8,B17=2021,L17*$P$9,B17=2022,L17*$P$10)} -> 2081.8433 | I17: =SUM(G17:H17) -> 104370.84 | J17: =IFERROR(VLOOKUP(F17,'LEAID Match'!$A$2:$B$227,2,FALSE),"") -> 3801950 | K17: =COUNTIF($A$2:$A$1757,A17) -> 8 | L17: {=_xlfn.IFS(B17=2015,G17/$P$13,B17=2016,G17/$P$14,B17=2017,G17/$P$15,B17=2018,G17/$P$16,B17=2019,G17/$P$17,B17=2019,G17/$P$18,B17=2020,G17/$P$18,B17=2021,G17/$P$19,B17=2022,G17/$P$20)} -> 0.0010195119 | O17: 2019 | P17: =SUMIF($B$2:$B$1757,O17,$G$2:$G$1757) -> 89444880
A18: 3802014 | B18: 2015 | C18: North Dakota | D18: ND | E18: North Dakota Teachers' Fund for Retirement | F18: Apple Creek Elem School | G18: 40947 | H18: {=_xlfn.IFS(B18=2015,L18*$P$3,B18=2016,L18*$P$4,B18=2017,L18*$P$5,B18=2018,L18*$P$6,B18=2019,L18*$P$7,B18=2020,L18*$P$8,B18=2021,L18*$P$9,B18=2022,L18*$P$10)} -> 925.74709 | I18: =SUM(G18:H18) -> 41872.747 | J18: =IFERROR(VLOOKUP(F18,'LEAID Match'!$A$2:$B$227,2,FALSE),"") -> 3802014 | K18: =COUNTIF($A$2:$A$1757,A18) -> 8 | L18: {=_xlfn.IFS(B18=2015,G18/$P$13,B18=2016,G18/$P$14,B18=2017,G18/$P$15,B18=2018,G18/$P$16,B18=2019,G18/$P$17,B18=2019,G18/$P$18,B18=2020,G18/$P$18,B18=2021,G18/$P$19,B18=2022,G18/$P$20)} -> 0.00052213598 | O18: 2020 | P18: =SUMIF($B$2:$B$1757,O18,$G$2:$G$1757) -> 93032458
A19: 3802014 | B19: 2016 | C19: North Dakota | D19: ND | E19: North Dakota Teachers' Fund for Retirement | F19: Apple Creek Elem School | G19: 44015 | H19: {=_xlfn.IFS(B19=2015,L19*$P$3,B19=2016,L19*$P$4,B19=2017,L19*$P$5,B19=2018,L19*$P$6,B19=2019,L19*$P$7,B19=2020,L19*$P$8,B19=2021,L19*$P$9,B19=2022,L19*$P$10)} -> 1494.6197 | I19: =SUM(G19:H19) -> 45509.62 | J19: =IFERROR(VLOOKUP(F19,'LEAID Match'!$A$2:$B$227,2,FALSE),"") -> 3802014 | K19: =COUNTIF($A$2:$A$1757,A19) -> 8 | L19: {=_xlfn.IFS(B19=2015,G19/$P$13,B19=2016,G19/$P$14,B19=2017,G19/$P$15,B19=2018,G19/$P$16,B19=2019,G19/$P$17,B19=2019,G19/$P$18,B19=2020,G19/$P$18,B19=2021,G19/$P$19,B19=2022,G19/$P$20)} -> 0.00053132589 | O19: 2021 | P19: =SUMIF($B$2:$B$1757,O19,$G$2:$G$1757) -> 98264206
A20: 3802014 | B20: 2017 | C20: North Dakota | D20: ND | E20: North Dakota Teachers' Fund for Retirement | F20: Apple Creek Elem School | G20: 44335 | H20: {=_xlfn.IFS(B20=2015,L20*$P$3,B20=2016,L20*$P$4,B20=2017,L20*$P$5,B20=2018,L20*$P$6,B20=2019,L20*$P$7,B20=2020,L20*$P$8,B20=2021,L20*$P$9,B20=2022,L20*$P$10)} -> 1436.8109 | I20: =SUM(G20:H20) -> 45771.811 | J20: =IFERROR(VLOOKUP(F20,'LEAID Match'!$A$2:$B$227,2,FALSE),"") -> 3802014 | K20: =COUNTIF($A$2:$A$1757,A20) -> 8 | L20: {=_xlfn.IFS(B20=2015,G20/$P$13,B20=2016,G20/$P$14,B20=2017,G20/$P$15,B20=2018,G20/$P$16,B20=2019,G20/$P$17,B20=2019,G20/$P$18,B20=2020,G20/$P$18,B20=2021,G20/$P$19,B20=2022,G20/$P$20)} -> 0.00051517065 | O20: 2022 | P20: =SUMIF($B$2:$B$1757,O20,$G$2:$G$1757) -> 100331344
A21: 3802014 | B21: 2018 | C21: North Dakota | D21: ND | E21: North Dakota Teachers' Fund for Retirement | F21: Apple Creek Elem School | G21: 38582 | H21: {=_xlfn.IFS(B21=2015,L21*$P$3,B21=2016,L21*$P$4,B21=2017,L21*$P$5,B21=2018,L21*$P$6,B21=2019,L21*$P$7,B21=2020,L21*$P$8,B21=2021,L21*$P$9,B21=2022,L21*$P$10)} -> 1057.1849 | I21: =SUM(G21:H21) -> 39639.185 | J21: =IFERROR(VLOOKUP(F21,'LEAID Match'!$A$2:$B$227,2,FALSE),"") -> 3802014 | K21: =COUNTIF($A$2:$A$1757,A21) -> 8 | L21: {=_xlfn.IFS(B21=2015,G21/$P$13,B21=2016,G21/$P$14,B21=2017,G21/$P$15,B21=2018,G21/$P$16,B21=2019,G21/$P$17,B21=2019,G21/$P$18,B21=2020,G21/$P$18,B21=2021,G21/$P$19,B21=2022,G21/$P$20)} -> 0.0004451305
A22: 3802014 | B22: 2019 | C22: North Dakota | D22: ND | E22: North Dakota Teachers' Fund for Retirement | F22: Apple Creek Elem School | G22: 37940 | H22: {=_xlfn.IFS(B22=2015,L22*$P$3,B22=2016,L22*$P$4,B22=2017,L22*$P$5,B22=2018,L22*$P$6,B22=2019,L22*$P$7,B22=2020,L22*$P$8,B22=2021,L22*$P$9,B22=2022,L22*$P$10)} -> 880.58076 | I22: =SUM(G22:H22) -> 38820.581 | J22: =IFERROR(VLOOKUP(F22,'LEAID Match'!$A$2:$B$227,2,FALSE),"") -> 3802014 | K22: =COUNTIF($A$2:$A$1757,A22) -> 8 | L22: {=_xlfn.IFS(B22=2015,G22/$P$13,B22=2016,G22/$P$14,B22=2017,G22/$P$15,B22=2018,G22/$P$16,B22=2019,G22/$P$17,B22=2019,G22/$P$18,B22=2020,G22/$P$18,B22=2021,G22/$P$19,B22=2022,G22/$P$20)} -> 0.00042417185 | N22: check | O22: 2015 | P22: =SUMIF($B$2:$B$1757,O22,$L$2:$L$1757) -> 1
A23: 3802014 | B23: 2020 | C23: North Dakota | D23: ND | E23: North Dakota Teachers' Fund for Retirement | F23: Apple Creek Elem School | G23: 39944 | H23: {=_xlfn.IFS(B23=2015,L23*$P$3,B23=2016,L23*$P$4,B23=2017,L23*$P$5,B23=2018,L23*$P$6,B23=2019,L23*$P$7,B23=2020,L23*$P$8,B23=2021,L23*$P$9,B23=2022,L23*$P$10)} -> 1002.1158 | I23: =SUM(G23:H23) -> 40946.116 | J23: =IFERROR(VLOOKUP(F23,'LEAID Match'!$A$2:$B$227,2,FALSE),"") -> 3802014 | K23: =COUNTIF($A$2:$A$1757,A23) -> 8 | L23: {=_xlfn.IFS(B23=2015,G23/$P$13,B23=2016,G23/$P$14,B23=2017,G23/$P$15,B23=2018,G23/$P$16,B23=2019,G23/$P$17,B23=2019,G23/$P$18,B23=2020,G23/$P$18,B23=2021,G23/$P$19,B23=2022,G23/$P$20)} -> 0.00042935553 | O23: 2016 | P23: =SUMIF($B$2:$B$1757,O23,$L$2:$L$1757) -> 1
A24: 3802014 | B24: 2021 | C24: North Dakota | D24: ND | E24: North Dakota Teachers' Fund for Retirement | F24: Apple Creek Elem School | G24: 45212 | H24: {=_xlfn.IFS(B24=2015,L24*$P$3,B24=2016,L24*$P$4,B24=2017,L24*$P$5,B24=2018,L24*$P$6,B24=2019,L24*$P$7,B24=2020,L24*$P$8,B24=2021,L24*$P$9,B24=2022,L24*$P$10)} -> 1235.386 | I24: =SUM(G24:H24) -> 46447.386 | J24: =IFERROR(VLOOKUP(F24,'LEAID Match'!$A$2:$B$227,2,FALSE),"") -> 3802014 | K24: =COUNTIF($A$2:$A$1757,A24) -> 8 | L24: {=_xlfn.IFS(B24=2015,G24/$P$13,B24=2016,G24/$P$14,B24=2017,G24/$P$15,B24=2018,G24/$P$16,B24=2019,G24/$P$17,B24=2019,G24/$P$18,B24=2020,G24/$P$18,B24=2021,G24/$P$19,B24=2022,G24/$P$20)} -> 0.0004601065 | O24: 2017 | P24: =SUMIF($B$2:$B$1757,O24,$L$2:$L$1757) -> 1
A25: 3802014 | B25: 2022 | C25: North Dakota | D25: ND | E25: North Dakota Teachers' Fund for Retirement | F25: Apple Creek Elem School | G25: 52680 | H25: {=_xlfn.IFS(B25=2015,L25*$P$3,B25=2016,L25*$P$4,B25=2017,L25*$P$5,B25=2018,L25*$P$6,B25=2019,L25*$P$7,B25=2020,L25*$P$8,B25=2021,L25*$P$9,B25=2022,L25*$P$10)} -> 1072.173 | I25: =SUM(G25:H25) -> 53752.173 | J25: =IFERROR(VLOOKUP(F25,'LEAID Match'!$A$2:$B$227,2,FALSE),"") -> 3802014 | K25: =COUNTIF($A$2:$A$1757,A25) -> 8 | L25: {=_xlfn.IFS(B25=2015,G25/$P$13,B25=2016,G25/$P$14,B25=2017,G25/$P$15,B25=2018,G25/$P$16,B25=2019,G25/$P$17,B25=2019,G25/$P$18,B25=2020,G25/$P$18,B25=2021,G25/$P$19,B25=2022,G25/$P$20)} -> 0.00052506024 | O25: 2018 | P25: =SUMIF($B$2:$B$1757,O25,$L$2:$L$1757) -> 1
A26: 3802170 | B26: 2015 | C26: North Dakota | D26: ND | E26: North Dakota Teachers' Fund for Retirement | F26: Ashley School | G26: 119917 | H26: {=_xlfn.IFS(B26=2015,L26*$P$3,B26=2016,L26*$P$4,B26=2017,L26*$P$5,B26=2018,L26*$P$6,B26=2019,L26*$P$7,B26=2020,L26*$P$8,B26=2021,L26*$P$9,B26=2022,L26*$P$10)} -> 2711.1342 | I26: =SUM(G26:H26) -> 122628.13 | J26: =IFERROR(VLOOKUP(F26,'LEAID Match'!$A$2:$B$227,2,FALSE),"") -> 3802170 | K26: =COUNTIF($A$2:$A$1757,A26) -> 8 | L26: {=_xlfn.IFS(B26=2015,G26/$P$13,B26=2016,G26/$P$14,B26=2017,G26/$P$15,B26=2018,G26/$P$16,B26=2019,G26/$P$17,B26=2019,G26/$P$18,B26=2020,G26/$P$18,B26=2021,G26/$P$19,B26=2022,G26/$P$20)} -> 0.0015291225 | O26: 2019 | P26: =SUMIF($B$2:$B$1757,O26,$L$2:$L$1757) -> 1
A27: 3802170 | B27: 2016 | C27: North Dakota | D27: ND | E27: North Dakota Teachers' Fund for Retirement | F27: Ashley School | G27: 121244 | H27: {=_xlfn.IFS(B27=2015,L27*$P$3,B27=2016,L27*$P$4,B27=2017,L27*$P$5,B27=2018,L27*$P$6,B27=2019,L27*$P$7,B27=2020,L27*$P$8,B27=2021,L27*$P$9,B27=2022,L27*$P$10)} -> 4117.089 | I27: =SUM(G27:H27) -> 125361.09 | J27: =IFERROR(VLOOKUP(F27,'LEAID Match'!$A$2:$B$227,2,FALSE),"") -> 3802170 | K27: =COUNTIF($A$2:$A$1757,A27) -> 8 | L27: {=_xlfn.IFS(B27=2015,G27/$P$13,B27=2016,G27/$P$14,B27=2017,G27/$P$15,B27=2018,G27/$P$16,B27=2019,G27/$P$17,B27=2019,G27/$P$18,B27=2020,G27/$P$18,B27=2021,G27/$P$19,B27=2022,G27/$P$20)} -> 0.0014635937 | O27: 2020 | P27: =SUMIF($B$2:$B$1757,O27,$L$2:$L$1757) -> 1
A28: 3802170 | B28: 2017 | C28: North Dakota | D28: ND | E28: North Dakota Teachers' Fund for Retirement | F28: Ashley School | G28: 121027 | H28: {=_xlfn.IFS(B28=2015,L28*$P$3,B28=2016,L28*$P$4,B28=2017,L28*$P$5,B28=2018,L28*$P$6,B28=2019,L28*$P$7,B28=2020,L28*$P$8,B28=2021,L28*$P$9,B28=2022,L28*$P$10)} -> 3922.2492 | I28: =SUM(G28:H28) -> 124949.25 | J28: =IFERROR(VLOOKUP(F28,'LEAID Match'!$A$2:$B$227,2,FALSE),"") -> 3802170 | K28: =COUNTIF($A$2:$A$1757,A28) -> 8 | L28: {=_xlfn.IFS(B28=2015,G28/$P$13,B28=2016,G28/$P$14,B28=2017,G28/$P$15,B28=2018,G28/$P$16,B28=2019,G28/$P$17,B28=2019,G28/$P$18,B28=2020,G28/$P$18,B28=2021,G28/$P$19,B28=2022,G28/$P$20)} -> 0.0014063281 | O28: 2021 | P28: =SUMIF($B$2:$B$1757,O28,$L$2:$L$1757) -> 1
A29: 3802170 | B29: 2018 | C29: North Dakota | D29: ND | E29: North Dakota Teachers' Fund for Retirement | F29: Ashley School | G29: 120772 | H29: {=_xlfn.IFS(B29=2015,L29*$P$3,B29=2016,L29*$P$4,B29=2017,L29*$P$5,B29=2018,L29*$P$6,B29=2019,L29*$P$7,B29=2020,L29*$P$8,B29=2021,L29*$P$9,B29=2022,L29*$P$10)} -> 3309.2722 | I29: =SUM(G29:H29) -> 124081.27 | J29: =IFERROR(VLOOKUP(F29,'LEAID Match'!$A$2:$B$227,2,FALSE),"") -> 3802170 | K29: =COUNTIF($A$2:$A$1757,A29) -> 8 | L29: {=_xlfn.IFS(B29=2015,G29/$P$13,B29=2016,G29/$P$14,B29=2017,G29/$P$15,B29=2018,G29/$P$16,B29=2019,G29/$P$17,B29=2019,G29/$P$18,B29=2020,G29/$P$18,B29=2021,G29/$P$19,B29=2022,G29/$P$20)} -> 0.0013933778 | O29: 2022 | P29: =SUMIF($B$2:$B$1757,O29,$L$2:$L$1757) -> 1
A30: 3802170 | B30: 2019 | C30: North Dakota | D30: ND | E30: North Dakota Teachers' Fund for Retirement | F30: Ashley School | G30: 123550 | H30: {=_xlfn.IFS(B30=2015,L30*$P$3,B30=2016,L30*$P$4,B30=2017,L30*$P$5,B30=2018,L30*$P$6,B30=2019,L30*$P$7,B30=2020,L30*$P$8,B30=2021,L30*$P$9,B30=2022,L30*$P$10)} -> 2867.5739 | I30: =SUM(G30:H30) -> 126417.57 | J30: =IFERROR(VLOOKUP(F30,'LEAID Match'!$A$2:$B$227,2,FALSE),"") -> 3802170 | K30: =COUNTIF($A$2:$A$1757,A30) -> 8 | L30: {=_xlfn.IFS(B30=2015,G30/$P$13,B30=2016,G30/$P$14,B30=2017,G30/$P$15,B30=2018,G30/$P$16,B30=2019,G30/$P$17,B30=2019,G30/$P$18,B30=2020,G30/$P$18,B30=2021,G30/$P$19,B30=2022,G30/$P$20)} -> 0.0013812976
A31: 3802170 | B31: 2020 | C31: North Dakota | D31: ND | E31: North Dakota Teachers' Fund for Retirement | F31: Ashley School | G31: 125671 | H31: {=_xlfn.IFS(B31=2015,L31*$P$3,B31=2016,L31*$P$4,B31=2017,L31*$P$5,B31=2018,L31*$P$6,B31=2019,L31*$P$7,B31=2020,L31*$P$8,B31=2021,L31*$P$9,B31=2022,L31*$P$10)} -> 3152.8363 | I31: =SUM(G31:H31) -> 128823.84 | J31: =IFERROR(VLOOKUP(F31,'LEAID Match'!$A$2:$B$227,2,FALSE),"") -> 3802170 | K31: =COUNTIF($A$2:$A$1757,A31) -> 8 | L31: {=_xlfn.IFS(B31=2015,G31/$P$13,B31=2016,G31/$P$14,B31=2017,G31/$P$15,B31=2018,G31/$P$16,B31=2019,G31/$P$17,B31=2019,G31/$P$18,B31=2020,G31/$P$18,B31=2021,G31/$P$19,B31=2022,G31/$P$20)} -> 0.0013508296
A32: 3802170 | B32: 2021 | C32: North Dakota | D32: ND | E32: North Dakota Teachers' Fund for Retirement | F32: Ashley School | G32: 136295 | H32: {=_xlfn.IFS(B32=2015,L32*$P$3,B32=2016,L32*$P$4,B32=2017,L32*$P$5,B32=2018,L32*$P$6,B32=2019,L32*$P$7,B32=2020,L32*$P$8,B32=2021,L32*$P$9,B32=2022,L32*$P$10)} -> 3724.1646 | I32: =SUM(G32:H32) -> 140019.16 | J32: =IFERROR(VLOOKUP(F32,'LEAID Match'!$A$2:$B$227,2,FALSE),"") -> 3802170 | K32: =COUNTIF($A$2:$A$1757,A32) -> 8 | L32: {=_xlfn.IFS(B32=2015,G32/$P$13,B32=2016,G32/$P$14,B32=2017,G32/$P$15,B32=2018,G32/$P$16,B32=2019,G32/$P$17,B32=2019,G32/$P$18,B32=2020,G32/$P$18,B32=2021,G32/$P$19,B32=2022,G32/$P$20)} -> 0.0013870259
A33: 3802170 | B33: 2022 | C33: North Dakota | D33: ND | E33: North Dakota Teachers' Fund for Retirement | F33: Ashley School | G33: 133921 | H33: {=_xlfn.IFS(B33=2015,L33*$P$3,B33=2016,L33*$P$4,B33=2017,L33*$P$5,B33=2018,L33*$P$6,B33=2019,L33*$P$7,B33=2020,L33*$P$8,B33=2021,L33*$P$9,B33=2022,L33*$P$10)} -> 2725.6356 | I33: =SUM(G33:H33) -> 136646.64 | J33: =IFERROR(VLOOKUP(F33,'LEAID Match'!$A$2:$B$227,2,FALSE),"") -> 3802170 | K33: =COUNTIF($A$2:$A$1757,A33) -> 8 | L33: {=_xlfn.IFS(B33=2015,G33/$P$13,B33=2016,G33/$P$14,B33=2017,G33/$P$15,B33=2018,G33/$P$16,B33=2019,G33/$P$17,B33=2019,G33/$P$18,B33=2020,G33/$P$18,B33=2021,G33/$P$19,B33=2022,G33/$P$20)} -> 0.0013347873
A34: 3802240 | B34: 2015 | C34: North Dakota | D34: ND | E34: North Dakota Teachers' Fund for Retirement | F34: Bakker Elem School | G34: 4399 | H34: {=_xlfn.IFS(B34=2015,L34*$P$3,B34=2016,L34*$P$4,B34=2017,L34*$P$5,B34=2018,L34*$P$6,B34=2019,L34*$P$7,B34=2020,L34*$P$8,B34=2021,L34*$P$9,B34=2022,L34*$P$10)} -> 99.454452 | I34: =SUM(G34:H34) -> 4498.4545 | J34: =IFERROR(VLOOKUP(F34,'LEAID Match'!$A$2:$B$227,2,FALSE),"") -> 3802240 | K34: =COUNTIF($A$2:$A$1757,A34) -> 8 | L34: {=_xlfn.IFS(B34=2015,G34/$P$13,B34=2016,G34/$P$14,B34=2017,G34/$P$15,B34=2018,G34/$P$16,B34=2019,G34/$P$17,B34=2019,G34/$P$18,B34=2020,G34/$P$18,B34=2021,G34/$P$19,B34=2022,G34/$P$20)} -> 5.6093882e-05
A35: 3802240 | B35: 2016 | C35: North Dakota | D35: ND | E35: North Dakota Teachers' Fund for Retirement | F35: Bakker Elem School | G35: 4399 | H35: {=_xlfn.IFS(B35=2015,L35*$P$3,B35=2016,L35*$P$4,B35=2017,L35*$P$5,B35=2018,L35*$P$6,B35=2019,L35*$P$7,B35=2020,L35*$P$8,B35=2021,L35*$P$9,B35=2022,L35*$P$10)} -> 149.37708 | I35: =SUM(G35:H35) -> 4548.3771 | J35: =IFERROR(VLOOKUP(F35,'LEAID Match'!$A$2:$B$227,2,FALSE),"") -> 3802240 | K35: =COUNTIF($A$2:$A$1757,A35) -> 8 | L35: {=_xlfn.IFS(B35=2015,G35/$P$13,B35=2016,G35/$P$14,B35=2017,G35/$P$15,B35=2018,G35/$P$16,B35=2019,G35/$P$17,B35=2019,G35/$P$18,B35=2020,G35/$P$18,B35=2021,G35/$P$19,B35=2022,G35/$P$20)} -> 5.310241e-05
A36: 3802240 | B36: 2017 | C36: North Dakota | D36: ND | E36: North Dakota Teachers' Fund for Retirement | F36: Bakker Elem School | G36: 4845 | H36: {=_xlfn.IFS(B36=2015,L36*$P$3,B36=2016,L36*$P$4,B36=2017,L36*$P$5,B36=2018,L36*$P$6,B36=2019,L36*$P$7,B36=2020,L36*$P$8,B36=2021,L36*$P$9,B36=2022,L36*$P$10)} -> 157.01701 | I36: =SUM(G36:H36) -> 5002.017 | J36: =IFERROR(VLOOKUP(F36,'LEAID Match'!$A$2:$B$227,2,FALSE),"") -> 3802240 | K36: =COUNTIF($A$2:$A$1757,A36) -> 8 | L36: {=_xlfn.IFS(B36=2015,G36/$P$13,B36=2016,G36/$P$14,B36=2017,G36/$P$15,B36=2018,G36/$P$16,B36=2019,G36/$P$17,B36=2019,G36/$P$18,B36=2020,G36/$P$18,B36=2021,G36/$P$19,B36=2022,G36/$P$20)} -> 5.6298675e-05
A37: 3802240 | B37: 2018 | C37: North Dakota | D37: ND | E37: North Dakota Teachers' Fund for Retirement | F37: Bakker Elem School | G37: 5227 | H37: {=_xlfn.IFS(B37=2015,L37*$P$3,B37=2016,L37*$P$4,B37=2017,L37*$P$5,B37=2018,L37*$P$6,B37=2019,L37*$P$7,B37=2020,L37*$P$8,B37=2021,L37*$P$9,B37=2022,L37*$P$10)} -> 143.22497 | I37: =SUM(G37:H37) -> 5370.225 | J37: =IFERROR(VLOOKUP(F37,'LEAID Match'!$A$2:$B$227,2,FALSE),"") -> 3802240 | K37: =COUNTIF($A$2:$A$1757,A37) -> 8 | L37: {=_xlfn.IFS(B37=2015,G37/$P$13,B37=2016,G37/$P$14,B37=2017,G37/$P$15,B37=2018,G37/$P$16,B37=2019,G37/$P$17,B37=2019,G37/$P$18,B37=2020,G37/$P$18,B37=2021,G37/$P$19,B37=2022,G37/$P$20)} -> 6.0305249e-05
A38: 3802240 | B38: 2019 | C38: North Dakota | D38: ND | E38: North Dakota Teachers' Fund for Retirement | F38: Bakker Elem School | G38: 5549 | H38: {=_xlfn.IFS(B38=2015,L38*$P$3,B38=2016,L38*$P$4,B38=2017,L38*$P$5,B38=2018,L38*$P$6,B38=2019,L38*$P$7,B38=2020,L38*$P$8,B38=2021,L38*$P$9,B38=2022,L38*$P$10)} -> 128.79132 | I38: =SUM(G38:H38) -> 5677.7913 | J38: =IFERROR(VLOOKUP(F38,'LEAID Match'!$A$2:$B$227,2,FALSE),"") -> 3802240 | K38: =COUNTIF($A$2:$A$1757,A38) -> 8 | L38: {=_xlfn.IFS(B38=2015,G38/$P$13,B38=2016,G38/$P$14,B38=2017,G38/$P$15,B38=2018,G38/$P$16,B38=2019,G38/$P$17,B38=2019,G38/$P$18,B38=2020,G38/$P$18,B38=2021,G38/$P$19,B38=2022,G38/$P$20)} -> 6.2038207e-05
A39: 3802240 | B39: 2020 | C39: North Dakota | D39: ND | E39: North Dakota Teachers' Fund for Retirement | F39: Bakker Elem School | G39: 5993 | H39: {=_xlfn.IFS(B39=2015,L39*$P$3,B39=2016,L39*$P$4,B39=2017,L39*$P$5,B39=2018,L39*$P$6,B39=2019,L39*$P$7,B39=2020,L39*$P$8,B39=2021,L39*$P$9,B39=2022,L39*$P$10)} -> 150.35249 | I39: =SUM(G39:H39) -> 6143.3525 | J39: =IFERROR(VLOOKUP(F39,'LEAID Match'!$A$2:$B$227,2,FALSE),"") -> 3802240 | K39: =COUNTIF($A$2:$A$1757,A39) -> 8 | L39: {=_xlfn.IFS(B39=2015,G39/$P$13,B39=2016,G39/$P$14,B39=2017,G39/$P$15,B39=2018,G39/$P$16,B39=2019,G39/$P$17,B39=2019,G39/$P$18,B39=2020,G39/$P$18,B39=2021,G39/$P$19,B39=2022,G39/$P$20)} -> 6.4418378e-05
A40: 3802240 | B40: 2021 | C40: North Dakota | D40: ND | E40: North Dakota Teachers' Fund for Retirement | F40: Bakker Elem School | G40: 7022 | H40: {=_xlfn.IFS(B40=2015,L40*$P$3,B40=2016,L40*$P$4,B40=2017,L40*$P$5,B40=2018,L40*$P$6,B40=2019,L40*$P$7,B40=2020,L40*$P$8,B40=2021,L40*$P$9,B40=2022,L40*$P$10)} -> 191.87119 | I40: =SUM(G40:H40) -> 7213.8712 | J40: =IFERROR(VLOOKUP(F40,'LEAID Match'!$A$2:$B$227,2,FALSE),"") -> 3802240 | K40: =COUNTIF($A$2:$A$1757,A40) -> 8 | L40: {=_xlfn.IFS(B40=2015,G40/$P$13,B40=2016,G40/$P$14,B40=2017,G40/$P$15,B40=2018,G40/$P$16,B40=2019,G40/$P$17,B40=2019,G40/$P$18,B40=2020,G40/$P$18,B40=2021,G40/$P$19,B40=2022,G40/$P$20)} -> 7.1460405e-05
...

Sheet GASB 68 Data -->

Sheet 2015
A1: Year | B1: Employer Name | C1: Employer's Proportionate Share Allocation | D1: Statutory Required Contribution
A2: 2015 | B2: Hettinger School | C2: 0.0023907 | D2: 187484
A3: 2015 | B3: Hillsboro School | C3: 0.00379546 | D3: 297648
A4: 2015 | B4: Hope School | C4: 0.00096912 | D4: 76000
A5: 2015 | B5: Horse Creek Elem. School | C5: 5.609e-05 | D5: 4399
A6: 2015 | B6: James River Multidistrict Spec Ed Unit | C6: 0.00203633 | D6: 159693
A7: 2015 | B7: Jamestown School | C7: 0.02088696 | D7: 1637999
A8: 2015 | B8: Kenmare School | C8: 0.00269469 | D8: 211323
A9: 2015 | B9: Kensal School | C9: 0.00067714 | D9: 53103
A10: 2015 | B10: Kidder County School District | C10: 0.00343549 | D10: 269418
A11: 2015 | B11: Killdeer School | C11: 0.00414983 | D11: 325438
A12: 2015 | B12: Kindred School | C12: 0.00496501 | D12: 389367
A13: 2015 | B13: Kulm School | C13: 0.00170658 | D13: 133834
... A81: 2015 | B81: Bismarck Public Schools | C81: 0.10783616 | D81: 8456738
A82: 2015 | B82: Bismarck State College | C82: 0
A83: 2015 | B83: Blessed John Paul II Catholic Sch Network | C83: 5.018e-05 | D83: 3935
A84: 2015 | B84: Bottineau School | C84: 0.00599059 | D84: 469795
A85: 2015 | B85: Bowbells School | C85: 0.00084862 | D85: 66551
A86: 2015 | B86: Bowman School | C86: 0.00443419 | D86: 347738
A87: 2015 | B87: Burke Central School | C87: 0.00121295 | D87: 95122
A88: 2015 | B88: Burleigh County Spec. Ed. | C88: 0.00014215 | D88: 11148
A89: 2015 | B89: Carrington School | C89: 0.00463644 | D89: 363599
A90: 2015 | B90: Cavalier School | C90: 0.0034918 | D90: 273834
A91: 2015 | B91: Center Stanton School | C91: 0.00230316 | D91: 180619
A92: 2015 | B92: Central Cass School | C92: 0.00557285 | D92: 437035
A93: 2015 | B93: Central Elementary School | C93: 0.00010393 | D93: 8150
A94: 2015 | B94: Central Valley School | C94: 0.00200824 | D94: 157490
... A157: 2015 | B157: Pingree - Buchanan School | C157: 0.00125338 | D157: 98293
A158: 2015 | B158: Pleasant Valley Elem | C158: 0
A159: 2015 | B159: Powers Lake School | C159: 0.00165744 | D159: 129980
A160: 2015 | B160: Richardton-Taylor | C160: 0.00275564 | D160: 216103
A161: 2015 | B161: Richland School | C161: 0.00255007 | D161: 199982
A162: 2015 | B162: Robinson School | C162: 6.053e-05 | D162: 4747
A163: 2015 | B163: Rolette County | C163: 0
A164: 2015 | B164: Rolette School | C164: 0.00187669 | D164: 147174
A165: 2015 | B165: Roosevelt School | C165: 0.00061829 | D165: 48488
A166: 2015 | B166: Roughrider Area Career And Tech Center | C166: 0.00026034 | D166: 20416
A167: 2015 | B167: Roughrider Service Program | C167: 0.00031103 | D167: 24392
A168: 2015 | B168: Rugby School | C168: 0.00500036 | D168: 392139
A169: 2015 | B169: Rural Cass Spec Ed | C169: 0.00166809 | D169: 130815
...

Sheet 2016
A1: Year | B1: Employer Name | C1: Employer's Proportionate Share Allocation | D1: Statutory Required Contribution
A2: 2016 | B2: Alexander School | C2: 0.0018082264 | D2: 149793
A3: 2016 | B3: Anamoose School | C3: 0.0011110816 | D3: 92042
A4: 2016 | B4: Apple Creek Elem School | C4: 0.0005313226 | D4: 44015
A5: 2016 | B5: Ashley School | C5: 0.0014635934 | D5: 121244
A6: 2016 | B6: Bakker Elem School | C6: 5.30994e-05 | D6: 4399
A7: 2016 | B7: Barnes County North | C7: 0.0024426476 | D7: 202349
A8: 2016 | B8: Beach School | C8: 0.0032910704 | D8: 272632
A9: 2016 | B9: Belcourt School | C9: 0.012791303 | D9: 1059631
A10: 2016 | B10: Belfield Public School | C10: 0.0022790756 | D10: 188798
A11: 2016 | B11: Beulah School | C11: 0.0052676803 | D11: 436374
A12: 2016 | B12: Billings Co. School Dist. | C12: 0.0011667315 | D12: 96652
A13: 2016 | B13: Bismarck Public Schools | C13: 0.10654036 | D13: 8825796
A14: 2016 | B14: Bismarck State College | C14: 0
A15: 2016 | B15: Blessed John Paul II Catholic Sch Network | C15: 0
A16: 2016 | B16: Bottineau School | C16: 0.0057864088 | D16: 479346
A17: 2016 | B17: Bowbells School | C17: 0.0008520072 | D17: 70580
A18: 2016 | B18: Bowman School | C18: 0.0042451206 | D18: 351666
A19: 2016 | B19: Burke Central School | C19: 0.0014695981 | D19: 121741
A20: 2016 | B20: Burleigh County Spec. Ed. | C20: 0.0001322689 | D20: 10957
A21: 2016 | B21: Carrington School | C21: 0.0045614091 | D21: 377867
A22: 2016 | B22: Cavalier School | C22: 0.0034367967 | D22: 284704
A23: 2016 | B23: Center Stanton School | C23: 0.0022374025 | D23: 185346
A24: 2016 | B24: Central Cass School | C24: 0.0053225813 | D24: 440922
A25: 2016 | B25: Central Elementary School | C25: 9.68396e-05 | D25: 8022
A26: 2016 | B26: Central Valley School | C26: 0.0018948599 | D26: 156970
A27: 2016 | B27: Dakota Prairie School | C27: 0.0028724742 | D27: 237956
... A157: 2016 | B157: Pingree - Buchanan School | C157: 0.0012689965 | D157: 105124
A158: 2016 | B158: Pleasant Valley Elem | C158: 0 | D158: -
A159: 2016 | B159: Powers Lake School | C159: 0.0017365859 | D159: 143859
A160: 2016 | B160: Richardton-Taylor | C160: 0.0026397999 | D160: 218681
A161: 2016 | B161: Richland School | C161: 0.0022294717 | D161: 184689
A162: 2016 | B162: Robinson School | C162: 0 | D162: -
A163: 2016 | B163: Rolette County | C163: 0 | D163: -
A164: 2016 | B164: Rolette School | C164: 0.0018543398 | D164: 153613
A165: 2016 | B165: Roosevelt School | C165: 0.0006548723 | D165: 54250
A166: 2016 | B166: Roughrider Area Career And Tech Center | C166: 0.0001468699 | D166: 12167
A167: 2016 | B167: Roughrider Service Program | C167: 0.0004661696 | D167: 38617
A168: 2016 | B168: Rugby School | C168: 0.0049502824 | D168: 410081
A169: 2016 | B169: Rural Cass Spec Ed | C169: 0.0016670854 | D169: 138101
...

Sheet 2017
A1: Year | B1: Employer Name | C1: Employer's Proportionate Share Allocation | D1: Statutory Required Contribution
A2: 2017 | B2: Alexander School | C2: 0.0017806399 | D2: 153240
A3: 2017 | B3: Anamoose School | C3: 0.0011321014 | D3: 97427
A4: 2017 | B4: Apple Creek Elem School | C4: 0.0005151764 | D4: 44335
A5: 2017 | B5: Ashley School | C5: 0.0014063328 | D5: 121027
A6: 2017 | B6: Bakker Elem School | C6: 5.62987e-05 | D6: 4845
A7: 2017 | B7: Barnes County North | C7: 0.0024012753 | D7: 206651
A8: 2017 | B8: Beach School | C8: 0.0030984007 | D8: 266645
A9: 2017 | B9: Belcourt School | C9: 0.012474897 | D9: 1073575
A10: 2017 | B10: Belfield Public School | C10: 0.0022096375 | D10: 190159
A11: 2017 | B11: Beulah School | C11: 0.0050863139 | D11: 437722
A12: 2017 | B12: Billings Co. School Dist. | C12: 0.0012333776 | D12: 106143
A13: 2017 | B13: Bismarck Public Schools | C13: 0.10790804 | D13: 9286444
A14: 2017 | B14: Bismarck State College | C14: 0
A15: 2017 | B15: Blessed John Paul II Catholic Sch Network | C15: 0
A16: 2017 | B16: Bottineau School | C16: 0.0053898062 | D16: 463841
A17: 2017 | B17: Bowbells School | C17: 0.0009296183 | D17: 80002
A18: 2017 | B18: Bowman School | C18: 0.0042070099 | D18: 362051
A19: 2017 | B19: Burke Central School | C19: 0.0013875068 | D19: 119407
A20: 2017 | B20: Burleigh County Spec. Ed. | C20: 0.0001417803 | D20: 12201
A21: 2017 | B21: Carrington School | C21: 0.0042749362 | D21: 367896
A22: 2017 | B22: Cavalier School | C22: 0.0033393501 | D22: 287381
A23: 2017 | B23: Center Stanton School | C23: 0.0022226779 | D23: 191281
A24: 2017 | B24: Central Cass School | C24: 0.0053879722 | D24: 463683
A25: 2017 | B25: Central Elementary School | C25: 9.11657e-05 | D25: 7846
A26: 2017 | B26: Central Valley School | C26: 0.0018835583 | D26: 162097
A27: 2017 | B27: Dakota Prairie School | C27: 0.0027978617 | D27: 240781
... A157: 2017 | B157: Pingree - Buchanan School | C157: 0.0012620413 | D157: 108610
A158: 2017 | B158: Pleasant Valley Elem | C158: 0
A159: 2017 | B159: Powers Lake School | C159: 0.001656461 | D159: 142553
A160: 2017 | B160: Richardton-Taylor | C160: 0.0026405936 | D160: 227246
A161: 2017 | B161: Richland School | C161: 0.0023303384 | D161: 200546
A162: 2017 | B162: Robinson School | C162: 0
A163: 2017 | B163: Rolette County | C163: 0
A164: 2017 | B164: Rolette School | C164: 0.0019429381 | D164: 167207
A165: 2017 | B165: Roosevelt School | C165: 0.0005284922 | D165: 45481
A166: 2017 | B166: Roughrider Area Career And Tech Center | C166: 0.0002049717 | D166: 17640
A167: 2017 | B167: Roughrider Service Program | C167: 0.000452437 | D167: 38936
A168: 2017 | B168: Rugby School | C168: 0.0049268855 | D168: 424002
A169: 2017 | B169: Rural Cass Spec Ed | C169: 0.0014503356 | D169: 124814
...

Sheet 2018
A1: Year | B1: Employer Name | C1: Employer's Proportionate Share Allocation | D1: Statutory Required Contribution
A2: 2018 | B2: Alexander School | C2: 0.0018056775 | D2: 156508
A3: 2018 | B3: Anamoose School | C3: 0.0011364838 | D3: 98506
A4: 2018 | B4: Apple Creek Elem School | C4: 0.0004451281 | D4: 38582
A5: 2018 | B5: Ashley School | C5: 0.0013933825 | D5: 120772
A6: 2018 | B6: Bakker Elem School | C6: 6.0311e-05 | D6: 5227
A7: 2018 | B7: Barnes County North | C7: 0.0022929762 | D7: 198745
A8: 2018 | B8: Beach School | C8: 0.003055944 | D8: 264876
A9: 2018 | B9: Belcourt School | C9: 0.012653409 | D9: 1096743
A10: 2018 | B10: Belfield Public School | C10: 0.0022847865 | D10: 198036
A11: 2018 | B11: Beulah School | C11: 0.005307094 | D11: 459996
A12: 2018 | B12: Billings Co. School Dist. | C12: 0.0012545235 | D12: 108737
A13: 2018 | B13: Bismarck Public Schools | C13: 0.10706402 | D13: 9279851
A14: 2018 | B14: Bismarck State College | C14: 0
A15: 2018 | B15: Blessed John Paul II Catholic Sch Network | C15: 0
A16: 2018 | B16: Bottineau School | C16: 0.0055666726 | D16: 482495
A17: 2018 | B17: Bowbells School | C17: 0.0008923249 | D17: 77343
A18: 2018 | B18: Bowman School | C18: 0.0042468449 | D18: 368098
A19: 2018 | B19: Burke Central School | C19: 0.0015325054 | D19: 132831
A20: 2018 | B20: Burleigh County Spec. Ed. | C20: 0.0001522871 | D20: 13200
A21: 2018 | B21: Carrington School | C21: 0.0043232212 | D21: 374718
A22: 2018 | B22: Cavalier School | C22: 0.0032760664 | D22: 283955
A23: 2018 | B23: Center Stanton School | C23: 0.0023119771 | D23: 200392
A24: 2018 | B24: Central Cass School | C24: 0.0053881875 | D24: 467025
A25: 2018 | B25: Central Elementary School | C25: 9.40373e-05 | D25: 8151
A26: 2018 | B26: Central Valley School | C26: 0.0019074831 | D26: 165332
A27: 2018 | B27: Dakota Prairie School | C27: 0.0029803638 | D27: 258325
... A123: 2018 | B123: Munich School | C123: 0.0014996072 | D123: 129980
A124: 2018 | B124: N Central Area Career And Tech Center | C124: 0
A125: 2018 | B125: Napoleon School | C125: 0.0022890714 | D125: 198407
A126: 2018 | B126: Naughton Rural School | C126: 0.0001393664 | D126: 12080
A127: 2018 | B127: Nd Center For Distance Education | C127: 0.0020156057 | D127: 174704
A128: 2018 | B128: Nd Dept Of Public Instruction | C128: 0.0003902183 | D128: 33822
A129: 2018 | B129: Nd School For Blind | C129: 0.0010572125 | D129: 91635
A130: 2018 | B130: Nd School For Deaf | C130: 0.0013983196 | D130: 121200
A131: 2018 | B131: Nd United | C131: 0.0004780184 | D131: 41433
A132: 2018 | B132: Nd Youth Correctional Cnt | C132: 0.0017965509 | D132: 155717
A133: 2018 | B133: Nedrose School | C133: 0.0040536633 | D133: 351354
A134: 2018 | B134: Nelson County | C134: 1.931e-05 | D134: 1674
A135: 2018 | B135: Nesson School | C135: 0.0026488198 | D135: 229588
...

Sheet 2019
A1: Year | B1: Employer Name | C1: Employer's Proportionate Share Allocation | D1: Statutory Required Contribution
A2: 2019 | B2: Alexander School | C2: 0.0020255003 | D2: 181171
A3: 2019 | B3: Anamoose School | C3: 0.0009855917 | D3: 88156
A4: 2019 | B4: Apple Creek Elem School | C4: 0.0004241743 | D4: 37940
A5: 2019 | B5: Ashley School | C5: 0.0013812935 | D5: 123550
A6: 2019 | B6: Bakker Elem School | C6: 6.20431e-05 | D6: 5549
A7: 2019 | B7: Barnes County North | C7: 0.0022560524 | D7: 201792
A8: 2019 | B8: Beach School | C8: 0.0030694385 | D8: 274546
A9: 2019 | B9: Belcourt School | C9: 0.01233157 | D9: 1102996
A10: 2019 | B10: Belfield Public School | C10: 0.0023347807 | D10: 208834
A11: 2019 | B11: Beulah School | C11: 0.0050677145 | D11: 453281
A12: 2019 | B12: Billings Co. School Dist. | C12: 0.0012097678 | D12: 108208
A13: 2019 | B13: Bismarck Public Schools | C13: 0.10586113 | D13: 9468736
A14: 2019 | B14: Bismarck State College | C14: 0
A15: 2019 | B15: Blessed John Paul II Catholic Sch Network | C15: 0
A16: 2019 | B16: Bottineau School | C16: 0.0054871056 | D16: 490794
A17: 2019 | B17: Bowbells School | C17: 0.0008732255 | D17: 78106
A18: 2019 | B18: Bowman School | C18: 0.0041982906 | D18: 375516
A19: 2019 | B19: Burke Central School | C19: 0.001430635 | D19: 127963
A20: 2019 | B20: Burleigh County Spec. Ed. | C20: 0.0001674181 | D20: 14975
A21: 2019 | B21: Carrington School | C21: 0.0041644826 | D21: 372492
A22: 2019 | B22: Cavalier School | C22: 0.0032912329 | D22: 294384
A23: 2019 | B23: Center Stanton School | C23: 0.0022615995 | D23: 202288
A24: 2019 | B24: Central Cass School | C24: 0.0056099057 | D24: 501777
A25: 2019 | B25: Central Elementary School | C25: 0
A26: 2019 | B26: Central Valley School | C26: 0.0019053708 | D26: 170426
A27: 2019 | B27: Dakota Prairie School | C27: 0.0029010482 | D27: 259484
A28: 2019 | B28: Devils Lake School | C28: 0.015425665 | D28: 1379747
A29: 2019 | B29: Dickinson School | C29: 0.031647584 | D29: 2830714
A30: 2019 | B30: Divide School | C30: 0.0035757553 | D30: 319833
A31: 2019 | B31: Drake School | C31: 0.0006898037 | D31: 61699
A32: 2019 | B32: Drayton School | C32: 0.0020198279 | D32: 180663
A33: 2019 | B33: Dunseith School | C33: 0.0047708456 | D33: 426728
A34: 2019 | B34: E Central Ctr Exc Childn | C34: 0.0011321875 | D34: 101268
A35: 2019 | B35: Earl Elem. School | C35: 3.70618e-05 | D35: 3315
A36: 2019 | B36: Edgeley School | C36: 0.0019607684 | D36: 175381
A37: 2019 | B37: Edmore School | C37: 0.0011109629 | D37: 99370
... A123: 2019 | B123: Munich School | C123: 0.0015425165 | D123: 137970
A124: 2019 | B124: N Central Area Career And Tech Center | C124: 0
A125: 2019 | B125: Napoleon School | C125: 0.0021579014 | D125: 193013
...

Sheet 2020
A1: Year | B1: Employer Name | C1: Employer's Proportionate Share Allocation | D1: Statutory Required Contribution
A2: 2020 | B2: Alexander School | C2: 0.0020781258 | D2: 193333
A3: 2020 | B3: Anamoose School | C3: 0.0009152008 | D3: 85143
A4: 2020 | B4: Apple Creek Elem School | C4: 0.0004293564 | D4: 39944
A5: 2020 | B5: Ashley School | C5: 0.0013508248 | D5: 125671
A6: 2020 | B6: Bakker Elem School | C6: 6.44137e-05 | D6: 5993
A7: 2020 | B7: Barnes County North | C7: 0.0023031533 | D7: 214268
A8: 2020 | B8: Beach School | C8: 0.0030102544 | D8: 280051
A9: 2020 | B9: Belcourt School | C9: 0.012487486 | D9: 1161741
A10: 2020 | B10: Belfield Public School | C10: 0.0021632708 | D10: 201254
A11: 2020 | B11: Beulah School | C11: 0.0051492958 | D11: 479052
A12: 2020 | B12: Billings Co. School Dist. | C12: 0.0013247364 | D12: 123243
A13: 2020 | B13: Bismarck Public Schools | C13: 0.10464261 | D13: 9735158
A14: 2020 | B14: Bismarck State College | C14: 0
A15: 2020 | B15: Blessed John Paul II Catholic Sch Network | C15: 0
A16: 2020 | B16: Bottineau School | C16: 0.0051648521 | D16: 480499
A17: 2020 | B17: Bowbells School | C17: 0.0008541637 | D17: 79465
A18: 2020 | B18: Bowman School | C18: 0.0044403698 | D18: 413098
A19: 2020 | B19: Burke Central School | C19: 0.0011626653 | D19: 108166
A20: 2020 | B20: Burleigh County Spec. Ed. | C20: 0.0001599626 | D20: 14882
A21: 2020 | B21: Carrington School | C21: 0.0039799494 | D21: 370264
A22: 2020 | B22: Cavalier School | C22: 0.0031679016 | D22: 294718
A23: 2020 | B23: Center Stanton School | C23: 0.0022338337 | D23: 207819
A24: 2020 | B24: Central Cass School | C24: 0.0059740047 | D24: 555776
A25: 2020 | B25: Central Regional Education Association | C25: 0.0010351589 | D25: 96303
A26: 2020 | B26: Central Elementary School | C26: 0
A27: 2020 | B27: Central Valley School | C27: 0.0018679788 | D27: 173783
A28: 2020 | B28: Dakota Prairie School | C28: 0.0030718659 | D28: 285783
A29: 2020 | B29: Devils Lake School | C29: 0.015543473 | D29: 1446047
A30: 2020 | B30: Dickinson School | C30: 0.031194016 | D30: 2902056
A31: 2020 | B31: Divide School | C31: 0.003848546 | D31: 358040
A32: 2020 | B32: Drake School | C32: 0.000666525 | D32: 62008
A33: 2020 | B33: Drayton School | C33: 0.0019502093 | D33: 181433
A34: 2020 | B34: Dunseith School | C34: 0.00483161 | D34: 449497
A35: 2020 | B35: E Central Ctr Exc Childn | C35: 0.000927604 | D35: 86297
A36: 2020 | B36: Earl Elem. School | C36: 3.64554e-05 | D36: 3392
A37: 2020 | B37: Edgeley School | C37: 0.0018388086 | D37: 171069
A38: 2020 | B38: Edmore School | C38: 0.0010695971 | D38: 99507
... A124: 2020 | B124: Munich School | C124: 0.0014518349 | D124: 135068
A125: 2020 | B125: N Central Area Career And Tech Center | C125: 0
...

Sheet 2021
A1: Year | B1: Employer Name | C1: Employer's Proportionate Share Allocation | D1: Statutory Required Contribution
A2: 2021 | B2: Alexander School | C2: 0.0019884342 | D2: 195392
A3: 2021 | B3: Anamoose School | C3: 0.0009169696 | D3: 90105
A4: 2021 | B4: Apple Creek Elem School | C4: 0.0004601094 | D4: 45212
A5: 2021 | B5: Ashley School | C5: 0.0013870276 | D5: 136295
A6: 2021 | B6: Bakker Elem School | C6: 7.14612e-05 | D6: 7022
A7: 2021 | B7: Barnes County North | C7: 0.0022346593 | D7: 219587
A8: 2021 | B8: Beach School | C8: 0.0028023624 | D8: 275372
A9: 2021 | B9: Belcourt School | C9: 0.011984802 | D9: 1177677
A10: 2021 | B10: Belfield Public School | C10: 0.002046204 | D10: 201069
A11: 2021 | B11: Beulah School | C11: 0.0051379667 | D11: 504878
A12: 2021 | B12: Billings Co. School Dist. | C12: 0.0012774806 | D12: 125531
A13: 2021 | B13: Bismarck Public Schools | C13: 0.1047685 | D13: 10294993
A14: 2021 | B14: Bismarck State College | C14: 0
A15: 2021 | B15: Blessed John Paul II Catholic Sch Network | C15: 0
A16: 2021 | B16: Bottineau School | C16: 0.0052297432 | D16: 513897
A17: 2021 | B17: Bowbells School | C17: 0.0008860802 | D17: 87070
A18: 2021 | B18: Bowman School | C18: 0.0044356212 | D18: 435863
A19: 2021 | B19: Burke Central School | C19: 0.0012157112 | D19: 119461
A20: 2021 | B20: Burleigh County Spec. Ed. | C20: 0.0001564848 | D20: 15377
A21: 2021 | B21: Carrington School | C21: 0.0038735126 | D21: 380628
A22: 2021 | B22: Cavalier School | C22: 0.0032599173 | D22: 320333
A23: 2021 | B23: Center Stanton School | C23: 0.0022830447 | D23: 224342
A24: 2021 | B24: Central Cass School | C24: 0.0058675909 | D24: 576574
A25: 2021 | B25: Central Elementary School | C25: 0
A26: 2021 | B26: Central Regional Education Association | C26: 0.0010332162 | D26: 101528
A27: 2021 | B27: Central Valley School | C27: 0.0018493426 | D27: 181724
A28: 2021 | B28: Dakota Prairie School | C28: 0.0030004219 | D28: 294834
A29: 2021 | B29: Devils Lake School | C29: 0.015214688 | D29: 1495059
A30: 2021 | B30: Dickinson School | C30: 0.032548776 | D30: 3198380
A31: 2021 | B31: Divide School | C31: 0.0038192398 | D31: 375295
A32: 2021 | B32: Drake School | C32: 0.0006626015 | D32: 65110
A33: 2021 | B33: Drayton School | C33: 0.0020908981 | D33: 205460
A34: 2021 | B34: Dunseith School | C34: 0.0048883622 | D34: 480351
A35: 2021 | B35: E Central Ctr Exc Childn | C35: 0.0007839937 | D35: 77039
A36: 2021 | B36: Earl Elem. School | C36: 3.52927e-05 | D36: 3468
A37: 2021 | B37: Edgeley School | C37: 0.001795756 | D37: 176459
... A94: 2021 | B94: Little Heart Elem. School | C94: 0.0002302545 | D94: 22626
A95: 2021 | B95: Logan County | C95: 0
A96: 2021 | B96: Lone Tree Elem. School | C96: 0.0003778266 | D96: 37127
...

Sheet 2022
A1: Year | B1: Employer Name | C1: Employer's Proportionate Share Allocation | D1: Statutory Required Contribution
A2: 2022 | B2: Alexander School | C2: 0.0021399356 | D2: 214703
A3: 2022 | B3: Anamoose School | C3: 0.0010195133 | D3: 102289
A4: 2022 | B4: Apple Creek Elem School | C4: 0.0005250609 | D4: 52680
A5: 2022 | B5: Ashley School | C5: 0.0013347904 | D5: 133921
A6: 2022 | B6: Bakker Elem School | C6: 6.5541e-05 | D6: 6576
A7: 2022 | B7: Barnes County North | C7: 0.0022206434 | D7: 222800
A8: 2022 | B8: Beach School | C8: 0.002920375 | D8: 293005
A9: 2022 | B9: Belcourt School | C9: 0.012709778 | D9: 1275189
A10: 2022 | B10: Belfield Public School | C10: 0.0018638605 | D10: 187004
A11: 2022 | B11: Beulah School | C11: 0.0049923666 | D11: 500891
A12: 2022 | B12: Billings Co. School Dist. | C12: 0.0012745353 | D12: 127876
A13: 2022 | B13: Bismarck Public Schools | C13: 0.10733713 | D13: 10769278
A14: 2022 | B14: Blessed John Paul II Catholic Sch Network | C14: 0
A15: 2022 | B15: Bottineau School | C15: 0.0052793431 | D15: 529684
A16: 2022 | B16: Bowbells School | C16: 0.0008817167 | D16: 88464
A17: 2022 | B17: Bowman School | C17: 0.0041788141 | D17: 419266
A18: 2022 | B18: Burke Central School | C18: 0.0011355444 | D18: 113931
A19: 2022 | B19: Burleigh County Spec. Ed. | C19: 0.0001560814 | D19: 15660
A20: 2022 | B20: Carrington School | C20: 0.003707231 | D20: 371951
A21: 2022 | B21: Cavalier School | C21: 0.0031834966 | D21: 319405
A22: 2022 | B22: Center Stanton School | C22: 0.0021765508 | D22: 218376
A23: 2022 | B23: Central Cass School | C23: 0.0059571772 | D23: 597692
A24: 2022 | B24: Central Elementary School | C24: 0
A25: 2022 | B25: Central Regional Education Association | C25: 0.0015732696 | D25: 157848
A26: 2022 | B26: Central Valley School | C26: 0.0017460968 | D26: 175188
A27: 2022 | B27: Dakota Prairie School | C27: 0.002884916 | D27: 289448
A28: 2022 | B28: Devils Lake School | C28: 0.014900779 | D28: 1495015
A29: 2022 | B29: Dickinson School | C29: 0.032124307 | D29: 3223075
A30: 2022 | B30: Divide School | C30: 0.0038707308 | D30: 388356
A31: 2022 | B31: Drake School | C31: 0.0007052203 | D31: 70756
A32: 2022 | B32: Drayton School | C32: 0.0018268245 | D32: 183288
A33: 2022 | B33: Dunseith School | C33: 0.0051555447 | D33: 517263
A34: 2022 | B34: E Central Ctr Exc Childn | C34: 0.0009036459 | D34: 90664
A35: 2022 | B35: Earl Elem. School | C35: 3.5328e-05 | D35: 3545
A36: 2022 | B36: Edgeley School | C36: 0.0018307861 | D36: 183685
... A56: 2022 | B56: Goodrich School | C56: 0.0002398939 | D56: 24069
A57: 2022 | B57: Grafton School | C57: 0
A58: 2022 | B58: Grafton School District | C58: 0.0060423401 | D58: 606236
A59: 2022 | B59: Grand Forks School | C59: 0.064753607 | D59: 6496817
...

Sheet NCES Data -->

Sheet LEAID Match
A1: district_name
A2: Alexander School | B2: 3801760
A3: Anamoose School | B3: 3801950
A4: Apple Creek Elem School | B4: 3802014
A5: Ashley School | B5: 3802170
A6: Bakker Elem School | B6: 3802240
A7: Barnes County North | B7: 3800060
A8: Beach School | B8: 3802380
A9: Belcourt School | B9: 3802530
A10: Belfield Public School | B10: 3806210
A11: Beulah School | B11: 3800032
A12: Billings Co. School Dist. | B12: 3802840
A13: Bismarck Public Schools | B13: 3800014
A14: Bismarck State College
A15: Blessed John Paul II Catholic Sch Network
A16: Bottineau School | B16: 3803060
A17: Bowbells School | B17: 3803090
A18: Bowman School | B18: 3803200
A19: Burke Central School | B19: 3803590
A20: Burleigh County Spec. Ed. | B20: 3880120
A21: Carrington School | B21: 3800053
A22: Cavalier School | B22: 3800018
A23: Center Stanton School | B23: 3800052
A24: Central Cass School | B24: 3804090
A25: Central Elementary School | B25: 3800037
A26: Central Regional Education Association
A27: Central Valley School | B27: 3804140
A28: Dakota Prairie School | B28: 3800040
A29: Devils Lake School | B29: 3805040
A30: Dickinson School | B30: 3800038
A31: Divide School | B31: 3805160
A32: Drake School | B32: 3800029
A33: Drayton School | B33: 3805340
A34: Dunseith School | B34: 3805460
A35: E Central Ctr Exc Childn | B35: 3880260
A36: Earl Elem. School | B36: 3805670
A37: Edgeley School | B37: 3805850
A38: Edmore School | B38: 3805950
... A96: Little Heart Elem. School | B96: 3811540
A97: Logan County
...
