Workbook

Sheet Summary
A1: LEAID | B1: Year | C1: State | D1: state_abv | E1: plan | F1: district_name | G1: employer_code | H1: district_contributions | I1: state_contributions | J1: total_contributions
A2: =K2 -> 2306780 | B2: 2015 | C2: Maine | D2: ME | E2: Maine Public Employees Retirement System - State Employee & Teacher Plan | F2: Isle Au Haut School Department | G2: T0802 | I2: 0 | J2: 0 | K2: =IFERROR(VLOOKUP(F2,'LEAID Match'!$A$2:$B$236,2,FALSE),"") -> 2306780
A3: =K3 -> 2306780 | B3: 2016 | C3: Maine | D3: ME | E3: Maine Public Employees Retirement System - State Employee & Teacher Plan | F3: Isle Au Haut School Department | G3: T0802 | I3: 0 | J3: 0 | K3: =IFERROR(VLOOKUP(F3,'LEAID Match'!$A$2:$B$236,2,FALSE),"") -> 2306780
A4: =K4 -> 2306780 | B4: 2017 | C4: Maine | D4: ME | E4: Maine Public Employees Retirement System - State Employee & Teacher Plan | F4: Isle Au Haut School Department | G4: T0802 | I4: 0 | J4: 0 | K4: =IFERROR(VLOOKUP(F4,'LEAID Match'!$A$2:$B$236,2,FALSE),"") -> 2306780
A5: =K5 -> 2306780 | B5: 2018 | C5: Maine | D5: ME | E5: Maine Public Employees Retirement System - State Employee & Teacher Plan | F5: Isle Au Haut School Department | G5: T0802 | I5: 0 | J5: 0 | K5: =IFERROR(VLOOKUP(F5,'LEAID Match'!$A$2:$B$236,2,FALSE),"") -> 2306780
A6: =K6 -> 2306780 | B6: 2019 | C6: Maine | D6: ME | E6: Maine Public Employees Retirement System - State Employee & Teacher Plan | F6: Isle Au Haut School Department | G6: T0802 | I6: 0 | J6: 0 | K6: =IFERROR(VLOOKUP(F6,'LEAID Match'!$A$2:$B$236,2,FALSE),"") -> 2306780
A7: =K7 -> 2306780 | B7: 2020 | C7: Maine | D7: ME | E7: Maine Public Employees Retirement System - State Employee & Teacher Plan | F7: Isle Au Haut School Department | G7: T0802 | I7: 0 | J7: 0 | K7: =IFERROR(VLOOKUP(F7,'LEAID Match'!$A$2:$B$236,2,FALSE),"") -> 2306780
A8: =K8 -> 2306780 | B8: 2021 | C8: Maine | D8: ME | E8: Maine Public Employees Retirement System - State Employee & Teacher Plan | F8: Isle Au Haut School Department | G8: T0802 | I8: 0 | J8: 0 | K8: =IFERROR(VLOOKUP(F8,'LEAID Match'!$A$2:$B$236,2,FALSE),"") -> 2306780
A9: =K9 -> 2306780 | B9: 2022 | C9: Maine | D9: ME | E9: Maine Public Employees Retirement System - State Employee & Teacher Plan | F9: Isle Au Haut School Department | G9: T0802 | I9: 0 | J9: 0 | K9: =IFERROR(VLOOKUP(F9,'LEAID Match'!$A$2:$B$236,2,FALSE),"") -> 2306780
A10: =K10 -> 2308340 | B10: 2015 | C10: Maine | D10: ME | E10: Maine Public Employees Retirement System - State Employee & Teacher Plan | F10: Monhegan Plantation School Department | G10: T0804 | I10: 0 | J10: 0 | K10: =IFERROR(VLOOKUP(F10,'LEAID Match'!$A$2:$B$236,2,FALSE),"") -> 2308340
A11: =K11 -> 2308340 | B11: 2016 | C11: Maine | D11: ME | E11: Maine Public Employees Retirement System - State Employee & Teacher Plan | F11: Monhegan Plantation School Department | G11: T0804 | I11: 0 | J11: 0 | K11: =IFERROR(VLOOKUP(F11,'LEAID Match'!$A$2:$B$236,2,FALSE),"") -> 2308340
A12: =K12 -> 2308340 | B12: 2017 | C12: Maine | D12: ME | E12: Maine Public Employees Retirement System - State Employee & Teacher Plan | F12: Monhegan Plantation School Department | G12: T0804 | I12: 0 | J12: 0 | K12: =IFERROR(VLOOKUP(F12,'LEAID Match'!$A$2:$B$236,2,FALSE),"") -> 2308340
A13: =K13 -> 2308340 | B13: 2018 | C13: Maine | D13: ME | E13: Maine Public Employees Retirement System - State Employee & Teacher Plan | F13: Monhegan Plantation School Department | G13: T0804 | I13: 0 | J13: 0 | K13: =IFERROR(VLOOKUP(F13,'LEAID Match'!$A$2:$B$236,2,FALSE),"") -> 2308340
... A17: =K17 -> 2308340 | B17: 2022 | C17: Maine | D17: ME | E17: Maine Public Employees Retirement System - State Employee & Teacher Plan | F17: Monhegan Plantation School Department | G17: T0804 | I17: 0 | J17: 0 | K17: =IFERROR(VLOOKUP(F17,'LEAID Match'!$A$2:$B$236,2,FALSE),"") -> 2308340
A18: =K18 -> 2304895 | B18: 2015 | C18: Maine | D18: ME | E18: Maine Public Employees Retirement System - State Employee & Teacher Plan | F18: CSD No. 13 Deer Isle - Stonington | G18: T0913 | H18: 12858 | I18: 246534.67 | J18: 259392.67 | K18: =IFERROR(VLOOKUP(F18,'LEAID Match'!$A$2:$B$236,2,FALSE),"") -> 2304895
A19: =K19 -> 2304895 | B19: 2016 | C19: Maine | D19: ME | E19: Maine Public Employees Retirement System - State Employee & Teacher Plan | F19: CSD No. 13 Deer Isle - Stonington | G19: T0913 | H19: 9376 | I19: 178187.15 | J19: 187563.15 | K19: =IFERROR(VLOOKUP(F19,'LEAID Match'!$A$2:$B$236,2,FALSE),"") -> 2304895
A20: =K20 -> 2304895 | B20: 2017 | C20: Maine | D20: ME | E20: Maine Public Employees Retirement System - State Employee & Teacher Plan | F20: CSD No. 13 Deer Isle - Stonington | G20: T0913 | H20: 9195 | I20: 175324.72 | J20: 184519.72 | K20: =IFERROR(VLOOKUP(F20,'LEAID Match'!$A$2:$B$236,2,FALSE),"") -> 2304895
A21: =K21 -> 2304895 | B21: 2018 | C21: Maine | D21: ME | E21: Maine Public Employees Retirement System - State Employee & Teacher Plan | F21: CSD No. 13 Deer Isle - Stonington | G21: T0913 | H21: 9751 | I21: 197645.88 | J21: 207396.88 | K21: =IFERROR(VLOOKUP(F21,'LEAID Match'!$A$2:$B$236,2,FALSE),"") -> 2304895
A22: =K22 -> 2304895 | B22: 2019 | C22: Maine | D22: ME | E22: Maine Public Employees Retirement System - State Employee & Teacher Plan | F22: CSD No. 13 Deer Isle - Stonington | G22: T0913 | H22: 7782 | I22: 166721.85 | J22: 174503.85 | K22: =IFERROR(VLOOKUP(F22,'LEAID Match'!$A$2:$B$236,2,FALSE),"") -> 2304895
A23: =K23 -> 2304895 | B23: 2020 | C23: Maine | D23: ME | E23: Maine Public Employees Retirement System - State Employee & Teacher Plan | F23: CSD No. 13 Deer Isle - Stonington | G23: T0913 | H23: 10566 | I23: 235430.84 | J23: 245996.84 | K23: =IFERROR(VLOOKUP(F23,'LEAID Match'!$A$2:$B$236,2,FALSE),"") -> 2304895
A24: =K24 -> 2304895 | B24: 2021 | C24: Maine | D24: ME | E24: Maine Public Employees Retirement System - State Employee & Teacher Plan | F24: CSD No. 13 Deer Isle - Stonington | G24: T0913 | H24: 35987 | I24: 604558.22 | J24: 640545.22 | K24: =IFERROR(VLOOKUP(F24,'LEAID Match'!$A$2:$B$236,2,FALSE),"") -> 2304895
A25: =K25 -> 2304895 | B25: 2022 | C25: Maine | D25: ME | E25: Maine Public Employees Retirement System - State Employee & Teacher Plan | F25: CSD No. 13 Deer Isle - Stonington | G25: T0913 | H25: 47998 | I25: 690929.9 | J25: 738927.9 | K25: =IFERROR(VLOOKUP(F25,'LEAID Match'!$A$2:$B$236,2,FALSE),"") -> 2304895
A26: =K26 -> 2308400 | B26: 2015 | C26: Maine | D26: ME | E26: Maine Public Employees Retirement System - State Employee & Teacher Plan | F26: CSD No. 17 Moosabec | G26: T0917 | H26: 32 | I26: 613.55651 | J26: 645.55651 | K26: =IFERROR(VLOOKUP(F26,'LEAID Match'!$A$2:$B$236,2,FALSE),"") -> 2308400
A27: =K27 -> 2308400 | B27: 2016 | C27: Maine | D27: ME | E27: Maine Public Employees Retirement System - State Employee & Teacher Plan | F27: CSD No. 17 Moosabec | G27: T0917 | H27: 24 | I27: 456.11045 | J27: 480.11045 | K27: =IFERROR(VLOOKUP(F27,'LEAID Match'!$A$2:$B$236,2,FALSE),"") -> 2308400
A28: =K28 -> 2308400 | B28: 2017 | C28: Maine | D28: ME | E28: Maine Public Employees Retirement System - State Employee & Teacher Plan | F28: CSD No. 17 Moosabec | G28: T0917 | H28: 1028 | I28: 19601.285 | J28: 20629.285 | K28: =IFERROR(VLOOKUP(F28,'LEAID Match'!$A$2:$B$236,2,FALSE),"") -> 2308400
A29: =K29 -> 2308400 | B29: 2018 | C29: Maine | D29: ME | E29: Maine Public Employees Retirement System - State Employee & Teacher Plan | F29: CSD No. 17 Moosabec | G29: T0917 | H29: 1986 | I29: 40254.818 | J29: 42240.818 | K29: =IFERROR(VLOOKUP(F29,'LEAID Match'!$A$2:$B$236,2,FALSE),"") -> 2308400
... A49: =K49 -> 2300053 | B49: 2022 | C49: Maine | D49: ME | E49: Maine Public Employees Retirement System - State Employee & Teacher Plan | F49: CSD No. 19 Five Town CSD | G49: T0919 | H49: 14224 | I49: 204754.09 | J49: 218978.09 | K49: =IFERROR(VLOOKUP(F49,'LEAID Match'!$A$2:$B$236,2,FALSE),"") -> 2300053
A50: =K50 -> 0 | B50: 2015 | C50: Maine | D50: ME | E50: Maine Public Employees Retirement System - State Employee & Teacher Plan | F50: Erskine Academy | G50: TAERS | I50: 0 | J50: 0 | K50: =IFERROR(VLOOKUP(F50,'LEAID Match'!$A$2:$B$236,2,FALSE),"") -> 0
A51: =K51 -> 0 | B51: 2016 | C51: Maine | D51: ME | E51: Maine Public Employees Retirement System - State Employee & Teacher Plan | F51: Erskine Academy | G51: TAERS | I51: 0 | J51: 0 | K51: =IFERROR(VLOOKUP(F51,'LEAID Match'!$A$2:$B$236,2,FALSE),"") -> 0
A52: =K52 -> 0 | B52: 2017 | C52: Maine | D52: ME | E52: Maine Public Employees Retirement System - State Employee & Teacher Plan | F52: Erskine Academy | G52: TAERS | I52: 0 | J52: 0 | K52: =IFERROR(VLOOKUP(F52,'LEAID Match'!$A$2:$B$236,2,FALSE),"") -> 0
A53: =K53 -> 0 | B53: 2018 | C53: Maine | D53: ME | E53: Maine Public Employees Retirement System - State Employee & Teacher Plan | F53: Erskine Academy | G53: TAERS | I53: 0 | J53: 0 | K53: =IFERROR(VLOOKUP(F53,'LEAID Match'!$A$2:$B$236,2,FALSE),"") -> 0
A54: =K54 -> 0 | B54: 2019 | C54: Maine | D54: ME | E54: Maine Public Employees Retirement System - State Employee & Teacher Plan | F54: Erskine Academy | G54: TAERS | I54: 0 | J54: 0 | K54: =IFERROR(VLOOKUP(F54,'LEAID Match'!$A$2:$B$236,2,FALSE),"") -> 0
A55: =K55 -> 0 | B55: 2020 | C55: Maine | D55: ME | E55: Maine Public Employees Retirement System - State Employee & Teacher Plan | F55: Erskine Academy | G55: TAERS | I55: 0 | J55: 0 | K55: =IFERROR(VLOOKUP(F55,'LEAID Match'!$A$2:$B$236,2,FALSE),"") -> 0
A56: =K56 -> 0 | B56: 2021 | C56: Maine | D56: ME | E56: Maine Public Employees Retirement System - State Employee & Teacher Plan | F56: Erskine Academy | G56: TAERS | I56: 0 | J56: 0 | K56: =IFERROR(VLOOKUP(F56,'LEAID Match'!$A$2:$B$236,2,FALSE),"") -> 0
A57: =K57 -> 0 | B57: 2022 | C57: Maine | D57: ME | E57: Maine Public Employees Retirement System - State Employee & Teacher Plan | F57: Erskine Academy | G57: TAERS | I57: 0 | J57: 0 | K57: =IFERROR(VLOOKUP(F57,'LEAID Match'!$A$2:$B$236,2,FALSE),"") -> 0
A58: =K58 -> 0 | B58: 2015 | C58: Maine | D58: ME | E58: Maine Public Employees Retirement System - State Employee & Teacher Plan | F58: Foxcroft Academy | G58: TAFOX | I58: 0 | J58: 0 | K58: =IFERROR(VLOOKUP(F58,'LEAID Match'!$A$2:$B$236,2,FALSE),"") -> 0
A59: =K59 -> 0 | B59: 2016 | C59: Maine | D59: ME | E59: Maine Public Employees Retirement System - State Employee & Teacher Plan | F59: Foxcroft Academy | G59: TAFOX | I59: 0 | J59: 0 | K59: =IFERROR(VLOOKUP(F59,'LEAID Match'!$A$2:$B$236,2,FALSE),"") -> 0
A60: =K60 -> 0 | B60: 2017 | C60: Maine | D60: ME | E60: Maine Public Employees Retirement System - State Employee & Teacher Plan | F60: Foxcroft Academy | G60: TAFOX | I60: 0 | J60: 0 | K60: =IFERROR(VLOOKUP(F60,'LEAID Match'!$A$2:$B$236,2,FALSE),"") -> 0
A61: =K61 -> 0 | B61: 2018 | C61: Maine | D61: ME | E61: Maine Public Employees Retirement System - State Employee & Teacher Plan | F61: Foxcroft Academy | G61: TAFOX | I61: 0 | J61: 0 | K61: =IFERROR(VLOOKUP(F61,'LEAID Match'!$A$2:$B$236,2,FALSE),"") -> 0
... A129: =K129 -> 0 | B129: 2022 | C129: Maine | D129: ME | E129: Maine Public Employees Retirement System - State Employee & Teacher Plan | F129: Washington Academy | G129: TAWAS | I129: 0 | J129: 0 | K129: =IFERROR(VLOOKUP(F129,'LEAID Match'!$A$2:$B$236,2,FALSE),"") -> 0
...

Sheet GASB Data -->

Sheet 2015
A1: Year | B1: district_name | C1: employer_code | D1: district_contributions | F1: state_contributions | G1: total_contributions
A2: 2015 | B2: Isle Au Haut School Department | C2: T0802 | E2: =D2/$D$242 -> 0 | F2: =E2*$D$244 -> 0 | G2: =SUM(F2,D2) -> 0
A3: 2015 | B3: Monhegan Plantation School Department | C3: T0804 | E3: =D3/$D$242 -> 0 | F3: =E3*$D$244 -> 0 | G3: =SUM(F3,D3) -> 0
A4: 2015 | B4: CSD No. 13 Deer Isle - Stonington | C4: T0913 | D4: 12858 | E4: =D4/$D$242 -> 0.001676563 | F4: =E4*$D$244 -> 246534.67 | G4: =SUM(F4,D4) -> 259392.67
A5: 2015 | B5: CSD No. 17 Moosabec | C5: T0917 | D5: 32 | E5: =D5/$D$242 -> 4.1725009e-06 | F5: =E5*$D$244 -> 613.55651 | G5: =SUM(F5,D5) -> 645.55651
A6: 2015 | B6: CSD No. 18 Wells - Ogunquit | C6: T0918 | D6: 17509 | E6: =D6/$D$242 -> 0.0022830099 | F6: =E6*$D$244 -> 335711.28 | G6: =SUM(F6,D6) -> 353220.28
A7: 2015 | B7: CSD No. 19 Five Town CSD | C7: T0919 | D7: 14959 | E7: =D7/$D$242 -> 0.0019505138 | F7: =E7*$D$244 -> 286818.49 | G7: =SUM(F7,D7) -> 301777.49
A8: 2015 | B8: Erskine Academy | C8: TAERS | E8: =D8/$D$242 -> 0 | F8: =E8*$D$244 -> 0 | G8: =SUM(F8,D8) -> 0
A9: 2015 | B9: Foxcroft Academy | C9: TAFOX | E9: =D9/$D$242 -> 0 | F9: =E9*$D$244 -> 0 | G9: =SUM(F9,D9) -> 0
A10: 2015 | B10: Fryeburg Academy | C10: TAFRY | E10: =D10/$D$242 -> 0 | F10: =E10*$D$244 -> 0 | G10: =SUM(F10,D10) -> 0
A11: 2015 | B11: George Stevens Academy | C11: TAGEO | E11: =D11/$D$242 -> 0 | F11: =E11*$D$244 -> 0 | G11: =SUM(F11,D11) -> 0
A12: 2015 | B12: Gould Academy | C12: TAGOU | E12: =D12/$D$242 -> 0 | F12: =E12*$D$244 -> 0 | G12: =SUM(F12,D12) -> 0
A13: 2015 | B13: Lee Academy | C13: TALEE | E13: =D13/$D$242 -> 0 | F13: =E13*$D$244 -> 0 | G13: =SUM(F13,D13) -> 0
A14: 2015 | B14: Lincoln Academy | C14: TALIN | E14: =D14/$D$242 -> 0 | F14: =E14*$D$244 -> 0 | G14: =SUM(F14,D14) -> 0
A15: 2015 | B15: Maine Central Institute | C15: TAMCI | E15: =D15/$D$242 -> 0 | F15: =E15*$D$244 -> 0 | G15: =SUM(F15,D15) -> 0
A16: 2015 | B16: Thornton Academy | C16: TATHO | E16: =D16/$D$242 -> 0 | F16: =E16*$D$244 -> 0 | G16: =SUM(F16,D16) -> 0
A17: 2015 | B17: Washington Academy | C17: TAWAS | E17: =D17/$D$242 -> 0 | F17: =E17*$D$244 -> 0 | G17: =SUM(F17,D17) -> 0
A18: 2015 | B18: Acton School Department | C18: TCACT | D18: 13906 | E18: =D18/$D$242 -> 0.0018132124 | F18: =E18*$D$244 -> 266628.65 | G18: =SUM(F18,D18) -> 280534.65
A19: 2015 | B19: Athens School Department | C19: TCATH | D19: 9146 | E19: =D19/$D$242 -> 0.0011925529 | F19: =E19*$D$244 -> 175362.12 | G19: =SUM(F19,D19) -> 184508.12
A20: 2015 | B20: Auburn School Department | C20: TCAUB | D20: 194316 | E20: =D20/$D$242 -> 0.02533699 | F20: =E20*$D$244 -> 3725745.2 | G20: =SUM(F20,D20) -> 3920061.2
A21: 2015 | B21: Augusta School Department | C21: TCAUG | D21: 171249 | E21: =D21/$D$242 -> 0.022329269 | F21: =E21*$D$244 -> 3283466.8 | G21: =SUM(F21,D21) -> 3454715.8
A22: 2015 | B22: Bangor School Department | C22: TCBAN | D22: 169568 | E22: =D22/$D$242 -> 0.022110082 | F22: =E22*$D$244 -> 3251235.9 | G22: =SUM(F22,D22) -> 3420803.9
A23: 2015 | B23: Biddeford School Department | C23: TCBID | D23: 129653 | E23: =D23/$D$242 -> 0.016905539 | F23: =E23*$D$244 -> 2485920.1 | G23: =SUM(F23,D23) -> 2615573.1
A24: 2015 | B24: Brewer School Department | C24: TCBRE | D24: 21487 | E24: =D24/$D$242 -> 0.002801704 | F24: =E24*$D$244 -> 411984.02 | G24: =SUM(F24,D24) -> 433471.02
A25: 2015 | B25: Brunswick School Department | C25: TCBRU | D25: 59783 | E25: =D25/$D$242 -> 0.0077951444 | F25: =E25*$D$244 -> 1146257.8 | G25: =SUM(F25,D25) -> 1206040.8
A26: 2015 | B26: Calais School Department | C26: TCCAL | D26: 21273 | E26: =D26/$D$242 -> 0.0027738004 | F26: =E26*$D$244 -> 407880.86 | G26: =SUM(F26,D26) -> 429153.86
A27: 2015 | B27: Caswell School Department | C27: TCCAS | E27: =D27/$D$242 -> 0 | F27: =E27*$D$244 -> 0 | G27: =SUM(F27,D27) -> 0
A28: 2015 | B28: Cape Elizabeth School Department | C28: TCCEL | D28: 14584 | E28: =D28/$D$242 -> 0.0019016173 | F28: =E28*$D$244 -> 279628.38 | G28: =SUM(F28,D28) -> 294212.38
A29: 2015 | B29: Chebeague Island School Department | C29: TCCHE | E29: =D29/$D$242 -> 0 | F29: =E29*$D$244 -> 0 | G29: =SUM(F29,D29) -> 0
A30: 2015 | B30: Cherryfield School Department | C30: TCCHR | D30: 4056 | E30: =D30/$D$242 -> 0.00052886449 | F30: =E30*$D$244 -> 77768.287 | G30: =SUM(F30,D30) -> 81824.287
A31: 2015 | B31: Dayton School Department | C31: TCDAY | D31: 3815 | E31: =D31/$D$242 -> 0.00049744034 | F31: =E31*$D$244 -> 73147.44 | G31: =SUM(F31,D31) -> 76962.44
A32: 2015 | B32: Easton School Department | C32: TCEAS | E32: =D32/$D$242 -> 0 | F32: =E32*$D$244 -> 0 | G32: =SUM(F32,D32) -> 0
A33: 2015 | B33: Ellsworth School Department | C33: TCELL | D33: 22182 | E33: =D33/$D$242 -> 0.0028923255 | F33: =E33*$D$244 -> 425309.7 | G33: =SUM(F33,D33) -> 447491.7
A34: 2015 | B34: East Millinocket School Department | C34: TCEML | D34: 12222 | E34: =D34/$D$242 -> 0.0015936346 | F34: =E34*$D$244 -> 234340.24 | G34: =SUM(F34,D34) -> 246562.24
A35: 2015 | B35: Eustis School Department | C35: TCEUS | D35: 5047 | E35: =D35/$D$242 -> 0.00065808162 | F35: =E35*$D$244 -> 96769.366 | G35: =SUM(F35,D35) -> 101816.37
A36: 2015 | B36: Falmouth School Department | C36: TCFAL | D36: 11326 | E36: =D36/$D$242 -> 0.0014768045 | F36: =E36*$D$244 -> 217160.66 | G36: =SUM(F36,D36) -> 228486.66
A37: 2015 | B37: Fayette School Department | C37: TCFAY | D37: 5236 | E37: =D37/$D$242 -> 0.00068272546 | F37: =E37*$D$244 -> 100393.18 | G37: =SUM(F37,D37) -> 105629.18
A38: 2015 | B38: Glenburn School Department | C38: TCGLE | D38: 9927 | E38: =D38/$D$242 -> 0.001294388 | F38: =E38*$D$244 -> 190336.73 | G38: =SUM(F38,D38) -> 200263.73
A39: 2015 | B39: Gorham School Department | C39: TCGOR | D39: 52421 | E39: =D39/$D$242 -> 0.0068352084 | F39: =E39*$D$244 -> 1005101.4 | G39: =SUM(F39,D39) -> 1057522.4
A40: 2015 | B40: Hancock School Department | C40: TCHAN | D40: 6164 | E40: =D40/$D$242 -> 0.00080372798 | F40: =E40*$D$244 -> 118186.32 | G40: =SUM(F40,D40) -> 124350.32
...

Sheet 2016
A1: Year | B1: district_name | C1: employer_code | D1: district_contributions | F1: state_contributions | G1: total_contributions
A2: 2016 | B2: Isle Au Haut School Department | C2: T0802 | E2: =D2/$D$248 -> 0 | F2: =E2*$D$250 -> 0 | G2: =SUM(D2,F2) -> 0
A3: 2016 | B3: Monhegan Plantation School Department | C3: T0804 | E3: =D3/$D$248 -> 0 | F3: =E3*$D$250 -> 0 | G3: =SUM(D3,F3) -> 0
A4: 2016 | B4: CSD No. 13 Deer Isle - Stonington | C4: T0913 | D4: 9376 | E4: =D4/$D$248 -> 0.0015887615 | F4: =E4*$D$250 -> 178187.15 | G4: =SUM(D4,F4) -> 187563.15
A5: 2016 | B5: CSD No. 17 Moosabec | C5: T0917 | D5: 24 | E5: =D5/$D$248 -> 4.0667958e-06 | F5: =E5*$D$250 -> 456.11045 | G5: =SUM(D5,F5) -> 480.11045
A6: 2016 | B6: CSD No. 18 Wells - Ogunquit | C6: T0918 | D6: 12861 | E6: =D6/$D$248 -> 0.0021792942 | F6: =E6*$D$250 -> 244418.19 | G6: =SUM(D6,F6) -> 257279.19
A7: 2016 | B7: CSD No. 19 Five Town CSD | C7: T0919 | D7: 9438 | E7: =D7/$D$248 -> 0.0015992674 | F7: =E7*$D$250 -> 179365.44 | G7: =SUM(D7,F7) -> 188803.44
A8: 2016 | B8: Erskine Academy | C8: TAERS | E8: =D8/$D$248 -> 0 | F8: =E8*$D$250 -> 0 | G8: =SUM(D8,F8) -> 0
A9: 2016 | B9: Foxcroft Academy | C9: TAFOX | E9: =D9/$D$248 -> 0 | F9: =E9*$D$250 -> 0 | G9: =SUM(D9,F9) -> 0
A10: 2016 | B10: Fryeburg Academy | C10: TAFRY | E10: =D10/$D$248 -> 0 | F10: =E10*$D$250 -> 0 | G10: =SUM(D10,F10) -> 0
A11: 2016 | B11: George Stevens Academy | C11: TAGEO | E11: =D11/$D$248 -> 0 | F11: =E11*$D$250 -> 0 | G11: =SUM(D11,F11) -> 0
A12: 2016 | B12: Gould Academy | C12: TAGOU | E12: =D12/$D$248 -> 0 | F12: =E12*$D$250 -> 0 | G12: =SUM(D12,F12) -> 0
A13: 2016 | B13: Lee Academy | C13: TALEE | E13: =D13/$D$248 -> 0 | F13: =E13*$D$250 -> 0 | G13: =SUM(D13,F13) -> 0
A14: 2016 | B14: Lincoln Academy | C14: TALIN | E14: =D14/$D$248 -> 0 | F14: =E14*$D$250 -> 0 | G14: =SUM(D14,F14) -> 0
A15: 2016 | B15: Maine Central Institute | C15: TAMCI | E15: =D15/$D$248 -> 0 | F15: =E15*$D$250 -> 0 | G15: =SUM(D15,F15) -> 0
A16: 2016 | B16: Thornton Academy | C16: TATHO | E16: =D16/$D$248 -> 0 | F16: =E16*$D$250 -> 0 | G16: =SUM(D16,F16) -> 0
A17: 2016 | B17: Washington Academy | C17: TAWAS | E17: =D17/$D$248 -> 0 | F17: =E17*$D$250 -> 0 | G17: =SUM(D17,F17) -> 0
A18: 2016 | B18: Acton School Department | C18: TCACT | D18: 6230 | E18: =D18/$D$248 -> 0.0010556724 | F18: =E18*$D$250 -> 118398.67 | G18: =SUM(D18,F18) -> 124628.67
A19: 2016 | B19: Andover School Department | C19: TCAND | D19: 1506 | E19: =D19/$D$248 -> 0.00025519143 | F19: =E19*$D$250 -> 28620.931 | G19: =SUM(D19,F19) -> 30126.931
A20: 2016 | B20: Athens School Department | C20: TCATH | D20: 6038 | E20: =D20/$D$248 -> 0.001023138 | F20: =E20*$D$250 -> 114749.79 | G20: =SUM(D20,F20) -> 120787.79
A21: 2016 | B21: Auburn School Department | C21: TCAUB | D21: 149677 | E21: =D21/$D$248 -> 0.025362741 | F21: =E21*$D$250 -> 2844551.9 | G21: =SUM(D21,F21) -> 2994228.9
A22: 2016 | B22: Augusta School Department | C22: TCAUG | D22: 120746 | E22: =D22/$D$248 -> 0.020460388 | F22: =E22*$D$250 -> 2294729.7 | G22: =SUM(D22,F22) -> 2415475.7
A23: 2016 | B23: Bangor School Department | C23: TCBAN | D23: 141709 | E23: =D23/$D$248 -> 0.024012565 | F23: =E23*$D$250 -> 2693123.2 | G23: =SUM(D23,F23) -> 2834832.2
A24: 2016 | B24: Biddeford School Department | C24: TCBID | D24: 113337 | E24: =D24/$D$248 -> 0.019204935 | F24: =E24*$D$250 -> 2153924.6 | G24: =SUM(D24,F24) -> 2267261.6
A25: 2016 | B25: Brewer School Department | C25: TCBRE | D25: 11388 | E25: =D25/$D$248 -> 0.0019296946 | F25: =E25*$D$250 -> 216424.41 | G25: =SUM(D25,F25) -> 227812.41
A26: 2016 | B26: Brunswick School Department | C26: TCBRU | D26: 52062 | E26: =D26/$D$248 -> 0.0088218967 | F26: =E26*$D$250 -> 989417.6 | G26: =SUM(D26,F26) -> 1041479.6
A27: 2016 | B27: Calais School Department | C27: TCCAL | D27: 17726 | E27: =D27/$D$248 -> 0.0030036676 | F27: =E27*$D$250 -> 336875.58 | G27: =SUM(D27,F27) -> 354601.58
A28: 2016 | B28: Caswell School Department | C28: TCCAS | D28: 1082 | E28: =D28/$D$248 -> 0.00018334471 | F28: =E28*$D$250 -> 20562.98 | G28: =SUM(D28,F28) -> 21644.98
A29: 2016 | B29: Cape Elizabeth School Department | C29: TCCEL | D29: 14382 | E29: =D29/$D$248 -> 0.0024370274 | F29: =E29*$D$250 -> 273324.19 | G29: =SUM(D29,F29) -> 287706.19
A30: 2016 | B30: Chebeague Island School Department | C30: TCCHE | E30: =D30/$D$248 -> 0 | F30: =E30*$D$250 -> 0 | G30: =SUM(D30,F30) -> 0
A31: 2016 | B31: Cherryfield School Department | C31: TCCHR | D31: 3679 | E31: =D31/$D$248 -> 0.0006234059 | F31: =E31*$D$250 -> 69917.932 | G31: =SUM(D31,F31) -> 73596.932
A32: 2016 | B32: Dayton School Department | C32: TCDAY | D32: 4241 | E32: =D32/$D$248 -> 0.0007186367 | F32: =E32*$D$250 -> 80598.518 | G32: =SUM(D32,F32) -> 84839.518
A33: 2016 | B33: Easton School Department | C33: TCEAS | E33: =D33/$D$248 -> 0 | F33: =E33*$D$250 -> 0 | G33: =SUM(D33,F33) -> 0
A34: 2016 | B34: Ellsworth School Department | C34: TCELL | D34: 37977 | E34: =D34/$D$248 -> 0.0064351959 | F34: =E34*$D$250 -> 721737.78 | G34: =SUM(D34,F34) -> 759714.78
A35: 2016 | B35: East Millinocket School Department | C35: TCEML | D35: 9934 | E35: =D35/$D$248 -> 0.0016833145 | F35: =E35*$D$250 -> 188791.72 | G35: =SUM(D35,F35) -> 198725.72
A36: 2016 | B36: Eustis School Department | C36: TCEUS | D36: 3827 | E36: =D36/$D$248 -> 0.00064848447 | F36: =E36*$D$250 -> 72730.613 | G36: =SUM(D36,F36) -> 76557.613
A37: 2016 | B37: Falmouth School Department | C37: TCFAL | D37: 6047 | E37: =D37/$D$248 -> 0.0010246631 | F37: =E37*$D$250 -> 114920.83 | G37: =SUM(D37,F37) -> 120967.83
A38: 2016 | B38: Fayette School Department | C38: TCFAY | D38: 2276 | E38: =D38/$D$248 -> 0.0003856678 | F38: =E38*$D$250 -> 43254.475 | G38: =SUM(D38,F38) -> 45530.475
A39: 2016 | B39: Glenburn School Department | C39: TCGLE | D39: 6722 | E39: =D39/$D$248 -> 0.0011390417 | F39: =E39*$D$250 -> 127748.94 | G39: =SUM(D39,F39) -> 134470.94
A40: 2016 | B40: Gorham School Department | C40: TCGOR | D40: 41508 | E40: =D40/$D$248 -> 0.0070335233 | F40: =E40*$D$250 -> 788843.03 | G40: =SUM(D40,F40) -> 830351.03
...

Sheet 2017
A1: Year | B1: district_name | C1: employer_code | D1: district_contributions | F1: state_contributions | G1: total_contributions
A2: 2017 | B2: Isle Au Haut School Department | C2: T0802 | E2: =D2/$D$249 -> 0 | F2: =E2*$D$251 -> 0 | G2: =SUM(F2,D2) -> 0
A3: 2017 | B3: Monhegan Plantation School Department | C3: T0804 | E3: =D3/$D$249 -> 0 | F3: =E3*$D$251 -> 0 | G3: =SUM(F3,D3) -> 0
A4: 2017 | B4: CSD No. 13 Deer Isle - Stonington | C4: T0913 | D4: 9195 | E4: =D4/$D$249 -> 0.0015103763 | F4: =E4*$D$251 -> 175324.72 | G4: =SUM(F4,D4) -> 184519.72
A5: 2017 | B5: CSD No. 17 Moosabec | C5: T0917 | D5: 1028 | E5: =D5/$D$249 -> 0.0001688599 | F5: =E5*$D$251 -> 19601.285 | G5: =SUM(F5,D5) -> 20629.285
A6: 2017 | B6: CSD No. 18 Wells - Ogunquit | C6: T0918 | D6: 17994 | E6: =D6/$D$249 -> 0.0029557053 | F6: =E6*$D$251 -> 343098.76 | G6: =SUM(F6,D6) -> 361092.76
A7: 2017 | B7: CSD No. 19 Five Town CSD | C7: T0919 | D7: 6281 | E7: =D7/$D$249 -> 0.0010317209 | F7: =E7*$D$251 -> 119762.33 | G7: =SUM(F7,D7) -> 126043.33
A8: 2017 | B8: Erskine Academy | C8: TAERS | E8: =D8/$D$249 -> 0 | F8: =E8*$D$251 -> 0 | G8: =SUM(F8,D8) -> 0
A9: 2017 | B9: Foxcroft Academy | C9: TAFOX | E9: =D9/$D$249 -> 0 | F9: =E9*$D$251 -> 0 | G9: =SUM(F9,D9) -> 0
A10: 2017 | B10: Fryeburg Academy | C10: TAFRY | E10: =D10/$D$249 -> 0 | F10: =E10*$D$251 -> 0 | G10: =SUM(F10,D10) -> 0
A11: 2017 | B11: George Stevens Academy | C11: TAGEO | E11: =D11/$D$249 -> 0 | F11: =E11*$D$251 -> 0 | G11: =SUM(F11,D11) -> 0
A12: 2017 | B12: Gould Academy | C12: TAGOU | E12: =D12/$D$249 -> 0 | F12: =E12*$D$251 -> 0 | G12: =SUM(F12,D12) -> 0
A13: 2017 | B13: Lee Academy | C13: TALEE | E13: =D13/$D$249 -> 0 | F13: =E13*$D$251 -> 0 | G13: =SUM(F13,D13) -> 0
A14: 2017 | B14: Lincoln Academy | C14: TALIN | E14: =D14/$D$249 -> 0 | F14: =E14*$D$251 -> 0 | G14: =SUM(F14,D14) -> 0
A15: 2017 | B15: Maine Central Institute | C15: TAMCI | E15: =D15/$D$249 -> 0 | F15: =E15*$D$251 -> 0 | G15: =SUM(F15,D15) -> 0
A16: 2017 | B16: Thornton Academy | C16: TATHO | E16: =D16/$D$249 -> 0 | F16: =E16*$D$251 -> 0 | G16: =SUM(F16,D16) -> 0
A17: 2017 | B17: Washington Academy | C17: TAWAS | E17: =D17/$D$249 -> 0 | F17: =E17*$D$251 -> 0 | G17: =SUM(F17,D17) -> 0
A18: 2017 | B18: Acton School Department | C18: TCACT | D18: 7571 | E18: =D18/$D$249 -> 0.001243617 | F18: =E18*$D$251 -> 144359.27 | G18: =SUM(F18,D18) -> 151930.27
A19: 2017 | B19: Andover School Department | C19: TCAND | D19: 501 | E19: =D19/$D$249 -> 8.2294563e-05 | F19: =E19*$D$251 -> 9552.7664 | G19: =SUM(F19,D19) -> 10053.766
A20: 2017 | B20: Athens School Department | C20: TCATH | D20: 6864 | E20: =D20/$D$249 -> 0.0011274848 | F20: =E20*$D$251 -> 130878.62 | G20: =SUM(F20,D20) -> 137742.62
A21: 2017 | B21: Auburn School Department | C21: TCAUB | D21: 172871 | E21: =D21/$D$249 -> 0.028395895 | F21: =E21*$D$251 -> 3296200.1 | G21: =SUM(F21,D21) -> 3469071.1
A22: 2017 | B22: Augusta School Department | C22: TCAUG | D22: 118907 | E22: =D22/$D$249 -> 0.019531736 | F22: =E22*$D$251 -> 2267247.1 | G22: =SUM(F22,D22) -> 2386154.1
A23: 2017 | B23: Bangor School Department | C23: TCBAN | D23: 160631 | E23: =D23/$D$249 -> 0.026385345 | F23: =E23*$D$251 -> 3062815.2 | G23: =SUM(F23,D23) -> 3223446.2
A24: 2017 | B24: Biddeford School Department | C24: TCBID | D24: 77698 | E24: =D24/$D$249 -> 0.01276272 | F24: =E24*$D$251 -> 1481498.7 | G24: =SUM(F24,D24) -> 1559196.7
A25: 2017 | B25: Brewer School Department | C25: TCBRE | D25: 18591 | E25: =D25/$D$249 -> 0.0030537689 | F25: =E25*$D$251 -> 354481.99 | G25: =SUM(F25,D25) -> 373072.99
A26: 2017 | B26: Brunswick School Department | C26: TCBRU | D26: 38866 | E26: =D26/$D$249 -> 0.0063841527 | F26: =E26*$D$251 -> 741073.49 | G26: =SUM(F26,D26) -> 779939.49
A27: 2017 | B27: Calais School Department | C27: TCCAL | D27: 17406 | E27: =D27/$D$249 -> 0.0028591201 | F27: =E27*$D$251 -> 331887.13 | G27: =SUM(F27,D27) -> 349293.13
A28: 2017 | B28: Caswell School Department | C28: TCCAS | E28: =D28/$D$249 -> 0 | F28: =E28*$D$251 -> 0 | G28: =SUM(F28,D28) -> 0
A29: 2017 | B29: Cape Elizabeth School Department | C29: TCCEL | D29: 17389 | E29: =D29/$D$249 -> 0.0028563277 | F29: =E29*$D$251 -> 331562.98 | G29: =SUM(F29,D29) -> 348951.98
A30: 2017 | B30: Chebeague Island School Department | C30: TCCHE | E30: =D30/$D$249 -> 0 | F30: =E30*$D$251 -> 0 | G30: =SUM(F30,D30) -> 0
A31: 2017 | B31: Cherryfield School Department | C31: TCCHR | D31: 3666 | E31: =D31/$D$249 -> 0.00060217938 | F31: =E31*$D$251 -> 69901.081 | G31: =SUM(F31,D31) -> 73567.081
A32: 2017 | B32: Dayton School Department | C32: TCDAY | D32: 6105 | E32: =D32/$D$249 -> 0.001002811 | F32: =E32*$D$251 -> 116406.46 | G32: =SUM(F32,D32) -> 122511.46
A33: 2017 | B33: Easton School Department | C33: TCEAS | E33: =D33/$D$249 -> 0 | F33: =E33*$D$251 -> 0 | G33: =SUM(F33,D33) -> 0
A34: 2017 | B34: Ellsworth School Department | C34: TCELL | D34: 30143 | E34: =D34/$D$249 -> 0.0049513074 | F34: =E34*$D$251 -> 574748.58 | G34: =SUM(F34,D34) -> 604891.58
A35: 2017 | B35: East Millinocket School Department | C35: TCEML | D35: 10111 | E35: =D35/$D$249 -> 0.001660839 | F35: =E35*$D$251 -> 192790.46 | G35: =SUM(F35,D35) -> 202901.46
A36: 2017 | B36: Eustis School Department | C36: TCEUS | D36: 2739 | E36: =D36/$D$249 -> 0.0004499098 | F36: =E36*$D$251 -> 52225.603 | G36: =SUM(F36,D36) -> 54964.603
A37: 2017 | B37: Falmouth School Department | C37: TCFAL | D37: 10653 | E37: =D37/$D$249 -> 0.0017498682 | F37: =E37*$D$251 -> 203124.99 | G37: =SUM(F37,D37) -> 213777.99
A38: 2017 | B38: Fayette School Department | C38: TCFAY | D38: 2535 | E38: =D38/$D$249 -> 0.00041640063 | F38: =E38*$D$251 -> 48335.854 | G38: =SUM(F38,D38) -> 50870.854
A39: 2017 | B39: Glenburn School Department | C39: TCGLE | D39: 6933 | E39: =D39/$D$249 -> 0.0011388188 | F39: =E39*$D$251 -> 132194.27 | G39: =SUM(F39,D39) -> 139127.27
A40: 2017 | B40: Gorham School Department | C40: TCGOR | D40: 41590 | E40: =D40/$D$249 -> 0.0068315985 | F40: =E40*$D$251 -> 793013.08 | G40: =SUM(F40,D40) -> 834603.08
...

Sheet 2018
A1: Year | B1: district_name | C1: employer_code | D1: district_contributions | F1: state_contributions | G1: total_contributions
A2: 2018 | B2: Isle Au Haut School Department | C2: T0802 | E2: =D2/$D$250 -> 0 | F2: =E2*$D$252 -> 0 | G2: =SUM(D2,F2) -> 0
A3: 2018 | B3: Monhegan Plantation School Department | C3: T0804 | E3: =D3/$D$250 -> 0 | F3: =E3*$D$252 -> 0 | G3: =SUM(D3,F3) -> 0
A4: 2018 | B4: CSD No. 13 Deer Isle - Stonington | C4: T0913 | D4: 9751 | E4: =D4/$D$250 -> 0.0015319433 | F4: =E4*$D$252 -> 197645.88 | G4: =SUM(D4,F4) -> 207396.88
A5: 2018 | B5: CSD No. 17 Moosabec | C5: T0917 | D5: 1986 | E5: =D5/$D$250 -> 0.00031201307 | F5: =E5*$D$252 -> 40254.818 | G5: =SUM(D5,F5) -> 42240.818
A6: 2018 | B6: CSD No. 18 Wells - Ogunquit | C6: T0918 | D6: 19357 | E6: =D6/$D$250 -> 0.0030411062 | F6: =E6*$D$252 -> 392352.72 | G6: =SUM(D6,F6) -> 411709.72
A7: 2018 | B7: CSD No. 19 Five Town CSD | C7: T0919 | D7: 8720 | E7: =D7/$D$250 -> 0.0013699667 | F7: =E7*$D$252 -> 176748.24 | G7: =SUM(D7,F7) -> 185468.24
A8: 2018 | B8: Erskine Academy | C8: TAERS | E8: =D8/$D$250 -> 0 | F8: =E8*$D$252 -> 0 | G8: =SUM(D8,F8) -> 0
A9: 2018 | B9: Foxcroft Academy | C9: TAFOX | E9: =D9/$D$250 -> 0 | F9: =E9*$D$252 -> 0 | G9: =SUM(D9,F9) -> 0
A10: 2018 | B10: Fryeburg Academy | C10: TAFRY | E10: =D10/$D$250 -> 0 | F10: =E10*$D$252 -> 0 | G10: =SUM(D10,F10) -> 0
A11: 2018 | B11: George Stevens Academy | C11: TAGEO | E11: =D11/$D$250 -> 0 | F11: =E11*$D$252 -> 0 | G11: =SUM(D11,F11) -> 0
A12: 2018 | B12: Gould Academy | C12: TAGOU | E12: =D12/$D$250 -> 0 | F12: =E12*$D$252 -> 0 | G12: =SUM(D12,F12) -> 0
A13: 2018 | B13: Lee Academy | C13: TALEE | E13: =D13/$D$250 -> 0 | F13: =E13*$D$252 -> 0 | G13: =SUM(D13,F13) -> 0
A14: 2018 | B14: Lincoln Academy | C14: TALIN | E14: =D14/$D$250 -> 0 | F14: =E14*$D$252 -> 0 | G14: =SUM(D14,F14) -> 0
A15: 2018 | B15: Maine Central Institute | C15: TAMCI | E15: =D15/$D$250 -> 0 | F15: =E15*$D$252 -> 0 | G15: =SUM(D15,F15) -> 0
A16: 2018 | B16: Thornton Academy | C16: TATHO | E16: =D16/$D$250 -> 0 | F16: =E16*$D$252 -> 0 | G16: =SUM(D16,F16) -> 0
A17: 2018 | B17: Washington Academy | C17: TAWAS | E17: =D17/$D$250 -> 0 | F17: =E17*$D$252 -> 0 | G17: =SUM(D17,F17) -> 0
A18: 2018 | B18: Acton School Department | C18: TCACT | D18: 6256 | E18: =D18/$D$250 -> 0.00098285688 | F18: =E18*$D$252 -> 126804.7 | G18: =SUM(D18,F18) -> 133060.7
A19: 2018 | B19: Andover School Department | C19: TCAND | E19: =D19/$D$250 -> 0 | F19: =E19*$D$252 -> 0 | G19: =SUM(D19,F19) -> 0
A20: 2018 | B20: Athens School Department | C20: TCATH | D20: 9962 | E20: =D20/$D$250 -> 0.0015650927 | F20: =E20*$D$252 -> 201922.71 | G20: =SUM(D20,F20) -> 211884.71
A21: 2018 | B21: Auburn School Department | C21: TCAUB | D21: 136597 | E21: =D21/$D$250 -> 0.021460246 | F21: =E21*$D$252 -> 2768724.7 | G21: =SUM(D21,F21) -> 2905321.7
A22: 2018 | B22: Augusta School Department | C22: TCAUG | D22: 135720 | E22: =D22/$D$250 -> 0.021322464 | F22: =E22*$D$252 -> 2750948.6 | G22: =SUM(D22,F22) -> 2886668.6
A23: 2018 | B23: Bangor School Department | C23: TCBAN | D23: 188548 | E23: =D23/$D$250 -> 0.029622075 | F23: =E23*$D$252 -> 3821734.8 | G23: =SUM(D23,F23) -> 4010282.8
A24: 2018 | B24: Biddeford School Department | C24: TCBID | D24: 122133 | E24: =D24/$D$250 -> 0.019187861 | F24: =E24*$D$252 -> 2475549.7 | G24: =SUM(D24,F24) -> 2597682.7
A25: 2018 | B25: Brewer School Department | C25: TCBRE | D25: 26765 | E25: =D25/$D$250 -> 0.0042049495 | F25: =E25*$D$252 -> 542507.65 | G25: =SUM(D25,F25) -> 569272.65
A26: 2018 | B26: Brunswick School Department | C26: TCBRU | D26: 32833 | E26: =D26/$D$250 -> 0.0051582704 | F26: =E26*$D$252 -> 665501.72 | G26: =SUM(D26,F26) -> 698334.72
A27: 2018 | B27: Calais School Department | C27: TCCAL | D27: 20400 | E27: =D27/$D$250 -> 0.0032049681 | F27: =E27*$D$252 -> 413493.59 | G27: =SUM(D27,F27) -> 433893.59
A28: 2018 | B28: Caswell School Department | C28: TCCAS | D28: 1596 | E28: =D28/$D$250 -> 0.00025074162 | F28: =E28*$D$252 -> 32349.793 | G28: =SUM(D28,F28) -> 33945.793
A29: 2018 | B29: Cape Elizabeth School Department | C29: TCCEL | D29: 21108 | E29: =D29/$D$250 -> 0.0033161993 | F29: =E29*$D$252 -> 427844.25 | G29: =SUM(D29,F29) -> 448952.25
A30: 2018 | B30: Chebeague Island School Department | C30: TCCHE | E30: =D30/$D$250 -> 0 | F30: =E30*$D$252 -> 0 | G30: =SUM(D30,F30) -> 0
A31: 2018 | B31: Cherryfield School Department | C31: TCCHR | D31: 2137 | E31: =D31/$D$250 -> 0.00033573612 | F31: =E31*$D$252 -> 43315.481 | G31: =SUM(D31,F31) -> 45452.481
A32: 2018 | B32: Dayton School Department | C32: TCDAY | D32: 6488 | E32: =D32/$D$250 -> 0.0010193055 | F32: =E32*$D$252 -> 131507.18 | G32: =SUM(D32,F32) -> 137995.18
A33: 2018 | B33: Easton School Department | C33: TCEAS | E33: =D33/$D$250 -> 0 | F33: =E33*$D$252 -> 0 | G33: =SUM(D33,F33) -> 0
A34: 2018 | B34: Ellsworth School Department | C34: TCELL | D34: 40646 | E34: =D34/$D$250 -> 0.0063857418 | F34: =E34*$D$252 -> 823865.72 | G34: =SUM(D34,F34) -> 864511.72
A35: 2018 | B35: East Millinocket School Department | C35: TCEML | D35: 12214 | E35: =D35/$D$250 -> 0.0019188961 | F35: =E35*$D$252 -> 247569.15 | G35: =SUM(D35,F35) -> 259783.15
A36: 2018 | B36: Eustis School Department | C36: TCEUS | D36: 5170 | E36: =D36/$D$250 -> 0.00081223946 | F36: =E36*$D$252 -> 104792.25 | G36: =SUM(D36,F36) -> 109962.25
A37: 2018 | B37: Falmouth School Department | C37: TCFAL | D37: 12558 | E37: =D37/$D$250 -> 0.0019729406 | F37: =E37*$D$252 -> 254541.79 | G37: =SUM(D37,F37) -> 267099.79
A38: 2018 | B38: Fayette School Department | C38: TCFAY | D38: 2454 | E38: =D38/$D$250 -> 0.00038553881 | F38: =E38*$D$252 -> 49740.847 | G38: =SUM(D38,F38) -> 52194.847
A39: 2018 | B39: Glenburn School Department | C39: TCGLE | D39: 7970 | E39: =D39/$D$250 -> 0.001252137 | F39: =E39*$D$252 -> 161546.27 | G39: =SUM(D39,F39) -> 169516.27
A40: 2018 | B40: Gorham School Department | C40: TCGOR | D40: 40533 | E40: =D40/$D$250 -> 0.0063679888 | F40: =E40*$D$252 -> 821575.29 | G40: =SUM(D40,F40) -> 862108.29
...

Sheet 2019
A1: Year | B1: district_name | C1: employer_code | D1: district_contributions | F1: state_contributions | G1: total_contributions
A2: 2019 | B2: Isle Au Haut School Department | C2: T0802 | E2: =D2/$D$253 -> 0 | F2: =E2*$D$255 -> 0 | G2: =SUM(F2,D2) -> 0
A3: 2019 | B3: Monhegan Plantation School Department | C3: T0804 | E3: =D3/$D$253 -> 0 | F3: =E3*$D$255 -> 0 | G3: =SUM(F3,D3) -> 0
A4: 2019 | B4: CSD No. 13 Deer Isle - Stonington | C4: T0913 | D4: 7782 | E4: =D4/$D$253 -> 0.0012576669 | F4: =E4*$D$255 -> 166721.85 | G4: =SUM(F4,D4) -> 174503.85
A5: 2019 | B5: CSD No. 17 Moosabec | C5: T0917 | D5: 1945 | E5: =D5/$D$253 -> 0.00031433592 | F5: =E5*$D$255 -> 41669.751 | G5: =SUM(F5,D5) -> 43614.751
A6: 2019 | B6: CSD No. 18 Wells - Ogunquit | C6: T0918 | D6: 26369 | E6: =D6/$D$253 -> 0.0042615546 | F6: =E6*$D$255 -> 564930.42 | G6: =SUM(F6,D6) -> 591299.42
A7: 2019 | B7: CSD No. 19 Five Town CSD | C7: T0919 | D7: 6981 | E7: =D7/$D$253 -> 0.0011282154 | F7: =E7*$D$255 -> 149561.2 | G7: =SUM(F7,D7) -> 156542.2
A8: 2019 | B8: Erskine Academy | C8: TAERS | E8: =D8/$D$253 -> 0 | F8: =E8*$D$255 -> 0 | G8: =SUM(F8,D8) -> 0
A9: 2019 | B9: Foxcroft Academy | C9: TAFOX | E9: =D9/$D$253 -> 0 | F9: =E9*$D$255 -> 0 | G9: =SUM(F9,D9) -> 0
A10: 2019 | B10: Fryeburg Academy | C10: TAFRY | E10: =D10/$D$253 -> 0 | F10: =E10*$D$255 -> 0 | G10: =SUM(F10,D10) -> 0
A11: 2019 | B11: George Stevens Academy | C11: TAGEO | E11: =D11/$D$253 -> 0 | F11: =E11*$D$255 -> 0 | G11: =SUM(F11,D11) -> 0
A12: 2019 | B12: Gould Academy | C12: TAGOU | E12: =D12/$D$253 -> 0 | F12: =E12*$D$255 -> 0 | G12: =SUM(F12,D12) -> 0
A13: 2019 | B13: Lee Academy | C13: TALEE | E13: =D13/$D$253 -> 0 | F13: =E13*$D$255 -> 0 | G13: =SUM(F13,D13) -> 0
A14: 2019 | B14: Lincoln Academy | C14: TALIN | E14: =D14/$D$253 -> 0 | F14: =E14*$D$255 -> 0 | G14: =SUM(F14,D14) -> 0
A15: 2019 | B15: Maine Central Institute | C15: TAMCI | E15: =D15/$D$253 -> 0 | F15: =E15*$D$255 -> 0 | G15: =SUM(F15,D15) -> 0
A16: 2019 | B16: Thornton Academy | C16: TATHO | E16: =D16/$D$253 -> 0 | F16: =E16*$D$255 -> 0 | G16: =SUM(F16,D16) -> 0
A17: 2019 | B17: Washington Academy | C17: TAWAS | E17: =D17/$D$253 -> 0 | F17: =E17*$D$255 -> 0 | G17: =SUM(F17,D17) -> 0
A18: 2019 | B18: Acton School Department | C18: TCACT | D18: 5858 | E18: =D18/$D$253 -> 0.00094672483 | F18: =E18*$D$255 -> 125502.01 | G18: =SUM(F18,D18) -> 131360.01
A19: 2019 | B19: Andover School Department | C19: TCAND | D19: 3084 | E19: =D19/$D$253 -> 0.00049841232 | F19: =E19*$D$255 -> 66071.728 | G19: =SUM(F19,D19) -> 69155.728
A20: 2019 | B20: Athens School Department | C20: TCATH | D20: 6820 | E20: =D20/$D$253 -> 0.0011021959 | F20: =E20*$D$255 -> 146111.93 | G20: =SUM(F20,D20) -> 152931.93
A21: 2019 | B21: Auburn School Department | C21: TCAUB | D21: 137736 | E21: =D21/$D$253 -> 0.022259831 | F21: =E21*$D$255 -> 2950861.1 | G21: =SUM(F21,D21) -> 3088597.1
A22: 2019 | B22: Augusta School Department | C22: TCAUG | D22: 127715 | E22: =D22/$D$253 -> 0.020640314 | F22: =E22*$D$255 -> 2736170.8 | G22: =SUM(F22,D22) -> 2863885.8
A23: 2019 | B23: Bangor School Department | C23: TCBAN | D23: 202991 | E23: =D23/$D$253 -> 0.032805842 | F23: =E23*$D$255 -> 4348886.6 | G23: =SUM(F23,D23) -> 4551877.6
A24: 2019 | B24: Biddeford School Department | C24: TCBID | D24: 78470 | E24: =D24/$D$253 -> 0.012681717 | F24: =E24*$D$255 -> 1681144.1 | G24: =SUM(F24,D24) -> 1759614.1
A25: 2019 | B25: Brewer School Department | C25: TCBRE | D25: 29387 | E25: =D25/$D$253 -> 0.0047493005 | F25: =E25*$D$255 -> 629588.16 | G25: =SUM(F25,D25) -> 658975.16
A26: 2019 | B26: Brunswick School Department | C26: TCBRU | D26: 33599 | E26: =D26/$D$253 -> 0.0054300115 | F26: =E26*$D$255 -> 719826.2 | G26: =SUM(F26,D26) -> 753425.2
A27: 2019 | B27: Calais School Department | C27: TCCAL | D27: 18582 | E27: =D27/$D$253 -> 0.0030030797 | F27: =E27*$D$255 -> 398101.44 | G27: =SUM(F27,D27) -> 416683.44
A28: 2019 | B28: Caswell School Department | C28: TCCAS | D28: 1785 | E28: =D28/$D$253 -> 0.00028847795 | F28: =E28*$D$255 -> 38241.905 | G28: =SUM(F28,D28) -> 40026.905
A29: 2019 | B29: Cape Elizabeth School Department | C29: TCCEL | D29: 23281 | E29: =D29/$D$253 -> 0.0037624959 | F29: =E29*$D$255 -> 498772.99 | G29: =SUM(F29,D29) -> 522053.99
A30: 2019 | B30: Chebeague Island School Department | C30: TCCHE | E30: =D30/$D$253 -> 0 | F30: =E30*$D$255 -> 0 | G30: =SUM(F30,D30) -> 0
A31: 2019 | B31: Cherryfield School Department | C31: TCCHR | D31: 3135 | E31: =D31/$D$253 -> 0.00050665455 | F31: =E31*$D$255 -> 67164.354 | G31: =SUM(F31,D31) -> 70299.354
A32: 2019 | B32: Dayton School Department | C32: TCDAY | D32: 3465 | E32: =D32/$D$253 -> 0.00055998661 | F32: =E32*$D$255 -> 74234.286 | G32: =SUM(F32,D32) -> 77699.286
A33: 2019 | B33: Easton School Department | C33: TCEAS | E33: =D33/$D$253 -> 0 | F33: =E33*$D$255 -> 0 | G33: =SUM(F33,D33) -> 0
A34: 2019 | B34: Ellsworth School Department | C34: TCELL | D34: 40465 | E34: =D34/$D$253 -> 0.0065396416 | F34: =E34*$D$255 -> 866923.63 | G34: =SUM(F34,D34) -> 907388.63
A35: 2019 | B35: East Millinocket School Department | C35: TCEML | D35: 11306 | E35: =D35/$D$253 -> 0.0018271886 | F35: =E35*$D$255 -> 242220.16 | G35: =SUM(F35,D35) -> 253526.16
A36: 2019 | B36: Eustis School Department | C36: TCEUS | D36: 6238 | E36: =D36/$D$253 -> 0.0010081375 | F36: =E36*$D$255 -> 133643.14 | G36: =SUM(F36,D36) -> 139881.14
A37: 2019 | B37: Falmouth School Department | C37: TCFAL | D37: 8211 | E37: =D37/$D$253 -> 0.0013269986 | F37: =E37*$D$255 -> 175912.76 | G37: =SUM(F37,D37) -> 184123.76
A38: 2019 | B38: Fayette School Department | C38: TCFAY | D38: 2184 | E38: =D38/$D$253 -> 0.00035296125 | F38: =E38*$D$255 -> 46790.096 | G38: =SUM(F38,D38) -> 48974.096
A39: 2019 | B39: Glenburn School Department | C39: TCGLE | D39: 8316 | E39: =D39/$D$253 -> 0.0013439679 | F39: =E39*$D$255 -> 178162.29 | G39: =SUM(F39,D39) -> 186478.29
A40: 2019 | B40: Gorham School Department | C40: TCGOR | D40: 40776 | E40: =D40/$D$253 -> 0.006589903 | F40: =E40*$D$255 -> 873586.51 | G40: =SUM(F40,D40) -> 914362.51
...

Sheet 2020
A1: Year | B1: district_name | C1: employer_code | D1: district_contributions | F1: state_contributions | G1: total_contributions
A2: 2020 | B2: Isle Au Haut School Department | C2: T0802 | E2: =D2/$D$254 -> 0 | F2: =E2*$D$256 -> 0 | G2: =SUM(F2,D2) -> 0
A3: 2020 | B3: Monhegan Plantation School Department | C3: T0804 | E3: =D3/$D$254 -> 0 | F3: =E3*$D$256 -> 0 | G3: =SUM(F3,D3) -> 0
A4: 2020 | B4: CSD No. 13 Deer Isle - Stonington | C4: T0913 | D4: 10566 | E4: =D4/$D$254 -> 0.0013523296 | F4: =E4*$D$256 -> 235430.84 | G4: =SUM(F4,D4) -> 245996.84
A5: 2020 | B5: CSD No. 17 Moosabec | C5: T0917 | D5: 3914 | E5: =D5/$D$254 -> 0.00050094814 | F5: =E5*$D$256 -> 87211.463 | G5: =SUM(F5,D5) -> 91125.463
A6: 2020 | B6: CSD No. 18 Wells - Ogunquit | C6: T0918 | D6: 42431 | E6: =D6/$D$254 -> 0.0054306925 | F6: =E6*$D$256 -> 945444.45 | G6: =SUM(F6,D6) -> 987875.45
A7: 2020 | B7: CSD No. 19 Five Town CSD | C7: T0919 | D7: 8218 | E7: =D7/$D$254 -> 0.0010518119 | F7: =E7*$D$256 -> 183112.88 | G7: =SUM(F7,D7) -> 191330.88
A8: 2020 | B8: Erskine Academy | C8: TAERS | E8: =D8/$D$254 -> 0 | F8: =E8*$D$256 -> 0 | G8: =SUM(F8,D8) -> 0
A9: 2020 | B9: Foxcroft Academy | C9: TAFOX | E9: =D9/$D$254 -> 0 | F9: =E9*$D$256 -> 0 | G9: =SUM(F9,D9) -> 0
A10: 2020 | B10: Fryeburg Academy | C10: TAFRY | E10: =D10/$D$254 -> 0 | F10: =E10*$D$256 -> 0 | G10: =SUM(F10,D10) -> 0
A11: 2020 | B11: George Stevens Academy | C11: TAGEO | E11: =D11/$D$254 -> 0 | F11: =E11*$D$256 -> 0 | G11: =SUM(F11,D11) -> 0
A12: 2020 | B12: Gould Academy | C12: TAGOU | E12: =D12/$D$254 -> 0 | F12: =E12*$D$256 -> 0 | G12: =SUM(F12,D12) -> 0
A13: 2020 | B13: Lee Academy | C13: TALEE | E13: =D13/$D$254 -> 0 | F13: =E13*$D$256 -> 0 | G13: =SUM(F13,D13) -> 0
A14: 2020 | B14: Lincoln Academy | C14: TALIN | E14: =D14/$D$254 -> 0 | F14: =E14*$D$256 -> 0 | G14: =SUM(F14,D14) -> 0
A15: 2020 | B15: Maine Central Institute | C15: TAMCI | E15: =D15/$D$254 -> 0 | F15: =E15*$D$256 -> 0 | G15: =SUM(F15,D15) -> 0
A16: 2020 | B16: Thornton Academy | C16: TATHO | E16: =D16/$D$254 -> 0 | F16: =E16*$D$256 -> 0 | G16: =SUM(F16,D16) -> 0
A17: 2020 | B17: Washington Academy | C17: TAWAS | E17: =D17/$D$254 -> 0 | F17: =E17*$D$256 -> 0 | G17: =SUM(F17,D17) -> 0
A18: 2020 | B18: Acton School Department | C18: TCACT | D18: 6799 | E18: =D18/$D$254 -> 0.00087019581 | F18: =E18*$D$256 -> 151494.82 | G18: =SUM(F18,D18) -> 158293.82
A19: 2020 | B19: Andover School Department | C19: TCAND | D19: 2732 | E19: =D19/$D$254 -> 0.00034966539 | F19: =E19*$D$256 -> 60874.225 | G19: =SUM(F19,D19) -> 63606.225
A20: 2020 | B20: Athens School Department | C20: TCATH | D20: 5885 | E20: =D20/$D$254 -> 0.00075321405 | F20: =E20*$D$256 -> 131129.14 | G20: =SUM(F20,D20) -> 137014.14
A21: 2020 | B21: Auburn School Department | C21: TCAUB | D21: 151327 | E21: =D21/$D$254 -> 0.01936816 | F21: =E21*$D$256 -> 3371857.2 | G21: =SUM(F21,D21) -> 3523184.2
A22: 2020 | B22: Augusta School Department | C22: TCAUG | D22: 160360 | E22: =D22/$D$254 -> 0.020524283 | F22: =E22*$D$256 -> 3573129.8 | G22: =SUM(F22,D22) -> 3733489.8
A23: 2020 | B23: Bangor School Department | C23: TCBAN | D23: 241833 | E23: =D23/$D$254 -> 0.030951914 | F23: =E23*$D$256 -> 5388505.3 | G23: =SUM(F23,D23) -> 5630338.3
A24: 2020 | B24: Biddeford School Department | C24: TCBID | D24: 103675 | E24: =D24/$D$254 -> 0.013269238 | F24: =E24*$D$256 -> 2310078.8 | G24: =SUM(F24,D24) -> 2413753.8
A25: 2020 | B25: Brewer School Department | C25: TCBRE | D25: 28032 | E25: =D25/$D$254 -> 0.0035877819 | F25: =E25*$D$256 -> 624606.98 | G25: =SUM(F25,D25) -> 652638.98
A26: 2020 | B26: Brunswick School Department | C26: TCBRU | D26: 37494 | E26: =D26/$D$254 -> 0.0047988119 | F26: =E26*$D$256 -> 835438.57 | G26: =SUM(F26,D26) -> 872932.57
A27: 2020 | B27: Calais School Department | C27: TCCAL | D27: 28321 | E27: =D27/$D$254 -> 0.0036247706 | F27: =E27*$D$256 -> 631046.46 | G27: =SUM(F27,D27) -> 659367.46
A28: 2020 | B28: Caswell School Department | C28: TCCAS | D28: 2914 | E28: =D28/$D$254 -> 0.00037295935 | F28: =E28*$D$256 -> 64929.535 | G28: =SUM(F28,D28) -> 67843.535
A29: 2020 | B29: Cape Elizabeth School Department | C29: TCCEL | D29: 28284 | E29: =D29/$D$254 -> 0.0036200351 | F29: =E29*$D$256 -> 630222.02 | G29: =SUM(F29,D29) -> 658506.02
A30: 2020 | B30: Chebeague Island School Department | C30: TCCHE | E30: =D30/$D$254 -> 0 | F30: =E30*$D$256 -> 0 | G30: =SUM(F30,D30) -> 0
A31: 2020 | B31: Cherryfield School Department | C31: TCCHR | D31: 11605 | E31: =D31/$D$254 -> 0.00148531 | F31: =E31*$D$256 -> 258581.76 | G31: =SUM(F31,D31) -> 270186.76
A32: 2020 | B32: Dayton School Department | C32: TCDAY | D32: 4509 | E32: =D32/$D$254 -> 0.00057710147 | F32: =E32*$D$256 -> 100469.21 | G32: =SUM(F32,D32) -> 104978.21
A33: 2020 | B33: Easton School Department | C33: TCEAS | E33: =D33/$D$254 -> 0 | F33: =E33*$D$256 -> 0 | G33: =SUM(F33,D33) -> 0
A34: 2020 | B34: Ellsworth School Department | C34: TCELL | D34: 39080 | E34: =D34/$D$254 -> 0.0050018021 | F34: =E34*$D$256 -> 870777.71 | G34: =SUM(F34,D34) -> 909857.71
A35: 2020 | B35: East Millinocket School Department | C35: TCEML | D35: 19808 | E35: =D35/$D$254 -> 0.002535202 | F35: =E35*$D$256 -> 441360.41 | G35: =SUM(F35,D35) -> 461168.41
A36: 2020 | B36: Eustis School Department | C36: TCEUS | D36: 5475 | E36: =D36/$D$254 -> 0.00070073865 | F36: =E36*$D$256 -> 121993.55 | G36: =SUM(F36,D36) -> 127468.55
A37: 2020 | B37: Falmouth School Department | C37: TCFAL | D37: 2472 | E37: =D37/$D$254 -> 0.0003163883 | F37: =E37*$D$256 -> 55080.924 | G37: =SUM(F37,D37) -> 57552.924
A38: 2020 | B38: Fayette School Department | C38: TCFAY | D38: 2266 | E38: =D38/$D$254 -> 0.00029002261 | F38: =E38*$D$256 -> 50490.847 | G38: =SUM(F38,D38) -> 52756.847
A39: 2020 | B39: Glenburn School Department | C39: TCGLE | D39: 8343 | E39: =D39/$D$254 -> 0.0010678105 | F39: =E39*$D$256 -> 185898.12 | G39: =SUM(F39,D39) -> 194241.12
A40: 2020 | B40: Gorham School Department | C40: TCGOR | D40: 41687 | E40: =D40/$D$254 -> 0.0053354689 | F40: =E40*$D$256 -> 928866.69 | G40: =SUM(F40,D40) -> 970553.69
...

Sheet 2021
A1: Year | B1: district_name | C1: employer_code | D1: district_contributions | F1: state_contributions | G1: total_contributions
A2: 2021 | B2: Isle Au Haut School Department | C2: T0802 | E2: =D2/$D$254 -> 0 | F2: =E2*$D$257 -> 0 | G2: =SUM(F2,D2) -> 0
A3: 2021 | B3: Monhegan Plantation School Department | C3: T0804 | E3: =D3/$D$254 -> 0 | F3: =E3*$D$257 -> 0 | G3: =SUM(F3,D3) -> 0
A4: 2021 | B4: CSD No. 13 Deer Isle - Stonington | C4: T0913 | D4: 35987 | E4: =D4/$D$254 -> 0.0033796795 | F4: =E4*$D$257 -> 604558.22 | G4: =SUM(F4,D4) -> 640545.22
A5: 2021 | B5: CSD No. 17 Moosabec | C5: T0917 | D5: 1902 | E5: =D5/$D$254 -> 0.00017862424 | F5: =E5*$D$257 -> 31952.364 | G5: =SUM(F5,D5) -> 33854.364
A6: 2021 | B6: CSD No. 18 Wells - Ogunquit | C6: T0918 | D6: 41449 | E6: =D6/$D$254 -> 0.0038926373 | F6: =E6*$D$257 -> 696316.28 | G6: =SUM(F6,D6) -> 737765.28
A7: 2021 | B7: CSD No. 19 Five Town CSD | C7: T0919 | D7: 20514 | E7: =D7/$D$254 -> 0.0019265498 | F7: =E7*$D$257 -> 344621.87 | G7: =SUM(F7,D7) -> 365135.87
A8: 2021 | B8: Erskine Academy | C8: TAERS | E8: =D8/$D$254 -> 0 | F8: =E8*$D$257 -> 0 | G8: =SUM(F8,D8) -> 0
A9: 2021 | B9: Foxcroft Academy | C9: TAFOX | E9: =D9/$D$254 -> 0 | F9: =E9*$D$257 -> 0 | G9: =SUM(F9,D9) -> 0
A10: 2021 | B10: Fryeburg Academy | C10: TAFRY | E10: =D10/$D$254 -> 0 | F10: =E10*$D$257 -> 0 | G10: =SUM(F10,D10) -> 0
A11: 2021 | B11: George Stevens Academy | C11: TAGEO | E11: =D11/$D$254 -> 0 | F11: =E11*$D$257 -> 0 | G11: =SUM(F11,D11) -> 0
A12: 2021 | B12: Gould Academy | C12: TAGOU | E12: =D12/$D$254 -> 0 | F12: =E12*$D$257 -> 0 | G12: =SUM(F12,D12) -> 0
A13: 2021 | B13: Lee Academy | C13: TALEE | E13: =D13/$D$254 -> 0 | F13: =E13*$D$257 -> 0 | G13: =SUM(F13,D13) -> 0
A14: 2021 | B14: Lincoln Academy | C14: TALIN | E14: =D14/$D$254 -> 0 | F14: =E14*$D$257 -> 0 | G14: =SUM(F14,D14) -> 0
A15: 2021 | B15: Maine Central Institute | C15: TAMCI | E15: =D15/$D$254 -> 0 | F15: =E15*$D$257 -> 0 | G15: =SUM(F15,D15) -> 0
A16: 2021 | B16: Thornton Academy | C16: TATHO | E16: =D16/$D$254 -> 0 | F16: =E16*$D$257 -> 0 | G16: =SUM(F16,D16) -> 0
A17: 2021 | B17: Washington Academy | C17: TAWAS | E17: =D17/$D$254 -> 0 | F17: =E17*$D$257 -> 0 | G17: =SUM(F17,D17) -> 0
A18: 2021 | B18: Acton School Department | C18: TCACT | D18: 7419 | E18: =D18/$D$254 -> 0.00069674723 | F18: =E18*$D$257 -> 124634.38 | G18: =SUM(F18,D18) -> 132053.38
A19: 2021 | B19: Andover School Department | C19: TCAND | D19: 2637 | E19: =D19/$D$254 -> 0.00024765096 | F19: =E19*$D$257 -> 44299.887 | G19: =SUM(F19,D19) -> 46936.887
A20: 2021 | B20: Athens School Department | C20: TCATH | D20: 7275 | E20: =D20/$D$254 -> 0.00068322362 | F20: =E20*$D$257 -> 122215.27 | G20: =SUM(F20,D20) -> 129490.27
A21: 2021 | B21: Auburn School Department | C21: TCAUB | D21: 144530 | E21: =D21/$D$254 -> 0.013573376 | F21: =E21*$D$257 -> 2428010.1 | G21: =SUM(F21,D21) -> 2572540.1
A22: 2021 | B22: Augusta School Department | C22: TCAUG | D22: 210150 | E22: =D22/$D$254 -> 0.019736006 | F22: =E22*$D$257 -> 3530383.5 | G22: =SUM(F22,D22) -> 3740533.5
A23: 2021 | B23: Bangor School Department | C23: TCBAN | D23: 231167 | E23: =D23/$D$254 -> 0.021709795 | F23: =E23*$D$257 -> 3883455.4 | G23: =SUM(F23,D23) -> 4114622.4
A24: 2021 | B24: Biddeford School Department | C24: TCBID | D24: 198056 | E24: =D24/$D$254 -> 0.018600211 | F24: =E24*$D$257 -> 3327212.1 | G24: =SUM(F24,D24) -> 3525268.1
A25: 2021 | B25: Brewer School Department | C25: TCBRE | D25: 59539 | E25: =D25/$D$254 -> 0.0055915397 | F25: =E25*$D$257 -> 1000216.5 | G25: =SUM(F25,D25) -> 1059755.5
A26: 2021 | B26: Brunswick School Department | C26: TCBRU | D26: 62332 | E26: =D26/$D$254 -> 0.0058538412 | F26: =E26*$D$257 -> 1047137.1 | G26: =SUM(F26,D26) -> 1109469.1
A27: 2021 | B27: Calais School Department | C27: TCCAL | D27: 34635 | E27: =D27/$D$254 -> 0.0032527079 | F27: =E27*$D$257 -> 581845.5 | G27: =SUM(F27,D27) -> 616480.5
A28: 2021 | B28: Caswell School Department | C28: TCCAS | D28: 1984 | E28: =D28/$D$254 -> 0.00018632518 | F28: =E28*$D$257 -> 33329.911 | G28: =SUM(F28,D28) -> 35313.911
A29: 2021 | B29: Cape Elizabeth School Department | C29: TCCEL | D29: 29693 | E29: =D29/$D$254 -> 0.0027885854 | F29: =E29*$D$257 -> 498823.11 | G29: =SUM(F29,D29) -> 528516.11
A30: 2021 | B30: Chebeague Island School Department | C30: TCCHE | E30: =D30/$D$254 -> 0 | F30: =E30*$D$257 -> 0 | G30: =SUM(F30,D30) -> 0
A31: 2021 | B31: Cherryfield School Department | C31: TCCHR | D31: 9144 | E31: =D31/$D$254 -> 0.0008587487 | F31: =E31*$D$257 -> 153613.26 | G31: =SUM(F31,D31) -> 162757.26
A32: 2021 | B32: Dayton School Department | C32: TCDAY | D32: 7639 | E32: =D32/$D$254 -> 0.00071740828 | F32: =E32*$D$257 -> 128330.24 | G32: =SUM(F32,D32) -> 135969.24
A33: 2021 | B33: Easton School Department | C33: TCEAS | D33: 2462 | E33: =D33/$D$254 -> 0.00023121602 | F33: =E33*$D$257 -> 41360.001 | G33: =SUM(F33,D33) -> 43822.001
A34: 2021 | B34: Ellsworth School Department | C34: TCELL | D34: 146108 | E34: =D34/$D$254 -> 0.013721572 | F34: =E34*$D$257 -> 2454519.5 | G34: =SUM(F34,D34) -> 2600627.5
A35: 2021 | B35: East Millinocket School Department | C35: TCEML | D35: 19433 | E35: =D35/$D$254 -> 0.0018250288 | F35: =E35*$D$257 -> 326461.78 | G35: =SUM(F35,D35) -> 345894.78
A36: 2021 | B36: Eustis School Department | C36: TCEUS | D36: 12131 | E36: =D36/$D$254 -> 0.0011392695 | F36: =E36*$D$257 -> 203792.92 | G36: =SUM(F36,D36) -> 215923.92
A37: 2021 | B37: Falmouth School Department | C37: TCFAL | D37: 50376 | E37: =D37/$D$254 -> 0.0047310066 | F37: =E37*$D$257 -> 846284.08 | G37: =SUM(F37,D37) -> 896660.08
A38: 2021 | B38: Fayette School Department | C38: TCFAY | D38: 3091 | E38: =D38/$D$254 -> 0.00029028787 | F38: =E38*$D$257 -> 51926.792 | G38: =SUM(F38,D38) -> 55017.792
A39: 2021 | B39: Glenburn School Department | C39: TCGLE | D39: 8500 | E39: =D39/$D$254 -> 0.00079826815 | F39: =E39*$D$257 -> 142794.48 | G39: =SUM(F39,D39) -> 151294.48
A40: 2021 | B40: Gorham School Department | C40: TCGOR | D40: 47795 | E40: =D40/$D$254 -> 0.0044886149 | F40: =E40*$D$257 -> 802924.95 | G40: =SUM(F40,D40) -> 850719.95
...

Sheet 2022
A1: Year | B1: district_name | C1: employer_code | D1: district_contributions | F1: state_contributions | G1: total_contributions
A2: 2022 | B2: Isle Au Haut School Department | C2: T0802 | E2: =D2/$D$255 -> 0 | F2: =E2*$D$257 -> 0 | G2: =SUM(F2,D2) -> 0
A3: 2022 | B3: Monhegan Plantation School Department | C3: T0804 | E3: =D3/$D$255 -> 0 | F3: =E3*$D$257 -> 0 | G3: =SUM(F3,D3) -> 0
A4: 2022 | B4: CSD No. 13 Deer Isle - Stonington | C4: T0913 | D4: 47998 | E4: =D4/$D$255 -> 0.003557292 | F4: =E4*$D$257 -> 690929.9 | G4: =SUM(F4,D4) -> 738927.9
A5: 2022 | B5: CSD No. 17 Moosabec | C5: T0917 | D5: 2592 | E5: =D5/$D$255 -> 0.00019210177 | F5: =E5*$D$257 -> 37311.769 | G5: =SUM(F5,D5) -> 39903.769
A6: 2022 | B6: CSD No. 18 Wells - Ogunquit | C6: T0918 | D6: 83037 | E6: =D6/$D$255 -> 0.0061541492 | F6: =E6*$D$257 -> 1195315.4 | G6: =SUM(F6,D6) -> 1278352.4
A7: 2022 | B7: CSD No. 19 Five Town CSD | C7: T0919 | D7: 14224 | E7: =D7/$D$255 -> 0.0010541881 | F7: =E7*$D$257 -> 204754.09 | G7: =SUM(F7,D7) -> 218978.09
A8: 2022 | B8: Erskine Academy | C8: TAERS | E8: =D8/$D$255 -> 0 | F8: =E8*$D$257 -> 0 | G8: =SUM(F8,D8) -> 0
A9: 2022 | B9: Foxcroft Academy | C9: TAFOX | E9: =D9/$D$255 -> 0 | F9: =E9*$D$257 -> 0 | G9: =SUM(F9,D9) -> 0
A10: 2022 | B10: Fryeburg Academy | C10: TAFRY | E10: =D10/$D$255 -> 0 | F10: =E10*$D$257 -> 0 | G10: =SUM(F10,D10) -> 0
A11: 2022 | B11: George Stevens Academy | C11: TAGEO | E11: =D11/$D$255 -> 0 | F11: =E11*$D$257 -> 0 | G11: =SUM(F11,D11) -> 0
A12: 2022 | B12: Gould Academy | C12: TAGOU | E12: =D12/$D$255 -> 0 | F12: =E12*$D$257 -> 0 | G12: =SUM(F12,D12) -> 0
A13: 2022 | B13: Lee Academy | C13: TALEE | E13: =D13/$D$255 -> 0 | F13: =E13*$D$257 -> 0 | G13: =SUM(F13,D13) -> 0
A14: 2022 | B14: Lincoln Academy | C14: TALIN | E14: =D14/$D$255 -> 0 | F14: =E14*$D$257 -> 0 | G14: =SUM(F14,D14) -> 0
A15: 2022 | B15: Maine Central Institute | C15: TAMCI | E15: =D15/$D$255 -> 0 | F15: =E15*$D$257 -> 0 | G15: =SUM(F15,D15) -> 0
A16: 2022 | B16: Thornton Academy | C16: TATHO | E16: =D16/$D$255 -> 0 | F16: =E16*$D$257 -> 0 | G16: =SUM(F16,D16) -> 0
A17: 2022 | B17: Washington Academy | C17: TAWAS | E17: =D17/$D$255 -> 0 | F17: =E17*$D$257 -> 0 | G17: =SUM(F17,D17) -> 0
A18: 2022 | B18: Acton School Department | C18: TCACT | D18: 22592 | E18: =D18/$D$255 -> 0.0016743685 | F18: =E18*$D$257 -> 325211.22 | G18: =SUM(F18,D18) -> 347803.22
A19: 2022 | B19: Andover School Department | C19: TCAND | D19: 3812 | E19: =D19/$D$255 -> 0.00028252004 | F19: =E19*$D$257 -> 54873.636 | G19: =SUM(F19,D19) -> 58685.636
A20: 2022 | B20: Athens School Department | C20: TCATH | D20: 8163 | E20: =D20/$D$255 -> 0.00060498718 | F20: =E20*$D$257 -> 117506.16 | G20: =SUM(F20,D20) -> 125669.16
A21: 2022 | B21: Auburn School Department | C21: TCAUB | D21: 360830 | E21: =D21/$D$255 -> 0.026742316 | F21: =E21*$D$257 -> 5194138 | G21: =SUM(F21,D21) -> 5554968
A22: 2022 | B22: Augusta School Department | C22: TCAUG | D22: 280236 | E22: =D22/$D$255 -> 0.020769225 | F22: =E22*$D$257 -> 4033989.6 | G22: =SUM(F22,D22) -> 4314225.6
A23: 2022 | B23: Bangor School Department | C23: TCBAN | D23: 230934 | E23: =D23/$D$255 -> 0.01711529 | F23: =E23*$D$257 -> 3324288.6 | G23: =SUM(F23,D23) -> 3555222.6
A24: 2022 | B24: Biddeford School Department | C24: TCBID | D24: 184309 | E24: =D24/$D$255 -> 0.013659755 | F24: =E24*$D$257 -> 2653123 | G24: =SUM(F24,D24) -> 2837432
A25: 2022 | B25: Brewer School Department | C25: TCBRE | D25: 49938 | E25: =D25/$D$255 -> 0.0037010719 | F25: =E25*$D$257 -> 718856.15 | G25: =SUM(F25,D25) -> 768794.15
A26: 2022 | B26: Brunswick School Department | C26: TCBRU | D26: 171057 | E26: =D26/$D$255 -> 0.012677605 | F26: =E26*$D$257 -> 2462360.9 | G26: =SUM(F26,D26) -> 2633417.9
A27: 2022 | B27: Calais School Department | C27: TCCAL | D27: 33056 | E27: =D27/$D$255 -> 0.0024498905 | F27: =E27*$D$257 -> 475840.22 | G27: =SUM(F27,D27) -> 508896.22
A28: 2022 | B28: Caswell School Department | C28: TCCAS | D28: 5231 | E28: =D28/$D$255 -> 0.00038768687 | F28: =E28*$D$257 -> 75300.102 | G28: =SUM(F28,D28) -> 80531.102
A29: 2022 | B29: Cape Elizabeth School Department | C29: TCCEL | D29: 12754 | E29: =D29/$D$255 -> 0.00094524151 | F29: =E29*$D$257 -> 183593.48 | G29: =SUM(F29,D29) -> 196347.48
A30: 2022 | B30: Chebeague Island School Department | C30: TCCHE | E30: =D30/$D$255 -> 0 | F30: =E30*$D$257 -> 0 | G30: =SUM(F30,D30) -> 0
A31: 2022 | B31: Cherryfield School Department | C31: TCCHR | D31: 18625 | E31: =D31/$D$255 -> 0.0013803609 | F31: =E31*$D$257 -> 268106.37 | G31: =SUM(F31,D31) -> 286731.37
A32: 2022 | B32: Dayton School Department | C32: TCDAY | D32: 9390 | E32: =D32/$D$255 -> 0.00069592424 | F32: =E32*$D$257 -> 135168.79 | G32: =SUM(F32,D32) -> 144558.79
A33: 2022 | B33: Easton School Department | C33: TCEAS | D33: 3144 | E33: =D33/$D$255 -> 0.00023301233 | F33: =E33*$D$257 -> 45257.794 | G33: =SUM(F33,D33) -> 48401.794
A34: 2022 | B34: Ellsworth School Department | C34: TCELL | D34: 162855 | E34: =D34/$D$255 -> 0.012069728 | F34: =E34*$D$257 -> 2344293.3 | G34: =SUM(F34,D34) -> 2507148.3
A35: 2022 | B35: East Millinocket School Department | C35: TCEML | D35: 16467 | E35: =D35/$D$255 -> 0.0012204243 | F35: =E35*$D$257 -> 237042.02 | G35: =SUM(F35,D35) -> 253509.02
A36: 2022 | B36: Eustis School Department | C36: TCEUS | D36: 10867 | E36: =D36/$D$255 -> 0.00080538964 | F36: =E36*$D$257 -> 156430.17 | G36: =SUM(F36,D36) -> 167297.17
A37: 2022 | B37: Falmouth School Department | C37: TCFAL | D37: 22762 | E37: =D37/$D$255 -> 0.0016869678 | F37: =E37*$D$257 -> 327658.37 | G37: =SUM(F37,D37) -> 350420.37
A38: 2022 | B38: Fayette School Department | C38: TCFAY | D38: 3168 | E38: =D38/$D$255 -> 0.00023479105 | F38: =E38*$D$257 -> 45603.274 | G38: =SUM(F38,D38) -> 48771.274
A39: 2022 | B39: Glenburn School Department | C39: TCGLE | D39: 14252 | E39: =D39/$D$255 -> 0.0010562633 | F39: =E39*$D$257 -> 205157.15 | G39: =SUM(F39,D39) -> 219409.15
A40: 2022 | B40: Gorham School Department | C40: TCGOR | D40: 107817 | E40: =D40/$D$255 -> 0.0079906777 | F40: =E40*$D$257 -> 1552022.8 | G40: =SUM(F40,D40) -> 1659839.8
...

Sheet NCES Data -->

Sheet LEAID Match
A1: district_name | B1: LEAID | C1: count
