Workbook

Sheet Summary
A1: LEAID | B1: Year | C1: State | D1: state_abv | E1: plan | F1: standardized_employer_name | G1: employer_id | H1: 1996_contribution | I1: 1996_employer_allocation | J1: pre-1996_employer_contribution | K1: pre_1996_state_contribution | M1: district_contributions | N1: state_contributions | O1: total_contributions | P1: LEAID Match | Q1: count | R1: District Contributions
A2: =P2 -> 1809370 | B2: 2015 | C2: Indiana | D2: IN | E2: Teachers' Retirement Fund 1996 Account & Pre-1996 | F2: WEST CLARK COMM SCHOOLS | G2: 10000 | H2: 894023 | I2: 0.004347372 | J2: 25262.578 | K2: 3676207.3 | M2: =SUM(H2,J2) -> 919285.58 | N2: =K2 -> 3676207.3 | O2: =SUM(M2:N2) -> 4595492.9 | P2: =VLOOKUP(F2,'LEAID Match'!$A$2:$B$436,2,FALSE) -> 1809370 | Q2: =COUNTIF($P$2:$P$3691,P2) -> 9 | R2: 2015 | S2: =SUMIF($B$2:$B$3691,$R2,$H$2:$H$3691) -> 205646770 | T2: =SUMIF($B$2:$B$3691,$R2,$J$2:$J$3691) -> 5811000 | U2: =SUM(S2:T2) -> 211457770
A3: =P3 -> 1809370 | B3: 2016 | C3: Indiana | D3: IN | E3: Teachers' Retirement Fund 1996 Account & Pre-1997 | F3: WEST CLARK COMM SCHOOLS | G3: 10000 | H3: 964405 | I3: 0.0044749576 | J3: 22589.586 | K3: 3971524.9 | M3: =SUM(H3,J3) -> 986994.59 | N3: =K3 -> 3971524.9 | O3: =SUM(M3:N3) -> 4958519.5 | P3: =VLOOKUP(F3,'LEAID Match'!$A$2:$B$436,2,FALSE) -> 1809370 | Q3: =COUNTIF($P$2:$P$3691,P3) -> 9 | R3: 2016 | S3: =SUMIF($B$2:$B$3691,$R3,$H$2:$H$3691) -> 215511537 | T3: =SUMIF($B$2:$B$3691,$R3,$J$2:$J$3691) -> 5048000 | U3: =SUM(S3:T3) -> 220559537
A4: =P4 -> 1809370 | B4: 2017 | C4: Indiana | D4: IN | E4: Teachers' Retirement Fund 1996 Account & Pre-1998 | F4: WEST CLARK COMM SCHOOLS | G4: 10000 | H4: 1062167 | I4: 0.0046771757 | J4: 21164.22 | K4: 4073820 | M4: =SUM(H4,J4) -> 1083331.2 | N4: =K4 -> 4073820 | O4: =SUM(M4:N4) -> 5157151.3 | P4: =VLOOKUP(F4,'LEAID Match'!$A$2:$B$436,2,FALSE) -> 1809370 | Q4: =COUNTIF($P$2:$P$3691,P4) -> 9 | R4: 2017 | S4: =SUMIF($B$2:$B$3691,$R4,$H$2:$H$3691) -> 227095809 | T4: =SUMIF($B$2:$B$3691,$R4,$J$2:$J$3691) -> 4525000 | U4: =SUM(S4:T4) -> 231620809
A5: =P5 -> 1809370 | B5: 2018 | C5: Indiana | D5: IN | E5: Teachers' Retirement Fund 1996 Account & Pre-1999 | F5: WEST CLARK COMM SCHOOLS | G5: 10000 | H5: 1144527 | I5: 0.0048555079 | J5: 20237.757 | K5: 2894322 | M5: =SUM(H5,J5) -> 1164764.8 | N5: =K5 -> 2894322 | O5: =SUM(M5:N5) -> 4059086.8 | P5: =VLOOKUP(F5,'LEAID Match'!$A$2:$B$436,2,FALSE) -> 1809370 | Q5: =COUNTIF($P$2:$P$3691,P5) -> 9 | R5: 2018 | S5: =SUMIF($B$2:$B$3691,$R5,$H$2:$H$3691) -> 235717254 | T5: =SUMIF($B$2:$B$3691,$R5,$J$2:$J$3691) -> 4168000 | U5: =SUM(S5:T5) -> 239885254
A6: =P6 -> 1809370 | B6: 2019 | C6: Indiana | D6: IN | E6: Teachers' Retirement Fund 1996 Account & Pre-2000 | F6: WEST CLARK COMM SCHOOLS | G6: 10000 | H6: 1104819 | I6: 0.0028106535 | J6: 9851.3407 | K6: 2652975.9 | M6: =SUM(H6,J6) -> 1114670.3 | N6: =K6 -> 2652975.9 | O6: =SUM(M6:N6) -> 3767646.2 | P6: =VLOOKUP(F6,'LEAID Match'!$A$2:$B$436,2,FALSE) -> 1809370 | Q6: =COUNTIF($P$2:$P$3691,P6) -> 9 | R6: 2019 | S6: =SUMIF($B$2:$B$3691,$R6,$H$2:$H$3691) -> 393082599 | T6: =SUMIF($B$2:$B$3691,$R6,$J$2:$J$3691) -> 3505000 | U6: =SUM(S6:T6) -> 396587599
A7: =P7 -> 1809370 | B7: 2020 | C7: Indiana | D7: IN | E7: Teachers' Retirement Fund 1996 Account & Pre-2001 | F7: WEST CLARK COMM SCHOOLS | G7: 10000 | H7: 811264 | I7: 0.0042986508 | J7: 10127.621 | K7: 2971761 | M7: =SUM(H7,J7) -> 821391.62 | N7: =K7 -> 2971761 | O7: =SUM(M7:N7) -> 3793152.6 | P7: =VLOOKUP(F7,'LEAID Match'!$A$2:$B$436,2,FALSE) -> 1809370 | Q7: =COUNTIF($P$2:$P$3691,P7) -> 9 | R7: 2020 | S7: =SUMIF($B$2:$B$3691,$R7,$H$2:$H$3691) -> 188725262 | T7: =SUMIF($B$2:$B$3691,$R7,$J$2:$J$3691) -> 2356000 | U7: =SUM(S7:T7) -> 191081262
A8: =P8 -> 1809370 | B8: 2021 | C8: Indiana | D8: IN | E8: Teachers' Retirement Fund 1996 Account & Pre-2002 | F8: WEST CLARK COMM SCHOOLS | G8: 10000 | H8: 100924 | I8: 0.00049857395 | J8: 1123.7857 | K8: 3696082 | M8: =SUM(H8,J8) -> 102047.79 | N8: =K8 -> 3696082 | O8: =SUM(M8:N8) -> 3798129.8 | P8: =VLOOKUP(F8,'LEAID Match'!$A$2:$B$436,2,FALSE) -> 1809370 | Q8: =COUNTIF($P$2:$P$3691,P8) -> 9 | R8: 2021 | S8: =SUMIF($B$2:$B$3691,$R8,$H$2:$H$3691) -> 202425339 | T8: =SUMIF($B$2:$B$3691,$R8,$J$2:$J$3691) -> 2254000 | U8: =SUM(S8:T8) -> 204679339
A9: =P9 -> 1809370 | B9: 2022 | C9: Indiana | D9: IN | E9: Teachers' Retirement Fund 1996 Account & Pre-2003 | F9: WEST CLARK COMM SCHOOLS | G9: 10000 | H9: - | I9: 0 | J9: 0 | K9: 3496950 | M9: =SUM(H9,J9) -> 0 | N9: =K9 -> 3496950 | O9: =SUM(M9:N9) -> 3496950 | P9: =VLOOKUP(F9,'LEAID Match'!$A$2:$B$436,2,FALSE) -> 1809370 | Q9: =COUNTIF($P$2:$P$3691,P9) -> 9 | R9: 2022 | S9: =SUMIF($B$2:$B$3691,$R9,$H$2:$H$3691) -> 210606752 | T9: =SUMIF($B$2:$B$3691,$R9,$J$2:$J$3691) -> 2205000 | U9: =SUM(S9:T9) -> 212811752
A10: =P10 -> 1809370 | B10: 2023 | C10: Indiana | D10: IN | E10: Teachers' Retirement Fund 1996 Account & Pre-2004 | F10: WEST CLARK COMM SCHOOLS | G10: 10000 | H10: - | I10: 0 | J10: 0 | K10: 7589120 | M10: =SUM(H10,J10) -> 0 | N10: =K10 -> 7589120 | O10: =SUM(M10:N10) -> 7589120 | P10: =VLOOKUP(F10,'LEAID Match'!$A$2:$B$436,2,FALSE) -> 1809370 | Q10: =COUNTIF($P$2:$P$3691,P10) -> 9
A11: =P11 -> 1800212 | B11: 2021 | C11: Indiana | D11: IN | E11: Teachers' Retirement Fund 1996 Account & Pre-2005 | F11: BORDEN-HENRYVILLE SCHOOL CORPOATION | G11: 10001 | H11: 269530 | I11: 0.0013315033 | J11: 3001.2084 | K11: 430762 | M11: =SUM(H11,J11) -> 272531.21 | N11: =K11 -> 430762 | O11: =SUM(M11:N11) -> 703293.21 | P11: =VLOOKUP(F11,'LEAID Match'!$A$2:$B$436,2,FALSE) -> 1800212 | Q11: =COUNTIF($P$2:$P$3691,P11) -> 3 | R11: State Contributions
A12: =P12 -> 1800212 | B12: 2022 | C12: Indiana | D12: IN | E12: Teachers' Retirement Fund 1996 Account & Pre-2006 | F12: BORDEN-HENRYVILLE SCHOOL CORPOATION | G12: 10001 | H12: 367374 | I12: 0.00174436 | J12: 3846.3139 | K12: 276438 | M12: =SUM(H12,J12) -> 371220.31 | N12: =K12 -> 276438 | O12: =SUM(M12:N12) -> 647658.31 | P12: =VLOOKUP(F12,'LEAID Match'!$A$2:$B$436,2,FALSE) -> 1800212 | Q12: =COUNTIF($P$2:$P$3691,P12) -> 3 | R12: 2015 | S12: =SUMIF($B$2:$B$3691,R12,$K$2:$K$3691) -> 8.45616e+08
A13: =P13 -> 1800212 | B13: 2023 | C13: Indiana | D13: IN | E13: Teachers' Retirement Fund 1996 Account & Pre-2007 | F13: BORDEN-HENRYVILLE SCHOOL CORPOATION | G13: 10001 | H13: 435453 | I13: 0.0017807635 | J13: 4393.1436 | K13: 1316238 | M13: =SUM(H13,J13) -> 439846.14 | N13: =K13 -> 1316238 | O13: =SUM(M13:N13) -> 1756084.1 | P13: =VLOOKUP(F13,'LEAID Match'!$A$2:$B$436,2,FALSE) -> 1800212 | Q13: =COUNTIF($P$2:$P$3691,P13) -> 3 | R13: 2016 | S13: =SUMIF($B$2:$B$3691,R13,$K$2:$K$3691) -> 8.875e+08
A14: =P14 -> 1800213 | B14: 2021 | C14: Indiana | D14: IN | E14: Teachers' Retirement Fund 1996 Account & Pre-2008 | F14: SILVER CREEK SCHOOL CORPORATION | G14: 10002 | H14: 466345 | I14: 0.0023037877 | J14: 5192.7374 | K14: 656612 | M14: =SUM(H14,J14) -> 471537.74 | N14: =K14 -> 656612 | O14: =SUM(M14:N14) -> 1128149.7 | P14: =VLOOKUP(F14,'LEAID Match'!$A$2:$B$436,2,FALSE) -> 1800213 | Q14: =COUNTIF($P$2:$P$3691,P14) -> 3 | R14: 2017 | S14: =SUMIF($B$2:$B$3691,R14,$K$2:$K$3691) -> 8.71e+08
A15: =P15 -> 1800213 | B15: 2022 | C15: Indiana | D15: IN | E15: Teachers' Retirement Fund 1996 Account & Pre-2009 | F15: SILVER CREEK SCHOOL CORPORATION | G15: 10002 | H15: 576146 | I15: 0.0027356483 | J15: 6032.1045 | K15: 755670 | M15: =SUM(H15,J15) -> 582178.1 | N15: =K15 -> 755670 | O15: =SUM(M15:N15) -> 1337848.1 | P15: =VLOOKUP(F15,'LEAID Match'!$A$2:$B$436,2,FALSE) -> 1800213 | Q15: =COUNTIF($P$2:$P$3691,P15) -> 3 | R15: 2018 | S15: =SUMIF($B$2:$B$3691,R15,$K$2:$K$3691) -> 917900000
A16: =P16 -> 1800213 | B16: 2023 | C16: Indiana | D16: IN | E16: Teachers' Retirement Fund 1996 Account & Pre-2010 | F16: SILVER CREEK SCHOOL CORPORATION | G16: 10002 | H16: 682899 | I16: 0.0027926817 | J16: 6889.5457 | K16: 3113149 | M16: =SUM(H16,J16) -> 689788.55 | N16: =K16 -> 3113149 | O16: =SUM(M16:N16) -> 3802937.5 | P16: =VLOOKUP(F16,'LEAID Match'!$A$2:$B$436,2,FALSE) -> 1800213 | Q16: =COUNTIF($P$2:$P$3691,P16) -> 3 | R16: 2019 | S16: =SUMIF($B$2:$B$3691,R16,$K$2:$K$3691) -> 9.439e+08
A17: =P17 -> 1801920 | B17: 2015 | C17: Indiana | D17: IN | E17: Teachers' Retirement Fund 1996 Account & Pre-2011 | F17: CLARKSVILLE COMM SCHOOL CORP | G17: 10013 | H17: 322792 | I17: 0.0015696429 | J17: 9121.1951 | K17: 1327315.2 | M17: =SUM(H17,J17) -> 331913.2 | N17: =K17 -> 1327315.2 | O17: =SUM(M17:N17) -> 1659228.4 | P17: =VLOOKUP(F17,'LEAID Match'!$A$2:$B$436,2,FALSE) -> 1801920 | Q17: =COUNTIF($P$2:$P$3691,P17) -> 9 | R17: 2020 | S17: =SUMIF($B$2:$B$3691,R17,$K$2:$K$3691) -> 971132000
A18: =P18 -> 1801920 | B18: 2016 | C18: Indiana | D18: IN | E18: Teachers' Retirement Fund 1996 Account & Pre-2012 | F18: CLARKSVILLE COMM SCHOOL CORP | G18: 10013 | H18: 335892 | I18: 0.0015585801 | J18: 7867.7125 | K18: 1383239.9 | M18: =SUM(H18,J18) -> 343759.71 | N18: =K18 -> 1383239.9 | O18: =SUM(M18:N18) -> 1726999.6 | P18: =VLOOKUP(F18,'LEAID Match'!$A$2:$B$436,2,FALSE) -> 1801920 | Q18: =COUNTIF($P$2:$P$3691,P18) -> 9 | R18: 2021 | S18: =SUMIF($B$2:$B$3691,R18,$K$2:$K$3691) -> 1598375000
A19: =P19 -> 1801920 | B19: 2017 | C19: Indiana | D19: IN | E19: Teachers' Retirement Fund 1996 Account & Pre-2013 | F19: CLARKSVILLE COMM SCHOOL CORP | G19: 10013 | H19: 330165 | I19: 0.0014538577 | J19: 6578.7063 | K19: 1266310.1 | M19: =SUM(H19,J19) -> 336743.71 | N19: =K19 -> 1266310.1 | O19: =SUM(M19:N19) -> 1603053.8 | P19: =VLOOKUP(F19,'LEAID Match'!$A$2:$B$436,2,FALSE) -> 1801920 | Q19: =COUNTIF($P$2:$P$3691,P19) -> 9 | R19: 2022 | S19: =SUMIF($B$2:$B$3691,R19,$K$2:$K$3691) -> 1550410326
A20: =P20 -> 1801920 | B20: 2018 | C20: Indiana | D20: IN | E20: Teachers' Retirement Fund 1996 Account & Pre-2014 | F20: CLARKSVILLE COMM SCHOOL CORP | G20: 10013 | H20: 467389 | I20: 0.0019828375 | J20: 8264.4665 | K20: 1243846 | M20: =SUM(H20,J20) -> 475653.47 | N20: =K20 -> 1243846 | O20: =SUM(M20:N20) -> 1719499.5 | P20: =VLOOKUP(F20,'LEAID Match'!$A$2:$B$436,2,FALSE) -> 1801920 | Q20: =COUNTIF($P$2:$P$3691,P20) -> 9
A21: =P21 -> 1801920 | B21: 2019 | C21: Indiana | D21: IN | E21: Teachers' Retirement Fund 1996 Account & Pre-2015 | F21: CLARKSVILLE COMM SCHOOL CORP | G21: 10013 | H21: 318654 | I21: 0.00081065405 | J21: 2841.3424 | K21: 765176.36 | M21: =SUM(H21,J21) -> 321495.34 | N21: =K21 -> 765176.36 | O21: =SUM(M21:N21) -> 1086671.7 | P21: =VLOOKUP(F21,'LEAID Match'!$A$2:$B$436,2,FALSE) -> 1801920 | Q21: =COUNTIF($P$2:$P$3691,P21) -> 9
A22: =P22 -> 1801920 | B22: 2020 | C22: Indiana | D22: IN | E22: Teachers' Retirement Fund 1996 Account & Pre-2016 | F22: CLARKSVILLE COMM SCHOOL CORP | G22: 10013 | H22: 229561 | I22: 0.0012163766 | J22: 2865.7834 | K22: 1287430 | M22: =SUM(H22,J22) -> 232426.78 | N22: =K22 -> 1287430 | O22: =SUM(M22:N22) -> 1519856.8 | P22: =VLOOKUP(F22,'LEAID Match'!$A$2:$B$436,2,FALSE) -> 1801920 | Q22: =COUNTIF($P$2:$P$3691,P22) -> 9 | R22: GASB 67 Figures | S22: District Contributions | T22: State Contributions
A23: =P23 -> 1801920 | B23: 2021 | C23: Indiana | D23: IN | E23: Teachers' Retirement Fund 1996 Account & Pre-2017 | F23: CLARKSVILLE COMM SCHOOL CORP | G23: 10013 | H23: 226616 | I23: 0.0011195041 | J23: 2523.3623 | K23: 2019707 | M23: =SUM(H23,J23) -> 229139.36 | N23: =K23 -> 2019707 | O23: =SUM(M23:N23) -> 2248846.4 | P23: =VLOOKUP(F23,'LEAID Match'!$A$2:$B$436,2,FALSE) -> 1801920 | Q23: =COUNTIF($P$2:$P$3691,P23) -> 9 | R23: 2015 | S23: 211574000 | T23: 845616000
A24: =P24 -> 1801920 | B24: 2022 | C24: Indiana | D24: IN | E24: Teachers' Retirement Fund 1996 Account & Pre-2018 | F24: CLARKSVILLE COMM SCHOOL CORP | G24: 10013 | H24: 235236 | I24: 0.0011169442 | J24: 2462.8621 | K24: 1949331 | M24: =SUM(H24,J24) -> 237698.86 | N24: =K24 -> 1949331 | O24: =SUM(M24:N24) -> 2187029.9 | P24: =VLOOKUP(F24,'LEAID Match'!$A$2:$B$436,2,FALSE) -> 1801920 | Q24: =COUNTIF($P$2:$P$3691,P24) -> 9 | R24: 2016 | S24: 220674000 | T24: 887500000
A25: =P25 -> 1801920 | B25: 2023 | C25: Indiana | D25: IN | E25: Teachers' Retirement Fund 1996 Account & Pre-2019 | F25: CLARKSVILLE COMM SCHOOL CORP | G25: 10013 | H25: 250626 | I25: 0.0010249226 | J25: 2528.4841 | K25: 5067601 | M25: =SUM(H25,J25) -> 253154.48 | N25: =K25 -> 5067601 | O25: =SUM(M25:N25) -> 5320755.5 | P25: =VLOOKUP(F25,'LEAID Match'!$A$2:$B$436,2,FALSE) -> 1801920 | Q25: =COUNTIF($P$2:$P$3691,P25) -> 9 | R25: 2017 | S25: 231732000 | T25: 871000000
A26: =P26 -> 1803940 | B26: 2015 | C26: Indiana | D26: IN | E26: Teachers' Retirement Fund 1996 Account & Pre-2020 | F26: GREATER CLARK CO SCHOOLS | G26: 10016 | H26: 2474633 | I26: 0.012033415 | J26: 69926.177 | K26: 10175649 | M26: =SUM(H26,J26) -> 2544559.2 | N26: =K26 -> 10175649 | O26: =SUM(M26:N26) -> 12720208 | P26: =VLOOKUP(F26,'LEAID Match'!$A$2:$B$436,2,FALSE) -> 1803940 | Q26: =COUNTIF($P$2:$P$3691,P26) -> 9 | R26: 2018 | S26: 239987000 | T26: 917900000
A27: =P27 -> 1803940 | B27: 2016 | C27: Indiana | D27: IN | E27: Teachers' Retirement Fund 1996 Account & Pre-2021 | F27: GREATER CLARK CO SCHOOLS | G27: 10016 | H27: 2532561 | I27: 0.011751394 | J27: 59321.037 | K27: 10429362 | M27: =SUM(H27,J27) -> 2591882 | N27: =K27 -> 10429362 | O27: =SUM(M27:N27) -> 13021244 | P27: =VLOOKUP(F27,'LEAID Match'!$A$2:$B$436,2,FALSE) -> 1803940 | Q27: =COUNTIF($P$2:$P$3691,P27) -> 9 | R27: 2019 | S27: 396677000 | T27: 943900000
A28: =P28 -> 1803940 | B28: 2017 | C28: Indiana | D28: IN | E28: Teachers' Retirement Fund 1996 Account & Pre-2022 | F28: GREATER CLARK CO SCHOOLS | G28: 10016 | H28: 2564127 | I28: 0.011290948 | J28: 51091.54 | K28: 9834415.8 | M28: =SUM(H28,J28) -> 2615218.5 | N28: =K28 -> 9834415.8 | O28: =SUM(M28:N28) -> 12449634 | P28: =VLOOKUP(F28,'LEAID Match'!$A$2:$B$436,2,FALSE) -> 1803940 | Q28: =COUNTIF($P$2:$P$3691,P28) -> 9 | R28: 2020 | S28: 191145000 | T28: 971132000
A29: =P29 -> 1803940 | B29: 2018 | C29: Indiana | D29: IN | E29: Teachers' Retirement Fund 1996 Account & Pre-2023 | F29: GREATER CLARK CO SCHOOLS | G29: 10016 | H29: 2582134 | I29: 0.01095437 | J29: 45657.814 | K29: 10231189 | M29: =SUM(H29,J29) -> 2627791.8 | N29: =K29 -> 10231189 | O29: =SUM(M29:N29) -> 12858981 | P29: =VLOOKUP(F29,'LEAID Match'!$A$2:$B$436,2,FALSE) -> 1803940 | Q29: =COUNTIF($P$2:$P$3691,P29) -> 9 | R29: 2021 | S29: 204743000 | T29: 1598375000
A30: =P30 -> 1803940 | B30: 2019 | C30: Indiana | D30: IN | E30: Teachers' Retirement Fund 1996 Account & Pre-2024 | F30: GREATER CLARK CO SCHOOLS | G30: 10016 | H30: 2653384 | I30: 0.0067501945 | J30: 23659.432 | K30: 6371508.6 | M30: =SUM(H30,J30) -> 2677043.4 | N30: =K30 -> 6371508.6 | O30: =SUM(M30:N30) -> 9048552 | P30: =VLOOKUP(F30,'LEAID Match'!$A$2:$B$436,2,FALSE) -> 1803940 | Q30: =COUNTIF($P$2:$P$3691,P30) -> 9 | R30: 2022 | S30: 212870000 | T30: 1550410000
A31: =P31 -> 1803940 | B31: 2020 | C31: Indiana | D31: IN | E31: Teachers' Retirement Fund 1996 Account & Pre-2025 | F31: GREATER CLARK CO SCHOOLS | G31: 10016 | H31: 1923174 | I31: 0.010190337 | J31: 24008.434 | K31: 10595827 | M31: =SUM(H31,J31) -> 1947182.4 | N31: =K31 -> 10595827 | O31: =SUM(M31:N31) -> 12543009 | P31: =VLOOKUP(F31,'LEAID Match'!$A$2:$B$436,2,FALSE) -> 1803940 | Q31: =COUNTIF($P$2:$P$3691,P31) -> 9
A32: =P32 -> 1803940 | B32: 2021 | C32: Indiana | D32: IN | E32: Teachers' Retirement Fund 1996 Account & Pre-2026 | F32: GREATER CLARK CO SCHOOLS | G32: 10016 | H32: 2091906 | I32: 0.01033421 | J32: 23293.31 | K32: 16913365 | M32: =SUM(H32,J32) -> 2115199.3 | N32: =K32 -> 16913365 | O32: =SUM(M32:N32) -> 19028564 | P32: =VLOOKUP(F32,'LEAID Match'!$A$2:$B$436,2,FALSE) -> 1803940 | Q32: =COUNTIF($P$2:$P$3691,P32) -> 9 | R32: Check
A33: =P33 -> 1803940 | B33: 2022 | C33: Indiana | D33: IN | E33: Teachers' Retirement Fund 1996 Account & Pre-2027 | F33: GREATER CLARK CO SCHOOLS | G33: 10016 | H33: 2081418 | I33: 0.0098829595 | J33: 21791.926 | K33: 16249541 | M33: =SUM(H33,J33) -> 2103209.9 | N33: =K33 -> 16249541 | O33: =SUM(M33:N33) -> 18352751 | P33: =VLOOKUP(F33,'LEAID Match'!$A$2:$B$436,2,FALSE) -> 1803940 | Q33: =COUNTIF($P$2:$P$3691,P33) -> 9 | R33: 2015 | S33: =U2-S23 -> -116230 | T33: =S12-T23 -> -1.9073486e-06
A34: =P34 -> 1803940 | B34: 2023 | C34: Indiana | D34: IN | E34: Teachers' Retirement Fund 1996 Account & Pre-2028 | F34: GREATER CLARK CO SCHOOLS | G34: 10016 | H34: 2389147 | I34: 0.0097702985 | J34: 24103.326 | K34: 41947252 | M34: =SUM(H34,J34) -> 2413250.3 | N34: =K34 -> 41947252 | O34: =SUM(M34:N34) -> 44360502 | P34: =VLOOKUP(F34,'LEAID Match'!$A$2:$B$436,2,FALSE) -> 1803940 | Q34: =COUNTIF($P$2:$P$3691,P34) -> 9 | R34: 2016 | S34: =U3-S24 -> -114463 | T34: =S13-T24 -> -9.5367432e-07
A35: =P35 -> 1800080 | B35: 2018 | C35: Indiana | D35: IN | E35: Teachers' Retirement Fund 1996 Account & Pre-2029 | F35: WILSON EDUCATION CENTER | G35: 10017 | H35: 0 | I35: 0 | J35: 0 | K35: 30382 | M35: =SUM(H35,J35) -> 0 | N35: =K35 -> 30382 | O35: =SUM(M35:N35) -> 30382 | P35: =VLOOKUP(F35,'LEAID Match'!$A$2:$B$436,2,FALSE) -> 1800080 | Q35: =COUNTIF($P$2:$P$3691,P35) -> 5 | R35: 2017 | S35: =U4-S25 -> -111191 | T35: =S14-T25 -> -2.1457672e-06
A36: =P36 -> 1800080 | B36: 2020 | C36: Indiana | D36: IN | E36: Teachers' Retirement Fund 1996 Account & Pre-2030 | F36: WILSON EDUCATION CENTER | G36: 10017 | H36: 0 | I36: 0 | J36: 0 | K36: 13693 | M36: =SUM(H36,J36) -> 0 | N36: =K36 -> 13693 | O36: =SUM(M36:N36) -> 13693 | P36: =VLOOKUP(F36,'LEAID Match'!$A$2:$B$436,2,FALSE) -> 1800080 | Q36: =COUNTIF($P$2:$P$3691,P36) -> 5 | R36: 2018 | S36: =U5-S26 -> -101746 | T36: =S15-T26 -> 0
A37: =P37 -> 1800080 | B37: 2021 | C37: Indiana | D37: IN | E37: Teachers' Retirement Fund 1996 Account & Pre-2031 | F37: WILSON EDUCATION CENTER | G37: 10017 | K37: 21738 | M37: =SUM(H37,J37) -> 0 | N37: =K37 -> 21738 | O37: =SUM(M37:N37) -> 21738 | P37: =VLOOKUP(F37,'LEAID Match'!$A$2:$B$436,2,FALSE) -> 1800080 | Q37: =COUNTIF($P$2:$P$3691,P37) -> 5 | R37: 2019 | S37: =U6-S27 -> -89401 | T37: =S16-T27 -> -1.9073486e-06
A38: =P38 -> 1800080 | B38: 2022 | C38: Indiana | D38: IN | E38: Teachers' Retirement Fund 1996 Account & Pre-2032 | F38: WILSON EDUCATION CENTER | G38: 10017 | K38: 21396 | M38: =SUM(H38,J38) -> 0 | N38: =K38 -> 21396 | O38: =SUM(M38:N38) -> 21396 | P38: =VLOOKUP(F38,'LEAID Match'!$A$2:$B$436,2,FALSE) -> 1800080 | Q38: =COUNTIF($P$2:$P$3691,P38) -> 5 | R38: 2020 | S38: =U7-S28 -> -63738 | T38: =S17-T28 -> 0
A39: =P39 -> 1800080 | B39: 2023 | C39: Indiana | D39: IN | E39: Teachers' Retirement Fund 1996 Account & Pre-2033 | F39: WILSON EDUCATION CENTER | G39: 10017 | H39: 4050 | I39: 1.6562275e-05 | J39: 40.859132 | K39: 425618 | M39: =SUM(H39,J39) -> 4090.8591 | N39: =K39 -> 425618 | O39: =SUM(M39:N39) -> 429708.86 | P39: =VLOOKUP(F39,'LEAID Match'!$A$2:$B$436,2,FALSE) -> 1800080 | Q39: =COUNTIF($P$2:$P$3691,P39) -> 5 | R39: 2021 | S39: =U8-S29 -> -63661 | T39: =S18-T29 -> 0
A40: =P40 -> 1800060 | B40: 2015 | C40: Indiana | D40: IN | E40: Teachers' Retirement Fund 1996 Account & Pre-2034 | F40: ADAMS CENTRAL COMM SCHOOLS | G40: 1005 | H40: 254564 | I40: 0.0012378702 | J40: 7193.2635 | K40: 1046762.8 | M40: =SUM(H40,J40) -> 261757.26 | N40: =K40 -> 1046762.8 | O40: =SUM(M40:N40) -> 1308520.1 | P40: =VLOOKUP(F40,'LEAID Match'!$A$2:$B$436,2,FALSE) -> 1800060 | Q40: =COUNTIF($P$2:$P$3691,P40) -> 9 | R40: 2022 | S40: =U9-S30 -> -58248 | T40: =S19-T30 -> 326
...

Sheet GASB Data -->

Sheet Check w GASB 68 Reports
A1: 1996 Plan Employer Contributions | H1: Pre-1996 State Contributions Check
A2: Year | B2: Reported Total | C2: Total from Formula | D2: Difference | H2: Year | I2: Reported Total | J2: Total from Formula | K2: Difference
A3: 2015 | B3: 205646770 | C3: =SUMIF(Summary!B:B,'Check w GASB 68 Reports'!A3,Summary!H:H) -> 205646770 | D3: =B3-C3 -> 0 | H3: 2015 | I3: 845616000 | J3: =SUMIF(Summary!B:B,'Check w GASB 68 Reports'!A3,Summary!K:K) -> 8.45616e+08 | K3: =I3-J3 -> 1.9073486e-06
A4: 2016 | B4: 215511537 | C4: =SUMIF(Summary!B:B,'Check w GASB 68 Reports'!A4,Summary!H:H) -> 215511537 | D4: =B4-C4 -> 0 | H4: 2016 | I4: 887500000 | J4: =SUMIF(Summary!B:B,'Check w GASB 68 Reports'!A4,Summary!K:K) -> 8.875e+08 | K4: =I4-J4 -> 9.5367432e-07
A5: 2017 | B5: 227095809 | C5: =SUMIF(Summary!B:B,'Check w GASB 68 Reports'!A5,Summary!H:H) -> 227095809 | D5: =B5-C5 -> 0 | H5: 2017 | I5: 871000000 | J5: =SUMIF(Summary!B:B,'Check w GASB 68 Reports'!A5,Summary!K:K) -> 8.71e+08 | K5: =I5-J5 -> 2.1457672e-06
A6: 2018 | B6: 235717254 | C6: =SUMIF(Summary!B:B,'Check w GASB 68 Reports'!A6,Summary!H:H) -> 235717254 | D6: =B6-C6 -> 0 | H6: 2018 | I6: 917900000 | J6: =SUMIF(Summary!B:B,'Check w GASB 68 Reports'!A6,Summary!K:K) -> 917900000 | K6: =I6-J6 -> 0
A7: 2019 | B7: 393082599 | C7: =SUMIF(Summary!B:B,'Check w GASB 68 Reports'!A7,Summary!H:H) -> 393082599 | D7: =B7-C7 -> 0 | H7: 2019 | I7: 943900000 | J7: =SUMIF(Summary!B:B,'Check w GASB 68 Reports'!A7,Summary!K:K) -> 9.439e+08 | K7: =I7-J7 -> 1.9073486e-06
A8: 2020 | B8: 188725262 | C8: =SUMIF(Summary!B:B,'Check w GASB 68 Reports'!A8,Summary!H:H) -> 188725262 | D8: =B8-C8 -> 0 | H8: 2020 | I8: 971132000 | J8: =SUMIF(Summary!B:B,'Check w GASB 68 Reports'!A8,Summary!K:K) -> 971132000 | K8: =I8-J8 -> 0
A9: 2021 | B9: 202425339 | C9: =SUMIF(Summary!B:B,'Check w GASB 68 Reports'!A9,Summary!H:H) -> 202425339 | D9: =B9-C9 -> 0 | H9: 2021 | I9: 1598375000 | J9: =SUMIF(Summary!B:B,'Check w GASB 68 Reports'!A9,Summary!K:K) -> 1598375000 | K9: =I9-J9 -> 0
A10: 2022 | B10: 210606752 | C10: =SUMIF(Summary!B:B,'Check w GASB 68 Reports'!A10,Summary!H:H) -> 210606752 | D10: =B10-C10 -> 0 | H10: 2022 | I10: 1550410326 | J10: =SUMIF(Summary!B:B,'Check w GASB 68 Reports'!A10,Summary!K:K) -> 1550410326 | K10: =I10-J10 -> 0
A11: 2023 | B11: 244531628 | C11: =SUMIF(Summary!B:B,'Check w GASB 68 Reports'!A11,Summary!H:H) -> 244531628 | D11: =B11-C11 -> 0 | H11: 2023 | I11: 4235000000 | J11: =SUMIF(Summary!B:B,'Check w GASB 68 Reports'!A11,Summary!K:K) -> 4235000000 | K11: =I11-J11 -> 0

Sheet NCES Data -->

Sheet LEAID Match
A1: district_name | B1: LEAID | C1: count
A2: SOUTHWEST SCHOOL CORP | B2: 1810860 | C2: =COUNTIF($B$2:$B$380,B2) -> 1
A3: SOUTHWESTERN CONS SCHOOL DIST | B3: 1810830 | C3: =COUNTIF($B$2:$B$380,B3) -> 1
A4: RUSH COUNTY SCHOOLS | B4: 1809750 | C4: =COUNTIF($B$2:$B$380,B4) -> 1
A5: MSD OF PERRY TOWNSHIP | B5: 1808820 | C5: =COUNTIF($B$2:$B$380,B5) -> 1
A6: PERRY CENTRAL COMM SCHOOL | B6: 1801740 | C6: =COUNTIF($B$2:$B$380,B6) -> 1
A7: MSD OF WASHINGTON TOWNSHIP | B7: 1812720 | C7: =COUNTIF($B$2:$B$380,B7) -> 1
A8: WHITKO COMM SCHOOL | B8: 1813230 | C8: =COUNTIF($B$2:$B$380,B8) -> 1
A9: SCHOOL CITY OF WHITING | B9: 1813200 | C9: =COUNTIF($B$2:$B$380,B9) -> 1
A10: WESTVIEW SCHOOL | B10: 1813110 | C10: =COUNTIF($B$2:$B$380,B10) -> 1
A11: WESTFIELD WASHINGTON SCHOOLS | B11: 1813080 | C11: =COUNTIF($B$2:$B$380,B11) -> 1
A12: WESTERN WAYNE SCHOOLS | B12: 1813050 | C12: =COUNTIF($B$2:$B$380,B12) -> 1
A13: WESTERN BOONE COMM SCHOOL CORP | B13: 1812990 | C13: =COUNTIF($B$2:$B$380,B13) -> 1
... A378: GREENE-SULLIVAN SPEC ED COOP | B378: 1800007 | C378: =COUNTIF($B$2:$B$380,B378) -> 1
A379: NORTHERN RUSH COUNTY SCHOOLS | C379: =COUNTIF($B$2:$B$380,B379) -> 0
A380: WASHINGTON TOWNSHIP SCHOOLS | C380: =COUNTIF($B$2:$B$380,B380) -> 0
A381: ADAM WELLS SPECIAL SERVICES COOPERATIVE | C381: =COUNTIF($B$2:$B$380,B381) -> 0
A382: ALTERNATIVE IN EDUCATION | C382: =COUNTIF($B$2:$B$380,B382) -> 0
A383: AMERICAN QUALITY SCHOOLS | C383: =COUNTIF($B$2:$B$380,B383) -> 0
A384: BALL STATE UNIVERSITY | C384: =COUNTIF($B$2:$B$380,B384) -> 0
A385: BLUE RIVER SPECIAL EDUCATION COOPERATIVE | C385: =COUNTIF($B$2:$B$380,B385) -> 0
A386: CARPE DIEM INDIANA INC. | C386: =COUNTIF($B$2:$B$380,B386) -> 0
A387: CASS TOWNSHIP SCHOOLS | C387: =COUNTIF($B$2:$B$380,B387) -> 0
A388: CHARLES A BEARD MEMORIAL SCHOOL CORP | C388: =COUNTIF($B$2:$B$380,B388) -> 0
A389: CHARTER SCHOOLS USA | C389: =COUNTIF($B$2:$B$380,B389) -> 0
A390: COLD SPRING SCHOOL INC | C390: =COUNTIF($B$2:$B$380,B390) -> 0
... A436: WHITLEY COUNTY AUDITOR | C436: =COUNTIF($B$2:$B$380,B436) -> 0
