Workbook

Sheet Final Data
A1: LEAID | B1: Year | C1: employer_code | D1: standardized_employer_name | E1: employer_name | F1: employer_contribution_trs | G1: employer_contribution_legacy | H1: district_contributions | I1: LEAID_match
A2: =I2 -> 4700147 | B2: 2015 | C2: 30002 | D2: ACHIEVEMENT SCHOOL DISTRICTS | E2: Achievement School Districts | F2: 146170 | G2: 3241604 | H2: =SUM(F2:G2) -> 3387774 | I2: =IFERROR(VLOOKUP(D2,'LEAID Match'!$A$2:$B$251,2,FALSE),"") -> 4700147
A3: =I3 -> 4700147 | B3: 2016 | C3: 30002 | D3: ACHIEVEMENT SCHOOL DISTRICTS | E3: Achievement School Districts | F3: 723551 | G3: 389471 | H3: =SUM(F3:G3) -> 1113022 | I3: =IFERROR(VLOOKUP(D3,'LEAID Match'!$A$2:$B$251,2,FALSE),"") -> 4700147
A4: =I4 -> 4700147 | B4: 2017 | C4: 30002 | D4: ACHIEVEMENT SCHOOL DISTRICTS | E4: ACHIEVEMENT SCHOOL DISTRICTS | F4: 51911 | G4: 122645 | H4: =SUM(F4:G4) -> 174556 | I4: =IFERROR(VLOOKUP(D4,'LEAID Match'!$A$2:$B$251,2,FALSE),"") -> 4700147
A5: =I5 -> 4700147 | B5: 2018 | C5: 30002 | D5: ACHIEVEMENT SCHOOL DISTRICTS | E5: Achievement School Districts | F5: 370 | H5: =SUM(F5:G5) -> 370 | I5: =IFERROR(VLOOKUP(D5,'LEAID Match'!$A$2:$B$251,2,FALSE),"") -> 4700147
A6: =I6 -> 4700147 | B6: 2019 | C6: 30002 | D6: ACHIEVEMENT SCHOOL DISTRICTS | E6: Achievement School Districts | H6: =SUM(F6:G6) -> 0 | I6: =IFERROR(VLOOKUP(D6,'LEAID Match'!$A$2:$B$251,2,FALSE),"") -> 4700147
A7: =I7 -> 4700147 | B7: 2020 | C7: 30002 | D7: ACHIEVEMENT SCHOOL DISTRICTS | E7: ACHIEVEMENT SCHOOL DISTRICTS | H7: =SUM(F7:G7) -> 0 | I7: =IFERROR(VLOOKUP(D7,'LEAID Match'!$A$2:$B$251,2,FALSE),"") -> 4700147
A8: =I8 -> 4700147 | B8: 2021 | C8: 30002 | D8: ACHIEVEMENT SCHOOL DISTRICTS | E8: Achievement School Districts | H8: =SUM(F8:G8) -> 0 | I8: =IFERROR(VLOOKUP(D8,'LEAID Match'!$A$2:$B$251,2,FALSE),"") -> 4700147
A9: =I9 -> 4700147 | B9: 2022 | C9: 30002 | D9: ACHIEVEMENT SCHOOL DISTRICTS | E9: Achievement School Districts | H9: =SUM(F9:G9) -> 0 | I9: =IFERROR(VLOOKUP(D9,'LEAID Match'!$A$2:$B$251,2,FALSE),"") -> 4700147
A10: =I10 -> 4700147 | B10: 2023 | C10: 30002 | D10: ACHIEVEMENT SCHOOL DISTRICTS | E10: ACHIEVEMENT SCHOOL DISTRICTS | H10: =SUM(F10:G10) -> 0 | I10: =IFERROR(VLOOKUP(D10,'LEAID Match'!$A$2:$B$251,2,FALSE),"") -> 4700147
A11: =I11 -> 4700030 | B11: 2015 | C11: 99117 | D11: ALAMO CITY SCHOOLS | E11: Alamo City Schools | F11: 6439 | G11: 196625 | H11: =SUM(F11:G11) -> 203064 | I11: =IFERROR(VLOOKUP(D11,'LEAID Match'!$A$2:$B$251,2,FALSE),"") -> 4700030
A12: =I12 -> 4700030 | B12: 2016 | C12: 99117 | D12: ALAMO CITY SCHOOLS | E12: Alamo City Schools | F12: 10191 | G12: 192951 | H12: =SUM(F12:G12) -> 203142 | I12: =IFERROR(VLOOKUP(D12,'LEAID Match'!$A$2:$B$251,2,FALSE),"") -> 4700030
A13: =I13 -> 4700030 | B13: 2017 | C13: 99117 | D13: ALAMO CITY SCHOOLS | E13: ALAMO CITY SCHOOLS | F13: 15397 | G13: 160882 | H13: =SUM(F13:G13) -> 176279 | I13: =IFERROR(VLOOKUP(D13,'LEAID Match'!$A$2:$B$251,2,FALSE),"") -> 4700030
A14: =I14 -> 4700030 | B14: 2018 | C14: 99117 | D14: ALAMO CITY SCHOOLS | E14: Alamo City Schools | F14: 20241 | G14: 165351 | H14: =SUM(F14:G14) -> 185592 | I14: =IFERROR(VLOOKUP(D14,'LEAID Match'!$A$2:$B$251,2,FALSE),"") -> 4700030
A15: =I15 -> 4700030 | B15: 2019 | C15: 99117 | D15: ALAMO CITY SCHOOLS | E15: ALAMO CITY SCHOOLS | F15: 11370 | G15: 179340 | H15: =SUM(F15:G15) -> 190710 | I15: =IFERROR(VLOOKUP(D15,'LEAID Match'!$A$2:$B$251,2,FALSE),"") -> 4700030
A16: =I16 -> 4700030 | B16: 2020 | C16: 99117 | D16: ALAMO CITY SCHOOLS | E16: ALAMO CITY SCHOOLS | F16: 12784 | G16: 180691 | H16: =SUM(F16:G16) -> 193475 | I16: =IFERROR(VLOOKUP(D16,'LEAID Match'!$A$2:$B$251,2,FALSE),"") -> 4700030
A17: =I17 -> 4700030 | B17: 2021 | C17: 99117 | D17: ALAMO CITY SCHOOLS | E17: ALAMO CITY SCHOOLS | F17: 13020 | G17: 178891 | H17: =SUM(F17:G17) -> 191911 | I17: =IFERROR(VLOOKUP(D17,'LEAID Match'!$A$2:$B$251,2,FALSE),"") -> 4700030
A18: =I18 -> 4700030 | B18: 2022 | C18: 99117 | D18: ALAMO CITY SCHOOLS | E18: ALAMO CITY SCHOOLS | F18: 13713.99 | G18: 189005.23 | H18: =SUM(F18:G18) -> 202719.22 | I18: =IFERROR(VLOOKUP(D18,'LEAID Match'!$A$2:$B$251,2,FALSE),"") -> 4700030
A19: =I19 -> 4700030 | B19: 2023 | C19: 99117 | D19: ALAMO CITY SCHOOLS | E19: ALAMO CITY SCHOOLS | F19: 24482.81 | G19: 154985.94 | H19: =SUM(F19:G19) -> 179468.75 | I19: =IFERROR(VLOOKUP(D19,'LEAID Match'!$A$2:$B$251,2,FALSE),"") -> 4700030
A20: =I20 -> 4700060 | B20: 2015 | C20: 99105 | D20: ALCOA CITY SCHOOLS | E20: Alcoa City Schools | F20: 2219 | G20: 787391 | H20: =SUM(F20:G20) -> 789610 | I20: =IFERROR(VLOOKUP(D20,'LEAID Match'!$A$2:$B$251,2,FALSE),"") -> 4700060
A21: =I21 -> 4700060 | B21: 2016 | C21: 99105 | D21: ALCOA CITY SCHOOLS | E21: Alcoa City Schools | F21: 10138 | G21: 805275 | H21: =SUM(F21:G21) -> 815413 | I21: =IFERROR(VLOOKUP(D21,'LEAID Match'!$A$2:$B$251,2,FALSE),"") -> 4700060
A22: =I22 -> 4700060 | B22: 2017 | C22: 99105 | D22: ALCOA CITY SCHOOLS | E22: ALCOA CITY SCHOOLS | F22: 26154 | G22: 835134 | H22: =SUM(F22:G22) -> 861288 | I22: =IFERROR(VLOOKUP(D22,'LEAID Match'!$A$2:$B$251,2,FALSE),"") -> 4700060
... A58: =I58 -> 0 | B58: 2020 | C58: 97966 | D58: ARTESIAN SCHOOLS, INC | E58: ARTESIAN SCHOOLS, INC | F58: 5395.03 | G58: 39669 | H58: =SUM(F58:G58) -> 45064.03 | I58: =IFERROR(VLOOKUP(D58,'LEAID Match'!$A$2:$B$251,2,FALSE),"") -> 0
A59: =I59 -> 0 | B59: 2021 | C59: 97966 | D59: ARTESIAN SCHOOLS, INC | E59: ARTESIAN SCHOOLS, INC | G59: 1308 | H59: =SUM(F59:G59) -> 1308 | I59: =IFERROR(VLOOKUP(D59,'LEAID Match'!$A$2:$B$251,2,FALSE),"") -> 0
A60: =I60 -> 0 | B60: 2022 | C60: 97966 | D60: ARTESIAN SCHOOLS, INC | E60: ARTESIAN SCHOOLS, INC | H60: =SUM(F60:G60) -> 0 | I60: =IFERROR(VLOOKUP(D60,'LEAID Match'!$A$2:$B$251,2,FALSE),"") -> 0
A61: =I61 -> 0 | B61: 2023 | C61: 97966 | D61: ARTESIAN SCHOOLS, INC | E61: ARTESIAN SCHOOLS, INC | H61: =SUM(F61:G61) -> 0 | I61: =IFERROR(VLOOKUP(D61,'LEAID Match'!$A$2:$B$251,2,FALSE),"") -> 0
A62: =I62 -> 0 | B62: 2016 | C62: 90604 | D62: ASD‐Aspire Public Schools | E62: ASD‐Aspire Public Schools | G62: 338386 | H62: =SUM(F62:G62) -> 338386 | I62: =IFERROR(VLOOKUP(D62,'LEAID Match'!$A$2:$B$251,2,FALSE),"") -> 0
A63: =I63 -> 0 | B63: 2017 | C63: 90604 | D63: ASD‐Aspire Public Schools | E63: ASD-ASPIRE PUBLIC SCHOOLS | F63: 129644 | G63: 367751 | H63: =SUM(F63:G63) -> 497395 | I63: =IFERROR(VLOOKUP(D63,'LEAID Match'!$A$2:$B$251,2,FALSE),"") -> 0
A64: =I64 -> 0 | B64: 2018 | C64: 90604 | D64: ASD‐Aspire Public Schools | E64: ASD-Aspire Public Schools | F64: 149596 | G64: 310255 | H64: =SUM(F64:G64) -> 459851 | I64: =IFERROR(VLOOKUP(D64,'LEAID Match'!$A$2:$B$251,2,FALSE),"") -> 0
A65: =I65 -> 0 | B65: 2019 | C65: 90604 | D65: ASD‐Aspire Public Schools | E65: ASD-ASPIRE PUBLIC SCHOOLS | F65: 79595 | G65: 272391 | H65: =SUM(F65:G65) -> 351986 | I65: =IFERROR(VLOOKUP(D65,'LEAID Match'!$A$2:$B$251,2,FALSE),"") -> 0
A66: =I66 -> 0 | B66: 2020 | C66: 90604 | D66: ASD‐Aspire Public Schools | E66: ASD-ASPIRE PUBLIC SCHOOLS | F66: 96630 | G66: 230513 | H66: =SUM(F66:G66) -> 327143 | I66: =IFERROR(VLOOKUP(D66,'LEAID Match'!$A$2:$B$251,2,FALSE),"") -> 0
A67: =I67 -> 0 | B67: 2021 | C67: 90604 | D67: ASD‐Aspire Public Schools | E67: ASD-ASPIRE PUBLIC SCHOOLS | F67: 97953 | G67: 239755 | H67: =SUM(F67:G67) -> 337708 | I67: =IFERROR(VLOOKUP(D67,'LEAID Match'!$A$2:$B$251,2,FALSE),"") -> 0
A68: =I68 -> 0 | B68: 2022 | C68: 90604 | D68: ASD‐Aspire Public Schools | E68: ASD-ASPIRE PUBLIC SCHOOLS | F68: 102081.22 | G68: 281584.27 | H68: =SUM(F68:G68) -> 383665.49 | I68: =IFERROR(VLOOKUP(D68,'LEAID Match'!$A$2:$B$251,2,FALSE),"") -> 0
A69: =I69 -> 0 | B69: 2023 | C69: 90604 | D69: ASD‐Aspire Public Schools | E69: ASD‐ASPIRE PUBLIC SCHOOLS | F69: 125742.94 | G69: 223277.89 | H69: =SUM(F69:G69) -> 349020.83 | I69: =IFERROR(VLOOKUP(D69,'LEAID Match'!$A$2:$B$251,2,FALSE),"") -> 0
A70: =I70 -> 0 | B70: 2016 | C70: 90605 | D70: ASD‐Capstone Education | E70: ASD‐Capstone Education | G70: 287991 | H70: =SUM(F70:G70) -> 287991 | I70: =IFERROR(VLOOKUP(D70,'LEAID Match'!$A$2:$B$251,2,FALSE),"") -> 0
A71: =I71 -> 0 | B71: 2017 | C71: 90605 | D71: ASD‐Capstone Education | E71: ASD-CAPSTONE EDUCATION | F71: 143090 | G71: 290361 | H71: =SUM(F71:G71) -> 433451 | I71: =IFERROR(VLOOKUP(D71,'LEAID Match'!$A$2:$B$251,2,FALSE),"") -> 0
A72: =I72 -> 0 | B72: 2018 | C72: 90605 | D72: ASD‐Capstone Education | E72: ASD-Capstone Education | F72: 163670 | G72: 302060 | H72: =SUM(F72:G72) -> 465730 | I72: =IFERROR(VLOOKUP(D72,'LEAID Match'!$A$2:$B$251,2,FALSE),"") -> 0
A73: =I73 -> 0 | B73: 2019 | C73: 90605 | D73: ASD‐Capstone Education | E73: ASD-CAPSTONE EDUCATION | F73: 93114 | G73: 286804 | H73: =SUM(F73:G73) -> 379918 | I73: =IFERROR(VLOOKUP(D73,'LEAID Match'!$A$2:$B$251,2,FALSE),"") -> 0
A74: =I74 -> 0 | B74: 2020 | C74: 90605 | D74: ASD‐Capstone Education | E74: ASD-CAPSTONE EDUCATION | F74: 107213 | G74: 290522 | H74: =SUM(F74:G74) -> 397735 | I74: =IFERROR(VLOOKUP(D74,'LEAID Match'!$A$2:$B$251,2,FALSE),"") -> 0
A75: =I75 -> 0 | B75: 2021 | C75: 90605 | D75: ASD‐Capstone Education | E75: ASD-CAPSTONE EDUCATION | F75: 104505 | G75: 267420 | H75: =SUM(F75:G75) -> 371925 | I75: =IFERROR(VLOOKUP(D75,'LEAID Match'!$A$2:$B$251,2,FALSE),"") -> 0
...

Sheet LEAID Match
A1: district_name | B1: LEAID
A2: ACHIEVEMENT SCHOOL DISTRICTS | B2: 4700147
A3: ALAMO CITY SCHOOLS | B3: 4700030
A4: ALCOA CITY SCHOOLS | B4: 4700060
A5: ANDERSON COUNTY SCHOOLS | B5: 4700090
A6: ARLINGTON MUNICIPAL SCHOOLS | B6: 4700152
A7: ARROW ACADEMY
A8: ARTESIAN SCHOOLS, INC
A9: ASD‐Aspire Public Schools
A10: ASD‐Capstone Education
A11: ASD‐Frayser Community Schools
A12: ASD‐Freedom Preparatory Schools ‐ ASD Teachers
A13: ASD‐Gestalt Charter Schools
A14: ASD‐Grad Academy
A15: ASD‐Green Dot Public Schools
A16: ASD‐Kipp Memphis Collegiate Schools
A17: ASD‐Lead Charter Schools
A18: ASD‐Libertas Schools Of Memphis
... A23: ASTER COLLEGE PREPARATORY, INC
A24: ATHENS CITY SCHOOLS | B24: 4700120
A25: AURORA COLLEGIATE ACADEMY INC.
A26: AVENTURA COMMUNITY SCHOOLS
A27: BARTLETT MUNICIPAL SCHOOLS | B27: 4700153
A28: BEACON COLLEGE PREP
A29: BEDFORD COUNTY SCHOOLS | B29: 4700180
A30: BELIEVE MEMPHIS ACADEMY
A31: Bells City Schools | B31: 4700210
A32: BENTON COUNTY SCHOOLS | B32: 4700240
A33: BLEDSOE COUNTY SCHOOLS | B33: 4700270
A34: BLOUNT COUNTY SCHOOLS | B34: 4700300
A35: BLUFF CITY HIGH SCHOOL
A36: Bradford Special Schools | B36: 4701390
A37: BRADLEY COUNTY SCHOOLS | B37: 4700330
A38: BRISTOL SCHOOLS | B38: 4700360
A39: CAMPBELL COUNTY SCHOOLS | B39: 4700420
A40: CANNON COUNTY SCHOOLS | B40: 4700450
A41: Carroll County Schools | B41: 4700480
A42: CARTER COUNTY SCHOOLS | B42: 4700510
A43: CHATTANOOGA CHARTER SCHOOL OF EXCELLENCE ‐ ELEMENTARY
A44: CHATTANOOGA CHARTER SCHOOL OF EXCELLENCE ‐ MIDDLE
...

Sheet Final Check
A1: TRS Employer Contribution Check | G1: Legacy Employer Contribution Check
A2: Year | B2: Total Reported | C2: Total from Formula | D2: Difference | E2: Notes | G2: Year | H2: Total Reported | I2: Total from Formula | J2: Difference | K2: Notes
A3: 2015 | B3: 8310939 | C3: =SUMIF('Final Data'!B:B,'Final Check'!A3,'Final Data'!F:F) -> 8310939 | D3: =B3-C3 -> 0 | G3: 2015 | H3: 338412630 | I3: =SUMIF('Final Data'!B:B,'Final Check'!G3,'Final Data'!G:G) -> 338412624 | J3: =H3-I3 -> 6
A4: 2016 | B4: 17584205 | C4: =SUMIF('Final Data'!B:B,'Final Check'!A4,'Final Data'!F:F) -> 17584206 | D4: =B4-C4 -> -1 | G4: 2016 | H4: 326379930 | I4: =SUMIF('Final Data'!B:B,'Final Check'!G4,'Final Data'!G:G) -> 326379928 | J4: =H4-I4 -> 2
A5: 2017 | B5: 26253539 | C5: =SUMIF('Final Data'!B:B,'Final Check'!A5,'Final Data'!F:F) -> 26253539 | D5: =B5-C5 -> 0 | G5: 2017 | H5: 319505383 | I5: =SUMIF('Final Data'!B:B,'Final Check'!G5,'Final Data'!G:G) -> 319505383 | J5: =H5-I5 -> 0
A6: 2018 | B6: 34955185 | C6: =SUMIF('Final Data'!B:B,'Final Check'!A6,'Final Data'!F:F) -> 34955192 | D6: =B6-C6 -> -7 | G6: 2018 | H6: 317952025 | I6: =SUMIF('Final Data'!B:B,'Final Check'!G6,'Final Data'!G:G) -> 317952019 | J6: =H6-I6 -> 6
A7: 2019 | B7: 20529151 | C7: =SUMIF('Final Data'!B:B,'Final Check'!A7,'Final Data'!F:F) -> 20529160 | D7: =B7-C7 -> -9.17 | G7: 2019 | H7: 3.5073882e+08 | I7: =SUMIF('Final Data'!B:B,'Final Check'!G7,'Final Data'!G:G) -> 350738812 | J7: =H7-I7 -> 10.75
A8: 2020 | B8: 25617003 | C8: =SUMIF('Final Data'!B:B,'Final Check'!A8,'Final Data'!F:F) -> 25617002 | D8: =B8-C8 -> 0.45 | G8: 2020 | H8: 3.5379382e+08 | I8: =SUMIF('Final Data'!B:B,'Final Check'!G8,'Final Data'!G:G) -> 353793826 | J8: =H8-I8 -> -4.8
A9: 2021 | B9: 29153070 | C9: =SUMIF('Final Data'!B:B,'Final Check'!A9,'Final Data'!F:F) -> 29153074 | D9: =B9-C9 -> -4.22 | G9: 2021 | H9: 337078947 | I9: =SUMIF('Final Data'!B:B,'Final Check'!G9,'Final Data'!G:G) -> 337078947 | J9: =H9-I9 -> 0
A10: 2022 | B10: 34324801 | C10: =SUMIF('Final Data'!B:B,'Final Check'!A10,'Final Data'!F:F) -> 34324801 | D10: =B10-C10 -> 0 | G10: 2022 | H10: 3.3896657e+08 | I10: =SUMIF('Final Data'!B:B,'Final Check'!G10,'Final Data'!G:G) -> 3.3896657e+08 | J10: =H10-I10 -> 0
A11: 2023 | B11: 57085587 | C11: =SUMIF('Final Data'!B:B,'Final Check'!A11,'Final Data'!F:F) -> 57085587 | D11: =B11-C11 -> 0 | G11: 2023 | H11: 2.8199461e+08 | I11: =SUMIF('Final Data'!B:B,'Final Check'!G11,'Final Data'!G:G) -> 2.8199461e+08 | J11: =H11-I11 -> 0

Sheet Source
A1: https://publicreports.treasury.tn.gov/Home/General?type=General
