Workbook
Name DISTRICT_TEMP: #REF!
Name TX: #REF!

Sheet Full Data
A1: LEAID | B1: year | C1: re_type | D1: re_code | E1: tea_code | F1: agency_code | G1: employer | H1: district_contributions | I1: LEAID | J1: prop | K1: state_contributions | L1: total_contributions
A2: 4813200 | B2: 2015 | C2: Public Education | D2: 0467 | E2: 001902 | G2: CAYUGA ISD | H2: 97080.86 | I2: =IFERROR(VLOOKUP(G2,'NCES Match'!$A$2:$B$1307,2,FALSE),"") -> 4813200 | J2: {=IFERROR(_xlfn.IFS(B2=2015,H2/$O$13,B2=2016,H2/$O$14,B2=2017,H2/$O$15,B2=2018,H2/$O$16,B2=2019,H2/$O$17,B2=2020,H2/$O$18,B2=2021,H2/$O$19,B2=2022,H2/$O$20),"")} -> 7.605351e-05 | K2: {=IFERROR(_xlfn.IFS(B2=2015,J2*$P$4,B2=2016,J2*$P$5,B2=2017,J2*$P$6,B2=2018,J2*$P$7,B2=2019,J2*$P$8,B2=2020,J2*$P$9,B2=2021,J2*$P$10,B2=2022,J2*$P$11),"")} -> 121037.87 | L2: =SUM(H2,K2) -> 218118.73
A3: 4813200 | B3: 2016 | C3: Public Education | D3: 0467 | E3: 001902 | G3: CAYUGA ISD | H3: 105338 | I3: =IFERROR(VLOOKUP(G3,'NCES Match'!$A$2:$B$1307,2,FALSE),"") -> 4813200 | J3: {=IFERROR(_xlfn.IFS(B3=2015,H3/$O$13,B3=2016,H3/$O$14,B3=2017,H3/$O$15,B3=2018,H3/$O$16,B3=2019,H3/$O$17,B3=2020,H3/$O$18,B3=2021,H3/$O$19,B3=2022,H3/$O$20),"")} -> 7.5407988e-05 | K3: {=IFERROR(_xlfn.IFS(B3=2015,J3*$P$4,B3=2016,J3*$P$5,B3=2017,J3*$P$6,B3=2018,J3*$P$7,B3=2019,J3*$P$8,B3=2020,J3*$P$9,B3=2021,J3*$P$10,B3=2022,J3*$P$11),"")} -> 126355.98 | L3: =SUM(H3,K3) -> 231693.98
A4: 4813200 | B4: 2017 | D4: 0467 | E4: 001902 | G4: CAYUGA ISD | H4: 100438 | I4: =IFERROR(VLOOKUP(G4,'NCES Match'!$A$2:$B$1307,2,FALSE),"") -> 4813200 | J4: {=IFERROR(_xlfn.IFS(B4=2015,H4/$O$13,B4=2016,H4/$O$14,B4=2017,H4/$O$15,B4=2018,H4/$O$16,B4=2019,H4/$O$17,B4=2020,H4/$O$18,B4=2021,H4/$O$19,B4=2022,H4/$O$20),"")} -> 6.9245851e-05 | K4: {=IFERROR(_xlfn.IFS(B4=2015,J4*$P$4,B4=2016,J4*$P$5,B4=2017,J4*$P$6,B4=2018,J4*$P$7,B4=2019,J4*$P$8,B4=2020,J4*$P$9,B4=2021,J4*$P$10,B4=2022,J4*$P$11),"")} -> 117596.62 | L4: =SUM(H4,K4) -> 218034.62 | N4: 2015 | O4: STATE OF TX AS NON EMPLOYER CONTRIBUTING ENTITY (NECE) | P4: 1.591483e+09
A5: 4813200 | B5: 2018 | D5: 0467 | E5: 001902 | G5: CAYUGA ISD | H5: 103822 | I5: =IFERROR(VLOOKUP(G5,'NCES Match'!$A$2:$B$1307,2,FALSE),"") -> 4813200 | J5: {=IFERROR(_xlfn.IFS(B5=2015,H5/$O$13,B5=2016,H5/$O$14,B5=2017,H5/$O$15,B5=2018,H5/$O$16,B5=2019,H5/$O$17,B5=2020,H5/$O$18,B5=2021,H5/$O$19,B5=2022,H5/$O$20),"")} -> 6.7749963e-05 | K5: {=IFERROR(_xlfn.IFS(B5=2015,J5*$P$4,B5=2016,J5*$P$5,B5=2017,J5*$P$6,B5=2018,J5*$P$7,B5=2019,J5*$P$8,B5=2020,J5*$P$9,B5=2021,J5*$P$10,B5=2022,J5*$P$11),"")} -> 116316.75 | L5: =SUM(H5,K5) -> 220138.75 | N5: 2016 | O5: STATE OF TX AS NON EMPLOYER CONTRIBUTING ENTITY (NECE) | P5: 1675631248
A6: 4813200 | B6: 2019 | D6: 0467 | E6: 001902 | G6: CAYUGA ISD | H6: 104998 | I6: =IFERROR(VLOOKUP(G6,'NCES Match'!$A$2:$B$1307,2,FALSE),"") -> 4813200 | J6: {=IFERROR(_xlfn.IFS(B6=2015,H6/$O$13,B6=2016,H6/$O$14,B6=2017,H6/$O$15,B6=2018,H6/$O$16,B6=2019,H6/$O$17,B6=2020,H6/$O$18,B6=2021,H6/$O$19,B6=2022,H6/$O$20),"")} -> 6.6482636e-05 | K6: {=IFERROR(_xlfn.IFS(B6=2015,J6*$P$4,B6=2016,J6*$P$5,B6=2017,J6*$P$6,B6=2018,J6*$P$7,B6=2019,J6*$P$8,B6=2020,J6*$P$9,B6=2021,J6*$P$10,B6=2022,J6*$P$11),"")} -> 115541.9 | L6: =SUM(H6,K6) -> 220539.9 | N6: 2017 | O6: STATE OF TX AS NON EMPLOYER CONTRIBUTING ENTITY (NECE) | P6: 1698247822
A7: 4813200 | B7: 2020 | D7: 0467 | E7: 001902 | G7: CAYUGA ISD | H7: 119825 | I7: =IFERROR(VLOOKUP(G7,'NCES Match'!$A$2:$B$1307,2,FALSE),"") -> 4813200 | J7: {=IFERROR(_xlfn.IFS(B7=2015,H7/$O$13,B7=2016,H7/$O$14,B7=2017,H7/$O$15,B7=2018,H7/$O$16,B7=2019,H7/$O$17,B7=2020,H7/$O$18,B7=2021,H7/$O$19,B7=2022,H7/$O$20),"")} -> 6.4934074e-05 | K7: {=IFERROR(_xlfn.IFS(B7=2015,J7*$P$4,B7=2016,J7*$P$5,B7=2017,J7*$P$6,B7=2018,J7*$P$7,B7=2019,J7*$P$8,B7=2020,J7*$P$9,B7=2021,J7*$P$10,B7=2022,J7*$P$11),"")} -> 136881.21 | L7: =SUM(H7,K7) -> 256706.21 | N7: 2018 | O7: STATE OF TX AS NON EMPLOYER CONTRIBUTING ENTITY (NECE) | P7: 1.7168533e+09
A8: 4813200 | B8: 2021 | D8: 0467 | E8: 001902 | G8: CAYUGA ISD | H8: 135843.61 | I8: =IFERROR(VLOOKUP(G8,'NCES Match'!$A$2:$B$1307,2,FALSE),"") -> 4813200 | J8: {=IFERROR(_xlfn.IFS(B8=2015,H8/$O$13,B8=2016,H8/$O$14,B8=2017,H8/$O$15,B8=2018,H8/$O$16,B8=2019,H8/$O$17,B8=2020,H8/$O$18,B8=2021,H8/$O$19,B8=2022,H8/$O$20),"")} -> 6.9503434e-05 | K8: {=IFERROR(_xlfn.IFS(B8=2015,J8*$P$4,B8=2016,J8*$P$5,B8=2017,J8*$P$6,B8=2018,J8*$P$7,B8=2019,J8*$P$8,B8=2020,J8*$P$9,B8=2021,J8*$P$10,B8=2022,J8*$P$11),"")} -> 148775.81 | L8: =SUM(H8,K8) -> 284619.42 | N8: 2019 | O8: STATE OF TX AS NON EMPLOYER CONTRIBUTING ENTITY (NECE) | P8: 1737925969
A9: 4813200 | B9: 2022 | D9: 0467 | E9: 001902 | G9: CAYUGA ISD | H9: 260445.68 | I9: =IFERROR(VLOOKUP(G9,'NCES Match'!$A$2:$B$1307,2,FALSE),"") -> 4813200 | J9: {=IFERROR(_xlfn.IFS(B9=2015,H9/$O$13,B9=2016,H9/$O$14,B9=2017,H9/$O$15,B9=2018,H9/$O$16,B9=2019,H9/$O$17,B9=2020,H9/$O$18,B9=2021,H9/$O$19,B9=2022,H9/$O$20),"")} -> 0.00011439572 | K9: {=IFERROR(_xlfn.IFS(B9=2015,J9*$P$4,B9=2016,J9*$P$5,B9=2017,J9*$P$6,B9=2018,J9*$P$7,B9=2019,J9*$P$8,B9=2020,J9*$P$9,B9=2021,J9*$P$10,B9=2022,J9*$P$11),"")} -> 246349.25 | L9: =SUM(H9,K9) -> 506794.93 | N9: 2020 | O9: STATE OF TX AS NON EMPLOYER CONTRIBUTING ENTITY (NECE) | P9: 2108002815
A10: 4813200 | B10: 2023 | D10: 0467 | E10: 001902 | G10: CAYUGA ISD | H10: 272946.36 | I10: =IFERROR(VLOOKUP(G10,'NCES Match'!$A$2:$B$1307,2,FALSE),"") -> 4813200 | J10: {=IFERROR(_xlfn.IFS(B10=2015,H10/$O$13,B10=2016,H10/$O$14,B10=2017,H10/$O$15,B10=2018,H10/$O$16,B10=2019,H10/$O$17,B10=2020,H10/$O$18,B10=2021,H10/$O$19,B10=2022,H10/$O$20),"")} | K10: {=IFERROR(_xlfn.IFS(B10=2015,J10*$P$4,B10=2016,J10*$P$5,B10=2017,J10*$P$6,B10=2018,J10*$P$7,B10=2019,J10*$P$8,B10=2020,J10*$P$9,B10=2021,J10*$P$10,B10=2022,J10*$P$11),"")} | L10: =SUM(H10,K10) -> 272946.36 | N10: 2021 | O10: STATE OF TX AS NON EMPLOYER CONTRIBUTING ENTITY (NECE) | P10: 2140553293
A11: 4818390 | B11: 2015 | C11: Public Education | D11: 0589 | E11: 001903 | G11: ELKHART ISD | H11: 144022.66 | I11: =IFERROR(VLOOKUP(G11,'NCES Match'!$A$2:$B$1307,2,FALSE),"") -> 4818390 | J11: {=IFERROR(_xlfn.IFS(B11=2015,H11/$O$13,B11=2016,H11/$O$14,B11=2017,H11/$O$15,B11=2018,H11/$O$16,B11=2019,H11/$O$17,B11=2020,H11/$O$18,B11=2021,H11/$O$19,B11=2022,H11/$O$20),"")} -> 0.00011282789 | K11: {=IFERROR(_xlfn.IFS(B11=2015,J11*$P$4,B11=2016,J11*$P$5,B11=2017,J11*$P$6,B11=2018,J11*$P$7,B11=2019,J11*$P$8,B11=2020,J11*$P$9,B11=2021,J11*$P$10,B11=2022,J11*$P$11),"")} -> 179563.67 | L11: =SUM(H11,K11) -> 323586.33 | N11: 2022 | O11: STATE OF TX AS NON EMPLOYER CONTRIBUTING ENTITY (NECE) | P11: 2153483006
A12: 4818390 | B12: 2016 | C12: Public Education | D12: 0589 | E12: 001903 | G12: ELKHART ISD | H12: 158721 | I12: =IFERROR(VLOOKUP(G12,'NCES Match'!$A$2:$B$1307,2,FALSE),"") -> 4818390 | J12: {=IFERROR(_xlfn.IFS(B12=2015,H12/$O$13,B12=2016,H12/$O$14,B12=2017,H12/$O$15,B12=2018,H12/$O$16,B12=2019,H12/$O$17,B12=2020,H12/$O$18,B12=2021,H12/$O$19,B12=2022,H12/$O$20),"")} -> 0.00011362311 | K12: {=IFERROR(_xlfn.IFS(B12=2015,J12*$P$4,B12=2016,J12*$P$5,B12=2017,J12*$P$6,B12=2018,J12*$P$7,B12=2019,J12*$P$8,B12=2020,J12*$P$9,B12=2021,J12*$P$10,B12=2022,J12*$P$11),"")} -> 190390.44 | L12: =SUM(H12,K12) -> 349111.44
A13: 4818390 | B13: 2017 | D13: 0589 | E13: 001903 | G13: ELKHART ISD | H13: 156203 | I13: =IFERROR(VLOOKUP(G13,'NCES Match'!$A$2:$B$1307,2,FALSE),"") -> 4818390 | J13: {=IFERROR(_xlfn.IFS(B13=2015,H13/$O$13,B13=2016,H13/$O$14,B13=2017,H13/$O$15,B13=2018,H13/$O$16,B13=2019,H13/$O$17,B13=2020,H13/$O$18,B13=2021,H13/$O$19,B13=2022,H13/$O$20),"")} -> 0.0001076924 | K13: {=IFERROR(_xlfn.IFS(B13=2015,J13*$P$4,B13=2016,J13*$P$5,B13=2017,J13*$P$6,B13=2018,J13*$P$7,B13=2019,J13*$P$8,B13=2020,J13*$P$9,B13=2021,J13*$P$10,B13=2022,J13*$P$11),"")} -> 182888.39 | L13: =SUM(H13,K13) -> 339091.39 | N13: 2015 | O13: =SUMIF($B$2:$B$12034,N13,$H$2:$H$12034) -> 1.276481e+09
A14: 4818390 | B14: 2018 | D14: 0589 | E14: 001903 | G14: ELKHART ISD | H14: 158921 | I14: =IFERROR(VLOOKUP(G14,'NCES Match'!$A$2:$B$1307,2,FALSE),"") -> 4818390 | J14: {=IFERROR(_xlfn.IFS(B14=2015,H14/$O$13,B14=2016,H14/$O$14,B14=2017,H14/$O$15,B14=2018,H14/$O$16,B14=2019,H14/$O$17,B14=2020,H14/$O$18,B14=2021,H14/$O$19,B14=2022,H14/$O$20),"")} -> 0.0001037053 | K14: {=IFERROR(_xlfn.IFS(B14=2015,J14*$P$4,B14=2016,J14*$P$5,B14=2017,J14*$P$6,B14=2018,J14*$P$7,B14=2019,J14*$P$8,B14=2020,J14*$P$9,B14=2021,J14*$P$10,B14=2022,J14*$P$11),"")} -> 178046.79 | L14: =SUM(H14,K14) -> 336967.79 | N14: 2016 | O14: =SUMIF($B$2:$B$12034,N14,$H$2:$H$12034) -> 1396907704
A15: 4818390 | B15: 2019 | D15: 0589 | E15: 001903 | G15: ELKHART ISD | H15: 165748 | I15: =IFERROR(VLOOKUP(G15,'NCES Match'!$A$2:$B$1307,2,FALSE),"") -> 4818390 | J15: {=IFERROR(_xlfn.IFS(B15=2015,H15/$O$13,B15=2016,H15/$O$14,B15=2017,H15/$O$15,B15=2018,H15/$O$16,B15=2019,H15/$O$17,B15=2020,H15/$O$18,B15=2021,H15/$O$19,B15=2022,H15/$O$20),"")} -> 0.00010494832 | K15: {=IFERROR(_xlfn.IFS(B15=2015,J15*$P$4,B15=2016,J15*$P$5,B15=2017,J15*$P$6,B15=2018,J15*$P$7,B15=2019,J15*$P$8,B15=2020,J15*$P$9,B15=2021,J15*$P$10,B15=2022,J15*$P$11),"")} -> 182392.42 | L15: =SUM(H15,K15) -> 348140.42 | N15: 2017 | O15: =SUMIF($B$2:$B$12034,N15,$H$2:$H$12034) -> 1450455136
A16: 4818390 | B16: 2020 | D16: 0589 | E16: 001903 | G16: ELKHART ISD | H16: 209514 | I16: =IFERROR(VLOOKUP(G16,'NCES Match'!$A$2:$B$1307,2,FALSE),"") -> 4818390 | J16: {=IFERROR(_xlfn.IFS(B16=2015,H16/$O$13,B16=2016,H16/$O$14,B16=2017,H16/$O$15,B16=2018,H16/$O$16,B16=2019,H16/$O$17,B16=2020,H16/$O$18,B16=2021,H16/$O$19,B16=2022,H16/$O$20),"")} -> 0.00011353722 | K16: {=IFERROR(_xlfn.IFS(B16=2015,J16*$P$4,B16=2016,J16*$P$5,B16=2017,J16*$P$6,B16=2018,J16*$P$7,B16=2019,J16*$P$8,B16=2020,J16*$P$9,B16=2021,J16*$P$10,B16=2022,J16*$P$11),"")} -> 239336.78 | L16: =SUM(H16,K16) -> 448850.78 | N16: 2018 | O16: =SUMIF($B$2:$B$12034,N16,$H$2:$H$12034) -> 1532428873
A17: 4818390 | B17: 2021 | D17: 0589 | E17: 001903 | G17: ELKHART ISD | H17: 208298.77 | I17: =IFERROR(VLOOKUP(G17,'NCES Match'!$A$2:$B$1307,2,FALSE),"") -> 4818390 | J17: {=IFERROR(_xlfn.IFS(B17=2015,H17/$O$13,B17=2016,H17/$O$14,B17=2017,H17/$O$15,B17=2018,H17/$O$16,B17=2019,H17/$O$17,B17=2020,H17/$O$18,B17=2021,H17/$O$19,B17=2022,H17/$O$20),"")} -> 0.00010657461 | K17: {=IFERROR(_xlfn.IFS(B17=2015,J17*$P$4,B17=2016,J17*$P$5,B17=2017,J17*$P$6,B17=2018,J17*$P$7,B17=2019,J17*$P$8,B17=2020,J17*$P$9,B17=2021,J17*$P$10,B17=2022,J17*$P$11),"")} -> 228128.63 | L17: =SUM(H17,K17) -> 436427.4 | N17: 2019 | O17: =SUMIF($B$2:$B$12034,N17,$H$2:$H$12034) -> 1579329666
A18: 4818390 | B18: 2022 | D18: 0589 | E18: 001903 | G18: ELKHART ISD | H18: 264355.44 | I18: =IFERROR(VLOOKUP(G18,'NCES Match'!$A$2:$B$1307,2,FALSE),"") -> 4818390 | J18: {=IFERROR(_xlfn.IFS(B18=2015,H18/$O$13,B18=2016,H18/$O$14,B18=2017,H18/$O$15,B18=2018,H18/$O$16,B18=2019,H18/$O$17,B18=2020,H18/$O$18,B18=2021,H18/$O$19,B18=2022,H18/$O$20),"")} -> 0.00011611301 | K18: {=IFERROR(_xlfn.IFS(B18=2015,J18*$P$4,B18=2016,J18*$P$5,B18=2017,J18*$P$6,B18=2018,J18*$P$7,B18=2019,J18*$P$8,B18=2020,J18*$P$9,B18=2021,J18*$P$10,B18=2022,J18*$P$11),"")} -> 250047.39 | L18: =SUM(H18,K18) -> 514402.83 | N18: 2020 | O18: =SUMIF($B$2:$B$12034,N18,$H$2:$H$12034) -> 1845333169
A19: 4818390 | B19: 2023 | D19: 0589 | E19: 001903 | G19: ELKHART ISD | H19: 284166.73 | I19: =IFERROR(VLOOKUP(G19,'NCES Match'!$A$2:$B$1307,2,FALSE),"") -> 4818390 | J19: {=IFERROR(_xlfn.IFS(B19=2015,H19/$O$13,B19=2016,H19/$O$14,B19=2017,H19/$O$15,B19=2018,H19/$O$16,B19=2019,H19/$O$17,B19=2020,H19/$O$18,B19=2021,H19/$O$19,B19=2022,H19/$O$20),"")} | K19: {=IFERROR(_xlfn.IFS(B19=2015,J19*$P$4,B19=2016,J19*$P$5,B19=2017,J19*$P$6,B19=2018,J19*$P$7,B19=2019,J19*$P$8,B19=2020,J19*$P$9,B19=2021,J19*$P$10,B19=2022,J19*$P$11),"")} | L19: =SUM(H19,K19) -> 284166.73 | N19: 2021 | O19: =SUMIF($B$2:$B$12034,N19,$H$2:$H$12034) -> 1.9544877e+09
A20: 4819770 | B20: 2015 | C20: Public Education | D20: 0628 | E20: 001904 | G20: FRANKSTON ISD | H20: 102631.62 | I20: =IFERROR(VLOOKUP(G20,'NCES Match'!$A$2:$B$1307,2,FALSE),"") -> 4819770 | J20: {=IFERROR(_xlfn.IFS(B20=2015,H20/$O$13,B20=2016,H20/$O$14,B20=2017,H20/$O$15,B20=2018,H20/$O$16,B20=2019,H20/$O$17,B20=2020,H20/$O$18,B20=2021,H20/$O$19,B20=2022,H20/$O$20),"")} -> 8.0401997e-05 | K20: {=IFERROR(_xlfn.IFS(B20=2015,J20*$P$4,B20=2016,J20*$P$5,B20=2017,J20*$P$6,B20=2018,J20*$P$7,B20=2019,J20*$P$8,B20=2020,J20*$P$9,B20=2021,J20*$P$10,B20=2022,J20*$P$11),"")} -> 127958.41 | L20: =SUM(H20,K20) -> 230590.03 | N20: 2022 | O20: =SUMIF($B$2:$B$12034,N20,$H$2:$H$12034) -> 2.2767082e+09
A21: 4819770 | B21: 2016 | C21: Public Education | D21: 0628 | E21: 001904 | G21: FRANKSTON ISD | H21: 126600 | I21: =IFERROR(VLOOKUP(G21,'NCES Match'!$A$2:$B$1307,2,FALSE),"") -> 4819770 | J21: {=IFERROR(_xlfn.IFS(B21=2015,H21/$O$13,B21=2016,H21/$O$14,B21=2017,H21/$O$15,B21=2018,H21/$O$16,B21=2019,H21/$O$17,B21=2020,H21/$O$18,B21=2021,H21/$O$19,B21=2022,H21/$O$20),"")} -> 9.0628751e-05 | K21: {=IFERROR(_xlfn.IFS(B21=2015,J21*$P$4,B21=2016,J21*$P$5,B21=2017,J21*$P$6,B21=2018,J21*$P$7,B21=2019,J21*$P$8,B21=2020,J21*$P$9,B21=2021,J21*$P$10,B21=2022,J21*$P$11),"")} -> 151860.37 | L21: =SUM(H21,K21) -> 278460.37
A22: 4819770 | B22: 2017 | D22: 0628 | E22: 001904 | G22: FRANKSTON ISD | H22: 123426 | I22: =IFERROR(VLOOKUP(G22,'NCES Match'!$A$2:$B$1307,2,FALSE),"") -> 4819770 | J22: {=IFERROR(_xlfn.IFS(B22=2015,H22/$O$13,B22=2016,H22/$O$14,B22=2017,H22/$O$15,B22=2018,H22/$O$16,B22=2019,H22/$O$17,B22=2020,H22/$O$18,B22=2021,H22/$O$19,B22=2022,H22/$O$20),"")} -> 8.5094669e-05 | K22: {=IFERROR(_xlfn.IFS(B22=2015,J22*$P$4,B22=2016,J22*$P$5,B22=2017,J22*$P$6,B22=2018,J22*$P$7,B22=2019,J22*$P$8,B22=2020,J22*$P$9,B22=2021,J22*$P$10,B22=2022,J22*$P$11),"")} -> 144511.84 | L22: =SUM(H22,K22) -> 267937.84
A23: 4819770 | B23: 2018 | D23: 0628 | E23: 001904 | G23: FRANKSTON ISD | H23: 144959 | I23: =IFERROR(VLOOKUP(G23,'NCES Match'!$A$2:$B$1307,2,FALSE),"") -> 4819770 | J23: {=IFERROR(_xlfn.IFS(B23=2015,H23/$O$13,B23=2016,H23/$O$14,B23=2017,H23/$O$15,B23=2018,H23/$O$16,B23=2019,H23/$O$17,B23=2020,H23/$O$18,B23=2021,H23/$O$19,B23=2022,H23/$O$20),"")} -> 9.4594276e-05 | K23: {=IFERROR(_xlfn.IFS(B23=2015,J23*$P$4,B23=2016,J23*$P$5,B23=2017,J23*$P$6,B23=2018,J23*$P$7,B23=2019,J23*$P$8,B23=2020,J23*$P$9,B23=2021,J23*$P$10,B23=2022,J23*$P$11),"")} -> 162404.49 | L23: =SUM(H23,K23) -> 307363.49
A24: 4819770 | B24: 2019 | D24: 0628 | E24: 001904 | G24: FRANKSTON ISD | H24: 162202 | I24: =IFERROR(VLOOKUP(G24,'NCES Match'!$A$2:$B$1307,2,FALSE),"") -> 4819770 | J24: {=IFERROR(_xlfn.IFS(B24=2015,H24/$O$13,B24=2016,H24/$O$14,B24=2017,H24/$O$15,B24=2018,H24/$O$16,B24=2019,H24/$O$17,B24=2020,H24/$O$18,B24=2021,H24/$O$19,B24=2022,H24/$O$20),"")} -> 0.00010270307 | K24: {=IFERROR(_xlfn.IFS(B24=2015,J24*$P$4,B24=2016,J24*$P$5,B24=2017,J24*$P$6,B24=2018,J24*$P$7,B24=2019,J24*$P$8,B24=2020,J24*$P$9,B24=2021,J24*$P$10,B24=2022,J24*$P$11),"")} -> 178490.33 | L24: =SUM(H24,K24) -> 340692.33
A25: 4819770 | B25: 2020 | D25: 0628 | E25: 001904 | G25: FRANKSTON ISD | H25: 173025 | I25: =IFERROR(VLOOKUP(G25,'NCES Match'!$A$2:$B$1307,2,FALSE),"") -> 4819770 | J25: {=IFERROR(_xlfn.IFS(B25=2015,H25/$O$13,B25=2016,H25/$O$14,B25=2017,H25/$O$15,B25=2018,H25/$O$16,B25=2019,H25/$O$17,B25=2020,H25/$O$18,B25=2021,H25/$O$19,B25=2022,H25/$O$20),"")} -> 9.3763556e-05 | K25: {=IFERROR(_xlfn.IFS(B25=2015,J25*$P$4,B25=2016,J25*$P$5,B25=2017,J25*$P$6,B25=2018,J25*$P$7,B25=2019,J25*$P$8,B25=2020,J25*$P$9,B25=2021,J25*$P$10,B25=2022,J25*$P$11),"")} -> 197653.84 | L25: =SUM(H25,K25) -> 370678.84
A26: 4819770 | B26: 2021 | D26: 0628 | E26: 001904 | G26: FRANKSTON ISD | H26: 171505.32 | I26: =IFERROR(VLOOKUP(G26,'NCES Match'!$A$2:$B$1307,2,FALSE),"") -> 4819770 | J26: {=IFERROR(_xlfn.IFS(B26=2015,H26/$O$13,B26=2016,H26/$O$14,B26=2017,H26/$O$15,B26=2018,H26/$O$16,B26=2019,H26/$O$17,B26=2020,H26/$O$18,B26=2021,H26/$O$19,B26=2022,H26/$O$20),"")} -> 8.7749499e-05 | K26: {=IFERROR(_xlfn.IFS(B26=2015,J26*$P$4,B26=2016,J26*$P$5,B26=2017,J26*$P$6,B26=2018,J26*$P$7,B26=2019,J26*$P$8,B26=2020,J26*$P$9,B26=2021,J26*$P$10,B26=2022,J26*$P$11),"")} -> 187832.48 | L26: =SUM(H26,K26) -> 359337.8
A27: 4819770 | B27: 2022 | D27: 0628 | E27: 001904 | G27: FRANKSTON ISD | H27: 246987.27 | I27: =IFERROR(VLOOKUP(G27,'NCES Match'!$A$2:$B$1307,2,FALSE),"") -> 4819770 | J27: {=IFERROR(_xlfn.IFS(B27=2015,H27/$O$13,B27=2016,H27/$O$14,B27=2017,H27/$O$15,B27=2018,H27/$O$16,B27=2019,H27/$O$17,B27=2020,H27/$O$18,B27=2021,H27/$O$19,B27=2022,H27/$O$20),"")} -> 0.00010848438 | K27: {=IFERROR(_xlfn.IFS(B27=2015,J27*$P$4,B27=2016,J27*$P$5,B27=2017,J27*$P$6,B27=2018,J27*$P$7,B27=2019,J27*$P$8,B27=2020,J27*$P$9,B27=2021,J27*$P$10,B27=2022,J27*$P$11),"")} -> 233619.26 | L27: =SUM(H27,K27) -> 480606.53
A28: 4819770 | B28: 2023 | D28: 0628 | E28: 001904 | G28: FRANKSTON ISD | H28: 240464.75 | I28: =IFERROR(VLOOKUP(G28,'NCES Match'!$A$2:$B$1307,2,FALSE),"") -> 4819770 | J28: {=IFERROR(_xlfn.IFS(B28=2015,H28/$O$13,B28=2016,H28/$O$14,B28=2017,H28/$O$15,B28=2018,H28/$O$16,B28=2019,H28/$O$17,B28=2020,H28/$O$18,B28=2021,H28/$O$19,B28=2022,H28/$O$20),"")} | K28: {=IFERROR(_xlfn.IFS(B28=2015,J28*$P$4,B28=2016,J28*$P$5,B28=2017,J28*$P$6,B28=2018,J28*$P$7,B28=2019,J28*$P$8,B28=2020,J28*$P$9,B28=2021,J28*$P$10,B28=2022,J28*$P$11),"")} | L28: =SUM(H28,K28) -> 240464.75
A29: 4832250 | B29: 2015 | C29: Public Education | D29: 0946 | E29: 001906 | G29: NECHES ISD | H29: 54028.01 | I29: =IFERROR(VLOOKUP(G29,'NCES Match'!$A$2:$B$1307,2,FALSE),"") -> 4832250 | J29: {=IFERROR(_xlfn.IFS(B29=2015,H29/$O$13,B29=2016,H29/$O$14,B29=2017,H29/$O$15,B29=2018,H29/$O$16,B29=2019,H29/$O$17,B29=2020,H29/$O$18,B29=2021,H29/$O$19,B29=2022,H29/$O$20),"")} -> 4.2325746e-05 | K29: {=IFERROR(_xlfn.IFS(B29=2015,J29*$P$4,B29=2016,J29*$P$5,B29=2017,J29*$P$6,B29=2018,J29*$P$7,B29=2019,J29*$P$8,B29=2020,J29*$P$9,B29=2021,J29*$P$10,B29=2022,J29*$P$11),"")} -> 67360.705 | L29: =SUM(H29,K29) -> 121388.71
A30: 4832250 | B30: 2016 | C30: Public Education | D30: 0946 | E30: 001906 | G30: NECHES ISD | H30: 64239 | I30: =IFERROR(VLOOKUP(G30,'NCES Match'!$A$2:$B$1307,2,FALSE),"") -> 4832250 | J30: {=IFERROR(_xlfn.IFS(B30=2015,H30/$O$13,B30=2016,H30/$O$14,B30=2017,H30/$O$15,B30=2018,H30/$O$16,B30=2019,H30/$O$17,B30=2020,H30/$O$18,B30=2021,H30/$O$19,B30=2022,H30/$O$20),"")} -> 4.5986574e-05 | K30: {=IFERROR(_xlfn.IFS(B30=2015,J30*$P$4,B30=2016,J30*$P$5,B30=2017,J30*$P$6,B30=2018,J30*$P$7,B30=2019,J30*$P$8,B30=2020,J30*$P$9,B30=2021,J30*$P$10,B30=2022,J30*$P$11),"")} -> 77056.541 | L30: =SUM(H30,K30) -> 141295.54
A31: 4832250 | B31: 2017 | D31: 0946 | E31: 001906 | G31: NECHES ISD | H31: 65306 | I31: =IFERROR(VLOOKUP(G31,'NCES Match'!$A$2:$B$1307,2,FALSE),"") -> 4832250 | J31: {=IFERROR(_xlfn.IFS(B31=2015,H31/$O$13,B31=2016,H31/$O$14,B31=2017,H31/$O$15,B31=2018,H31/$O$16,B31=2019,H31/$O$17,B31=2020,H31/$O$18,B31=2021,H31/$O$19,B31=2022,H31/$O$20),"")} -> 4.5024488e-05 | K31: {=IFERROR(_xlfn.IFS(B31=2015,J31*$P$4,B31=2016,J31*$P$5,B31=2017,J31*$P$6,B31=2018,J31*$P$7,B31=2019,J31*$P$8,B31=2020,J31*$P$9,B31=2021,J31*$P$10,B31=2022,J31*$P$11),"")} -> 76462.739 | L31: =SUM(H31,K31) -> 141768.74
A32: 4832250 | B32: 2018 | D32: 0946 | E32: 001906 | G32: NECHES ISD | H32: 61101 | I32: =IFERROR(VLOOKUP(G32,'NCES Match'!$A$2:$B$1307,2,FALSE),"") -> 4832250 | J32: {=IFERROR(_xlfn.IFS(B32=2015,H32/$O$13,B32=2016,H32/$O$14,B32=2017,H32/$O$15,B32=2018,H32/$O$16,B32=2019,H32/$O$17,B32=2020,H32/$O$18,B32=2021,H32/$O$19,B32=2022,H32/$O$20),"")} -> 3.9871997e-05 | K32: {=IFERROR(_xlfn.IFS(B32=2015,J32*$P$4,B32=2016,J32*$P$5,B32=2017,J32*$P$6,B32=2018,J32*$P$7,B32=2019,J32*$P$8,B32=2020,J32*$P$9,B32=2021,J32*$P$10,B32=2022,J32*$P$11),"")} -> 68454.37 | L32: =SUM(H32,K32) -> 129555.37
A33: 4832250 | B33: 2019 | D33: 0946 | E33: 001906 | G33: NECHES ISD | H33: 63067 | I33: =IFERROR(VLOOKUP(G33,'NCES Match'!$A$2:$B$1307,2,FALSE),"") -> 4832250 | J33: {=IFERROR(_xlfn.IFS(B33=2015,H33/$O$13,B33=2016,H33/$O$14,B33=2017,H33/$O$15,B33=2018,H33/$O$16,B33=2019,H33/$O$17,B33=2020,H33/$O$18,B33=2021,H33/$O$19,B33=2022,H33/$O$20),"")} -> 3.9932765e-05 | K33: {=IFERROR(_xlfn.IFS(B33=2015,J33*$P$4,B33=2016,J33*$P$5,B33=2017,J33*$P$6,B33=2018,J33*$P$7,B33=2019,J33*$P$8,B33=2020,J33*$P$9,B33=2021,J33*$P$10,B33=2022,J33*$P$11),"")} -> 69400.189 | L33: =SUM(H33,K33) -> 132467.19
A34: 4832250 | B34: 2020 | D34: 0946 | E34: 001906 | G34: NECHES ISD | H34: 73051 | I34: =IFERROR(VLOOKUP(G34,'NCES Match'!$A$2:$B$1307,2,FALSE),"") -> 4832250 | J34: {=IFERROR(_xlfn.IFS(B34=2015,H34/$O$13,B34=2016,H34/$O$14,B34=2017,H34/$O$15,B34=2018,H34/$O$16,B34=2019,H34/$O$17,B34=2020,H34/$O$18,B34=2021,H34/$O$19,B34=2022,H34/$O$20),"")} -> 3.9586889e-05 | K34: {=IFERROR(_xlfn.IFS(B34=2015,J34*$P$4,B34=2016,J34*$P$5,B34=2017,J34*$P$6,B34=2018,J34*$P$7,B34=2019,J34*$P$8,B34=2020,J34*$P$9,B34=2021,J34*$P$10,B34=2022,J34*$P$11),"")} -> 83449.274 | L34: =SUM(H34,K34) -> 156500.27
A35: 4832250 | B35: 2021 | D35: 0946 | E35: 001906 | G35: NECHES ISD | H35: 75088.96 | I35: =IFERROR(VLOOKUP(G35,'NCES Match'!$A$2:$B$1307,2,FALSE),"") -> 4832250 | J35: {=IFERROR(_xlfn.IFS(B35=2015,H35/$O$13,B35=2016,H35/$O$14,B35=2017,H35/$O$15,B35=2018,H35/$O$16,B35=2019,H35/$O$17,B35=2020,H35/$O$18,B35=2021,H35/$O$19,B35=2022,H35/$O$20),"")} -> 3.8418742e-05 | K35: {=IFERROR(_xlfn.IFS(B35=2015,J35*$P$4,B35=2016,J35*$P$5,B35=2017,J35*$P$6,B35=2018,J35*$P$7,B35=2019,J35*$P$8,B35=2020,J35*$P$9,B35=2021,J35*$P$10,B35=2022,J35*$P$11),"")} -> 82237.365 | L35: =SUM(H35,K35) -> 157326.32
A36: 4832250 | B36: 2022 | D36: 0946 | E36: 001906 | G36: NECHES ISD | H36: 94876.5 | I36: =IFERROR(VLOOKUP(G36,'NCES Match'!$A$2:$B$1307,2,FALSE),"") -> 4832250 | J36: {=IFERROR(_xlfn.IFS(B36=2015,H36/$O$13,B36=2016,H36/$O$14,B36=2017,H36/$O$15,B36=2018,H36/$O$16,B36=2019,H36/$O$17,B36=2020,H36/$O$18,B36=2021,H36/$O$19,B36=2022,H36/$O$20),"")} -> 4.1672666e-05 | K36: {=IFERROR(_xlfn.IFS(B36=2015,J36*$P$4,B36=2016,J36*$P$5,B36=2017,J36*$P$6,B36=2018,J36*$P$7,B36=2019,J36*$P$8,B36=2020,J36*$P$9,B36=2021,J36*$P$10,B36=2022,J36*$P$11),"")} -> 89741.378 | L36: =SUM(H36,K36) -> 184617.88
A37: 4832250 | B37: 2023 | D37: 0946 | E37: 001906 | G37: NECHES ISD | H37: 110774.45 | I37: =IFERROR(VLOOKUP(G37,'NCES Match'!$A$2:$B$1307,2,FALSE),"") -> 4832250 | J37: {=IFERROR(_xlfn.IFS(B37=2015,H37/$O$13,B37=2016,H37/$O$14,B37=2017,H37/$O$15,B37=2018,H37/$O$16,B37=2019,H37/$O$17,B37=2020,H37/$O$18,B37=2021,H37/$O$19,B37=2022,H37/$O$20),"")} | K37: {=IFERROR(_xlfn.IFS(B37=2015,J37*$P$4,B37=2016,J37*$P$5,B37=2017,J37*$P$6,B37=2018,J37*$P$7,B37=2019,J37*$P$8,B37=2020,J37*$P$9,B37=2021,J37*$P$10,B37=2022,J37*$P$11),"")} | L37: =SUM(H37,K37) -> 110774.45
A38: 4834050 | B38: 2015 | C38: Public Education | D38: 0987 | E38: 001907 | G38: PALESTINE ISD | H38: 655233.02 | I38: =IFERROR(VLOOKUP(G38,'NCES Match'!$A$2:$B$1307,2,FALSE),"") -> 4834050 | J38: {=IFERROR(_xlfn.IFS(B38=2015,H38/$O$13,B38=2016,H38/$O$14,B38=2017,H38/$O$15,B38=2018,H38/$O$16,B38=2019,H38/$O$17,B38=2020,H38/$O$18,B38=2021,H38/$O$19,B38=2022,H38/$O$20),"")} -> 0.00051331201 | K38: {=IFERROR(_xlfn.IFS(B38=2015,J38*$P$4,B38=2016,J38*$P$5,B38=2017,J38*$P$6,B38=2018,J38*$P$7,B38=2019,J38*$P$8,B38=2020,J38*$P$9,B38=2021,J38*$P$10,B38=2022,J38*$P$11),"")} -> 816927.33 | L38: =SUM(H38,K38) -> 1472160.4
A39: 4834050 | B39: 2016 | C39: Public Education | D39: 0987 | E39: 001907 | G39: PALESTINE ISD | H39: 672775 | I39: =IFERROR(VLOOKUP(G39,'NCES Match'!$A$2:$B$1307,2,FALSE),"") -> 4834050 | J39: {=IFERROR(_xlfn.IFS(B39=2015,H39/$O$13,B39=2016,H39/$O$14,B39=2017,H39/$O$15,B39=2018,H39/$O$16,B39=2019,H39/$O$17,B39=2020,H39/$O$18,B39=2021,H39/$O$19,B39=2022,H39/$O$20),"")} -> 0.00048161736 | K39: {=IFERROR(_xlfn.IFS(B39=2015,J39*$P$4,B39=2016,J39*$P$5,B39=2017,J39*$P$6,B39=2018,J39*$P$7,B39=2019,J39*$P$8,B39=2020,J39*$P$9,B39=2021,J39*$P$10,B39=2022,J39*$P$11),"")} -> 807013.1 | L39: =SUM(H39,K39) -> 1479788.1
A40: 4834050 | B40: 2017 | D40: 0987 | E40: 001907 | G40: PALESTINE ISD | H40: 689661 | I40: =IFERROR(VLOOKUP(G40,'NCES Match'!$A$2:$B$1307,2,FALSE),"") -> 4834050 | J40: {=IFERROR(_xlfn.IFS(B40=2015,H40/$O$13,B40=2016,H40/$O$14,B40=2017,H40/$O$15,B40=2018,H40/$O$16,B40=2019,H40/$O$17,B40=2020,H40/$O$18,B40=2021,H40/$O$19,B40=2022,H40/$O$20),"")} -> 0.00047547903 | K40: {=IFERROR(_xlfn.IFS(B40=2015,J40*$P$4,B40=2016,J40*$P$5,B40=2017,J40*$P$6,B40=2018,J40*$P$7,B40=2019,J40*$P$8,B40=2020,J40*$P$9,B40=2021,J40*$P$10,B40=2022,J40*$P$11),"")} -> 807481.23 | L40: =SUM(H40,K40) -> 1497142.2
...

Sheet Data Checks -->

Sheet Check
A1: Year | B1: Total as Reported | C1: Total from Formula | D1: Difference
A2: 2015 | B2: 2.961043e+09 | C2: =SUMIF('Full Data'!B$2:B$12034,A2,'Full Data'!H$2:H$12034) -> 1.276481e+09 | D2: =B2-C2 -> 1.684562e+09
A3: 2016 | B3: 3177253173 | C3: =SUMIF('Full Data'!B$2:B$12034,A3,'Full Data'!H$2:H$12034) -> 1396907704 | D3: =B3-C3 -> 1780345469
A4: 2017 | B4: 3277416424 | C4: =SUMIF('Full Data'!B$2:B$12034,A4,'Full Data'!H$2:H$12034) -> 1450455136 | D4: =B4-C4 -> 1826961288
A5: 2018 | B5: 3368747009 | C5: =SUMIF('Full Data'!B$2:B$12034,A5,'Full Data'!H$2:H$12034) -> 1532428873 | D5: =B5-C5 -> 1836318136
A6: 2019 | B6: 3500120523 | C6: =SUMIF('Full Data'!B$2:B$12034,A6,'Full Data'!H$2:H$12034) -> 1579329666 | D6: =B6-C6 -> 1920790857
A7: 2020 | B7: 4126027317 | C7: =SUMIF('Full Data'!B$2:B$12034,A7,'Full Data'!H$2:H$12034) -> 1845333169 | D7: =B7-C7 -> 2280694148
A8: 2021 | B8: 4267475179 | C8: =SUMIF('Full Data'!B$2:B$12034,A8,'Full Data'!H$2:H$12034) -> 1.9544877e+09 | D8: =B8-C8 -> 2.3129874e+09
A9: 2022 | B9: 4666295602 | C9: =SUMIF('Full Data'!B$2:B$12034,A9,'Full Data'!H$2:H$12034) -> 2.2767082e+09 | D9: =B9-C9 -> 2.3895874e+09
A10: 2023 | B10: 5140238554 | C10: =SUMIF('Full Data'!B$2:B$12034,A10,'Full Data'!H$2:H$12034) -> 2.5911111e+09 | D10: =B10-C10 -> 2.5491274e+09

Sheet NCES Match
A1: district_name | B1: LEAID
A2: UPLIFT EDUCATION | B2: 4800030
A3: THE NORTH HILLS SCHOOL | B3: 4800030
A4: BURNHAM WOOD CHARTER SCHOOL | B4: 4800037
A5: BURNHAM WOOD CHARTER SCH. | B5: 4800037
A6: NEW FRONTIERS CHARTER SCHOOL | B6: 4800061
A7: NEW FRONTIERS PUBLIC SCHOOLS | B7: 4800061
A8: SCHOOL OF EXCELLENCE IN EDUCATION | B8: 4800062
A9: LEGACY TRADITIONAL SCHOOLS - TEXAS | B9: 4800062
A10: SOUTHWEST PREPARATORY SCHOOL | B10: 4800063
A11: SOUTHWEST PREPARATORY SCH | B11: 4800063
A12: SOUTH TEXAS EDUCATIONAL TECH | B12: 4800065
A13: SOUTH TEXAS EDUCATIONAL TECH INC | B13: 4800065
... A1307: STAFFORD MUNCPL SCH DIST | B1307: 4841350
