Workbook

Sheet Summary
A1: LEAID | B1: Year | C1: district_name | D1: State | E1: state_abv | F1: district_contributions | G1: state_contributions | H1: total_contributions | I1: LEAID Match
A2: 0 | B2: 2020 | C2: ACADIANA AREA HUMAN SERVICES DISTRICT | D2: Louisiana | E2: LA | F2: 5613 | G2: 198 | H2: 5811 | I2: =VLOOKUP(C2,LEAIDs!$A$2:$B$305,2,FALSE) -> 0
A3: 0 | B3: 2015 | C3: ADVOCATES FOR ACADEMIC EXCELLENCE | D3: Louisiana | E3: LA | F3: 1131891 | G3: 34795 | H3: 1166686 | I3: =VLOOKUP(C3,LEAIDs!$A$2:$B$305,2,FALSE) -> 0
A4: 0 | B4: 2016 | C4: ADVOCATES FOR ACADEMIC EXCELLENCE | D4: Louisiana | E4: LA | F4: 1136214 | G4: 37478 | H4: 1173692 | I4: =VLOOKUP(C4,LEAIDs!$A$2:$B$305,2,FALSE) -> 0
A5: 0 | B5: 2017 | C5: ADVOCATES FOR ACADEMIC EXCELLENCE | D5: Louisiana | E5: LA | F5: 1182106 | G5: 40829 | H5: 1222935 | I5: =VLOOKUP(C5,LEAIDs!$A$2:$B$305,2,FALSE) -> 0
A6: 0 | B6: 2018 | C6: ADVOCATES FOR ACADEMIC EXCELLENCE | D6: Louisiana | E6: LA | F6: 1382116 | G6: 45483 | H6: 1427599 | I6: =VLOOKUP(C6,LEAIDs!$A$2:$B$305,2,FALSE) -> 0
A7: 0 | B7: 2019 | C7: ADVOCATES FOR ACADEMIC EXCELLENCE | D7: Louisiana | E7: LA | F7: 1405354 | G7: 47166 | H7: 1452520 | I7: =VLOOKUP(C7,LEAIDs!$A$2:$B$305,2,FALSE) -> 0
A8: 0 | B8: 2020 | C8: ADVOCATES FOR ACADEMIC EXCELLENCE | D8: Louisiana | E8: LA | F8: 1291152 | G8: 45563 | H8: 1336715 | I8: =VLOOKUP(C8,LEAIDs!$A$2:$B$305,2,FALSE) -> 0
A9: 0 | B9: 2021 | C9: ADVOCATES FOR ACADEMIC EXCELLENCE | D9: Louisiana | E9: LA | F9: 1400081 | G9: 48733 | H9: 1448814 | I9: =VLOOKUP(C9,LEAIDs!$A$2:$B$305,2,FALSE) -> 0
A10: 0 | B10: 2022 | C10: ADVOCATES FOR ACADEMIC EXCELLENCE | D10: Louisiana | E10: LA | F10: 1316137 | G10: 47022 | H10: 1363159 | I10: =VLOOKUP(C10,LEAIDs!$A$2:$B$305,2,FALSE) -> 0
A11: 0 | B11: 2023 | C11: ADVOCATES FOR ACADEMIC EXCELLENCE | D11: Louisiana | E11: LA | F11: 1425106 | G11: 50807 | H11: 1475913 | I11: =VLOOKUP(C11,LEAIDs!$A$2:$B$305,2,FALSE) -> 0
A12: 0 | B12: 2023 | C12: ADVOCATES FOR ARTS - BASED EDUCATION CORP | D12: Louisiana | E12: LA | F12: 2967206 | G12: 105786 | H12: 3072992 | I12: =VLOOKUP(C12,LEAIDs!$A$2:$B$305,2,FALSE) -> 0
A13: 0 | B13: 2015 | C13: ADVOCATES FOR ARTS-BASED EDUCATION CORP | D13: Louisiana | E13: LA | F13: 2419812 | G13: 74386 | H13: 2494198 | I13: =VLOOKUP(C13,LEAIDs!$A$2:$B$305,2,FALSE) -> 0
... A2028: 2280100 | B2028: 2022 | C2028: SPECIAL SCHOOL DISTRICTS | D2028: Louisiana | E2028: LA | F2028: 2427522 | G2028: 86730 | H2028: 2514252 | I2028: =VLOOKUP(C2028,LEAIDs!$A$2:$B$305,2,FALSE) -> 2280100

Sheet Yearly Data & Checks -->

Sheet 2023
A1: Year | B1: district_name | C1: State | D1: state_abv | E1: district_contributions | F1: state_contributions | G1: total_contributions
A2: 2023 | B2: A. E. PHILLIPS LABORATORY SCHOOL | C2: Louisiana | D2: LA | E2: 134179 | F2: 4784 | G2: =SUM(E2:F2) -> 138963
A3: 2023 | B3: ACADIA PARISH SCHOOL BOARD | C3: Louisiana | D3: LA | E3: 12222129 | F3: 435739 | G3: =SUM(E3:F3) -> 12657868
A4: 2023 | B4: ADVOCATES FOR ACADEMIC EXCELLENCE | C4: Louisiana | D4: LA | E4: 1425106 | F4: 50807 | G4: =SUM(E4:F4) -> 1475913
A5: 2023 | B5: ADVOCATES FOR ARTS - BASED EDUCATION CORP | C5: Louisiana | D5: LA | E5: 2967206 | F5: 105786 | G5: =SUM(E5:F5) -> 3072992
A6: 2023 | B6: ADVOCATES FOR INNOVATIVE SCHOOLS | C6: Louisiana | D6: LA | E6: 541354 | F6: 19300 | G6: =SUM(E6:F6) -> 560654
A7: 2023 | B7: ALGIERS CHARTER SCHOOLS ASSOCIATION | C7: Louisiana | D7: LA | E7: 2701342 | F7: 96307 | G7: =SUM(E7:F7) -> 2797649
A8: 2023 | B8: ALLEN PARISH SCHOOL BOARD | C8: Louisiana | D8: LA | E8: 6264813 | F8: 223351 | G8: =SUM(E8:F8) -> 6488164
A9: 2023 | B9: ASCENSION PARISH SCHOOL BOARD | C9: Louisiana | D9: LA | E9: 33950435 | F9: 1210389 | G9: =SUM(E9:F9) -> 35160824
A10: 2023 | B10: ASSOCIATED PROFESSIONAL EDUCATORS OF LA | C10: Louisiana | D10: LA | E10: 30302 | F10: 1080 | G10: =SUM(E10:F10) -> 31382
A11: 2023 | B11: ASSUMPTION PARISH SCHOOL BOARD | C11: Louisiana | D11: LA | E11: 4248229 | F11: 151456 | G11: =SUM(E11:F11) -> 4399685
A12: 2023 | B12: AVOYELLES CORRECTIONAL CENTER | C12: Louisiana | D12: LA | E12: 53271 | F12: 1899 | G12: =SUM(E12:F12) -> 55170
A13: 2023 | B13: AVOYELLES PARISH SCHOOL BOARD | C13: Louisiana | D13: LA | E13: 5827323 | F13: 207754 | G13: =SUM(E13:F13) -> 6035077
... A232: 2023 | B232: ZACHARY COMMUNITY SCHOOL BOARD | C232: Louisiana | D232: LA | E232: 8120784 | F232: 289519 | G232: =SUM(E232:F232) -> 8410303
D234: Summed Formula | E234: =SUM(E2:E232) -> 1333120543 | F234: =SUM(F2:F232) -> 47527936
D236: GASB 68 | E236: 1333120541 | F236: 47527931
D238: Check | E238: =E234-E236 -> 2 | F238: =F234-F236 -> 5

Sheet 2022
A1: Year | B1: district_name | C1: State | D1: state_abv | E1: district_contributions | F1: state_contributions | G1: total_contributions
A2: 2022 | B2: ACADIA PARISH SCHOOL BOARD | C2: Louisiana | D2: LA | E2: 11977068 | F2: 427912 | G2: =SUM(E2:F2) -> 12404980
A3: 2022 | B3: ALLEN PARISH SCHOOL BOARD | C3: Louisiana | D3: LA | E3: 5800925 | F3: 207253 | G3: =SUM(E3:F3) -> 6008178
A4: 2022 | B4: ASCENSION PARISH SCHOOL BOARD | C4: Louisiana | D4: LA | E4: 31953546 | F4: 1141624 | G4: =SUM(E4:F4) -> 33095170
A5: 2022 | B5: ASSUMPTION PARISH SCHOOL BOARD | C5: Louisiana | D5: LA | E5: 4268274 | F5: 152495 | G5: =SUM(E5:F5) -> 4420769
A6: 2022 | B6: AVOYELLES PARISH SCHOOL BOARD | C6: Louisiana | D6: LA | E6: 5284462 | F6: 188801 | G6: =SUM(E6:F6) -> 5473263
A7: 2022 | B7: BEAUREGARD PARISH SCHOOL BOARD | C7: Louisiana | D7: LA | E7: 7921952 | F7: 283032 | G7: =SUM(E7:F7) -> 8204984
A8: 2022 | B8: BIENVILLE PARISH SCHOOL BOARD | C8: Louisiana | D8: LA | E8: 4372208 | F8: 156209 | G8: =SUM(E8:F8) -> 4528417
A9: 2022 | B9: BOSSIER PARISH SCHOOL BOARD | C9: Louisiana | D9: LA | E9: 32496217 | F9: 1161012 | G9: =SUM(E9:F9) -> 33657229
A10: 2022 | B10: CADDO PARISH SCHOOL BOARD | C10: Louisiana | D10: LA | E10: 52406125 | F10: 1872346 | G10: =SUM(E10:F10) -> 54278471
A11: 2022 | B11: CALCASIEU PARISH SCHOOL SYSTEM | C11: Louisiana | D11: LA | E11: 47477142 | F11: 1696245 | G11: =SUM(E11:F11) -> 49173387
A12: 2022 | B12: CALDWELL PARISH SCHOOL BOARD | C12: Louisiana | D12: LA | E12: 2656532 | F12: 94912 | G12: =SUM(E12:F12) -> 2751444
A13: 2022 | B13: CAMERON PARISH SCHOOL BOARD | C13: Louisiana | D13: LA | E13: 2751653 | F13: 98310 | G13: =SUM(E13:F13) -> 2849963
... A225: 2022 | B225: DEPARTMENT OF ENVIRONMENTAL QUALITY | C225: Louisiana | D225: LA | E225: 45516 | F225: 1626 | G225: =SUM(E225:F225) -> 47142
D227: Summed Formula | E227: =SUM(E2:E225) -> 1266088195 | F227: =SUM(F2:F225) -> 45234318
D229: GASB 68 | E229: 1266088182 | F229: 45234317
D231: Check | E231: =E227-E229 -> 13 | F231: =F227-F229 -> 1

Sheet 2021
A1: Year | B1: district_name | C1: State | D1: state_abv | E1: district_contributions | F1: state_contributions | G1: total_contributions
A2: 2021 | B2: ACADIA PARISH SCHOOL BOARD | C2: Louisiana | D2: LA | E2: 11159926 | F2: 388447 | G2: =SUM(E2:F2) -> 11548373
A3: 2021 | B3: ALLEN PARISH SCHOOL BOARD | C3: Louisiana | D3: LA | E3: 5537199 | F3: 192735 | G3: =SUM(E3:F3) -> 5729934
A4: 2021 | B4: ASCENSION PARISH SCHOOL BOARD | C4: Louisiana | D4: LA | E4: 30482997 | F4: 1061032 | G4: =SUM(E4:F4) -> 31544029
A5: 2021 | B5: ASSUMPTION PARISH SCHOOL BOARD | C5: Louisiana | D5: LA | E5: 4259775 | F5: 148271 | G5: =SUM(E5:F5) -> 4408046
A6: 2021 | B6: AVOYELLES PARISH SCHOOL BOARD | C6: Louisiana | D6: LA | E6: 5004371 | F6: 174189 | G6: =SUM(E6:F6) -> 5178560
A7: 2021 | B7: BEAUREGARD PARISH SCHOOL BOARD | C7: Louisiana | D7: LA | E7: 7601593 | F7: 264591 | G7: =SUM(E7:F7) -> 7866184
A8: 2021 | B8: BIENVILLE PARISH SCHOOL BOARD | C8: Louisiana | D8: LA | E8: 4152118 | F8: 144524 | G8: =SUM(E8:F8) -> 4296642
A9: 2021 | B9: BOSSIER PARISH SCHOOL BOARD | C9: Louisiana | D9: LA | E9: 30592389 | F9: 1064839 | G9: =SUM(E9:F9) -> 31657228
A10: 2021 | B10: CADDO PARISH SCHOOL BOARD | C10: Louisiana | D10: LA | E10: 49479020 | F10: 1722233 | G10: =SUM(E10:F10) -> 51201253
A11: 2021 | B11: CALCASIEU PARISH SCHOOL SYSTEM | C11: Louisiana | D11: LA | E11: 47022481 | F11: 1636727 | G11: =SUM(E11:F11) -> 48659208
A12: 2021 | B12: CALDWELL PARISH SCHOOL BOARD | C12: Louisiana | D12: LA | E12: 2631091 | F12: 91581 | G12: =SUM(E12:F12) -> 2722672
A13: 2021 | B13: CAMERON PARISH SCHOOL BOARD | C13: Louisiana | D13: LA | E13: 2646240 | F13: 92109 | G13: =SUM(E13:F13) -> 2738349
... A225: 2021 | B225: DEPARTMENT OF ENVIRONMENTAL QUALITY | C225: Louisiana | D225: LA | E225: 45522 | F225: 1585 | G225: =SUM(E225:F225) -> 47107
D227: Summed Formula | E227: =SUM(E2:E225) -> 1239712156 | F227: =SUM(F2:F225) -> 43151068
D229: GASB 68 | E229: 1239712158 | F229: 43151074
D231: Check | E231: =E227-E229 -> -2 | F231: =F227-F229 -> -6

Sheet 2020
A1: Year | B1: district_name | C1: State | D1: state_abv | E1: district_contributions | F1: state_contributions | G1: total_contributions
A2: 2020 | B2: ACADIA PARISH SCHOOL BOARD | C2: Louisiana | D2: LA | E2: 10930804 | F2: 385731 | G2: =SUM(E2:F2) -> 11316535
A3: 2020 | B3: ALLEN PARISH SCHOOL BOARD | C3: Louisiana | D3: LA | E3: 5530364 | F3: 195158 | G3: =SUM(E3:F3) -> 5725522
A4: 2020 | B4: ASCENSION PARISH SCHOOL BOARD | C4: Louisiana | D4: LA | E4: 29706615 | F4: 1048301 | G4: =SUM(E4:F4) -> 30754916
A5: 2020 | B5: ASSUMPTION PARISH SCHOOL BOARD | C5: Louisiana | D5: LA | E5: 4218656 | F5: 148870 | G5: =SUM(E5:F5) -> 4367526
A6: 2020 | B6: AVOYELLES PARISH SCHOOL BOARD | C6: Louisiana | D6: LA | E6: 4888083 | F6: 172493 | G6: =SUM(E6:F6) -> 5060576
A7: 2020 | B7: BEAUREGARD PARISH SCHOOL BOARD | C7: Louisiana | D7: LA | E7: 7408012 | F7: 261417 | G7: =SUM(E7:F7) -> 7669429
A8: 2020 | B8: BIENVILLE PARISH SCHOOL BOARD | C8: Louisiana | D8: LA | E8: 3882738 | F8: 137016 | G8: =SUM(E8:F8) -> 4019754
A9: 2020 | B9: BOSSIER PARISH SCHOOL BOARD | C9: Louisiana | D9: LA | E9: 30382927 | F9: 1072167 | G9: =SUM(E9:F9) -> 31455094
A10: 2020 | B10: CADDO PARISH SCHOOL BOARD | C10: Louisiana | D10: LA | E10: 50314611 | F10: 1775526 | G10: =SUM(E10:F10) -> 52090137
A11: 2020 | B11: CALCASIEU PARISH SCHOOL SYSTEM | C11: Louisiana | D11: LA | E11: 50233172 | F11: 1772652 | G11: =SUM(E11:F11) -> 52005824
A12: 2020 | B12: CALDWELL PARISH SCHOOL BOARD | C12: Louisiana | D12: LA | E12: 2452234 | F12: 86536 | G12: =SUM(E12:F12) -> 2538770
A13: 2020 | B13: CAMERON PARISH SCHOOL BOARD | C13: Louisiana | D13: LA | E13: 2535532 | F13: 89475 | G13: =SUM(E13:F13) -> 2625007
... A226: 2020 | B226: DEPARTMENT OF ENVIRONMENTAL QUALITY | C226: Louisiana | D226: LA | E226: 43520 | F226: 1536 | G226: =SUM(E226:F226) -> 45056
D228: Summed Formula | E228: =SUM(E2:E226) -> 1222809471 | F228: =SUM(F2:F226) -> 43151075
D230: GASB 68 | E230: 1222809468 | F230: 43151074
D232: Check | E232: =E228-E230 -> 3 | F232: =F228-F230 -> 1

Sheet 2019
A1: Year | B1: district_name | C1: State | D1: state_abv | E1: district_contributions | F1: state_contributions | G1: total_contributions
A2: 2019 | B2: ACADIA PARISH SCHOOL BOARD | C2: Louisiana | D2: LA | E2: 10518018 | F2: 353001 | G2: =SUM(E2:F2) -> 10871019
A3: 2019 | B3: ALLEN PARISH SCHOOL BOARD | C3: Louisiana | D3: LA | E3: 5789396 | F3: 194301 | G3: =SUM(E3:F3) -> 5983697
A4: 2019 | B4: ASCENSION PARISH SCHOOL BOARD | C4: Louisiana | D4: LA | E4: 28236274 | F4: 947654 | G4: =SUM(E4:F4) -> 29183928
A5: 2019 | B5: ASSUMPTION PARISH SCHOOL BOARD | C5: Louisiana | D5: LA | E5: 4115279 | F5: 138115 | G5: =SUM(E5:F5) -> 4253394
A6: 2019 | B6: AVOYELLES PARISH SCHOOL BOARD | C6: Louisiana | D6: LA | E6: 4727405 | F6: 158659 | G6: =SUM(E6:F6) -> 4886064
A7: 2019 | B7: BEAUREGARD PARISH SCHOOL BOARD | C7: Louisiana | D7: LA | E7: 7191378 | F7: 241354 | G7: =SUM(E7:F7) -> 7432732
A8: 2019 | B8: BIENVILLE PARISH SCHOOL BOARD | C8: Louisiana | D8: LA | E8: 3864701 | F8: 129706 | G8: =SUM(E8:F8) -> 3994407
A9: 2019 | B9: BOSSIER PARISH SCHOOL BOARD | C9: Louisiana | D9: LA | E9: 30993559 | F9: 1040193 | G9: =SUM(E9:F9) -> 32033752
A10: 2019 | B10: CADDO PARISH SCHOOL BOARD | C10: Louisiana | D10: LA | E10: 51518092 | F10: 1729029 | G10: =SUM(E10:F10) -> 53247121
A11: 2019 | B11: CALCASIEU PARISH SCHOOL SYSTEM | C11: Louisiana | D11: LA | E11: 49325426 | F11: 1655440 | G11: =SUM(E11:F11) -> 50980866
A12: 2019 | B12: CALDWELL PARISH SCHOOL BOARD | C12: Louisiana | D12: LA | E12: 2443707 | F12: 82015 | G12: =SUM(E12:F12) -> 2525722
A13: 2019 | B13: CAMERON PARISH SCHOOL BOARD | C13: Louisiana | D13: LA | E13: 2533400 | F13: 85025 | G13: =SUM(E13:F13) -> 2618425
... A227: 2019 | B227: DEPARTMENT OF ENVIRONMENTAL QUALITY | C227: Louisiana | D227: LA | E227: 42869 | F227: 1439 | G227: =SUM(E227:F227) -> 44308
D229: Summed Formula | E229: =SUM(E2:E227) -> 1217167327 | F229: =SUM(F2:F227) -> 40850067
D231: GASB 68 | E231: 1217167321 | F231: 40850075
D233: Check | E233: =E229-E231 -> 6 | F233: =F229-F231 -> -8

Sheet 2018
A1: Year | B1: district_name | C1: State | D1: state_abv | E1: district_contributions | F1: state_contributions | G1: total_contributions
A2: 2018 | B2: ACADIA PARISH SCHOOL BOARD | C2: Louisiana | D2: LA | E2: 10948978 | F2: 360314 | G2: =SUM(E2:F2) -> 11309292
A3: 2018 | B3: ALLEN PARISH SCHOOL BOARD | C3: Louisiana | D3: LA | E3: 5839160 | F3: 192158 | G3: =SUM(E3:F3) -> 6031318
A4: 2018 | B4: ASCENSION PARISH SCHOOL BOARD | C4: Louisiana | D4: LA | E4: 29264545 | F4: 963050 | G4: =SUM(E4:F4) -> 30227595
A5: 2018 | B5: ASSUMPTION PARISH SCHOOL BOARD | C5: Louisiana | D5: LA | E5: 4711664 | F5: 155053 | G5: =SUM(E5:F5) -> 4866717
A6: 2018 | B6: AVOYELLES PARISH SCHOOL BOARD | C6: Louisiana | D6: LA | E6: 4885677 | F6: 160780 | G6: =SUM(E6:F6) -> 5046457
A7: 2018 | B7: BEAUREGARD PARISH SCHOOL BOARD | C7: Louisiana | D7: LA | E7: 7077309 | F7: 232903 | G7: =SUM(E7:F7) -> 7310212
A8: 2018 | B8: BIENVILLE PARISH SCHOOL BOARD | C8: Louisiana | D8: LA | E8: 4071149 | F8: 133975 | G8: =SUM(E8:F8) -> 4205124
A9: 2018 | B9: BOSSIER PARISH SCHOOL BOARD | C9: Louisiana | D9: LA | E9: 29144194 | F9: 959090 | G9: =SUM(E9:F9) -> 30103284
A10: 2018 | B10: CADDO PARISH SCHOOL BOARD | C10: Louisiana | D10: LA | E10: 52523572 | F10: 1728468 | G10: =SUM(E10:F10) -> 54252040
A11: 2018 | B11: CALCASIEU PARISH SCHOOL SYSTEM | C11: Louisiana | D11: LA | E11: 50343442 | F11: 1656724 | G11: =SUM(E11:F11) -> 52000166
A12: 2018 | B12: CALDWELL PARISH SCHOOL BOARD | C12: Louisiana | D12: LA | E12: 2406002 | F12: 79178 | G12: =SUM(E12:F12) -> 2485180
A13: 2018 | B13: CAMERON PARISH SCHOOL BOARD | C13: Louisiana | D13: LA | E13: 2515104 | F13: 82768 | G13: =SUM(E13:F13) -> 2597872
... A222: 2018 | B222: DEPARTMENT OF ENVIRONMENTAL QUALITY | C222: Louisiana | D222: LA | E222: 37834 | F222: 1245 | G222: =SUM(E222:F222) -> 39079
D224: Summed Formula | E224: =SUM(E2:E222) -> 1201829346 | F224: =SUM(F2:F222) -> 39550321
D226: GASB 68 | E226: 1201829353 | F226: 39550321
D228: Check | E228: =E224-E226 -> -7 | F228: =F224-F226 -> 0

Sheet 2017
A1: Year | B1: district_name | C1: State | D1: state_abv | E1: district_contributions | F1: state_contributions | G1: total_contributions
A2: 2017 | B2: ACADIA PARISH SCHOOL BOARD | C2: Louisiana | D2: LA | E2: 10430504 | F2: 360265 | G2: =SUM(E2:F2) -> 10790769
A3: 2017 | B3: ALLEN PARISH SCHOOL BOARD | C3: Louisiana | D3: LA | E3: 5774017 | F3: 199432 | G3: =SUM(E3:F3) -> 5973449
A4: 2017 | B4: ASCENSION PARISH SCHOOL BOARD | C4: Louisiana | D4: LA | E4: 28079867 | F4: 969866 | G4: =SUM(E4:F4) -> 29049733
A5: 2017 | B5: ASSUMPTION PARISH SCHOOL BOARD | C5: Louisiana | D5: LA | E5: 4761352 | F5: 164455 | G5: =SUM(E5:F5) -> 4925807
A6: 2017 | B6: AVOYELLES PARISH SCHOOL BOARD | C6: Louisiana | D6: LA | E6: 5042382 | F6: 174162 | G6: =SUM(E6:F6) -> 5216544
A7: 2017 | B7: BEAUREGARD PARISH SCHOOL BOARD | C7: Louisiana | D7: LA | E7: 7043133 | F7: 243267 | G7: =SUM(E7:F7) -> 7286400
A8: 2017 | B8: BIENVILLE PARISH SCHOOL BOARD | C8: Louisiana | D8: LA | E8: 3557003 | F8: 122857 | G8: =SUM(E8:F8) -> 3679860
A9: 2017 | B9: BOSSIER PARISH SCHOOL BOARD | C9: Louisiana | D9: LA | E9: 27135830 | F9: 937259 | G9: =SUM(E9:F9) -> 28073089
A10: 2017 | B10: CADDO PARISH SCHOOL BOARD | C10: Louisiana | D10: LA | E10: 48001046 | F10: 1657935 | G10: =SUM(E10:F10) -> 49658981
A11: 2017 | B11: CALCASIEU PARISH SCHOOL SYSTEM | C11: Louisiana | D11: LA | E11: 46800725 | F11: 1616476 | G11: =SUM(E11:F11) -> 48417201
A12: 2017 | B12: CALDWELL PARISH SCHOOL BOARD | C12: Louisiana | D12: LA | E12: 2334528 | F12: 80634 | G12: =SUM(E12:F12) -> 2415162
A13: 2017 | B13: CAMERON PARISH SCHOOL BOARD | C13: Louisiana | D13: LA | E13: 2337132 | F13: 80723 | G13: =SUM(E13:F13) -> 2417855
... A227: 2017 | B227: DEPARTMENT OF ENVIRONMENTAL QUALITY | C227: Louisiana | D227: LA | E227: 36059 | F227: 1245 | G227: =SUM(E227:F227) -> 37304
D229: Summed Formula | E229: =SUM(E2:E227) -> 1122277560 | F229: =SUM(F2:F227) -> 38762964
D231: GASB 68 | E231: 1122277562 | F231: 38762968
D233: Check | E233: =E229-E231 -> -2 | F233: =F229-F231 -> -4

Sheet 2016
A1: Year | B1: district_name | C1: State | D1: state_abv | E1: district_contributions | F1: state_contributions | G1: total_contributions
A2: 2016 | B2: ACADIA PARISH SCHOOL BOARD | C2: Louisiana | D2: LA | E2: 11118421 | F2: 366741 | G2: =SUM(E2:F2) -> 11485162
A3: 2016 | B3: ALLEN PARISH SCHOOL BOARD | C3: Louisiana | D3: LA | E3: 6162176 | F3: 203259 | G3: =SUM(E3:F3) -> 6365435
A4: 2016 | B4: ASCENSION PARISH SCHOOL BOARD | C4: Louisiana | D4: LA | E4: 28606364 | F4: 943580 | G4: =SUM(E4:F4) -> 29549944
A5: 2016 | B5: ASSUMPTION PARISH SCHOOL BOARD | C5: Louisiana | D5: LA | E5: 5216692 | F5: 172072 | G5: =SUM(E5:F5) -> 5388764
A6: 2016 | B6: AVOYELLES PARISH SCHOOL BOARD | C6: Louisiana | D6: LA | E6: 5282333 | F6: 174238 | G6: =SUM(E6:F6) -> 5456571
A7: 2016 | B7: BEAUREGARD PARISH SCHOOL BOARD | C7: Louisiana | D7: LA | E7: 7753144 | F7: 255737 | G7: =SUM(E7:F7) -> 8008881
A8: 2016 | B8: BIENVILLE PARISH SCHOOL BOARD | C8: Louisiana | D8: LA | E8: 3782215 | F8: 124756 | G8: =SUM(E8:F8) -> 3906971
A9: 2016 | B9: BOSSIER PARISH SCHOOL BOARD | C9: Louisiana | D9: LA | E9: 27129102 | F9: 894852 | G9: =SUM(E9:F9) -> 28023954
A10: 2016 | B10: CADDO PARISH SCHOOL BOARD | C10: Louisiana | D10: LA | E10: 51076709 | F10: 1684763 | G10: =SUM(E10:F10) -> 52761472
A11: 2016 | B11: CALCASIEU PARISH SCHOOL SYSTEM | C11: Louisiana | D11: LA | E11: 47228737 | F11: 1557838 | G11: =SUM(E11:F11) -> 48786575
A12: 2016 | B12: CALDWELL PARISH SCHOOL BOARD | C12: Louisiana | D12: LA | E12: 2504447 | F12: 82609 | G12: =SUM(E12:F12) -> 2587056
A13: 2016 | B13: CAMERON PARISH SCHOOL BOARD | C13: Louisiana | D13: LA | E13: 2494999 | F13: 82297 | G13: =SUM(E13:F13) -> 2577296
... A227: 2016 | B227: OFFICE OF ENVIRONMENTAL SERVICES | C227: Louisiana | D227: LA | E227: 14080 | F227: 464 | G227: =SUM(E227:F227) -> 14544
D229: Summed Formula | E229: =SUM(E2:E227) -> 1157901121 | F229: =SUM(F2:F227) -> 38193321
D231: GASB 68 | E231: 1157901123 | F231: 38193328
D233: Check | E233: =E229-E231 -> -2 | F233: =F229-F231 -> -7

Sheet 2015
A1: Year | B1: district_name | C1: State | D1: state_abv | E1: district_contributions | F1: state_contributions | G1: total_contributions
A2: 2015 | B2: ACADIA PARISH SCHOOL BOARD | C2: Louisiana | D2: LA | E2: 11893931 | F2: 365626 | G2: =SUM(E2:F2) -> 12259557
A3: 2015 | B3: ALLEN PARISH SCHOOL BOARD | C3: Louisiana | D3: LA | E3: 6527825 | F3: 200669 | G3: =SUM(E3:F3) -> 6728494
A4: 2015 | B4: ASCENSION PARISH SCHOOL BOARD | C4: Louisiana | D4: LA | E4: 29287391 | F4: 900311 | G4: =SUM(E4:F4) -> 30187702
A5: 2015 | B5: ASSUMPTION PARISH SCHOOL BOARD | C5: Louisiana | D5: LA | E5: 5521991 | F5: 169749 | G5: =SUM(E5:F5) -> 5691740
A6: 2015 | B6: AVOYELLES PARISH SCHOOL BOARD | C6: Louisiana | D6: LA | E6: 5695760 | F6: 175091 | G6: =SUM(E6:F6) -> 5870851
A7: 2015 | B7: BEAUREGARD PARISH SCHOOL BOARD | C7: Louisiana | D7: LA | E7: 7847583 | F7: 241239 | G7: =SUM(E7:F7) -> 8088822
A8: 2015 | B8: BIENVILLE PARISH SCHOOL BOARD | C8: Louisiana | D8: LA | E8: 4195293 | F8: 128966 | G8: =SUM(E8:F8) -> 4324259
A9: 2015 | B9: BOSSIER PARISH SCHOOL BOARD | C9: Louisiana | D9: LA | E9: 27664812 | F9: 850432 | G9: =SUM(E9:F9) -> 28515244
A10: 2015 | B10: CADDO PARISH SCHOOL BOARD | C10: Louisiana | D10: LA | E10: 56216232 | F10: 1728119 | G10: =SUM(E10:F10) -> 57944351
A11: 2015 | B11: CALCASIEU PARISH SCHOOL SYSTEM | C11: Louisiana | D11: LA | E11: 45774896 | F11: 1407147 | G11: =SUM(E11:F11) -> 47182043
A12: 2015 | B12: CALDWELL PARISH SCHOOL BOARD | C12: Louisiana | D12: LA | E12: 2609262 | F12: 80210 | G12: =SUM(E12:F12) -> 2689472
A13: 2015 | B13: CAMERON PARISH SCHOOL BOARD | C13: Louisiana | D13: LA | E13: 2751523 | F13: 84583 | G13: =SUM(E13:F13) -> 2836106
... A226: 2015 | B226: OFFICE OF ENVIRONMENTAL SERVICES | C226: Louisiana | D226: LA | E226: 14476 | F226: 445 | G226: =SUM(E226:F226) -> 14921
D228: Summed Formula | E228: =SUM(E2:E226) -> 1217466677 | F228: =SUM(F2:F226) -> 37425628
D230: GASB 68 | E230: 1217466676 | F230: 37425629
D232: Check | E232: =E228-E230 -> 1 | F232: =F228-F230 -> -1

Sheet NCES Match -->

Sheet LEAIDs
A1: district_name
A2: LA SCH FOR THE DEAF & VISUALLY IMPAIRED | B2: 2200018
A3: ACADIA PARISH SCHOOL BOARD | B3: 2200030
A4: AVOYELLES PUBLIC CHARTER SCHOOL INC. | B4: 2200035
A5: DELHI CHARTER SCHOOL | B5: 2200038
A6: ZACHARY COMMUNITY SCHOOL BOARD | B6: 2200039
A7: CITY OF BAKER SCHOOL SYSTEM | B7: 2200040
A8: OFFICE OF JUVENILE JUSTICE | B8: 2200047
A9: RECOVERY SCHOOL DISTRICT OF LOUISIANA | B9: 2200054
A10: A. E. PHILLIPS LABORATORY SCHOOL | B10: 2200056
A11: ALLEN PARISH SCHOOL BOARD | B11: 2200060
A12: ASCENSION PARISH SCHOOL BOARD | B12: 2200090
A13: ASSUMPTION PARISH SCHOOL BOARD | B13: 2200120
... A90: SPECIAL SCHOOL DISTRICTS | B90: 2280100
A91: ACADIANA AREA HUMAN SERVICES DISTRICT
A92: ADVOCATES FOR ACADEMIC EXCELLENCE
A93: ADVOCATES FOR ARTS - BASED EDUCATION CORP
A94: ADVOCATES FOR ARTS-BASED EDUCATION CORP
A95: ADVOCATES FOR INNOVATIVE SCHOOLS
A96: ADVOCATES FOR SCIENCE & MATHEMATICS EDUC
A97: ALGIERS CHARTER SCHOOLS ASSOCIATION | B97: 2200053
A98: ALMA J. BROWN/GRAMBLING LAB SCHOOL
A99: ASSOCIATED PROFESSIONAL EDUCATORS OF LA
A100: AVOYELLES CORRECTIONAL CENTER
A101: BATON ROUGE COMMUNITY COLLEGE
A102: BAYOU COMMUNITY ACADEMY
A103: BEEKMAN CHARTER SCHOOL
A104: BOARD OF ELEMENTARY & SECONDARY EDUC/DOA
A105: BOARD OF REGENTS
A106: BOARD OF SUPERVISORS - UNIV. OF LA SYSTEM
A107: BOARD OF SUPERVISORS-UNIV. OF LA SYSTEM
A108: BOGALUSA CITY SCHOOLS | B108: 2200240
A109: BOSSIER PARISH COMMUNITY COLLEGE
A110: CAPITAL AREA HUMAN SERVICE DISTRICT
A111: CENTRAL COMMUNITY SCHOOL SYSTEM | B111: 2200125
A112: CENTRAL LA TECHNICAL COMMUNITY COLLEGE
A113: CENTRAL LOUISIANA HUMAN SERVICE DISTRICT
A114: CRT - OFFICE OF STATE PARKS
A115: CRT - OFFICE OF THE SECRETARY
A116: CRT--OFFICE OF STATE PARKS
...
