Workbook

Sheet Summary
A1: LEAID | B1: Year | C1: employer_code | D1: standardized_employer_name | E1: employer_name | F1: present_value_contribution_effort | G1: allocation_percentage | H1: district_contributions | I1: LEAID_match
A2: =I2 | B2: 2015 | C2: 1000 | D2: State Agencies | E2: State Agencies | F2: 3497778764 | G2: 0.25469773 | H2: 2.8610196e+08 | I2: =IFERROR(VLOOKUP(D2,'LEAID Match'!$A$2:$B$186,2,FALSE),"")
A3: =I3 | B3: 2016 | C3: 1000 | D3: State Agencies | E3: State Agencies | F3: 5172948025 | G3: 0.26819654 | H3: 2.6210847e+08 | I3: =IFERROR(VLOOKUP(D3,'LEAID Match'!$A$2:$B$186,2,FALSE),"")
A4: =I4 | B4: 2017 | C4: 1000 | D4: State Agencies | E4: State Agencies | F4: 6476229494 | G4: 0.27356708 | H4: 2.7964027e+08 | I4: =IFERROR(VLOOKUP(D4,'LEAID Match'!$A$2:$B$186,2,FALSE),"")
A5: =I5 | B5: 2018 | C5: 1000 | D5: State Agencies | E5: State Agencies | F5: 7579476074 | G5: 0.26998682 | H5: 3.7530868e+08 | I5: =IFERROR(VLOOKUP(D5,'LEAID Match'!$A$2:$B$186,2,FALSE),"")
A6: =I6 | B6: 2019 | C6: 1000 | D6: State Agencies | E6: State Agencies | F6: 7026314679 | G6: 0.28372325 | H6: 4.8806074e+08 | I6: =IFERROR(VLOOKUP(D6,'LEAID Match'!$A$2:$B$186,2,FALSE),"")
A7: =I7 | B7: 2020 | C7: 1000 | D7: State Agencies | E7: State Agencies | F7: 8674749125 | G7: 0.28358073 | H7: 6.519521e+08 | I7: =IFERROR(VLOOKUP(D7,'LEAID Match'!$A$2:$B$186,2,FALSE),"")
A8: =I8 | B8: 2021 | C8: 1000 | D8: State Agencies | E8: State Agencies | F8: 7830869115 | G8: 0.27242175 | H8: 5.8883962e+08 | I8: =IFERROR(VLOOKUP(D8,'LEAID Match'!$A$2:$B$186,2,FALSE),"")
A9: =I9 | B9: 2022 | C9: 1000 | D9: State Agencies | E9: State Agencies | F9: 9806668763 | G9: 0.2946182 | H9: 1.1873703e+09 | I9: =IFERROR(VLOOKUP(D9,'LEAID Match'!$A$2:$B$186,2,FALSE),"")
A10: =I10 | B10: 2023 | C10: 1000 | D10: State Agencies | E10: State Agencies | F10: 7585792772 | G10: 0.29838807 | H10: 7.1401282e+08 | I10: =IFERROR(VLOOKUP(D10,'LEAID Match'!$A$2:$B$186,2,FALSE),"")
A11: =I11 | B11: 2020 | C11: 1039 | D11: SAIF | E11: SAIF | F11: 116240899 | G11: 0.0037999577 | H11: 8736102.8 | I11: =IFERROR(VLOOKUP(D11,'LEAID Match'!$A$2:$B$186,2,FALSE),"")
A12: =I12 | B12: 2021 | C12: 1039 | D12: SAIF | E12: SAIF | F12: 106468385 | G12: 0.0037038423 | H12: 8005855.1 | I12: =IFERROR(VLOOKUP(D12,'LEAID Match'!$A$2:$B$186,2,FALSE),"")
A13: =I13 | B13: 2022 | C13: 1039 | D13: SAIF | E13: SAIF | F13: 157983551 | G13: 0.0047462427 | H13: 19128307 | I13: =IFERROR(VLOOKUP(D13,'LEAID Match'!$A$2:$B$186,2,FALSE),"")
... A209: =I209 -> 4108520 | B209: 2015 | C209: 2023 | D209: Morrow County Rural School District Board | E209: Morrow County Rural School District Board | F209: 1579 | G209: 1.15e-07 | H209: 129.1795 | I209: =IFERROR(VLOOKUP(D209,'LEAID Match'!$A$2:$B$186,2,FALSE),"") -> 4108520
A210: =I210 -> 4108520 | B210: 2016 | C210: 2023 | D210: Morrow County Rural School District Board | E210: Morrow County Rural School District Board | F210: - | G210: 0 | H210: 0 | I210: =IFERROR(VLOOKUP(D210,'LEAID Match'!$A$2:$B$186,2,FALSE),"") -> 4108520
A211: =I211 -> 4108520 | B211: 2017 | C211: 2023 | D211: Morrow County Rural School District Board | E211: Morrow County Rural School District Board | F211: - | G211: 0 | H211: 0 | I211: =IFERROR(VLOOKUP(D211,'LEAID Match'!$A$2:$B$186,2,FALSE),"") -> 4108520
A212: =I212 -> 4108520 | B212: 2018 | C212: 2023 | D212: Morrow County Rural School District Board | E212: Morrow County Rural School District Board | F212: - | G212: 0 | H212: 0 | I212: =IFERROR(VLOOKUP(D212,'LEAID Match'!$A$2:$B$186,2,FALSE),"") -> 4108520
A213: =I213 -> 4108520 | B213: 2019 | C213: 2023 | D213: Morrow County Rural School District Board | E213: Morrow County Rural School District Board | F213: - | G213: 0 | H213: 0 | I213: =IFERROR(VLOOKUP(D213,'LEAID Match'!$A$2:$B$186,2,FALSE),"") -> 4108520
A214: =I214 -> 4108520 | B214: 2020 | C214: 2023 | D214: Morrow County Rural School District Board | E214: Morrow County Rural School District Board | F214: - | G214: 0 | H214: 0 | I214: =IFERROR(VLOOKUP(D214,'LEAID Match'!$A$2:$B$186,2,FALSE),"") -> 4108520
A215: =I215 -> 4108520 | B215: 2021 | C215: 2023 | D215: Morrow County Rural School District Board | E215: Morrow County Rural School District Board | F215: - | G215: 0 | H215: 0 | I215: =IFERROR(VLOOKUP(D215,'LEAID Match'!$A$2:$B$186,2,FALSE),"") -> 4108520
A216: =I216 -> 4108520 | B216: 2022 | C216: 2023 | D216: Morrow County Rural School District Board | E216: Morrow County Rural School District Board | F216: - | G216: 0 | H216: 0 | I216: =IFERROR(VLOOKUP(D216,'LEAID Match'!$A$2:$B$186,2,FALSE),"") -> 4108520
A217: =I217 -> 4108520 | B217: 2023 | C217: 2023 | D217: Morrow County Rural School District Board | E217: Morrow County Rural School District Board | G217: 0 | H217: 0 | I217: =IFERROR(VLOOKUP(D217,'LEAID Match'!$A$2:$B$186,2,FALSE),"") -> 4108520
A218: =I218 | B218: 2015 | C218: 2027 | D218: Deschutes County | E218: Deschutes County | F218: 88461643 | G218: 0.0064415108 | H218: 7235749.1 | I218: =IFERROR(VLOOKUP(D218,'LEAID Match'!$A$2:$B$186,2,FALSE),"")
A219: =I219 | B219: 2016 | C219: 2027 | D219: Deschutes County | E219: Deschutes County | F219: 119989926 | G219: 0.0062209947 | H219: 6079778.1 | I219: =IFERROR(VLOOKUP(D219,'LEAID Match'!$A$2:$B$186,2,FALSE),"")
A220: =I220 | B220: 2017 | C220: 2027 | D220: Deschutes County | E220: Deschutes County | F220: 147352403 | G220: 0.0062244192 | H220: 6362601.3 | I220: =IFERROR(VLOOKUP(D220,'LEAID Match'!$A$2:$B$186,2,FALSE),"")
A221: =I221 | B221: 2018 | C221: 2027 | D221: Deschutes County | E221: Deschutes County | F221: 177606348 | G221: 0.0063264759 | H221: 8794434.1 | I221: =IFERROR(VLOOKUP(D221,'LEAID Match'!$A$2:$B$186,2,FALSE),"")
A222: =I222 | B222: 2019 | C222: 2027 | D222: Deschutes County | E222: Deschutes County | F222: 164242850 | G222: 0.0066321419 | H222: 11408610 | I222: =IFERROR(VLOOKUP(D222,'LEAID Match'!$A$2:$B$186,2,FALSE),"")
A223: =I223 | B223: 2020 | C223: 2027 | D223: Deschutes County | E223: Deschutes County | F223: 196137224 | G223: 0.0064117978 | H223: 14740723 | I223: =IFERROR(VLOOKUP(D223,'LEAID Match'!$A$2:$B$186,2,FALSE),"")
A224: =I224 | B224: 2021 | C224: 2027 | D224: Deschutes County | E224: Deschutes County | F224: 191649240 | G224: 0.0066671299 | H224: 14411001 | I224: =IFERROR(VLOOKUP(D224,'LEAID Match'!$A$2:$B$186,2,FALSE),"")
A225: =I225 | B225: 2022 | C225: 2027 | D225: Deschutes County | E225: Deschutes County | F225: 243115709 | G225: 0.0073038373 | H225: 29435925 | I225: =IFERROR(VLOOKUP(D225,'LEAID Match'!$A$2:$B$186,2,FALSE),"")
A226: =I226 | B226: 2023 | C226: 2027 | D226: Deschutes County | E226: Deschutes County | F226: 193878274 | G226: 0.0076262253 | H226: 18248795 | I226: =IFERROR(VLOOKUP(D226,'LEAID Match'!$A$2:$B$186,2,FALSE),"")
A227: =I227 | B227: 2015 | C227: 2028 | D227: Union County | E227: Union County | F227: - | G227: 0 | H227: 0 | I227: =IFERROR(VLOOKUP(D227,'LEAID Match'!$A$2:$B$186,2,FALSE),"")
A228: =I228 | B228: 2016 | C228: 2028 | D228: Union County | E228: Union County | F228: - | G228: 0 | H228: 0 | I228: =IFERROR(VLOOKUP(D228,'LEAID Match'!$A$2:$B$186,2,FALSE),"")
A229: =I229 | B229: 2017 | C229: 2028 | D229: Union County | E229: Union County | F229: - | G229: 0 | H229: 0 | I229: =IFERROR(VLOOKUP(D229,'LEAID Match'!$A$2:$B$186,2,FALSE),"")
A230: =I230 | B230: 2018 | C230: 2028 | D230: Union County | E230: Union County | F230: - | G230: 0 | H230: 0 | I230: =IFERROR(VLOOKUP(D230,'LEAID Match'!$A$2:$B$186,2,FALSE),"")
A231: =I231 | B231: 2019 | C231: 2028 | D231: Union County | E231: Union County | F231: - | G231: 0 | H231: 0 | I231: =IFERROR(VLOOKUP(D231,'LEAID Match'!$A$2:$B$186,2,FALSE),"")
A232: =I232 | B232: 2020 | C232: 2028 | D232: Union County | E232: Union County | F232: - | G232: 0 | H232: 0 | I232: =IFERROR(VLOOKUP(D232,'LEAID Match'!$A$2:$B$186,2,FALSE),"")
A233: =I233 | B233: 2021 | C233: 2028 | D233: Union County | E233: Union County | F233: - | G233: 0 | H233: 0 | I233: =IFERROR(VLOOKUP(D233,'LEAID Match'!$A$2:$B$186,2,FALSE),"")
A234: =I234 | B234: 2022 | C234: 2028 | D234: Union County | E234: Union County | F234: - | G234: 0 | H234: 0 | I234: =IFERROR(VLOOKUP(D234,'LEAID Match'!$A$2:$B$186,2,FALSE),"")
A235: =I235 | B235: 2023 | C235: 2028 | D235: Union County | E235: Union County | G235: 0 | H235: 0 | I235: =IFERROR(VLOOKUP(D235,'LEAID Match'!$A$2:$B$186,2,FALSE),"")
...

Sheet GASB Data -->

Sheet GASB Data
A1: year | B1: employer_id | C1: standardized_employer_name | D1: employer_name | E1: present_value_contribution_effort | F1: allocation_percentage | G1: employer_contribution
A2: 2015 | B2: 1000 | C2: State Agencies | D2: State Agencies | E2: 3497778764 | F2: 0.25469773 | G2: =F2* VLOOKUP(A2,'GASB 67 Employer Contributions'!$A$1:$B$10,2,FALSE) -> 2.8610196e+08
A3: 2015 | B3: 2000 | C3: Lake County | D3: Lake County | E3: 6208561 | F3: 0.0004520887 | G3: =F3* VLOOKUP(A3,'GASB 67 Employer Contributions'!$A$1:$B$10,2,FALSE) -> 507831.24
A4: 2015 | B4: 2001 | C4: Clackamas County | D4: Clackamas County | E4: 261952370 | F4: 0.019074584 | G4: =F4* VLOOKUP(A4,'GASB 67 Employer Contributions'!$A$1:$B$10,2,FALSE) -> 21426480
A5: 2015 | B5: 2002 | C5: Curry County | D5: Curry County | E5: 13046246 | F5: 0.0009499884 | G5: =F5* VLOOKUP(A5,'GASB 67 Employer Contributions'!$A$1:$B$10,2,FALSE) -> 1067122
A6: 2015 | B6: 2003 | C6: Douglas County | D6: Douglas County | E6: 93772610 | F6: 0.0068282395 | G6: =F6* VLOOKUP(A6,'GASB 67 Employer Contributions'!$A$1:$B$10,2,FALSE) -> 7670161.4
A7: 2015 | B7: 2004 | C7: Harney County | D7: Harney County | E7: 6642790 | F7: 0.000483708 | G7: =F7* VLOOKUP(A7,'GASB 67 Employer Contributions'!$A$1:$B$10,2,FALSE) -> 543349.2
A8: 2015 | B8: 2005 | C8: Jackson County | D8: Jackson County | E8: 85961614 | F8: 0.0062594662 | G8: =F8* VLOOKUP(A8,'GASB 67 Employer Contributions'!$A$1:$B$10,2,FALSE) -> 7031258.4
A9: 2015 | B9: 2006 | C9: Jefferson County | D9: Jefferson County | E9: 9035489 | F9: 0.0006579371 | G9: =F9* VLOOKUP(A9,'GASB 67 Employer Contributions'!$A$1:$B$10,2,FALSE) -> 739060.74
A10: 2015 | B10: 2007 | C10: Klamath County | D10: Klamath County | E10: 3089694 | F10: 0.0002249822 | G10: =F10* VLOOKUP(A10,'GASB 67 Employer Contributions'!$A$1:$B$10,2,FALSE) -> 252722.51
A11: 2015 | B11: 2008 | C11: Lane County | D11: Lane County | E11: 152180191 | F11: 0.011081304 | G11: =F11* VLOOKUP(A11,'GASB 67 Employer Contributions'!$A$1:$B$10,2,FALSE) -> 12447629
A12: 2015 | B12: 2009 | C12: Marion County | D12: Marion County | E12: 110864996 | F12: 0.0080728556 | G12: =F12* VLOOKUP(A12,'GASB 67 Employer Contributions'!$A$1:$B$10,2,FALSE) -> 9068238.7
A13: 2015 | B13: 2011 | C13: Washington County | D13: Washington County | E13: 247701477 | F13: 0.018036877 | G13: =F13* VLOOKUP(A13,'GASB 67 Employer Contributions'!$A$1:$B$10,2,FALSE) -> 20260823
... A25: 2015 | B25: 2027 | C25: Deschutes County | D25: Deschutes County | E25: 88461643 | F25: 0.0064415108 | G25: =F25* VLOOKUP(A25,'GASB 67 Employer Contributions'!$A$1:$B$10,2,FALSE) -> 7235749.1
A26: 2015 | B26: 2028 | C26: Union County | D26: Union County | E26: - | F26: 0 | G26: =F26* VLOOKUP(A26,'GASB 67 Employer Contributions'!$A$1:$B$10,2,FALSE) -> 0
A27: 2015 | B27: 2035 | C27: Hood River County | D27: Hood River County | E27: 6307354 | F27: 0.0004592826 | G27: =F27* VLOOKUP(A27,'GASB 67 Employer Contributions'!$A$1:$B$10,2,FALSE) -> 515912.14
A28: 2015 | B28: 2036 | C28: Clatsop County | D28: Clatsop County | E28: 17344164 | F28: 0.0012629499 | G28: =F28* VLOOKUP(A28,'GASB 67 Employer Contributions'!$A$1:$B$10,2,FALSE) -> 1418671.6
A29: 2015 | B29: 2037 | C29: Polk County | D29: Polk County | E29: 29000776 | F29: 0.0021117493 | G29: =F29* VLOOKUP(A29,'GASB 67 Employer Contributions'!$A$1:$B$10,2,FALSE) -> 2372128
A30: 2015 | B30: 2038 | C30: Multnomah County | D30: Multnomah County | E30: 493038625 | F30: 0.03590159 | G30: =F30* VLOOKUP(A30,'GASB 67 Employer Contributions'!$A$1:$B$10,2,FALSE) -> 40328256
A31: 2015 | B31: 2039 | C31: Malheur County | D31: Malheur County | E31: 9676082 | F31: 0.0007045832 | G31: =F31* VLOOKUP(A31,'GASB 67 Employer Contributions'!$A$1:$B$10,2,FALSE) -> 791458.31
A32: 2015 | B32: 2040 | C32: Benton County | D32: Benton County | E32: 32210762 | F32: 0.0023454908 | G32: =F32* VLOOKUP(A32,'GASB 67 Employer Contributions'!$A$1:$B$10,2,FALSE) -> 2634689.8
A33: 2015 | B33: 2042 | C33: Josephine County | D33: Josephine County | E33: 27408454 | F33: 0.0019958012 | G33: =F33* VLOOKUP(A33,'GASB 67 Employer Contributions'!$A$1:$B$10,2,FALSE) -> 2241883.5
A34: 2015 | B34: 2043 | C34: Lincoln County | D34: Lincoln County | E34: 7008182 | F34: 0.0005103147 | G34: =F34* VLOOKUP(A34,'GASB 67 Employer Contributions'!$A$1:$B$10,2,FALSE) -> 573236.5
A35: 2015 | B35: 2044 | C35: Crook County | D35: Crook County | E35: 1928111 | F35: 0.0001403992 | G35: =F35* VLOOKUP(A35,'GASB 67 Employer Contributions'!$A$1:$B$10,2,FALSE) -> 157710.42
A36: 2015 | B36: 2050 | C36: Wallowa County | D36: Wallowa County | E36: 178902 | F36: 1.30271e-05 | G36: =F36* VLOOKUP(A36,'GASB 67 Employer Contributions'!$A$1:$B$10,2,FALSE) -> 14633.341
A37: 2015 | B37: 2052 | C37: Tillamook County | D37: Tillamook County | E37: 17337 | F37: 1.2624e-06 | G37: =F37* VLOOKUP(A37,'GASB 67 Employer Contributions'!$A$1:$B$10,2,FALSE) -> 1418.0539
A38: 2015 | B38: 2099 | C38: State Judiciary | D38: State Judiciary | E38: 22330578 | F38: 0.0016260455 | G38: =F38* VLOOKUP(A38,'GASB 67 Employer Contributions'!$A$1:$B$10,2,FALSE) -> 1826536.9
... A64: 2015 | B64: 2128 | C64: City of Tillamook | D64: City of Tillamook | E64: 3557280 | F64: 0.0002590304 | G64: =F64* VLOOKUP(A64,'GASB 67 Employer Contributions'!$A$1:$B$10,2,FALSE) -> 290968.85
A65: 2015 | B65: 2129 | C65: City of Sweet Home | D65: City of Sweet Home | E65: - | F65: 0 | G65: =F65* VLOOKUP(A65,'GASB 67 Employer Contributions'!$A$1:$B$10,2,FALSE) -> 0
A66: 2015 | B66: 2131 | C66: City of Drain | D66: City of Drain | E66: 1028329 | F66: 7.48798e-05 | G66: =F66* VLOOKUP(A66,'GASB 67 Employer Contributions'!$A$1:$B$10,2,FALSE) -> 84112.479
A67: 2015 | B67: 2132 | C67: Eugene Water & Electric Board | D67: Eugene Water & Electric Board | E67: 108835121 | F67: 0.0079250462 | G67: =F67* VLOOKUP(A67,'GASB 67 Employer Contributions'!$A$1:$B$10,2,FALSE) -> 8902204.4
A68: 2015 | B68: 2138 | C68: City of Hood River | D68: City of Hood River | E68: 7339286 | F68: 0.0005344247 | G68: =F68* VLOOKUP(A68,'GASB 67 Employer Contributions'!$A$1:$B$10,2,FALSE) -> 600319.27
A69: 2015 | B69: 2139 | C69: City of Reedsport | D69: City of Reedsport | E69: 1108238 | F69: 8.06986e-05 | G69: =F69* VLOOKUP(A69,'GASB 67 Employer Contributions'!$A$1:$B$10,2,FALSE) -> 90648.737
A70: 2015 | B70: 2140 | C70: City of Lebanon | D70: City of Lebanon | E70: 9363904 | F70: 0.0006818513 | G70: =F70* VLOOKUP(A70,'GASB 67 Employer Contributions'!$A$1:$B$10,2,FALSE) -> 765923.57
A71: 2015 | B71: 2142 | C71: City of Sherwood | D71: City of Sherwood | E71: 12394434 | F71: 0.0009025254 | G71: =F71* VLOOKUP(A71,'GASB 67 Employer Contributions'!$A$1:$B$10,2,FALSE) -> 1013806.8
A72: 2015 | B72: 2143 | C72: City of Oakland | D72: City of Oakland | E72: 316050 | F72: 2.30138e-05 | G72: =F72* VLOOKUP(A72,'GASB 67 Employer Contributions'!$A$1:$B$10,2,FALSE) -> 25851.402
A73: 2015 | B73: 2145 | C73: City of Vale | D73: City of Vale | E73: 740235 | F73: 5.39017e-05 | G73: =F73* VLOOKUP(A73,'GASB 67 Employer Contributions'!$A$1:$B$10,2,FALSE) -> 60547.78
A74: 2015 | B74: 2146 | C74: City of Prineville | D74: City of Prineville | E74: 7030092 | F74: 0.0005119102 | G74: =F74* VLOOKUP(A74,'GASB 67 Employer Contributions'!$A$1:$B$10,2,FALSE) -> 575028.73
A75: 2015 | B75: 2147 | C75: City of Wheeler | D75: City of Wheeler | E75: 254978 | F75: 1.85667e-05 | G75: =F75* VLOOKUP(A75,'GASB 67 Employer Contributions'!$A$1:$B$10,2,FALSE) -> 20855.974
A76: 2015 | B76: 2148 | C76: City of Klamath Falls | D76: City of Klamath Falls | E76: 12449193 | F76: 0.0009065128 | G76: =F76* VLOOKUP(A76,'GASB 67 Employer Contributions'!$A$1:$B$10,2,FALSE) -> 1018285.8
...

Sheet Final Check
A1: Year | B1: Employer PV Total Reported | C1: Employer PV Total from Formula | D1: Reported Allocation Percentage Total | E1: Allocation Percentage Total from Formula | F1: Employer Contribution Reported | G1: Employer Contribution from Formula | H1: Employer PV Difference | I1: Allocation Percentage Difference | J1: Employer Contribution Difference
A2: 2015 | B2: 13733058223 | C2: =SUMIF(Summary!B:B,'Final Check'!A2,Summary!F:F) -> 13733058223 | D2: 1 | E2: =SUMIF(Summary!B:B,'Final Check'!A2,Summary!G:G) -> 1 | F2: 1123300000 | G2: =SUMIF(Summary!B:B,'Final Check'!A2,Summary!H:H) -> 1.1233e+09 | H2: =B2-C2 -> 0 | I2: =D2-E2 -> -1.9999802e-10 | J2: =F2-G2 -> -0.22465968
A3: 2016 | B3: 19287900237 | C3: =SUMIF(Summary!B:B,'Final Check'!A3,Summary!F:F) -> 19287900237 | D3: 1 | E3: =SUMIF(Summary!B:B,'Final Check'!A3,Summary!G:G) -> 1 | F3: 977300000 | G3: =SUMIF(Summary!B:B,'Final Check'!A3,Summary!H:H) -> 9.773e+08 | H3: =B3-C3 -> 0 | I3: =D3-E3 -> -1.1000014e-09 | J3: =F3-G3 -> -1.075031
A4: 2017 | B4: 23673277639 | C4: =SUMIF(Summary!B:B,'Final Check'!A4,Summary!F:F) -> 23673277639 | D4: 1 | E4: =SUMIF(Summary!B:B,'Final Check'!A4,Summary!G:G) -> 1 | F4: 1022200000 | G4: =SUMIF(Summary!B:B,'Final Check'!A4,Summary!H:H) -> 1.0222e+09 | H4: =B4-C4 -> 0 | I4: =D4-E4 -> -9.0000163e-10 | J4: =F4-G4 -> -0.91997957
A5: 2018 | B5: 28073504157 | C5: =SUMIF(Summary!B:B,'Final Check'!A5,Summary!F:F) -> 28073504157 | D5: 1 | E5: =SUMIF(Summary!B:B,'Final Check'!A5,Summary!G:G) -> 1 | F5: 1390100000 | G5: =SUMIF(Summary!B:B,'Final Check'!A5,Summary!H:H) -> 1.3901e+09 | H5: =B5-C5 -> 0 | I5: =D5-E5 -> 3.9999948e-10 | J5: =F5-G5 -> 0.55603981
A6: 2019 | B6: 24764676763 | C6: =SUMIF(Summary!B:B,'Final Check'!A6,Summary!F:F) -> 24764676763 | D6: 1 | E6: =SUMIF(Summary!B:B,'Final Check'!A6,Summary!G:G) -> 1 | F6: 1720200000 | G6: =SUMIF(Summary!B:B,'Final Check'!A6,Summary!H:H) -> 1.7202e+09 | H6: =B6-C6 -> 0 | I6: =D6-E6 -> -3.0000069e-10 | J6: =F6-G6 -> -0.51605844
A7: 2020 | B7: 30590051173 | C7: =SUMIF(Summary!B:B,'Final Check'!A7,Summary!F:F) -> 30590051173 | D7: 1 | E7: =SUMIF(Summary!B:B,'Final Check'!A7,Summary!G:G) -> 1 | F7: 2299000000 | G7: =SUMIF(Summary!B:B,'Final Check'!A7,Summary!H:H) -> 2.299e+09 | H7: =B7-C7 -> 0 | I7: =D7-E7 -> -9.9999342e-11 | J7: =F7-G7 -> -0.22990179
A8: 2021 | B8: 28745388516 | C8: =SUMIF(Summary!B:B,'Final Check'!A8,Summary!F:F) -> 28745388517 | D8: 1 | E8: =SUMIF(Summary!B:B,'Final Check'!A8,Summary!G:G) -> 1 | F8: 2161500000 | G8: =SUMIF(Summary!B:B,'Final Check'!A8,Summary!H:H) -> 2.1615e+09 | H8: =B8-C8 -> -1 | I8: =D8-E8 -> -4.9999938e-10 | J8: =F8-G8 -> -1.0807528
A9: 2022 | B9: 33286024718 | C9: =SUMIF(Summary!B:B,'Final Check'!A9,Summary!F:F) -> 33286024718 | D9: 1 | E9: =SUMIF(Summary!B:B,'Final Check'!A9,Summary!G:G) -> 1 | F9: 4030200000 | G9: =SUMIF(Summary!B:B,'Final Check'!A9,Summary!H:H) -> 4.0302e+09 | H9: =B9-C9 -> 0 | I9: =D9-E9 -> 4.9999993e-10 | J9: =F9-G9 -> 2.0150962
A10: 2023 | B10: 25422573543 | C10: =SUMIF(Summary!B:B,'Final Check'!A10,Summary!F:F) -> 25422573543 | D10: 1 | E10: =SUMIF(Summary!B:B,'Final Check'!A10,Summary!G:G) -> 1 | F10: 2392900000 | G10: =SUMIF(Summary!B:B,'Final Check'!A10,Summary!H:H) -> 2.3929e+09 | H10: =B10-C10 -> 0 | I10: =D10-E10 -> -4.9999938e-10 | J10: =F10-G10 -> -1.1964431

Sheet Check
A1: Employer Contribution Check Plan 1
A2: Year | B2: Employer PV Total Reported | C2: Employer PV Total from Formula | D2: Reported Allocation Percentage Total | E2: Allocation Percentage Total from Formula | F2: Employer Contribution Difference | G2: Allocation Percentage Difference | H2: Notes
A3: 2015 | B3: 13733058223 | C3: =SUMIF('GASB Data'!A:A,Check!A3,'GASB Data'!E:E) -> 13733058223 | D3: 1 | E3: =SUMIF('GASB Data'!A:A,Check!A3,'GASB Data'!F:F) -> 1 | F3: =B3-C3 -> 0 | G3: =D3-E3 -> -1.9999802e-10
A4: 2016 | B4: 19287900237 | C4: =SUMIF('GASB Data'!A:A,Check!A4,'GASB Data'!E:E) -> 19287900237 | D4: 1 | E4: =SUMIF('GASB Data'!A:A,Check!A4,'GASB Data'!F:F) -> 1 | F4: =B4-C4 -> 0 | G4: =D4-E4 -> -1.1000014e-09
A5: 2017 | B5: 23673277639 | C5: =SUMIF('GASB Data'!A:A,Check!A5,'GASB Data'!E:E) -> 23673277639 | D5: 1 | E5: =SUMIF('GASB Data'!A:A,Check!A5,'GASB Data'!F:F) -> 1 | F5: =B5-C5 -> 0 | G5: =D5-E5 -> -9.0000163e-10
A6: 2018 | B6: 28073504157 | C6: =SUMIF('GASB Data'!A:A,Check!A6,'GASB Data'!E:E) -> 28073504157 | D6: 1 | E6: =SUMIF('GASB Data'!A:A,Check!A6,'GASB Data'!F:F) -> 1 | F6: =B6-C6 -> 0 | G6: =D6-E6 -> 3.9999948e-10
A7: 2019 | B7: 24764676763 | C7: =SUMIF('GASB Data'!A:A,Check!A7,'GASB Data'!E:E) -> 24764676763 | D7: 1 | E7: =SUMIF('GASB Data'!A:A,Check!A7,'GASB Data'!F:F) -> 1 | F7: =B7-C7 -> 0 | G7: =D7-E7 -> -3.0000069e-10
A8: 2020 | B8: 30590051173 | C8: =SUMIF('GASB Data'!A:A,Check!A8,'GASB Data'!E:E) -> 30590051173 | D8: 1 | E8: =SUMIF('GASB Data'!A:A,Check!A8,'GASB Data'!F:F) -> 1 | F8: =B8-C8 -> 0 | G8: =D8-E8 -> -9.9999342e-11
A9: 2021 | B9: 28745388516 | C9: =SUMIF('GASB Data'!A:A,Check!A9,'GASB Data'!E:E) -> 28745388517 | D9: 1 | E9: =SUMIF('GASB Data'!A:A,Check!A9,'GASB Data'!F:F) -> 1 | F9: =B9-C9 -> -1 | G9: =D9-E9 -> -4.9999938e-10
A10: 2022 | B10: 33286024718 | C10: =SUMIF('GASB Data'!A:A,Check!A10,'GASB Data'!E:E) -> 33286024718 | D10: 1 | E10: =SUMIF('GASB Data'!A:A,Check!A10,'GASB Data'!F:F) -> 1 | F10: =B10-C10 -> 0 | G10: =D10-E10 -> 4.9999993e-10
A11: 2023 | B11: 25422573543 | C11: =SUMIF('GASB Data'!A:A,Check!A11,'GASB Data'!E:E) -> 25422573543 | D11: 1 | E11: =SUMIF('GASB Data'!A:A,Check!A11,'GASB Data'!F:F) -> 1 | F11: =B11-C11 -> 0 | G11: =D11-E11 -> -4.9999938e-10

Sheet GASB 67 Employer Contributions
A1: Year | B1: Employer Contributions
A2: 2015 | B2: 1123300000
A3: 2016 | B3: 977300000
A4: 2017 | B4: 1022200000
A5: 2018 | B5: 1390100000
A6: 2019 | B6: 1720200000
A7: 2020 | B7: 2299000000
A8: 2021 | B8: 2161500000
A9: 2022 | B9: 4030200000
A10: 2023 | B10: 2392900000

Sheet NCES Data -->

Sheet LEAID Match
A1: standardized_employer_name | B1: LEAID
A2: Falls City School District | B2: 4100003
A3: Vale School District 84 | B3: 4100014
A4: Gervais School District 1 | B4: 4100015
A5: Yamhill-Carlton School District 1 | B5: 4100016
A6: Harrisburg Sschool District 7 | B6: 4100019
A7: North Santiam School District 29J | B7: 4100020
A8: South Wasco County School District 1 | B8: 4100021
A9: Hillsboro School District 1J | B9: 4100023
A10: Knappa School District 4 | B10: 4100040
A11: Ione School District | B11: 4100047
A12: North Wasco County School District 21 | B12: 4100048
A13: Myrtle Point School District 41 | B13: 4100640
... A186: Yoncalla School District 32 | B186: 4113650
