Workbook

Sheet Summary
A1: Year | B1: State | C1: state_abv | D1: plan | E1: district_name_standardized | F1: district_name | G1: district_contributions | H1: state_contributions | I1: total_contributions | J1: LEAID_match
A2: 2015 | B2: New Hampshire | C2: NH | D2: New Hampshire Retirement System | E2: Albany - Emp | F2: ALBANY - EMP | G2: 4273.25 | H2: 0 | I2: =SUM(G2:H2) -> 4273.25 | J2: =IFERROR(VLOOKUP(E2,'LEAID Match'!$A$2:$B$168,2,FALSE),"")
A3: 2016 | B3: New Hampshire | C3: NH | D3: New Hampshire Retirement System | E3: Albany - Emp | F3: Albany - Emp | G3: 4528 | H3: 0 | I3: =SUM(G3:H3) -> 4528 | J3: =IFERROR(VLOOKUP(E3,'LEAID Match'!$A$2:$B$168,2,FALSE),"")
A4: 2017 | B4: New Hampshire | C4: NH | D4: New Hampshire Retirement System | E4: Albany - Emp | F4: Albany - Emp | G4: 4484 | H4: 0 | I4: =SUM(G4:H4) -> 4484 | J4: =IFERROR(VLOOKUP(E4,'LEAID Match'!$A$2:$B$168,2,FALSE),"")
A5: 2018 | B5: New Hampshire | C5: NH | D5: New Hampshire Retirement System | E5: Albany - Emp | F5: Albany - Emp | G5: 4662 | H5: 0 | I5: =SUM(G5:H5) -> 4662 | J5: =IFERROR(VLOOKUP(E5,'LEAID Match'!$A$2:$B$168,2,FALSE),"")
A6: 2019 | B6: New Hampshire | C6: NH | D6: New Hampshire Retirement System | E6: Albany - Emp | F6: Albany - Emp | G6: 4839 | H6: 0 | I6: =SUM(G6:H6) -> 4839 | J6: =IFERROR(VLOOKUP(E6,'LEAID Match'!$A$2:$B$168,2,FALSE),"")
A7: 2015 | B7: New Hampshire | C7: NH | D7: New Hampshire Retirement System | E7: Alexandria - Emp/Pol | F7: ALEXANDRIA - EMP/POL | G7: 35431.44 | H7: 0 | I7: =SUM(G7:H7) -> 35431.44 | J7: =IFERROR(VLOOKUP(E7,'LEAID Match'!$A$2:$B$168,2,FALSE),"")
A8: 2016 | B8: New Hampshire | C8: NH | D8: New Hampshire Retirement System | E8: Alexandria - Emp/Pol | F8: Alexandria - Emp/Pol | G8: 42440 | H8: 0 | I8: =SUM(G8:H8) -> 42440 | J8: =IFERROR(VLOOKUP(E8,'LEAID Match'!$A$2:$B$168,2,FALSE),"")
A9: 2017 | B9: New Hampshire | C9: NH | D9: New Hampshire Retirement System | E9: Alexandria - Emp/Pol | F9: Alexandria - Emp/Pol | G9: 42952 | H9: 0 | I9: =SUM(G9:H9) -> 42952 | J9: =IFERROR(VLOOKUP(E9,'LEAID Match'!$A$2:$B$168,2,FALSE),"")
A10: 2018 | B10: New Hampshire | C10: NH | D10: New Hampshire Retirement System | E10: Alexandria - Emp/Pol | F10: Alexandria - Emp/Pol | G10: 47287 | H10: 0 | I10: =SUM(G10:H10) -> 47287 | J10: =IFERROR(VLOOKUP(E10,'LEAID Match'!$A$2:$B$168,2,FALSE),"")
A11: 2019 | B11: New Hampshire | C11: NH | D11: New Hampshire Retirement System | E11: Alexandria - Emp/Pol | F11: Alexandria - Emp/Pol | G11: 50980 | H11: 0 | I11: =SUM(G11:H11) -> 50980 | J11: =IFERROR(VLOOKUP(E11,'LEAID Match'!$A$2:$B$168,2,FALSE),"")
A12: 2015 | B12: New Hampshire | C12: NH | D12: New Hampshire Retirement System | E12: Allenstown - Emp/Fire/Pol | F12: ALLENSTOWN - EMP/FIRE/POL | G12: 185934.67 | H12: 0 | I12: =SUM(G12:H12) -> 185934.67 | J12: =IFERROR(VLOOKUP(E12,'LEAID Match'!$A$2:$B$168,2,FALSE),"")
A13: 2016 | B13: New Hampshire | C13: NH | D13: New Hampshire Retirement System | E13: Allenstown - Emp/Fire/Pol | F13: Allenstown - Emp/Fire/Pol | G13: 207076 | H13: 0 | I13: =SUM(G13:H13) -> 207076 | J13: =IFERROR(VLOOKUP(E13,'LEAID Match'!$A$2:$B$168,2,FALSE),"")
... A28: 2017 | B28: New Hampshire | C28: NH | D28: New Hampshire Retirement System | E28: Allenstown Sewer Commission | F28: Allenstown Sewer Commission | G28: 19632 | H28: 0 | I28: =SUM(G28:H28) -> 19632 | J28: =IFERROR(VLOOKUP(E28,'LEAID Match'!$A$2:$B$168,2,FALSE),"")
A29: 2018 | B29: New Hampshire | C29: NH | D29: New Hampshire Retirement System | E29: Allenstown Sewer Commission | F29: Allenstown Sewer Commission | H29: 0 | I29: =SUM(G29:H29) -> 0 | J29: =IFERROR(VLOOKUP(E29,'LEAID Match'!$A$2:$B$168,2,FALSE),"")
A30: 2019 | B30: New Hampshire | C30: NH | D30: New Hampshire Retirement System | E30: Allenstown Sewer Commission | F30: Allenstown Sewer Commission | H30: 0 | I30: =SUM(G30:H30) -> 0 | J30: =IFERROR(VLOOKUP(E30,'LEAID Match'!$A$2:$B$168,2,FALSE),"")
A31: 2020 | B31: New Hampshire | C31: NH | D31: New Hampshire Retirement System | E31: Allenstown Sewer Commission | F31: Allenstown Sewer Commission | H31: 0 | I31: =SUM(G31:H31) -> 0 | J31: =IFERROR(VLOOKUP(E31,'LEAID Match'!$A$2:$B$168,2,FALSE),"")
A32: 2021 | B32: New Hampshire | C32: NH | D32: New Hampshire Retirement System | E32: Allenstown Sewer Commission | F32: Allenstown Sewer Commission | H32: 0 | I32: =SUM(G32:H32) -> 0 | J32: =IFERROR(VLOOKUP(E32,'LEAID Match'!$A$2:$B$168,2,FALSE),"")
A33: 2015 | B33: New Hampshire | C33: NH | D33: New Hampshire Retirement System | E33: Alstead - Police | F33: ALSTEAD - POLICE | G33: 17607.59 | H33: 0 | I33: =SUM(G33:H33) -> 17607.59 | J33: =IFERROR(VLOOKUP(E33,'LEAID Match'!$A$2:$B$168,2,FALSE),"")
A34: 2016 | B34: New Hampshire | C34: NH | D34: New Hampshire Retirement System | E34: Alstead - Police | F34: Alstead - Police | G34: 14318 | H34: 0 | I34: =SUM(G34:H34) -> 14318 | J34: =IFERROR(VLOOKUP(E34,'LEAID Match'!$A$2:$B$168,2,FALSE),"")
A35: 2017 | B35: New Hampshire | C35: NH | D35: New Hampshire Retirement System | E35: Alstead - Police | F35: Alstead - Police | G35: 17349 | H35: 0 | I35: =SUM(G35:H35) -> 17349 | J35: =IFERROR(VLOOKUP(E35,'LEAID Match'!$A$2:$B$168,2,FALSE),"")
A36: 2018 | B36: New Hampshire | C36: NH | D36: New Hampshire Retirement System | E36: Alstead - Police | F36: Alstead - Police | G36: 26431 | H36: 0 | I36: =SUM(G36:H36) -> 26431 | J36: =IFERROR(VLOOKUP(E36,'LEAID Match'!$A$2:$B$168,2,FALSE),"")
A37: 2019 | B37: New Hampshire | C37: NH | D37: New Hampshire Retirement System | E37: Alstead - Police | F37: Alstead - Police | G37: 28710 | H37: 0 | I37: =SUM(G37:H37) -> 28710 | J37: =IFERROR(VLOOKUP(E37,'LEAID Match'!$A$2:$B$168,2,FALSE),"")
A38: 2015 | B38: New Hampshire | C38: NH | D38: New Hampshire Retirement System | E38: Alton - Emp/Fire/Pol | F38: ALTON - EMP/FIRE/POL | G38: 384134.46 | H38: 0 | I38: =SUM(G38:H38) -> 384134.46 | J38: =IFERROR(VLOOKUP(E38,'LEAID Match'!$A$2:$B$168,2,FALSE),"")
A39: 2016 | B39: New Hampshire | C39: NH | D39: New Hampshire Retirement System | E39: Alton - Emp/Fire/Pol | F39: Alton - Emp/Fire/Pol | G39: 408396 | H39: 0 | I39: =SUM(G39:H39) -> 408396 | J39: =IFERROR(VLOOKUP(E39,'LEAID Match'!$A$2:$B$168,2,FALSE),"")
A40: 2017 | B40: New Hampshire | C40: NH | D40: New Hampshire Retirement System | E40: Alton - Emp/Fire/Pol | F40: Alton - Emp/Fire/Pol | G40: 385599 | H40: 0 | I40: =SUM(G40:H40) -> 385599 | J40: =IFERROR(VLOOKUP(E40,'LEAID Match'!$A$2:$B$168,2,FALSE),"")
A41: 2018 | B41: New Hampshire | C41: NH | D41: New Hampshire Retirement System | E41: Alton - Emp/Fire/Pol | F41: Alton - Emp/Fire/Pol | G41: 423616 | H41: 0 | I41: =SUM(G41:H41) -> 423616 | J41: =IFERROR(VLOOKUP(E41,'LEAID Match'!$A$2:$B$168,2,FALSE),"")
A42: 2019 | B42: New Hampshire | C42: NH | D42: New Hampshire Retirement System | E42: Alton - Emp/Fire/Pol | F42: Alton - Emp/Fire/Pol | G42: 464330 | H42: 0 | I42: =SUM(G42:H42) -> 464330 | J42: =IFERROR(VLOOKUP(E42,'LEAID Match'!$A$2:$B$168,2,FALSE),"")
A43: 2015 | B43: New Hampshire | C43: NH | D43: New Hampshire Retirement System | E43: Alton SD | F43: ALTON SD - EMP/TEACH | G43: 500661.01 | H43: 0 | I43: =SUM(G43:H43) -> 500661.01 | J43: =IFERROR(VLOOKUP(E43,'LEAID Match'!$A$2:$B$168,2,FALSE),"") -> 3301440
A44: 2016 | B44: New Hampshire | C44: NH | D44: New Hampshire Retirement System | E44: Alton SD | F44: Alton Sd - Emp/Teach | G44: 536840 | H44: 0 | I44: =SUM(G44:H44) -> 536840 | J44: =IFERROR(VLOOKUP(E44,'LEAID Match'!$A$2:$B$168,2,FALSE),"") -> 3301440
... A104: 2020 | B104: New Hampshire | C104: NH | D104: New Hampshire Retirement System | E104: Ashland Electric Dept - Emp | F104: Ashland Electric Dept - Emp | G104: 12012 | H104: 0 | I104: =SUM(G104:H104) -> 12012 | J104: =IFERROR(VLOOKUP(E104,'LEAID Match'!$A$2:$B$168,2,FALSE),"")
A105: 2021 | B105: New Hampshire | C105: NH | D105: New Hampshire Retirement System | E105: Ashland Electric Dept - Emp | F105: Ashland Electric Dept - Emp | H105: 0 | I105: =SUM(G105:H105) -> 0 | J105: =IFERROR(VLOOKUP(E105,'LEAID Match'!$A$2:$B$168,2,FALSE),"")
A106: 2015 | B106: New Hampshire | C106: NH | D106: New Hampshire Retirement System | E106: Ashland SD | F106: ASHLAND SD - (SAU 02) | G106: 158958.18 | H106: 0 | I106: =SUM(G106:H106) -> 158958.18 | J106: =IFERROR(VLOOKUP(E106,'LEAID Match'!$A$2:$B$168,2,FALSE),"") -> 3301560
A107: 2016 | B107: New Hampshire | C107: NH | D107: New Hampshire Retirement System | E107: Ashland SD | F107: Ashland Sd - (Sau 02) | G107: 167612 | H107: 0 | I107: =SUM(G107:H107) -> 167612 | J107: =IFERROR(VLOOKUP(E107,'LEAID Match'!$A$2:$B$168,2,FALSE),"") -> 3301560
A108: 2017 | B108: New Hampshire | C108: NH | D108: New Hampshire Retirement System | E108: Ashland SD | F108: Ashland Sd - (Sau 02) | G108: 178164 | H108: 0 | I108: =SUM(G108:H108) -> 178164 | J108: =IFERROR(VLOOKUP(E108,'LEAID Match'!$A$2:$B$168,2,FALSE),"") -> 3301560
A109: 2018 | B109: New Hampshire | C109: NH | D109: New Hampshire Retirement System | E109: Ashland SD | F109: Ashland Sd - (Sau 02) | G109: 217688 | H109: 0 | I109: =SUM(G109:H109) -> 217688 | J109: =IFERROR(VLOOKUP(E109,'LEAID Match'!$A$2:$B$168,2,FALSE),"") -> 3301560
A110: 2019 | B110: New Hampshire | C110: NH | D110: New Hampshire Retirement System | E110: Ashland SD | F110: Ashland Sd - (Sau 02) | G110: 229681 | H110: 0 | I110: =SUM(G110:H110) -> 229681 | J110: =IFERROR(VLOOKUP(E110,'LEAID Match'!$A$2:$B$168,2,FALSE),"") -> 3301560
A111: 2020 | B111: New Hampshire | C111: NH | D111: New Hampshire Retirement System | E111: Ashland SD | F111: Ashland SD | G111: 246870 | H111: 0 | I111: =SUM(G111:H111) -> 246870 | J111: =IFERROR(VLOOKUP(E111,'LEAID Match'!$A$2:$B$168,2,FALSE),"") -> 3301560
A112: 2021 | B112: New Hampshire | C112: NH | D112: New Hampshire Retirement System | E112: Ashland SD | F112: Ashland SD | G112: 250299 | H112: 0 | I112: =SUM(G112:H112) -> 250299 | J112: =IFERROR(VLOOKUP(E112,'LEAID Match'!$A$2:$B$168,2,FALSE),"") -> 3301560
A113: 2022 | B113: New Hampshire | C113: NH | D113: New Hampshire Retirement System | E113: Ashland SD | F113: Ashland SD | G113: 331478 | H113: 0 | I113: =SUM(G113:H113) -> 331478 | J113: =IFERROR(VLOOKUP(E113,'LEAID Match'!$A$2:$B$168,2,FALSE),"") -> 3301560
...

Sheet GASB 68 Data -->

Sheet 2022 & 2023
A1: Year | B1: district_name | C1: district_contributions | E1: Year | F1: district_name | G1: district_contributions
A2: 2023 | B2: Allenstown SD | C2: 522842 | E2: 2022 | F2: Allenstown SD | G2: 519261
A3: 2023 | B3: Alton SD | C3: 810441 | E3: 2022 | F3: Alton SD | G3: 834939
A4: 2023 | B4: Amherst SD | C4: 2691798 | E4: 2022 | F4: Amherst SD | G4: 2738262
A5: 2023 | B5: Andover SD | C5: 340073 | E5: 2022 | F5: Andover SD | G5: 338223
A6: 2023 | B6: Androscoggin Valley Reg Refuse | C6: 118659 | E6: 2022 | F6: Androscoggin Valley Reg Refuse | G6: 107946
A7: 2023 | B7: Ashland SD | C7: 349587 | E7: 2022 | F7: Ashland SD | G7: 331478
A8: 2023 | B8: Auburn SD | C8: 768265 | E8: 2022 | F8: Auburn SD | G8: 791606
A9: 2023 | B9: Barnstead SD | C9: 680775 | E9: 2022 | F9: Barnstead SD | G9: 786707
A10: 2023 | B10: Barrington SD | C10: 1623198 | E10: 2022 | F10: Barrington SD | G10: 1567097
A11: 2023 | B11: Bartlett SD | C11: 415676 | E11: 2022 | F11: Bartlett SD | G11: 479290
A12: 2023 | B12: Bath SD | C12: 120388 | E12: 2022 | F12: Bath SD | G12: 125648
A13: 2023 | B13: Bcep Solid Waste District | C13: 45025 | E13: 2022 | F13: Bcep Solid Waste District | G13: 41869
... A168: 2023 | B168: NH Municipal Bond Bank | C168: 37580 | E168: 2022 | F168: NH Municipal Bond Bank | G168: 33235
A169: 2023 | B169: NH Retirement System | E169: 2022 | F169: NH Retirement System
A170: 2023 | B170: North Conway Wtr Precinct | C170: 167275 | E170: 2022 | F170: North Conway Wtr Precinct | G170: 154335
A171: 2023 | B171: North Country Charter Academy | C171: 51856 | E171: 2022 | F171: North Country Charter Academy | G171: 42677
A172: 2023 | B172: North Country Edu Srvc Ag Inc | C172: 105127 | E172: 2022 | F172: North Country Edu Srvc Ag Inc | G172: 114542
A173: 2023 | B173: North Hampton SD | C173: 816310 | E173: 2022 | F173: North Hampton SD | G173: 793314
A174: 2023 | B174: Northumberland SD | C174: 566617 | E174: 2022 | F174: Northumberland SD | G174: 543988
A175: 2023 | B175: Northwood SD | C175: 604191 | E175: 2022 | F175: Northwood SD | G175: 521325
A176: 2023 | B176: Nottingham SD | C176: 742774 | E176: 2022 | F176: Nottingham SD | G176: 667830
A177: 2023 | B177: Oyster River Coop SD | C177: 4212316 | E177: 2022 | F177: Oyster River Coop SD | G177: 4007724
A178: 2023 | B178: Pease Development Authority | C178: 613465 | E178: 2022 | F178: Pease Development Authority | G178: 533656
A179: 2023 | B179: Pelham SD | C179: 2550707 | E179: 2022 | F179: Pelham SD | G179: 2469082
A180: 2023 | B180: Pembroke SD | C180: 2317885 | E180: 2022 | F180: Pembroke SD | G180: 2260426
A181: 2023 | B181: Pemi Baker Coop | C181: 1171361 | E181: 2022 | F181: Pemi Baker Coop | G181: 1169099
... A225: 2023 | B225: SAU 42 | C225: 16483447 | E225: 2022 | F225: SAU 42 | G225: 15628166
A226: 2023 | B226: SAU 44 | E226: 2022 | F226: SAU 44 | G226: 165750
A227: 2023 | B227: SAU 46 | C227: 116077 | E227: 2022 | F227: SAU 46 | G227: 96852
A228: 2023 | B228: SAU 48 | C228: 194675 | E228: 2022 | F228: SAU 48 | G228: 191232
A229: 2023 | B229: SAU 50 | C229: 151034 | E229: 2022 | F229: SAU 50 | G229: 148332
A230: 2023 | B230: SAU 53 | C230: 503517 | E230: 2022 | F230: SAU 53 | G230: 481560
A231: 2023 | B231: SAU 58 | C231: 57409 | E231: 2022 | F231: SAU 58 | G231: 54765
A232: 2023 | B232: SAU 67 | C232: 102495 | E232: 2022 | F232: SAU 67 | G232: 110611
A233: 2023 | B233: SAU 70 | C233: 172512 | E233: 2022 | F233: SAU 70 | G233: 166160
A234: 2023 | B234: Seabrook SD | C234: 1523576 | E234: 2022 | F234: Seabrook SD | G234: 1474447
A235: 2023 | B235: Seacoast Charter School | C235: 209811 | E235: 2022 | F235: Seacoast Charter School | G235: 203135
A236: 2023 | B236: Shaker Regional SD - SAU 80 | C236: 2039494 | E236: 2022 | F236: Shaker Regional SD - SAU 80 | G236: 2032711
A237: 2023 | B237: Somersworth Housing Authority | C237: 85061 | E237: 2022 | F237: Somersworth Housing Authority | G237: 85961
...

Sheet 2020 & 2021
A1: Year | B1: district_name | C1: district_contributions | E1: Year | F1: district_name | G1: district_contributions
A2: 2021 | B2: Allenstown SD | C2: 403813 | E2: 2020 | F2: Allenstown SD | G2: 398686
A3: 2021 | B3: Allenstown Sewer Commission | E3: 2020 | F3: Allenstown Sewer Commission
A4: 2021 | B4: Alton SD | C4: 686106 | E4: 2020 | F4: Alton SD | G4: 633688
A5: 2021 | B5: Amherst SD | C5: 2105222 | E5: 2020 | F5: Amherst SD | G5: 1985874
A6: 2021 | B6: Andover SD | C6: 281559 | E6: 2020 | F6: Andover SD | G6: 280520
A7: 2021 | B7: Androscoggin Valley Reg Refuse | C7: 77920 | E7: 2020 | F7: Androscoggin Valley Reg Refuse | G7: 70000
A8: 2021 | B8: Ashland Electric Dept - Emp | E8: 2020 | F8: Ashland Electric Dept - Emp | G8: 12012
A9: 2021 | B9: Ashland SD | C9: 250299 | E9: 2020 | F9: Ashland SD | G9: 246870
A10: 2021 | B10: Auburn SD | C10: 609948 | E10: 2020 | F10: Auburn SD | G10: 562917
A11: 2021 | B11: Baker Free Library - Emp | E11: 2020 | F11: Baker Free Library - Emp
A12: 2021 | B12: Barnstead SD | C12: 643935 | E12: 2020 | F12: Barnstead SD | G12: 628826
A13: 2021 | B13: Barrington SD | C13: 1209681 | E13: 2020 | F13: Barrington SD | G13: 1170380
A14: 2021 | B14: Bartlett SD | C14: 391006 | E14: 2020 | F14: Bartlett SD | G14: 382434
A15: 2021 | B15: Bath SD | C15: 95874 | E15: 2020 | F15: Bath SD | G15: 88973
A16: 2021 | B16: Bcep Solid Waste District | C16: 22333 | E16: 2020 | F16: Bcep Solid Waste District | G16: 29679
A17: 2021 | B17: Bedford SD | C17: 5108512 | E17: 2020 | F17: Bedford SD | G17: 4872213
A18: 2021 | B18: Belknap County | C18: 1205240 | E18: 2020 | F18: Belknap County | G18: 1186092
A19: 2021 | B19: Belknap County Conserv. Dist | C19: 5962 | E19: 2020 | F19: Belknap County Conserv. Dist | G19: 5962
A20: 2021 | B20: Berlin - Emp/Fire/Pol | C20: 1074225 | E20: 2020 | F20: Berlin - Emp/Fire/Pol | G20: 1048292
A21: 2021 | B21: Berlin Housing Authority | C21: 30437 | E21: 2020 | F21: Berlin Housing Authority | G21: 29135
A22: 2021 | B22: Berlin Water Works | C22: 73553 | E22: 2020 | F22: Berlin Water Works | G22: 71172
A23: 2021 | B23: Bethlehem SD | C23: 256747 | E23: 2020 | F23: Bethlehem SD | G23: 227935
... A28: 2021 | B28: Campton SD | C28: 434085 | E28: 2020 | F28: Campton SD | G28: 443423
A29: 2021 | B29: Campton/Thornton Fire Dept | E29: 2020 | F29: Campton/Thornton Fire Dept
A30: 2021 | B30: Candia SD | C30: 354192 | E30: 2020 | F30: Candia SD | G30: 347852
A31: 2021 | B31: Carroll County | C31: 1452826 | E31: 2020 | F31: Carroll County | G31: 1390041
A32: 2021 | B32: Center Conway Fire Precinct | C32: 14841 | E32: 2020 | F32: Center Conway Fire Precinct | G32: 14216
A33: 2021 | B33: Central Hooksett Wtr Precinct | C33: 19134 | E33: 2020 | F33: Central Hooksett Wtr Precinct | G33: 22915
A34: 2021 | B34: Cheshire County | C34: 1935855 | E34: 2020 | F34: Cheshire County | G34: 1887585
A35: 2021 | B35: Chester SD - (SAU 82) | C35: 572543 | E35: 2020 | F35: Chester SD - (SAU 82) | G35: 539186
A36: 2021 | B36: Chesterfield SD | C36: 344744 | E36: 2020 | F36: Chesterfield SD | G36: 342536
A37: 2021 | B37: Chichester SD | C37: 301915 | E37: 2020 | F37: Chichester SD | G37: 303555
A38: 2021 | B38: City of Claremont | C38: 1048187 | E38: 2020 | F38: City of Claremont | G38: 1017901
A39: 2021 | B39: City of Concord | C39: 6100373 | E39: 2020 | F39: City of Concord | G39: 5616819
A40: 2021 | B40: City of Dover | C40: 7520055 | E40: 2020 | F40: City of Dover | G40: 7208430
A41: 2021 | B41: City of Franklin | C41: 936214 | E41: 2020 | F41: City of Franklin | G41: 877083
... A53: 2021 | B53: Community College System of NH | C53: 4833157 | E53: 2020 | F53: Community College System of NH | G53: 4749061
A54: 2021 | B54: Concord Reg Sol Waste Res Rec | E54: 2020 | F54: Concord Reg Sol Waste Res Rec
A55: 2021 | B55: Concord SD | C55: 6298991 | E55: 2020 | F55: Concord SD | G55: 5988664
...

Sheet 2018 & 2019
A1: Year | B1: district_name | C1: district_contributions | E1: Year | F1: district_name | G1: district_contributions
A2: 2019 | B2: Albany - Emp | C2: 4839 | E2: 2018 | F2: Albany - Emp | G2: 4662
A3: 2019 | B3: Alexandria - Emp/Pol | C3: 50980 | E3: 2018 | F3: Alexandria - Emp/Pol | G3: 47287
A4: 2019 | B4: Allenstown - Emp/Fire/Pol | C4: 271092 | E4: 2018 | F4: Allenstown - Emp/Fire/Pol | G4: 268821
A5: 2019 | B5: Allenstown Sd - (Sau 53) | C5: 383431 | E5: 2018 | F5: Allenstown Sd - (Sau 53) | G5: 381768
A6: 2019 | B6: Allenstown Sewer Commission | E6: 2018 | F6: Allenstown Sewer Commission
A7: 2019 | B7: Alstead - Police | C7: 28710 | E7: 2018 | F7: Alstead - Police | G7: 26431
A8: 2019 | B8: Alton - Emp/Fire/Pol | C8: 464330 | E8: 2018 | F8: Alton - Emp/Fire/Pol | G8: 423616
A9: 2019 | B9: Alton Sd - Emp/Teach | C9: 630478 | E9: 2018 | F9: Alton Sd - Emp/Teach | G9: 613113
A10: 2019 | B10: Amherst - Fire/Pol | C10: 415805 | E10: 2018 | F10: Amherst - Fire/Pol | G10: 388044
A11: 2019 | B11: Amherst Sd - (Sau 39) | C11: 1916022 | E11: 2018 | F11: Amherst Sd - (Sau 39) | G11: 1806788
A12: 2019 | B12: Andover - Police | C12: 17549 | E12: 2018 | F12: Andover - Police | G12: 16452
A13: 2019 | B13: Andover Sd - (Sau 46) | C13: 260917 | E13: 2018 | F13: Andover Sd - (Sau 46) | G13: 245256
A14: 2019 | B14: Androscoggin Valley Reg Refuse | C14: 69976 | E14: 2018 | F14: Androscoggin Valley Reg Refuse | G14: 67119
A15: 2019 | B15: Antrim - Emp/Pol | C15: 161430 | E15: 2018 | F15: Antrim - Emp/Pol | G15: 157453
A16: 2019 | B16: Ashland - Emp/Pol | C16: 126340 | E16: 2018 | F16: Ashland - Emp/Pol | G16: 117209
A17: 2019 | B17: Ashland Electric Dept - Emp | C17: 30535 | E17: 2018 | F17: Ashland Electric Dept - Emp | G17: 32653
A18: 2019 | B18: Ashland Sd - (Sau 02) | C18: 229681 | E18: 2018 | F18: Ashland Sd - (Sau 02) | G18: 217688
... A21: 2019 | B21: Auburn Sd - (Sau 15) | C21: 570624 | E21: 2018 | F21: Auburn Sd - (Sau 15) | G21: 544718
A22: 2019 | B22: Baker Free Library - Emp | E22: 2018 | F22: Baker Free Library - Emp
A23: 2019 | B23: Barnstead - Emp/Fire/Pol | C23: 207702 | E23: 2018 | F23: Barnstead - Emp/Fire/Pol | G23: 200249
A24: 2019 | B24: Barnstead Sd - Emp/Teach | C24: 558781 | E24: 2018 | F24: Barnstead Sd - Emp/Teach | G24: 519474
A25: 2019 | B25: Barrington - Emp/Pol/Fire | C25: 362696 | E25: 2018 | F25: Barrington - Emp/Pol/Fire | G25: 335148
A26: 2019 | B26: Barrington Sd - Emp/Teach | C26: 1110657 | E26: 2018 | F26: Barrington Sd - Emp/Teach | G26: 1070439
A27: 2019 | B27: Bartlett - Fire/Pol | C27: 66896 | E27: 2018 | F27: Bartlett - Fire/Pol | G27: 54719
A28: 2019 | B28: Bartlett Sd - (Sau 09) | C28: 370715 | E28: 2018 | F28: Bartlett Sd - (Sau 09) | G28: 373988
A29: 2019 | B29: Bath Sd - (Sau 23) | C29: 82651 | E29: 2018 | F29: Bath Sd - (Sau 23) | G29: 77720
A30: 2019 | B30: Bcep Solid Waste District | C30: 30461 | E30: 2018 | F30: Bcep Solid Waste District | G30: 33315
A31: 2019 | B31: Bedford - Emp/Fire/Pol | C31: 1926893 | E31: 2018 | F31: Bedford - Emp/Fire/Pol | G31: 1859338
A32: 2019 | B32: Bedford Sd - Emp/Teach | C32: 4753822 | E32: 2018 | F32: Bedford Sd - Emp/Teach | G32: 4527132
A33: 2019 | B33: Belknap County - Emp/Pol | C33: 1214705 | E33: 2018 | F33: Belknap County - Emp/Pol | G33: 1187740
A34: 2019 | B34: Belknap County Conserv. Dist | C34: 6072 | E34: 2018 | F34: Belknap County Conserv. Dist | G34: 5838
... A47: 2019 | B47: Brentwood Sd - (Sau 16) | C47: 346089 | E47: 2018 | F47: Brentwood Sd - (Sau 16) | G47: 318532
A48: 2019 | B48: Bridgewater - Police/Fire | E48: 2018 | F48: Bridgewater - Police/Fire
A49: 2019 | B49: Bristol - Emp/Fire/Pol | C49: 369000 | E49: 2018 | F49: Bristol - Emp/Fire/Pol | G49: 383837
A50: 2019 | B50: Brookline - Emp/Fire/Pol | C50: 252989 | E50: 2018 | F50: Brookline - Emp/Fire/Pol | G50: 241907
A51: 2019 | B51: Brookline Public Library - Emp | C51: 8369 | E51: 2018 | F51: Brookline Public Library - Emp | G51: 9148
A52: 2019 | B52: Brookline Sd - (Sau 41) | C52: 628402 | E52: 2018 | F52: Brookline Sd - (Sau 41) | G52: 606030
A53: 2019 | B53: Campton - Emp/Pol/Fire | C53: 178905 | E53: 2018 | F53: Campton - Emp/Pol/Fire | G53: 134288
A54: 2019 | B54: Campton Sd - (Sau 48) | C54: 431492 | E54: 2018 | F54: Campton Sd - (Sau 48) | G54: 418694
...

Sheet 2016 & 2017
A1: Year | B1: district_name | C1: district_contributions | E1: Year | F1: district_name | G1: district_contributions
A2: 2017 | B2: Albany - Emp | C2: 4484 | E2: 2016 | F2: Albany - Emp | G2: 4528
A3: 2017 | B3: Alexandria - Emp/Pol | C3: 42952 | E3: 2016 | F3: Alexandria - Emp/Pol | G3: 42440
A4: 2017 | B4: Allenstown - Emp/Fire/Pol | C4: 234685 | E4: 2016 | F4: Allenstown - Emp/Fire/Pol | G4: 207076
A5: 2017 | B5: Allenstown Sd - (Sau 53) | C5: 308891 | E5: 2016 | F5: Allenstown Sd - (Sau 53) | G5: 318434
A6: 2017 | B6: Allenstown Sewer Commission | C6: 19632 | E6: 2016 | F6: Allenstown Sewer Commission | G6: 42629
A7: 2017 | B7: Alstead - Police | C7: 17349 | E7: 2016 | F7: Alstead - Police | G7: 14318
A8: 2017 | B8: Alton - Emp/Fire/Pol | C8: 385599 | E8: 2016 | F8: Alton - Emp/Fire/Pol | G8: 408396
A9: 2017 | B9: Alton Sd - Emp/Teach | C9: 550245 | E9: 2016 | F9: Alton Sd - Emp/Teach | G9: 536840
A10: 2017 | B10: Amherst - Fire/Pol | C10: 336060 | E10: 2016 | F10: Amherst - Fire/Pol | G10: 318016
A11: 2017 | B11: Amherst Sd - (Sau 39) | C11: 1464946 | E11: 2016 | F11: Amherst Sd - (Sau 39) | G11: 1467727
A12: 2017 | B12: Andover - Police | C12: 13500 | E12: 2016 | F12: Andover - Police | G12: 12592
A13: 2017 | B13: Andover Sd - (Sau 46) | C13: 187775 | E13: 2016 | F13: Andover Sd - (Sau 46) | G13: 187415
... A47: 2017 | B47: Brentwood Sd - (Sau 16) | C47: 251579 | E47: 2016 | F47: Brentwood Sd - (Sau 16) | G47: 248273
A48: 2017 | B48: Bridgewater - Police/Fire | C48: 0 | E48: 2016 | F48: Bridgewater - Police/Fire
A49: 2017 | B49: Bristol - Emp/Fire/Pol | C49: 306943 | E49: 2016 | F49: Bristol - Emp/Fire/Pol | G49: 312518
A50: 2017 | B50: Brookline - Emp/Fire/Pol | C50: 213878 | E50: 2016 | F50: Brookline - Emp/Fire/Pol | G50: 188256
A51: 2017 | B51: Brookline Public Library - Emp | C51: 9365 | E51: 2016 | F51: Brookline Public Library - Emp | G51: 6475
A52: 2017 | B52: Brookline Sd - (Sau 41) | C52: 466463 | E52: 2016 | F52: Brookline Sd - (Sau 41) | G52: 448251
A53: 2017 | B53: Campton - Emp/Pol | C53: 119923 | E53: 2016 | F53: Campton - Emp/Pol | G53: 107119
A54: 2017 | B54: Campton Sd - (Sau 48) | C54: 328072 | E54: 2016 | F54: Campton Sd - (Sau 48) | G54: 338384
A55: 2017 | B55: Campton/Thornton Fire Dept | C55: 57171 | E55: 2016 | F55: Campton/Thornton Fire Dept | G55: 40123
A56: 2017 | B56: Canaan - Emp/Pol | C56: 154276 | E56: 2016 | F56: Canaan - Emp/Pol | G56: 147461
A57: 2017 | B57: Candia - Police | C57: 90478 | E57: 2016 | F57: Candia - Police | G57: 88790
A58: 2017 | B58: Candia Sd - (Sau 15) | C58: 283200 | E58: 2016 | F58: Candia Sd - (Sau 15) | G58: 283800
A59: 2017 | B59: Canterbury - Emp/Pol/Fire | C59: 65277 | E59: 2016 | F59: Canterbury - Emp/Pol/Fire | G59: 54050
A60: 2017 | B60: Carroll - Emp/Fire/Pol | C60: 101054 | E60: 2016 | F60: Carroll - Emp/Fire/Pol | G60: 96669
A61: 2017 | B61: Carroll County - Emp/Pol | C61: 1174965 | E61: 2016 | F61: Carroll County - Emp/Pol | G61: 1057195
A62: 2017 | B62: Center Conway Fire Precinct | C62: 13755 | E62: 2016 | F62: Center Conway Fire Precinct
A63: 2017 | B63: Center Harbor - Police | C63: 50019 | E63: 2016 | F63: Center Harbor - Police | G63: 48800
A64: 2017 | B64: Central Hooksett Water Precnct | C64: 19331 | E64: 2016 | F64: Central Hooksett Water Precnct | G64: 15633
A65: 2017 | B65: Charlestown - Emp/Pol | C65: 159025 | E65: 2016 | F65: Charlestown - Emp/Pol | G65: 135404
A66: 2017 | B66: Cheshire County - Emp/Pol | C66: 1823297 | E66: 2016 | F66: Cheshire County - Emp/Pol | G66: 1780113
A67: 2017 | B67: Chester - Emp/Fire/Pol | C67: 179631 | E67: 2016 | F67: Chester - Emp/Fire/Pol | G67: 165260
A68: 2017 | B68: Chester Sd - (Sau 82) | C68: 403597 | E68: 2016 | F68: Chester Sd - (Sau 82) | G68: 386956
A69: 2017 | B69: Chesterfield - Emp/Pol | C69: 126971 | E69: 2016 | F69: Chesterfield - Emp/Pol | G69: 125610
A70: 2017 | B70: Chesterfield Sd - (Sau 29) | C70: 235678 | E70: 2016 | F70: Chesterfield Sd - (Sau 29) | G70: 226953
A71: 2017 | B71: Chichester - Emp/Pol | C71: 88266 | E71: 2016 | F71: Chichester - Emp/Pol | G71: 72074
A72: 2017 | B72: Chichester Sd - (Sau 53) | C72: 230158 | E72: 2016 | F72: Chichester Sd - (Sau 53) | G72: 230692
A73: 2017 | B73: Claremont - Emp/Fire/Pol | C73: 1033810 | E73: 2016 | F73: Claremont - Emp/Fire/Pol | G73: 1015464
...

Sheet 2015
A1: Year | B1: district_name | C1: district_contributions
A2: 2015 | B2: ALBANY - EMP | C2: 4273.25
A3: 2015 | B3: ALEXANDRIA - EMP/POL | C3: 35431.44
A4: 2015 | B4: ALLENSTOWN - EMP/FIRE/POL | C4: 185934.67
A5: 2015 | B5: ALLENSTOWN SD - (SAU 53) | C5: 300445.41
A6: 2015 | B6: ALLENSTOWN SEWER COMMISSION | C6: 40260.82
A7: 2015 | B7: ALSTEAD - POLICE | C7: 17607.59
A8: 2015 | B8: ALTON - EMP/FIRE/POL | C8: 384134.46
A9: 2015 | B9: ALTON SD - EMP/TEACH | C9: 500661.01
A10: 2015 | B10: AMHERST - FIRE/POL | C10: 272728.94
A11: 2015 | B11: AMHERST SD - (SAU 39) | C11: 1375117.6
A12: 2015 | B12: ANDOVER - POLICE | C12: 11930.06
A13: 2015 | B13: ANDOVER SD - (SAU 46) | C13: 165748.54
... A478: 2015 | B478: WOODSVILLE WATER & LIGHT DEPT | C478: 39776.86
B480: Summed Figures | C480: =SUM(C2:C478) -> 3.3548814e+08
B482: GASB 68 Numbers | C482: 335488145
B484: Check | C484: =C480-C482 -> -0.10999966

Sheet NCES Match -->

Sheet LEAID Match
A1: district_name_standardized | B1: LEAID
A2: Allenstown SD | B2: 3301380
A3: Alton SD | B3: 3301440
A4: Amherst SD | B4: 3399939
A5: Andover SD | B5: 3301500
A6: Ashland SD | B6: 3301560
A7: Auburn SD | B7: 3301590
A8: Barnstead SD | B8: 3301620
A9: Barrington SD | B9: 3301650
A10: Bartlett SD | B10: 3301680
A11: Bath SD | B11: 3301710
A12: Bedford SD | B12: 3301740
A13: Bethlehem SD | B13: 3301890
... A129: Raymond SD | B129: 3305880
A130: Rivendell Interstate SD
A131: Rochester SD | B131: 3305940
A132: Rollinsford SD | B132: 3305970
A133: Rumney SD | B133: 3306000
A134: Rye SD | B134: 3306030
A135: Salem SD | B135: 3306060
A136: Sanborn Regional SD | B136: 3306080
A137: Sau 10 (Derry Coop Sd) | B137: 3302610
A138: Sau 54 (Rochester Sd) | B138: 3305940
A139: Seabrook SD | B139: 3306150
A140: Shaker Regional Sd - (Sau 80) | B140: 3306180
A141: Somersworth SD | B141: 3306240
A142: Souhegan Coop SD | B142: 3306260
... A168: Winnisquam Reg Sd | B168: 3307300
