Workbook
Name AZ: #REF!
Name DISTRICT_TEMP: #REF!

Sheet Final
A1: LEAID | B1: Year | C1: employer_code | D1: State | E1: state_abv | F1: standardized_employer_name | G1: employer_name | H1: district_contributions | I1: LEAID Match | J1: state_contributions | K1: total_contributions
B2: 2015 | C2: 100000 | D2: Arizona | E2: AZ | F2: Arizona Department of Administration | G2: Arizona Department Of Administration | H2: 3731576 | I2: =IFERROR(VLOOKUP(Final!F2,'LEAID Match'!$A$2:$B$374,2,FALSE),"") | K2: =SUM(H2,J2) -> 3731576
B3: 2016 | C3: 100000 | D3: Arizona | E3: AZ | F3: Arizona Department of Administration | G3: Arizona Department Of Administration | H3: 3519985 | I3: =IFERROR(VLOOKUP(Final!F3,'LEAID Match'!$A$2:$B$374,2,FALSE),"") | K3: =SUM(H3,J3) -> 3519985
B4: 2017 | C4: 100000 | D4: Arizona | E4: AZ | F4: Arizona Department of Administration | G4: Arizona Department of Administration | H4: 3638820 | I4: =IFERROR(VLOOKUP(Final!F4,'LEAID Match'!$A$2:$B$374,2,FALSE),"") | K4: =SUM(H4,J4) -> 3638820
B5: 2018 | C5: 100000 | D5: Arizona | E5: AZ | F5: Arizona Department of Administration | G5: Arizona Department of Administratio | H5: 3590201 | I5: =IFERROR(VLOOKUP(Final!F5,'LEAID Match'!$A$2:$B$374,2,FALSE),"") | K5: =SUM(H5,J5) -> 3590201
B6: 2019 | C6: 100000 | D6: Arizona | E6: AZ | F6: Arizona Department of Administration | G6: Arizona Department of Administration | H6: 3635238 | I6: =IFERROR(VLOOKUP(Final!F6,'LEAID Match'!$A$2:$B$374,2,FALSE),"") | K6: =SUM(H6,J6) -> 3635238
B7: 2020 | C7: 100000 | D7: Arizona | E7: AZ | F7: Arizona Department of Administration | G7: Arizona Department of Administration | H7: 3841165 | I7: =IFERROR(VLOOKUP(Final!F7,'LEAID Match'!$A$2:$B$374,2,FALSE),"") | K7: =SUM(H7,J7) -> 3841165
B8: 2021 | C8: 100000 | D8: Arizona | E8: AZ | F8: Arizona Department of Administration | G8: Arizona Department of Administration | H8: 4064362 | I8: =IFERROR(VLOOKUP(Final!F8,'LEAID Match'!$A$2:$B$374,2,FALSE),"") | K8: =SUM(H8,J8) -> 4064362
B9: 2022 | C9: 100000 | D9: Arizona | E9: AZ | F9: Arizona Department of Administration | G9: Arizona Department of Administration | H9: 4081015 | I9: =IFERROR(VLOOKUP(Final!F9,'LEAID Match'!$A$2:$B$374,2,FALSE),"") | K9: =SUM(H9,J9) -> 4081015
B10: 2023 | C10: 100000 | D10: Arizona | E10: AZ | F10: Arizona Department of Administration | G10: Arizona Department of Administration | H10: 5043498 | I10: =IFERROR(VLOOKUP(Final!F10,'LEAID Match'!$A$2:$B$374,2,FALSE),"") | K10: =SUM(H10,J10) -> 5043498
B11: 2015 | C11: 101030 | D11: Arizona | E11: AZ | F11: Arizona State Personnel Board | G11: Arizona Personnel Board | H11: 11736 | I11: =IFERROR(VLOOKUP(Final!F11,'LEAID Match'!$A$2:$B$374,2,FALSE),"") | K11: =SUM(H11,J11) -> 11736
B12: 2016 | C12: 101030 | D12: Arizona | E12: AZ | F12: Arizona State Personnel Board | G12: Arizona Personnel Board | H12: 11889 | I12: =IFERROR(VLOOKUP(Final!F12,'LEAID Match'!$A$2:$B$374,2,FALSE),"") | K12: =SUM(H12,J12) -> 11889
B13: 2017 | C13: 101030 | D13: Arizona | E13: AZ | F13: Arizona State Personnel Board | G13: Arizona State Personnel Board | H13: 12065 | I13: =IFERROR(VLOOKUP(Final!F13,'LEAID Match'!$A$2:$B$374,2,FALSE),"") | K13: =SUM(H13,J13) -> 12065
... B55: 2023 | C55: 101150 | D55: Arizona | E55: AZ | F55: Arizona Court of Appeals Division Two | G55: Arizona Court of Appeals Division Two | H55: 279134 | I55: =IFERROR(VLOOKUP(Final!F55,'LEAID Match'!$A$2:$B$374,2,FALSE),"") | K55: =SUM(H55,J55) -> 279134
A56: 400836 | B56: 2015 | C56: 101170 | D56: Arizona | E56: AZ | F56: Arizona Supreme Court | G56: Arizona Supreme Court | H56: 2617136 | I56: =IFERROR(VLOOKUP(Final!F56,'LEAID Match'!$A$2:$B$374,2,FALSE),"") -> 400836 | K56: =SUM(H56,J56) -> 2617136
A57: 400836 | B57: 2016 | C57: 101170 | D57: Arizona | E57: AZ | F57: Arizona Supreme Court | G57: Arizona Supreme Court | H57: 2676023 | I57: =IFERROR(VLOOKUP(Final!F57,'LEAID Match'!$A$2:$B$374,2,FALSE),"") -> 400836 | K57: =SUM(H57,J57) -> 2676023
A58: 400836 | B58: 2017 | C58: 101170 | D58: Arizona | E58: AZ | F58: Arizona Supreme Court | G58: Arizona Supreme Court | H58: 2829783 | I58: =IFERROR(VLOOKUP(Final!F58,'LEAID Match'!$A$2:$B$374,2,FALSE),"") -> 400836 | K58: =SUM(H58,J58) -> 2829783
A59: 400836 | B59: 2018 | C59: 101170 | D59: Arizona | E59: AZ | F59: Arizona Supreme Court | G59: Arizona Supreme Court | H59: 2975713 | I59: =IFERROR(VLOOKUP(Final!F59,'LEAID Match'!$A$2:$B$374,2,FALSE),"") -> 400836 | K59: =SUM(H59,J59) -> 2975713
A60: 400836 | B60: 2019 | C60: 101170 | D60: Arizona | E60: AZ | F60: Arizona Supreme Court | G60: Arizona Supreme Court | H60: 3092437 | I60: =IFERROR(VLOOKUP(Final!F60,'LEAID Match'!$A$2:$B$374,2,FALSE),"") -> 400836 | K60: =SUM(H60,J60) -> 3092437
A61: 400836 | B61: 2020 | C61: 101170 | D61: Arizona | E61: AZ | F61: Arizona Supreme Court | G61: Arizona Supreme Court | H61: 3364390 | I61: =IFERROR(VLOOKUP(Final!F61,'LEAID Match'!$A$2:$B$374,2,FALSE),"") -> 400836 | K61: =SUM(H61,J61) -> 3364390
A62: 400836 | B62: 2021 | C62: 101170 | D62: Arizona | E62: AZ | F62: Arizona Supreme Court | G62: Arizona Supreme Court | H62: 3550057 | I62: =IFERROR(VLOOKUP(Final!F62,'LEAID Match'!$A$2:$B$374,2,FALSE),"") -> 400836 | K62: =SUM(H62,J62) -> 3550057
A63: 400836 | B63: 2022 | C63: 101170 | D63: Arizona | E63: AZ | F63: Arizona Supreme Court | G63: Arizona Supreme Court | H63: 3669397 | I63: =IFERROR(VLOOKUP(Final!F63,'LEAID Match'!$A$2:$B$374,2,FALSE),"") -> 400836 | K63: =SUM(H63,J63) -> 3669397
A64: 400836 | B64: 2023 | C64: 101170 | D64: Arizona | E64: AZ | F64: Arizona Supreme Court | G64: Arizona Supreme Court | H64: 4187131 | I64: =IFERROR(VLOOKUP(Final!F64,'LEAID Match'!$A$2:$B$374,2,FALSE),"") -> 400836 | K64: =SUM(H64,J64) -> 4187131
B65: 2015 | C65: 101190 | D65: Arizona | E65: AZ | F65: Arizona Criminal Justice Commission | G65: Arizona Criminal Justice Commission | H65: 151115 | I65: =IFERROR(VLOOKUP(Final!F65,'LEAID Match'!$A$2:$B$374,2,FALSE),"") | K65: =SUM(H65,J65) -> 151115
B66: 2016 | C66: 101190 | D66: Arizona | E66: AZ | F66: Arizona Criminal Justice Commission | G66: Arizona Criminal Justice Commission | H66: 144532 | I66: =IFERROR(VLOOKUP(Final!F66,'LEAID Match'!$A$2:$B$374,2,FALSE),"") | K66: =SUM(H66,J66) -> 144532
B67: 2017 | C67: 101190 | D67: Arizona | E67: AZ | F67: Arizona Criminal Justice Commission | G67: Arizona Criminal Justice Commission | H67: 141505 | I67: =IFERROR(VLOOKUP(Final!F67,'LEAID Match'!$A$2:$B$374,2,FALSE),"") | K67: =SUM(H67,J67) -> 141505
B68: 2018 | C68: 101190 | D68: Arizona | E68: AZ | F68: Arizona Criminal Justice Commission | G68: Arizona Criminal Justice Commission | H68: 143946 | I68: =IFERROR(VLOOKUP(Final!F68,'LEAID Match'!$A$2:$B$374,2,FALSE),"") | K68: =SUM(H68,J68) -> 143946
B69: 2019 | C69: 101190 | D69: Arizona | E69: AZ | F69: Arizona Criminal Justice Commission | G69: Arizona Criminal Justice Commission | H69: 135242 | I69: =IFERROR(VLOOKUP(Final!F69,'LEAID Match'!$A$2:$B$374,2,FALSE),"") | K69: =SUM(H69,J69) -> 135242
B70: 2020 | C70: 101190 | D70: Arizona | E70: AZ | F70: Arizona Criminal Justice Commission | G70: Arizona Criminal Justice Commission | H70: 148711 | I70: =IFERROR(VLOOKUP(Final!F70,'LEAID Match'!$A$2:$B$374,2,FALSE),"") | K70: =SUM(H70,J70) -> 148711
B71: 2021 | C71: 101190 | D71: Arizona | E71: AZ | F71: Arizona Criminal Justice Commission | G71: Arizona Criminal Justice Commission | H71: 167453 | I71: =IFERROR(VLOOKUP(Final!F71,'LEAID Match'!$A$2:$B$374,2,FALSE),"") | K71: =SUM(H71,J71) -> 167453
B72: 2022 | C72: 101190 | D72: Arizona | E72: AZ | F72: Arizona Criminal Justice Commission | G72: Arizona Criminal Justice Commission | H72: 170486 | I72: =IFERROR(VLOOKUP(Final!F72,'LEAID Match'!$A$2:$B$374,2,FALSE),"") | K72: =SUM(H72,J72) -> 170486
B73: 2023 | C73: 101190 | D73: Arizona | E73: AZ | F73: Arizona Criminal Justice Commission | G73: Arizona Criminal Justice Commission | H73: 185626 | I73: =IFERROR(VLOOKUP(Final!F73,'LEAID Match'!$A$2:$B$374,2,FALSE),"") | K73: =SUM(H73,J73) -> 185626
B74: 2015 | C74: 101400 | D74: Arizona | E74: AZ | F74: Arizona Governor's Office | G74: Arizona Governor's Office | H74: 746406 | I74: =IFERROR(VLOOKUP(Final!F74,'LEAID Match'!$A$2:$B$374,2,FALSE),"") | K74: =SUM(H74,J74) -> 746406
B75: 2016 | C75: 101400 | D75: Arizona | E75: AZ | F75: Arizona Governor's Office | G75: Arizona Governor's Office | H75: 685628 | I75: =IFERROR(VLOOKUP(Final!F75,'LEAID Match'!$A$2:$B$374,2,FALSE),"") | K75: =SUM(H75,J75) -> 685628
B76: 2017 | C76: 101400 | D76: Arizona | E76: AZ | F76: Arizona Governor's Office | G76: Arizona Governor's Office | H76: 751445 | I76: =IFERROR(VLOOKUP(Final!F76,'LEAID Match'!$A$2:$B$374,2,FALSE),"") | K76: =SUM(H76,J76) -> 751445
... B82: 2023 | C82: 101400 | D82: Arizona | E82: AZ | F82: Arizona Governor's Office | G82: Arizona Governor's Office | H82: 1034084 | I82: =IFERROR(VLOOKUP(Final!F82,'LEAID Match'!$A$2:$B$374,2,FALSE),"") | K82: =SUM(H82,J82) -> 1034084
B83: 2015 | C83: 101410 | D83: Arizona | E83: AZ | F83: Arizona Office of Equal Opportunity | G83: Arizona Office Of Equal Opportunity | I83: =IFERROR(VLOOKUP(Final!F83,'LEAID Match'!$A$2:$B$374,2,FALSE),"") | K83: =SUM(H83,J83) -> 0
B84: 2016 | C84: 101410 | D84: Arizona | E84: AZ | F84: Arizona Office of Equal Opportunity | G84: Arizona Office Of Equal Opportunity | I84: =IFERROR(VLOOKUP(Final!F84,'LEAID Match'!$A$2:$B$374,2,FALSE),"") | K84: =SUM(H84,J84) -> 0
B85: 2017 | C85: 101410 | D85: Arizona | E85: AZ | F85: Arizona Office of Equal Opportunity | G85: Arizona Office of Equal Opportunity | I85: =IFERROR(VLOOKUP(Final!F85,'LEAID Match'!$A$2:$B$374,2,FALSE),"") | K85: =SUM(H85,J85) -> 0
B86: 2018 | C86: 101410 | D86: Arizona | E86: AZ | F86: Arizona Office of Equal Opportunity | G86: Arizona Office of Equal Opportunity | I86: =IFERROR(VLOOKUP(Final!F86,'LEAID Match'!$A$2:$B$374,2,FALSE),"") | K86: =SUM(H86,J86) -> 0
...

Sheet Dataset Checks & NCES Match -->

Sheet Contributions Check
A1: Employer Contribution Check
A2: Year | B2: Reported Total | C2: Total From Formula | D2: Difference
A3: 2015 | B3: 1003030750 | C3: =SUMIF(Final!B$2:B$6407,'Contributions Check'!A3,Final!H$2:H$6407) -> 1003030750 | D3: =B3-C3 -> 0
A4: 2016 | B4: 1015920247 | C4: =SUMIF(Final!B$2:B$6407,'Contributions Check'!A4,Final!H$2:H$6407) -> 1015920247 | D4: =B4-C4 -> 0
A5: 2017 | B5: 1051469476 | C5: =SUMIF(Final!B$2:B$6407,'Contributions Check'!A5,Final!H$2:H$6407) -> 1051469476 | D5: =B5-C5 -> 0
A6: 2018 | B6: 1083432138 | C6: =SUMIF(Final!B$2:B$6407,'Contributions Check'!A6,Final!H$2:H$6407) -> 1083432138 | D6: =B6-C6 -> 0
A7: 2019 | B7: 1179092833 | C7: =SUMIF(Final!B$2:B$6407,'Contributions Check'!A7,Final!H$2:H$6407) -> 1179092833 | D7: =B7-C7 -> 0
A8: 2020 | B8: 1251493308 | C8: =SUMIF(Final!B$2:B$6407,'Contributions Check'!A8,Final!H$2:H$6407) -> 1251493308 | D8: =B8-C8 -> 0
A9: 2021 | B9: 1309666248 | C9: =SUMIF(Final!B$2:B$6407,'Contributions Check'!A9,Final!H$2:H$6407) -> 1309666244 | D9: =B9-C9 -> 4
A10: 2022 | B10: 1429670650 | C10: =SUMIF(Final!B$2:B$6407,'Contributions Check'!A10,Final!H$2:H$6407) -> 1429670650 | D10: =B10-C10 -> 0
A11: 2023 | B11: 1556007811 | C11: =SUMIF(Final!B$2:B$6407,'Contributions Check'!A11,Final!H$2:H$6407) -> 1556007811 | D11: =B11-C11 -> 0

Sheet LEAID Match
A1: standardized_employer_name | B1: LEAID
A2: Cave Creek Unified School District No. 93 | B2: 400001
A3: Clarkdale-Jerome Elementary School District #3 | B3: 400004
A4: Salome Consolidated Elementary School District #30 | B4: 400005
A5: Pine Forest Charter School | B5: 400018
A6: Flagstaff Arts And Leadership Academy | B6: 400019
A7: Colorado City Unified School District #14 | B7: 400021
A8: Vernon Elementary School District #9 | B8: 400022
A9: Pinon Unified School District #4 | B9: 400023
A10: Heber-Overgaard Unified School District #6 | B10: 400026
A11: Triumphant Learning Center | B11: 400028
A12: Ridgeline Academy | B12: 400031
A13: STEP UP School | B13: 400040
... A374: Sedona-Oak Creek Unified School District #9 | B374: 409733
A375: Arizona Charter Academy
A376: Arizona Community Development Corporation (La Paloma Academy)
A377: Arts Academy at Estrella Mountain
A378: Chino Valley Unified School District #51
A379: Desert Mosaic School
A380: Edkey (Arizona Conservatory for Arts and Academics)
A381: Ehrenberg Improvement District
A382: Grand Canyon College Preparatory Charter School
A383: Intelli-School (Paradise Valley)
A384: Navajo County Arizona - Hope School
A385: Navajo County Arizona - Special Services Consortium
A386: Northern Arizona Academy for Career Development
... A397: Willow Creek Charter

Sheet Old Data -->

Sheet Data As Collected
A1: year | B1: employer_code | C1: employer_name | D1: employer_contribution | E1: allocation_percentage
A2: 2015 | B2: 102300 | C2: A H C C C S | D2: 4565257 | E2: 0.0045515
A3: 2015 | B3: 307810 | C3: AAEC Paradise Valley | D3: 478197 | E3: 0.0004768
A4: 2015 | B4: 307850 | C4: Academy Of Excellence | D4: 28397 | E4: 2.83e-05
A5: 2015 | B5: 450540 | C5: Academy Of Tucson | D5: 263201 | E5: 0.0002624
A6: 2015 | B6: 307940 | C6: Accelerated Elem And Secondary Schls | D6: 66764 | E6: 6.66e-05
A7: 2015 | B7: 303320 | C7: Accelerated Learning Center | D7: 77520 | E7: 7.73e-05
A8: 2015 | B8: 307490 | C8: ACCLAIM Charter School (ACCLAIM Academy) | D8: 134215 | E8: 0.0001338
A9: 2015 | B9: 302160 | C9: Agua Fria Union High Sch Dist 216 | D9: 3407931 | E9: 0.0033976
A10: 2015 | B10: 300630 | C10: Aguila School District 63 | D10: 98855 | E10: 9.86e-05
A11: 2015 | B11: 302310 | C11: AIBT Chtr HS (RCB Medical Arts Academy) | D11: 70606 | E11: 7.04e-05
A12: 2015 | B12: 450150 | C12: Ajo USD | D12: 212251 | E12: 0.0002116
A13: 2015 | B13: 302800 | C13: Akimel O'Otham Pee Posh Chtr Schl (3-5) | D13: 24816 | E13: 2.47e-05
... A56: 2015 | B56: 103830 | C56: Arizona Board Of Physical Therapy | D56: 20761 | E56: 2.07e-05
A57: 2015 | B57: 109220 | C57: Arizona CapPostConvictionPublic Defender | E57: 0
A58: 2015 | B58: 495900 | C58: Arizona City Sanitary District | D58: 58187 | E58: 5.8e-05
A59: 2015 | B59: 102100 | C59: Arizona Comm For Deaf & Hard Of Hearing | D59: 87962 | E59: 8.77e-05
A60: 2015 | B60: 109030 | C60: Arizona Comm For Postsecondary Educ ation | D60: 36425 | E60: 3.63e-05
A61: 2015 | B61: 104820 | C61: Arizona Commission On The Arts | D61: 56835 | E61: 5.67e-05
A62: 2015 | B62: 103250 | C62: Arizona Corporation Commission | D62: 1632964 | E62: 0.001628
A63: 2015 | B63: 109270 | C63: Arizona Cotton Research & Protection | D63: 105805 | E63: 0.0001055
A64: 2015 | B64: 497380 | C64: Arizona Counties Insurance Pool | D64: 89528 | E64: 8.93e-05
A65: 2015 | B65: 101140 | C65: Arizona Court Of Appeals Division One | D65: 348019 | E65: 0.000347
A66: 2015 | B66: 101150 | C66: Arizona Court Of Appeals Division Two | D66: 161378 | E66: 0.0001609
A67: 2015 | B67: 101190 | C67: Arizona Criminal Justice Commission | D67: 151115 | E67: 0.0001507
A68: 2015 | B68: 100000 | C68: Arizona Department Of Administration | D68: 3731576 | E68: 0.0037203
A69: 2015 | B69: 103880 | C69: Arizona Department Of Racing | D69: 143598 | E69: 0.0001432
... A99: 2015 | B99: 104920 | C99: Arizona Historical Society | D99: 173717 | E99: 0.0001732
A100: 2015 | B100: 103200 | C100: Arizona Homeopathic Medical Examiners | E100: 0
A101: 2015 | B101: 101520 | C101: Arizona House Of Representatives | D101: 650833 | E101: 0.0006489
A102: 2015 | B102: 109150 | C102: Arizona Independent Redistricting Com | D102: 27218 | E102: 2.71e-05
A103: 2015 | B103: 103500 | C103: Arizona Industrial Commission | D103: 1134350 | E103: 0.0011309
A104: 2015 | B104: 495300 | C104: Arizona Interscholastic Association | D104: 148014 | E104: 0.0001476
A105: 2015 | B105: 101540 | C105: Arizona Joint Legislative Budget Commit | D105: 161433 | E105: 0.0001609
A106: 2015 | B106: 101470 | C106: Arizona Law Enforc ement Merit SysCouncil | E106: 0
A107: 2015 | B107: 101530 | C107: Arizona Legislative Council | D107: 335529 | E107: 0.0003345
A108: 2015 | B108: 103610 | C108: Arizona Lottery | D108: 421061 | E108: 0.0004198
A109: 2015 | B109: 103620 | C109: Arizona Medical Board | D109: 263790 | E109: 0.000263
A110: 2015 | B110: 495090 | C110: Arizona Municipal Water Users Assn | D110: 59547 | E110: 5.94e-05
A111: 2015 | B111: 103680 | C111: Arizona Naturopathic Phys Bd Of Med Exam | D111: 8905 | E111: 8.9e-06
...

Sheet Backup
A1: year | B1: employer_code | C1: standardized_employer_name | D1: employer_name | E1: employer_contribution | F1: allocation_percentage
A2: 2015 | B2: 102300 | C2: Arizona Health Care Cost Containment System | D2: A H C C C S | E2: 4565257 | F2: 0.0045515
A3: 2015 | B3: 307810 | C3: Arizona Agribusiness & Equine Center | D3: AAEC Paradise Valley | E3: 478197 | F3: 0.0004768
A4: 2015 | B4: 307850 | C4: Academy Of Excellence | D4: Academy Of Excellence | E4: 28397 | F4: 2.83e-05
A5: 2015 | B5: 450540 | C5: Academy Of Tucson | D5: Academy Of Tucson | E5: 263201 | F5: 0.0002624
A6: 2015 | B6: 307940 | C6: Accelerated Elementary and Secondary Schools | D6: Accelerated Elem And Secondary Schls | E6: 66764 | F6: 6.66e-05
A7: 2015 | B7: 303320 | C7: Accelerated Learning Center | D7: Accelerated Learning Center | E7: 77520 | F7: 7.73e-05
A8: 2015 | B8: 307490 | C8: Acclaim Charter School | D8: ACCLAIM Charter School (ACCLAIM Academy) | E8: 134215 | F8: 0.0001338
A9: 2015 | B9: 302160 | C9: Agua Fria Union High School District #216 | D9: Agua Fria Union High Sch Dist 216 | E9: 3407931 | F9: 0.0033976
A10: 2015 | B10: 300630 | C10: Aguila Elementary School District #63 | D10: Aguila School District 63 | E10: 98855 | F10: 9.86e-05
A11: 2015 | B11: 302310 | C11: AIBT Non-Profit Charter High School | D11: AIBT Chtr HS (RCB Medical Arts Academy) | E11: 70606 | F11: 7.04e-05
A12: 2015 | B12: 450150 | C12: Ajo Unified School District | D12: Ajo USD | E12: 212251 | F12: 0.0002116
A13: 2015 | B13: 302800 | C13: Akimel O'Otham Pee Posh (3-5) | D13: Akimel O'Otham Pee Posh Chtr Schl (3-5) | E13: 24816 | F13: 2.47e-05
... A56: 2015 | B56: 103830 | C56: Arizona State Board of Physical Therapy | D56: Arizona Board Of Physical Therapy | E56: 20761 | F56: 2.07e-05
A57: 2015 | B57: 109220 | C57: Arizona Capital Post Conviction Pub | D57: Arizona CapPostConvictionPublic Defender | F57: 0
A58: 2015 | B58: 495900 | C58: Arizona City Sanitary District | D58: Arizona City Sanitary District | E58: 58187 | F58: 5.8e-05
A59: 2015 | B59: 102100 | C59: Arizona Commission for the Deaf and Hard of Hearing | D59: Arizona Comm For Deaf & Hard Of Hearing | E59: 87962 | F59: 8.77e-05
A60: 2015 | B60: 109030 | C60: Arizona Commission for Postsecondary Education | D60: Arizona Comm For Postsecondary Educ ation | E60: 36425 | F60: 3.63e-05
A61: 2015 | B61: 104820 | C61: Arizona Commission on the Arts | D61: Arizona Commission On The Arts | E61: 56835 | F61: 5.67e-05
A62: 2015 | B62: 103250 | C62: Arizona Corporation Commission | D62: Arizona Corporation Commission | E62: 1632964 | F62: 0.001628
A63: 2015 | B63: 109270 | C63: Arizona Cotton Research and Protection Council | D63: Arizona Cotton Research & Protection | E63: 105805 | F63: 0.0001055
A64: 2015 | B64: 497380 | C64: Arizona Counties Insurance Pool | D64: Arizona Counties Insurance Pool | E64: 89528 | F64: 8.93e-05
A65: 2015 | B65: 101140 | C65: Arizona Court of Appeals Division One | D65: Arizona Court Of Appeals Division One | E65: 348019 | F65: 0.000347
A66: 2015 | B66: 101150 | C66: Arizona Court of Appeals Division Two | D66: Arizona Court Of Appeals Division Two | E66: 161378 | F66: 0.0001609
A67: 2015 | B67: 101190 | C67: Arizona Criminal Justice Commission | D67: Arizona Criminal Justice Commission | E67: 151115 | F67: 0.0001507
A68: 2015 | B68: 100000 | C68: Arizona Department of Administration | D68: Arizona Department Of Administration | E68: 3731576 | F68: 0.0037203
A69: 2015 | B69: 103880 | C69: Arizona Department of Gaming / Racing Division | D69: Arizona Department Of Racing | E69: 143598 | F69: 0.0001432
... A99: 2015 | B99: 104920 | C99: Arizona Historical Society | D99: Arizona Historical Society | E99: 173717 | F99: 0.0001732
A100: 2015 | B100: 103200 | C100: Arizona Board of Homeopathic and Integrated Medicine Examiners | D100: Arizona Homeopathic Medical Examiners | F100: 0
A101: 2015 | B101: 101520 | C101: Arizona House of Representatives | D101: Arizona House Of Representatives | E101: 650833 | F101: 0.0006489
A102: 2015 | B102: 109150 | C102: Arizona Independent Redistricting Commission | D102: Arizona Independent Redistricting Com | E102: 27218 | F102: 2.71e-05
A103: 2015 | B103: 103500 | C103: Arizona Industrial Commission | D103: Arizona Industrial Commission | E103: 1134350 | F103: 0.0011309
A104: 2015 | B104: 495300 | C104: Arizona Interscholastic Association | D104: Arizona Interscholastic Association | E104: 148014 | F104: 0.0001476
A105: 2015 | B105: 101540 | C105: Arizona Joint Legislative Budget Committee | D105: Arizona Joint Legislative Budget Commit | E105: 161433 | F105: 0.0001609
A106: 2015 | B106: 101470 | C106: Arizona Law Enforcement Merit Syste | D106: Arizona Law Enforc ement Merit SysCouncil | F106: 0
A107: 2015 | B107: 101530 | C107: Arizona Legislative Council | D107: Arizona Legislative Council | E107: 335529 | F107: 0.0003345
A108: 2015 | B108: 103610 | C108: Arizona State Lottery | D108: Arizona Lottery | E108: 421061 | F108: 0.0004198
A109: 2015 | B109: 103620 | C109: Arizona Medical Board | D109: Arizona Medical Board | E109: 263790 | F109: 0.000263
A110: 2015 | B110: 495090 | C110: Arizona Municipal Water Users Association | D110: Arizona Municipal Water Users Assn | E110: 59547 | F110: 5.94e-05
A111: 2015 | B111: 103680 | C111: Arizona Naturopathic Physicians Board of Medical Examiners | D111: Arizona Naturopathic Phys Bd Of Med Exam | E111: 8905 | F111: 8.9e-06
...
