Workbook

Sheet Summary
A1: LEAID | B1: Year | C1: employer_code | D1: State | E1: state_abv | F1: employer_name | G1: district_contributions | H1: State Sponsored Charters Marker | I1: district_cont_prop | J1: state_contributions | K1: total_contributions | L1: LEAID
A2: 0 | B2: 2015 | C2: 100 | D2: Nevada | E2: NV | F2: STATE OF NEVADA | G2: 248642575 | L2: =IFERROR(VLOOKUP(F2,'LEAID Match'!$A$2:$B$240,2,FALSE),"") -> 0
A3: 0 | B3: 2016 | C3: 100 | D3: Nevada | E3: NV | F3: STATE OF NEVADA | G3: 271203080 | L3: =IFERROR(VLOOKUP(F3,'LEAID Match'!$A$2:$B$240,2,FALSE),"") -> 0
A4: 0 | B4: 2017 | C4: 100 | D4: Nevada | E4: NV | F4: STATE OF NEVADA | G4: 148086587 | L4: =IFERROR(VLOOKUP(F4,'LEAID Match'!$A$2:$B$240,2,FALSE),"") -> 0
A5: 0 | B5: 2018 | C5: 100 | D5: Nevada | E5: NV | F5: STATE OF NEVADA | G5: 150523924 | L5: =IFERROR(VLOOKUP(F5,'LEAID Match'!$A$2:$B$240,2,FALSE),"") -> 0
A6: 0 | B6: 2019 | C6: 100 | D6: Nevada | E6: NV | F6: STATE OF NEVADA | G6: 158028122 | L6: =IFERROR(VLOOKUP(F6,'LEAID Match'!$A$2:$B$240,2,FALSE),"") -> 0
A7: 0 | B7: 2020 | C7: 100 | D7: Nevada | E7: NV | F7: STATE OF NEVADA | G7: 172683894 | L7: =IFERROR(VLOOKUP(F7,'LEAID Match'!$A$2:$B$240,2,FALSE),"") -> 0
A8: 0 | B8: 2021 | C8: 100 | D8: Nevada | E8: NV | F8: STATE OF NEVADA | G8: 171616836 | L8: =IFERROR(VLOOKUP(F8,'LEAID Match'!$A$2:$B$240,2,FALSE),"") -> 0
A9: 0 | B9: 2022 | C9: 100 | D9: Nevada | E9: NV | F9: STATE OF NEVADA | G9: 169585649 | L9: =IFERROR(VLOOKUP(F9,'LEAID Match'!$A$2:$B$240,2,FALSE),"") -> 0
A10: 0 | B10: 2023 | C10: 100 | D10: Nevada | E10: NV | F10: STATE OF NEVADA | G10: 169985319 | L10: =IFERROR(VLOOKUP(F10,'LEAID Match'!$A$2:$B$240,2,FALSE),"") -> 0
A11: 0 | B11: 2015 | C11: 161 | D11: Nevada | E11: NV | F11: NV BD OF VET MEDICAL EXAM | G11: 42671 | I11: {=_xlfn.IFS(B11=2015,G11/$H$1957,B11=2016,G11/$H$1958,B11=2017,G11/$H$1959,B11=2018,G11/$H$1960,B11=2019,G11/$H$1961,B11=2020,G11/$H$1962,B11=2021,G11/$H$1963,B11=2022,G11/$H$1964,B11=2023,G11/$H$1965)} -> 3.2953042e-05 | J11: {=_xlfn.IFS(B11=2015,I11*$G$2,B11=2016,I11*$G$3,B11=2017,I11*$G$4,B11=2018,I11*$G$5,B11=2019,I11*$G$6,B11=2020,I11*$G$7,B11=2021,I11*$G$8,B11=2022,I11*$G$9,B11=2023,I11*$G$10)} -> 8193.5292 | K11: =SUM(G11,J11) -> 50864.529 | L11: =IFERROR(VLOOKUP(F11,'LEAID Match'!$A$2:$B$240,2,FALSE),"") -> 0
A12: 0 | B12: 2016 | C12: 161 | D12: Nevada | E12: NV | F12: NV BD OF VET MEDICAL EXAM | G12: 53794 | I12: {=_xlfn.IFS(B12=2015,G12/$H$1957,B12=2016,G12/$H$1958,B12=2017,G12/$H$1959,B12=2018,G12/$H$1960,B12=2019,G12/$H$1961,B12=2020,G12/$H$1962,B12=2021,G12/$H$1963,B12=2022,G12/$H$1964,B12=2023,G12/$H$1965)} -> 3.7763365e-05 | J12: {=_xlfn.IFS(B12=2015,I12*$G$2,B12=2016,I12*$G$3,B12=2017,I12*$G$4,B12=2018,I12*$G$5,B12=2019,I12*$G$6,B12=2020,I12*$G$7,B12=2021,I12*$G$8,B12=2022,I12*$G$9,B12=2023,I12*$G$10)} -> 10241.541 | K12: =SUM(G12,J12) -> 64035.541 | L12: =IFERROR(VLOOKUP(F12,'LEAID Match'!$A$2:$B$240,2,FALSE),"") -> 0
A13: 0 | B13: 2017 | C13: 161 | D13: Nevada | E13: NV | F13: NV BD OF VET MEDICAL EXAM | G13: 26984 | I13: {=_xlfn.IFS(B13=2015,G13/$H$1957,B13=2016,G13/$H$1958,B13=2017,G13/$H$1959,B13=2018,G13/$H$1960,B13=2019,G13/$H$1961,B13=2020,G13/$H$1962,B13=2021,G13/$H$1963,B13=2022,G13/$H$1964,B13=2023,G13/$H$1965)} -> 3.6002398e-05 | J13: {=_xlfn.IFS(B13=2015,I13*$G$2,B13=2016,I13*$G$3,B13=2017,I13*$G$4,B13=2018,I13*$G$5,B13=2019,I13*$G$6,B13=2020,I13*$G$7,B13=2021,I13*$G$8,B13=2022,I13*$G$9,B13=2023,I13*$G$10)} -> 5331.4723 | K13: =SUM(G13,J13) -> 32315.472 | L13: =IFERROR(VLOOKUP(F13,'LEAID Match'!$A$2:$B$240,2,FALSE),"") -> 0
A14: 0 | B14: 2018 | C14: 161 | D14: Nevada | E14: NV | F14: NV BD OF VET MEDICAL EXAM | G14: 26202 | I14: {=_xlfn.IFS(B14=2015,G14/$H$1957,B14=2016,G14/$H$1958,B14=2017,G14/$H$1959,B14=2018,G14/$H$1960,B14=2019,G14/$H$1961,B14=2020,G14/$H$1962,B14=2021,G14/$H$1963,B14=2022,G14/$H$1964,B14=2023,G14/$H$1965)} -> 3.3714387e-05 | J14: {=_xlfn.IFS(B14=2015,I14*$G$2,B14=2016,I14*$G$3,B14=2017,I14*$G$4,B14=2018,I14*$G$5,B14=2019,I14*$G$6,B14=2020,I14*$G$7,B14=2021,I14*$G$8,B14=2022,I14*$G$9,B14=2023,I14*$G$10)} -> 5074.8218 | K14: =SUM(G14,J14) -> 31276.822 | L14: =IFERROR(VLOOKUP(F14,'LEAID Match'!$A$2:$B$240,2,FALSE),"") -> 0
A15: 0 | B15: 2019 | C15: 161 | D15: Nevada | E15: NV | F15: NV BD OF VET MEDICAL EXAM | G15: 27126 | I15: {=_xlfn.IFS(B15=2015,G15/$H$1957,B15=2016,G15/$H$1958,B15=2017,G15/$H$1959,B15=2018,G15/$H$1960,B15=2019,G15/$H$1961,B15=2020,G15/$H$1962,B15=2021,G15/$H$1963,B15=2022,G15/$H$1964,B15=2023,G15/$H$1965)} -> 3.3712102e-05 | J15: {=_xlfn.IFS(B15=2015,I15*$G$2,B15=2016,I15*$G$3,B15=2017,I15*$G$4,B15=2018,I15*$G$5,B15=2019,I15*$G$6,B15=2020,I15*$G$7,B15=2021,I15*$G$8,B15=2022,I15*$G$9,B15=2023,I15*$G$10)} -> 5327.4602 | K15: =SUM(G15,J15) -> 32453.46 | L15: =IFERROR(VLOOKUP(F15,'LEAID Match'!$A$2:$B$240,2,FALSE),"") -> 0
A16: 0 | B16: 2020 | C16: 161 | D16: Nevada | E16: NV | F16: NV BD OF VET MEDICAL EXAM | G16: 27091 | I16: {=_xlfn.IFS(B16=2015,G16/$H$1957,B16=2016,G16/$H$1958,B16=2017,G16/$H$1959,B16=2018,G16/$H$1960,B16=2019,G16/$H$1961,B16=2020,G16/$H$1962,B16=2021,G16/$H$1963,B16=2022,G16/$H$1964,B16=2023,G16/$H$1965)} -> 3.1159076e-05 | J16: {=_xlfn.IFS(B16=2015,I16*$G$2,B16=2016,I16*$G$3,B16=2017,I16*$G$4,B16=2018,I16*$G$5,B16=2019,I16*$G$6,B16=2020,I16*$G$7,B16=2021,I16*$G$8,B16=2022,I16*$G$9,B16=2023,I16*$G$10)} -> 5380.6706 | K16: =SUM(G16,J16) -> 32471.671 | L16: =IFERROR(VLOOKUP(F16,'LEAID Match'!$A$2:$B$240,2,FALSE),"") -> 0
A17: 0 | B17: 2021 | C17: 161 | D17: Nevada | E17: NV | F17: NV BD OF VET MEDICAL EXAM | G17: 25012 | I17: {=_xlfn.IFS(B17=2015,G17/$H$1957,B17=2016,G17/$H$1958,B17=2017,G17/$H$1959,B17=2018,G17/$H$1960,B17=2019,G17/$H$1961,B17=2020,G17/$H$1962,B17=2021,G17/$H$1963,B17=2022,G17/$H$1964,B17=2023,G17/$H$1965)} -> 2.8583586e-05 | J17: {=_xlfn.IFS(B17=2015,I17*$G$2,B17=2016,I17*$G$3,B17=2017,I17*$G$4,B17=2018,I17*$G$5,B17=2019,I17*$G$6,B17=2020,I17*$G$7,B17=2021,I17*$G$8,B17=2022,I17*$G$9,B17=2023,I17*$G$10)} -> 4905.4246 | K17: =SUM(G17,J17) -> 29917.425 | L17: =IFERROR(VLOOKUP(F17,'LEAID Match'!$A$2:$B$240,2,FALSE),"") -> 0
A18: 0 | B18: 2022 | C18: 161 | D18: Nevada | E18: NV | F18: NV BD OF VET MEDICAL EXAM | G18: 28072 | I18: {=_xlfn.IFS(B18=2015,G18/$H$1957,B18=2016,G18/$H$1958,B18=2017,G18/$H$1959,B18=2018,G18/$H$1960,B18=2019,G18/$H$1961,B18=2020,G18/$H$1962,B18=2021,G18/$H$1963,B18=2022,G18/$H$1964,B18=2023,G18/$H$1965)} -> 3.017185e-05 | J18: {=_xlfn.IFS(B18=2015,I18*$G$2,B18=2016,I18*$G$3,B18=2017,I18*$G$4,B18=2018,I18*$G$5,B18=2019,I18*$G$6,B18=2020,I18*$G$7,B18=2021,I18*$G$8,B18=2022,I18*$G$9,B18=2023,I18*$G$10)} -> 5116.7128 | K18: =SUM(G18,J18) -> 33188.713 | L18: =IFERROR(VLOOKUP(F18,'LEAID Match'!$A$2:$B$240,2,FALSE),"") -> 0
A19: 0 | B19: 2023 | C19: 161 | D19: Nevada | E19: NV | F19: NV BD OF VET MEDICAL EXAM | G19: 27823 | I19: {=_xlfn.IFS(B19=2015,G19/$H$1957,B19=2016,G19/$H$1958,B19=2017,G19/$H$1959,B19=2018,G19/$H$1960,B19=2019,G19/$H$1961,B19=2020,G19/$H$1962,B19=2021,G19/$H$1963,B19=2022,G19/$H$1964,B19=2023,G19/$H$1965)} -> 2.8170498e-05 | J19: {=_xlfn.IFS(B19=2015,I19*$G$2,B19=2016,I19*$G$3,B19=2017,I19*$G$4,B19=2018,I19*$G$5,B19=2019,I19*$G$6,B19=2020,I19*$G$7,B19=2021,I19*$G$8,B19=2022,I19*$G$9,B19=2023,I19*$G$10)} -> 4788.5711 | K19: =SUM(G19,J19) -> 32611.571 | L19: =IFERROR(VLOOKUP(F19,'LEAID Match'!$A$2:$B$240,2,FALSE),"") -> 0
A20: 0 | B20: 2015 | C20: 162 | D20: Nevada | E20: NV | F20: BD OF EXAM FOR SOC WORKER | G20: 37432 | I20: {=_xlfn.IFS(B20=2015,G20/$H$1957,B20=2016,G20/$H$1958,B20=2017,G20/$H$1959,B20=2018,G20/$H$1960,B20=2019,G20/$H$1961,B20=2020,G20/$H$1962,B20=2021,G20/$H$1963,B20=2022,G20/$H$1964,B20=2023,G20/$H$1965)} -> 2.890718e-05 | J20: {=_xlfn.IFS(B20=2015,I20*$G$2,B20=2016,I20*$G$3,B20=2017,I20*$G$4,B20=2018,I20*$G$5,B20=2019,I20*$G$6,B20=2020,I20*$G$7,B20=2021,I20*$G$8,B20=2022,I20*$G$9,B20=2023,I20*$G$10)} -> 7187.5556 | K20: =SUM(G20,J20) -> 44619.556 | L20: =IFERROR(VLOOKUP(F20,'LEAID Match'!$A$2:$B$240,2,FALSE),"") -> 0
A21: 0 | B21: 2016 | C21: 162 | D21: Nevada | E21: NV | F21: BD OF EXAM FOR SOC WORKER | G21: 41228 | I21: {=_xlfn.IFS(B21=2015,G21/$H$1957,B21=2016,G21/$H$1958,B21=2017,G21/$H$1959,B21=2018,G21/$H$1960,B21=2019,G21/$H$1961,B21=2020,G21/$H$1962,B21=2021,G21/$H$1963,B21=2022,G21/$H$1964,B21=2023,G21/$H$1965)} -> 2.8942038e-05 | J21: {=_xlfn.IFS(B21=2015,I21*$G$2,B21=2016,I21*$G$3,B21=2017,I21*$G$4,B21=2018,I21*$G$5,B21=2019,I21*$G$6,B21=2020,I21*$G$7,B21=2021,I21*$G$8,B21=2022,I21*$G$9,B21=2023,I21*$G$10)} -> 7849.1699 | K21: =SUM(G21,J21) -> 49077.17 | L21: =IFERROR(VLOOKUP(F21,'LEAID Match'!$A$2:$B$240,2,FALSE),"") -> 0
A22: 0 | B22: 2017 | C22: 162 | D22: Nevada | E22: NV | F22: BD OF EXAM FOR SOC WORKER | G22: 22999 | I22: {=_xlfn.IFS(B22=2015,G22/$H$1957,B22=2016,G22/$H$1958,B22=2017,G22/$H$1959,B22=2018,G22/$H$1960,B22=2019,G22/$H$1961,B22=2020,G22/$H$1962,B22=2021,G22/$H$1963,B22=2022,G22/$H$1964,B22=2023,G22/$H$1965)} -> 3.068556e-05 | J22: {=_xlfn.IFS(B22=2015,I22*$G$2,B22=2016,I22*$G$3,B22=2017,I22*$G$4,B22=2018,I22*$G$5,B22=2019,I22*$G$6,B22=2020,I22*$G$7,B22=2021,I22*$G$8,B22=2022,I22*$G$9,B22=2023,I22*$G$10)} -> 4544.1199 | K22: =SUM(G22,J22) -> 27543.12 | L22: =IFERROR(VLOOKUP(F22,'LEAID Match'!$A$2:$B$240,2,FALSE),"") -> 0
... A175: 0 | B175: 2020 | C175: 190 | D175: Nevada | E175: NV | F175: UNIVERSITY OF NEVADA-RENO | G175: 776 | I175: {=_xlfn.IFS(B175=2015,G175/$H$1957,B175=2016,G175/$H$1958,B175=2017,G175/$H$1959,B175=2018,G175/$H$1960,B175=2019,G175/$H$1961,B175=2020,G175/$H$1962,B175=2021,G175/$H$1963,B175=2022,G175/$H$1964,B175=2023,G175/$H$1965)} -> 8.9252678e-07 | J175: {=_xlfn.IFS(B175=2015,I175*$G$2,B175=2016,I175*$G$3,B175=2017,I175*$G$4,B175=2018,I175*$G$5,B175=2019,I175*$G$6,B175=2020,I175*$G$7,B175=2021,I175*$G$8,B175=2022,I175*$G$9,B175=2023,I175*$G$10)} -> 154.125 | K175: =SUM(G175,J175) -> 930.125 | L175: =IFERROR(VLOOKUP(F175,'LEAID Match'!$A$2:$B$240,2,FALSE),"") -> 0
A176: 0 | B176: 2021 | C176: 190 | D176: Nevada | E176: NV | F176: UNIVERSITY OF NEVADA-RENO | I176: {=_xlfn.IFS(B176=2015,G176/$H$1957,B176=2016,G176/$H$1958,B176=2017,G176/$H$1959,B176=2018,G176/$H$1960,B176=2019,G176/$H$1961,B176=2020,G176/$H$1962,B176=2021,G176/$H$1963,B176=2022,G176/$H$1964,B176=2023,G176/$H$1965)} -> 0 | J176: {=_xlfn.IFS(B176=2015,I176*$G$2,B176=2016,I176*$G$3,B176=2017,I176*$G$4,B176=2018,I176*$G$5,B176=2019,I176*$G$6,B176=2020,I176*$G$7,B176=2021,I176*$G$8,B176=2022,I176*$G$9,B176=2023,I176*$G$10)} -> 0 | K176: =SUM(G176,J176) -> 0 | L176: =IFERROR(VLOOKUP(F176,'LEAID Match'!$A$2:$B$240,2,FALSE),"") -> 0
A177: 0 | B177: 2022 | C177: 190 | D177: Nevada | E177: NV | F177: UNIVERSITY OF NEVADA-RENO | I177: {=_xlfn.IFS(B177=2015,G177/$H$1957,B177=2016,G177/$H$1958,B177=2017,G177/$H$1959,B177=2018,G177/$H$1960,B177=2019,G177/$H$1961,B177=2020,G177/$H$1962,B177=2021,G177/$H$1963,B177=2022,G177/$H$1964,B177=2023,G177/$H$1965)} -> 0 | J177: {=_xlfn.IFS(B177=2015,I177*$G$2,B177=2016,I177*$G$3,B177=2017,I177*$G$4,B177=2018,I177*$G$5,B177=2019,I177*$G$6,B177=2020,I177*$G$7,B177=2021,I177*$G$8,B177=2022,I177*$G$9,B177=2023,I177*$G$10)} -> 0 | K177: =SUM(G177,J177) -> 0 | L177: =IFERROR(VLOOKUP(F177,'LEAID Match'!$A$2:$B$240,2,FALSE),"") -> 0
A178: 0 | B178: 2023 | C178: 190 | D178: Nevada | E178: NV | F178: UNIVERSITY OF NEVADA-RENO | I178: {=_xlfn.IFS(B178=2015,G178/$H$1957,B178=2016,G178/$H$1958,B178=2017,G178/$H$1959,B178=2018,G178/$H$1960,B178=2019,G178/$H$1961,B178=2020,G178/$H$1962,B178=2021,G178/$H$1963,B178=2022,G178/$H$1964,B178=2023,G178/$H$1965)} -> 0 | J178: {=_xlfn.IFS(B178=2015,I178*$G$2,B178=2016,I178*$G$3,B178=2017,I178*$G$4,B178=2018,I178*$G$5,B178=2019,I178*$G$6,B178=2020,I178*$G$7,B178=2021,I178*$G$8,B178=2022,I178*$G$9,B178=2023,I178*$G$10)} -> 0 | K178: =SUM(G178,J178) -> 0 | L178: =IFERROR(VLOOKUP(F178,'LEAID Match'!$A$2:$B$240,2,FALSE),"") -> 0
A179: 0 | B179: 2015 | C179: 191 | D179: Nevada | E179: NV | F179: UNLV | G179: 20634985 | I179: {=_xlfn.IFS(B179=2015,G179/$H$1957,B179=2016,G179/$H$1958,B179=2017,G179/$H$1959,B179=2018,G179/$H$1960,B179=2019,G179/$H$1961,B179=2020,G179/$H$1962,B179=2021,G179/$H$1963,B179=2022,G179/$H$1964,B179=2023,G179/$H$1965)} -> 0.015935542 | J179: {=_xlfn.IFS(B179=2015,I179*$G$2,B179=2016,I179*$G$3,B179=2017,I179*$G$4,B179=2018,I179*$G$5,B179=2019,I179*$G$6,B179=2020,I179*$G$7,B179=2021,I179*$G$8,B179=2022,I179*$G$9,B179=2023,I179*$G$10)} -> 3962254.3 | K179: =SUM(G179,J179) -> 24597239 | L179: =IFERROR(VLOOKUP(F179,'LEAID Match'!$A$2:$B$240,2,FALSE),"") -> 0
A180: 0 | B180: 2016 | C180: 191 | D180: Nevada | E180: NV | F180: UNLV | G180: 23142993 | I180: {=_xlfn.IFS(B180=2015,G180/$H$1957,B180=2016,G180/$H$1958,B180=2017,G180/$H$1959,B180=2018,G180/$H$1960,B180=2019,G180/$H$1961,B180=2020,G180/$H$1962,B180=2021,G180/$H$1963,B180=2022,G180/$H$1964,B180=2023,G180/$H$1965)} -> 0.016246371 | J180: {=_xlfn.IFS(B180=2015,I180*$G$2,B180=2016,I180*$G$3,B180=2017,I180*$G$4,B180=2018,I180*$G$5,B180=2019,I180*$G$6,B180=2020,I180*$G$7,B180=2021,I180*$G$8,B180=2022,I180*$G$9,B180=2023,I180*$G$10)} -> 4406065.9 | K180: =SUM(G180,J180) -> 27549059 | L180: =IFERROR(VLOOKUP(F180,'LEAID Match'!$A$2:$B$240,2,FALSE),"") -> 0
A181: 0 | B181: 2017 | C181: 191 | D181: Nevada | E181: NV | F181: UNLV | G181: 12473237 | I181: {=_xlfn.IFS(B181=2015,G181/$H$1957,B181=2016,G181/$H$1958,B181=2017,G181/$H$1959,B181=2018,G181/$H$1960,B181=2019,G181/$H$1961,B181=2020,G181/$H$1962,B181=2021,G181/$H$1963,B181=2022,G181/$H$1964,B181=2023,G181/$H$1965)} -> 0.016641953 | J181: {=_xlfn.IFS(B181=2015,I181*$G$2,B181=2016,I181*$G$3,B181=2017,I181*$G$4,B181=2018,I181*$G$5,B181=2019,I181*$G$6,B181=2020,I181*$G$7,B181=2021,I181*$G$8,B181=2022,I181*$G$9,B181=2023,I181*$G$10)} -> 2464450 | K181: =SUM(G181,J181) -> 14937687 | L181: =IFERROR(VLOOKUP(F181,'LEAID Match'!$A$2:$B$240,2,FALSE),"") -> 0
A182: 0 | B182: 2018 | C182: 191 | D182: Nevada | E182: NV | F182: UNLV | G182: 3294268 | I182: {=_xlfn.IFS(B182=2015,G182/$H$1957,B182=2016,G182/$H$1958,B182=2017,G182/$H$1959,B182=2018,G182/$H$1960,B182=2019,G182/$H$1961,B182=2020,G182/$H$1962,B182=2021,G182/$H$1963,B182=2022,G182/$H$1964,B182=2023,G182/$H$1965)} -> 0.0042387691 | J182: {=_xlfn.IFS(B182=2015,I182*$G$2,B182=2016,I182*$G$3,B182=2017,I182*$G$4,B182=2018,I182*$G$5,B182=2019,I182*$G$6,B182=2020,I182*$G$7,B182=2021,I182*$G$8,B182=2022,I182*$G$9,B182=2023,I182*$G$10)} -> 638036.15 | K182: =SUM(G182,J182) -> 3932304.2 | L182: =IFERROR(VLOOKUP(F182,'LEAID Match'!$A$2:$B$240,2,FALSE),"") -> 0
A183: 0 | B183: 2019 | C183: 191 | D183: Nevada | E183: NV | F183: UNLV | G183: 649648 | I183: {=_xlfn.IFS(B183=2015,G183/$H$1957,B183=2016,G183/$H$1958,B183=2017,G183/$H$1959,B183=2018,G183/$H$1960,B183=2019,G183/$H$1961,B183=2020,G183/$H$1962,B183=2021,G183/$H$1963,B183=2022,G183/$H$1964,B183=2023,G183/$H$1965)} -> 0.00080738036 | J183: {=_xlfn.IFS(B183=2015,I183*$G$2,B183=2016,I183*$G$3,B183=2017,I183*$G$4,B183=2018,I183*$G$5,B183=2019,I183*$G$6,B183=2020,I183*$G$7,B183=2021,I183*$G$8,B183=2022,I183*$G$9,B183=2023,I183*$G$10)} -> 127588.8 | K183: =SUM(G183,J183) -> 777236.8 | L183: =IFERROR(VLOOKUP(F183,'LEAID Match'!$A$2:$B$240,2,FALSE),"") -> 0
A184: 0 | B184: 2020 | C184: 191 | D184: Nevada | E184: NV | F184: UNLV | I184: {=_xlfn.IFS(B184=2015,G184/$H$1957,B184=2016,G184/$H$1958,B184=2017,G184/$H$1959,B184=2018,G184/$H$1960,B184=2019,G184/$H$1961,B184=2020,G184/$H$1962,B184=2021,G184/$H$1963,B184=2022,G184/$H$1964,B184=2023,G184/$H$1965)} -> 0 | J184: {=_xlfn.IFS(B184=2015,I184*$G$2,B184=2016,I184*$G$3,B184=2017,I184*$G$4,B184=2018,I184*$G$5,B184=2019,I184*$G$6,B184=2020,I184*$G$7,B184=2021,I184*$G$8,B184=2022,I184*$G$9,B184=2023,I184*$G$10)} -> 0 | K184: =SUM(G184,J184) -> 0 | L184: =IFERROR(VLOOKUP(F184,'LEAID Match'!$A$2:$B$240,2,FALSE),"") -> 0
A185: 0 | B185: 2021 | C185: 191 | D185: Nevada | E185: NV | F185: UNLV | I185: {=_xlfn.IFS(B185=2015,G185/$H$1957,B185=2016,G185/$H$1958,B185=2017,G185/$H$1959,B185=2018,G185/$H$1960,B185=2019,G185/$H$1961,B185=2020,G185/$H$1962,B185=2021,G185/$H$1963,B185=2022,G185/$H$1964,B185=2023,G185/$H$1965)} -> 0 | J185: {=_xlfn.IFS(B185=2015,I185*$G$2,B185=2016,I185*$G$3,B185=2017,I185*$G$4,B185=2018,I185*$G$5,B185=2019,I185*$G$6,B185=2020,I185*$G$7,B185=2021,I185*$G$8,B185=2022,I185*$G$9,B185=2023,I185*$G$10)} -> 0 | K185: =SUM(G185,J185) -> 0 | L185: =IFERROR(VLOOKUP(F185,'LEAID Match'!$A$2:$B$240,2,FALSE),"") -> 0
A186: 0 | B186: 2022 | C186: 191 | D186: Nevada | E186: NV | F186: UNLV | I186: {=_xlfn.IFS(B186=2015,G186/$H$1957,B186=2016,G186/$H$1958,B186=2017,G186/$H$1959,B186=2018,G186/$H$1960,B186=2019,G186/$H$1961,B186=2020,G186/$H$1962,B186=2021,G186/$H$1963,B186=2022,G186/$H$1964,B186=2023,G186/$H$1965)} -> 0 | J186: {=_xlfn.IFS(B186=2015,I186*$G$2,B186=2016,I186*$G$3,B186=2017,I186*$G$4,B186=2018,I186*$G$5,B186=2019,I186*$G$6,B186=2020,I186*$G$7,B186=2021,I186*$G$8,B186=2022,I186*$G$9,B186=2023,I186*$G$10)} -> 0 | K186: =SUM(G186,J186) -> 0 | L186: =IFERROR(VLOOKUP(F186,'LEAID Match'!$A$2:$B$240,2,FALSE),"") -> 0
A187: 0 | B187: 2023 | C187: 191 | D187: Nevada | E187: NV | F187: UNLV | I187: {=_xlfn.IFS(B187=2015,G187/$H$1957,B187=2016,G187/$H$1958,B187=2017,G187/$H$1959,B187=2018,G187/$H$1960,B187=2019,G187/$H$1961,B187=2020,G187/$H$1962,B187=2021,G187/$H$1963,B187=2022,G187/$H$1964,B187=2023,G187/$H$1965)} -> 0 | J187: {=_xlfn.IFS(B187=2015,I187*$G$2,B187=2016,I187*$G$3,B187=2017,I187*$G$4,B187=2018,I187*$G$5,B187=2019,I187*$G$6,B187=2020,I187*$G$7,B187=2021,I187*$G$8,B187=2022,I187*$G$9,B187=2023,I187*$G$10)} -> 0 | K187: =SUM(G187,J187) -> 0 | L187: =IFERROR(VLOOKUP(F187,'LEAID Match'!$A$2:$B$240,2,FALSE),"") -> 0
A188: 0 | B188: 2018 | C188: 193 | D188: Nevada | E188: NV | F188: NEVADA SYSTEMS OF HIGHER EDUCATION (NSHE) | G188: 20383578 | I188: {=_xlfn.IFS(B188=2015,G188/$H$1957,B188=2016,G188/$H$1958,B188=2017,G188/$H$1959,B188=2018,G188/$H$1960,B188=2019,G188/$H$1961,B188=2020,G188/$H$1962,B188=2021,G188/$H$1963,B188=2022,G188/$H$1964,B188=2023,G188/$H$1965)} -> 0.026227763 | J188: {=_xlfn.IFS(B188=2015,I188*$G$2,B188=2016,I188*$G$3,B188=2017,I188*$G$4,B188=2018,I188*$G$5,B188=2019,I188*$G$6,B188=2020,I188*$G$7,B188=2021,I188*$G$8,B188=2022,I188*$G$9,B188=2023,I188*$G$10)} -> 3947905.8 | K188: =SUM(G188,J188) -> 24331484 | L188: =IFERROR(VLOOKUP(F188,'LEAID Match'!$A$2:$B$240,2,FALSE),"") -> 0
A189: 0 | B189: 2019 | C189: 193 | D189: Nevada | E189: NV | F189: NEVADA SYSTEMS OF HIGHER EDUCATION (NSHE) | G189: 28575713 | I189: {=_xlfn.IFS(B189=2015,G189/$H$1957,B189=2016,G189/$H$1958,B189=2017,G189/$H$1959,B189=2018,G189/$H$1960,B189=2019,G189/$H$1961,B189=2020,G189/$H$1962,B189=2021,G189/$H$1963,B189=2022,G189/$H$1964,B189=2023,G189/$H$1965)} -> 0.0355138 | J189: {=_xlfn.IFS(B189=2015,I189*$G$2,B189=2016,I189*$G$3,B189=2017,I189*$G$4,B189=2018,I189*$G$5,B189=2019,I189*$G$6,B189=2020,I189*$G$7,B189=2021,I189*$G$8,B189=2022,I189*$G$9,B189=2023,I189*$G$10)} -> 5612179.2 | K189: =SUM(G189,J189) -> 34187892 | L189: =IFERROR(VLOOKUP(F189,'LEAID Match'!$A$2:$B$240,2,FALSE),"") -> 0
A190: 0 | B190: 2020 | C190: 193 | D190: Nevada | E190: NV | F190: NEVADA SYSTEMS OF HIGHER EDUCATION (NSHE) | G190: 31740945 | I190: {=_xlfn.IFS(B190=2015,G190/$H$1957,B190=2016,G190/$H$1958,B190=2017,G190/$H$1959,B190=2018,G190/$H$1960,B190=2019,G190/$H$1961,B190=2020,G190/$H$1962,B190=2021,G190/$H$1963,B190=2022,G190/$H$1964,B190=2023,G190/$H$1965)} -> 0.036507272 | J190: {=_xlfn.IFS(B190=2015,I190*$G$2,B190=2016,I190*$G$3,B190=2017,I190*$G$4,B190=2018,I190*$G$5,B190=2019,I190*$G$6,B190=2020,I190*$G$7,B190=2021,I190*$G$8,B190=2022,I190*$G$9,B190=2023,I190*$G$10)} -> 6304218 | K190: =SUM(G190,J190) -> 38045163 | L190: =IFERROR(VLOOKUP(F190,'LEAID Match'!$A$2:$B$240,2,FALSE),"") -> 0
A191: 0 | B191: 2021 | C191: 193 | D191: Nevada | E191: NV | F191: NEVADA SYSTEMS OF HIGHER EDUCATION (NSHE) | G191: 31330626 | I191: {=_xlfn.IFS(B191=2015,G191/$H$1957,B191=2016,G191/$H$1958,B191=2017,G191/$H$1959,B191=2018,G191/$H$1960,B191=2019,G191/$H$1961,B191=2020,G191/$H$1962,B191=2021,G191/$H$1963,B191=2022,G191/$H$1964,B191=2023,G191/$H$1965)} -> 0.035804479 | J191: {=_xlfn.IFS(B191=2015,I191*$G$2,B191=2016,I191*$G$3,B191=2017,I191*$G$4,B191=2018,I191*$G$5,B191=2019,I191*$G$6,B191=2020,I191*$G$7,B191=2021,I191*$G$8,B191=2022,I191*$G$9,B191=2023,I191*$G$10)} -> 6144651.5 | K191: =SUM(G191,J191) -> 37475277 | L191: =IFERROR(VLOOKUP(F191,'LEAID Match'!$A$2:$B$240,2,FALSE),"") -> 0
A192: 0 | B192: 2022 | C192: 193 | D192: Nevada | E192: NV | F192: NEVADA SYSTEMS OF HIGHER EDUCATION (NSHE) | G192: 30545880 | I192: {=_xlfn.IFS(B192=2015,G192/$H$1957,B192=2016,G192/$H$1958,B192=2017,G192/$H$1959,B192=2018,G192/$H$1960,B192=2019,G192/$H$1961,B192=2020,G192/$H$1962,B192=2021,G192/$H$1963,B192=2022,G192/$H$1964,B192=2023,G192/$H$1965)} -> 0.032830782 | J192: {=_xlfn.IFS(B192=2015,I192*$G$2,B192=2016,I192*$G$3,B192=2017,I192*$G$4,B192=2018,I192*$G$5,B192=2019,I192*$G$6,B192=2020,I192*$G$7,B192=2021,I192*$G$8,B192=2022,I192*$G$9,B192=2023,I192*$G$10)} -> 5567629.5 | K192: =SUM(G192,J192) -> 36113510 | L192: =IFERROR(VLOOKUP(F192,'LEAID Match'!$A$2:$B$240,2,FALSE),"") -> 0
...

Sheet LEAID Match
A1: employer_name | B1: LEAID
A2: 100 ACADEMY OF EXCELLENCE
A3: ACADEMY FOR CAREER ED
A4: ACCOUNTANCY BOARD
A5: ALAMO SEWER & WATER GID
A6: ALPINE ACADEMY CHARTER
A7: AMERICAN LEADERSHIP ACADEMY
A8: AMERICAN PREP ACADEMY
A9: ANDRE AGASSI PREP ACDMY
A10: AUSTIN VOL FIRE DEPT
A11: BAILEY CHARTER SCHOOL
A12: BATTLE BORN ACADEMY
A13: BATTLE MOUNTAIN GEN HOSP
... A23: CARSON CITY AIRPORT AUTH
A24: CARSON CITY SCHOOL | B24: 3200390
A25: CARSON MONTESSORI SCHOOL
A26: CC COMMUNICATIONS
A27: CENTRAL LYON COUNTY FPD
A28: CHURCHILL CO MOSQ ABATE
A29: CHURCHILL CO SCHOOL DIST | B29: 3200030
A30: CHURCHILL CO VOL FIRE DPT
A31: CHURCHILL COUNTY
A32: CITY OF BOULDER
A33: CITY OF CALIENTE
A34: CITY OF CARLIN
A35: CITY OF CARSON
A36: CITY OF ELKO
A37: CITY OF ELY
A38: CITY OF FALLON
A39: CITY OF FERNLEY
A40: CITY OF HENDERSON
A41: CITY OF LAS VEGAS
... A52: CIVICA NEVADA ACADEMY
A53: CLARK CO SCHOOL DISTRICT | B53: 3200060
A54: CLARK CO WATER RECLAM DST
A55: CLARK COUNTY
A56: CLV STRONG START ACADEMY
A57: CNTRL DISPATCH ADMIN AUTH
A58: CONSERVATION DST OF SO NV
A59: CORAL ACADEMY LAS VEGAS
...

Sheet State Sponsored Charter Schools
A1: Year | B1: district_contributions | C1: state_contributions | E1: Elementary Schools
A2: 2015 | B2: =SUMIFS(Summary!$G$2:$G$1934,Summary!$H$2:$H$1934,1,Summary!$B$2:$B$1934,'State Sponsored Charter Schools'!$A2) -> 12113731 | C2: =SUMIFS(Summary!$J$2:$J$1934,Summary!$H$2:$H$1934,1,Summary!$B$2:$B$1934,'State Sponsored Charter Schools'!$A2) -> 2326034.3 | E2: Democracy Prep At Agassi Elementary
A3: 2016 | B3: =SUMIFS(Summary!$G$2:$G$1934,Summary!$H$2:$H$1934,1,Summary!$B$2:$B$1934,'State Sponsored Charter Schools'!A3) -> 17645220 | C3: =SUMIFS(Summary!$J$2:$J$1934,Summary!$H$2:$H$1934,1,Summary!$B$2:$B$1934,'State Sponsored Charter Schools'!$A3) -> 3359375.4 | E3: Discovery Charter School Sandhill
A4: 2017 | B4: =SUMIFS(Summary!$G$2:$G$1934,Summary!$H$2:$H$1934,1,Summary!$B$2:$B$1934,'State Sponsored Charter Schools'!A4) -> 11448136 | C4: =SUMIFS(Summary!$J$2:$J$1934,Summary!$H$2:$H$1934,1,Summary!$B$2:$B$1934,'State Sponsored Charter Schools'!$A4) -> 2261911.5 | E4: Futuro Academy Elementary
A5: 2018 | B5: =SUMIFS(Summary!$G$2:$G$1934,Summary!$H$2:$H$1934,1,Summary!$B$2:$B$1934,'State Sponsored Charter Schools'!A5) -> 14404210 | C5: =SUMIFS(Summary!$J$2:$J$1934,Summary!$H$2:$H$1934,1,Summary!$B$2:$B$1934,'State Sponsored Charter Schools'!$A5) -> 2789817.6 | E5: Imagine School Mountain View
A6: 2019 | B6: =SUMIFS(Summary!$G$2:$G$1934,Summary!$H$2:$H$1934,1,Summary!$B$2:$B$1934,'State Sponsored Charter Schools'!A6) -> 17080752 | C6: =SUMIFS(Summary!$J$2:$J$1934,Summary!$H$2:$H$1934,1,Summary!$B$2:$B$1934,'State Sponsored Charter Schools'!$A6) -> 3354605.4 | E6: Pinecrest Academy Of Nevada Horizon
A7: 2020 | B7: =SUMIFS(Summary!$G$2:$G$1934,Summary!$H$2:$H$1934,1,Summary!$B$2:$B$1934,'State Sponsored Charter Schools'!A7) -> 21347611 | C7: =SUMIFS(Summary!$J$2:$J$1934,Summary!$H$2:$H$1934,1,Summary!$B$2:$B$1934,'State Sponsored Charter Schools'!$A7) -> 4239949.2 | E7: Middle Schools
A8: 2021 | B8: =SUMIFS(Summary!$G$2:$G$1934,Summary!$H$2:$H$1934,1,Summary!$B$2:$B$1934,'State Sponsored Charter Schools'!A8) -> 23620492 | C8: =SUMIFS(Summary!$J$2:$J$1934,Summary!$H$2:$H$1934,1,Summary!$B$2:$B$1934,'State Sponsored Charter Schools'!$A8) -> 4632518.1 | E8: Democracy Prep At Agassi Middle
A9: 2022 | B9: =SUMIFS(Summary!$G$2:$G$1934,Summary!$H$2:$H$1934,1,Summary!$B$2:$B$1934,'State Sponsored Charter Schools'!A9) -> 27130542 | C9: =SUMIFS(Summary!$J$2:$J$1934,Summary!$H$2:$H$1934,1,Summary!$B$2:$B$1934,'State Sponsored Charter Schools'!$A9) -> 4945112.3 | E9: High Schools
A10: 2023 | B10: =SUMIFS(Summary!$G$2:$G$1934,Summary!$H$2:$H$1934,1,Summary!$B$2:$B$1934,'State Sponsored Charter Schools'!A10) -> 31690717 | C10: =SUMIFS(Summary!$J$2:$J$1934,Summary!$H$2:$H$1934,1,Summary!$B$2:$B$1934,'State Sponsored Charter Schools'!$A10) -> 5454237.5 | E10: Alpine Academy High School
E11: Beacon Academy Of Nevada
E12: Democracy Prep At Agassi High
E13: Nevada Connections Academy
E14: Nevada State High School Downtown
E15: Nevada State High School Downtown Henderson
E16: Nevada State High School Henderson
E17: Nevada State High School Ii Meadowwood
E18: Nevada State High School Northwest
E19: Nevada State High School Southwest
E20: Nevada State High School Summerlin
E21: Nevada State High School Sunrise
E22: Other Schools
... E84: Quest Academy West Alexander

Sheet Check
A1: Employer Contribution Check
A2: Year | B2: Total Reported | C2: Total from Formula | D2: Difference | E2: Notes
A3: 2015 | B3: 1543545788 | C3: =SUMIF(Summary!B:B,Check!A3,Summary!G:G) -> 1555659519 | D3: =B3-C3+'State Sponsored Charter Schools'!B2 -> 0
A4: 2016 | B4: 1695705372 | C4: =SUMIF(Summary!B:B,Check!A4,Summary!G:G) -> 1713350592 | D4: =B4-C4+'State Sponsored Charter Schools'!B3 -> 0
A5: 2017 | B5: 897592209 | C5: =SUMIF(Summary!B:B,Check!A5,Summary!G:G) -> 909040345 | D5: =B5-C5+'State Sponsored Charter Schools'!B4 -> 0
A6: 2018 | B6: 927699552 | C6: =SUMIF(Summary!B:B,Check!A6,Summary!G:G) -> 942103762 | D6: =B6-C6+'State Sponsored Charter Schools'!B5 -> 0
A7: 2019 | B7: 962664986 | C7: =SUMIF(Summary!B:B,Check!A7,Summary!G:G) -> 979745738 | D7: =B7-C7+'State Sponsored Charter Schools'!B6 -> 0
A8: 2020 | B8: 1042125593 | C8: =SUMIF(Summary!B:B,Check!A8,Summary!G:G) -> 1063473204 | D8: =B8-C8+'State Sponsored Charter Schools'!B7 -> 0
A9: 2021 | B9: 1046664500 | C9: =SUMIF(Summary!B:B,Check!A9,Summary!G:G) -> 1070284992 | D9: =B9-C9+'State Sponsored Charter Schools'!B8 -> 0
A10: 2022 | B10: 1099989308 | C10: =SUMIF(Summary!B:B,Check!A10,Summary!G:G) -> 1127119850 | D10: =B10-C10+'State Sponsored Charter Schools'!B9 -> 0
A11: 2023 | B11: 1157649798 | C11: =SUMIF(Summary!B:B,Check!A11,Summary!G:G) -> 1189340511 | D11: =B11-C11+'State Sponsored Charter Schools'!B10 -> 4
