Workbook

Sheet Data
A1: Year | B1: employer_code | C1: State | D1: state_abv | E1: plan | F1: standardized_employer_name | G1: employer_contributions_tier2 | H1: employer_contributions_noncon | I1: employer_contributions_con | J1: total_contributions | K1: _merge1 | L1: _merge2 | M1: employer_name_tier2 | N1: employer_name_noncon | O1: employer_name_con | P1: LEAID_match
A2: 2015 | B2: 1 | C2: Utah | D2: UT | E2: Public Employees Contributory Retirement System & Non-Contributory Retirement System & Tier 2 Public Employees Contributory Retirement System | F2: 4 CORNERS COMM BEHAVIOR HEALTH | G2: 45591 | J2: =SUM(G2:I2) -> 45591 | K2: Master only (1) | L2: Master only (1) | M2: 4 Corners Comm Behavior Health | P2: =IFERROR(VLOOKUP(F2,Sheet1!$A$2:$B$54,2,FALSE),"")
A3: 2016 | B3: 1 | C3: Utah | D3: UT | E3: Public Employees Contributory Retirement System & Non-Contributory Retirement System & Tier 2 Public Employees Contributory Retirement System | F3: 4 CORNERS COMM BEHAVIOR HEALTH | G3: 63033 | J3: =SUM(G3:I3) -> 63033 | K3: Master only (1) | L3: Master only (1) | M3: 4 Corners Community Behavior Health | P3: =IFERROR(VLOOKUP(F3,Sheet1!$A$2:$B$54,2,FALSE),"")
A4: 2017 | B4: 1 | C4: Utah | D4: UT | E4: Public Employees Contributory Retirement System & Non-Contributory Retirement System & Tier 2 Public Employees Contributory Retirement System | F4: 4 CORNERS COMM BEHAVIOR HEALTH | G4: 82576 | J4: =SUM(G4:I4) -> 82576 | K4: Master only (1) | L4: Master only (1) | M4: 4 Corners Comm Behavior Health | P4: =IFERROR(VLOOKUP(F4,Sheet1!$A$2:$B$54,2,FALSE),"")
A5: 2018 | B5: 1 | C5: Utah | D5: UT | E5: Public Employees Contributory Retirement System & Non-Contributory Retirement System & Tier 2 Public Employees Contributory Retirement System | F5: 4 CORNERS COMM BEHAVIOR HEALTH | G5: 101227 | J5: =SUM(G5:I5) -> 101227 | K5: Master only (1) | L5: Master only (1) | M5: 4 Corners Comm Behavior Health | P5: =IFERROR(VLOOKUP(F5,Sheet1!$A$2:$B$54,2,FALSE),"")
A6: 2019 | B6: 1 | C6: Utah | D6: UT | E6: Public Employees Contributory Retirement System & Non-Contributory Retirement System & Tier 2 Public Employees Contributory Retirement System | F6: 4 CORNERS COMM BEHAVIOR HEALTH | G6: 136196 | J6: =SUM(G6:I6) -> 136196 | K6: Master only (1) | L6: Master only (1) | M6: 4 Corners Comm Behavior Health | P6: =IFERROR(VLOOKUP(F6,Sheet1!$A$2:$B$54,2,FALSE),"")
A7: 2020 | B7: 1 | C7: Utah | D7: UT | E7: Public Employees Contributory Retirement System & Non-Contributory Retirement System & Tier 2 Public Employees Contributory Retirement System | F7: 4 CORNERS COMM BEHAVIOR HEALTH | G7: 165021 | J7: =SUM(G7:I7) -> 165021 | K7: Master only (1) | L7: Master only (1) | M7: 4 Corners Comm Behavior Health | P7: =IFERROR(VLOOKUP(F7,Sheet1!$A$2:$B$54,2,FALSE),"")
A8: 2021 | B8: 1 | C8: Utah | D8: UT | E8: Public Employees Contributory Retirement System & Non-Contributory Retirement System & Tier 2 Public Employees Contributory Retirement System | F8: 4 CORNERS COMM BEHAVIOR HEALTH | G8: 204180 | J8: =SUM(G8:I8) -> 204180 | K8: Master only (1) | L8: Master only (1) | M8: 4 CORNERS COMM BEHAVIOR HEALTH | P8: =IFERROR(VLOOKUP(F8,Sheet1!$A$2:$B$54,2,FALSE),"")
A9: 2022 | B9: 1 | C9: Utah | D9: UT | E9: Public Employees Contributory Retirement System & Non-Contributory Retirement System & Tier 2 Public Employees Contributory Retirement System | F9: 4 CORNERS COMM BEHAVIOR HEALTH | G9: 287279 | J9: =SUM(G9:I9) -> 287279 | K9: Master only (1) | L9: Master only (1) | M9: 4 CORNERS COMM BEHAVIOR HEALTH | P9: =IFERROR(VLOOKUP(F9,Sheet1!$A$2:$B$54,2,FALSE),"")
A10: 2023 | B10: 1 | C10: Utah | D10: UT | E10: Public Employees Contributory Retirement System & Non-Contributory Retirement System & Tier 2 Public Employees Contributory Retirement System | F10: 4 CORNERS COMM BEHAVIOR HEALTH | G10: 332425 | J10: =SUM(G10:I10) -> 332425 | K10: Master only (1) | L10: Master only (1) | M10: 4 CORNERS COMM BEHAVIOR HEALTH | P10: =IFERROR(VLOOKUP(F10,Sheet1!$A$2:$B$54,2,FALSE),"")
A11: 2015 | B11: 2 | C11: Utah | D11: UT | E11: Public Employees Contributory Retirement System & Non-Contributory Retirement System & Tier 2 Public Employees Contributory Retirement System | F11: ACTIVE RE ENTRY INC | G11: 0 | H11: 68584 | J11: =SUM(G11:I11) -> 68584 | K11: Matched (3) | L11: Master only (1) | M11: Active Re Entry Inc | N11: Active Re Entry Inc | P11: =IFERROR(VLOOKUP(F11,Sheet1!$A$2:$B$54,2,FALSE),"")
A12: 2016 | B12: 2 | C12: Utah | D12: UT | E12: Public Employees Contributory Retirement System & Non-Contributory Retirement System & Tier 2 Public Employees Contributory Retirement System | F12: ACTIVE RE ENTRY INC | G12: 1262 | H12: 67677 | J12: =SUM(G12:I12) -> 68939 | K12: Matched (3) | L12: Master only (1) | M12: Active Re Entry Inc | N12: Active Re Entry Inc | P12: =IFERROR(VLOOKUP(F12,Sheet1!$A$2:$B$54,2,FALSE),"")
A13: 2017 | B13: 2 | C13: Utah | D13: UT | E13: Public Employees Contributory Retirement System & Non-Contributory Retirement System & Tier 2 Public Employees Contributory Retirement System | F13: ACTIVE RE ENTRY INC | G13: 1757 | H13: 68763 | J13: =SUM(G13:I13) -> 70520 | K13: Matched (3) | L13: Master only (1) | M13: Active Re Entry Inc | N13: Active Re Entry Inc | P13: =IFERROR(VLOOKUP(F13,Sheet1!$A$2:$B$54,2,FALSE),"")
A14: 2018 | B14: 2 | C14: Utah | D14: UT | E14: Public Employees Contributory Retirement System & Non-Contributory Retirement System & Tier 2 Public Employees Contributory Retirement System | F14: ACTIVE RE ENTRY INC | G14: 1114 | H14: 76000 | J14: =SUM(G14:I14) -> 77114 | K14: Matched (3) | L14: Master only (1) | M14: Active Re Entry Inc | N14: Active Re Entry Inc | P14: =IFERROR(VLOOKUP(F14,Sheet1!$A$2:$B$54,2,FALSE),"")
A15: 2019 | B15: 2 | C15: Utah | D15: UT | E15: Public Employees Contributory Retirement System & Non-Contributory Retirement System & Tier 2 Public Employees Contributory Retirement System | F15: ACTIVE RE ENTRY INC | G15: 3160 | H15: 70695 | J15: =SUM(G15:I15) -> 73855 | K15: Matched (3) | L15: Master only (1) | M15: Active Re Entry Inc | N15: Active Re Entry Inc | P15: =IFERROR(VLOOKUP(F15,Sheet1!$A$2:$B$54,2,FALSE),"")
A16: 2020 | B16: 2 | C16: Utah | D16: UT | E16: Public Employees Contributory Retirement System & Non-Contributory Retirement System & Tier 2 Public Employees Contributory Retirement System | F16: ACTIVE RE ENTRY INC | G16: 10558 | H16: 85052 | J16: =SUM(G16:I16) -> 95610 | K16: Matched (3) | L16: Master only (1) | M16: Active Re Entry Inc | N16: Active Re Entry Inc | P16: =IFERROR(VLOOKUP(F16,Sheet1!$A$2:$B$54,2,FALSE),"")
A17: 2021 | B17: 2 | C17: Utah | D17: UT | E17: Public Employees Contributory Retirement System & Non-Contributory Retirement System & Tier 2 Public Employees Contributory Retirement System | F17: ACTIVE RE ENTRY INC | G17: 6993 | H17: 74751 | J17: =SUM(G17:I17) -> 81744 | K17: Matched (3) | L17: Master only (1) | M17: ACTIVE RE ENTRY INC | N17: ACTIVE RE ENTRY INC | P17: =IFERROR(VLOOKUP(F17,Sheet1!$A$2:$B$54,2,FALSE),"")
A18: 2022 | B18: 2 | C18: Utah | D18: UT | E18: Public Employees Contributory Retirement System & Non-Contributory Retirement System & Tier 2 Public Employees Contributory Retirement System | F18: ACTIVE RE ENTRY INC | G18: 6755 | H18: 76869 | J18: =SUM(G18:I18) -> 83624 | K18: Matched (3) | L18: Master only (1) | M18: ACTIVE RE ENTRY INC | N18: ACTIVE RE ENTRY INC | P18: =IFERROR(VLOOKUP(F18,Sheet1!$A$2:$B$54,2,FALSE),"")
A19: 2023 | B19: 2 | C19: Utah | D19: UT | E19: Public Employees Contributory Retirement System & Non-Contributory Retirement System & Tier 2 Public Employees Contributory Retirement System | F19: ACTIVE RE ENTRY INC | G19: 6356 | H19: 85192 | J19: =SUM(G19:I19) -> 91548 | K19: Matched (3) | L19: Master only (1) | M19: ACTIVE RE ENTRY INC | N19: ACTIVE RE ENTRY INC | P19: =IFERROR(VLOOKUP(F19,Sheet1!$A$2:$B$54,2,FALSE),"")
A20: 2015 | B20: 3 | C20: Utah | D20: UT | E20: Public Employees Contributory Retirement System & Non-Contributory Retirement System & Tier 2 Public Employees Contributory Retirement System | F20: ALPINE CITY | G20: 9435 | J20: =SUM(G20:I20) -> 9435 | K20: Master only (1) | L20: Master only (1) | M20: Alpine City | P20: =IFERROR(VLOOKUP(F20,Sheet1!$A$2:$B$54,2,FALSE),"")
A21: 2016 | B21: 3 | C21: Utah | D21: UT | E21: Public Employees Contributory Retirement System & Non-Contributory Retirement System & Tier 2 Public Employees Contributory Retirement System | F21: ALPINE CITY | G21: 11480 | J21: =SUM(G21:I21) -> 11480 | K21: Master only (1) | L21: Master only (1) | M21: Alpine City | P21: =IFERROR(VLOOKUP(F21,Sheet1!$A$2:$B$54,2,FALSE),"")
A22: 2017 | B22: 3 | C22: Utah | D22: UT | E22: Public Employees Contributory Retirement System & Non-Contributory Retirement System & Tier 2 Public Employees Contributory Retirement System | F22: ALPINE CITY | G22: 17813 | J22: =SUM(G22:I22) -> 17813 | K22: Master only (1) | L22: Master only (1) | M22: Alpine City | P22: =IFERROR(VLOOKUP(F22,Sheet1!$A$2:$B$54,2,FALSE),"")
A23: 2018 | B23: 3 | C23: Utah | D23: UT | E23: Public Employees Contributory Retirement System & Non-Contributory Retirement System & Tier 2 Public Employees Contributory Retirement System | F23: ALPINE CITY | G23: 19831 | J23: =SUM(G23:I23) -> 19831 | K23: Master only (1) | L23: Master only (1) | M23: Alpine City | P23: =IFERROR(VLOOKUP(F23,Sheet1!$A$2:$B$54,2,FALSE),"")
A24: 2019 | B24: 3 | C24: Utah | D24: UT | E24: Public Employees Contributory Retirement System & Non-Contributory Retirement System & Tier 2 Public Employees Contributory Retirement System | F24: ALPINE CITY | G24: 24810 | J24: =SUM(G24:I24) -> 24810 | K24: Master only (1) | L24: Master only (1) | M24: Alpine City | P24: =IFERROR(VLOOKUP(F24,Sheet1!$A$2:$B$54,2,FALSE),"")
A25: 2020 | B25: 3 | C25: Utah | D25: UT | E25: Public Employees Contributory Retirement System & Non-Contributory Retirement System & Tier 2 Public Employees Contributory Retirement System | F25: ALPINE CITY | G25: 26242 | J25: =SUM(G25:I25) -> 26242 | K25: Master only (1) | L25: Master only (1) | M25: Alpine City | P25: =IFERROR(VLOOKUP(F25,Sheet1!$A$2:$B$54,2,FALSE),"")
A26: 2021 | B26: 3 | C26: Utah | D26: UT | E26: Public Employees Contributory Retirement System & Non-Contributory Retirement System & Tier 2 Public Employees Contributory Retirement System | F26: ALPINE CITY | G26: 30395 | J26: =SUM(G26:I26) -> 30395 | K26: Master only (1) | L26: Master only (1) | M26: ALPINE CITY | P26: =IFERROR(VLOOKUP(F26,Sheet1!$A$2:$B$54,2,FALSE),"")
A27: 2022 | B27: 3 | C27: Utah | D27: UT | E27: Public Employees Contributory Retirement System & Non-Contributory Retirement System & Tier 2 Public Employees Contributory Retirement System | F27: ALPINE CITY | G27: 34622 | J27: =SUM(G27:I27) -> 34622 | K27: Master only (1) | L27: Master only (1) | M27: ALPINE CITY | P27: =IFERROR(VLOOKUP(F27,Sheet1!$A$2:$B$54,2,FALSE),"")
A28: 2023 | B28: 3 | C28: Utah | D28: UT | E28: Public Employees Contributory Retirement System & Non-Contributory Retirement System & Tier 2 Public Employees Contributory Retirement System | F28: ALPINE CITY | G28: 42931 | J28: =SUM(G28:I28) -> 42931 | K28: Master only (1) | L28: Master only (1) | M28: ALPINE CITY | P28: =IFERROR(VLOOKUP(F28,Sheet1!$A$2:$B$54,2,FALSE),"")
A29: 2015 | B29: 4 | C29: Utah | D29: UT | E29: Public Employees Contributory Retirement System & Non-Contributory Retirement System & Tier 2 Public Employees Contributory Retirement System | F29: ALPINE SCHOOL DISTRICT | G29: 3021679 | H29: 45090758 | I29: 213001 | J29: =SUM(G29:I29) -> 48325438 | K29: Matched (3) | L29: Matched (3) | M29: Alpine School District | N29: Alpine School District | O29: Alpine School District | P29: =IFERROR(VLOOKUP(F29,Sheet1!$A$2:$B$54,2,FALSE),"") -> 4900030
A30: 2016 | B30: 4 | C30: Utah | D30: UT | E30: Public Employees Contributory Retirement System & Non-Contributory Retirement System & Tier 2 Public Employees Contributory Retirement System | F30: ALPINE SCHOOL DISTRICT | G30: 3768441 | H30: 47060547 | I30: 177633 | J30: =SUM(G30:I30) -> 51006621 | K30: Matched (3) | L30: Matched (3) | M30: Alpine School District | N30: Alpine School District | O30: Alpine School District | P30: =IFERROR(VLOOKUP(F30,Sheet1!$A$2:$B$54,2,FALSE),"") -> 4900030
A31: 2017 | B31: 4 | C31: Utah | D31: UT | E31: Public Employees Contributory Retirement System & Non-Contributory Retirement System & Tier 2 Public Employees Contributory Retirement System | F31: ALPINE SCHOOL DISTRICT | G31: 4592044 | H31: 48766784 | I31: 150886 | J31: =SUM(G31:I31) -> 53509714 | K31: Matched (3) | L31: Matched (3) | M31: Alpine School District | N31: Alpine School District | O31: Alpine School District | P31: =IFERROR(VLOOKUP(F31,Sheet1!$A$2:$B$54,2,FALSE),"") -> 4900030
A32: 2018 | B32: 4 | C32: Utah | D32: UT | E32: Public Employees Contributory Retirement System & Non-Contributory Retirement System & Tier 2 Public Employees Contributory Retirement System | F32: ALPINE SCHOOL DISTRICT | G32: 5685454 | H32: 50640824 | I32: 117064 | J32: =SUM(G32:I32) -> 56443342 | K32: Matched (3) | L32: Matched (3) | M32: Alpine School District | N32: Alpine School District | O32: Alpine School District | P32: =IFERROR(VLOOKUP(F32,Sheet1!$A$2:$B$54,2,FALSE),"") -> 4900030
A33: 2019 | B33: 4 | C33: Utah | D33: UT | E33: Public Employees Contributory Retirement System & Non-Contributory Retirement System & Tier 2 Public Employees Contributory Retirement System | F33: ALPINE SCHOOL DISTRICT | G33: 7129418 | H33: 53982408 | I33: 109839 | J33: =SUM(G33:I33) -> 61221665 | K33: Matched (3) | L33: Matched (3) | M33: Alpine School District | N33: Alpine School District | O33: Alpine School District | P33: =IFERROR(VLOOKUP(F33,Sheet1!$A$2:$B$54,2,FALSE),"") -> 4900030
A34: 2020 | B34: 4 | C34: Utah | D34: UT | E34: Public Employees Contributory Retirement System & Non-Contributory Retirement System & Tier 2 Public Employees Contributory Retirement System | F34: ALPINE SCHOOL DISTRICT | G34: 8418551 | H34: 57172626 | I34: 99317 | J34: =SUM(G34:I34) -> 65690494 | K34: Matched (3) | L34: Matched (3) | M34: Alpine School District | N34: Alpine School District | O34: Alpine School District | P34: =IFERROR(VLOOKUP(F34,Sheet1!$A$2:$B$54,2,FALSE),"") -> 4900030
A35: 2021 | B35: 4 | C35: Utah | D35: UT | E35: Public Employees Contributory Retirement System & Non-Contributory Retirement System & Tier 2 Public Employees Contributory Retirement System | F35: ALPINE SCHOOL DISTRICT | G35: 10175615 | H35: 61600619 | I35: 84846 | J35: =SUM(G35:I35) -> 71861080 | K35: Matched (3) | L35: Matched (3) | M35: ALPINE SCHOOL DISTRICT | N35: ALPINE SCHOOL DISTRICT | O35: ALPINE SCHOOL DISTRICT | P35: =IFERROR(VLOOKUP(F35,Sheet1!$A$2:$B$54,2,FALSE),"") -> 4900030
A36: 2022 | B36: 4 | C36: Utah | D36: UT | E36: Public Employees Contributory Retirement System & Non-Contributory Retirement System & Tier 2 Public Employees Contributory Retirement System | F36: ALPINE SCHOOL DISTRICT | G36: 12534346 | H36: 65773348 | I36: 54354 | J36: =SUM(G36:I36) -> 78362048 | K36: Matched (3) | L36: Matched (3) | M36: ALPINE SCHOOL DISTRICT | N36: ALPINE SCHOOL DISTRICT | O36: ALPINE SCHOOL DISTRICT | P36: =IFERROR(VLOOKUP(F36,Sheet1!$A$2:$B$54,2,FALSE),"") -> 4900030
A37: 2023 | B37: 4 | C37: Utah | D37: UT | E37: Public Employees Contributory Retirement System & Non-Contributory Retirement System & Tier 2 Public Employees Contributory Retirement System | F37: ALPINE SCHOOL DISTRICT | G37: 15556618 | H37: 72071075 | I37: 37508 | J37: =SUM(G37:I37) -> 87665201 | K37: Matched (3) | L37: Matched (3) | M37: ALPINE SCHOOL DISTRICT | N37: ALPINE SCHOOL DISTRICT | O37: ALPINE SCHOOL DISTRICT | P37: =IFERROR(VLOOKUP(F37,Sheet1!$A$2:$B$54,2,FALSE),"") -> 4900030
A38: 2015 | B38: 5 | C38: Utah | D38: UT | E38: Public Employees Contributory Retirement System & Non-Contributory Retirement System & Tier 2 Public Employees Contributory Retirement System | F38: ALPINE UNISERV | G38: 2785 | H38: 20372 | J38: =SUM(G38:I38) -> 23157 | K38: Matched (3) | L38: Master only (1) | M38: Alpine Uniserv | N38: Alpine Uniserv | P38: =IFERROR(VLOOKUP(F38,Sheet1!$A$2:$B$54,2,FALSE),"")
A39: 2016 | B39: 5 | C39: Utah | D39: UT | E39: Public Employees Contributory Retirement System & Non-Contributory Retirement System & Tier 2 Public Employees Contributory Retirement System | F39: ALPINE UNISERV | G39: 0 | H39: 19785 | J39: =SUM(G39:I39) -> 19785 | K39: Matched (3) | L39: Master only (1) | M39: Alpine Uniserv | N39: Alpine Uniserv | P39: =IFERROR(VLOOKUP(F39,Sheet1!$A$2:$B$54,2,FALSE),"")
A40: 2017 | B40: 5 | C40: Utah | D40: UT | E40: Public Employees Contributory Retirement System & Non-Contributory Retirement System & Tier 2 Public Employees Contributory Retirement System | F40: ALPINE UNISERV | G40: 0 | H40: 17987 | J40: =SUM(G40:I40) -> 17987 | K40: Matched (3) | L40: Master only (1) | M40: Alpine Uniserv | N40: Alpine Uniserv | P40: =IFERROR(VLOOKUP(F40,Sheet1!$A$2:$B$54,2,FALSE),"")
...

Sheet Sheet1
A1: district_name
A2: ALPINE SCHOOL DISTRICT | B2: 4900030
A3: AMERICAN LEADERSHIP ACADEMY | B3: 4900030
A4: AMES CHARTER SCHOOL | B4: 4900017
A5: BEAVER SCHOOL DISTRICT | B5: 4900060
A6: BOX ELDER SCHOOL DISTRICT | B6: 4900090
A7: CACHE COUNTY SCHOOL DISTRICT | B7: 4900120
A8: CANYONS SCHOOL DISTRICT | B8: 4900142
A9: CARBON SCHOOL DISTRICT | B9: 4900150
A10: DAGGETT SCHOOL DISTRICT | B10: 4900180
A11: DAVIS SCHOOL DISTRICT | B11: 4900210
A12: DUCHESNE SCHOOL DISTRICT | B12: 4900240
A13: EMERY SCHOOL DISTRICT | B13: 4900270
... A22: KANE SCHOOL DISTRICT | B22: 4900480
A23: LIBERTY ACADEMY CHARTER
A24: LOGAN SCHOOL DISTRICT | B24: 4900510
A25: MILLARD SCHOOL DISTRICT | B25: 4900540
A26: MONTICELLO ACADEMY | B26: 4900049
A27: MORGAN SCHOOL DISTRICT | B27: 4900570
A28: MURRAY SCHOOL DISTRICT | B28: 4900600
A29: NEBO SCHOOL DISTRICT | B29: 4900630
A30: NORTH SANPETE SCHOOL DISTRICT | B30: 4900660
A31: NORTH SUMMIT SCHOOL DISTRICT | B31: 4900690
A32: NUAMES CHARTER SCHOOL | B32: 4900063
A33: OGDEN SCHOOL DISTRICT | B33: 4900720
A34: PARK CITY SCHOOL DISTRICT | B34: 4900750
A35: PIUTE SCHOOL DISTRICT | B35: 4900780
... A54: WEBER COUNTY SCHOOL DISTRICT | B54: 4901200

Sheet Check
A1: Tier 2 | G1: Noncontributory | M1: Contributory
A2: Year | B2: Reported | C2: Total from Formula | D2: Difference | E2: Notes | G2: Year | H2: Reported | I2: Total from Formula | J2: Difference | K2: Notes | M2: Year | N2: Reported | O2: Total from Formula | P2: Difference | Q2: Notes
A3: 2015 | B3: 53713837 | C3: =SUMIF(Data!A:A,Check!A3,Data!G:G) -> 53713832 | D3: =B3-C3 -> 5 | G3: 2015 | H3: 640324454 | I3: =SUMIF(Data!A:A,Check!A3,Data!H:H) -> 640324453 | J3: =H3-I3 -> 1 | M3: 2015 | N3: 5606961 | O3: =SUMIF(Data!A:A,Check!A3,Data!I:I) -> 5606963 | P3: =N3-O3 -> -2
A4: 2016 | B4: 68066603 | C4: =SUMIF(Data!A:A,Check!A4,Data!G:G) -> 68066610 | D4: =B4-C4 -> -7 | G4: 2016 | H4: 655450485 | I4: =SUMIF(Data!A:A,Check!A4,Data!H:H) -> 655450486 | J4: =H4-I4 -> -1 | M4: 2016 | N4: 4744792 | O4: =SUMIF(Data!A:A,Check!A4,Data!I:I) -> 4744795 | P4: =N4-O4 -> -3
A5: 2017 | B5: 82274953 | C5: =SUMIF(Data!A:A,Check!A5,Data!G:G) -> 82274948 | D5: =B5-C5 -> 5 | G5: 2017 | H5: 661095616 | I5: =SUMIF(Data!A:A,Check!A5,Data!H:H) -> 661095617 | J5: =H5-I5 -> -1 | M5: 2017 | N5: 4027252 | O5: =SUMIF(Data!A:A,Check!A5,Data!I:I) -> 4027254 | P5: =N5-O5 -> -2
A6: 2018 | B6: 101883279 | C6: =SUMIF(Data!A:A,Check!A6,Data!G:G) -> 101883278 | D6: =B6-C6 -> 1 | G6: 2018 | H6: 679843579 | I6: =SUMIF(Data!A:A,Check!A6,Data!H:H) -> 679843580 | J6: =H6-I6 -> -1 | M6: 2018 | N6: 3435106 | O6: =SUMIF(Data!A:A,Check!A6,Data!I:I) -> 3435104 | P6: =N6-O6 -> 2
A7: 2019 | B7: 124977980 | C7: =SUMIF(Data!A:A,Check!A7,Data!G:G) -> 124977982 | D7: =B7-C7 -> -2 | G7: 2019 | H7: 650951891 | I7: =SUMIF(Data!A:A,Check!A7,Data!H:H) -> 650951893 | J7: =H7-I7 -> -2 | M7: 2019 | N7: 1974684 | O7: =SUMIF(Data!A:A,Check!A7,Data!I:I) -> 1974685 | P7: =N7-O7 -> -1
A8: 2020 | B8: 145842014 | C8: =SUMIF(Data!A:A,Check!A8,Data!G:G) -> 145842010 | D8: =B8-C8 -> 4 | G8: 2020 | H8: 673314260 | I8: =SUMIF(Data!A:A,Check!A8,Data!H:H) -> 673314264 | J8: =H8-I8 -> -4 | M8: 2020 | N8: 1707033 | O8: =SUMIF(Data!A:A,Check!A8,Data!I:I) -> 1707035 | P8: =N8-O8 -> -2
A9: 2021 | B9: 173214968 | C9: =SUMIF(Data!A:A,Check!A9,Data!G:G) -> 173214971 | D9: =B9-C9 -> -3 | G9: 2021 | H9: 702128198 | I9: =SUMIF(Data!A:A,Check!A9,Data!H:H) -> 702128203 | J9: =H9-I9 -> -5 | M9: 2021 | N9: 1498182 | O9: =SUMIF(Data!A:A,Check!A9,Data!I:I) -> 1498182 | P9: =N9-O9 -> 0
A10: 2022 | B10: 211419012 | C10: =SUMIF(Data!A:A,Check!A10,Data!G:G) -> 211419001 | D10: =B10-C10 -> 11 | G10: 2022 | H10: 730814329 | I10: =SUMIF(Data!A:A,Check!A10,Data!H:H) -> 730814330 | J10: =H10-I10 -> -1 | M10: 2022 | N10: 1162184 | O10: =SUMIF(Data!A:A,Check!A10,Data!I:I) -> 1162186 | P10: =N10-O10 -> -2
A11: 2023 | B11: 255949107 | C11: =SUMIF(Data!A:A,Check!A11,Data!G:G) -> 255949116 | D11: =B11-C11 -> -9 | G11: 2023 | H11: 784541621 | I11: =SUMIF(Data!A:A,Check!A11,Data!H:H) -> 784541622 | J11: =H11-I11 -> -1 | M11: 2023 | N11: 919015 | O11: =SUMIF(Data!A:A,Check!A11,Data!I:I) -> 919015 | P11: =N11-O11 -> 0
F14: 2015 | H14: =SUM(B3,H3,N3) -> 699645252
F15: 2016 | H15: =SUM(B4,H4,N4) -> 728261880
F16: 2017 | H16: =SUM(B5,H5,N5) -> 747397821
F17: 2018 | H17: =SUM(B6,H6,N6) -> 785161964
F18: 2019 | H18: =SUM(B7,H7,N7) -> 777904555
F19: 2020 | H19: =SUM(B8,H8,N8) -> 820863307
F20: 2021 | H20: =SUM(B9,H9,N9) -> 876841348
F21: 2022 | H21: =SUM(B10,H10,N10) -> 943395525
F22: 2023 | H22: =SUM(B11,H11,N11) -> 1041409743
