Workbook

Sheet Data for Export
A1: LEAID | B1: Year | C1: state | D1: state_abv | E1: plan | F1: district_name | G1: district_contributions | H1: state_contributions | I1: total_contributions
A2: 0200050 | B2: 2015 | C2: Alaska | D2: AK | E2: Alaska Teachers' Retirement System Defined Benefit Pension Plan | F2: Alaska Gateway School District | G2: 127792 | H2: 4343857.9 | I2: 4471649.9
A3: 0200050 | B3: 2016 | C3: Alaska | D3: AK | E3: Alaska Teachers' Retirement System Defined Benefit Pension Plan | F3: Alaska Gateway School District | G3: 124560 | H3: 328494.14 | I3: 453054.14
A4: 0200050 | B4: 2017 | C4: Alaska | D4: AK | E4: Alaska Teachers' Retirement System Defined Benefit Pension Plan | F4: Alaska Gateway School District | G4: 115657 | H4: 359107.16 | I4: 474764.16
A5: 0200050 | B5: 2018 | C5: Alaska | D5: AK | E5: Alaska Teachers' Retirement System Defined Benefit Pension Plan | F5: Alaska Gateway School District | G5: 147901 | H5: 405009.86 | I5: 552910.86
A6: 0200050 | B6: 2019 | C6: Alaska | D6: AK | E6: Alaska Teachers' Retirement System Defined Benefit Pension Plan | F6: Alaska Gateway School District | G6: 82923 | H6: 286955.81 | I6: 369878.81
A7: 0200050 | B7: 2020 | C7: Alaska | D7: AK | E7: Alaska Teachers' Retirement System Defined Benefit Pension Plan | F7: Alaska Gateway School District | G7: 90858 | H7: 373449.84 | I7: 464307.84
A8: 0200050 | B8: 2021 | C8: Alaska | D8: AK | E8: Alaska Teachers' Retirement System Defined Benefit Pension Plan | F8: Alaska Gateway School District | G8: 75615 | H8: 345577.1 | I8: 421192.1
A9: 0200050 | B9: 2022 | C9: Alaska | D9: AK | E9: Alaska Teachers' Retirement System Defined Benefit Pension Plan | F9: Alaska Gateway School District | G9: 82785 | H9: 382120.65 | I9: 464905.65
A10: 0200050 | B10: 2023 | C10: Alaska | D10: AK | E10: Alaska Teachers' Retirement System Defined Benefit Pension Plan | F10: Alaska Gateway School District | G10: 96718 | I10: 96718
A11: 0200010 | B11: 2015 | C11: Alaska | D11: AK | E11: Alaska Teachers' Retirement System Defined Benefit Pension Plan | F11: Aleutian Region School District | G11: 14119 | H11: 479927.77 | I11: 494046.77
A12: 0200010 | B12: 2016 | C12: Alaska | D12: AK | E12: Alaska Teachers' Retirement System Defined Benefit Pension Plan | F12: Aleutian Region School District | G12: 7850 | H12: 20702.304 | I12: 28552.304
A13: 0200010 | B13: 2017 | C13: Alaska | D13: AK | E13: Alaska Teachers' Retirement System Defined Benefit Pension Plan | F13: Aleutian Region School District | G13: 10585 | H13: 32865.708 | I13: 43450.708
A14: 0200010 | B14: 2018 | C14: Alaska | D14: AK | E14: Alaska Teachers' Retirement System Defined Benefit Pension Plan | F14: Aleutian Region School District | G14: 12437 | H14: 34057.292 | I14: 46494.292
A15: 0200010 | B15: 2019 | C15: Alaska | D15: AK | E15: Alaska Teachers' Retirement System Defined Benefit Pension Plan | F15: Aleutian Region School District | G15: 11751 | H15: 40664.444 | I15: 52415.444
A16: 0200010 | B16: 2020 | C16: Alaska | D16: AK | E16: Alaska Teachers' Retirement System Defined Benefit Pension Plan | F16: Aleutian Region School District | G16: 11761 | H16: 48340.746 | I16: 60101.746
A17: 0200010 | B17: 2021 | C17: Alaska | D17: AK | E17: Alaska Teachers' Retirement System Defined Benefit Pension Plan | F17: Aleutian Region School District | G17: 10241 | H17: 46803.611 | I17: 57044.611
A18: 0200010 | B18: 2022 | C18: Alaska | D18: AK | E18: Alaska Teachers' Retirement System Defined Benefit Pension Plan | F18: Aleutian Region School District | G18: 10364 | H18: 47838.358 | I18: 58202.358
A19: 0200010 | B19: 2023 | C19: Alaska | D19: AK | E19: Alaska Teachers' Retirement System Defined Benefit Pension Plan | F19: Aleutian Region School District | G19: 13673 | I19: 13673
A20: 0200007 | B20: 2015 | C20: Alaska | D20: AK | E20: Alaska Teachers' Retirement System Defined Benefit Pension Plan | F20: Aleutians East Borough School District | G20: 87302 | H20: 2967536.9 | I20: 3054838.9
A21: 0200007 | B21: 2016 | C21: Alaska | D21: AK | E21: Alaska Teachers' Retirement System Defined Benefit Pension Plan | F21: Aleutians East Borough School District | G21: 75752 | H21: 199775.92 | I21: 275527.92
A22: 0200007 | B22: 2017 | C22: Alaska | D22: AK | E22: Alaska Teachers' Retirement System Defined Benefit Pension Plan | F22: Aleutians East Borough School District | G22: 86296 | H22: 267943.24 | I22: 354239.24
A23: 0200007 | B23: 2018 | C23: Alaska | D23: AK | E23: Alaska Teachers' Retirement System Defined Benefit Pension Plan | F23: Aleutians East Borough School District | G23: 112452 | H23: 307936.85 | I23: 420388.85
A24: 0200007 | B24: 2019 | C24: Alaska | D24: AK | E24: Alaska Teachers' Retirement System Defined Benefit Pension Plan | F24: Aleutians East Borough School District | G24: 79651 | H24: 275633.02 | I24: 355284.02
A25: 0200007 | B25: 2020 | C25: Alaska | D25: AK | E25: Alaska Teachers' Retirement System Defined Benefit Pension Plan | F25: Aleutians East Borough School District | G25: 88884 | H25: 365336.19 | I25: 454220.19
A26: 0200007 | B26: 2021 | C26: Alaska | D26: AK | E26: Alaska Teachers' Retirement System Defined Benefit Pension Plan | F26: Aleutians East Borough School District | G26: 65293 | H26: 298403.3 | I26: 363696.3
A27: 0200007 | B27: 2022 | C27: Alaska | D27: AK | E27: Alaska Teachers' Retirement System Defined Benefit Pension Plan | F27: Aleutians East Borough School District | G27: 100088 | H27: 461988.18 | I27: 562076.18
A28: 0200007 | B28: 2023 | C28: Alaska | D28: AK | E28: Alaska Teachers' Retirement System Defined Benefit Pension Plan | F28: Aleutians East Borough School District | G28: 81050 | I28: 81050
A29: 0200180 | B29: 2015 | C29: Alaska | D29: AK | E29: Alaska Teachers' Retirement System Defined Benefit Pension Plan | F29: Anchorage School District | G29: 12824989 | H29: 4.3594223e+08 | I29: 4.4876722e+08
A30: 0200180 | B30: 2016 | C30: Alaska | D30: AK | E30: Alaska Teachers' Retirement System Defined Benefit Pension Plan | F30: Anchorage School District | G30: 11850582 | H30: 31252784 | I30: 43103366
A31: 0200180 | B31: 2017 | C31: Alaska | D31: AK | E31: Alaska Teachers' Retirement System Defined Benefit Pension Plan | F31: Anchorage School District | G31: 12990980 | H31: 40336114 | I31: 53327094
A32: 0200180 | B32: 2018 | C32: Alaska | D32: AK | E32: Alaska Teachers' Retirement System Defined Benefit Pension Plan | F32: Anchorage School District | G32: 13953834 | H32: 38210967 | I32: 52164801
A33: 0200180 | B33: 2019 | C33: Alaska | D33: AK | E33: Alaska Teachers' Retirement System Defined Benefit Pension Plan | F33: Anchorage School District | G33: 13405087 | H33: 46388427 | I33: 59793514
A34: 0200180 | B34: 2020 | C34: Alaska | D34: AK | E34: Alaska Teachers' Retirement System Defined Benefit Pension Plan | F34: Anchorage School District | G34: 12025123 | H34: 49426360 | I34: 61451483
A35: 0200180 | B35: 2021 | C35: Alaska | D35: AK | E35: Alaska Teachers' Retirement System Defined Benefit Pension Plan | F35: Anchorage School District | G35: 9845817 | H35: 44997538 | I35: 54843355
A36: 0200180 | B36: 2022 | C36: Alaska | D36: AK | E36: Alaska Teachers' Retirement System Defined Benefit Pension Plan | F36: Anchorage School District | G36: 10949649 | H36: 50541608 | I36: 61491257
A37: 0200180 | B37: 2023 | C37: Alaska | D37: AK | E37: Alaska Teachers' Retirement System Defined Benefit Pension Plan | F37: Anchorage School District | G37: 18982470 | I37: 18982470
A38: 0200525 | B38: 2015 | C38: Alaska | D38: AK | E38: Alaska Teachers' Retirement System Defined Benefit Pension Plan | F38: Annette Island School District | G38: 81026 | H38: 2754205.5 | I38: 2835231.5
A39: 0200525 | B39: 2016 | C39: Alaska | D39: AK | E39: Alaska Teachers' Retirement System Defined Benefit Pension Plan | F39: Annette Island School District | G39: 70301 | H39: 185400.34 | I39: 255701.34
A40: 0200525 | B40: 2017 | C40: Alaska | D40: AK | E40: Alaska Teachers' Retirement System Defined Benefit Pension Plan | F40: Annette Island School District | G40: 67477 | H40: 209511.52 | I40: 276988.52
...

Sheet Relevant Data Files -->

Sheet Raw Data with Formulas
A1: Year | B1: state | C1: state_abv | D1: plan | E1: district_name | F1: district_code | G1: district_contributions | H1: Prop | I1: state_contributions | J1: total_contributions | K1: LEAID
A2: 2015 | B2: Alaska | C2: AK | D2: Alaska Teachers' Retirement System Defined Benefit Pension Plan | E2: Alaska Gateway School District | F2: 766 | G2: 127792 | H2: {=IFERROR(_xlfn.IFS(A2=$F$517,G2/$G$517,A2=$F$518,G2/$G$518,A2=$F$519,G2/$G$519,A2=$F$520,G2/$G$520,A2=$F$521,G2/$G$521,A2=$F$522,G2/$G$522,A2=$F$523,G2/$G$523,A2=$F$524,G2/$G$524),"")} -> 0.0026318165 | I2: {=IFERROR(_xlfn.IFS(A2=$M$3,H2*$S$3,A2=$M$4,H2*$S$4,A2=$M$5,H2*$S$5,A2=$M$6,H2*$S$6,A2=$M$7,H2*$S$7,A2=$M$8,H2*$S$8,A2=$M$9,H2*$S$9,A2=$M$10,H2*$S$10),"")} -> 4343857.9 | J2: =SUM(G2,I2) -> 4471649.9 | K2: =IFERROR(VLOOKUP(E2,'GASB Match'!$A$2:$C$58,3,FALSE),"") -> 0200050
A3: 2016 | B3: Alaska | C3: AK | D3: Alaska Teachers' Retirement System Defined Benefit Pension Plan | E3: Alaska Gateway School District | F3: 766 | G3: 124560 | H3: {=IFERROR(_xlfn.IFS(A3=$F$517,G3/$G$517,A3=$F$518,G3/$G$518,A3=$F$519,G3/$G$519,A3=$F$520,G3/$G$520,A3=$F$521,G3/$G$521,A3=$F$522,G3/$G$522,A3=$F$523,G3/$G$523,A3=$F$524,G3/$G$524),"")} -> 0.0036516612 | I3: {=IFERROR(_xlfn.IFS(A3=$M$3,H3*$S$3,A3=$M$4,H3*$S$4,A3=$M$5,H3*$S$5,A3=$M$6,H3*$S$6,A3=$M$7,H3*$S$7,A3=$M$8,H3*$S$8,A3=$M$9,H3*$S$9,A3=$M$10,H3*$S$10),"")} -> 328494.14 | J3: =SUM(G3,I3) -> 453054.14 | K3: =IFERROR(VLOOKUP(E3,'GASB Match'!$A$2:$C$58,3,FALSE),"") -> 0200050 | M3: 2015 | N3: Alaska | O3: AK | P3: Alaska Teachers' Retirement System Defined Benefit Pension Plan | Q3: State of Alaska (Nonemployer) | R3: 999 | S3: 1650517011
A4: 2017 | B4: Alaska | C4: AK | D4: Alaska Teachers' Retirement System Defined Benefit Pension Plan | E4: Alaska Gateway School District | F4: 766 | G4: 115657 | H4: {=IFERROR(_xlfn.IFS(A4=$F$517,G4/$G$517,A4=$F$518,G4/$G$518,A4=$F$519,G4/$G$519,A4=$F$520,G4/$G$520,A4=$F$521,G4/$G$521,A4=$F$522,G4/$G$522,A4=$F$523,G4/$G$523,A4=$F$524,G4/$G$524),"")} -> 0.0030962788 | I4: {=IFERROR(_xlfn.IFS(A4=$M$3,H4*$S$3,A4=$M$4,H4*$S$4,A4=$M$5,H4*$S$5,A4=$M$6,H4*$S$6,A4=$M$7,H4*$S$7,A4=$M$8,H4*$S$8,A4=$M$9,H4*$S$9,A4=$M$10,H4*$S$10),"")} -> 359107.16 | J4: =SUM(G4,I4) -> 474764.16 | K4: =IFERROR(VLOOKUP(E4,'GASB Match'!$A$2:$C$58,3,FALSE),"") -> 0200050 | M4: 2016 | N4: Alaska | O4: AK | P4: Alaska Teachers' Retirement System Defined Benefit Pension Plan | Q4: State of Alaska (Nonemployer) | R4: 999 | S4: 89957454
A5: 2018 | B5: Alaska | C5: AK | D5: Alaska Teachers' Retirement System Defined Benefit Pension Plan | E5: Alaska Gateway School District | F5: 766 | G5: 147901 | H5: {=IFERROR(_xlfn.IFS(A5=$F$517,G5/$G$517,A5=$F$518,G5/$G$518,A5=$F$519,G5/$G$519,A5=$F$520,G5/$G$520,A5=$F$521,G5/$G$521,A5=$F$522,G5/$G$522,A5=$F$523,G5/$G$523,A5=$F$524,G5/$G$524),"")} -> 0.0036473488 | I5: {=IFERROR(_xlfn.IFS(A5=$M$3,H5*$S$3,A5=$M$4,H5*$S$4,A5=$M$5,H5*$S$5,A5=$M$6,H5*$S$6,A5=$M$7,H5*$S$7,A5=$M$8,H5*$S$8,A5=$M$9,H5*$S$9,A5=$M$10,H5*$S$10),"")} -> 405009.86 | J5: =SUM(G5,I5) -> 552910.86 | K5: =IFERROR(VLOOKUP(E5,'GASB Match'!$A$2:$C$58,3,FALSE),"") -> 0200050 | M5: 2017 | N5: Alaska | O5: AK | P5: Alaska Teachers' Retirement System Defined Benefit Pension Plan | Q5: State of Alaska (Nonemployer) | R5: 999 | S5: 115980238
A6: 2019 | B6: Alaska | C6: AK | D6: Alaska Teachers' Retirement System Defined Benefit Pension Plan | E6: Alaska Gateway School District | F6: 766 | G6: 82923 | H6: {=IFERROR(_xlfn.IFS(A6=$F$517,G6/$G$517,A6=$F$518,G6/$G$518,A6=$F$519,G6/$G$519,A6=$F$520,G6/$G$520,A6=$F$521,G6/$G$521,A6=$F$522,G6/$G$522,A6=$F$523,G6/$G$523,A6=$F$524,G6/$G$524),"")} -> 0.0022530235 | I6: {=IFERROR(_xlfn.IFS(A6=$M$3,H6*$S$3,A6=$M$4,H6*$S$4,A6=$M$5,H6*$S$5,A6=$M$6,H6*$S$6,A6=$M$7,H6*$S$7,A6=$M$8,H6*$S$8,A6=$M$9,H6*$S$9,A6=$M$10,H6*$S$10),"")} -> 286955.81 | J6: =SUM(G6,I6) -> 369878.81 | K6: =IFERROR(VLOOKUP(E6,'GASB Match'!$A$2:$C$58,3,FALSE),"") -> 0200050 | M6: 2018 | N6: Alaska | O6: AK | P6: Alaska Teachers' Retirement System Defined Benefit Pension Plan | Q6: State of Alaska (Nonemployer) | R6: 999 | S6: 111042261
A7: 2020 | B7: Alaska | C7: AK | D7: Alaska Teachers' Retirement System Defined Benefit Pension Plan | E7: Alaska Gateway School District | F7: 766 | G7: 90858 | H7: {=IFERROR(_xlfn.IFS(A7=$F$517,G7/$G$517,A7=$F$518,G7/$G$518,A7=$F$519,G7/$G$519,A7=$F$520,G7/$G$520,A7=$F$521,G7/$G$521,A7=$F$522,G7/$G$522,A7=$F$523,G7/$G$523,A7=$F$524,G7/$G$524),"")} -> 0.0026633304 | I7: {=IFERROR(_xlfn.IFS(A7=$M$3,H7*$S$3,A7=$M$4,H7*$S$4,A7=$M$5,H7*$S$5,A7=$M$6,H7*$S$6,A7=$M$7,H7*$S$7,A7=$M$8,H7*$S$8,A7=$M$9,H7*$S$9,A7=$M$10,H7*$S$10),"")} -> 373449.84 | J7: =SUM(G7,I7) -> 464307.84 | K7: =IFERROR(VLOOKUP(E7,'GASB Match'!$A$2:$C$58,3,FALSE),"") -> 0200050 | M7: 2019 | N7: Alaska | O7: AK | P7: Alaska Teachers' Retirement System Defined Benefit Pension Plan | Q7: State of Alaska (Nonemployer) | R7: 999 | S7: 127364762
A8: 2021 | B8: Alaska | C8: AK | D8: Alaska Teachers' Retirement System Defined Benefit Pension Plan | E8: Alaska Gateway School District | F8: 766 | G8: 75615 | H8: {=IFERROR(_xlfn.IFS(A8=$F$517,G8/$G$517,A8=$F$518,G8/$G$518,A8=$F$519,G8/$G$519,A8=$F$520,G8/$G$520,A8=$F$521,G8/$G$521,A8=$F$522,G8/$G$522,A8=$F$523,G8/$G$523,A8=$F$524,G8/$G$524),"")} -> 0.0025775871 | I8: {=IFERROR(_xlfn.IFS(A8=$M$3,H8*$S$3,A8=$M$4,H8*$S$4,A8=$M$5,H8*$S$5,A8=$M$6,H8*$S$6,A8=$M$7,H8*$S$7,A8=$M$8,H8*$S$8,A8=$M$9,H8*$S$9,A8=$M$10,H8*$S$10),"")} -> 345577.1 | J8: =SUM(G8,I8) -> 421192.1 | K8: =IFERROR(VLOOKUP(E8,'GASB Match'!$A$2:$C$58,3,FALSE),"") -> 0200050 | M8: 2020 | N8: Alaska | O8: AK | P8: Alaska Teachers' Retirement System Defined Benefit Pension Plan | Q8: State of Alaska (Nonemployer) | R8: 999 | S8: 140219115
A9: 2022 | B9: Alaska | C9: AK | D9: Alaska Teachers' Retirement System Defined Benefit Pension Plan | E9: Alaska Gateway School District | F9: 766 | G9: 82785 | H9: {=IFERROR(_xlfn.IFS(A9=$F$517,G9/$G$517,A9=$F$518,G9/$G$518,A9=$F$519,G9/$G$519,A9=$F$520,G9/$G$520,A9=$F$521,G9/$G$521,A9=$F$522,G9/$G$522,A9=$F$523,G9/$G$523,A9=$F$524,G9/$G$524),"")} -> 0.0026959383 | I9: {=IFERROR(_xlfn.IFS(A9=$M$3,H9*$S$3,A9=$M$4,H9*$S$4,A9=$M$5,H9*$S$5,A9=$M$6,H9*$S$6,A9=$M$7,H9*$S$7,A9=$M$8,H9*$S$8,A9=$M$9,H9*$S$9,A9=$M$10,H9*$S$10),"")} -> 382120.65 | J9: =SUM(G9,I9) -> 464905.65 | K9: =IFERROR(VLOOKUP(E9,'GASB Match'!$A$2:$C$58,3,FALSE),"") -> 0200050 | M9: 2021 | N9: Alaska | O9: AK | P9: Alaska Teachers' Retirement System Defined Benefit Pension Plan | Q9: State of Alaska (Nonemployer) | R9: 999 | S9: 134069997
A10: 2023 | B10: Alaska | C10: AK | D10: Alaska Teachers' Retirement System Defined Benefit Pension Plan | E10: Alaska Gateway School District | F10: 766 | G10: 96718 | H10: {=IFERROR(_xlfn.IFS(A10=$F$517,G10/$G$517,A10=$F$518,G10/$G$518,A10=$F$519,G10/$G$519,A10=$F$520,G10/$G$520,A10=$F$521,G10/$G$521,A10=$F$522,G10/$G$522,A10=$F$523,G10/$G$523,A10=$F$524,G10/$G$524),"")} | I10: {=IFERROR(_xlfn.IFS(A10=$M$3,H10*$S$3,A10=$M$4,H10*$S$4,A10=$M$5,H10*$S$5,A10=$M$6,H10*$S$6,A10=$M$7,H10*$S$7,A10=$M$8,H10*$S$8,A10=$M$9,H10*$S$9,A10=$M$10,H10*$S$10),"")} | J10: =SUM(G10,I10) -> 96718 | K10: =IFERROR(VLOOKUP(E10,'GASB Match'!$A$2:$C$58,3,FALSE),"") -> 0200050 | M10: 2022 | N10: Alaska | O10: AK | P10: Alaska Teachers' Retirement System Defined Benefit Pension Plan | Q10: State of Alaska (Nonemployer) | R10: 999 | S10: 141739390
A11: 2015 | B11: Alaska | C11: AK | D11: Alaska Teachers' Retirement System Defined Benefit Pension Plan | E11: Aleutian Region School District | F11: 758 | G11: 14119 | H11: {=IFERROR(_xlfn.IFS(A11=$F$517,G11/$G$517,A11=$F$518,G11/$G$518,A11=$F$519,G11/$G$519,A11=$F$520,G11/$G$520,A11=$F$521,G11/$G$521,A11=$F$522,G11/$G$522,A11=$F$523,G11/$G$523,A11=$F$524,G11/$G$524),"")} -> 0.0002907742 | I11: {=IFERROR(_xlfn.IFS(A11=$M$3,H11*$S$3,A11=$M$4,H11*$S$4,A11=$M$5,H11*$S$5,A11=$M$6,H11*$S$6,A11=$M$7,H11*$S$7,A11=$M$8,H11*$S$8,A11=$M$9,H11*$S$9,A11=$M$10,H11*$S$10),"")} -> 479927.77 | J11: =SUM(G11,I11) -> 494046.77 | K11: =IFERROR(VLOOKUP(E11,'GASB Match'!$A$2:$C$58,3,FALSE),"") -> 0200010 | M11: 2023 | N11: Alaska | O11: AK | P11: Alaska Teachers' Retirement System Defined Benefit Pension Plan | Q11: State of Alaska (Nonemployer) | R11: 999 | S11: 90412123
A12: 2016 | B12: Alaska | C12: AK | D12: Alaska Teachers' Retirement System Defined Benefit Pension Plan | E12: Aleutian Region School District | F12: 758 | G12: 7850 | H12: {=IFERROR(_xlfn.IFS(A12=$F$517,G12/$G$517,A12=$F$518,G12/$G$518,A12=$F$519,G12/$G$519,A12=$F$520,G12/$G$520,A12=$F$521,G12/$G$521,A12=$F$522,G12/$G$522,A12=$F$523,G12/$G$523,A12=$F$524,G12/$G$524),"")} -> 0.0002301344 | I12: {=IFERROR(_xlfn.IFS(A12=$M$3,H12*$S$3,A12=$M$4,H12*$S$4,A12=$M$5,H12*$S$5,A12=$M$6,H12*$S$6,A12=$M$7,H12*$S$7,A12=$M$8,H12*$S$8,A12=$M$9,H12*$S$9,A12=$M$10,H12*$S$10),"")} -> 20702.304 | J12: =SUM(G12,I12) -> 28552.304 | K12: =IFERROR(VLOOKUP(E12,'GASB Match'!$A$2:$C$58,3,FALSE),"") -> 0200010
A13: 2017 | B13: Alaska | C13: AK | D13: Alaska Teachers' Retirement System Defined Benefit Pension Plan | E13: Aleutian Region School District | F13: 758 | G13: 10585 | H13: {=IFERROR(_xlfn.IFS(A13=$F$517,G13/$G$517,A13=$F$518,G13/$G$518,A13=$F$519,G13/$G$519,A13=$F$520,G13/$G$520,A13=$F$521,G13/$G$521,A13=$F$522,G13/$G$522,A13=$F$523,G13/$G$523,A13=$F$524,G13/$G$524),"")} -> 0.00028337335 | I13: {=IFERROR(_xlfn.IFS(A13=$M$3,H13*$S$3,A13=$M$4,H13*$S$4,A13=$M$5,H13*$S$5,A13=$M$6,H13*$S$6,A13=$M$7,H13*$S$7,A13=$M$8,H13*$S$8,A13=$M$9,H13*$S$9,A13=$M$10,H13*$S$10),"")} -> 32865.708 | J13: =SUM(G13,I13) -> 43450.708 | K13: =IFERROR(VLOOKUP(E13,'GASB Match'!$A$2:$C$58,3,FALSE),"") -> 0200010
A14: 2018 | B14: Alaska | C14: AK | D14: Alaska Teachers' Retirement System Defined Benefit Pension Plan | E14: Aleutian Region School District | F14: 758 | G14: 12437 | H14: {=IFERROR(_xlfn.IFS(A14=$F$517,G14/$G$517,A14=$F$518,G14/$G$518,A14=$F$519,G14/$G$519,A14=$F$520,G14/$G$520,A14=$F$521,G14/$G$521,A14=$F$522,G14/$G$522,A14=$F$523,G14/$G$523,A14=$F$524,G14/$G$524),"")} -> 0.00030670568 | I14: {=IFERROR(_xlfn.IFS(A14=$M$3,H14*$S$3,A14=$M$4,H14*$S$4,A14=$M$5,H14*$S$5,A14=$M$6,H14*$S$6,A14=$M$7,H14*$S$7,A14=$M$8,H14*$S$8,A14=$M$9,H14*$S$9,A14=$M$10,H14*$S$10),"")} -> 34057.292 | J14: =SUM(G14,I14) -> 46494.292 | K14: =IFERROR(VLOOKUP(E14,'GASB Match'!$A$2:$C$58,3,FALSE),"") -> 0200010
A15: 2019 | B15: Alaska | C15: AK | D15: Alaska Teachers' Retirement System Defined Benefit Pension Plan | E15: Aleutian Region School District | F15: 758 | G15: 11751 | H15: {=IFERROR(_xlfn.IFS(A15=$F$517,G15/$G$517,A15=$F$518,G15/$G$518,A15=$F$519,G15/$G$519,A15=$F$520,G15/$G$520,A15=$F$521,G15/$G$521,A15=$F$522,G15/$G$522,A15=$F$523,G15/$G$523,A15=$F$524,G15/$G$524),"")} -> 0.00031927547 | I15: {=IFERROR(_xlfn.IFS(A15=$M$3,H15*$S$3,A15=$M$4,H15*$S$4,A15=$M$5,H15*$S$5,A15=$M$6,H15*$S$6,A15=$M$7,H15*$S$7,A15=$M$8,H15*$S$8,A15=$M$9,H15*$S$9,A15=$M$10,H15*$S$10),"")} -> 40664.444 | J15: =SUM(G15,I15) -> 52415.444 | K15: =IFERROR(VLOOKUP(E15,'GASB Match'!$A$2:$C$58,3,FALSE),"") -> 0200010
A16: 2020 | B16: Alaska | C16: AK | D16: Alaska Teachers' Retirement System Defined Benefit Pension Plan | E16: Aleutian Region School District | F16: 758 | G16: 11761 | H16: {=IFERROR(_xlfn.IFS(A16=$F$517,G16/$G$517,A16=$F$518,G16/$G$518,A16=$F$519,G16/$G$519,A16=$F$520,G16/$G$520,A16=$F$521,G16/$G$521,A16=$F$522,G16/$G$522,A16=$F$523,G16/$G$523,A16=$F$524,G16/$G$524),"")} -> 0.00034475147 | I16: {=IFERROR(_xlfn.IFS(A16=$M$3,H16*$S$3,A16=$M$4,H16*$S$4,A16=$M$5,H16*$S$5,A16=$M$6,H16*$S$6,A16=$M$7,H16*$S$7,A16=$M$8,H16*$S$8,A16=$M$9,H16*$S$9,A16=$M$10,H16*$S$10),"")} -> 48340.746 | J16: =SUM(G16,I16) -> 60101.746 | K16: =IFERROR(VLOOKUP(E16,'GASB Match'!$A$2:$C$58,3,FALSE),"") -> 0200010
A17: 2021 | B17: Alaska | C17: AK | D17: Alaska Teachers' Retirement System Defined Benefit Pension Plan | E17: Aleutian Region School District | F17: 758 | G17: 10241 | H17: {=IFERROR(_xlfn.IFS(A17=$F$517,G17/$G$517,A17=$F$518,G17/$G$518,A17=$F$519,G17/$G$519,A17=$F$520,G17/$G$520,A17=$F$521,G17/$G$521,A17=$F$522,G17/$G$522,A17=$F$523,G17/$G$523,A17=$F$524,G17/$G$524),"")} -> 0.00034909832 | I17: {=IFERROR(_xlfn.IFS(A17=$M$3,H17*$S$3,A17=$M$4,H17*$S$4,A17=$M$5,H17*$S$5,A17=$M$6,H17*$S$6,A17=$M$7,H17*$S$7,A17=$M$8,H17*$S$8,A17=$M$9,H17*$S$9,A17=$M$10,H17*$S$10),"")} -> 46803.611 | J17: =SUM(G17,I17) -> 57044.611 | K17: =IFERROR(VLOOKUP(E17,'GASB Match'!$A$2:$C$58,3,FALSE),"") -> 0200010
A18: 2022 | B18: Alaska | C18: AK | D18: Alaska Teachers' Retirement System Defined Benefit Pension Plan | E18: Aleutian Region School District | F18: 758 | G18: 10364 | H18: {=IFERROR(_xlfn.IFS(A18=$F$517,G18/$G$517,A18=$F$518,G18/$G$518,A18=$F$519,G18/$G$519,A18=$F$520,G18/$G$520,A18=$F$521,G18/$G$521,A18=$F$522,G18/$G$522,A18=$F$523,G18/$G$523,A18=$F$524,G18/$G$524),"")} -> 0.00033750927 | I18: {=IFERROR(_xlfn.IFS(A18=$M$3,H18*$S$3,A18=$M$4,H18*$S$4,A18=$M$5,H18*$S$5,A18=$M$6,H18*$S$6,A18=$M$7,H18*$S$7,A18=$M$8,H18*$S$8,A18=$M$9,H18*$S$9,A18=$M$10,H18*$S$10),"")} -> 47838.358 | J18: =SUM(G18,I18) -> 58202.358 | K18: =IFERROR(VLOOKUP(E18,'GASB Match'!$A$2:$C$58,3,FALSE),"") -> 0200010
A19: 2023 | B19: Alaska | C19: AK | D19: Alaska Teachers' Retirement System Defined Benefit Pension Plan | E19: Aleutian Region School District | F19: 758 | G19: 13673 | H19: {=IFERROR(_xlfn.IFS(A19=$F$517,G19/$G$517,A19=$F$518,G19/$G$518,A19=$F$519,G19/$G$519,A19=$F$520,G19/$G$520,A19=$F$521,G19/$G$521,A19=$F$522,G19/$G$522,A19=$F$523,G19/$G$523,A19=$F$524,G19/$G$524),"")} | I19: {=IFERROR(_xlfn.IFS(A19=$M$3,H19*$S$3,A19=$M$4,H19*$S$4,A19=$M$5,H19*$S$5,A19=$M$6,H19*$S$6,A19=$M$7,H19*$S$7,A19=$M$8,H19*$S$8,A19=$M$9,H19*$S$9,A19=$M$10,H19*$S$10),"")} | J19: =SUM(G19,I19) -> 13673 | K19: =IFERROR(VLOOKUP(E19,'GASB Match'!$A$2:$C$58,3,FALSE),"") -> 0200010
A20: 2015 | B20: Alaska | C20: AK | D20: Alaska Teachers' Retirement System Defined Benefit Pension Plan | E20: Aleutians East Borough School District | F20: 780 | G20: 87302 | H20: {=IFERROR(_xlfn.IFS(A20=$F$517,G20/$G$517,A20=$F$518,G20/$G$518,A20=$F$519,G20/$G$519,A20=$F$520,G20/$G$520,A20=$F$521,G20/$G$521,A20=$F$522,G20/$G$522,A20=$F$523,G20/$G$523,A20=$F$524,G20/$G$524),"")} -> 0.0017979439 | I20: {=IFERROR(_xlfn.IFS(A20=$M$3,H20*$S$3,A20=$M$4,H20*$S$4,A20=$M$5,H20*$S$5,A20=$M$6,H20*$S$6,A20=$M$7,H20*$S$7,A20=$M$8,H20*$S$8,A20=$M$9,H20*$S$9,A20=$M$10,H20*$S$10),"")} -> 2967536.9 | J20: =SUM(G20,I20) -> 3054838.9 | K20: =IFERROR(VLOOKUP(E20,'GASB Match'!$A$2:$C$58,3,FALSE),"") -> 0200007
A21: 2016 | B21: Alaska | C21: AK | D21: Alaska Teachers' Retirement System Defined Benefit Pension Plan | E21: Aleutians East Borough School District | F21: 780 | G21: 75752 | H21: {=IFERROR(_xlfn.IFS(A21=$F$517,G21/$G$517,A21=$F$518,G21/$G$518,A21=$F$519,G21/$G$519,A21=$F$520,G21/$G$520,A21=$F$521,G21/$G$521,A21=$F$522,G21/$G$522,A21=$F$523,G21/$G$523,A21=$F$524,G21/$G$524),"")} -> 0.0022207823 | I21: {=IFERROR(_xlfn.IFS(A21=$M$3,H21*$S$3,A21=$M$4,H21*$S$4,A21=$M$5,H21*$S$5,A21=$M$6,H21*$S$6,A21=$M$7,H21*$S$7,A21=$M$8,H21*$S$8,A21=$M$9,H21*$S$9,A21=$M$10,H21*$S$10),"")} -> 199775.92 | J21: =SUM(G21,I21) -> 275527.92 | K21: =IFERROR(VLOOKUP(E21,'GASB Match'!$A$2:$C$58,3,FALSE),"") -> 0200007
A22: 2017 | B22: Alaska | C22: AK | D22: Alaska Teachers' Retirement System Defined Benefit Pension Plan | E22: Aleutians East Borough School District | F22: 780 | G22: 86296 | H22: {=IFERROR(_xlfn.IFS(A22=$F$517,G22/$G$517,A22=$F$518,G22/$G$518,A22=$F$519,G22/$G$519,A22=$F$520,G22/$G$520,A22=$F$521,G22/$G$521,A22=$F$522,G22/$G$522,A22=$F$523,G22/$G$523,A22=$F$524,G22/$G$524),"")} -> 0.0023102491 | I22: {=IFERROR(_xlfn.IFS(A22=$M$3,H22*$S$3,A22=$M$4,H22*$S$4,A22=$M$5,H22*$S$5,A22=$M$6,H22*$S$6,A22=$M$7,H22*$S$7,A22=$M$8,H22*$S$8,A22=$M$9,H22*$S$9,A22=$M$10,H22*$S$10),"")} -> 267943.24 | J22: =SUM(G22,I22) -> 354239.24 | K22: =IFERROR(VLOOKUP(E22,'GASB Match'!$A$2:$C$58,3,FALSE),"") -> 0200007
A23: 2018 | B23: Alaska | C23: AK | D23: Alaska Teachers' Retirement System Defined Benefit Pension Plan | E23: Aleutians East Borough School District | F23: 780 | G23: 112452 | H23: {=IFERROR(_xlfn.IFS(A23=$F$517,G23/$G$517,A23=$F$518,G23/$G$518,A23=$F$519,G23/$G$519,A23=$F$520,G23/$G$520,A23=$F$521,G23/$G$521,A23=$F$522,G23/$G$522,A23=$F$523,G23/$G$523,A23=$F$524,G23/$G$524),"")} -> 0.0027731501 | I23: {=IFERROR(_xlfn.IFS(A23=$M$3,H23*$S$3,A23=$M$4,H23*$S$4,A23=$M$5,H23*$S$5,A23=$M$6,H23*$S$6,A23=$M$7,H23*$S$7,A23=$M$8,H23*$S$8,A23=$M$9,H23*$S$9,A23=$M$10,H23*$S$10),"")} -> 307936.85 | J23: =SUM(G23,I23) -> 420388.85 | K23: =IFERROR(VLOOKUP(E23,'GASB Match'!$A$2:$C$58,3,FALSE),"") -> 0200007
... A514: 2023 | B514: Alaska | C514: AK | D514: Alaska Teachers' Retirement System Defined Benefit Pension Plan | E514: Yupiit School District | F514: 778 | G514: 142997 | H514: {=IFERROR(_xlfn.IFS(A514=$F$517,G514/$G$517,A514=$F$518,G514/$G$518,A514=$F$519,G514/$G$519,A514=$F$520,G514/$G$520,A514=$F$521,G514/$G$521,A514=$F$522,G514/$G$522,A514=$F$523,G514/$G$523,A514=$F$524,G514/$G$524),"")} | I514: {=IFERROR(_xlfn.IFS(A514=$M$3,H514*$S$3,A514=$M$4,H514*$S$4,A514=$M$5,H514*$S$5,A514=$M$6,H514*$S$6,A514=$M$7,H514*$S$7,A514=$M$8,H514*$S$8,A514=$M$9,H514*$S$9,A514=$M$10,H514*$S$10),"")} | J514: =SUM(G514,I514) -> 142997 | K514: =IFERROR(VLOOKUP(E514,'GASB Match'!$A$2:$C$58,3,FALSE),"") -> 0200004
F517: 2015 | G517: =SUMIF($A$2:$A$514,F517,$G$2:$G$514) -> 48556577
F518: 2016 | G518: =SUMIF($A$2:$A$514,F518,$G$2:$G$514) -> 34110503
F519: 2017 | G519: =SUMIF($A$2:$A$514,F519,$G$2:$G$514) -> 37353548
F520: 2018 | G520: =SUMIF($A$2:$A$514,F520,$G$2:$G$514) -> 40550276
F521: 2019 | G521: =SUMIF($A$2:$A$514,F521,$G$2:$G$514) -> 36805208
F522: 2020 | G522: =SUMIF($A$2:$A$514,F522,$G$2:$G$514) -> 34114430
F523: 2021 | G523: =SUMIF($A$2:$A$514,F523,$G$2:$G$514) -> 29335575
F524: 2022 | G524: =SUMIF($A$2:$A$514,F524,$G$2:$G$514) -> 30707305

Sheet GASB Match
A1: district_name | B1: LEAID
A2: Alaska Gateway School District | B2: 200050 | C2: =IF(B2>0,0&B2,"") -> 0200050
A3: Aleutian Region School District | B3: 200010 | C3: =IF(B3>0,0&B3,"") -> 0200010
A4: Aleutians East Borough School District | B4: 200007 | C4: =IF(B4>0,0&B4,"") -> 0200007
A5: Anchorage School District | B5: 200180 | C5: =IF(B5>0,0&B5,"") -> 0200180
A6: Annette Island School District | B6: 200525 | C6: =IF(B6>0,0&B6,"") -> 0200525
A7: Bering Strait School District | B7: 200020 | C7: =IF(B7>0,0&B7,"") -> 0200020
A8: Bristol Bay Borough School District | B8: 200030 | C8: =IF(B8>0,0&B8,"") -> 0200030
A9: Chatham School District | B9: 200730 | C9: =IF(B9>0,0&B9,"") -> 0200730
A10: Chugach School District | B10: 200800 | C10: =IF(B10>0,0&B10,"") -> 0200800
A11: Copper River School District | B11: 200070 | C11: =IF(B11>0,0&B11,"") -> 0200070
A12: Cordova City School District | B12: 200060 | C12: =IF(B12>0,0&B12,"") -> 0200060
A13: Craig City School District | B13: 200090 | C13: =IF(B13>0,0&B13,"") -> 0200090
... A45: Southeast Island School District | B45: 200700 | C45: =IF(B45>0,0&B45,"") -> 0200700
A46: Southeast Regional Resource Center | C46: =IF(B46>0,0&B46,"")
A47: Southwest Region School District | B47: 200710 | C47: =IF(B47>0,0&B47,"") -> 0200710
A48: Special Education Service Agency | C48: =IF(B48>0,0&B48,"")
A49: State of Alaska | C49: =IF(B49>0,0&B49,"")
A50: Tanana School District | B50: 200715 | C50: =IF(B50>0,0&B50,"") -> 0200715
A51: Unalaska City School District | B51: 200720 | C51: =IF(B51>0,0&B51,"") -> 0200720
A52: University of Alaska | C52: =IF(B52>0,0&B52,"")
A53: Valdez City School District | B53: 200780 | C53: =IF(B53>0,0&B53,"") -> 0200780
A54: Wrangell Public School District | B54: 200810 | C54: =IF(B54>0,0&B54,"") -> 0200810
A55: Yakutat School District | B55: 200840 | C55: =IF(B55>0,0&B55,"") -> 0200840
A56: Yukon / Koyukuk School District | B56: 200862 | C56: =IF(B56>0,0&B56,"") -> 0200862
A57: Yukon Flats School District | B57: 200775 | C57: =IF(B57>0,0&B57,"") -> 0200775
A58: Yupiit School District | B58: 200004 | C58: =IF(B58>0,0&B58,"") -> 0200004
