Workbook

Sheet Summary
A1: Year | B1: State | C1: state_abv | D1: plan | E1: district_name | F1: district_contributions | G1: state_contributions | H1: total_contributions | I1: LEAID_match
A2: 2015 | B2: Delaware | C2: DE | D2: Delaware Public Employees' Retirement System - State Employees' Plan | E2: Academia Antonia Alonso Charter | F2: 71109 | G2: 127097.04 | H2: =SUM(F2:G2) -> 198206.04 | I2: =IFERROR(VLOOKUP(E2,'LEAID Match'!$A$2:$B$44,2,FALSE),"") -> 1000053
A3: 2016 | B3: Delaware | C3: DE | D3: Delaware Public Employees' Retirement System - State Employees' Plan | E3: Academia Antonia Alonso Charter | F3: 105534 | G3: 215679.27 | H3: =SUM(F3:G3) -> 321213.27 | I3: =IFERROR(VLOOKUP(E3,'LEAID Match'!$A$2:$B$44,2,FALSE),"") -> 1000053
A4: 2017 | B4: Delaware | C4: DE | D4: Delaware Public Employees' Retirement System - State Employees' Plan | E4: Academia Antonia Alonso Charter | F4: 119341 | G4: 185128.21 | H4: =SUM(F4:G4) -> 304469.21 | I4: =IFERROR(VLOOKUP(E4,'LEAID Match'!$A$2:$B$44,2,FALSE),"") -> 1000053
A5: 2018 | B5: Delaware | C5: DE | D5: Delaware Public Employees' Retirement System - State Employees' Plan | E5: Academia Antonia Alonso Charter | F5: 193483 | G5: 91999.869 | H5: =SUM(F5:G5) -> 285482.87 | I5: =IFERROR(VLOOKUP(E5,'LEAID Match'!$A$2:$B$44,2,FALSE),"") -> 1000053
A6: 2019 | B6: Delaware | C6: DE | D6: Delaware Public Employees' Retirement System - State Employees' Plan | E6: Academia Antonia Alonso Charter | F6: 350968 | G6: 283876.31 | H6: =SUM(F6:G6) -> 634844.31 | I6: =IFERROR(VLOOKUP(E6,'LEAID Match'!$A$2:$B$44,2,FALSE),"") -> 1000053
A7: 2020 | B7: Delaware | C7: DE | D7: Delaware Public Employees' Retirement System - State Employees' Plan | E7: Academia Antonia Alonso Charter | F7: 426516 | G7: 87713.989 | H7: =SUM(F7:G7) -> 514229.99 | I7: =IFERROR(VLOOKUP(E7,'LEAID Match'!$A$2:$B$44,2,FALSE),"") -> 1000053
A8: 2021 | B8: Delaware | C8: DE | D8: Delaware Public Employees' Retirement System - State Employees' Plan | E8: Academia Antonia Alonso Charter | F8: 459545 | G8: 0 | H8: =SUM(F8:G8) -> 459545 | I8: =IFERROR(VLOOKUP(E8,'LEAID Match'!$A$2:$B$44,2,FALSE),"") -> 1000053
A9: 2022 | B9: Delaware | C9: DE | D9: Delaware Public Employees' Retirement System - State Employees' Plan | E9: Academia Antonia Alonso Charter | F9: 535781 | G9: 535781 | H9: =SUM(F9:G9) -> 1071562 | I9: =IFERROR(VLOOKUP(E9,'LEAID Match'!$A$2:$B$44,2,FALSE),"") -> 1000053
A10: 2023 | B10: Delaware | C10: DE | D10: Delaware Public Employees' Retirement System - State Employees' Plan | E10: Academia Antonia Alonso Charter | F10: 527365 | G10: 2758011.8 | H10: =SUM(F10:G10) -> 3285376.8 | I10: =IFERROR(VLOOKUP(E10,'LEAID Match'!$A$2:$B$44,2,FALSE),"") -> 1000053
A11: 2015 | B11: Delaware | C11: DE | D11: Delaware Public Employees' Retirement System - State Employees' Plan | E11: Academy of Dover Charter | F11: 124896 | G11: 223233.51 | H11: =SUM(F11:G11) -> 348129.51 | I11: =IFERROR(VLOOKUP(E11,'LEAID Match'!$A$2:$B$44,2,FALSE),"") -> 1000017
A12: 2016 | B12: Delaware | C12: DE | D12: Delaware Public Employees' Retirement System - State Employees' Plan | E12: Academy of Dover Charter | F12: 121924 | G12: 249175.43 | H12: =SUM(F12:G12) -> 371099.43 | I12: =IFERROR(VLOOKUP(E12,'LEAID Match'!$A$2:$B$44,2,FALSE),"") -> 1000017
A13: 2017 | B13: Delaware | C13: DE | D13: Delaware Public Employees' Retirement System - State Employees' Plan | E13: Academy of Dover Charter | F13: 110385 | G13: 171235.18 | H13: =SUM(F13:G13) -> 281620.18 | I13: =IFERROR(VLOOKUP(E13,'LEAID Match'!$A$2:$B$44,2,FALSE),"") -> 1000017
... A46: 2016 | B46: Delaware | C46: DE | D46: Delaware Public Employees' Retirement System - State Employees' Plan | E46: DE College Prep Charter | F46: 94532 | G46: 193194.54 | H46: =SUM(F46:G46) -> 287726.54 | I46: =IFERROR(VLOOKUP(E46,'LEAID Match'!$A$2:$B$44,2,FALSE),"") -> 1000047
A47: 2017 | B47: Delaware | C47: DE | D47: Delaware Public Employees' Retirement System - State Employees' Plan | E47: DE College Prep Charter | G47: 0 | H47: =SUM(F47:G47) -> 0 | I47: =IFERROR(VLOOKUP(E47,'LEAID Match'!$A$2:$B$44,2,FALSE),"") -> 1000047
A48: 2018 | B48: Delaware | C48: DE | D48: Delaware Public Employees' Retirement System - State Employees' Plan | E48: DE College Prep Charter | G48: 0 | H48: =SUM(F48:G48) -> 0 | I48: =IFERROR(VLOOKUP(E48,'LEAID Match'!$A$2:$B$44,2,FALSE),"") -> 1000047
A49: 2016 | B49: Delaware | C49: DE | D49: Delaware Public Employees' Retirement System - State Employees' Plan | E49: DE Military Academy Charter | F49: 266831 | G49: 545321.09 | H49: =SUM(F49:G49) -> 812152.09 | I49: =IFERROR(VLOOKUP(E49,'LEAID Match'!$A$2:$B$44,2,FALSE),"") -> 1000016
A50: 2017 | B50: Delaware | C50: DE | D50: Delaware Public Employees' Retirement System - State Employees' Plan | E50: DE Military Academy Charter | F50: 272738 | G50: 423085.93 | H50: =SUM(F50:G50) -> 695823.93 | I50: =IFERROR(VLOOKUP(E50,'LEAID Match'!$A$2:$B$44,2,FALSE),"") -> 1000016
A51: 2015 | B51: Delaware | C51: DE | D51: Delaware Public Employees' Retirement System - State Employees' Plan | E51: DE Military Academy Charter | F51: 252762 | G51: 451775.47 | H51: =SUM(F51:G51) -> 704537.47 | I51: =IFERROR(VLOOKUP(E51,'LEAID Match'!$A$2:$B$44,2,FALSE),"") -> 1000016
A52: 2018 | B52: Delaware | C52: DE | D52: Delaware Public Employees' Retirement System - State Employees' Plan | E52: DE Military Academy Charter | F52: 318088 | G52: 151248.71 | H52: =SUM(F52:G52) -> 469336.71 | I52: =IFERROR(VLOOKUP(E52,'LEAID Match'!$A$2:$B$44,2,FALSE),"") -> 1000016
A53: 2019 | B53: Delaware | C53: DE | D53: Delaware Public Employees' Retirement System - State Employees' Plan | E53: DE Military Academy Charter | F53: 376713 | G53: 304699.84 | H53: =SUM(F53:G53) -> 681412.84 | I53: =IFERROR(VLOOKUP(E53,'LEAID Match'!$A$2:$B$44,2,FALSE),"") -> 1000016
A54: 2020 | B54: Delaware | C54: DE | D54: Delaware Public Employees' Retirement System - State Employees' Plan | E54: DE Military Academy Charter | F54: 390357 | G54: 80277.808 | H54: =SUM(F54:G54) -> 470634.81 | I54: =IFERROR(VLOOKUP(E54,'LEAID Match'!$A$2:$B$44,2,FALSE),"") -> 1000016
A55: 2021 | B55: Delaware | C55: DE | D55: Delaware Public Employees' Retirement System - State Employees' Plan | E55: DE Military Academy Charter | F55: 428201 | G55: 0 | H55: =SUM(F55:G55) -> 428201 | I55: =IFERROR(VLOOKUP(E55,'LEAID Match'!$A$2:$B$44,2,FALSE),"") -> 1000016
A56: 2022 | B56: Delaware | C56: DE | D56: Delaware Public Employees' Retirement System - State Employees' Plan | E56: DE Military Academy Charter | F56: 423842 | G56: 423842 | H56: =SUM(F56:G56) -> 847684 | I56: =IFERROR(VLOOKUP(E56,'LEAID Match'!$A$2:$B$44,2,FALSE),"") -> 1000016
A57: 2023 | B57: Delaware | C57: DE | D57: Delaware Public Employees' Retirement System - State Employees' Plan | E57: DE Military Academy Charter | F57: 415811 | G57: 2174607 | H57: =SUM(F57:G57) -> 2590418 | I57: =IFERROR(VLOOKUP(E57,'LEAID Match'!$A$2:$B$44,2,FALSE),"") -> 1000016
A58: 2022 | B58: Delaware | C58: DE | D58: Delaware Public Employees' Retirement System - State Employees' Plan | E58: Delaware Agricultural Lands Preservation Foundation | F58: 8200 | G58: 8200 | H58: =SUM(F58:G58) -> 16400 | I58: =IFERROR(VLOOKUP(E58,'LEAID Match'!$A$2:$B$44,2,FALSE),"") -> 0
A59: 2023 | B59: Delaware | C59: DE | D59: Delaware Public Employees' Retirement System - State Employees' Plan | E59: Delaware Agricultural Lands Preservation Foundation | F59: 7629 | G59: 39898.119 | H59: =SUM(F59:G59) -> 47527.119 | I59: =IFERROR(VLOOKUP(E59,'LEAID Match'!$A$2:$B$44,2,FALSE),"") -> 0
A60: 2015 | B60: Delaware | C60: DE | D60: Delaware Public Employees' Retirement System - State Employees' Plan | E60: Delaware Department of Transportation | F60: 6508133 | G60: 11632345 | H60: =SUM(F60:G60) -> 18140478 | I60: =IFERROR(VLOOKUP(E60,'LEAID Match'!$A$2:$B$44,2,FALSE),"") -> 0
... A107: 2017 | B107: Delaware | C107: DE | D107: Delaware Public Employees' Retirement System - State Employees' Plan | E107: Delaware STEM Academy | F107: 210 | G107: 325.76336 | H107: =SUM(F107:G107) -> 535.76336 | I107: =IFERROR(VLOOKUP(E107,'LEAID Match'!$A$2:$B$44,2,FALSE),"") -> 1000061
A108: 2018 | B108: Delaware | C108: DE | D108: Delaware Public Employees' Retirement System - State Employees' Plan | E108: Delaware STEM Academy | G108: 0 | H108: =SUM(F108:G108) -> 0 | I108: =IFERROR(VLOOKUP(E108,'LEAID Match'!$A$2:$B$44,2,FALSE),"") -> 1000061
A109: 2015 | B109: Delaware | C109: DE | D109: Delaware Public Employees' Retirement System - State Employees' Plan | E109: Early College High School Charter | F109: 34099 | G109: 60947.025 | H109: =SUM(F109:G109) -> 95046.025 | I109: =IFERROR(VLOOKUP(E109,'LEAID Match'!$A$2:$B$44,2,FALSE),"") -> 1000055
A110: 2016 | B110: Delaware | C110: DE | D110: Delaware Public Employees' Retirement System - State Employees' Plan | E110: Early College High School Charter | F110: 85941 | G110: 175637.16 | H110: =SUM(F110:G110) -> 261578.16 | I110: =IFERROR(VLOOKUP(E110,'LEAID Match'!$A$2:$B$44,2,FALSE),"") -> 1000055
A111: 2017 | B111: Delaware | C111: DE | D111: Delaware Public Employees' Retirement System - State Employees' Plan | E111: Early College High School Charter | F111: 121375 | G111: 188283.46 | H111: =SUM(F111:G111) -> 309658.46 | I111: =IFERROR(VLOOKUP(E111,'LEAID Match'!$A$2:$B$44,2,FALSE),"") -> 1000055
A112: 2018 | B112: Delaware | C112: DE | D112: Delaware Public Employees' Retirement System - State Employees' Plan | E112: Early College High School Charter | F112: 152884 | G112: 72695.317 | H112: =SUM(F112:G112) -> 225579.32 | I112: =IFERROR(VLOOKUP(E112,'LEAID Match'!$A$2:$B$44,2,FALSE),"") -> 1000055
A113: 2019 | B113: Delaware | C113: DE | D113: Delaware Public Employees' Retirement System - State Employees' Plan | E113: Early College High School Charter | F113: 173310 | G113: 140179.74 | H113: =SUM(F113:G113) -> 313489.74 | I113: =IFERROR(VLOOKUP(E113,'LEAID Match'!$A$2:$B$44,2,FALSE),"") -> 1000055
A114: 2020 | B114: Delaware | C114: DE | D114: Delaware Public Employees' Retirement System - State Employees' Plan | E114: Early College High School Charter | F114: 195904 | G114: 40288.105 | H114: =SUM(F114:G114) -> 236192.1 | I114: =IFERROR(VLOOKUP(E114,'LEAID Match'!$A$2:$B$44,2,FALSE),"") -> 1000055
A115: 2021 | B115: Delaware | C115: DE | D115: Delaware Public Employees' Retirement System - State Employees' Plan | E115: Early College High School Charter | F115: 187393 | G115: 0 | H115: =SUM(F115:G115) -> 187393 | I115: =IFERROR(VLOOKUP(E115,'LEAID Match'!$A$2:$B$44,2,FALSE),"") -> 1000055
A116: 2022 | B116: Delaware | C116: DE | D116: Delaware Public Employees' Retirement System - State Employees' Plan | E116: Early College High School Charter | F116: 244534 | G116: 244534 | H116: =SUM(F116:G116) -> 489068 | I116: =IFERROR(VLOOKUP(E116,'LEAID Match'!$A$2:$B$44,2,FALSE),"") -> 1000055
A117: 2023 | B117: Delaware | C117: DE | D117: Delaware Public Employees' Retirement System - State Employees' Plan | E117: Early College High School Charter | F117: 302228 | G117: 1580591 | H117: =SUM(F117:G117) -> 1882819 | I117: =IFERROR(VLOOKUP(E117,'LEAID Match'!$A$2:$B$44,2,FALSE),"") -> 1000055
A118: 2015 | B118: Delaware | C118: DE | D118: Delaware Public Employees' Retirement System - State Employees' Plan | E118: East Side Charter | F118: 302200 | G118: 540138.74 | H118: =SUM(F118:G118) -> 842338.74 | I118: =IFERROR(VLOOKUP(E118,'LEAID Match'!$A$2:$B$44,2,FALSE),"") -> 1000006
...

Sheet Delaware St Emp GASB 68 -->

Sheet 2015
A1: Year | B1: district_name | C1: district_contributions | D1: district_prop | E1: state_contributions
A2: 2015 | B2: Academia Antonia Alonso Charter | C2: 71109 | D2: =C2/$C$39 -> 0.003892235 | E2: =D2*$C$37 -> 127097.04
A3: 2015 | B3: Academy of Dover Charter | C3: 124896 | D3: =C3/$C$39 -> 0.0068363298 | E3: =D3*$C$37 -> 223233.51
A4: 2015 | B4: Campus Community Charter | C4: 186452 | D4: =C4/$C$39 -> 0.01020567 | E4: =D4*$C$37 -> 333255.95
A5: 2015 | B5: De Academy Public Safety Charter | C5: 189970 | D5: =C5/$C$39 -> 0.010398232 | E5: =D5*$C$37 -> 339543.87
A6: 2015 | B6: DE Aglands | C6: 8259 | D6: =C6/$C$39 -> 0.0004520661 | E6: =D6*$C$37 -> 14761.767
A7: 2015 | B7: DE College Prep Charter | C7: 84663 | D7: =C7/$C$39 -> 0.0046341291 | E7: =D7*$C$37 -> 151322.85
A8: 2015 | B8: DE Military Academy Charter | C8: 252762 | D8: =C8/$C$39 -> 0.013835226 | E8: =D8*$C$37 -> 451775.47
A9: 2015 | B9: Delaware Economic Development Office | C9: 239141 | D9: =C9/$C$39 -> 0.013089665 | E9: =D9*$C$37 -> 427429.91
A10: 2015 | B10: Delaware Department of Transportation | C10: 6508133 | D10: =C10/$C$39 -> 0.35623033 | E10: =D10*$C$37 -> 11632345
A11: 2015 | B11: Delaware State Education Association | C11: 9311 | D11: =C11/$C$39 -> 0.00050964857 | E11: =D11*$C$37 -> 16642.064
A12: 2015 | B12: Delaware State Housing Authority | C12: 82415 | D12: =C12/$C$39 -> 0.0045110822 | E12: =D12*$C$37 -> 147304.88
A13: 2015 | B13: Delaware State University | C13: 4543491 | D13: =C13/$C$39 -> 0.24869334 | E13: =D13*$C$37 -> 8120832.3
... A27: 2015 | B27: Odyssey Charter | C27: 465410 | D27: =C27/$C$39 -> 0.025474765 | E27: =D27*$C$37 -> 831852.98
A28: 2015 | B28: Pencader Charter | D28: =C28/$C$39 -> 0 | E28: =D28*$C$37 -> 0
A29: 2015 | B29: Positive Outcomes Charter | C29: 130283 | D29: =C29/$C$39 -> 0.0071311936 | E29: =D29*$C$37 -> 232862
A30: 2015 | B30: Prestige Charter | C30: 138146 | D30: =C30/$C$39 -> 0.0075615842 | E30: =D30*$C$37 -> 246915.97
A31: 2015 | B31: Providence Creek Charter | C31: 241709 | D31: =C31/$C$39 -> 0.013230227 | E31: =D31*$C$37 -> 432019.84
A32: 2015 | B32: Reach Charter | C32: 204772 | D32: =C32/$C$39 -> 0.011208437 | E32: =D32*$C$37 -> 366000.3
A33: 2015 | B33: Sussex Academy Charter | C33: 220473 | D33: =C33/$C$39 -> 0.01206785 | E33: =D33*$C$37 -> 394063.56
A34: 2015 | B34: The Charter School of Wilmington | C34: 486345 | D34: =C34/$C$39 -> 0.026620667 | E34: =D34*$C$37 -> 869271.26
A35: 2015 | B35: The Delaware Met Charter | C35: 3989 | D35: =C35/$C$39 -> 0.00021834262 | E35: =D35*$C$37 -> 7129.7599
A36: 2015 | B36: Thomas Edison Charter | C36: 354261 | D36: =C36/$C$39 -> 0.019390894 | E36: =D36*$C$37 -> 633190.24
A37: 2015 | B37: State of Delaware | C37: 32654000
C39: =SUM(C2:C36) -> 18269452

Sheet 2016
A1: Year | B1: district_name | C1: district_contributions | D1: district_prop | E1: state_contributions
A2: 2016 | B2: Academia Antonia Alonso Charter | C2: 105534 | D2: =C2/$C$43 -> 0.0055618684 | E2: =D2*$C$41 -> 215679.27
A3: 2016 | B3: Academy of Dover Charter | C3: 121924 | D3: =C3/$C$43 -> 0.0064256566 | E3: =D3*$C$41 -> 249175.43
A4: 2016 | B4: Campus Communit y Charter | C4: 190678 | D4: =C4/$C$43 -> 0.01004914 | E4: =D4*$C$41 -> 389687.61
A5: 2016 | B5: DE Academy Public Safety Charter | C5: 162547 | D5: =C5/$C$43 -> 0.0085665759 | E5: =D5*$C$41 -> 332196.44
A6: 2016 | B6: DE Aglands | C6: 9141 | D6: =C6/$C$43 -> 0.00048175033 | E6: =D6*$C$41 -> 18681.413
A7: 2016 | B7: DE College Prep Charter | C7: 94532 | D7: =C7/$C$43 -> 0.0049820394 | E7: =D7*$C$41 -> 193194.54
A8: 2016 | B8: DE Milit ary Academy Charter | C8: 266831 | D8: =C8/$C$43 -> 0.014062567 | E8: =D8*$C$41 -> 545321.09
A9: 2016 | B9: Delaware Design-Lab | C9: 62252 | D9: =C9/$C$43 -> 0.0032808141 | E9: =D9*$C$41 -> 127224.08
A10: 2016 | B10: Delaware Department of Transportation | C10: 6508250 | D10: =C10/$C$43 -> 0.34299875 | E10: =D10*$C$41 -> 13300876
A11: 2016 | B11: Delaware Economic Development Office | C11: 244967 | D11: =C11/$C$43 -> 0.012910287 | E11: =D11*$C$41 -> 500637.75
A12: 2016 | B12: Delaware Solid Waste Authority | C12: 519277 | D12: =C12/$C$43 -> 0.027367013 | E12: =D12*$C$41 -> 1061243.6
A13: 2016 | B13: Delaware State Educat ion Association | C13: 10205 | D13: =C13/$C$43 -> 0.00053782541 | E13: =D13*$C$41 -> 20855.904
... A28: 2016 | B28: MOT Charter | C28: 434928 | D28: =C28/$C$43 -> 0.022921639 | E28: =D28*$C$41 -> 888860.03
A29: 2016 | B29: Moyer Academy Charter | D29: =C29/$C$43 -> 0 | E29: =D29*$C$41 -> 0
A30: 2016 | B30: Newark Charter | C30: 1175501 | D30: =C30/$C$43 -> 0.061951427 | E30: =D30*$C$41 -> 2402365.1
A31: 2016 | B31: Odyssey Charter | C31: 504157 | D31: =C31/$C$43 -> 0.026570156 | E31: =D31*$C$41 -> 1030343
A32: 2016 | B32: Pencader Charter | D32: =C32/$C$43 -> 0 | E32: =D32*$C$41 -> 0
A33: 2016 | B33: Posit ive Out comes Charter | C33: 130635 | D33: =C33/$C$43 -> 0.006884745 | E33: =D33*$C$41 -> 266978.05
A34: 2016 | B34: Prestige Charter | C34: 150889 | D34: =C34/$C$43 -> 0.0079521743 | E34: =D34*$C$41 -> 308371.04
A35: 2016 | B35: Providence Creek Charter | C35: 266745 | D35: =C35/$C$43 -> 0.014058034 | E35: =D35*$C$41 -> 545145.33
A36: 2016 | B36: Reach Charter | D36: =C36/$C$43 -> 0 | E36: =D36*$C$41 -> 0
A37: 2016 | B37: Sussex Academy Charter | C37: 275448 | D37: =C37/$C$43 -> 0.014516701 | E37: =D37*$C$41 -> 562931.61
A38: 2016 | B38: The Charter School of Wilmington | C38: 503089 | D38: =C38/$C$43 -> 0.02651387 | E38: =D38*$C$41 -> 1028160.3
A39: 2016 | B39: The Delaware Met Charter | C39: 39611 | D39: =C39/$C$43 -> 0.0020875847 | E39: =D39*$C$41 -> 80952.789
A40: 2016 | B40: Thomas Edison Charter | C40: 348903 | D40: =C40/$C$43 -> 0.018387937 | E40: =D40*$C$41 -> 713051.2
A41: 2016 | B41: State of Delaware | C41: 38778205
C43: =SUM(C2:C40) -> 18974559

Sheet 2017
A1: Year | B1: district_name | C1: district_contributions | D1: district_prop | E1: state_contributions
A2: 2017 | B2: Academia Antonia Alonso Charter | C2: 119341 | D2: =C2/$C$43 -> 0.0061094791 | E2: =D2*$C$41 -> 185128.21
A3: 2017 | B3: Academy of Dover Charter | C3: 110385 | D3: =C3/$C$43 -> 0.0056509904 | E3: =D3*$C$41 -> 171235.18
A4: 2017 | B4: Campus Communit y Charter | C4: 180877 | D4: =C4/$C$43 -> 0.00925972 | E4: =D4*$C$41 -> 280586.18
A5: 2017 | B5: DE Academy Public Safety Charter | C5: 151412 | D5: =C5/$C$43 -> 0.0077513046 | E5: =D5*$C$41 -> 234878.48
A6: 2017 | B6: DE Aglands | C6: 10008 | D6: =C6/$C$43 -> 0.00051234418 | E6: =D6*$C$41 -> 15524.951
A7: 2017 | B7: DE College Prep Charter | D7: =C7/$C$43 -> 0 | E7: =D7*$C$41 -> 0
A8: 2017 | B8: DE Milit ary Academy Charter | C8: 272738 | D8: =C8/$C$43 -> 0.013962403 | E8: =D8*$C$41 -> 423085.93
A9: 2017 | B9: Delaware Design-Lab | C9: 108016 | D9: =C9/$C$43 -> 0.0055297131 | E9: =D9*$C$41 -> 167560.26
A10: 2017 | B10: Delaware Department of Transportation | C10: 6575637 | D10: =C10/$C$43 -> 0.33662963 | E10: =D10*$C$41 -> 10200484
A11: 2017 | B11: Delaware Economic Development Office | C11: 238684 | D11: =C11/$C$43 -> 0.012219061 | E11: =D11*$C$41 -> 370259.53
A12: 2017 | B12: Delaware Solid Waste Authority | C12: 526179 | D12: =C12/$C$43 -> 0.026936925 | E12: =D12*$C$41 -> 816237.32
A13: 2017 | B13: Delaware St ate Education Association | C13: 7697 | D13: =C13/$C$43 -> 0.00039403608 | E13: =D13*$C$41 -> 11940.003
A14: 2017 | B14: Delaware State Housing Authority | C14: 52807 | D14: =C14/$C$43 -> 0.0027033732 | E14: =D14*$C$41 -> 81917.074
A15: 2017 | B15: Delaware State University | C15: 4596417 | D15: =C15/$C$43 -> 0.2353065 | E15: =D15*$C$41 -> 7130210.6
A16: 2017 | B16: Delaware STEM Academy | C16: 210 | D16: =C16/$C$43 -> 1.0750627e-05 | E16: =D16*$C$41 -> 325.76336
A17: 2017 | B17: Early College High School Charter | C17: 121375 | D17: =C17/$C$43 -> 0.0062136066 | E17: =D17*$C$41 -> 188283.46
A18: 2017 | B18: East Side Charter | C18: 300991 | D18: =C18/$C$43 -> 0.015408772 | E18: =D18*$C$41 -> 466913.52
A19: 2017 | B19: Family Foundations Charter | C19: 383158 | D19: =C19/$C$43 -> 0.019615185 | E19: =D19*$C$41 -> 594375.41
... A28: 2017 | B28: MOT Charter | C28: 518808 | D28: =C28/$C$43 -> 0.026559578 | E28: =D28*$C$41 -> 804803.02
A29: 2017 | B29: Moyer Academy Charter | D29: =C29/$C$43 -> 0 | E29: =D29*$C$41 -> 0
A30: 2017 | B30: Newark Charter | C30: 1279678 | D30: =C30/$C$43 -> 0.065511148 | E30: =D30*$C$41 -> 1985105.7
A31: 2017 | B31: Odyssey Charter | C31: 617960 | D31: =C31/$C$43 -> 0.031635512 | E31: =D31*$C$41 -> 958612.97
A32: 2017 | B32: Pencader Charter | D32: =C32/$C$43 -> 0 | E32: =D32*$C$41 -> 0
A33: 2017 | B33: Positive Outcomes Charter | C33: 138372 | D33: =C33/$C$43 -> 0.0070837419 | E33: =D33*$C$41 -> 214650.13
A34: 2017 | B34: Prest ige Charter | C34: 84167 | D34: =C34/$C$43 -> 0.0043088002 | E34: =D34*$C$41 -> 130564.4
A35: 2017 | B35: Providence Creek Charter | C35: 277599 | D35: =C35/$C$43 -> 0.014211254 | E35: =D35*$C$41 -> 430626.58
A36: 2017 | B36: Reach Charter | D36: =C36/$C$43 -> 0 | E36: =D36*$C$41 -> 0
A37: 2017 | B37: Sussex Academy Charter | C37: 309118 | D37: =C37/$C$43 -> 0.015824821 | E37: =D37*$C$41 -> 479520.56
A38: 2017 | B38: The Charter School of Wilmington | C38: 513436 | D38: =C38/$C$43 -> 0.026284567 | E38: =D38*$C$41 -> 796469.69
A39: 2017 | B39: The Delaware Met Charter | D39: =C39/$C$43 -> 0 | E39: =D39*$C$41 -> 0
A40: 2017 | B40: Thomas Edison Charter | C40: 360069 | D40: =C40/$C$43 -> 0.018433179 | E40: =D40*$C$41 -> 558558.5
A41: 2017 | B41: State of Delaware | C41: 30301800
C43: =SUM(C2:C40) -> 19533744

Sheet 2018
A1: Year | B1: district_name | C1: district_contributions | D1: district_prop | E1: state_contributions
A2: 2018 | B2: Academia Antonia Alonso Charter | C2: 193483 | D2: =C2/$C$43 -> 0.0086791478 | E2: =D2*$C$41 -> 91999.869
A3: 2018 | B3: Academy of Dover Charter | C3: 112249 | D3: =C3/$C$43 -> 0.0050352003 | E3: =D3*$C$41 -> 53373.647
A4: 2018 | B4: Campus Community Charter | C4: 213620 | D4: =C4/$C$43 -> 0.0095824416 | E4: =D4*$C$41 -> 101574.88
A5: 2018 | B5: DE Academy Public Safety Charter | C5: 156945 | D5: =C5/$C$43 -> 0.0070401474 | E5: =D5*$C$41 -> 74626.295
A6: 2018 | B6: DE Aglands | C6: 11060 | D6: =C6/$C$43 -> 0.00049612304 | E6: =D6*$C$41 -> 5258.9558
A7: 2018 | B7: DE College Prep Charter | D7: =C7/$C$43 -> 0 | E7: =D7*$C$41 -> 0
A8: 2018 | B8: DE Military Academy Charter | C8: 318088 | D8: =C8/$C$43 -> 0.014268606 | E8: =D8*$C$41 -> 151248.71
A9: 2018 | B9: Delaware Design-Lab | C9: 148306 | D9: =C9/$C$43 -> 0.0066526242 | E9: =D9*$C$41 -> 70518.508
A10: 2018 | B10: Delaware Department of Transportation | C10: 7301989 | D10: =C10/$C$43 -> 0.32754837 | E10: =D10*$C$41 -> 3472046.8
A11: 2018 | B11: Delaware Economic Development Office | C11: 184544 | D11: =C11/$C$43 -> 0.0082781673 | E11: =D11*$C$41 -> 87749.434
A12: 2018 | B12: Delaware Solid Waste Authority | C12: 626327 | D12: =C12/$C$43 -> 0.028095412 | E12: =D12*$C$41 -> 297814.29
A13: 2018 | B13: Delaware State Education Association | C13: 6404 | D13: =C13/$C$43 -> 0.0002872669 | E13: =D13*$C$41 -> 3045.0591
A14: 2018 | B14: Delaware State Housing Authority | C14: 46856 | D14: =C14/$C$43 -> 0.0021018392 | E14: =D14*$C$41 -> 22279.714
A15: 2018 | B15: Delaware State University | C15: 5066411 | D15: =C15/$C$43 -> 0.22726611 | E15: =D15*$C$41 -> 2409044.5
A16: 2018 | B16: Delaware STEM Academy | D16: =C16/$C$43 -> 0 | E16: =D16*$C$41 -> 0
A17: 2018 | B17: Early College High School Charter | C17: 152884 | D17: =C17/$C$43 -> 0.0068579815 | E17: =D17*$C$41 -> 72695.317
A18: 2018 | B18: East Side Charter | C18: 347940 | D18: =C18/$C$43 -> 0.01560769 | E18: =D18*$C$41 -> 165443.14
A19: 2018 | B19: Family Foundations Charter | C19: 421309 | D19: =C19/$C$43 -> 0.018898834 | E19: =D19*$C$41 -> 200329.6
A20: 2018 | B20: First State Military Academy | C20: 191786 | D20: =C20/$C$43 -> 0.0086030247 | E20: =D20*$C$41 -> 91192.957
A21: 2018 | B21: First State Montessori Academy Charter | C21: 294859 | D21: =C21/$C$43 -> 0.013226613 | E21: =D21*$C$41 -> 140203.48
A22: 2018 | B22: Freire Charter School | C22: 187646 | D22: =C22/$C$43 -> 0.008417315 | E22: =D22*$C$41 -> 89224.415
A23: 2018 | B23: Gateway Lab Charter | C23: 187642 | D23: =C23/$C$43 -> 0.0084171356 | E23: =D23*$C$41 -> 89222.513
A24: 2018 | B24: Great Oaks Charter School | C24: 178761 | D24: =C24/$C$43 -> 0.0080187569 | E24: =D24*$C$41 -> 84999.657
A25: 2018 | B25: Kumba Charter | C25: 394678 | D25: =C25/$C$43 -> 0.017704236 | E25: =D25*$C$41 -> 187666.74
A26: 2018 | B26: Las America Aspira Charter | C26: 495387 | D26: =C26/$C$43 -> 0.022221782 | E26: =D26*$C$41 -> 235553.2
A27: 2018 | B27: Lottery | C27: 253999 | D27: =C27/$C$43 -> 0.011393739 | E27: =D27*$C$41 -> 120774.82
A28: 2018 | B28: MOT Charter | C28: 639803 | D28: =C28/$C$43 -> 0.02869991 | E28: =D28*$C$41 -> 304222.04
A29: 2018 | B29: Moyer Academy Charter | D29: =C29/$C$43 -> 0 | E29: =D29*$C$41 -> 0
A30: 2018 | B30: Newark Charter | C30: 1499664 | D30: =C30/$C$43 -> 0.067271055 | E30: =D30*$C$41 -> 713080.17
A31: 2018 | B31: Odyssey Charter | C31: 863761 | D31: =C31/$C$43 -> 0.038746088 | E31: =D31*$C$41 -> 410712.56
A32: 2018 | B32: Pencader Charter | D32: =C32/$C$43 -> 0 | E32: =D32*$C$41 -> 0
A33: 2018 | B33: Positive Outcomes Charter | C33: 159160 | D33: =C33/$C$43 -> 0.0071395066 | E33: =D33*$C$41 -> 75679.513
A34: 2018 | B34: Prestige Charter | D34: =C34/$C$43 -> 0 | E34: =D34*$C$41 -> 0
A35: 2018 | B35: Providence Creek Charter | C35: 293402 | D35: =C35/$C$43 -> 0.013161256 | E35: =D35*$C$41 -> 139510.68
A36: 2018 | B36: Reach Charter | D36: =C36/$C$43 -> 0 | E36: =D36*$C$41 -> 0
A37: 2018 | B37: Sussex Academy Charter | C37: 379987 | D37: =C37/$C$43 -> 0.017045236 | E37: =D37*$C$41 -> 180681.27
A38: 2018 | B38: The Delaware Met Charter | D38: =C38/$C$43 -> 0 | E38: =D38*$C$41 -> 0
A39: 2018 | B39: The Charter School of Wilmington | C39: 558360 | D39: =C39/$C$43 -> 0.025046588 | E39: =D39*$C$41 -> 265496.44
A40: 2018 | B40: Thomas Edison Charter | C40: 405547 | D40: =C40/$C$43 -> 0.018191791 | E40: =D40*$C$41 -> 192834.88
...

Sheet 2019
A1: Year | B1: district_name | C1: district_contributions | D1: district_prop | E1: state_contributions
A2: 2019 | B2: Academia Antonia Alonso Charter | C2: 350968 | D2: =C2/$C$35 -> 0.013046026 | E2: =D2*$C$33 -> 283876.31
A3: 2019 | B3: Academy of Dover Charter | C3: 138460 | D3: =C3/$C$35 -> 0.0051467734 | E3: =D3*$C$33 -> 111991.73
A4: 2019 | B4: Campus Community Charter | C4: 229165 | D4: =C4/$C$35 -> 0.0085184192 | E4: =D4*$C$33 -> 185357.39
A5: 2019 | B5: DE Academy Public Safety Charter | C5: 49340 | D5: =C5/$C$35 -> 0.0018340445 | E5: =D5*$C$33 -> 39908.074
A6: 2019 | B6: DE Aglands | C6: 10742 | D6: =C6/$C$35 -> 0.00039929683 | E6: =D6*$C$33 -> 8688.5394
A7: 2019 | B7: DE Military Academy Charter | C7: 376713 | D7: =C7/$C$35 -> 0.014003008 | E7: =D7*$C$33 -> 304699.84
A8: 2019 | B8: Delaware Design Lab (Design Thinking) | C8: 243957 | D8: =C8/$C$35 -> 0.0090682608 | E8: =D8*$C$33 -> 197321.73
A9: 2019 | B9: Delaware Department of Transportation | C9: 8745416 | D9: =C9/$C$35 -> 0.3250807 | E9: =D9*$C$33 -> 7073626.1
A10: 2019 | B10: Delaware Solid Waste Authority | C10: 731139 | D10: =C10/$C$35 -> 0.027177573 | E10: =D10*$C$33 -> 591373.11
A11: 2019 | B11: Delaware State Education Association | C11: 7311 | D11: =C11/$C$35 -> 0.00027176123 | E11: =D11*$C$33 -> 5913.4157
A12: 2019 | B12: Delaware State Housing Authority | C12: 42151 | D12: =C12/$C$35 -> 0.0015668182 | E12: =D12*$C$33 -> 34093.337
A13: 2019 | B13: Delaware State University | C13: 5918085 | D13: =C13/$C$35 -> 0.21998442 | E13: =D13*$C$33 -> 4786772.9
... A32: 2019 | B32: Thomas Edison Charter | C32: 467629 | D32: =C32/$C$35 -> 0.017382497 | E32: =D32*$C$33 -> 378236.17
A33: 2019 | B33: State of Delaware | C33: 21759600
C35: =SUM(C2:C32) -> 26902292

Sheet 2020
A1: Year | B1: district_name | C1: district_contributions | E1: state_contributions
A2: 2020 | B2: Academia Antonia Alonso Charter | C2: 426516 | D2: =C2/$C$33 -> 0.015524331 | E2: =D2*$C$31 -> 87713.989
A3: 2020 | B3: Academy of Dover Charter | C3: 169130 | D3: =C3/$C$33 -> 0.0061559942 | E3: =D3*$C$31 -> 34781.97
A4: 2020 | B4: Campus Community Charter | C4: 229550 | D4: =C4/$C$33 -> 0.0083551615 | E4: =D4*$C$31 -> 47207.481
A5: 2020 | B5: DE Aglands | C5: 11737 | D5: =C5/$C$33 -> 0.00042720336 | E5: =D5*$C$31 -> 2413.7408
A6: 2020 | B6: DE Military Academy Charter | C6: 390357 | D6: =C6/$C$33 -> 0.014208215 | E6: =D6*$C$31 -> 80277.808
A7: 2020 | B7: Delaware Design Lab (Design Thinking Academy) | C7: 2362 | D7: =C7/$C$33 -> 8.5972082e-05 | E7: =D7*$C$31 -> 485.75069
A8: 2020 | B8: Delaware Department of Transportation | C8: 9118264 | D8: =C8/$C$33 -> 0.3318866 | E8: =D8*$C$31 -> 1875191.8
A9: 2020 | B9: Delaware State Housing Authority | C9: 34185 | D9: =C9/$C$33 -> 0.0012442657 | E9: =D9*$C$31 -> 7030.2233
A10: 2020 | B10: Delaware State University | C10: 6165787 | D10: =C10/$C$33 -> 0.22442233 | E10: =D10*$C$31 -> 1268008.2
A11: 2020 | B11: Early College High School Charter | C11: 195904 | D11: =C11/$C$33 -> 0.0071305143 | E11: =D11*$C$31 -> 40288.105
A12: 2020 | B12: East Side Charter | C12: 426636 | D12: =C12/$C$33 -> 0.015528698 | E12: =D12*$C$31 -> 87738.667
A13: 2020 | B13: Family Foundations Charter | C13: 503610 | D13: =C13/$C$33 -> 0.018330398 | E13: =D13*$C$31 -> 103568.55
... A30: 2020 | B30: Thomas Edison Charter | C30: 484118 | D30: =C30/$C$33 -> 0.017620928 | E30: =D30*$C$31 -> 99559.972
A31: 2020 | B31: State of Delaware | C31: 5650098
C33: =SUM(C2:C30) -> 27474035

Sheet 2021
A1: Year | B1: district_name | C1: district_contributions | D1: state_contributions
A2: 2021 | B2: Academia Antonia Alonso Charter | C2: 459545 | D2: 0
A3: 2021 | B3: Academy of Dover Charter | C3: 211530 | D3: 0
A4: 2021 | B4: Campus Community Charter | C4: 250162 | D4: 0
A5: 2021 | B5: Charter School of New Castle | C5: 521987 | D5: 0
A6: 2021 | B6: DE Aglands | C6: 8087 | D6: 0
A7: 2021 | B7: DE Military Academy Charter | C7: 428201 | D7: 0
A8: 2021 | B8: Delaware Department of Transportation | C8: 9625479 | D8: 0
A9: 2021 | B9: Delaware State Housing Authority | C9: 34501 | D9: 0
A10: 2021 | B10: Delaware State University | C10: 6459505 | D10: 0
A11: 2021 | B11: Early College High School Charter | C11: 187393 | D11: 0
A12: 2021 | B12: East Side Charter | C12: 457535 | D12: 0
A13: 2021 | B13: First State Military Academy | C13: 339757 | D13: 0
... A30: 2021 | B30: State of Delaware | C30: 0 | D30: 0

Sheet 2022
A1: Year | B1: district_name | C1: district_contributions | E1: state_contributions
A2: 2022 | B2: Academia Antonia Alonso Charter | C2: 535781 | D2: =C2/$C$32 -> 0.016925893 | E2: =D2*$C$32 -> 535781
A3: 2022 | B3: Academy of Dover Charter | C3: 280886 | D3: =C3/$C$32 -> 0.0088734882 | E3: =D3*$C$32 -> 280886
A4: 2022 | B4: Campus Community Charter | C4: 282942 | D4: =C4/$C$32 -> 0.0089384394 | E4: =D4*$C$32 -> 282942
A5: 2022 | B5: Charter School of New Castle | C5: 539308 | D5: =C5/$C$32 -> 0.017037315 | E5: =D5*$C$32 -> 539308
A6: 2022 | B6: DE Military Academy Charter | C6: 423842 | D6: =C6/$C$32 -> 0.013389621 | E6: =D6*$C$32 -> 423842
A7: 2022 | B7: Delaware Agricultural Lands Preservation Foundation | C7: 8200 | D7: =C7/$C$32 -> 0.00025904674 | E7: =D7*$C$32 -> 8200
A8: 2022 | B8: Delaware Department of Transportation | C8: 9869851 | D8: =C8/$C$32 -> 0.31179911 | E8: =D8*$C$32 -> 9869851
A9: 2022 | B9: Delaware State Housing Authority | C9: 31402 | D9: =C9/$C$32 -> 0.00099202266 | E9: =D9*$C$32 -> 31402
A10: 2022 | B10: Delaware State University | C10: 7212747 | D10: =C10/$C$32 -> 0.22785837 | E10: =D10*$C$32 -> 7212747
A11: 2022 | B11: Early College High School Charter | C11: 244534 | D11: =C11/$C$32 -> 0.0077250897 | E11: =D11*$C$32 -> 244534
A12: 2022 | B12: East Side Charter | C12: 514756 | D12: =C12/$C$32 -> 0.016261691 | E12: =D12*$C$32 -> 514756
A13: 2022 | B13: First State Military Academy | C13: 384466 | D13: =C13/$C$32 -> 0.012145691 | E13: =D13*$C$32 -> 384466
... A29: 2022 | B29: Thomas Edison Charter | C29: 550002 | D29: =C29/$C$32 -> 0.01737515 | E29: =D29*$C$32 -> 550002
A30: 2022 | B30: State of Delaware | C30: 26653400
C32: =SUM(C2:C29) -> 31654519

Sheet 2023
A1: Year | B1: district_name | C1: district_contributions | E1: state_contributions
A2: 2023 | B2: Academia Antonia Alonso Charter | C2: 527365 | D2: =C2/$C$33 -> 0.017364288 | E2: =D2*$C$31 -> 2758011.8
A3: 2023 | B3: Academy of Dover Charter | C3: 317098 | D3: =C3/$C$33 -> 0.01044093 | E3: =D3*$C$31 -> 1658358.1
A4: 2023 | B4: Bryan Allen Stevenson School of Excellence | C4: 16099 | D4: =C4/$C$33 -> 0.00053008386 | E4: =D4*$C$31 -> 84194.498
A5: 2023 | B5: Campus Community Charter | C5: 267334 | D5: =C5/$C$33 -> 0.0088023753 | E5: =D5*$C$31 -> 1398102.5
A6: 2023 | B6: Charter School of New Castle | C6: 508351 | D6: =C6/$C$33 -> 0.016738224 | E6: =D6*$C$31 -> 2658572.4
A7: 2023 | B7: DE Military Academy Charter | C7: 415811 | D7: =C7/$C$33 -> 0.013691205 | E7: =D7*$C$31 -> 2174607
A8: 2023 | B8: Delaware Agricultural Lands Preservation Foundation | C8: 7629 | D8: =C8/$C$33 -> 0.00025119634 | E8: =D8*$C$31 -> 39898.119
A9: 2023 | B9: Delaware Department of Transportation | C9: 9015305 | D9: =C9/$C$33 -> 0.29684252 | E9: =D9*$C$31 -> 47148213
A10: 2023 | B10: Delaware State Housing Authority | C10: 16354 | D10: =C10/$C$33 -> 0.00053848012 | E10: =D10*$C$31 -> 85528.096
A11: 2023 | B11: Delaware State University | C11: 7021763 | D11: =C11/$C$33 -> 0.23120214 | E11: =D11*$C$31 -> 36722393
A12: 2023 | B12: Early College High School Charter | C12: 302228 | D12: =C12/$C$33 -> 0.0099513129 | E12: =D12*$C$31 -> 1580591
A13: 2023 | B13: East Side Charter | C13: 504026 | D13: =C13/$C$33 -> 0.016595817 | E13: =D13*$C$31 -> 2635953.5
... A30: 2023 | B30: Thomas Edison Charter | C30: 464733 | D30: =C30/$C$33 -> 0.015302035 | E30: =D30*$C$31 -> 2430459.1
A31: 2023 | B31: State of Delaware | C31: 158832410
C33: =SUM(C2:C30) -> 30370666

Sheet NCES Data -->

Sheet LEAID Match
A1: district_name
A2: Academia Antonia Alonso Charter | B2: 1000053
A3: Academy of Dover Charter | B3: 1000017
A4: Bryan Allen Stevenson School of Excellence
A5: Campus Community Charter | B5: 1000007
A6: Charter School of New Castle | B6: 1000024
A7: De Academy Public Safety Charter | B7: 1000049
A8: DE Aglands
A9: DE College Prep Charter | B9: 1000047
A10: DE Military Academy Charter | B10: 1000016
A11: Delaware Agricultural Lands Preservation Foundation
A12: Delaware Department of Transportation
A13: Delaware Design-Lab | B13: 1000056
A14: Delaware Economic Development Office
A15: Delaware Solid Waste Authority
A16: Delaware State Education Association
A17: Delaware State Housing Authority
A18: Delaware State University
A19: Delaware STEM Academy | B19: 1000061
A20: Early College High School Charter | B20: 1000055
A21: East Side Charter | B21: 1000006
A22: Family Foundations Charter | B22: 1000024
A23: First State Military Academy | B23: 1000057
A24: First State Montessori Academy Charter | B24: 1000054
A25: Freire Charter School | B25: 1000059
A26: Gateway Lab Charter | B26: 1000052
A27: Great Oaks Charter School | B27: 1000062
A28: Kumba Charter | B28: 1000014
A29: Las America Aspira Charter | B29: 1000050
A30: Lottery
A31: MOT Charter | B31: 1000019
A32: Moyer Academy Charter | B32: 1000023
A33: Newark Charter | B33: 1000015
A34: Odyssey Charter | B34: 1000026
A35: Pencader Charter
A36: Positive Outcomes Charter | B36: 1000005
A37: Prestige Charter | B37: 1000048
A38: Providence Creek Charter | B38: 1000018
A39: Reach Charter | B39: 1000051
A40: Sussex Academy Charter | B40: 1000011
...
