Workbook

Sheet Summary
A1: LEAID | B1: Year | C1: employer_code | D1: year_employer_code | E1: standardized_employer_name | F1: plan1_employer_contributions | G1: plan1_allocation_percentage | H1: plan1_state_agency_contributions | I1: plan1_state_agency_allocation | J1: plan2_3_employer_contributions | K1: plan2_3_allocation_percentage | L1: plan_2_3state_agency_contributio | M1: plan2_3_state_agency_allocation | N1: uaal_employer_contributions | O1: uaal_allocation_percentage | P1: uaal_state_agency_contributions | Q1: uaal_state_agency_allocation | R1: employer_name_1 | S1: employer_name_2_3 | T1: employer_name_uaal | U1: total_plan1_allocation | V1: state_transfer_to_uaal | W1: LEAID_match | X1: district_contributions | Y1: state_contributions | Z1: total_contributions
A2: =W2 -> 5300030 | B2: 2015 | C2: 0002 | D2: 2015_0002 | E2: Aberdeen School District 005 | F2: 16203.45 | G2: 7.241e-05 | J2: 843611.2 | K2: 0.00317449 | N2: 673366.29 | O2: 0.0030091 | R2: Aberdeen School District 005 | S2: Aberdeen School District 005 | T2: Aberdeen School District 005 | U2: =SUM(G2,I2,O2,Q2) -> 0.00308151 | W2: =IFERROR(VLOOKUP(E2,'LEAID Match'!$A$2:$B$326,2,FALSE),"") -> 5300030 | X2: =SUM(F2,J2) -> 859814.65 | Y2: =V2 -> 0 | Z2: =SUM(X2:Y2) -> 859814.65
A3: =W3 -> 5300030 | B3: 2016 | C3: 0002 | D3: 2016_0002 | E3: Aberdeen School District 005 | F3: 9831.81 | G3: 3.235e-05 | J3: 916252.96 | K3: 0.00280712 | N3: 825766.04 | O3: 0.00271709 | R3: Aberdeen School District 005 | S3: Aberdeen School District 005 | T3: Aberdeen School District 005 | U3: =SUM(G3,I3,O3,Q3) -> 0.00274944 | W3: =IFERROR(VLOOKUP(E3,'LEAID Match'!$A$2:$B$326,2,FALSE),"") -> 5300030 | X3: =SUM(F3,J3) -> 926084.77 | Y3: =V3 -> 0 | Z3: =SUM(X3:Y3) -> 926084.77
A4: =W4 -> 5300030 | B4: 2017 | C4: 0002 | D4: 2017_0002 | E4: Aberdeen School District 005 | F4: 10785.44 | G4: 3.082e-05 | J4: 1180625 | K4: 0.0032043 | N4: 1094541.5 | O4: 0.00312783 | R4: Aberdeen School District 005 | S4: Aberdeen School District 005 | T4: Aberdeen School District 005 | U4: =SUM(G4,I4,O4,Q4) -> 0.00315865 | W4: =IFERROR(VLOOKUP(E4,'LEAID Match'!$A$2:$B$326,2,FALSE),"") -> 5300030 | X4: =SUM(F4,J4) -> 1191410.4 | Y4: =V4 -> 0 | Z4: =SUM(X4:Y4) -> 1191410.4
A5: =W5 -> 5300030 | B5: 2018 | C5: 0002 | D5: 2018_0002 | E5: Aberdeen School District 005 | F5: 11614.09 | G5: 2.793e-05 | J5: 1310785.1 | K5: 0.00294836 | N5: 1205823.6 | O5: 0.00289936 | R5: Aberdeen School District 005 | S5: Aberdeen School District 005 | T5: Aberdeen School District 005 | U5: =SUM(G5,I5,O5,Q5) -> 0.00292729 | W5: =IFERROR(VLOOKUP(E5,'LEAID Match'!$A$2:$B$326,2,FALSE),"") -> 5300030 | X5: =SUM(F5,J5) -> 1322399.2 | Y5: =V5 -> 0 | Z5: =SUM(X5:Y5) -> 1322399.2
A6: =W6 -> 5300030 | B6: 2019 | C6: 0002 | D6: 2019_0002 | E6: Aberdeen School District 005 | F6: 14236.27 | G6: 2.867e-05 | J6: 1594959.8 | K6: 0.00305147 | N6: 1499030.4 | O6: 0.00301843 | R6: Aberdeen School District 005 | S6: Aberdeen School District 005 | T6: Aberdeen School District 005 | U6: =SUM(G6,I6,O6,Q6) -> 0.0030471 | W6: =IFERROR(VLOOKUP(E6,'LEAID Match'!$A$2:$B$326,2,FALSE),"") -> 5300030 | X6: =SUM(F6,J6) -> 1609196.1 | Y6: =V6 -> 0 | Z6: =SUM(X6:Y6) -> 1609196.1
A7: =W7 -> 5300030 | B7: 2020 | C7: 0002 | D7: 2020_0002 | E7: Aberdeen School District 005 | F7: 2538.41 | G7: 4.83e-06 | J7: 1512740.3 | K7: 0.00259993 | N7: 1354628.2 | O7: 0.0025795 | R7: Aberdeen School District 005 | S7: Aberdeen School District 005 | T7: Aberdeen School District 005 | U7: =SUM(G7,I7,O7,Q7) -> 0.00258433 | W7: =IFERROR(VLOOKUP(E7,'LEAID Match'!$A$2:$B$326,2,FALSE),"") -> 5300030 | X7: =SUM(F7,J7) -> 1515278.7 | Y7: =V7 -> 0 | Z7: =SUM(X7:Y7) -> 1515278.7
A8: =W8 -> 5300030 | B8: 2021 | C8: 0002 | D8: 2021_0002 | E8: Aberdeen School District 005 | J8: 1492988 | K8: 0.00246708 | N8: 1346779.2 | O8: 0.00245039 | S8: Aberdeen School District 005 | T8: Aberdeen School District 005 | U8: =SUM(G8,I8,O8,Q8) -> 0.00245039 | W8: =IFERROR(VLOOKUP(E8,'LEAID Match'!$A$2:$B$326,2,FALSE),"") -> 5300030 | X8: =SUM(F8,J8) -> 1492988 | Y8: =V8 -> 0 | Z8: =SUM(X8:Y8) -> 1492988
A9: =W9 -> 5300030 | B9: 2022 | C9: 0002 | D9: 2022_0002 | E9: Aberdeen School District 005 | J9: 1597289.3 | K9: 0.00249726 | N9: 1287189.4 | O9: 0.00250841 | S9: Aberdeen School District 005 | T9: Aberdeen School District 005 | U9: =SUM(G9,I9,O9,Q9) -> 0.00250841 | W9: =IFERROR(VLOOKUP(E9,'LEAID Match'!$A$2:$B$326,2,FALSE),"") -> 5300030 | X9: =SUM(F9,J9) -> 1597289.3 | Y9: =V9 -> 0 | Z9: =SUM(X9:Y9) -> 1597289.3
A10: =W10 -> 5300030 | B10: 2023 | C10: 0002 | D10: 2023_0002 | E10: Aberdeen School District 005 | J10: 1957433.1 | K10: 0.00289276 | N10: 1552291.9 | O10: 0.0028761 | S10: Aberdeen School District 005 | T10: Aberdeen School District 005 | U10: =SUM(G10,I10,O10,Q10) -> 0.0028761 | V10: =U10*250000000 -> 719025 | W10: =IFERROR(VLOOKUP(E10,'LEAID Match'!$A$2:$B$326,2,FALSE),"") -> 5300030 | X10: =SUM(F10,J10) -> 1957433.1 | Y10: =V10 -> 719025 | Z10: =SUM(X10:Y10) -> 2676458.1
A11: =W11 | B11: 2015 | C11: 0008 | D11: 2015_0008 | E11: Administrative Office of the Courts | H11: 15867.71 | I11: 7.091e-05 | R11: Administrative Office of the Court | U11: =SUM(G11,I11,O11,Q11) -> 7.091e-05 | W11: =IFERROR(VLOOKUP(E11,'LEAID Match'!$A$2:$B$326,2,FALSE),"") | X11: =SUM(F11,J11) -> 0 | Y11: =V11 -> 0 | Z11: =SUM(X11:Y11) -> 0
A12: =W12 | B12: 2016 | C12: 0008 | D12: 2016_0008 | E12: Administrative Office of the Courts | H12: 19997.69 | I12: 6.58e-05 | R12: Administrative Office of the Courts | U12: =SUM(G12,I12,O12,Q12) -> 6.58e-05 | W12: =IFERROR(VLOOKUP(E12,'LEAID Match'!$A$2:$B$326,2,FALSE),"") | X12: =SUM(F12,J12) -> 0 | Y12: =V12 -> 0 | Z12: =SUM(X12:Y12) -> 0
A13: =W13 | B13: 2017 | C13: 0008 | D13: 2017_0008 | E13: Administrative Office of the Courts | H13: 11547.38 | I13: 3.3e-05 | R13: Administrative Office of the Courts | U13: =SUM(G13,I13,O13,Q13) -> 3.3e-05 | W13: =IFERROR(VLOOKUP(E13,'LEAID Match'!$A$2:$B$326,2,FALSE),"") | X13: =SUM(F13,J13) -> 0 | Y13: =V13 -> 0 | Z13: =SUM(X13:Y13) -> 0
A14: =W14 -> 5300060 | B14: 2015 | C14: 0010 | D14: 2015_0010 | E14: Adna School District 226 | F14: 26571.52 | G14: 0.00011874 | J14: 110832.78 | K14: 0.00041706 | N14: 88424.29 | O14: 0.00039514 | R14: Adna School District 226 | S14: Adna School District 226 | T14: Adna School District 226 | U14: =SUM(G14,I14,O14,Q14) -> 0.00051388 | W14: =IFERROR(VLOOKUP(E14,'LEAID Match'!$A$2:$B$326,2,FALSE),"") -> 5300060 | X14: =SUM(F14,J14) -> 137404.3 | Y14: =V14 -> 0 | Z14: =SUM(X14:Y14) -> 137404.3
A15: =W15 -> 5300060 | B15: 2016 | C15: 0010 | D15: 2016_0010 | E15: Adna School District 226 | F15: 17912.64 | G15: 5.894e-05 | J15: 142809.68 | K15: 0.00043753 | N15: 128106.09 | O15: 0.00042152 | R15: Adna School District 226 | S15: Adna School District 226 | T15: Adna School District 226 | U15: =SUM(G15,I15,O15,Q15) -> 0.00048046 | W15: =IFERROR(VLOOKUP(E15,'LEAID Match'!$A$2:$B$326,2,FALSE),"") -> 5300060 | X15: =SUM(F15,J15) -> 160722.32 | Y15: =V15 -> 0 | Z15: =SUM(X15:Y15) -> 160722.32
A16: =W16 -> 5300060 | B16: 2017 | C16: 0010 | D16: 2017_0010 | E16: Adna School District 226 | F16: 4606.14 | G16: 1.316e-05 | J16: 157838.78 | K16: 0.00042839 | N16: 146295.19 | O16: 0.00041806 | R16: Adna School District 226 | S16: Adna School District 226 | T16: Adna School District 226 | U16: =SUM(G16,I16,O16,Q16) -> 0.00043122 | W16: =IFERROR(VLOOKUP(E16,'LEAID Match'!$A$2:$B$326,2,FALSE),"") -> 5300060 | X16: =SUM(F16,J16) -> 162444.92 | Y16: =V16 -> 0 | Z16: =SUM(X16:Y16) -> 162444.92
A17: =W17 -> 5300060 | B17: 2018 | C17: 0010 | D17: 2018_0010 | E17: Adna School District 226 | J17: 193729.25 | K17: 0.00043576 | N17: 178276.53 | O17: 0.00042866 | S17: Adna School District 226 | T17: Adna School District 226 | U17: =SUM(G17,I17,O17,Q17) -> 0.00042866 | W17: =IFERROR(VLOOKUP(E17,'LEAID Match'!$A$2:$B$326,2,FALSE),"") -> 5300060 | X17: =SUM(F17,J17) -> 193729.25 | Y17: =V17 -> 0 | Z17: =SUM(X17:Y17) -> 193729.25
A18: =W18 -> 5300060 | B18: 2019 | C18: 0010 | D18: 2019_0010 | E18: Adna School District 226 | J18: 229309.7 | K18: 0.00043871 | N18: 215176.09 | O18: 0.00043328 | S18: Adna School District 226 | T18: Adna School District 226 | U18: =SUM(G18,I18,O18,Q18) -> 0.00043328 | W18: =IFERROR(VLOOKUP(E18,'LEAID Match'!$A$2:$B$326,2,FALSE),"") -> 5300060 | X18: =SUM(F18,J18) -> 229309.7 | Y18: =V18 -> 0 | Z18: =SUM(X18:Y18) -> 229309.7
A19: =W19 -> 5300060 | B19: 2020 | C19: 0010 | D19: 2020_0010 | E19: Adna School District 226 | J19: 264605.24 | K19: 0.00045477 | N19: 237024.73 | O19: 0.00045135 | S19: Adna School District 226 | T19: Adna School District 226 | U19: =SUM(G19,I19,O19,Q19) -> 0.00045135 | W19: =IFERROR(VLOOKUP(E19,'LEAID Match'!$A$2:$B$326,2,FALSE),"") -> 5300060 | X19: =SUM(F19,J19) -> 264605.24 | Y19: =V19 -> 0 | Z19: =SUM(X19:Y19) -> 264605.24
A20: =W20 -> 5300060 | B20: 2021 | C20: 0010 | D20: 2021_0010 | E20: Adna School District 226 | J20: 235760.33 | K20: 0.00038958 | N20: 213131.24 | O20: 0.00038778 | S20: Adna School District 226 | T20: Adna School District 226 | U20: =SUM(G20,I20,O20,Q20) -> 0.00038778 | W20: =IFERROR(VLOOKUP(E20,'LEAID Match'!$A$2:$B$326,2,FALSE),"") -> 5300060 | X20: =SUM(F20,J20) -> 235760.33 | Y20: =V20 -> 0 | Z20: =SUM(X20:Y20) -> 235760.33
A21: =W21 -> 5300060 | B21: 2022 | C21: 0010 | D21: 2022_0010 | E21: Adna School District 226 | J21: 306078.04 | K21: 0.00047853 | N21: 246078.83 | O21: 0.00047955 | S21: Adna School District 226 | T21: Adna School District 226 | U21: =SUM(G21,I21,O21,Q21) -> 0.00047955 | W21: =IFERROR(VLOOKUP(E21,'LEAID Match'!$A$2:$B$326,2,FALSE),"") -> 5300060 | X21: =SUM(F21,J21) -> 306078.04 | Y21: =V21 -> 0 | Z21: =SUM(X21:Y21) -> 306078.04
A22: =W22 -> 5300060 | B22: 2023 | C22: 0010 | D22: 2023_0010 | E22: Adna School District 226 | J22: 292261.89 | K22: 0.00043191 | N22: 232715.66 | O22: 0.00043118 | S22: Adna School District 226 | T22: Adna School District 226 | U22: =SUM(G22,I22,O22,Q22) -> 0.00043118 | V22: =U22*250000000 -> 107795 | W22: =IFERROR(VLOOKUP(E22,'LEAID Match'!$A$2:$B$326,2,FALSE),"") -> 5300060 | X22: =SUM(F22,J22) -> 292261.89 | Y22: =V22 -> 107795 | Z22: =SUM(X22:Y22) -> 400056.89
A23: =W23 -> 5300090 | B23: 2015 | C23: 0017 | D23: 2015_0017 | E23: Almira School District 017 | F23: 6663.06 | G23: 2.978e-05 | J23: 37055.38 | K23: 0.00013944 | N23: 29570.38 | O23: 0.00013214 | R23: Almira School District 017 | S23: Almira School District 017 | T23: Almira School District 017 | U23: =SUM(G23,I23,O23,Q23) -> 0.00016192 | W23: =IFERROR(VLOOKUP(E23,'LEAID Match'!$A$2:$B$326,2,FALSE),"") -> 5300090 | X23: =SUM(F23,J23) -> 43718.44 | Y23: =V23 -> 0 | Z23: =SUM(X23:Y23) -> 43718.44
A24: =W24 -> 5300090 | B24: 2016 | C24: 0017 | D24: 2016_0017 | E24: Almira School District 017 | F24: 8256.9 | G24: 2.717e-05 | J24: 41808.72 | K24: 0.00012809 | N24: 37323.79 | O24: 0.00012281 | R24: Almira School District 017 | S24: Almira School District 017 | T24: Almira School District 017 | U24: =SUM(G24,I24,O24,Q24) -> 0.00014998 | W24: =IFERROR(VLOOKUP(E24,'LEAID Match'!$A$2:$B$326,2,FALSE),"") -> 5300090 | X24: =SUM(F24,J24) -> 50065.62 | Y24: =V24 -> 0 | Z24: =SUM(X24:Y24) -> 50065.62
A25: =W25 -> 5300090 | B25: 2017 | C25: 0017 | D25: 2017_0017 | E25: Almira School District 017 | F25: 8865.49 | G25: 2.533e-05 | J25: 48095.3 | K25: 0.00013053 | N25: 44588.35 | O25: 0.00012742 | R25: Almira School District 017 | S25: Almira School District 017 | T25: Almira School District 017 | U25: =SUM(G25,I25,O25,Q25) -> 0.00015275 | W25: =IFERROR(VLOOKUP(E25,'LEAID Match'!$A$2:$B$326,2,FALSE),"") -> 5300090 | X25: =SUM(F25,J25) -> 56960.79 | Y25: =V25 -> 0 | Z25: =SUM(X25:Y25) -> 56960.79
A26: =W26 -> 5300090 | B26: 2018 | C26: 0017 | D26: 2018_0017 | E26: Almira School District 017 | F26: 10016.95 | G26: 2.409e-05 | J26: 54656.6 | K26: 0.00012294 | N26: 49879.99 | O26: 0.00011993 | R26: Almira School District 017 | S26: Almira School District 017 | T26: Almira School District 017 | U26: =SUM(G26,I26,O26,Q26) -> 0.00014402 | W26: =IFERROR(VLOOKUP(E26,'LEAID Match'!$A$2:$B$326,2,FALSE),"") -> 5300090 | X26: =SUM(F26,J26) -> 64673.55 | Y26: =V26 -> 0 | Z26: =SUM(X26:Y26) -> 64673.55
A27: =W27 -> 5300090 | B27: 2019 | C27: 0017 | D27: 2019_0017 | E27: Almira School District 017 | F27: 11165.67 | G27: 2.248e-05 | J27: 57484.84 | K27: 0.00010998 | N27: 53913.45 | O27: 0.00010856 | R27: Almira School District 017 | S27: Almira School District 017 | T27: Almira School District 017 | U27: =SUM(G27,I27,O27,Q27) -> 0.00013104 | W27: =IFERROR(VLOOKUP(E27,'LEAID Match'!$A$2:$B$326,2,FALSE),"") -> 5300090 | X27: =SUM(F27,J27) -> 68650.51 | Y27: =V27 -> 0 | Z27: =SUM(X27:Y27) -> 68650.51
A28: =W28 -> 5300090 | B28: 2020 | C28: 0017 | D28: 2020_0017 | E28: Almira School District 017 | F28: 2804.4 | G28: 5.34e-06 | J28: 62676.48 | K28: 0.00010772 | N28: 56200.91 | O28: 0.00010702 | R28: Almira School District 017 | S28: Almira School District 017 | T28: Almira School District 017 | U28: =SUM(G28,I28,O28,Q28) -> 0.00011236 | W28: =IFERROR(VLOOKUP(E28,'LEAID Match'!$A$2:$B$326,2,FALSE),"") -> 5300090 | X28: =SUM(F28,J28) -> 65480.88 | Y28: =V28 -> 0 | Z28: =SUM(X28:Y28) -> 65480.88
A29: =W29 -> 5300090 | B29: 2021 | C29: 0017 | D29: 2021_0017 | E29: Almira School District 017 | J29: 60448.22 | K29: 9.989e-05 | N29: 54432.33 | O29: 9.904e-05 | S29: Almira School District 017 | T29: Almira School District 017 | U29: =SUM(G29,I29,O29,Q29) -> 9.904e-05 | W29: =IFERROR(VLOOKUP(E29,'LEAID Match'!$A$2:$B$326,2,FALSE),"") -> 5300090 | X29: =SUM(F29,J29) -> 60448.22 | Y29: =V29 -> 0 | Z29: =SUM(X29:Y29) -> 60448.22
A30: =W30 -> 5300090 | B30: 2022 | C30: 0017 | D30: 2022_0017 | E30: Almira School District 017 | J30: 68589.96 | K30: 0.00010724 | N30: 54611.46 | O30: 0.00010642 | S30: Almira School District 017 | T30: Almira School District 017 | U30: =SUM(G30,I30,O30,Q30) -> 0.00010642 | W30: =IFERROR(VLOOKUP(E30,'LEAID Match'!$A$2:$B$326,2,FALSE),"") -> 5300090 | X30: =SUM(F30,J30) -> 68589.96 | Y30: =V30 -> 0 | Z30: =SUM(X30:Y30) -> 68589.96
A31: =W31 -> 5300090 | B31: 2023 | C31: 0017 | D31: 2023_0017 | E31: Almira School District 017 | J31: 64551.59 | K31: 9.54e-05 | N31: 51508.65 | O31: 9.544e-05 | S31: Almira School District 017 | T31: Almira School District 017 | U31: =SUM(G31,I31,O31,Q31) -> 9.544e-05 | V31: =U31*250000000 -> 23860 | W31: =IFERROR(VLOOKUP(E31,'LEAID Match'!$A$2:$B$326,2,FALSE),"") -> 5300090 | X31: =SUM(F31,J31) -> 64551.59 | Y31: =V31 -> 23860 | Z31: =SUM(X31:Y31) -> 88411.59
A32: =W32 -> 5300150 | B32: 2015 | C32: 0020 | D32: 2015_0020 | E32: Anacortes School District 103 | F32: 18136.72 | G32: 8.105e-05 | J32: 680420.16 | K32: 0.0025604 | N32: 542825.85 | O32: 0.00242575 | R32: Anacortes School District 103 | S32: Anacortes School District 103 | T32: Anacortes School District 103 | U32: =SUM(G32,I32,O32,Q32) -> 0.0025068 | W32: =IFERROR(VLOOKUP(E32,'LEAID Match'!$A$2:$B$326,2,FALSE),"") -> 5300150 | X32: =SUM(F32,J32) -> 698556.88 | Y32: =V32 -> 0 | Z32: =SUM(X32:Y32) -> 698556.88
A33: =W33 -> 5300150 | B33: 2016 | C33: 0020 | D33: 2016_0020 | E33: Anacortes School District 103 | F33: 23216.83 | G33: 7.639e-05 | J33: 837418.15 | K33: 0.00256559 | N33: 757940.6 | O33: 0.00249391 | R33: Anacortes School District 103 | S33: Anacortes School District 103 | T33: Anacortes School District 103 | U33: =SUM(G33,I33,O33,Q33) -> 0.0025703 | W33: =IFERROR(VLOOKUP(E33,'LEAID Match'!$A$2:$B$326,2,FALSE),"") -> 5300150 | X33: =SUM(F33,J33) -> 860634.98 | Y33: =V33 -> 0 | Z33: =SUM(X33:Y33) -> 860634.98
A34: =W34 -> 5300150 | B34: 2017 | C34: 0020 | D34: 2017_0020 | E34: Anacortes School District 103 | F34: 12583.5 | G34: 3.596e-05 | J34: 892670.68 | K34: 0.00242277 | N34: 827580.1 | O34: 0.00236495 | R34: Anacortes School District 103 | S34: Anacortes School District 103 | T34: Anacortes School District 103 | U34: =SUM(G34,I34,O34,Q34) -> 0.00240091 | W34: =IFERROR(VLOOKUP(E34,'LEAID Match'!$A$2:$B$326,2,FALSE),"") -> 5300150 | X34: =SUM(F34,J34) -> 905254.18 | Y34: =V34 -> 0 | Z34: =SUM(X34:Y34) -> 905254.18
A35: =W35 -> 5300150 | B35: 2018 | C35: 0020 | D35: 2018_0020 | E35: Anacortes School District 103 | F35: 2612.23 | G35: 6.28e-06 | J35: 1185172.7 | K35: 0.00266582 | N35: 1090753.3 | O35: 0.00262268 | R35: Anacortes School District 103 | S35: Anacortes School District 103 | T35: Anacortes School District 103 | U35: =SUM(G35,I35,O35,Q35) -> 0.00262896 | W35: =IFERROR(VLOOKUP(E35,'LEAID Match'!$A$2:$B$326,2,FALSE),"") -> 5300150 | X35: =SUM(F35,J35) -> 1187784.9 | Y35: =V35 -> 0 | Z35: =SUM(X35:Y35) -> 1187784.9
A36: =W36 -> 5300150 | B36: 2019 | C36: 0020 | D36: 2019_0020 | E36: Anacortes School District 103 | J36: 1478392.9 | K36: 0.00282846 | N36: 1388703.7 | O36: 0.00279628 | S36: Anacortes School District 103 | T36: Anacortes School District 103 | U36: =SUM(G36,I36,O36,Q36) -> 0.00279628 | W36: =IFERROR(VLOOKUP(E36,'LEAID Match'!$A$2:$B$326,2,FALSE),"") -> 5300150 | X36: =SUM(F36,J36) -> 1478392.9 | Y36: =V36 -> 0 | Z36: =SUM(X36:Y36) -> 1478392.9
A37: =W37 -> 5300150 | B37: 2020 | C37: 0020 | D37: 2020_0020 | E37: Anacortes School District 103 | J37: 1454387.9 | K37: 0.00249964 | N37: 1296419.5 | O37: 0.00246866 | S37: Anacortes School District 103 | T37: Anacortes School District 103 | U37: =SUM(G37,I37,O37,Q37) -> 0.00246866 | W37: =IFERROR(VLOOKUP(E37,'LEAID Match'!$A$2:$B$326,2,FALSE),"") -> 5300150 | X37: =SUM(F37,J37) -> 1454387.9 | Y37: =V37 -> 0 | Z37: =SUM(X37:Y37) -> 1454387.9
A38: =W38 -> 5300150 | B38: 2021 | C38: 0020 | D38: 2021_0020 | E38: Anacortes School District 103 | J38: 1469471.6 | K38: 0.00242822 | N38: 1328928.9 | O38: 0.00241791 | S38: Anacortes School District 103 | T38: Anacortes School District 103 | U38: =SUM(G38,I38,O38,Q38) -> 0.00241791 | W38: =IFERROR(VLOOKUP(E38,'LEAID Match'!$A$2:$B$326,2,FALSE),"") -> 5300150 | X38: =SUM(F38,J38) -> 1469471.6 | Y38: =V38 -> 0 | Z38: =SUM(X38:Y38) -> 1469471.6
A39: =W39 -> 5300150 | B39: 2022 | C39: 0020 | D39: 2022_0020 | E39: Anacortes School District 103 | J39: 1539973.6 | K39: 0.00240765 | N39: 1222705.1 | O39: 0.00238275 | S39: Anacortes School District 103 | T39: Anacortes School District 103 | U39: =SUM(G39,I39,O39,Q39) -> 0.00238275 | W39: =IFERROR(VLOOKUP(E39,'LEAID Match'!$A$2:$B$326,2,FALSE),"") -> 5300150 | X39: =SUM(F39,J39) -> 1539973.6 | Y39: =V39 -> 0 | Z39: =SUM(X39:Y39) -> 1539973.6
A40: =W40 -> 5300150 | B40: 2023 | C40: 0020 | D40: 2023_0020 | E40: Anacortes School District 103 | J40: 1694391.1 | K40: 0.00250402 | N40: 1351247.6 | O40: 0.0025036 | S40: Anacortes School District 103 | T40: Anacortes School District 103 | U40: =SUM(G40,I40,O40,Q40) -> 0.0025036 | V40: =U40*250000000 -> 625900 | W40: =IFERROR(VLOOKUP(E40,'LEAID Match'!$A$2:$B$326,2,FALSE),"") -> 5300150 | X40: =SUM(F40,J40) -> 1694391.1 | Y40: =V40 -> 625900 | Z40: =SUM(X40:Y40) -> 2320291.1
...

Sheet GASB Data -->

Sheet Final Check
A1: Employer Contribution Check Plan 1 | J1: Employer Contribution Check Plan 2/3 | S1: Employer Contribution Check Plan 1 UAAL | AB1: Allocation Percentage Check
A2: Year | B2: Employer Reported | C2: Employer Total from Formula | D2: State Agency Contributions | E2: State Total from Formula | F2: Employer Difference | G2: State Difference | H2: Notes | J2: Year | K2: Employer Reported | L2: Employer Total from Formula | M2: State Agency Contributions | N2: State Total from Formula | O2: Employer Difference | P2: State Difference | Q2: Notes | S2: Year | T2: Employer Reported | U2: Employer Total from Formula | V2: State Agency Contributions | W2: State Total from Formula | X2: Employer Difference | Y2: State Difference | Z2: Notes | AB2: Year | AC2: Plan 1 Employer | AD2: Plan 1 State | AE2: Plan 1 UAAL Employer | AF2: Plan 1 UAAL State | AG2: Total
A3: 2015 | B3: 11366880 | C3: =SUMIF(Summary!B:B,'Final Check'!A3,Summary!F:F) -> 11366880 | D3: 388219.29 | E3: =SUMIF(Summary!B:B,'Final Check'!A3,Summary!H:H) -> 388219.29 | F3: =B3-C3 -> 0 | G3: =D3-E3 -> 0 | J3: 2015 | K3: 2.6382385e+08 | L3: =SUMIF(Summary!B:B,'Final Check'!A3,Summary!J:J) -> 2.6382385e+08 | M3: 1923475.1 | N3: =SUMIF(Summary!B:B,'Final Check'!A3,Summary!L:L) -> 1923475.1 | O3: =K3-L3 -> 0 | P3: =M3-N3 -> 0 | S3: 2015 | T3: 2.1048975e+08 | U3: =SUMIF(Summary!B:B,'Final Check'!A3,Summary!N:N) -> 2.1048975e+08 | V3: 1532019.3 | W3: =SUMIF(Summary!B:B,'Final Check'!A3,Summary!P:P) -> 1532019.3 | X3: =T3-U3 -> 2.682209e-07 | Y3: =V3-W3 -> 0 | AB3: 2015 | AC3: =SUMIF(Summary!B:B,'Final Check'!AB3,Summary!G:G) -> 0.05079567 | AD3: =SUMIF(Summary!B:B,'Final Check'!AB3,Summary!I:I) -> 0.00173489 | AE3: =SUMIF(Summary!B:B,'Final Check'!AB3,Summary!O:O) -> 0.94062337 | AF3: =SUMIF(Summary!B:B,'Final Check'!AB3,Summary!Q:Q) -> 0.00684619 | AG3: =SUM(AC3:AF3) -> 1.0000001
A4: 2016 | B4: 10029664 | C4: =SUMIF(Summary!B:B,'Final Check'!A4,Summary!F:F) -> 10029664 | D4: 368815.48 | E4: =SUMIF(Summary!B:B,'Final Check'!A4,Summary!H:H) -> 368815.48 | F4: =B4-C4 -> 0 | G4: =D4-E4 -> 0 | J4: 2016 | K4: 3.2357568e+08 | L4: =SUMIF(Summary!B:B,'Final Check'!A4,Summary!J:J) -> 3.2357568e+08 | M4: 2827472.4 | N4: =SUMIF(Summary!B:B,'Final Check'!A4,Summary!L:L) -> 2827472.5 | O4: =K4-L4 -> 0 | P4: =M4-N4 -> -0.1 | S4: 2016 | T4: 2.909465e+08 | U4: =SUMIF(Summary!B:B,'Final Check'!A4,Summary!N:N) -> 2.909465e+08 | V4: 2570989.3 | W4: =SUMIF(Summary!B:B,'Final Check'!A4,Summary!P:P) -> 2570989.3 | X4: =T4-U4 -> 0 | Y4: =V4-W4 -> 0 | AB4: 2016 | AC4: =SUMIF(Summary!B:B,'Final Check'!AB4,Summary!G:G) -> 0.0330014 | AD4: =SUMIF(Summary!B:B,'Final Check'!AB4,Summary!I:I) -> 0.00121352 | AE4: =SUMIF(Summary!B:B,'Final Check'!AB4,Summary!O:O) -> 0.95732554 | AF4: =SUMIF(Summary!B:B,'Final Check'!AB4,Summary!Q:Q) -> 0.00845956 | AG4: =SUM(AC4:AF4) -> 1
A5: 2017 | B5: 8086251.5 | C5: =SUMIF(Summary!B:B,'Final Check'!A5,Summary!F:F) -> 8086251.6 | D5: 326043.38 | E5: =SUMIF(Summary!B:B,'Final Check'!A5,Summary!H:H) -> 326043.38 | F5: =B5-C5 -> 0 | G5: =D5-E5 -> 0 | J5: 2017 | K5: 3.6490793e+08 | L5: =SUMIF(Summary!B:B,'Final Check'!A5,Summary!J:J) -> 3.6490793e+08 | M5: 3542176 | N5: =SUMIF(Summary!B:B,'Final Check'!A5,Summary!L:L) -> 3542176 | O5: =K5-L5 -> 0 | P5: =M5-N5 -> 0 | S5: 2017 | T5: 3.3824175e+08 | U5: =SUMIF(Summary!B:B,'Final Check'!A5,Summary!N:N) -> 3.3824175e+08 | V5: 3282093.9 | W5: =SUMIF(Summary!B:B,'Final Check'!A5,Summary!P:P) -> 3282093.9 | X5: =T5-U5 -> 0 | Y5: =V5-W5 -> 0 | AB5: 2017 | AC5: =SUMIF(Summary!B:B,'Final Check'!AB5,Summary!G:G) -> 0.02310781 | AD5: =SUMIF(Summary!B:B,'Final Check'!AB5,Summary!I:I) -> 0.00093172 | AE5: =SUMIF(Summary!B:B,'Final Check'!AB5,Summary!O:O) -> 0.96658137 | AF5: =SUMIF(Summary!B:B,'Final Check'!AB5,Summary!Q:Q) -> 0.00937909 | AG5: =SUM(AC5:AF5) -> 0.99999999
A6: 2018 | B6: 6678806.5 | C6: =SUMIF(Summary!B:B,'Final Check'!A6,Summary!F:F) -> 6678806.5 | D6: 271603.94 | E6: =SUMIF(Summary!B:B,'Final Check'!A6,Summary!H:H) -> 271603.94 | F6: =B6-C6 -> 0 | G6: =D6-E6 -> 0 | J6: 2018 | K6: 4.3988162e+08 | L6: =SUMIF(Summary!B:B,'Final Check'!A6,Summary!J:J) -> 4.3988162e+08 | M6: 4698876.1 | N6: =SUMIF(Summary!B:B,'Final Check'!A6,Summary!L:L) -> 4698876.1 | O6: =K6-L6 -> 0 | P6: =M6-N6 -> 0 | S6: 2018 | T6: 4.046323e+08 | U6: =SUMIF(Summary!B:B,'Final Check'!A6,Summary!N:N) -> 4.046323e+08 | V6: 4310448.2 | W6: =SUMIF(Summary!B:B,'Final Check'!A6,Summary!P:P) -> 4310448.2 | X6: =T6-U6 -> 0 | Y6: =V6-W6 -> 0 | AB6: 2018 | AC6: =SUMIF(Summary!B:B,'Final Check'!AB6,Summary!G:G) -> 0.01605893 | AD6: =SUMIF(Summary!B:B,'Final Check'!AB6,Summary!I:I) -> 0.00065304 | AE6: =SUMIF(Summary!B:B,'Final Check'!AB6,Summary!O:O) -> 0.97292369 | AF6: =SUMIF(Summary!B:B,'Final Check'!AB6,Summary!Q:Q) -> 0.01036432 | AG6: =SUM(AC6:AF6) -> 0.99999998
A7: 2019 | B7: 5381785 | C7: =SUMIF(Summary!B:B,'Final Check'!A7,Summary!F:F) -> 5381785 | D7: 241304.74 | E7: =SUMIF(Summary!B:B,'Final Check'!A7,Summary!H:H) -> 241304.74 | F7: =B7-C7 -> 0 | G7: =D7-E7 -> 0 | J7: 2019 | K7: 5.1714333e+08 | L7: =SUMIF(Summary!B:B,'Final Check'!A7,Summary!J:J) -> 5.1714333e+08 | M7: 5541972.2 | N7: =SUMIF(Summary!B:B,'Final Check'!A7,Summary!L:L) -> 5541972.2 | O7: =K7-L7 -> 0 | P7: =M7-N7 -> 0 | S7: 2019 | T7: 4.8580801e+08 | U7: =SUMIF(Summary!B:B,'Final Check'!A7,Summary!N:N) -> 4.8580801e+08 | V7: 5195170.5 | W7: =SUMIF(Summary!B:B,'Final Check'!A7,Summary!P:P) -> 5195170.5 | X7: =T7-U7 -> 0 | Y7: =V7-W7 -> 0 | AB7: 2019 | AC7: =SUMIF(Summary!B:B,'Final Check'!AB7,Summary!G:G) -> 0.01083669 | AD7: =SUMIF(Summary!B:B,'Final Check'!AB7,Summary!I:I) -> 0.00048588 | AE7: =SUMIF(Summary!B:B,'Final Check'!AB7,Summary!O:O) -> 0.97821649 | AF7: =SUMIF(Summary!B:B,'Final Check'!AB7,Summary!Q:Q) -> 0.01046093 | AG7: =SUM(AC7:AF7) -> 0.99999999
A8: 2020 | B8: 4223996.3 | C8: =SUMIF(Summary!B:B,'Final Check'!A8,Summary!F:F) -> 4223996.3 | D8: 224773.37 | E8: =SUMIF(Summary!B:B,'Final Check'!A8,Summary!H:H) -> 224773.37 | F8: =B8-C8 -> 0 | G8: =D8-E8 -> 0 | J8: 2020 | K8: 5.7510956e+08 | L8: =SUMIF(Summary!B:B,'Final Check'!A8,Summary!J:J) -> 5.7510956e+08 | M8: 6730413.9 | N8: =SUMIF(Summary!B:B,'Final Check'!A8,Summary!L:L) -> 6730413.9 | O8: =K8-L8 -> 0 | P8: =M8-N8 -> 0 | S8: 2020 | T8: 5.1471309e+08 | U8: =SUMIF(Summary!B:B,'Final Check'!A8,Summary!N:N) -> 5.1471309e+08 | V8: 5990088.5 | W8: =SUMIF(Summary!B:B,'Final Check'!A8,Summary!P:P) -> 5990088.5 | X8: =T8-U8 -> 0 | Y8: =V8-W8 -> 0 | AB8: 2020 | AC8: =SUMIF(Summary!B:B,'Final Check'!AB8,Summary!G:G) -> 0.00804332 | AD8: =SUMIF(Summary!B:B,'Final Check'!AB8,Summary!I:I) -> 0.00042801 | AE8: =SUMIF(Summary!B:B,'Final Check'!AB8,Summary!O:O) -> 0.98012218 | AF8: =SUMIF(Summary!B:B,'Final Check'!AB8,Summary!Q:Q) -> 0.01140639 | AG8: =SUM(AC8:AF8) -> 0.9999999
A9: 2021 | B9: 2893717 | C9: =SUMIF(Summary!B:B,'Final Check'!A9,Summary!F:F) -> 2893717 | D9: 175966.81 | E9: =SUMIF(Summary!B:B,'Final Check'!A9,Summary!H:H) -> 175966.81 | F9: =B9-C9 -> 0 | G9: =D9-E9 -> 0 | J9: 2021 | K9: 5.9742305e+08 | L9: =SUMIF(Summary!B:B,'Final Check'!A9,Summary!J:J) -> 5.9742305e+08 | M9: 7741682.4 | N9: =SUMIF(Summary!B:B,'Final Check'!A9,Summary!L:L) -> 7741682.4 | O9: =K9-L9 -> -9.5367432e-07 | P9: =M9-N9 -> 0 | S9: 2021 | T9: 5.3954277e+08 | U9: =SUMIF(Summary!B:B,'Final Check'!A9,Summary!N:N) -> 5.3954277e+08 | V9: 7006043.5 | W9: =SUMIF(Summary!B:B,'Final Check'!A9,Summary!P:P) -> 7006043.5 | X9: =T9-U9 -> 0 | Y9: =V9-W9 -> 0 | AB9: 2021 | AC9: =SUMIF(Summary!B:B,'Final Check'!AB9,Summary!G:G) -> 0.00526497 | AD9: =SUMIF(Summary!B:B,'Final Check'!AB9,Summary!I:I) -> 0.00032018 | AE9: =SUMIF(Summary!B:B,'Final Check'!AB9,Summary!O:O) -> 0.98166772 | AF9: =SUMIF(Summary!B:B,'Final Check'!AB9,Summary!Q:Q) -> 0.01274712 | AG9: =SUM(AC9:AF9) -> 0.99999999
A10: 2022 | B10: 1836087.4 | C10: =SUMIF(Summary!B:B,'Final Check'!A10,Summary!F:F) -> 1836087.4 | D10: 103921.6 | E10: =SUMIF(Summary!B:B,'Final Check'!A10,Summary!H:H) -> 103921.6 | F10: =B10-C10 -> 0 | G10: =D10-E10 -> 0 | J10: 2022 | K10: 631238644 | L10: =SUMIF(Summary!B:B,'Final Check'!A10,Summary!J:J) -> 6.3123864e+08 | M10: 8377438.5 | N10: =SUMIF(Summary!B:B,'Final Check'!A10,Summary!L:L) -> 8377438.5 | O10: =K10-L10 -> 0 | P10: =M10-N10 -> 0 | S10: 2022 | T10: 5.0458304e+08 | U10: =SUMIF(Summary!B:B,'Final Check'!A10,Summary!N:N) -> 5.0458304e+08 | V10: 6625866.7 | W10: =SUMIF(Summary!B:B,'Final Check'!A10,Summary!P:P) -> 6625866.7 | X10: =T10-U10 -> 0 | Y10: =V10-W10 -> 0 | AB10: 2022 | AC10: =SUMIF(Summary!B:B,'Final Check'!AB10,Summary!G:G) -> 0.00357812 | AD10: =SUMIF(Summary!B:B,'Final Check'!AB10,Summary!I:I) -> 0.00020252 | AE10: =SUMIF(Summary!B:B,'Final Check'!AB10,Summary!O:O) -> 0.98330726 | AF10: =SUMIF(Summary!B:B,'Final Check'!AB10,Summary!Q:Q) -> 0.01291217 | AG10: =SUM(AC10:AF10) -> 1.0000001
A11: 2023 | B11: 1341220.8 | C11: =SUMIF(Summary!B:B,'Final Check'!A11,Summary!F:F) -> 1341220.8 | D11: 109560.56 | E11: =SUMIF(Summary!B:B,'Final Check'!A11,Summary!H:H) -> 109560.56 | F11: =B11-C11 -> 0 | G11: =D11-E11 -> 0 | J11: 2023 | K11: 6.6703359e+08 | L11: =SUMIF(Summary!B:B,'Final Check'!A11,Summary!J:J) -> 6.6703359e+08 | M11: 9633439.8 | N11: =SUMIF(Summary!B:B,'Final Check'!A11,Summary!L:L) -> 9633439.8 | O11: =K11-L11 -> 0 | P11: =M11-N11 -> 0 | S11: 2023 | T11: 5.3058379e+08 | U11: =SUMIF(Summary!B:B,'Final Check'!A11,Summary!N:N) -> 5.3058379e+08 | V11: 7687443.8 | W11: =SUMIF(Summary!B:B,'Final Check'!A11,Summary!P:P) -> 7687443.7 | X11: =T11-U11 -> 0 | Y11: =V11-W11 -> 0 | AB11: 2023 | AC11: =SUMIF(Summary!B:B,'Final Check'!AB11,Summary!G:G) -> 0.002485 | AD11: =SUMIF(Summary!B:B,'Final Check'!AB11,Summary!I:I) -> 0.00020299 | AE11: =SUMIF(Summary!B:B,'Final Check'!AB11,Summary!O:O) -> 0.98306867 | AF11: =SUMIF(Summary!B:B,'Final Check'!AB11,Summary!Q:Q) -> 0.01424333 | AG11: =SUM(AC11:AF11) -> 0.99999999

Sheet Plan 1
A1: year | B1: employer_code | C1: year_employer_code | D1: standardized_employer_name | E1: employer_name_1 | F1: plan1_employer_contributions | G1: plan1_allocation_percentage | H1: state_agency_contributions | I1: state_agency_allocation
A2: 2015 | B2: 1219 | C2: =_xlfn.TEXTJOIN("_",TRUE,A2:B2) -> 2015_1219 | D2: University of WA | E2: University of WA | H2: 43230.42 | I2: 0.00019319
A3: 2015 | B3: 0772 | C3: =_xlfn.TEXTJOIN("_",TRUE,A3:B3) -> 2015_0772 | D3: Superintendent of Public Instruction | E3: Superintendent of Public Instruction | H3: 29066.84 | I3: 0.00012989
A4: 2015 | B4: 0873 | C4: =_xlfn.TEXTJOIN("_",TRUE,A4:B4) -> 2015_0873 | D4: Skagit Valley College | E4: Skagit Valley College | H4: 23909.88 | I4: 0.00010685
A5: 2015 | B5: 0179 | C5: =_xlfn.TEXTJOIN("_",TRUE,A5:B5) -> 2015_0179 | D5: Spokane Community College | E5: Spokane Community College | H5: 18081.77 | I5: 8.08e-05
A6: 2015 | B6: 0839 | C6: =_xlfn.TEXTJOIN("_",TRUE,A6:B6) -> 2015_0839 | D6: Seattle Community College | E6: Seattle Community College | H6: 17606.05 | I6: 7.868e-05
A7: 2015 | B7: 0008 | C7: =_xlfn.TEXTJOIN("_",TRUE,A7:B7) -> 2015_0008 | D7: Administrative Office of the Court | E7: Administrative Office of the Court | H7: 15867.71 | I7: 7.091e-05
A8: 2015 | B8: 0169 | C8: =_xlfn.TEXTJOIN("_",TRUE,A8:B8) -> 2015_0169 | D8: Columbia Basin Community College | E8: Columbia Basin Community College | H8: 15085.47 | I8: 6.741e-05
A9: 2015 | B9: 1079 | C9: =_xlfn.TEXTJOIN("_",TRUE,A9:B9) -> 2015_1079 | D9: Western WA University | E9: Western WA University | H9: 15010.04 | I9: 6.708e-05
A10: 2015 | B10: 0049 | C10: =_xlfn.TEXTJOIN("_",TRUE,A10:B10) -> 2015_0049 | D10: Bellevue Community College | E10: Bellevue Community College | H10: 14775.14 | I10: 6.603e-05
A11: 2015 | B11: 1667 | C11: =_xlfn.TEXTJOIN("_",TRUE,A11:B11) -> 2015_1667 | D11: Bellingham Technical College | E11: Bellingham Technical College | H11: 14474.2 | I11: 6.468e-05
A12: 2015 | B12: 0906 | C12: =_xlfn.TEXTJOIN("_",TRUE,A12:B12) -> 2015_0906 | D12: Social & Health Services Department of | E12: Social & Health Services Department of | H12: 13138.13 | I12: 5.871e-05
A13: 2015 | B13: 0256 | C13: =_xlfn.TEXTJOIN("_",TRUE,A13:B13) -> 2015_0256 | D13: Edmonds Community College | E13: Edmonds Community College | H13: 12581.9 | I13: 5.623e-05
A14: 2015 | B14: 0287 | C14: =_xlfn.TEXTJOIN("_",TRUE,A14:B14) -> 2015_0287 | D14: Everett Community College | E14: Everett Community College | H14: 12238.19 | I14: 5.469e-05
A15: 2015 | B15: 0360 | C15: =_xlfn.TEXTJOIN("_",TRUE,A15:B15) -> 2015_0360 | D15: Grays Harbor College | E15: Grays Harbor College | H15: 10720.32 | I15: 4.791e-05
A16: 2015 | B16: 0273 | C16: =_xlfn.TEXTJOIN("_",TRUE,A16:B16) -> 2015_0273 | D16: Employment Security Department of | E16: Employment Security Department of | H16: 10526.88 | I16: 4.704e-05
A17: 2015 | B17: 0176 | C17: =_xlfn.TEXTJOIN("_",TRUE,A17:B17) -> 2015_0176 | D17: Community & Technical Colleges State Board for | E17: Community & Technical Colleges State Board for | H17: 10517.04 | I17: 4.7e-05
A18: 2015 | B18: 0675 | C18: =_xlfn.TEXTJOIN("_",TRUE,A18:B18) -> 2015_0675 | D18: Olympic College | E18: Olympic College | H18: 8216.03 | I18: 3.672e-05
A19: 2015 | B19: 1088 | C19: =_xlfn.TEXTJOIN("_",TRUE,A19:B19) -> 2015_1088 | D19: Whatcom Community College | E19: Whatcom Community College | H19: 8132.32 | I19: 3.634e-05
A20: 2015 | B20: 1735 | C20: =_xlfn.TEXTJOIN("_",TRUE,A20:B20) -> 2015_1735 | D20: Financial Institutions Department of | E20: Financial Institutions Department of | H20: 8102.15 | I20: 3.621e-05
A21: 2015 | B21: 0254 | C21: =_xlfn.TEXTJOIN("_",TRUE,A21:B21) -> 2015_0254 | D21: Ecology Department of | E21: Ecology Department of | H21: 8015.05 | I21: 3.582e-05
A22: 2015 | B22: 0068 | C22: =_xlfn.TEXTJOIN("_",TRUE,A22:B22) -> 2015_0068 | D22: Big Bend Community College | E22: Big Bend Community College | H22: 7998.96 | I22: 3.575e-05
A23: 2015 | B23: 0864 | C23: =_xlfn.TEXTJOIN("_",TRUE,A23:B23) -> 2015_0864 | D23: Shoreline Community College | E23: Shoreline Community College | H23: 7992.36 | I23: 3.572e-05
A24: 2015 | B24: 0997 | C24: =_xlfn.TEXTJOIN("_",TRUE,A24:B24) -> 2015_0997 | D24: Transportation Department of | E24: Transportation Department of | H24: 7832.43 | I24: 3.5e-05
A25: 2015 | B25: 1053 | C25: =_xlfn.TEXTJOIN("_",TRUE,A25:B25) -> 2015_1053 | D25: Walla Walla Community College | E25: Walla Walla Community College | H25: 7482.15 | I25: 3.344e-05
A26: 2015 | B26: 0178 | C26: =_xlfn.TEXTJOIN("_",TRUE,A26:B26) -> 2015_0178 | D26: Centralia College | E26: Centralia College | H26: 7333.2 | I26: 3.277e-05
A27: 2015 | B27: 1074 | C27: =_xlfn.TEXTJOIN("_",TRUE,A27:B27) -> 2015_1074 | D27: Wenatchee Valley College | E27: Wenatchee Valley College | H27: 7172.05 | I27: 3.205e-05
A28: 2015 | B28: 1021 | C28: =_xlfn.TEXTJOIN("_",TRUE,A28:B28) -> 2015_1021 | D28: WA State University | E28: WA State University | H28: 6428.75 | I28: 2.873e-05
A29: 2015 | B29: 0377 | C29: =_xlfn.TEXTJOIN("_",TRUE,A29:B29) -> 2015_0377 | D29: Highline Community College | E29: Highline Community College | H29: 6210.5 | I29: 2.775e-05
A30: 2015 | B30: 1591 | C30: =_xlfn.TEXTJOIN("_",TRUE,A30:B30) -> 2015_1591 | D30: South Puget Sound Community College | E30: South Puget Sound Community College | H30: 5274.54 | I30: 2.357e-05
A31: 2015 | B31: 0117 | C31: =_xlfn.TEXTJOIN("_",TRUE,A31:B31) -> 2015_0117 | D31: Central WA University | E31: Central WA University | H31: 3907.71 | I31: 1.746e-05
A32: 2015 | B32: 0152 | C32: =_xlfn.TEXTJOIN("_",TRUE,A32:B32) -> 2015_0152 | D32: Clark Community College | E32: Clark Community College | H32: 3563.41 | I32: 1.592e-05
A33: 2015 | B33: 0365 | C33: =_xlfn.TEXTJOIN("_",TRUE,A33:B33) -> 2015_0365 | D33: Green Hill School | E33: Green Hill School | H33: 2888.41 | I33: 1.291e-05
A34: 2015 | B34: 1673 | C34: =_xlfn.TEXTJOIN("_",TRUE,A34:B34) -> 2015_1673 | D34: Lake Washington Institute of Technology | E34: Lake Washington Institute of Technology | H34: 2563.45 | I34: 1.146e-05
A35: 2015 | B35: 1130 | C35: =_xlfn.TEXTJOIN("_",TRUE,A35:B35) -> 2015_1130 | D35: Yakima Valley College | E35: Yakima Valley College | H35: 1294.61 | I35: 5.79e-06
A36: 2015 | B36: 0741 | C36: =_xlfn.TEXTJOIN("_",TRUE,A36:B36) -> 2015_0741 | D36: Pierce College | E36: Pierce College | H36: 940.39 | I36: 4.2e-06
A37: 2015 | B37: 0247 | C37: =_xlfn.TEXTJOIN("_",TRUE,A37:B37) -> 2015_0247 | D37: Eastern WA University | E37: Eastern WA University | H37: 40.84 | I37: 1.8e-07
A38: 2015 | B38: 0844 | C38: =_xlfn.TEXTJOIN("_",TRUE,A38:B38) -> 2015_0844 | D38: Seattle School District 001 | E38: Seattle School District 001 | F38: 694302.83 | G38: 0.00310266
A39: 2015 | B39: 0966 | C39: =_xlfn.TEXTJOIN("_",TRUE,A39:B39) -> 2015_0966 | D39: Tacoma School District 010 | E39: Tacoma School District 010 | F39: 547754.85 | G39: 0.00244777
A40: 2015 | B40: 0653 | C40: =_xlfn.TEXTJOIN("_",TRUE,A40:B40) -> 2015_0653 | D40: Northshore School District 417 | E40: Northshore School District 417 | F40: 390283.46 | G40: 0.00174407
...

Sheet Plan 2 and 3
A1: year | B1: employer_code | C1: employer_code_year | D1: standardized_employer_code | E1: employer_name_2_3 | F1: plan2_3_employer_contributions | G1: plan2_3_allocation_percentage | H1: plan_2_3state_agency_contributions | I1: plan2_3_state_agency_allocation
A2: 2015 | B2: 1021 | C2: =_xlfn.TEXTJOIN("_",TRUE,A2:B2) -> 2015_1021 | D2: WA State University | E2: WA State University | H2: 359624.59 | I2: 0.00135326
A3: 2015 | B3: 1219 | C3: =_xlfn.TEXTJOIN("_",TRUE,A3:B3) -> 2015_1219 | D3: University of WA | E3: University of WA | H3: 305200.26 | I3: 0.00114846
A4: 2015 | B4: 0938 | C4: =_xlfn.TEXTJOIN("_",TRUE,A4:B4) -> 2015_0938 | D4: School for the Blind | E4: School for the Blind | H4: 132137.86 | I4: 0.00049723
A5: 2015 | B5: 0939 | C5: =_xlfn.TEXTJOIN("_",TRUE,A5:B5) -> 2015_0939 | D5: Center for Childhood Deafness WA State | E5: Center for Childhood Deafness WA State | H5: 112559.93 | I5: 0.00042356
A6: 2015 | B6: 0179 | C6: =_xlfn.TEXTJOIN("_",TRUE,A6:B6) -> 2015_0179 | D6: Spokane Community College | E6: Spokane Community College | H6: 73369.16 | I6: 0.00027609
A7: 2015 | B7: 0152 | C7: =_xlfn.TEXTJOIN("_",TRUE,A7:B7) -> 2015_0152 | D7: Clark Community College | E7: Clark Community College | H7: 70112.53 | I7: 0.00026383
A8: 2015 | B8: 0963 | C8: =_xlfn.TEXTJOIN("_",TRUE,A8:B8) -> 2015_0963 | D8: Tacoma Community College | E8: Tacoma Community College | H8: 69729.84 | I8: 0.00026239
A9: 2015 | B9: 0117 | C9: =_xlfn.TEXTJOIN("_",TRUE,A9:B9) -> 2015_0117 | D9: Central WA University | E9: Central WA University | H9: 69629.13 | I9: 0.00026201
A10: 2015 | B10: 0839 | C10: =_xlfn.TEXTJOIN("_",TRUE,A10:B10) -> 2015_0839 | D10: Seattle Community College | E10: Seattle Community College | H10: 61251.05 | I10: 0.00023049
A11: 2015 | B11: 1591 | C11: =_xlfn.TEXTJOIN("_",TRUE,A11:B11) -> 2015_1591 | D11: South Puget Sound Community College | E11: South Puget Sound Community College | H11: 57183.53 | I11: 0.00021518
A12: 2015 | B12: 0049 | C12: =_xlfn.TEXTJOIN("_",TRUE,A12:B12) -> 2015_0049 | D12: Bellevue Community College | E12: Bellevue Community College | H12: 46584.91 | I12: 0.0001753
A13: 2015 | B13: 0247 | C13: =_xlfn.TEXTJOIN("_",TRUE,A13:B13) -> 2015_0247 | D13: Eastern WA University | E13: Eastern WA University | H13: 42309.11 | I13: 0.00015921
... A45: 2015 | B45: 0298 | C45: =_xlfn.TEXTJOIN("_",TRUE,A45:B45) -> 2015_0298 | D45: Ferries WA State | E45: Ferries WA State | H45: 152.15 | I45: 5.7e-07
A46: 2015 | B46: 0844 | C46: =_xlfn.TEXTJOIN("_",TRUE,A46:B46) -> 2015_0844 | D46: Seattle School District 001 | E46: Seattle School District 001 | F46: 15048761 | G46: 0.05662808
A47: 2015 | B47: 0966 | C47: =_xlfn.TEXTJOIN("_",TRUE,A47:B47) -> 2015_0966 | D47: Tacoma School District 010 | E47: Tacoma School District 010 | F47: 8522516.4 | G47: 0.03207
A48: 2015 | B48: 0926 | C48: =_xlfn.TEXTJOIN("_",TRUE,A48:B48) -> 2015_0926 | D48: Spokane Public Schools | E48: Spokane Public Schools | F48: 8309907.2 | G48: 0.03126996
A49: 2015 | B49: 0518 | C49: =_xlfn.TEXTJOIN("_",TRUE,A49:B49) -> 2015_0518 | D49: Lake Washington School District 414 | E49: Lake Washington School District 414 | F49: 7033264.5 | G49: 0.02646598
A50: 2015 | B50: 0435 | C50: =_xlfn.TEXTJOIN("_",TRUE,A50:B50) -> 2015_0435 | D50: Kent School District 415 | E50: Kent School District 415 | F50: 7021184 | G50: 0.02642053
A51: 2015 | B51: 0291 | C51: =_xlfn.TEXTJOIN("_",TRUE,A51:B51) -> 2015_0291 | D51: Evergreen School District 114 | E51: Evergreen School District 114 | F51: 6735260.8 | G51: 0.0253446
A52: 2015 | B52: 0294 | C52: =_xlfn.TEXTJOIN("_",TRUE,A52:B52) -> 2015_0294 | D52: Federal Way School District 210 | E52: Federal Way School District 210 | F52: 5754300.8 | G52: 0.02165328
A53: 2015 | B53: 0258 | C53: =_xlfn.TEXTJOIN("_",TRUE,A53:B53) -> 2015_0258 | D53: Edmonds School District 015 | E53: Edmonds School District 015 | F53: 5614524.1 | G53: 0.0211273
A54: 2015 | B54: 0290 | C54: =_xlfn.TEXTJOIN("_",TRUE,A54:B54) -> 2015_0290 | D54: Everett School District 002 | E54: Everett School District 002 | F54: 5512496.5 | G54: 0.02074337
A55: 2015 | B55: 1031 | C55: =_xlfn.TEXTJOIN("_",TRUE,A55:B55) -> 2015_1031 | D55: Vancouver School District 037 | E55: Vancouver School District 037 | F55: 5483520.4 | G55: 0.02063434
A56: 2015 | B56: 0050 | C56: =_xlfn.TEXTJOIN("_",TRUE,A56:B56) -> 2015_0050 | D56: Bellevue School District 405 | E56: Bellevue School District 405 | F56: 5482730.4 | G56: 0.02063137
A57: 2015 | B57: 0653 | C57: =_xlfn.TEXTJOIN("_",TRUE,A57:B57) -> 2015_0653 | D57: Northshore School District 417 | E57: Northshore School District 417 | F57: 5330002.4 | G57: 0.02005665
... A348: 2015 | B348: 0932 | C348: =_xlfn.TEXTJOIN("_",TRUE,A348:B348) -> 2015_0932 | D348: Star School District 054 | E348: Star School District 054 | F348: 4505.86 | G348: 1.696e-05
A349: 2016 | B349: 1021 | C349: =_xlfn.TEXTJOIN("_",TRUE,A349:B349) -> 2016_1021 | D349: WA State University | E349: WA State University | H349: 579531.83 | I349: 0.00177551
A350: 2016 | B350: 1219 | C350: =_xlfn.TEXTJOIN("_",TRUE,A350:B350) -> 2016_1219 | D350: University of WA | E350: University of WA | H350: 493645.65 | I350: 0.00151238
A351: 2016 | B351: 0938 | C351: =_xlfn.TEXTJOIN("_",TRUE,A351:B351) -> 2016_0938 | D351: School for the Blind | E351: School for the Blind | H351: 157201.62 | I351: 0.00048162
A352: 2016 | B352: 0939 | C352: =_xlfn.TEXTJOIN("_",TRUE,A352:B352) -> 2016_0939 | D352: Center for Childhood Deafness WA State | E352: Center for Childhood Deafness WA State | H352: 155101.45 | I352: 0.00047518
A353: 2016 | B353: 0117 | C353: =_xlfn.TEXTJOIN("_",TRUE,A353:B353) -> 2016_0117 | D353: Central WA University | E353: Central WA University | H353: 108345.11 | I353: 0.00033194
A354: 2016 | B354: 0152 | C354: =_xlfn.TEXTJOIN("_",TRUE,A354:B354) -> 2016_0152 | D354: Clark Community College | E354: Clark Community College | H354: 91012.96 | I354: 0.00027884
A355: 2016 | B355: 0839 | C355: =_xlfn.TEXTJOIN("_",TRUE,A355:B355) -> 2016_0839 | D355: Seattle Community College | E355: Seattle Community College | H355: 90737.9 | I355: 0.00027799
A356: 2016 | B356: 0179 | C356: =_xlfn.TEXTJOIN("_",TRUE,A356:B356) -> 2016_0179 | D356: Spokane Community College | E356: Spokane Community College | H356: 84091.43 | I356: 0.00025763
A357: 2016 | B357: 0963 | C357: =_xlfn.TEXTJOIN("_",TRUE,A357:B357) -> 2016_0963 | D357: Tacoma Community College | E357: Tacoma Community College | H357: 80748.05 | I357: 0.00024739
A358: 2016 | B358: 1591 | C358: =_xlfn.TEXTJOIN("_",TRUE,A358:B358) -> 2016_1591 | D358: South Puget Sound Community College | E358: South Puget Sound Community College | H358: 74358.6 | I358: 0.00022781
A359: 2016 | B359: 0049 | C359: =_xlfn.TEXTJOIN("_",TRUE,A359:B359) -> 2016_0049 | D359: Bellevue Community College | E359: Bellevue Community College | H359: 68774.77 | I359: 0.0002107
A360: 2016 | B360: 1079 | C360: =_xlfn.TEXTJOIN("_",TRUE,A360:B360) -> 2016_1079 | D360: Western WA University | E360: Western WA University | H360: 61236.23 | I360: 0.00018761
... A392: 2016 | B392: 0635 | C392: =_xlfn.TEXTJOIN("_",TRUE,A392:B392) -> 2016_0635 | D392: Natural Resources Department of | E392: Natural Resources Department of | H392: 11.65 | I392: 4e-08
...

Sheet Plan 1 UAAL
A1: year | B1: employer_code | C1: year_employer_code | D1: standardized_employer_name | E1: employer_name_uaal | F1: 1uaal_employer_contributions | G1: 1uaal_allocation_percentage | H1: 1uaal_state_agency_contributions | I1: 1uaal_state_agency_allocation
A2: 2015 | B2: 1021 | C2: =_xlfn.TEXTJOIN("_",TRUE,A2:B2) -> 2015_1021 | D2: WA State University | E2: WA State University | H2: 286384.46 | I2: 0.00127978
A3: 2015 | B3: 1219 | C3: =_xlfn.TEXTJOIN("_",TRUE,A3:B3) -> 2015_1219 | D3: University of WA | E3: University of WA | H3: 242738.21 | I3: 0.00108473
A4: 2015 | B4: 0938 | C4: =_xlfn.TEXTJOIN("_",TRUE,A4:B4) -> 2015_0938 | D4: School for the Blind | E4: School for the Blind | H4: 105405.36 | I4: 0.00047103
A5: 2015 | B5: 0939 | C5: =_xlfn.TEXTJOIN("_",TRUE,A5:B5) -> 2015_0939 | D5: Center for Childhood Deafness WA State | E5: Center for Childhood Deafness WA State | H5: 89878.83 | I5: 0.00040164
A6: 2015 | B6: 0179 | C6: =_xlfn.TEXTJOIN("_",TRUE,A6:B6) -> 2015_0179 | D6: Spokane Community College | E6: Spokane Community College | H6: 58356.3 | I6: 0.00026078
A7: 2015 | B7: 0152 | C7: =_xlfn.TEXTJOIN("_",TRUE,A7:B7) -> 2015_0152 | D7: Clark Community College | E7: Clark Community College | H7: 55655.1 | I7: 0.00024871
A8: 2015 | B8: 0117 | C8: =_xlfn.TEXTJOIN("_",TRUE,A8:B8) -> 2015_0117 | D8: Central WA University | E8: Central WA University | H8: 55493.08 | I8: 0.00024798
A9: 2015 | B9: 0963 | C9: =_xlfn.TEXTJOIN("_",TRUE,A9:B9) -> 2015_0963 | D9: Tacoma Community College | E9: Tacoma Community College | H9: 55363.84 | I9: 0.00024741
A10: 2015 | B10: 0839 | C10: =_xlfn.TEXTJOIN("_",TRUE,A10:B10) -> 2015_0839 | D10: Seattle Community College | E10: Seattle Community College | H10: 48643.75 | I10: 0.00021738
A11: 2015 | B11: 1591 | C11: =_xlfn.TEXTJOIN("_",TRUE,A11:B11) -> 2015_1591 | D11: South Puget Sound Community College | E11: South Puget Sound Community College | H11: 45459.76 | I11: 0.00020315
A12: 2015 | B12: 0049 | C12: =_xlfn.TEXTJOIN("_",TRUE,A12:B12) -> 2015_0049 | D12: Bellevue Community College | E12: Bellevue Community College | H12: 36998.01 | I12: 0.00016533
A13: 2015 | B13: 1079 | C13: =_xlfn.TEXTJOIN("_",TRUE,A13:B13) -> 2015_1079 | D13: Western WA University | E13: Western WA University | H13: 33687.62 | I13: 0.00015054
... A45: 2015 | B45: 0298 | C45: =_xlfn.TEXTJOIN("_",TRUE,A45:B45) -> 2015_0298 | D45: Ferries WA State | E45: Ferries WA State | H45: 118.95 | I45: 5.3e-07
A46: 2015 | B46: 0844 | C46: =_xlfn.TEXTJOIN("_",TRUE,A46:B46) -> 2015_0844 | D46: Seattle School District 001 | E46: Seattle School District 001 | F46: 12003890 | G46: 0.05364223
A47: 2015 | B47: 0966 | C47: =_xlfn.TEXTJOIN("_",TRUE,A47:B47) -> 2015_0966 | D47: Tacoma School District 010 | E47: Tacoma School District 010 | F47: 6798731 | G47: 0.03038174
A48: 2015 | B48: 0926 | C48: =_xlfn.TEXTJOIN("_",TRUE,A48:B48) -> 2015_0926 | D48: Spokane Public Schools | E48: Spokane Public Schools | F48: 6623280 | G48: 0.0295977
A49: 2015 | B49: 0518 | C49: =_xlfn.TEXTJOIN("_",TRUE,A49:B49) -> 2015_0518 | D49: Lake Washington School District 414 | E49: Lake Washington School District 414 | F49: 5606749 | G49: 0.02505509
A50: 2015 | B50: 0435 | C50: =_xlfn.TEXTJOIN("_",TRUE,A50:B50) -> 2015_0435 | D50: Kent School District 415 | E50: Kent School District 415 | F50: 5605762.8 | G50: 0.02505068
A51: 2015 | B51: 0291 | C51: =_xlfn.TEXTJOIN("_",TRUE,A51:B51) -> 2015_0291 | D51: Evergreen School District 114 | E51: Evergreen School District 114 | F51: 5374313 | G51: 0.02401639
A52: 2015 | B52: 0294 | C52: =_xlfn.TEXTJOIN("_",TRUE,A52:B52) -> 2015_0294 | D52: Federal Way School District 210 | E52: Federal Way School District 210 | F52: 4595962.1 | G52: 0.02053815
A53: 2015 | B53: 0258 | C53: =_xlfn.TEXTJOIN("_",TRUE,A53:B53) -> 2015_0258 | D53: Edmonds School District 015 | E53: Edmonds School District 015 | F53: 4465257.6 | G53: 0.01995406
A54: 2015 | B54: 0290 | C54: =_xlfn.TEXTJOIN("_",TRUE,A54:B54) -> 2015_0290 | D54: Everett School District 002 | E54: Everett School District 002 | F54: 4398019.4 | G54: 0.01965359
A55: 2015 | B55: 0050 | C55: =_xlfn.TEXTJOIN("_",TRUE,A55:B55) -> 2015_0050 | D55: Bellevue School District 405 | E55: Bellevue School District 405 | F55: 4375984.9 | G55: 0.01955513
A56: 2015 | B56: 1031 | C56: =_xlfn.TEXTJOIN("_",TRUE,A56:B56) -> 2015_1031 | D56: Vancouver School District 037 | E56: Vancouver School District 037 | F56: 4373567 | G56: 0.01954432
A57: 2015 | B57: 0653 | C57: =_xlfn.TEXTJOIN("_",TRUE,A57:B57) -> 2015_0653 | D57: Northshore School District 417 | E57: Northshore School District 417 | F57: 4251525.7 | G57: 0.01899895
... A348: 2015 | B348: 0932 | C348: =_xlfn.TEXTJOIN("_",TRUE,A348:B348) -> 2015_0932 | D348: Star School District 054 | E348: Star School District 054 | F348: 3604.35 | G348: 1.611e-05
A349: 2016 | B349: 1021 | C349: =_xlfn.TEXTJOIN("_",TRUE,A349:B349) -> 2016_1021 | D349: WA State University | E349: WA State University | H349: 526803.62 | I349: 0.00173339
A350: 2016 | B350: 1219 | C350: =_xlfn.TEXTJOIN("_",TRUE,A350:B350) -> 2016_1219 | D350: University of WA | E350: University of WA | H350: 448563.74 | I350: 0.00147595
A351: 2016 | B351: 0938 | C351: =_xlfn.TEXTJOIN("_",TRUE,A351:B351) -> 2016_0938 | D351: School for the Blind | E351: School for the Blind | H351: 141254.36 | I351: 0.00046478
A352: 2016 | B352: 0939 | C352: =_xlfn.TEXTJOIN("_",TRUE,A352:B352) -> 2016_0939 | D352: Center for Childhood Deafness WA State | E352: Center for Childhood Deafness WA State | H352: 140028.01 | I352: 0.00046075
A353: 2016 | B353: 0117 | C353: =_xlfn.TEXTJOIN("_",TRUE,A353:B353) -> 2016_0117 | D353: Central WA University | E353: Central WA University | H353: 99167.81 | I353: 0.0003263
A354: 2016 | B354: 0152 | C354: =_xlfn.TEXTJOIN("_",TRUE,A354:B354) -> 2016_0152 | D354: Clark Community College | E354: Clark Community College | H354: 83260.27 | I354: 0.00027396
A355: 2016 | B355: 0839 | C355: =_xlfn.TEXTJOIN("_",TRUE,A355:B355) -> 2016_0839 | D355: Seattle Community College | E355: Seattle Community College | H355: 82526.03 | I355: 0.00027154
A356: 2016 | B356: 0179 | C356: =_xlfn.TEXTJOIN("_",TRUE,A356:B356) -> 2016_0179 | D356: Spokane Community College | E356: Spokane Community College | H356: 76448.08 | I356: 0.00025154
A357: 2016 | B357: 0963 | C357: =_xlfn.TEXTJOIN("_",TRUE,A357:B357) -> 2016_0963 | D357: Tacoma Community College | E357: Tacoma Community College | H357: 73850.63 | I357: 0.000243
A358: 2016 | B358: 1591 | C358: =_xlfn.TEXTJOIN("_",TRUE,A358:B358) -> 2016_1591 | D358: South Puget Sound Community College | E358: South Puget Sound Community College | H358: 68317.28 | I358: 0.00022479
A359: 2016 | B359: 0049 | C359: =_xlfn.TEXTJOIN("_",TRUE,A359:B359) -> 2016_0049 | D359: Bellevue Community College | E359: Bellevue Community College | H359: 62803.9 | I359: 0.00020665
A360: 2016 | B360: 1079 | C360: =_xlfn.TEXTJOIN("_",TRUE,A360:B360) -> 2016_1079 | D360: Western WA University | E360: Western WA University | H360: 56202.23 | I360: 0.00018493
... A392: 2016 | B392: 0635 | C392: =_xlfn.TEXTJOIN("_",TRUE,A392:B392) -> 2016_0635 | D392: Natural Resources Department of | E392: Natural Resources Department of | H392: 10.79 | I392: 4e-08
...

Sheet NCES Data -->

Sheet LEAID Match
A1: district_name | B1: LEAID | C1: count
A2: Enumclaw School District 216 | B2: 5300001 | C2: =COUNTIF($B$2:$B$322,B2) -> 1
A3: Inchelium School District 070 | B3: 5300002 | C3: =COUNTIF($B$2:$B$322,B3) -> 1
A4: Kelso School District 458 | B4: 5300003 | C4: =COUNTIF($B$2:$B$322,B4) -> 1
A5: North Central WA Educational Service District 171 | B5: 5300004 | C5: =COUNTIF($B$2:$B$322,B5) -> 1
A6: Educational Service District 112 | B6: 5300005 | C6: =COUNTIF($B$2:$B$322,B6) -> 1
A7: Puget Sound Educational Service District 121 | B7: 5300006 | C7: =COUNTIF($B$2:$B$322,B7) -> 1
A8: Olympic Educational Service District 114 | B8: 5300007 | C8: =COUNTIF($B$2:$B$322,B8) -> 1
A9: Northwest Regional Educational Service District 189 | B9: 5300008 | C9: =COUNTIF($B$2:$B$322,B9) -> 1
A10: Northeast WA Educational Service District 101 | B10: 5300010 | C10: =COUNTIF($B$2:$B$322,B10) -> 1
A11: Educational Service District 113 | B11: 5300011 | C11: =COUNTIF($B$2:$B$322,B11) -> 1
A12: Educational Service District 123 | B12: 5300012 | C12: =COUNTIF($B$2:$B$322,B12) -> 1
A13: Aberdeen School District 005 | B13: 5300030 | C13: =COUNTIF($B$2:$B$322,B13) -> 1
... A29: Rainier Valley Leadership Academy | B29: 5300342 | C29: =COUNTIF($B$2:$B$322,B29) -> 1
A30: Summit Public Schools | C30: =COUNTIF($B$2:$B$322,B30) -> 0
A31: Innovation Schools | B31: 5300344 | C31: =COUNTIF($B$2:$B$322,B31) -> 1
A32: Impact Public Schools | B32: 5300345 | C32: =COUNTIF($B$2:$B$322,B32) -> 1
A33: Catalyst Public Schools | B33: 5300347 | C33: =COUNTIF($B$2:$B$322,B33) -> 1
A34: Lumen Public School | B34: 5300350 | C34: =COUNTIF($B$2:$B$322,B34) -> 1
A35: Intergenerational School | B35: 5300351 | C35: =COUNTIF($B$2:$B$322,B35) -> 1
A36: Pinnacles Prep Charter School | B36: 5300352 | C36: =COUNTIF($B$2:$B$322,B36) -> 1
A37: Pullman Community Motessori | B37: 5300355 | C37: =COUNTIF($B$2:$B$322,B37) -> 1
A38: Battle Ground School District 119 | B38: 5300380 | C38: =COUNTIF($B$2:$B$322,B38) -> 1
A39: Bellevue School District 405 | B39: 5300390 | C39: =COUNTIF($B$2:$B$322,B39) -> 1
A40: Bellingham School District 501 | B40: 5300420 | C40: =COUNTIF($B$2:$B$322,B40) -> 1
A41: Benge School District 122 | B41: 5300450 | C41: =COUNTIF($B$2:$B$322,B41) -> 1
A42: Bethel School District 403 | B42: 5300480 | C42: =COUNTIF($B$2:$B$322,B42) -> 1
... A320: Zillah School District 205 | B320: 5310170 | C320: =COUNTIF($B$2:$B$322,B320) -> 1
A321: Cascade Public Schools | C321: =COUNTIF($B$2:$B$322,B321) -> 0
A322: Center for Childhood Deafness WA State | B322: 5300015 | C322: =COUNTIF($B$2:$B$322,B322) -> 1
A323: Chief Leschi Schools | C323: =COUNTIF($B$2:$B$322,B323) -> 0
A324: Green Hill School | C324: =COUNTIF($B$2:$B$322,B324) -> 0
A325: Quileute Tribal School | C325: =COUNTIF($B$2:$B$322,B325) -> 0
A326: Quinault Lake School District 097 | C326: =COUNTIF($B$2:$B$322,B326) -> 0
