Workbook

Sheet Summary
A1: LEAID | B1: Year | C1: district_name | D1: state_contributions | E1: LEAID
B2: 2015 | C2: Addison Central SU | D2: 368073.12 | E2: =IFERROR(VLOOKUP(C2,'LEAID Match'!$A$2:$B$214,2,FALSE),"")
B3: 2016 | C3: Addison Central SU | D3: 388128.09 | E3: =IFERROR(VLOOKUP(C3,'LEAID Match'!$A$2:$B$214,2,FALSE),"")
B4: 2017 | C4: Addison Central SU | D4: 405265 | E4: =IFERROR(VLOOKUP(C4,'LEAID Match'!$A$2:$B$214,2,FALSE),"")
B5: 2018 | C5: Addison Central SU | E5: =IFERROR(VLOOKUP(C5,'LEAID Match'!$A$2:$B$214,2,FALSE),"")
B6: 2019 | C6: Addison Central SU | D6: 0 | E6: =IFERROR(VLOOKUP(C6,'LEAID Match'!$A$2:$B$214,2,FALSE),"")
B7: 2020 | C7: Addison Central SU | D7: 0 | E7: =IFERROR(VLOOKUP(C7,'LEAID Match'!$A$2:$B$214,2,FALSE),"")
B8: 2021 | C8: Addison Central SU | D8: 0 | E8: =IFERROR(VLOOKUP(C8,'LEAID Match'!$A$2:$B$214,2,FALSE),"")
B9: 2018 | C9: Addison Central Unified USD | D9: 2438169 | E9: =IFERROR(VLOOKUP(C9,'LEAID Match'!$A$2:$B$214,2,FALSE),"")
B10: 2019 | C10: Addison Central Unified USD | D10: 2356959 | E10: =IFERROR(VLOOKUP(C10,'LEAID Match'!$A$2:$B$214,2,FALSE),"")
B11: 2020 | C11: Addison Central Unified USD | D11: 2547252 | E11: =IFERROR(VLOOKUP(C11,'LEAID Match'!$A$2:$B$214,2,FALSE),"")
B12: 2021 | C12: Addison Central Unified USD | D12: 2637631 | E12: =IFERROR(VLOOKUP(C12,'LEAID Match'!$A$2:$B$214,2,FALSE),"")
B13: 2022 | C13: Addison Central Unified USD | D13: 6494062 | E13: =IFERROR(VLOOKUP(C13,'LEAID Match'!$A$2:$B$214,2,FALSE),"")
B14: 2015 | C14: Addison Northwest SU | D14: 230714.04 | E14: =IFERROR(VLOOKUP(C14,'LEAID Match'!$A$2:$B$214,2,FALSE),"")
B15: 2016 | C15: Addison Northwest SU | D15: 246220.22 | E15: =IFERROR(VLOOKUP(C15,'LEAID Match'!$A$2:$B$214,2,FALSE),"")
B16: 2017 | C16: Addison Northwest SU | D16: 263421 | E16: =IFERROR(VLOOKUP(C16,'LEAID Match'!$A$2:$B$214,2,FALSE),"")
B17: 2018 | C17: Addison Northwest SU | E17: =IFERROR(VLOOKUP(C17,'LEAID Match'!$A$2:$B$214,2,FALSE),"")
B18: 2019 | C18: Addison Northwest SU | D18: 0 | E18: =IFERROR(VLOOKUP(C18,'LEAID Match'!$A$2:$B$214,2,FALSE),"")
B19: 2020 | C19: Addison Northwest SU | D19: 0 | E19: =IFERROR(VLOOKUP(C19,'LEAID Match'!$A$2:$B$214,2,FALSE),"")
B20: 2021 | C20: Addison Northwest SU | D20: 0 | E20: =IFERROR(VLOOKUP(C20,'LEAID Match'!$A$2:$B$214,2,FALSE),"")
B21: 2018 | C21: Addison NW Unified USD | D21: 1303544 | E21: =IFERROR(VLOOKUP(C21,'LEAID Match'!$A$2:$B$214,2,FALSE),"")
B22: 2019 | C22: Addison NW Unified USD | D22: 1372296 | E22: =IFERROR(VLOOKUP(C22,'LEAID Match'!$A$2:$B$214,2,FALSE),"")
B23: 2020 | C23: Addison NW Unified USD | D23: 1360802 | E23: =IFERROR(VLOOKUP(C23,'LEAID Match'!$A$2:$B$214,2,FALSE),"")
B24: 2021 | C24: Addison NW Unified USD | D24: 1323092 | E24: =IFERROR(VLOOKUP(C24,'LEAID Match'!$A$2:$B$214,2,FALSE),"")
B25: 2022 | C25: Addison NW Unified USD | D25: 3367013 | E25: =IFERROR(VLOOKUP(C25,'LEAID Match'!$A$2:$B$214,2,FALSE),"")
B26: 2015 | C26: Austine School | D26: 1362.59 | E26: =IFERROR(VLOOKUP(C26,'LEAID Match'!$A$2:$B$214,2,FALSE),"")
B27: 2016 | C27: Austine School | E27: =IFERROR(VLOOKUP(C27,'LEAID Match'!$A$2:$B$214,2,FALSE),"")
B28: 2017 | C28: Austine School | E28: =IFERROR(VLOOKUP(C28,'LEAID Match'!$A$2:$B$214,2,FALSE),"")
B29: 2018 | C29: Austine School | E29: =IFERROR(VLOOKUP(C29,'LEAID Match'!$A$2:$B$214,2,FALSE),"")
B30: 2019 | C30: Austine School | D30: 0 | E30: =IFERROR(VLOOKUP(C30,'LEAID Match'!$A$2:$B$214,2,FALSE),"")
B31: 2020 | C31: Barre Unified USD | D31: 3148844 | E31: =IFERROR(VLOOKUP(C31,'LEAID Match'!$A$2:$B$214,2,FALSE),"")
B32: 2021 | C32: Barre Unified USD | D32: 3251765 | E32: =IFERROR(VLOOKUP(C32,'LEAID Match'!$A$2:$B$214,2,FALSE),"")
B33: 2022 | C33: Barre Unified USD | D33: 8046178 | E33: =IFERROR(VLOOKUP(C33,'LEAID Match'!$A$2:$B$214,2,FALSE),"")
B34: 2015 | C34: Barstow Joint | D34: 121062.37 | E34: =IFERROR(VLOOKUP(C34,'LEAID Match'!$A$2:$B$214,2,FALSE),"")
B35: 2016 | C35: Barstow Joint | D35: 139052.6 | E35: =IFERROR(VLOOKUP(C35,'LEAID Match'!$A$2:$B$214,2,FALSE),"")
B36: 2017 | C36: Barstow Joint | E36: =IFERROR(VLOOKUP(C36,'LEAID Match'!$A$2:$B$214,2,FALSE),"")
B37: 2018 | C37: Barstow Joint | E37: =IFERROR(VLOOKUP(C37,'LEAID Match'!$A$2:$B$214,2,FALSE),"")
B38: 2019 | C38: Barstow Joint | D38: 0 | E38: =IFERROR(VLOOKUP(C38,'LEAID Match'!$A$2:$B$214,2,FALSE),"")
B39: 2020 | C39: Barstow Joint | D39: 0 | E39: =IFERROR(VLOOKUP(C39,'LEAID Match'!$A$2:$B$214,2,FALSE),"")
B40: 2017 | C40: Barstow Unified USD | D40: 158748 | E40: =IFERROR(VLOOKUP(C40,'LEAID Match'!$A$2:$B$214,2,FALSE),"")
...

Sheet GASB 68 Data -->

Sheet 2015
A1: Year | B1: employer_number | C1: district_name | D1: district_contributions
A2: 2015 | B2: 300100 | C2: Addison School | D2: 56010.18
A3: 2015 | B3: 300200 | C3: Albany School | D3: 59865.38
A4: 2015 | B4: 300300 | C4: Alburg School | D4: 163807.84
A5: 2015 | B5: 300500 | C5: Arlington School | D5: 349530.48
A6: 2015 | B6: 300700 | C6: Bakersfield School | D6: 71031.1
A7: 2015 | B7: 300900 | C7: Barnard School | D7: 54919.37
A8: 2015 | B8: 301000 | C8: Barnet School | D8: 165974.81
A9: 2015 | B9: 301100 | C9: Barre City School | D9: 668933.74
A10: 2015 | B10: 301200 | C10: Barre Town School | D10: 527849.27
A11: 2015 | B11: 301300 | C11: Barton School | D11: 110989.81
A12: 2015 | B12: 301600 | C12: Bennington School | D12: 408793.46
A13: 2015 | B13: 301800 | C13: Benson School | D13: 46477
... A109: 2015 | B109: 314900 | C109: Newport Town School | D109: 77007.91
A110: 2015 | B110: 315000 | C110: No Bennington Id School
A111: 2015 | B111: 315100 | C111: North Hero School | D111: 48528.41
A112: 2015 | B112: 315500 | C112: Northfield School | D112: 390159.57
A113: 2015 | B113: 315700 | C113: Norwich School | D113: 289145.71
A114: 2015 | B114: 315800 | C114: Orange School | D114: 78174.02
A115: 2015 | B115: 315900 | C115: Orleans Id School | D115: 69456.47
A116: 2015 | B116: 316000 | C116: Orwell School | D116: 65165.28
A117: 2015 | B117: 316200 | C117: Union District #47 | D117: 183812.69
A118: 2015 | B118: 316300 | C118: Peacham School | D118: 45848.07
A119: 2015 | B119: 316600 | C119: Pittsford School | D119: 139488.53
A120: 2015 | B120: 316900 | C120: Pomfret School | D120: 6081.53
A121: 2015 | B121: 317000 | C121: Poultney School | D121: 273651.42
A122: 2015 | B122: 317100 | C122: Pownal School | D122: 170104.15
... A204: 2015 | B204: 327850 | C204: Dept Of Social & Rehab Serv | D204: 8350.44
A205: 2015 | B205: 327890 | C205: Department Of Corrections
A206: 2015 | B206: 327900 | C206: Addison Northwest SU | D206: 230714.04
A207: 2015 | B207: 328100 | C207: Rutland Northeast SU | D207: 345907.97
A208: 2015 | B208: 328300 | C208: Rutland South West SU | D208: 85346.87
A209: 2015 | B209: 328400 | C209: Addison Central SU | D209: 368073.12
A210: 2015 | B210: 328500 | C210: Grand Isle SU | D210: 41201.29
A211: 2015 | B211: 328600 | C211: Barstow Joint | D211: 121062.37
A212: 2015 | B212: 328700 | C212: Addison NE SU | D212: 139861.76
A213: 2015 | B213: 328800 | C213: Washington NE SU | D213: 106620.19
A214: 2015 | B214: 329100 | C214: Austine School | D214: 1362.59
A215: 2015 | B215: 329300 | C215: Vac School | D215: 12935.92
A216: 2015 | B216: 329400 | C216: Windsor SW SU
...

Sheet 2016
A1: Year | B1: district_name | C1: district_contributions
A2: 2016 | B2: Addison School | C2: 54922.82
A3: 2016 | B3: Albany School | C3: 57014.25
A4: 2016 | B4: Alburg School | C4: 150487.72
A5: 2016 | B5: Arlington School | C5: 378749.61
A6: 2016 | B6: Bakersfield School | C6: 85455.65
A7: 2016 | B7: Barnard School | C7: 44687.79
A8: 2016 | B8: Barnet School | C8: 153563.2
A9: 2016 | B9: Barre City School | C9: 568285.37
A10: 2016 | B10: Barre Town School | C10: 505038.22
A11: 2016 | B11: Barton School | C11: 100922.91
A12: 2016 | B12: Bennington School | C12: 411318.66
A13: 2016 | B13: Benson School | C13: 51069.95
... A21: 2016 | B21: Brattleboro Town School | C21: 515798.77
A22: 2016 | B22: Bridgewater School
A23: 2016 | B23: Bridport School | C23: 55894.5
A24: 2016 | B24: Brighton School | C24: 85807.07
A25: 2016 | B25: Bristol School | C25: 193216.03
A26: 2016 | B26: Brookfield School | C26: 39770.6
A27: 2016 | B27: Brownington School | C27: 63398.16
A28: 2016 | B28: Burke School | C28: 127895.41
A29: 2016 | B29: Burlington School | C29: 3410479.1
A30: 2016 | B30: Cabot School | C30: 132091.79
A31: 2016 | B31: Calais School | C31: 86389.57
A32: 2016 | B32: Cambridge School | C32: 231894.76
A33: 2016 | B33: Canaan School | C33: 170899.03
A34: 2016 | B34: Castleton/Hubbardton SD 42 | C34: 210041.23
... A83: 2016 | B83: Jay/Westfield School | C83: 66335.2
A84: 2016 | B84: Jericho School
A85: 2016 | B85: Johnson School | C85: 149189.91
A86: 2016 | B86: Leicester School | C86: 42212.9
A87: 2016 | B87: Lincoln School | C87: 77454.45
A88: 2016 | B88: Lowell School | C88: 90139.67
A89: 2016 | B89: Ludlow School | C89: 91612.91
A90: 2016 | B90: Lunenburg School | C90: 65108.02
A91: 2016 | B91: Lyndon Town School | C91: 263960.57
A92: 2016 | B92: Manchester School | C92: 349495.35
A93: 2016 | B93: Marlboro School | C93: 73650.66
A94: 2016 | B94: Middlebury Id School | C94: 254826.27
A95: 2016 | B95: Middlesex School | C95: 111576.68
...

Sheet 2017
A1: Year | B1: district_name | C1: district_contributions
A2: 2017 | B2: Addison Central SU | C2: 405265
A3: 2017 | B3: Addison NE SU | C3: 280006
A4: 2017 | B4: Addison Northwest SU | C4: 263421
A5: 2017 | B5: Addison Rutland SU | C5: 279929
A6: 2017 | B6: Addison School | C6: 59629
A7: 2017 | B7: Albany School | C7: 64137
A8: 2017 | B8: Alburg School | C8: 130349
A9: 2017 | B9: Arlington School | C9: 423575
A10: 2017 | B10: Austine School
A11: 2017 | B11: Bakersfield School | C11: 88083
A12: 2017 | B12: Barnard School | C12: 52640
A13: 2017 | B13: Barnet School | C13: 147561
A14: 2017 | B14: Barre City School | C14: 515012
A15: 2017 | B15: Barre SU | C15: 394693
A16: 2017 | B16: Barre Town School | C16: 438105
A17: 2017 | B17: Barstow Joint
A18: 2017 | B18: Barstow Unified USD | C18: 158748
A19: 2017 | B19: Barton School | C19: 109490
A20: 2017 | B20: Bellows Free Academy | C20: 865456
A21: 2017 | B21: Bennington School | C21: 432367
A22: 2017 | B22: Bennington-Rutland SU | C22: 358569
A23: 2017 | B23: Benson School | C23: 54716
A24: 2017 | B24: Berkshire School | C24: 99864
A25: 2017 | B25: Berlin School | C25: 149457
A26: 2017 | B26: Bethel School | C26: 217296
A27: 2017 | B27: Blue Mtn Union #21 | C27: 383350
A28: 2017 | B28: Bolton School
A29: 2017 | B29: Bradford School | C29: 156431
A30: 2017 | B30: Braintree School | C30: 48411
A31: 2017 | B31: Brandon Town School
A32: 2017 | B32: Brattleboro Town School | C32: 559102
A33: 2017 | B33: Brattleboro Union #6 | C33: 853460
A34: 2017 | B34: Bridgewater School
A35: 2017 | B35: Bridport School | C35: 65937
A36: 2017 | B36: Brighton School | C36: 75565
A37: 2017 | B37: Bristol School | C37: 203367
A38: 2017 | B38: Brookfield School | C38: 38686
A39: 2017 | B39: Brownington School | C39: 68630
A40: 2017 | B40: Burke School | C40: 134752
...

Sheet 2018
A1: Year | B1: district_name | C1: district_contributions
A2: 2018 | B2: Addison Central SU
A3: 2018 | B3: Addison Central Unified USD | C3: 2438169
A4: 2018 | B4: Addison NE SU | C4: 425068
A5: 2018 | B5: Addison Northwest SU
A6: 2018 | B6: Addison NW Unified USD | C6: 1303544
A7: 2018 | B7: Addison Rutland SU | C7: 435904
A8: 2018 | B8: Addison School | C8: 394
A9: 2018 | B9: Albany School | C9: 69931
A10: 2018 | B10: Alburg School | C10: 193711
A11: 2018 | B11: Arlington School | C11: 558829
A12: 2018 | B12: Austine School
A13: 2018 | B13: Bakersfield School | C13: 116123
A14: 2018 | B14: Barnard School | C14: 81968
A15: 2018 | B15: Barnet School | C15: 209336
A16: 2018 | B16: Barre City School | C16: 724966
A17: 2018 | B17: Barre SU | C17: 591490
A18: 2018 | B18: Barre Town School | C18: 627920
A19: 2018 | B19: Barstow Joint
A20: 2018 | B20: Barstow Unified USD | C20: 198520
A21: 2018 | B21: Barton School | C21: 116598
A22: 2018 | B22: Bellows Free Academy
A23: 2018 | B23: Bennington School | C23: 586140
A24: 2018 | B24: Bennington-Rutland SU | C24: 544913
A25: 2018 | B25: Benson School | C25: 75996
A26: 2018 | B26: Berkshire School | C26: 145655
A27: 2018 | B27: Berlin School | C27: 206757
A28: 2018 | B28: Bethel School | C28: 306673
A29: 2018 | B29: Blue Mtn Union #21 | C29: 542301
A30: 2018 | B30: Bolton School
A31: 2018 | B31: Bradford School | C31: 233779
A32: 2018 | B32: Braintree School
A33: 2018 | B33: Brandon Town School
A34: 2018 | B34: Brattleboro Town School | C34: 785879
A35: 2018 | B35: Brattleboro Union #6 | C35: 1208716
A36: 2018 | B36: Bridgewater School
A37: 2018 | B37: Bridport School
A38: 2018 | B38: Brighton School | C38: 110270
A39: 2018 | B39: Bristol School | C39: 246441
A40: 2018 | B40: Brookfield School
...

Sheet 2019
A1: Year | B1: district_name | C1: district_contributions
A2: 2019 | B2: Addison Central SU | C2: 0
A3: 2019 | B3: Addison Central Unified USD | C3: 2356959
A4: 2019 | B4: Addison NE SU | C4: 0
A5: 2019 | B5: Addison Northwest SU | C5: 0
A6: 2019 | B6: Addison NW Unified USD | C6: 1372296
A7: 2019 | B7: Addison Rutland SU | C7: 524541
A8: 2019 | B8: Addison School | C8: 0
A9: 2019 | B9: Albany School | C9: 72779
A10: 2019 | B10: Alburg School | C10: 191576
A11: 2019 | B11: Arlington School | C11: 564865
A12: 2019 | B12: Austine School | C12: 0
A13: 2019 | B13: Bakersfield School | C13: 116951
... A324: 2019 | B324: Worcester School | C324: 96566
B326: Summed Formulas | C326: =SUM(C2:C324) -> 113747928
B328: GASB 68 Number | C328: 113747925
B330: Check | C330: =C326-C328 -> 3

Sheet 2020
A1: Year | B1: district_name | C1: district_contributions
A2: 2020 | B2: Addison Central SU | C2: 0
A3: 2020 | B3: Addison Central Unified USD | C3: 2547252
A4: 2020 | B4: Addison NE SU | C4: 0
A5: 2020 | B5: Addison Northwest SU | C5: 0
A6: 2020 | B6: Addison NW Unified USD | C6: 1360802
A7: 2020 | B7: Addison Rutland SU | C7: 0
A8: 2020 | B8: Addison School | C8: 0
A9: 2020 | B9: Albany School | C9: 0
A10: 2020 | B10: Alburg School | C10: 209896
A11: 2020 | B11: Arlington School | C11: 583653
A12: 2020 | B12: Bakersfield School | C12: 0
A13: 2020 | B13: Barnard School | C13: 89301
... A331: 2020 | B331: Worcester School | C331: 0
B333: Summed Formulas | C333: =SUM(C2:C331) -> 120247383
B335: GASB 68 Number | C335: 120247389
B337: Check | C337: =C333-C335 -> -6

Sheet 2021
A1: Year
A2: 2021 | B2: Addison Central SU | C2: 0
A3: 2021 | B3: Addison Central Unified USD | C3: 2637631
A4: 2021 | B4: Addison NE SU | C4: 0
A5: 2021 | B5: Addison Northwest SU | C5: 0
A6: 2021 | B6: Addison NW Unified USD | C6: 1323092
A7: 2021 | B7: Addison Rutland SU | C7: 0
A8: 2021 | B8: Addison School | C8: 0
A9: 2021 | B9: Albany School | C9: 0
A10: 2021 | B10: Alburg School | C10: 222580
A11: 2021 | B11: Arlington School | C11: 585633
A12: 2021 | B12: Bakersfield School | C12: 0
A13: 2021 | B13: Barnard School | C13: 0
... A311: 2021 | B311: Worcester School | C311: 0
B313: Summed Formulas | C313: =SUM(C2:C311) -> 125910462
B315: GASB 68 Number | C315: 125910465
B317: Check | C317: =C313-C315 -> -3

Sheet 2022
A1: Year | B1: district_name | C1: district_contributions
A2: 2022 | B2: Burke School | C2: 0
A3: 2022 | B3: Burlington School | C3: 14780207
A4: 2022 | B4: Burr & Burton Seminary | C4: 2295577
A5: 2022 | B5: Addison Central Unified USD | C5: 6494062
A6: 2022 | B6: Addison NE SU | C6: 0
A7: 2022 | B7: Addison NW Unified USD | C7: 3367013
A8: 2022 | B8: Addison Rutland SU | C8: 0
A9: 2022 | B9: Addison School | C9: 0
A10: 2022 | B10: Albany School | C10: 0
A11: 2022 | B11: Alburg School | C11: 562740
A12: 2022 | B12: Arlington School | C12: 1099652
A13: 2022 | B13: Bakersfield School | C13: 0
... A268: 2022 | B268: Worcester School | C268: 0
B270: Summed Formulas | C270: =SUM(C2:C268) -> 314663635
B272: GASB 68 Number | C272: 314663632
B274: Check | C274: =C270-C272 -> 3

Sheet NCES Data -->

Sheet Combining LEAID
A1: LEAID | B1: NAME | C1: STNAME | D1: Year | E1: TOTALEXP | F1: TCURELSC | G1: TCURINST | H1: E13 | I1: V91 | J1: V92 | K1: TCURSSVC | L1: E17 | M1: E07 | N1: E08 | O1: E09 | P1: V40 | Q1: V45 | R1: V90 | S1: E11
A2: 5009570 | B2: North Country Junior UHSD #22 | C2: Vermont | D2: 2015 | E2: 7145000 | F2: 5354000 | G2: 3417000 | H2: 3417000 | I2: 0 | J2: 0 | K2: 1806000 | L2: 428000 | M2: 100000 | N2: 21000 | O2: 393000 | P2: 506000 | Q2: 221000 | R2: 137000 | S2: 149000
A3: 5009570 | B3: North Country Junior UHSD #22 | C3: Vermont | D3: 2016 | E3: 5673000 | F3: 5400000 | G3: 3447000 | H3: 3447000 | I3: 0 | J3: 0 | K3: 1953000 | L3: 409000 | M3: 87000 | N3: 179000 | O3: 412000 | P3: 518000 | Q3: 270000 | R3: 78000 | S3: 165000
A4: 5009570 | B4: North Country Junior UHSD #22 | C4: Vermont | D4: 2017 | E4: 5712000 | F4: 4470000 | G4: 2860000 | H4: 2860000 | I4: 0 | J4: 0 | K4: 1445000 | L4: 313000 | M4: 107000 | N4: 17000 | O4: 387000 | P4: 534000 | Q4: 6000 | R4: 81000 | S4: 155000
A5: 5009570 | B5: North Country Junior UHSD #22 | C5: Vermont | D5: 2018 | E5: 5370000 | F5: 4440000 | G5: 2969000 | H5: 2969000 | I5: 0 | J5: 0 | K5: 1322000 | L5: 278000 | M5: 88000 | N5: 15000 | O5: 409000 | P5: 532000 | Q5: 0 | R5: 0 | S5: 131000
A6: 5009570 | B6: North Country Junior UHSD #22 | C6: Vermont | D6: 2019 | E6: 5177000 | F6: 4497000 | G6: 3058000 | H6: 3058000 | I6: 0 | J6: 0 | K6: 1286000 | L6: 218000 | M6: 93000 | N6: 17000 | O6: 416000 | P6: 542000 | Q6: 0 | R6: 0 | S6: 153000
A7: 5009570 | B7: North Country Junior UHSD #22 | C7: Vermont | D7: 2020 | E7: 5180000 | F7: 4356000 | G7: 2856000 | H7: 2856000 | I7: 0 | J7: 0 | K7: 1389000 | L7: 265000 | M7: 72000 | N7: 24000 | O7: 455000 | P7: 573000 | Q7: 0 | R7: 0 | S7: 111000
A8: 5009570 | B8: North Country Junior UHSD #22 | C8: Vermont | D8: 2021 | E8: 5462000 | F8: 4730000 | G8: 2878000 | H8: 2878000 | I8: 0 | J8: 0 | K8: 1697000 | L8: 208000 | M8: 52000 | N8: 180000 | O8: 444000 | P8: 634000 | Q8: 5000 | R8: 174000 | S8: 150000
A9: 5009570 | B9: North Country Junior UHSD #22 | C9: Vermont | D9: 2022 | E9: 5954000 | F9: 5113000 | G9: 3334000 | H9: 3334000 | I9: 0 | J9: 0 | K9: 1629000 | L9: 347000 | M9: 118000 | N9: 20000 | O9: 485000 | P9: 654000 | Q9: 5000 | R9: 0 | S9: 0
A10: 5009600 | B10: North Country Senior UHSD #22 | C10: Vermont | D10: 2015 | E10: 20203000 | F10: 16362000 | G10: 10637000 | H10: 10637000 | I10: 0 | J10: 0 | K10: 5206000 | L10: 789000 | M10: 379000 | N10: 85000 | O10: 1410000 | P10: 1407000 | Q10: 817000 | R10: 319000 | S10: 440000
A11: 5009600 | B11: North Country Senior UHSD #22 | C11: Vermont | D11: 2016 | E11: 19999000 | F11: 15386000 | G11: 9623000 | H11: 9623000 | I11: 0 | J11: 0 | K11: 5323000 | L11: 912000 | M11: 335000 | N11: 58000 | O11: 1462000 | P11: 1390000 | Q11: 857000 | R11: 309000 | S11: 204000
A12: 5009600 | B12: North Country Senior UHSD #22 | C12: Vermont | D12: 2017 | E12: 19234000 | F12: 13113000 | G12: 8408000 | H12: 8408000 | I12: 0 | J12: 0 | K12: 4283000 | L12: 730000 | M12: 492000 | N12: 48000 | O12: 1419000 | P12: 1272000 | Q12: 4000 | R12: 318000 | S12: 422000
A13: 5009600 | B13: North Country Senior UHSD #22 | C13: Vermont | D13: 2018 | E13: 17874000 | F13: 12245000 | G13: 7815000 | H13: 7815000 | I13: 0 | J13: 0 | K13: 4036000 | L13: 823000 | M13: 432000 | N13: 44000 | O13: 1367000 | P13: 1252000 | Q13: 1000 | R13: 117000 | S13: 252000
... A17: 5009600 | B17: North Country Senior UHSD #22 | C17: Vermont | D17: 2022 | E17: 20866000 | F17: 15586000 | G17: 9187000 | H17: 9187000 | I17: 0 | J17: 0 | K17: 6073000 | L17: 1488000 | M17: 745000 | N17: 69000 | O17: 1693000 | P17: 1670000 | Q17: 90000 | R17: 318000 | S17: 326000
A19: LEAID | B19: NAME | C19: STNAME | D19: Year | E19: TOTALEXP | F19: TCURELSC | G19: TCURINST | H19: E13 | I19: V91 | J19: V92 | K19: TCURSSVC | L19: E17 | M19: E07 | N19: E08 | O19: E09 | P19: V40 | Q19: V45 | R19: V90 | S19: E11
A20: 5009600 | B20: North Country Senior UHSD #22 | C20: Vermont | D20: 2015 | E20: 27348000 | F20: 21716000 | G20: 14054000 | H20: 14054000 | I20: 0 | J20: 0 | K20: 7012000 | L20: 1217000 | M20: 479000 | N20: 106000 | O20: 1803000 | P20: 1913000 | Q20: 1038000 | R20: 456000 | S20: 589000
A21: 5009600 | B21: North Country Senior UHSD #22 | C21: Vermont | D21: 2016 | E21: 25672000 | F21: 20786000 | G21: 13070000 | H21: 13070000 | I21: 0 | J21: 0 | K21: 7276000 | L21: 1321000 | M21: 422000 | N21: 237000 | O21: 1874000 | P21: 1908000 | Q21: 1127000 | R21: 387000 | S21: 369000
A22: 5009600 | B22: North Country Senior UHSD #22 | C22: Vermont | D22: 2017 | E22: 24946000 | F22: 17583000 | G22: 11268000 | H22: 11268000 | I22: 0 | J22: 0 | K22: 5728000 | L22: 1043000 | M22: 599000 | N22: 65000 | O22: 1806000 | P22: 1806000 | Q22: 10000 | R22: 399000 | S22: 577000
A23: 5009600 | B23: North Country Senior UHSD #22 | C23: Vermont | D23: 2018 | E23: 23244000 | F23: 16685000 | G23: 10784000 | H23: 10784000 | I23: 0 | J23: 0 | K23: 5358000 | L23: 1101000 | M23: 520000 | N23: 59000 | O23: 1776000 | P23: 1784000 | Q23: 1000 | R23: 117000 | S23: 383000
A24: 5009600 | B24: North Country Senior UHSD #22 | C24: Vermont | D24: 2019 | E24: 22766000 | F24: 16817000 | G24: 10674000 | H24: 10674000 | I24: 0 | J24: 0 | K24: 5617000 | L24: 1207000 | M24: 528000 | N24: 65000 | O24: 1833000 | P24: 1877000 | Q24: 0 | R24: 107000 | S24: 526000
A25: 5009600 | B25: North Country Senior UHSD #22 | C25: Vermont | D25: 2020 | E25: 23533000 | F25: 17756000 | G25: 11386000 | H25: 11386000 | I25: 0 | J25: 0 | K25: 6007000 | L25: 1248000 | M25: 864000 | N25: 93000 | O25: 1738000 | P25: 1940000 | Q25: 31000 | R25: 93000 | S25: 505000
A26: 5009600 | B26: North Country Senior UHSD #22 | C26: Vermont | D26: 2021 | E26: 23594000 | F26: 18617000 | G26: 11500000 | H26: 11500000 | I26: 0 | J26: 0 | K26: 6758000 | L26: 1383000 | M26: 610000 | N26: 256000 | O26: 2045000 | P26: 2177000 | Q26: 17000 | R26: 270000 | S26: 669000
A27: 5009600 | B27: North Country Senior UHSD #22 | C27: Vermont | D27: 2022 | E27: 26820000 | F27: 20699000 | G27: 12521000 | H27: 12521000 | I27: 0 | J27: 0 | K27: 7702000 | L27: 1835000 | M27: 863000 | N27: 89000 | O27: 2178000 | P27: 2324000 | Q27: 95000 | R27: 318000 | S27: 326000

Sheet LEAID Match
A1: Name | B1: LEAID
A2: Addison NE SU | B2: 5099901
A3: Addison Rutland SU | B3: 5099904
A4: Addison School | B4: 5001710
A5: Albany School | B5: 5001740
A6: Alburg School | B6: 5001770
A7: Arlington School | B7: 5001830
A8: Bakersfield School | B8: 5001890
A9: Barnard School | B9: 5001950
A10: Barnet School | B10: 5001980
A11: Barre City School | B11: 5002010
A12: Barre SU | B12: 5000007
A13: Barre Town School | B13: 5002040
... A29: Burlington School | B29: 5002820
A30: Burr & Burton Seminary
A31: Cabot School | B31: 5002850
A32: Calais School | B32: 5002880
A33: Caledonia -Fed | B33: 5099909
A34: Caledonia North SU | B34: 5099908
A35: Cambridge School | B35: 5002910
A36: Canaan School | B36: 5002940
A37: Castleton/Hubbardton SD 42 | B37: 5000001
A38: Cavendish School | B38: 5003010
A39: Charleston School | B39: 5003060
A40: Chelsea School | B40: 5003120
A41: Chittenden East SU
A42: Colchester School | B42: 5003240
A43: Concord School | B43: 5003270
A44: Coventry School | B44: 5003360
A45: Craftsbury School | B45: 5003390
A46: Danville School | B46: 5003450
A47: Dept Of Education
A48: Dept Of Social & Rehab Serv
A49: Derby School | B49: 5003480
A50: Dorset School | B50: 5003510
A51: Dover School | B51: 5003540
A52: Dummerston School | B52: 5003570
A53: East Montpelier School | B53: 5003690
A54: Enosburg School | B54: 5003780
A55: Essex Caledonia SU | B55: 5099918
...
