Workbook

Sheet Summary
A1: Year | B1: district_code | C1: district_name | D1: district_contributions | E1: LEAID | F1: count
A2: 2015 | B2: 8105 | C2: =VLOOKUP(B2,'All Districts'!$A$3:$B$874,2,FALSE) -> Cayuga | D2: 733987 | E2: =VLOOKUP(C2,'All Districts'!$B$3:$C$874,2,FALSE) -> 0 | F2: =COUNTIF($E$2:$E$7106,E2) -> 352
A3: 2016 | B3: 8105 | C3: =VLOOKUP(B3,'All Districts'!$A$3:$B$874,2,FALSE) -> Cayuga | D3: 515660 | E3: =VLOOKUP(C3,'All Districts'!$B$3:$C$874,2,FALSE) -> 0 | F3: =COUNTIF($E$2:$E$7106,E3) -> 352
A4: 2017 | B4: 8105 | C4: =VLOOKUP(B4,'All Districts'!$A$3:$B$874,2,FALSE) -> Cayuga | D4: 420623 | E4: =VLOOKUP(C4,'All Districts'!$B$3:$C$874,2,FALSE) -> 0 | F4: =COUNTIF($E$2:$E$7106,E4) -> 352
A5: 2018 | B5: 8105 | C5: =VLOOKUP(B5,'All Districts'!$A$3:$B$874,2,FALSE) -> Cayuga | D5: 346806 | E5: =VLOOKUP(C5,'All Districts'!$B$3:$C$874,2,FALSE) -> 0 | F5: =COUNTIF($E$2:$E$7106,E5) -> 352
A6: 2019 | B6: 8105 | C6: =VLOOKUP(B6,'All Districts'!$A$3:$B$874,2,FALSE) -> Cayuga | D6: 419304 | E6: =VLOOKUP(C6,'All Districts'!$B$3:$C$874,2,FALSE) -> 0 | F6: =COUNTIF($E$2:$E$7106,E6) -> 352
A7: 2020 | B7: 8105 | C7: =VLOOKUP(B7,'All Districts'!$A$3:$B$874,2,FALSE) -> Cayuga | D7: 353066 | E7: =VLOOKUP(C7,'All Districts'!$B$3:$C$874,2,FALSE) -> 0 | F7: =COUNTIF($E$2:$E$7106,E7) -> 352
A8: 2021 | B8: 8105 | C8: =VLOOKUP(B8,'All Districts'!$A$3:$B$874,2,FALSE) -> Cayuga | D8: 335562 | E8: =VLOOKUP(C8,'All Districts'!$B$3:$C$874,2,FALSE) -> 0 | F8: =COUNTIF($E$2:$E$7106,E8) -> 352
A9: 2022 | B9: 8105 | C9: =VLOOKUP(B9,'All Districts'!$A$3:$B$874,2,FALSE) -> Cayuga | D9: 344281 | E9: =VLOOKUP(C9,'All Districts'!$B$3:$C$874,2,FALSE) -> 0 | F9: =COUNTIF($E$2:$E$7106,E9) -> 352
A10: 2023 | B10: 8105 | C10: =VLOOKUP(B10,'All Districts'!$A$3:$B$874,2,FALSE) -> Cayuga | D10: 365973 | E10: =VLOOKUP(C10,'All Districts'!$B$3:$C$874,2,FALSE) -> 0 | F10: =COUNTIF($E$2:$E$7106,E10) -> 352
A11: 2023 | B11: 8442 | C11: =VLOOKUP(B11,'All Districts'!$A$3:$B$874,2,FALSE) -> Citizenship and Science Academy of Rochester | D11: 99264 | E11: =VLOOKUP(C11,'All Districts'!$B$3:$C$874,2,FALSE) -> 0 | F11: =COUNTIF($E$2:$E$7106,E11) -> 352
A12: 2015 | B12: 8113 | C12: =VLOOKUP(B12,'All Districts'!$A$3:$B$874,2,FALSE) -> Columbia-Greene | D12: 271897 | E12: =VLOOKUP(C12,'All Districts'!$B$3:$C$874,2,FALSE) -> 0 | F12: =COUNTIF($E$2:$E$7106,E12) -> 352
A13: 2016 | B13: 8113 | C13: =VLOOKUP(B13,'All Districts'!$A$3:$B$874,2,FALSE) -> Columbia-Greene | D13: 215714 | E13: =VLOOKUP(C13,'All Districts'!$B$3:$C$874,2,FALSE) -> 0 | F13: =COUNTIF($E$2:$E$7106,E13) -> 352
... A7106: 2023 | B7106: 8439 | C7106: =VLOOKUP(B7106,'All Districts'!$A$3:$B$874,2,FALSE) -> University Preparatory Charter School for Young Men (Uprep) | D7106: 378331 | E7106: =VLOOKUP(C7106,'All Districts'!$B$3:$C$874,2,FALSE) -> 3600963 | F7106: =COUNTIF($E$2:$E$7106,E7106) -> 1

Sheet GASB 68 Data -->

Sheet 2015
A1: Year | B1: district_code | C1: district_contributions
A2: 2015 | B2: 1005 | C2: 12755224
A3: 2015 | B3: 1010 | C3: 4107536
A4: 2015 | B4: 1015 | C4: 4612784
A5: 2015 | B5: 1020 | C5: 2741539
A6: 2015 | B6: 1025 | C6: 4178070
A7: 2015 | B7: 1030 | C7: 6523188
A8: 2015 | B8: 1035 | C8: 43929028
A9: 2015 | B9: 1040 | C9: 4221331
A10: 2015 | B10: 1045 | C10: 2379542
A11: 2015 | B11: 1050 | C11: 6193738
A12: 2015 | B12: 1055 | C12: 2913063
A13: 2015 | B13: 1060 | C13: 2826746
... A790: 2015 | B790: 8431 | C790: 170825
B792: Summed Formulas | C792: =SUM(C2:C790) -> 2633243848
B794: GASB 68 | C794: 2633243839
B796: Check | C796: =C792-C794 -> 9

Sheet 2016
A1: Year | B1: district_code | C1: district_contributions
A2: 2016 | B2: 1005 | C2: 10546992
A3: 2016 | B3: 1010 | C3: 3159934
A4: 2016 | B4: 1015 | C4: 3530378
A5: 2016 | B5: 1020 | C5: 2067857
A6: 2016 | B6: 1025 | C6: 3276105
A7: 2016 | B7: 1030 | C7: 5132702
A8: 2016 | B8: 1035 | C8: 33792153
A9: 2016 | B9: 1040 | C9: 3209657
A10: 2016 | B10: 1045 | C10: 1860173
A11: 2016 | B11: 1050 | C11: 4816761
A12: 2016 | B12: 1055 | C12: 2309646
A13: 2016 | B13: 1060 | C13: 2232164
... A793: 2016 | B793: 8432 | C793: 161104
B795: Summed Formulas | C795: =SUM(C2:C793) -> 2046151755
B797: GASB 68 | C797: 2046151737
B799: Check | C799: =C795-C797 -> 18

Sheet 2017
A1: Year | B1: district_code | C1: district_contributions
A2: 2017 | B2: 1005 | C2: 9839703
A3: 2017 | B3: 1010 | C3: 2864476
A4: 2017 | B4: 1015 | C4: 3355673
A5: 2017 | B5: 1020 | C5: 1943864
A6: 2017 | B6: 1025 | C6: 2954466
A7: 2017 | B7: 1030 | C7: 4715410
A8: 2017 | B8: 1035 | C8: 34111982
A9: 2017 | B9: 1040 | C9: 2901991
A10: 2017 | B10: 1045 | C10: 1661418
A11: 2017 | B11: 1050 | C11: 4344034
A12: 2017 | B12: 1055 | C12: 2090133
A13: 2017 | B13: 1060 | C13: 1943555
... A789: 2017 | B789: 8434 | C789: 9510
B791: Summed Formulas | C791: =SUM(C2:C789) -> 1857233869
B793: GASB 68 | C793: 1857233863
B795: Check | C795: =C791-C793 -> 6

Sheet 2018
A1: Year | B1: district_code | C1: district_contributions
A2: 2018 | B2: 1005 | C2: 8692217
A3: 2018 | B3: 1010 | C3: 2396499
A4: 2018 | B4: 1015 | C4: 2714889
A5: 2018 | B5: 1020 | C5: 1664710
A6: 2018 | B6: 1025 | C6: 2599174
A7: 2018 | B7: 1030 | C7: 4121801
A8: 2018 | B8: 1035 | C8: 29085441
A9: 2018 | B9: 1040 | C9: 2513642
A10: 2018 | B10: 1045 | C10: 1460880
A11: 2018 | B11: 1050 | C11: 3666178
A12: 2018 | B12: 1055 | C12: 1750776
A13: 2018 | B13: 1060 | C13: 1761333
... A791: 2018 | B791: 8436 | C791: 313019
B793: Summed Formulas | C793: =SUM(C2:C791) -> 1596310619
B795: GASB 68 | C795: 1596310607
B797: Check | C797: =C793-C795 -> 12

Sheet 2019
A1: Year | B1: district_code | C1: district_contributions
A2: 2019 | B2: 1005 | C2: 9893500
A3: 2019 | B3: 1010 | C3: 2680351
A4: 2019 | B4: 1015 | C4: 2878043
A5: 2019 | B5: 1020 | C5: 1858796
A6: 2019 | B6: 1025 | C6: 2974066
A7: 2019 | B7: 1030 | C7: 4589301
A8: 2019 | B8: 1035 | C8: 31671613
A9: 2019 | B9: 1040 | C9: 2847689
A10: 2019 | B10: 1045 | C10: 1686229
A11: 2019 | B11: 1050 | C11: 4162158
A12: 2019 | B12: 1055 | C12: 1881349
A13: 2019 | B13: 1060 | C13: 1957360
... A790: 2019 | B790: 8436 | C790: 454672
B792: Summed Formulas | C792: =SUM(C2:C790) -> 1772650712
B794: GASB 68 | C794: 1772650717
B796: Check | C796: =C792-C794 -> -5

Sheet 2020
A1: Year | B1: district_code | C1: district_contributions
A2: 2020 | B2: 1005 | C2: 8349598
A3: 2020 | B3: 1010 | C3: 2314373
A4: 2020 | B4: 1015 | C4: 2485086
A5: 2020 | B5: 1020 | C5: 1582591
A6: 2020 | B6: 1025 | C6: 2536580
A7: 2020 | B7: 1030 | C7: 3959255
A8: 2020 | B8: 1035 | C8: 27346681
A9: 2020 | B9: 1040 | C9: 2403079
A10: 2020 | B10: 1045 | C10: 1406580
A11: 2020 | B11: 1050 | C11: 3547095
A12: 2020 | B12: 1055 | C12: 1539122
A13: 2020 | B13: 1060 | C13: 1614834
... A789: 2020 | B789: 8437 | C789: 181360
B791: Summed Formulas | C791: =SUM(C2:C789) -> 1503822933
B793: GASB 68 | C793: 1503822923
B795: Check | C795: =C791-C793 -> 10

Sheet 2021
A1: Year | B1: district_code | C1: district_contributions
A2: 2021 | B2: 1005 | C2: 8019213
A3: 2021 | B3: 1010 | C3: 2432559
A4: 2021 | B4: 1015 | C4: 2787398
A5: 2021 | B5: 1020 | C5: 1666430
A6: 2021 | B6: 1025 | C6: 2760166
A7: 2021 | B7: 1030 | C7: 3993385
A8: 2021 | B8: 1035 | C8: 28800016
A9: 2021 | B9: 1040 | C9: 2595093
A10: 2021 | B10: 1045 | C10: 1430894
A11: 2021 | B11: 1050 | C11: 3873302
A12: 2021 | B12: 1055 | C12: 1553195
A13: 2021 | B13: 1060 | C13: 1746223
... A789: 2021 | B789: 8437 | C789: 212239
B791: Summed Formulas | C791: =SUM(C2:C789) -> 1617546594
B793: GASB 68 | C793: 1617546595
B795: Check | C795: =C791-C793 -> -1

Sheet 2022
A1: Year | B1: district_code | C1: district_contributions
A2: 2022 | B2: 1005 | C2: 9227330
A3: 2022 | B3: 1010 | C3: 2648498
A4: 2022 | B4: 1015 | C4: 3162536
A5: 2022 | B5: 1020 | C5: 1771675
A6: 2022 | B6: 1025 | C6: 2923690
A7: 2022 | B7: 1030 | C7: 4564482
A8: 2022 | B8: 1035 | C8: 31173702
A9: 2022 | B9: 1040 | C9: 2806692
A10: 2022 | B10: 1045 | C10: 1550759
A11: 2022 | B11: 1050 | C11: 4051696
A12: 2022 | B12: 1055 | C12: 1625898
A13: 2022 | B13: 1060 | C13: 1936370
... A789: 2022 | B789: 8438 | C789: 29338
B791: Summed Formulas | C791: =SUM(C2:C789) -> 1736096798
B793: GASB 68 | C793: 1736096794
B795: Check | C795: =C791-C793 -> 4

Sheet 2023
A1: Year | B1: district_code | C1: district_contributions
A2: 2023 | B2: 1005 | C2: 9811542
A3: 2023 | B3: 1010 | C3: 2910710
A4: 2023 | B4: 1015 | C4: 3550600
A5: 2023 | B5: 1020 | C5: 2062575
A6: 2023 | B6: 1025 | C6: 3249320
A7: 2023 | B7: 1030 | C7: 5062869
A8: 2023 | B8: 1035 | C8: 37766211
A9: 2023 | B9: 1040 | C9: 3018595
A10: 2023 | B10: 1045 | C10: 1700236
A11: 2023 | B11: 1050 | C11: 4376803
A12: 2023 | B12: 1055 | C12: 1837060
A13: 2023 | B13: 1060 | C13: 2084118
... A794: 2023 | B794: 8443 | C794: 75255
B796: Summed Formulas | C796: =SUM(C2:C794) -> 1900473516
B798: GASB 68 | C798: 1900473507
B800: Check | C800: =C796-C798 -> 9

Sheet NY Identifiers & LEAIDs -->

Sheet All Districts
A1: List of School Dist.
A2: School Dis Code | B2: District Name ()=also known as | C2: LEAID
A3: 4027 | B3: Dolgeville | C3: 3600001
A4: 4437 | B4: Sauquoit Valley | C4: 3600002
A5: 4979 | B5: Edwards-Knox | C5: 3600003
A6: 2381 | B6: Rotterdam-Mohonasen | C6: 3600004
A7: 4009 | B7: Broadalbin-Perth | C7: 3600005
A8: 3991 | B8: Cherry Valley-Springfield | C8: 3600006
A9: 5282 | B9: Jasper-Troupsburg | C9: 3600007
A10: 2563 | B10: South Country | C10: 3600008
A11: 2514 | B11: Saranac | C11: 3600009
A12: 2081 | B12: Cobleskill-Richmondville | C12: 3600010
A13: 4180 | B13: Wayland-Cohocton | C13: 3600011
A14: 3082 | B14: Bolivar-Richburg | C14: 3600012
... A698: 2645 | B698: Westbury | C698: 3630960
A699: 6109 | B699: Westchester 2 (Southern Westchester)
A700: 3309 | B700: Westfield | C700: 3630990
A701: 5361 | B701: Westhampton Beach | C701: 3631020
A702: 4439 | B702: Westmoreland | C702: 3631050
A703: 4258 | B703: Wheatland-Chili | C703: 3631170
A704: 4010 | B704: Wheelerville | C704: 3631200
A705: 1300 | B705: White Plains | C705: 3631260
A706: 2650 | B706: Whitehall | C706: 3631290
A707: 2649 | B707: Whitesboro | C707: 3631320
A708: 3079 | B708: Whitesville | C708: 3631350
A709: 2648 | B709: Whitney Point | C709: 3631380
A710: 4883 | B710: North Greenbush | C710: 3631410
A711: 4597 | B711: Williamson | C711: 3631440
... A802: 5800 | B802: Westchester 2 | C802: 3680960
A803: 8105 | B803: Cayuga
A804: 8442 | B804: Citizenship and Science Academy of Rochester
A805: 8113 | B805: Columbia-Greene
A806: 1050 | B806: Corning-Painted Post
A807: 2084 | B807: Cornwall
A808: 8000 | B808: Education Department
A809: 8124 | B809: Erie Community College Central Staff
A810: 8130 | B810: Fashion Institute of Technology
A811: 8129 | B811: Finger Lakes
A812: 8131 | B812: Fulton-Montgomery
A813: 8133 | B813: Genesee
...
