Workbook

Sheet Final Data
A1: LEAID | B1: Year | C1: standardized_employer_name | D1: employer_name | E1: district_contributions | F1: state_contributions | G1: total_contributions | H1: LEAID_match | I1: count
A2: =H2 | B2: 2015 | C2: Allegany County Board of Elections Supervisors | D2: Allegany County Board of Elections Supervisors | E2: 22089 | F2: 346511.33 | G2: =SUM(E2:F2) -> 368600.33 | H2: =IFERROR(VLOOKUP(C2,Sheet1!$B$2:$C$25,2,FALSE),"") | I2: =COUNTIF($H$2:$H$1812,H2) -> 1613
A3: =H3 | B3: 2016 | C3: Allegany County Board of Elections Supervisors | D3: Allegany County Board of Elections Supervisors | E3: 24601 | F3: 383993.02 | G3: =SUM(E3:F3) -> 408594.02 | H3: =IFERROR(VLOOKUP(C3,Sheet1!$B$2:$C$25,2,FALSE),"") | I3: =COUNTIF($H$2:$H$1812,H3) -> 1613
A4: =H4 | B4: 2017 | C4: Allegany County Board of Elections Supervisors | D4: Allegany County Board of Elections Supervisors | E4: - | F4: 0 | G4: =SUM(E4:F4) -> 0 | H4: =IFERROR(VLOOKUP(C4,Sheet1!$B$2:$C$25,2,FALSE),"") | I4: =COUNTIF($H$2:$H$1812,H4) -> 1613
A5: =H5 | B5: 2018 | C5: Allegany County Board of Elections Supervisors | D5: Allegany County Board of Elections Supervisors | E5: 28753 | F5: 432626.41 | G5: =SUM(E5:F5) -> 461379.41 | H5: =IFERROR(VLOOKUP(C5,Sheet1!$B$2:$C$25,2,FALSE),"") | I5: =COUNTIF($H$2:$H$1812,H5) -> 1613
A6: =H6 | B6: 2019 | C6: Allegany County Board of Elections Supervisors | D6: Allegany County Board of Elections Supervisors | E6: 29314 | F6: 421773.31 | G6: =SUM(E6:F6) -> 451087.31 | H6: =IFERROR(VLOOKUP(C6,Sheet1!$B$2:$C$25,2,FALSE),"") | I6: =COUNTIF($H$2:$H$1812,H6) -> 1613
A7: =H7 | B7: 2020 | C7: Allegany County Board of Elections Supervisors | D7: Allegany County Board of Elections Supervisors | E7: 33987 | F7: 475115.99 | G7: =SUM(E7:F7) -> 509102.99 | H7: =IFERROR(VLOOKUP(C7,Sheet1!$B$2:$C$25,2,FALSE),"") | I7: =COUNTIF($H$2:$H$1812,H7) -> 1613
A8: =H8 | B8: 2021 | C8: Allegany County Board of Elections Supervisors | D8: Allegany County Board of Elections Supervisors | E8: 34959 | F8: 456354.27 | G8: =SUM(E8:F8) -> 491313.27 | H8: =IFERROR(VLOOKUP(C8,Sheet1!$B$2:$C$25,2,FALSE),"") | I8: =COUNTIF($H$2:$H$1812,H8) -> 1613
A9: =H9 | B9: 2022 | C9: Allegany County Board of Elections Supervisors | D9: Allegany County Board of Elections Supervisors | E9: 35315 | F9: 485493.74 | G9: =SUM(E9:F9) -> 520808.74 | H9: =IFERROR(VLOOKUP(C9,Sheet1!$B$2:$C$25,2,FALSE),"") | I9: =COUNTIF($H$2:$H$1812,H9) -> 1613
A10: =H10 | B10: 2023 | C10: Allegany County Board of Elections Supervisors | D10: Allegany County Board of Elections Supervisors | E10: 49332 | F10: 660247.75 | G10: =SUM(E10:F10) -> 709579.75 | H10: =IFERROR(VLOOKUP(C10,Sheet1!$B$2:$C$25,2,FALSE),"") | I10: =COUNTIF($H$2:$H$1812,H10) -> 1613
A11: =H11 | B11: 2015 | C11: Allegany County College of Maryland | D11: Allegany County College of Maryland | E11: 81960 | F11: 1285710.9 | G11: =SUM(E11:F11) -> 1367670.9 | H11: =IFERROR(VLOOKUP(C11,Sheet1!$B$2:$C$25,2,FALSE),"") | I11: =COUNTIF($H$2:$H$1812,H11) -> 1613
A12: =H12 | B12: 2016 | C12: Allegany County College of Maryland | D12: Allegany County College of Maryland | E12: 75011 | F12: 1170834.5 | G12: =SUM(E12:F12) -> 1245845.5 | H12: =IFERROR(VLOOKUP(C12,Sheet1!$B$2:$C$25,2,FALSE),"") | I12: =COUNTIF($H$2:$H$1812,H12) -> 1613
A13: =H13 | B13: 2017 | C13: Allegany County College of Maryland | D13: Allegany County College of Maryland | E13: 77433 | F13: 1279998.4 | G13: =SUM(E13:F13) -> 1357431.4 | H13: =IFERROR(VLOOKUP(C13,Sheet1!$B$2:$C$25,2,FALSE),"") | I13: =COUNTIF($H$2:$H$1812,H13) -> 1613
A14: =H14 | B14: 2018 | C14: Allegany County College of Maryland | D14: Allegany County College of Maryland | E14: 75345 | F14: 1133663.8 | G14: =SUM(E14:F14) -> 1209008.8 | H14: =IFERROR(VLOOKUP(C14,Sheet1!$B$2:$C$25,2,FALSE),"") | I14: =COUNTIF($H$2:$H$1812,H14) -> 1613
A15: =H15 | B15: 2019 | C15: Allegany County College of Maryland | D15: Allegany County College of Maryland | E15: 74423 | F15: 1070806.9 | G15: =SUM(E15:F15) -> 1145229.9 | H15: =IFERROR(VLOOKUP(C15,Sheet1!$B$2:$C$25,2,FALSE),"") | I15: =COUNTIF($H$2:$H$1812,H15) -> 1613
A16: =H16 | B16: 2020 | C16: Allegany County College of Maryland | D16: Allegany County College of Maryland | E16: 82099 | F16: 1147690.2 | G16: =SUM(E16:F16) -> 1229789.2 | H16: =IFERROR(VLOOKUP(C16,Sheet1!$B$2:$C$25,2,FALSE),"") | I16: =COUNTIF($H$2:$H$1812,H16) -> 1613
... A42: =H42 | B42: 2022 | C42: Allegany County Library | D42: Allegany County Library | E42: 3479 | F42: 47827.629 | G42: =SUM(E42:F42) -> 51306.629 | H42: =IFERROR(VLOOKUP(C42,Sheet1!$B$2:$C$25,2,FALSE),"") | I42: =COUNTIF($H$2:$H$1812,H42) -> 1613
A43: =H43 | B43: 2023 | C43: Allegany County Library | D43: Allegany County Library | E43: - | F43: 0 | G43: =SUM(E43:F43) -> 0 | H43: =IFERROR(VLOOKUP(C43,Sheet1!$B$2:$C$25,2,FALSE),"") | I43: =COUNTIF($H$2:$H$1812,H43) -> 1613
A44: =H44 | B44: 2015 | C44: Allegany County Officials | D44: Allegany County Officials | E44: 27924 | F44: 438045.29 | G44: =SUM(E44:F44) -> 465969.29 | H44: =IFERROR(VLOOKUP(C44,Sheet1!$B$2:$C$25,2,FALSE),"") | I44: =COUNTIF($H$2:$H$1812,H44) -> 1613
A45: =H45 | B45: 2016 | C45: Allegany County Officials | D45: Allegany County Officials | E45: 36935 | F45: 576512.43 | G45: =SUM(E45:F45) -> 613447.43 | H45: =IFERROR(VLOOKUP(C45,Sheet1!$B$2:$C$25,2,FALSE),"") | I45: =COUNTIF($H$2:$H$1812,H45) -> 1613
A46: =H46 | B46: 2017 | C46: Allegany County Officials | D46: Allegany County Officials | E46: 41809 | F46: 691119.47 | G46: =SUM(E46:F46) -> 732928.47 | H46: =IFERROR(VLOOKUP(C46,Sheet1!$B$2:$C$25,2,FALSE),"") | I46: =COUNTIF($H$2:$H$1812,H46) -> 1613
A47: =H47 | B47: 2018 | C47: Allegany County Officials | D47: Allegany County Officials | E47: 29068 | F47: 437365.99 | G47: =SUM(E47:F47) -> 466433.99 | H47: =IFERROR(VLOOKUP(C47,Sheet1!$B$2:$C$25,2,FALSE),"") | I47: =COUNTIF($H$2:$H$1812,H47) -> 1613
A48: =H48 | B48: 2019 | C48: Allegany County Officials | D48: Allegany County Officials | E48: 29099 | F48: 418679.86 | G48: =SUM(E48:F48) -> 447778.86 | H48: =IFERROR(VLOOKUP(C48,Sheet1!$B$2:$C$25,2,FALSE),"") | I48: =COUNTIF($H$2:$H$1812,H48) -> 1613
A49: =H49 | B49: 2020 | C49: Allegany County Officials | D49: Allegany County Officials | E49: 38945 | F49: 544425.59 | G49: =SUM(E49:F49) -> 583370.59 | H49: =IFERROR(VLOOKUP(C49,Sheet1!$B$2:$C$25,2,FALSE),"") | I49: =COUNTIF($H$2:$H$1812,H49) -> 1613
A50: =H50 | B50: 2021 | C50: Allegany County Officials | D50: Allegany County Officials | E50: 42373 | F50: 553136.51 | G50: =SUM(E50:F50) -> 595509.51 | H50: =IFERROR(VLOOKUP(C50,Sheet1!$B$2:$C$25,2,FALSE),"") | I50: =COUNTIF($H$2:$H$1812,H50) -> 1613
A51: =H51 | B51: 2022 | C51: Allegany County Officials | D51: Allegany County Officials | E51: 43071 | F51: 592119.53 | G51: =SUM(E51:F51) -> 635190.53 | H51: =IFERROR(VLOOKUP(C51,Sheet1!$B$2:$C$25,2,FALSE),"") | I51: =COUNTIF($H$2:$H$1812,H51) -> 1613
A52: =H52 | B52: 2023 | C52: Allegany County Officials | D52: Allegany County Officials | E52: 44587 | F52: 596741.8 | G52: =SUM(E52:F52) -> 641328.8 | H52: =IFERROR(VLOOKUP(C52,Sheet1!$B$2:$C$25,2,FALSE),"") | I52: =COUNTIF($H$2:$H$1812,H52) -> 1613
A53: =H53 -> 2400030 | B53: 2015 | C53: Allegany County Public Schools | D53: Allegany County Public Schools | E53: 701600 | F53: 11006037 | G53: =SUM(E53:F53) -> 11707637 | H53: =IFERROR(VLOOKUP(C53,Sheet1!$B$2:$C$25,2,FALSE),"") -> 2400030 | I53: =COUNTIF($H$2:$H$1812,H53) -> 9
A54: =H54 -> 2400030 | B54: 2016 | C54: Allegany County Public Schools | D54: Allegany County Public Schools | E54: 572404 | F54: 8934561.2 | G54: =SUM(E54:F54) -> 9506965.2 | H54: =IFERROR(VLOOKUP(C54,Sheet1!$B$2:$C$25,2,FALSE),"") -> 2400030 | I54: =COUNTIF($H$2:$H$1812,H54) -> 9
A55: =H55 -> 2400030 | B55: 2017 | C55: Allegany County Public Schools | D55: Allegany County Public Schools | E55: 532468 | F55: 8801908.7 | G55: =SUM(E55:F55) -> 9334376.7 | H55: =IFERROR(VLOOKUP(C55,Sheet1!$B$2:$C$25,2,FALSE),"") -> 2400030 | I55: =COUNTIF($H$2:$H$1812,H55) -> 9
... A94: =H94 | B94: 2020 | C94: Anne Arundel County Commission | D94: Anne Arundel County Commission | E94: 2366721 | F94: 33085209 | G94: =SUM(E94:F94) -> 35451930 | H94: =IFERROR(VLOOKUP(C94,Sheet1!$B$2:$C$25,2,FALSE),"") | I94: =COUNTIF($H$2:$H$1812,H94) -> 1613
A95: =H95 | B95: 2021 | C95: Anne Arundel County Commission | D95: Anne Arundel County Commission | E95: - | F95: 0 | G95: =SUM(E95:F95) -> 0 | H95: =IFERROR(VLOOKUP(C95,Sheet1!$B$2:$C$25,2,FALSE),"") | I95: =COUNTIF($H$2:$H$1812,H95) -> 1613
A96: =H96 | B96: 2022 | C96: Anne Arundel County Commission | D96: Anne Arundel County Commission | E96: - | F96: 0 | G96: =SUM(E96:F96) -> 0 | H96: =IFERROR(VLOOKUP(C96,Sheet1!$B$2:$C$25,2,FALSE),"") | I96: =COUNTIF($H$2:$H$1812,H96) -> 1613
A97: =H97 | B97: 2023 | C97: Anne Arundel County Commission | D97: Anne Arundel County Commission | E97: - | F97: 0 | G97: =SUM(E97:F97) -> 0 | H97: =IFERROR(VLOOKUP(C97,Sheet1!$B$2:$C$25,2,FALSE),"") | I97: =COUNTIF($H$2:$H$1812,H97) -> 1613
A98: =H98 | B98: 2015 | C98: Anne Arundel County Community College | D98: Anne Arundel Co. Community College | E98: 378329 | F98: 5934867.4 | G98: =SUM(E98:F98) -> 6313196.4 | H98: =IFERROR(VLOOKUP(C98,Sheet1!$B$2:$C$25,2,FALSE),"") | I98: =COUNTIF($H$2:$H$1812,H98) -> 1613
A99: =H99 | B99: 2016 | C99: Anne Arundel County Community College | D99: Anne Arundel County Community College | E99: 345140 | F99: 5387234.3 | G99: =SUM(E99:F99) -> 5732374.3 | H99: =IFERROR(VLOOKUP(C99,Sheet1!$B$2:$C$25,2,FALSE),"") | I99: =COUNTIF($H$2:$H$1812,H99) -> 1613
A100: =H100 | B100: 2017 | C100: Anne Arundel County Community College | D100: Anne Arundel County Community College | E100: 312775 | F100: 5170295.7 | G100: =SUM(E100:F100) -> 5483070.7 | H100: =IFERROR(VLOOKUP(C100,Sheet1!$B$2:$C$25,2,FALSE),"") | I100: =COUNTIF($H$2:$H$1812,H100) -> 1613
A101: =H101 | B101: 2018 | C101: Anne Arundel County Community College | D101: Anne Arundel County Community College | E101: 304070 | F101: 4575129.9 | G101: =SUM(E101:F101) -> 4879199.9 | H101: =IFERROR(VLOOKUP(C101,Sheet1!$B$2:$C$25,2,FALSE),"") | I101: =COUNTIF($H$2:$H$1812,H101) -> 1613
A102: =H102 | B102: 2019 | C102: Anne Arundel County Community College | D102: Anne Arundel County Community College | E102: 315548 | F102: 4540142 | G102: =SUM(E102:F102) -> 4855690 | H102: =IFERROR(VLOOKUP(C102,Sheet1!$B$2:$C$25,2,FALSE),"") | I102: =COUNTIF($H$2:$H$1812,H102) -> 1613
A103: =H103 | B103: 2020 | C103: Anne Arundel County Community College | D103: Anne Arundel County Community College | E103: 341931 | F103: 4779971.4 | G103: =SUM(E103:F103) -> 5121902.4 | H103: =IFERROR(VLOOKUP(C103,Sheet1!$B$2:$C$25,2,FALSE),"") | I103: =COUNTIF($H$2:$H$1812,H103) -> 1613
...

Sheet Sheet1
A1: name | B1: NAME
A2: Allegany County Public Schools | B2: Allegany County Public Schools | C2: 2400030
A3: Anne Arundel County Public Schools | B3: Anne Arundel County Public Schools | C3: 2400060
A4: Calvert County Public Schools | B4: Baltimore City Public Schools | C4: 2400090
A5: Caroline County Public Schools | B5: Baltimore County Public Schools | C5: 2400120
A6: Carroll County Public Schools | B6: Calvert County Public Schools | C6: 2400150
A7: Cecil County Public Schools | B7: Caroline County Public Schools | C7: 2400180
A8: Dorchester County Public Schools | B8: Carroll County Public Schools | C8: 2400210
A9: Frederick County Public Schools | B9: Cecil County Public Schools | C9: 2400240
A10: Garrett County Public Schools | B10: Charles County Public Schools
A11: Harford County Board of Education | B11: Dorchester County Public Schools | C11: 2400300
A12: Howard County Public Schools | B12: Frederick County Public Schools | C12: 2400330
A13: Kent County Public Schools | B13: Garrett County Public Schools | C13: 2400360
A14: Montgomery County Board of Education | B14: Harford County Board of Education | C14: 2400390
A15: Prince George's County Public Schools | B15: Howard County Public Schools | C15: 2400420
A16: Queen Anne's County Public Schools | B16: Kent County Public Schools | C16: 2400450
A17: Somerset County Public Schools | B17: Montgomery County Board of Education | C17: 2400480
A18: St. Mary's County Board of Education | B18: Prince George's County Public Schools | C18: 2400510
A19: Talbot County Public Schools | B19: Queen Anne's County Public Schools | C19: 2400540
A20: Washington County Board of Education | B20: Somerset County Public Schools | C20: 2400570
A21: Worcester County Board of Education | B21: St. Mary's County Board of Education | C21: 2400600
A22: Baltimore City Public Schools | B22: Talbot County Public Schools | C22: 2400630
A23: Baltimore County Public Schools | B23: Washington County Board of Education | C23: 2400660
B24: Wicomico County Public Schools
B25: Worcester County Board of Education | C25: 2400720

Sheet Almost Final Data
A1: year | B1: employer_name | C1: employer_contributions | D1: employer_allocation | E1: employer_allocation_no_state | F1: state_contributions
A2: 2015 | B2: Allegany County Board of Elections Supervisors | C2: 22089 | D2: 1.048e-05 | E2: 0.00017488024 | F2: =E2* VLOOKUP(A2,Check!A$2:F$11,4,FALSE) -> 346511.33
A3: 2015 | B3: Allegany County College of Maryland | C3: 81960 | D3: 3.8885e-05 | E3: 0.00064888336 | F3: =E3* VLOOKUP(A3,Check!A$2:F$11,4,FALSE) -> 1285710.9
A4: 2015 | B4: Allegany County Commission | C4: 1356253 | D4: 0.000643466 | E4: 0.010737555 | F4: =E4* VLOOKUP(A4,Check!A$2:F$11,4,FALSE) -> 21275614
A5: 2015 | B5: Allegany County Library | C5: 8755 | D5: 4.154e-06 | E5: 6.931398e-05 | F5: =E5* VLOOKUP(A5,Check!A$2:F$11,4,FALSE) -> 137340.16
A6: 2015 | B6: Allegany County Officials | C6: 27924 | D6: 1.3248e-05 | E6: 0.00022107637 | F6: =E6* VLOOKUP(A6,Check!A$2:F$11,4,FALSE) -> 438045.29
A7: 2015 | B7: Allegany County Public Schools | C7: 701600 | D7: 0.00033287 | E7: 0.0055546189 | F7: =E7* VLOOKUP(A7,Check!A$2:F$11,4,FALSE) -> 11006037
A8: 2015 | B8: Allegany County Transit Authority | C8: 56490 | D8: 2.6801e-05 | E8: 0.00044723549 | F8: =E8* VLOOKUP(A8,Check!A$2:F$11,4,FALSE) -> 886161.67
A9: 2015 | B9: WMHPA (Allegany County Gov't) | C9: 9379 | D9: 4.45e-06 | E9: 7.4254234e-05 | F9: =E9* VLOOKUP(A9,Check!A$2:F$11,4,FALSE) -> 147128.88
A10: 2015 | B10: Allegany, Housing Authority of | C10: 30733 | D10: 1.4581e-05 | E10: 0.00024331543 | F10: =E10* VLOOKUP(A10,Check!A$2:F$11,4,FALSE) -> 482110.22
A11: 2015 | B11: Annapolis, City of | C11: 1655775 | D11: 0.000785573 | E11: 0.013108893 | F11: =E11* VLOOKUP(A11,Check!A$2:F$11,4,FALSE) -> 25974232
A12: 2015 | B12: Anne Arundel Co. Community College | C12: 378329 | D12: 0.000179496 | E12: 0.0029952586 | F12: =E12* VLOOKUP(A12,Check!A$2:F$11,4,FALSE) -> 5934867.4
A13: 2015 | B13: Anne Arundel Co. Economic Opp. Com. | C13: 114853 | D13: 5.4491e-05 | E13: 0.00090929967 | F13: =E13* VLOOKUP(A13,Check!A$2:F$11,4,FALSE) -> 1801705.2
... A48: 2015 | B48: Chesapeake Bay Commission | C48: 28311 | D48: 1.3432e-05 | E48: 0.00022414027 | F48: =E48* VLOOKUP(A48,Check!A$2:F$11,4,FALSE) -> 444116.18
A49: 2015 | B49: Cheaspeake Employers Insurance | C49: - | D49: 0 | F49: =E49* VLOOKUP(A49,Check!A$2:F$11,4,FALSE) -> 0
A50: 2015 | B50: Chestertown, Town of | C50: 120353 | D50: 5.7101e-05 | E50: 0.00095284357 | F50: =E50* VLOOKUP(A50,Check!A$2:F$11,4,FALSE) -> 1887984
A51: 2015 | B51: Chestertown, Town of (LEOPS) | C51: 97353 | D51: 4.6189e-05 | E51: 0.00077075088 | F51: =E51* VLOOKUP(A51,Check!A$2:F$11,4,FALSE) -> 1527181.7
A52: 2015 | B52: Cheverly, Town of | C52: 241826 | D52: 0.000114733 | E52: 0.0019145543 | F52: =E52* VLOOKUP(A52,Check!A$2:F$11,4,FALSE) -> 3793537.5
A53: 2015 | B53: Chevy Chase Fire Department | C53: 4470 | D53: 2.121e-06 | E53: 3.538932e-05 | F53: =E53* VLOOKUP(A53,Check!A$2:F$11,4,FALSE) -> 70121.131
A54: 2015 | B54: College of Southern Maryland | C54: 216576 | D54: 0.000102753 | E54: 0.0017146482 | F54: =E54* VLOOKUP(A54,Check!A$2:F$11,4,FALSE) -> 3397439.4
A55: 2015 | B55: College Park, City of | C55: 519846 | D55: 0.000246638 | E55: 0.0041156591 | F55: =E55* VLOOKUP(A55,Check!A$2:F$11,4,FALSE) -> 8154852.2
A56: 2015 | B56: Crisfield, City of | C56: 91939 | D56: 4.362e-05 | E56: 0.00072788784 | F56: =E56* VLOOKUP(A56,Check!A$2:F$11,4,FALSE) -> 1442252
A57: 2015 | B57: Crisfield, Housing Authority of | C57: 44400 | D57: 2.1065e-05 | E57: 0.00035151807 | F57: =E57* VLOOKUP(A57,Check!A$2:F$11,4,FALSE) -> 696505.19
A58: 2015 | B58: Cumberland Police Department, City of | C58: 696348 | D58: 0.000330378 | E58: 0.0055130385 | F58: =E58* VLOOKUP(A58,Check!A$2:F$11,4,FALSE) -> 10923649
A59: 2015 | B59: Cumberland, City of | C59: 1110294 | D59: 0.000526772 | E59: 0.0087902794 | F59: =E59* VLOOKUP(A59,Check!A$2:F$11,4,FALSE) -> 17417242
A60: 2015 | B60: Denton, Town of | C60: 233252 | D60: 0.000110665 | E60: 0.0018466733 | F60: =E60* VLOOKUP(A60,Check!A$2:F$11,4,FALSE) -> 3659036.7
A61: 2015 | B61: District Heights, City of | C61: 181389 | D61: 8.6059e-05 | E61: 0.0014360701 | F61: =E61* VLOOKUP(A61,Check!A$2:F$11,4,FALSE) -> 2845459
... A66: 2015 | B66: Dorchester County Roads Board | C66: 159520 | D66: 7.5683e-05 | E66: 0.0012629316 | F66: =E66* VLOOKUP(A66,Check!A$2:F$11,4,FALSE) -> 2502398.8
A67: 2015 | B67: Dorchester County Sanitary Commission | C67: - | D67: 0 | F67: =E67* VLOOKUP(A67,Check!A$2:F$11,4,FALSE) -> 0
A68: 2015 | B68: Eastern Shore Regional Library | C68: 35511 | D68: 1.6848e-05 | E68: 0.0002811432 | F68: =E68* VLOOKUP(A68,Check!A$2:F$11,4,FALSE) -> 557062.97
A69: 2015 | B69: Edmonston, Town of | C69: 17412 | D69: 8.261e-06 | E69: 0.00013785209 | F69: =E69* VLOOKUP(A69,Check!A$2:F$11,4,FALSE) -> 273142.98
A70: 2015 | B70: Elkton, Town of | C70: 6354 | D70: 3.014e-06 | E70: 5.0305086e-05 | F70: =E70* VLOOKUP(A70,Check!A$2:F$11,4,FALSE) -> 99675.54
A71: 2015 | B71: Emmitsburg, Town of | C71: 60516 | D71: 2.8712e-05 | E71: 0.00047910963 | F71: =E71* VLOOKUP(A71,Check!A$2:F$11,4,FALSE) -> 949317.75
A72: 2015 | B72: Federalsburg, Town of | C72: 124854 | D72: 5.9236e-05 | E72: 0.00098847832 | F72: =E72* VLOOKUP(A72,Check!A$2:F$11,4,FALSE) -> 1958591.4
A73: 2015 | B73: WMHPA (Frederick County Gov't) | C73: 9378 | D73: 4.449e-06 | E73: 7.4246317e-05 | F73: =E73* VLOOKUP(A73,Check!A$2:F$11,4,FALSE) -> 147113.19
A74: 2015 | B74: Frederick County Public Schools | C74: 3982050 | D74: 0.00188926 | E74: 0.031526183 | F74: =E74* VLOOKUP(A74,Check!A$2:F$11,4,FALSE) -> 62466633
A75: 2015 | B75: Frostburg, City of | C75: 169575 | D75: 8.0454e-05 | E75: 0.0013425378 | F75: =E75* VLOOKUP(A75,Check!A$2:F$11,4,FALSE) -> 2660132.1
A76: 2015 | B76: Fruitland, City of | C76: 79393 | D76: 3.7667e-05 | E76: 0.00062856023 | F76: =E76* VLOOKUP(A76,Check!A$2:F$11,4,FALSE) -> 1245442.3
A77: 2015 | B77: Fruitland, City of (LEOPS) | C77: 123683 | D77: 5.8681e-05 | E77: 0.00097920743 | F77: =E77* VLOOKUP(A77,Check!A$2:F$11,4,FALSE) -> 1940221.9
A78: 2015 | B78: Garrett County Commission | C78: 3303 | D78: 1.567e-06 | E78: 2.6150094e-05 | F78: =E78* VLOOKUP(A78,Check!A$2:F$11,4,FALSE) -> 51814.339
...

Sheet Check
A1: Employer Contribution Check
A2: Year | B2: Total Reported | C2: Total from Formula | D2: State Contributions | E2: Formula Total + State | F2: Difference | G2: Notes
A3: 2015 | B3: 2107730000 | C3: =SUMIF('Final Data'!B:B,Check!A3,'Final Data'!E:E) -> 1.3494278e+08 | D3: 1981420707 | E3: =SUM(C3:D3) -> 2.1163635e+09 | F3: =B3-E3 -> -8633487.1
A4: 2016 | B4: 1948083000 | C4: =SUMIF('Final Data'!B:B,Check!A4,'Final Data'!E:E) -> 1.2603636e+08 | D4: 1830791050 | E4: =SUM(C4:D4) -> 1.9568274e+09 | F4: =B4-E4 -> -8744409.8
A5: 2017 | B5: 2035341000 | C5: =SUMIF('Final Data'!B:B,Check!A5,'Final Data'!E:E) -> 1.249883e+08 | D5: 1919237489 | E5: =SUM(C5:D5) -> 2.0442258e+09 | F5: =B5-E5 -> -8884790.4
A6: 2018 | B6: 1994076000 | C6: =SUMIF('Final Data'!B:B,Check!A6,'Final Data'!E:E) -> 133293003 | D6: 1869805897 | E6: =SUM(C6:D6) -> 2003098900 | F6: =B6-E6 -> -9022900
A7: 2019 | B7: 2053499000 | C7: =SUMIF('Final Data'!B:B,Check!A7,'Final Data'!E:E) -> 143059945 | D7: 1920051952 | E7: =SUM(C7:D7) -> 2063111897 | F7: =B7-E7 -> -9612897
A8: 2020 | B8: 2144063000 | C8: =SUMIF('Final Data'!B:B,Check!A8,'Final Data'!E:E) -> 150991165 | D8: 2000928371 | E8: =SUM(C8:D8) -> 2151919536 | F8: =B8-E8 -> -7856536
A9: 2021 | B9: 2203524000 | C9: =SUMIF('Final Data'!B:B,Check!A9,'Final Data'!E:E) -> 165652348 | D9: 2046734024 | E9: =SUM(C9:D9) -> 2212386372 | F9: =B9-E9 -> -8862372
A10: 2022 | B10: 2282303000 | C10: =SUMIF('Final Data'!B:B,Check!A10,'Final Data'!E:E) -> 163998797 | D10: 2127544596 | E10: =SUM(C10:D10) -> 2291543393 | F10: =B10-E10 -> -9240393
A11: 2023 | B11: 2438917249 | C11: =SUMIF('Final Data'!B:B,Check!A11,'Final Data'!E:E) -> 179321017 | D11: 2269356786 | E11: =SUM(C11:D11) -> 2448677803 | F11: =B11-E11 -> -9760554

Sheet Data as Collected
A1: year | B1: employer_name | C1: employer_contributions | D1: employer_allocation
A2: 2015 | B2: State of Maryland | C2: 1981420707 | D2: 0.9400733
A3: 2015 | B3: Allegany County Board of Elections Supervisors | C3: 22089 | D3: 1.048e-05
A4: 2015 | B4: Allegany County College of Maryland | C4: 81960 | D4: 3.8885e-05
A5: 2015 | B5: Allegany County Commission | C5: 1356253 | D5: 0.000643466
A6: 2015 | B6: Allegany County Library | C6: 8755 | D6: 4.154e-06
A7: 2015 | B7: Allegany County Officials | C7: 27924 | D7: 1.3248e-05
A8: 2015 | B8: Allegany County Public Schools | C8: 701600 | D8: 0.00033287
A9: 2015 | B9: Allegany County Transit Authority | C9: 56490 | D9: 2.6801e-05
A10: 2015 | B10: WMHPA (Allegany County Gov't) | C10: 9379 | D10: 4.45e-06
A11: 2015 | B11: Allegany, Housing Authority of | C11: 30733 | D11: 1.4581e-05
A12: 2015 | B12: Annapolis, City of | C12: 1655775 | D12: 0.000785573
A13: 2015 | B13: Anne Arundel Co. Community College | C13: 378329 | D13: 0.000179496
... A49: 2015 | B49: Chesapeake Bay Commission | C49: 28311 | D49: 1.3432e-05
A50: 2015 | B50: Cheaspeake Employers Insurance | C50: - | D50: 0
A51: 2015 | B51: Chestertown, Town of | C51: 120353 | D51: 5.7101e-05
A52: 2015 | B52: Chestertown, Town of (LEOPS) | C52: 97353 | D52: 4.6189e-05
A53: 2015 | B53: Cheverly, Town of | C53: 241826 | D53: 0.000114733
A54: 2015 | B54: Chevy Chase Fire Department | C54: 4470 | D54: 2.121e-06
A55: 2015 | B55: College of Southern Maryland | C55: 216576 | D55: 0.000102753
A56: 2015 | B56: College Park, City of | C56: 519846 | D56: 0.000246638
A57: 2015 | B57: Crisfield, City of | C57: 91939 | D57: 4.362e-05
A58: 2015 | B58: Crisfield, Housing Authority of | C58: 44400 | D58: 2.1065e-05
A59: 2015 | B59: Cumberland Police Department, City of | C59: 696348 | D59: 0.000330378
A60: 2015 | B60: Cumberland, City of | C60: 1110294 | D60: 0.000526772
A61: 2015 | B61: Denton, Town of | C61: 233252 | D61: 0.000110665
A62: 2015 | B62: District Heights, City of | C62: 181389 | D62: 8.6059e-05
... A67: 2015 | B67: Dorchester County Roads Board | C67: 159520 | D67: 7.5683e-05
A68: 2015 | B68: Dorchester County Sanitary Commission | C68: - | D68: 0
A69: 2015 | B69: Eastern Shore Regional Library | C69: 35511 | D69: 1.6848e-05
A70: 2015 | B70: Edmonston, Town of | C70: 17412 | D70: 8.261e-06
A71: 2015 | B71: Elkton, Town of | C71: 6354 | D71: 3.014e-06
A72: 2015 | B72: Emmitsburg, Town of | C72: 60516 | D72: 2.8712e-05
A73: 2015 | B73: Federalsburg, Town of | C73: 124854 | D73: 5.9236e-05
A74: 2015 | B74: WMHPA (Frederick County Gov't) | C74: 9378 | D74: 4.449e-06
A75: 2015 | B75: Frederick County Public Schools | C75: 3982050 | D75: 0.00188926
A76: 2015 | B76: Frostburg, City of | C76: 169575 | D76: 8.0454e-05
A77: 2015 | B77: Fruitland, City of | C77: 79393 | D77: 3.7667e-05
A78: 2015 | B78: Fruitland, City of (LEOPS) | C78: 123683 | D78: 5.8681e-05
A79: 2015 | B79: Garrett County Commission | C79: 3303 | D79: 1.567e-06
...
