Workbook

Sheet Final Data
A1: LEAID | B1: Year | C1: state | D1: state_abv | E1: plan | F1: district_name | G1: district_code | H1: employer_contributions | I1: relevant_entity
A2: 0500001 | B2: 2015 | C2: Arkansas | D2: AR | E2: Arkansas Teacher Retirement System | F2: Dewitt School District | G2: 731 | H2: 939463 | I2: 1
A3: 0500001 | B3: 2016 | C3: Arkansas | D3: AR | E3: Arkansas Teacher Retirement System | F3: Dewitt School District | G3: 731 | H3: 955583 | I3: 1
A4: 0500001 | B4: 2017 | C4: Arkansas | D4: AR | E4: Arkansas Teacher Retirement System | F4: Dewitt School District | G4: 731 | H4: 949179 | I4: 1
A5: 0500001 | B5: 2018 | C5: Arkansas | D5: AR | E5: Arkansas Teacher Retirement System | F5: Dewitt School District | G5: 731 | H5: 984458 | I5: 1
A6: 0500001 | B6: 2019 | C6: Arkansas | D6: AR | E6: Arkansas Teacher Retirement System | F6: Dewitt School District | G6: 731 | H6: 1000954 | I6: 1
A7: 0500001 | B7: 2020 | C7: Arkansas | D7: AR | E7: Arkansas Teacher Retirement System | F7: Dewitt School District | G7: 731 | H7: 1031327 | I7: 1
A8: 0500001 | B8: 2021 | C8: Arkansas | D8: AR | E8: Arkansas Teacher Retirement System | F8: Dewitt School District | G8: 731 | H8: 1096548 | I8: 1
A9: 0500001 | B9: 2022 | C9: Arkansas | D9: AR | E9: Arkansas Teacher Retirement System | F9: Dewitt School District | G9: 731 | H9: 1094616 | I9: 1
A10: 0500001 | B10: 2023 | C10: Arkansas | D10: AR | E10: Arkansas Teacher Retirement System | F10: Dewitt School District | G10: 731 | H10: 1205264 | I10: 1
A11: 0500005 | B11: 2015 | C11: Arkansas | D11: AR | E11: Arkansas Teacher Retirement System | F11: Ozarks Unlimited Resource Educational Service Co-Op | G11: 1336 | H11: 502020 | I11: 0
A12: 0500005 | B12: 2016 | C12: Arkansas | D12: AR | E12: Arkansas Teacher Retirement System | F12: Ozarks Unlimited Resource Educational Service Co-Op | G12: 1336 | H12: 515561 | I12: 0
A13: 0500005 | B13: 2017 | C13: Arkansas | D13: AR | E13: Arkansas Teacher Retirement System | F13: Ozarks Unlimited Resource Educational Service Co-Op | G13: 1336 | H13: 497914 | I13: 0
... A172: 0500024 | B172: 2023 | C172: Arkansas | D172: AR | E172: Arkansas Teacher Retirement System | F172: Arkansas River Education Service Co-Op | G172: 1349 | H172: 878520 | I172: 0
A173: 0500025 | B173: 2015 | C173: Arkansas | D173: AR | E173: Arkansas Teacher Retirement System | F173: Arkansas Correctional School | G173: 1-328 | H173: 681401 | I173: 0
A174: 0500025 | B174: 2016 | C174: Arkansas | D174: AR | E174: Arkansas Teacher Retirement System | F174: Arkansas Correctional School | G174: 1-328 | H174: 723652 | I174: 0
A175: 0500025 | B175: 2017 | C175: Arkansas | D175: AR | E175: Arkansas Teacher Retirement System | F175: Arkansas Correctional School | G175: 1-328 | H175: 752135 | I175: 0
A176: 0500025 | B176: 2018 | C176: Arkansas | D176: AR | E176: Arkansas Teacher Retirement System | F176: Arkansas Correctional School | G176: 1-328 | H176: 766841 | I176: 0
A177: 0500025 | B177: 2019 | C177: Arkansas | D177: AR | E177: Arkansas Teacher Retirement System | F177: Arkansas Correctional School | G177: 1-328 | H177: 745798 | I177: 0
A178: 0500025 | B178: 2020 | C178: Arkansas | D178: AR | E178: Arkansas Teacher Retirement System | F178: Arkansas Correctional School | G178: 1-328 | H178: 721278 | I178: 0
A179: 0500025 | B179: 2021 | C179: Arkansas | D179: AR | E179: Arkansas Teacher Retirement System | F179: Arkansas Correctional School | G179: 1-328 | H179: 707141 | I179: 0
A180: 0500025 | B180: 2022 | C180: Arkansas | D180: AR | E180: Arkansas Teacher Retirement System | F180: Arkansas Correctional School | G180: 1-328 | H180: 921503 | I180: 0
A181: 0500025 | B181: 2023 | C181: Arkansas | D181: AR | E181: Arkansas Teacher Retirement System | F181: Arkansas Correctional School | G181: 1-328 | H181: 918898 | I181: 0
A182: 0500026 | B182: 2015 | C182: Arkansas | D182: AR | E182: Arkansas Teacher Retirement System | F182: Pine Bluff School District | G182: 593 | H182: 3875632 | I182: 1
A183: 0500026 | B183: 2016 | C183: Arkansas | D183: AR | E183: Arkansas Teacher Retirement System | F183: Pine Bluff School District | G183: 593 | H183: 3632162 | I183: 1
A184: 0500026 | B184: 2017 | C184: Arkansas | D184: AR | E184: Arkansas Teacher Retirement System | F184: Pine Bluff School District | G184: 593 | H184: 3457582 | I184: 1
A185: 0500026 | B185: 2018 | C185: Arkansas | D185: AR | E185: Arkansas Teacher Retirement System | F185: Pine Bluff School District | G185: 593 | H185: 3362266 | I185: 1
A186: 0500026 | B186: 2019 | C186: Arkansas | D186: AR | E186: Arkansas Teacher Retirement System | F186: Pine Bluff School District | G186: 593 | H186: 2965103 | I186: 1
A187: 0500026 | B187: 2020 | C187: Arkansas | D187: AR | E187: Arkansas Teacher Retirement System | F187: Pine Bluff School District | G187: 593 | H187: 2843222 | I187: 1
A188: 0500026 | B188: 2021 | C188: Arkansas | D188: AR | E188: Arkansas Teacher Retirement System | F188: Pine Bluff School District | G188: 593 | H188: 2749563 | I188: 1
A189: 0500026 | B189: 2022 | C189: Arkansas | D189: AR | E189: Arkansas Teacher Retirement System | F189: Pine Bluff School District | G189: 593 | H189: 4282216 | I189: 1
A190: 0500026 | B190: 2023 | C190: Arkansas | D190: AR | E190: Arkansas Teacher Retirement System | F190: Pine Bluff School District | G190: 593 | H190: 4708150 | I190: 1
A191: 0500028 | B191: 2015 | C191: Arkansas | D191: AR | E191: Arkansas Teacher Retirement System | F191: Star City School District | G191: 687 | H191: 1207060 | I191: 1
A192: 0500028 | B192: 2016 | C192: Arkansas | D192: AR | E192: Arkansas Teacher Retirement System | F192: Star City School District | G192: 687 | H192: 1222195 | I192: 1
A193: 0500028 | B193: 2017 | C193: Arkansas | D193: AR | E193: Arkansas Teacher Retirement System | F193: Star City School District | G193: 687 | H193: 1169845 | I193: 1
... A253: 0500034 | B253: 2023 | C253: Arkansas | D253: AR | E253: Arkansas Teacher Retirement System | F253: Crowley'S Ridge Educational Service Co-Op | G253: 1354 | H253: 865831 | I253: 0
A254: 0500035 | B254: 2015 | C254: Arkansas | D254: AR | E254: Arkansas Teacher Retirement System | F254: Arkansas School For The Blind | G254: 1-008 | H254: 494332 | I254: 0
A255: 0500035 | B255: 2016 | C255: Arkansas | D255: AR | E255: Arkansas Teacher Retirement System | F255: Arkansas School For The Blind | G255: 1-008 | H255: 541257 | I255: 0
A256: 0500035 | B256: 2017 | C256: Arkansas | D256: AR | E256: Arkansas Teacher Retirement System | F256: Arkansas School For The Blind | G256: 1-008 | H256: 540012 | I256: 0
A257: 0500035 | B257: 2018 | C257: Arkansas | D257: AR | E257: Arkansas Teacher Retirement System | F257: Arkansas School For The Blind | G257: 1-008 | H257: 532290 | I257: 0
...

Sheet Sheet1
A1: District | B1: LEAID
A2: Texarkana Career And Technological Center | B2: 500430
A3: Texarkana School District | B3: =IFERROR(VLOOKUP(A3,Sheet2!$A$2:$B$2336,2,FALSE),"") -> 513110
A4: Friendship Aspire - Southeast Pine Bluff | B4: 500427
A5: Friendship Aspire Academy - Pine Bluff | B5: 500423
A6: Lisa Academy Charter | B6: =IFERROR(VLOOKUP(A6,Sheet2!$A$2:$B$2336,2,FALSE),"") -> 500074
A7: Lisa Academy-North Little Rock | B7: 500399
A8: Arkansas Virtual Academy Charter | B8: 500394
A9: Dhs-Divison Of Youth Services | B9: 500390
A10: E-Stem Public Charter School | B10: 500398
A11: Yellville-Summit Public School | B11: 514490
A12: Wynne Public Schools | B12: 514430
A13: Woodlawn School District | B13: =IFERROR(VLOOKUP(A13,Sheet2!$A$2:$B$2336,2,FALSE),"") -> 514400
A14: Wonderview School District | B14: =IFERROR(VLOOKUP(A14,Sheet2!$A$2:$B$2336,2,FALSE),"") -> 514370
A15: White Hall School District | B15: =IFERROR(VLOOKUP(A15,Sheet2!$A$2:$B$2336,2,FALSE),"") -> 514140
A16: West Side School District | B16: =IFERROR(VLOOKUP(A16,Sheet2!$A$2:$B$2336,2,FALSE),"") -> 514040
A17: Westside School District | B17: =IFERROR(VLOOKUP(A17,Sheet2!$A$2:$B$2336,2,FALSE),"") -> 514020
A18: West Fork School District | B18: =IFERROR(VLOOKUP(A18,Sheet2!$A$2:$B$2336,2,FALSE),"") -> 514010
A19: Watson Chapel School District | B19: =IFERROR(VLOOKUP(A19,Sheet2!$A$2:$B$2336,2,FALSE),"") -> 513930
A20: Waldron Public Schools | B20: 513680
A21: Viola School District | B21: =IFERROR(VLOOKUP(A21,Sheet2!$A$2:$B$2336,2,FALSE),"") -> 513560
A22: Vilonia School District | B22: =IFERROR(VLOOKUP(A22,Sheet2!$A$2:$B$2336,2,FALSE),"") -> 513530
A23: Van Buren School District | B23: =IFERROR(VLOOKUP(A23,Sheet2!$A$2:$B$2336,2,FALSE),"") -> 513410
A24: Valley View Public Schools | B24: 513380
A25: Valley Springs Public Schools | B25: 513350
A26: Jackson County School District | B26: 513230
A27: Greene County Tech School District | B27: =IFERROR(VLOOKUP(A27,Sheet2!$A$2:$B$2336,2,FALSE),"") -> 513080
A28: Stuttgart School District | B28: =IFERROR(VLOOKUP(A28,Sheet2!$A$2:$B$2336,2,FALSE),"") -> 512960
A29: Strong-Huttig School District | B29: =IFERROR(VLOOKUP(A29,Sheet2!$A$2:$B$2336,2,FALSE),"") -> 512930
A30: Stephens School Dist | B30: 512870
A31: Springdale Public Schools | B31: 512660
A32: Spring Hill School District | B32: =IFERROR(VLOOKUP(A32,Sheet2!$A$2:$B$2336,2,FALSE),"") -> 512630
A33: Southside Bee Branch School District | B33: 512570
A34: Southside School District | B34: =IFERROR(VLOOKUP(A34,Sheet2!$A$2:$B$2336,2,FALSE),"") -> 512540
A35: South Conway County School District | B35: =IFERROR(VLOOKUP(A35,Sheet2!$A$2:$B$2336,2,FALSE),"") -> 512520
A36: Smackover-Norphlet School District | B36: =IFERROR(VLOOKUP(A36,Sheet2!$A$2:$B$2336,2,FALSE),"") -> 512510
A37: Sloan-Hendrix School District | B37: =IFERROR(VLOOKUP(A37,Sheet2!$A$2:$B$2336,2,FALSE),"") -> 512480
A38: Siloam Springs School District | B38: =IFERROR(VLOOKUP(A38,Sheet2!$A$2:$B$2336,2,FALSE),"") -> 512450
A39: Shirley School District | B39: =IFERROR(VLOOKUP(A39,Sheet2!$A$2:$B$2336,2,FALSE),"") -> 512420
A40: Searcy School District | B40: =IFERROR(VLOOKUP(A40,Sheet2!$A$2:$B$2336,2,FALSE),"") -> 512210
...

Sheet Sheet2
A1: NAME | B1: LEAID | F1: district_name
A2: ACADEMICS PLUS CHARTER SCHOOL | B2: 500059 | F2: Craighead County Sd Executive
A3: ACADEMICS PLUS CHARTER SCHOOL | B3: 500059 | F3: Northcentral Arkansas Education Service Co-Op
A4: ACADEMICS PLUS CHARTER SCHOOL | B4: 500059 | F4: Northeast Arkansas Education Co-Op
A5: ACADEMICS PLUS CHARTER SCHOOL | B5: 500059
A6: ACADEMICS PLUS CHARTER SCHOOL | B6: 500059 | F6: Jonesboro Vocational Center
A7: ACADEMICS PLUS CHARTER SCHOOL | B7: 500059 | F7: Monticello Vocational Center
A8: ACADEMICS PLUS CHARTER SCHOOL | B8: 500059 | F8: River Valley Career Academy
A9: ACADEMICS PLUS PUBLIC CHARTER SCHOOLS | B9: 500059 | F9: Metropolitan Vocational Center
A10: ALMA SCHOOL DISTRICT | B10: 502250 | F10: Warren Vocational Center
A11: ALMA SCHOOL DISTRICT | B11: 502250 | F11: Kipp Delta College Preparatory Charter
A12: ALMA SCHOOL DISTRICT | B12: 502250 | F12: Arkansas Activities Association
A13: ALMA SCHOOL DISTRICT | B13: 502250 | F13: Arkansas Easter Seals
A14: ALMA SCHOOL DISTRICT | B14: 502250 | F14: Arkansas School Boards Association
A15: ALMA SCHOOL DISTRICT | B15: 502250
A16: ALMA SCHOOL DISTRICT | B16: 502250 | F16: Arkansas Association Educational Administrators
A17: ALMA SCHOOL DISTRICT | B17: 502250 | F17: Economics Arkansas
A18: ALPENA SCHOOL DISTRICT | B18: 502280 | F18: Boston Mountain Educational Co-Op
A19: ALPENA SCHOOL DISTRICT | B19: 502280 | F19: Arkansas Department Of Education
A20: ARCH FORD EDUC. SERVICE COOP | B20: 500011 | F20: Arkansas Department Of Career Education (Rehab)
A21: ARCH FORD EDUC. SERVICE COOP | B21: 500011 | F21: Arkansas Teacher Retirement System
A22: ARK TECH UNIVERISTY CAREER CENTER | B22: 500436 | F22: Arkansas Educational Tv Network
A23: ARK. RIVER EDUC SERVICE COOP | B23: 500024 | F23: Crowleys Ridge Technical Institute
A24: ARK. RIVER EDUC SERVICE COOP | B24: 500024 | F24: Arkansas Department Of Career Education (Workforce)
A25: ARK. SCHOOL FOR THE BLIND | B25: 500035 | F25: Northwest Technical Institute
A26: ARK. SCHOOL FOR THE DEAF | B26: 500036 | F26: Riverside Vocational Technical School
A27: ARKADELPHIA SCHOOL DISTRICT | B27: 502430
A28: ARKADELPHIA SCHOOL DISTRICT | B28: 502430 | F28: South Arkansas Developmental Center
A29: ARKADELPHIA SCHOOL DISTRICT | B29: 502430 | F29: Arkansas School For Math, Sciences & Arts
A30: ARKADELPHIA SCHOOL DISTRICT | B30: 502430
A31: ARKADELPHIA SCHOOL DISTRICT | B31: 502430
A32: ARKADELPHIA SCHOOL DISTRICT | B32: 502430
A33: ARKANSAS CONNECTIONS ACADEMY | B33: 500417
A34: ARKANSAS CONNECTIONS ACADEMY | B34: 500417
A35: ARKANSAS CONNECTIONS ACADEMY | B35: 500417
A36: ARKANSAS CONNECTIONS ACADEMY | B36: 500417
A37: ARKANSAS CONNECTIONS ACADEMY | B37: 500417
A38: ARKANSAS CONNECTIONS ACADEMY | B38: 500417
A39: ARKANSAS CORRECTIONAL SCHOOLS | B39: 500025
A40: ARKANSAS CORRECTIONAL SCHOOLS | B40: 500025
...

Sheet Original Data
A1: year | B1: state | C1: state_abv | D1: plan | E1: district_name | F1: district_code | G1: employer_contributions
A2: 2015 | B2: Arkansas | C2: AR | D2: Arkansas Teacher Retirement System | E2: COTTER PUBLIC SCHOOLS | F2: 106 | G2: 492920
A3: 2015 | B3: Arkansas | C3: AR | D3: Arkansas Teacher Retirement System | E3: ROGERS PUBLIC SCHOOLS | F3: 108 | G3: 12187852
A4: 2015 | B4: Arkansas | C4: AR | D4: Arkansas Teacher Retirement System | E4: GRAVETTE SCHOOL DISTRICT | F4: 109 | G4: 1402514
A5: 2015 | B5: Arkansas | C5: AR | D5: Arkansas Teacher Retirement System | E5: SILOAM SPRINGS SCHOOL DISTRICT | F5: 110 | G5: 3100128
A6: 2015 | B6: Arkansas | C6: AR | D6: Arkansas Teacher Retirement System | E6: HERMITAGE PUBLIC SCHOOL DISTRI | F6: 111 | G6: 372194
A7: 2015 | B7: Arkansas | C7: AR | D7: Arkansas Teacher Retirement System | E7: WARREN SCHOOL DISTRICT | F7: 113 | G7: 1192643
A8: 2015 | B8: Arkansas | C8: AR | D8: Arkansas Teacher Retirement System | E8: BERRYVILLE PUBLIC SCHOOLS | F8: 115 | G8: 1427754
A9: 2015 | B9: Arkansas | C9: AR | D9: Arkansas Teacher Retirement System | E9: LAKESIDE SCHOOL DISTRICT | F9: 116 | G9: 1009247
A10: 2015 | B10: Arkansas | C10: AR | D10: Arkansas Teacher Retirement System | E10: GURDON PUBLIC SCHOOLS | F10: 117 | G10: 653823
A11: 2015 | B11: Arkansas | C11: AR | D11: Arkansas Teacher Retirement System | E11: ARKADELPHIA PUBLIC SCHOOLS | F11: 119 | G11: 1570438
A12: 2015 | B12: Arkansas | C12: AR | D12: Arkansas Teacher Retirement System | E12: WOODLAWN SCHOOL DISTRICT | F12: 121 | G12: 366949
A13: 2015 | B13: Arkansas | C13: AR | D13: Arkansas Teacher Retirement System | E13: MAGNOLIA SCHOOL DISTRICT | F13: 123 | G13: 2202665
... A135: 2015 | B135: Arkansas | C135: AR | D135: Arkansas Teacher Retirement System | E135: DIERKS PUBLIC SCHOOLS | F135: 566 | G135: 416639
A136: 2015 | B136: Arkansas | C136: AR | D136: Arkansas Teacher Retirement System | E136: STEPHENS SCHOOL DIST | F136: 568
A137: 2015 | B137: Arkansas | C137: AR | D137: Arkansas Teacher Retirement System | E137: POTTSVILLE SCHOOL DISTRICT | F137: 569 | G137: 1219725
A138: 2015 | B138: Arkansas | C138: AR | D138: Arkansas Teacher Retirement System | E138: PIGGOTT SCHOOL DISTRICT | F138: 571 | G138: 544904
A139: 2015 | B139: Arkansas | C139: AR | D139: Arkansas Teacher Retirement System | E139: HECTOR SCHOOL DISTRICT | F139: 583 | G139: 421593
A140: 2015 | B140: Arkansas | C140: AR | D140: Arkansas Teacher Retirement System | E140: BLYTHEVILLE PUBLIC SCHOOLS | F140: 586 | G140: 2029748
A141: 2015 | B141: Arkansas | C141: AR | D141: Arkansas Teacher Retirement System | E141: BEARDEN SCHOOL DISTRICT | F141: 592 | G141: 396437
A142: 2015 | B142: Arkansas | C142: AR | D142: Arkansas Teacher Retirement System | E142: PINE BLUFF SCHOOL DISTRICT | F142: 593 | G142: 3875632
A143: 2015 | B143: Arkansas | C143: AR | D143: Arkansas Teacher Retirement System | E143: MARMADUKE SCHOOL DISTRICT | F143: 597 | G143: 565315
A144: 2015 | B144: Arkansas | C144: AR | D144: Arkansas Teacher Retirement System | E144: FOUKE SCHOOL DISTRICT | F144: 601 | G144: 786347
A145: 2015 | B145: Arkansas | C145: AR | D145: Arkansas Teacher Retirement System | E145: HORATIO SCHOOL DISTRICT | F145: 602 | G145: 637724
A146: 2015 | B146: Arkansas | C146: AR | D146: Arkansas Teacher Retirement System | E146: ENGLAND PUBLIC SCHOOL DISTRICT | F146: 606 | G146: 559643
A147: 2015 | B147: Arkansas | C147: AR | D147: Arkansas Teacher Retirement System | E147: JASPER SCHOOL DISTRICT | F147: 607 | G147: 829629
A148: 2015 | B148: Arkansas | C148: AR | D148: Arkansas Teacher Retirement System | E148: TRUMANN SCHOOL DISTRICT | F148: 608 | G148: 1138480
... A201: 2015 | B201: Arkansas | C201: AR | D201: Arkansas Teacher Retirement System | E201: GENOA CENTRAL SCHOOL DISTRICT | F201: 873 | G201: 725999
A202: 2015 | B202: Arkansas | C202: AR | D202: Arkansas Teacher Retirement System | E202: NORPHLET SCHOOL DIST | F202: 876
A203: 2015 | B203: Arkansas | C203: AR | D203: Arkansas Teacher Retirement System | E203: BERGMAN PUBLIC SCHOOLS | F203: 956 | G203: 731640
A204: 2015 | B204: Arkansas | C204: AR | D204: Arkansas Teacher Retirement System | E204: LEAD HILL SCHOOL DISTRICT | F204: 957 | G204: 275274
A205: 2015 | B205: Arkansas | C205: AR | D205: Arkansas Teacher Retirement System | E205: DERMOTT SCHOOL DISTRICT | F205: 958 | G205: 419278
A206: 2015 | B206: Arkansas | C206: AR | D206: Arkansas Teacher Retirement System | E206: GUY-PERKINS SCHOOL DISTRICT | F206: 963 | G206: 356185
A207: 2015 | B207: Arkansas | C207: AR | D207: Arkansas Teacher Retirement System | E207: MT. VERNON-ENOLA SCHOOL DISTRI | F207: 964 | G207: 377990
A208: 2015 | B208: Arkansas | C208: AR | D208: Arkansas Teacher Retirement System | E208: MOUNTAIN PINE SCHOOL DISTRICT | F208: 965 | G208: 366894
A209: 2015 | B209: Arkansas | C209: AR | D209: Arkansas Teacher Retirement System | E209: ARMOREL SCHOOL DISTRICT | F209: 973 | G209: 353021
A210: 2015 | B210: Arkansas | C210: AR | D210: Arkansas Teacher Retirement System | E210: WHITE COUNTY CENTRAL SCHOOLS | F210: 987 | G210: 530099
A211: 2015 | B211: Arkansas | C211: AR | D211: Arkansas Teacher Retirement System | E211: CRAIGHEAD COUNTY SD EXECUTIVE | F211: 990 | G211: 6340
A212: 2015 | B212: Arkansas | C212: AR | D212: Arkansas Teacher Retirement System | E212: LAFAYETTE COUNTY SCHOOL DISTRI | F212: 1000 | G212: 557568
A213: 2015 | B213: Arkansas | C213: AR | D213: Arkansas Teacher Retirement System | E213: CEDAR RIDGE SCHOOL DISTRICT | F213: 1001 | G213: 794975
...

Sheet Included Employers
A1: Unique Included Employers | B1: Unique Included IDs
A2: Cotter Public Schools | B2: 106
A3: Rogers Public Schools | B3: 108
A4: Gravette School District | B4: 109
A5: Siloam Springs School District | B5: 110
A6: Hermitage Public School District | B6: 111
A7: Warren School District | B7: 113
A8: Berryville Public Schools | B8: 115
A9: Lakeside School District 1 | B9: 116
A10: Gurdon Public Schools | B10: 117
A11: Arkadelphia Public Schools | B11: 119
A12: Woodlawn School District | B12: 121
A13: Magnolia School District | B13: 123
... A276: Premier High School Of Springdale | B276: 2044

Sheet Excluded Employers
A1: Unique Excluded Employers | B1: Unique Excluded IDs
A2: Southwest Arkansas Education Co-Op | B2: 1307
A3: Southeast Arkansas Education Service Co-Op | B3: 1308
A4: Guy Fenter Education Service Co-Op | B4: 1330
A5: Northcentral Arkansas Education Service Co-Op | B5: 1332
A6: Ozarks Unlimited Resource Educational Service Co-Op | B6: 1336
A7: Northeast Arkansas Education Co-Op | B7: 1337
A8: Dawson Education Service Co-Op | B8: 1338
A9: Arch Ford Education Service Co-Op | B9: 1339
A10: Wilbur D Mills Education Service Co-Op | B10: 1345
A11: Arkansas River Education Service Co-Op | B11: 1349
A12: Great Rivers Education Service Co-Op | B12: 1350
A13: Northwest Arkansas Education Service Co-Op | B13: 1351
... A31: Boston Mountain Educational Co-Op | B31: 9492
A32: University Of Arkansas - Monticello | B32: 1-005
A33: University Of Arkansas - Pine Bluff | B33: 1-006
A34: Arkansas School For The Blind | B34: 1-008
A35: Arkansas School For The Deaf | B35: 1-016
A36: Arkansas Department Of Education | B36: 1-017
A37: Henderson State University | B37: 1-025
A38: Arkansas State University- Beebe | B38: 1-028
A39: Arkansas State University- Newport | B39: 1-029
A40: Arkansas Tech University | B40: 1-045
A41: Southern Arkansas University | B41: 1-051
A42: Arkansas State University- Mt. Home | B42: 1-052
A43: Arkansas State University | B43: 1-053
... A87: Arkansas Department Of Health | B87: 1-409
