Workbook

Sheet Final Data
A1: LEAID | B1: Year | D1: employer_code | F1: standardized_employer_name | G1: employer_name | H1: county_name | I1: employer_contributions | J1: proportionate_share | K1: LEAID_match
A2: =K2 -> 3900305 | B2: 2015 | C2: =F2 -> A PLUS ARTS ACADEMY | D2: D023 | E2: =D2&F2 -> D023A PLUS ARTS ACADEMY | F2: A PLUS ARTS ACADEMY | G2: A PLUS ARTS ACADEMY | H2: FRANKLIN | I2: 198080.75 | J2: 0.0001356099 | K2: =IFERROR(VLOOKUP(E2,Sheet1!$D$2:$E$1226,2,FALSE),"") -> 3900305
A3: =K3 -> 3900305 | B3: 2016 | C3: =F3 -> A PLUS ARTS ACADEMY | D3: D023 | E3: =D3&F3 -> D023A PLUS ARTS ACADEMY | F3: A PLUS ARTS ACADEMY | G3: A PLUS ARTS ACADEMY | H3: FRANKLIN | I3: 302711.77 | J3: 0.0002054973 | K3: =IFERROR(VLOOKUP(E3,Sheet1!$D$2:$E$1226,2,FALSE),"") -> 3900305
A4: =K4 -> 3900305 | B4: 2017 | C4: =F4 -> A PLUS ARTS ACADEMY | D4: D023 | E4: =D4&F4 -> D023A PLUS ARTS ACADEMY | F4: A PLUS ARTS ACADEMY | G4: A PLUS ARTS ACADEMY | H4: FRANKLIN | I4: 309914.72 | J4: 0.0002013573 | K4: =IFERROR(VLOOKUP(E4,Sheet1!$D$2:$E$1226,2,FALSE),"") -> 3900305
A5: =K5 -> 3900305 | B5: 2018 | C5: =F5 -> A PLUS ARTS ACADEMY | D5: D023 | E5: =D5&F5 -> D023A PLUS ARTS ACADEMY | F5: A PLUS ARTS ACADEMY | G5: A PLUS ARTS ACADEMY | H5: FRANKLIN | I5: 355814.7 | J5: 0.0002235629 | K5: =IFERROR(VLOOKUP(E5,Sheet1!$D$2:$E$1226,2,FALSE),"") -> 3900305
A6: =K6 -> 3900305 | B6: 2019 | C6: =F6 -> A PLUS ARTS ACADEMY | D6: D023 | E6: =D6&F6 -> D023A PLUS ARTS ACADEMY | F6: A PLUS ARTS ACADEMY | G6: A PLUS ARTS ACADEMY | H6: FRANKLIN | I6: 392674.9 | J6: 0.0002389036 | K6: =IFERROR(VLOOKUP(E6,Sheet1!$D$2:$E$1226,2,FALSE),"") -> 3900305
A7: =K7 -> 3900305 | B7: 2020 | C7: =F7 -> A PLUS ARTS ACADEMY | D7: D023 | E7: =D7&F7 -> D023A PLUS ARTS ACADEMY | F7: A PLUS ARTS ACADEMY | G7: A PLUS ARTS ACADEMY | H7: FRANKLIN | I7: 380394.49 | J7: 0.0002251413 | K7: =IFERROR(VLOOKUP(E7,Sheet1!$D$2:$E$1226,2,FALSE),"") -> 3900305
A8: =K8 -> 3900305 | B8: 2021 | C8: =F8 -> A PLUS ARTS ACADEMY | D8: D023 | E8: =D8&F8 -> D023A PLUS ARTS ACADEMY | F8: A PLUS ARTS ACADEMY | G8: A PLUS ARTS ACADEMY | H8: FRANKLIN | I8: 315729.03 | J8: 0.00018276556 | K8: =IFERROR(VLOOKUP(E8,Sheet1!$D$2:$E$1226,2,FALSE),"") -> 3900305
A9: =K9 -> 3900305 | B9: 2022 | C9: =F9 -> A PLUS ARTS ACADEMY | D9: D023 | E9: =D9&F9 -> D023A PLUS ARTS ACADEMY | F9: A PLUS ARTS ACADEMY | G9: A PLUS ARTS ACADEMY | H9: FRANKLIN | I9: 307994.25 | J9: 0.0001692214 | K9: =IFERROR(VLOOKUP(E9,Sheet1!$D$2:$E$1226,2,FALSE),"") -> 3900305
A10: =K10 -> 3900305 | B10: 2023 | C10: =F10 -> A PLUS ARTS ACADEMY | D10: D023 | E10: =D10&F10 -> D023A PLUS ARTS ACADEMY | F10: A PLUS ARTS ACADEMY | G10: A PLUS ARTS ACADEMY | H10: FRANKLIN | I10: 305394.51 | J10: 0.0001615026 | K10: =IFERROR(VLOOKUP(E10,Sheet1!$D$2:$E$1226,2,FALSE),"") -> 3900305
A11: =K11 -> 3901480 | B11: 2015 | C11: =F11 -> A-PLUS CHILDRENS ACADEMY | D11: D336 | E11: =D11&F11 -> D336A-PLUS CHILDRENS ACADEMY | F11: A-PLUS CHILDRENS ACADEMY | G11: A-PLUS CHILDRENS ACADEMY | H11: FRANKLIN | I11: 42665.7 | J11: 2.92098e-05 | K11: =IFERROR(VLOOKUP(E11,Sheet1!$D$2:$E$1226,2,FALSE),"") -> 3901480
A12: =K12 -> 3901480 | B12: 2016 | C12: =F12 -> A-PLUS CHILDRENS ACADEMY | D12: D336 | E12: =D12&F12 -> D336A-PLUS CHILDRENS ACADEMY | F12: A-PLUS CHILDRENS ACADEMY | G12: A-PLUS CHILDRENS ACADEMY | H12: FRANKLIN | I12: 48341.21 | J12: 3.28167e-05 | K12: =IFERROR(VLOOKUP(E12,Sheet1!$D$2:$E$1226,2,FALSE),"") -> 3901480
A13: =K13 -> 3901480 | B13: 2017 | C13: =F13 -> A-PLUS CHILDRENS ACADEMY | D13: D336 | E13: =D13&F13 -> D336A-PLUS CHILDRENS ACADEMY | F13: A-PLUS CHILDRENS ACADEMY | G13: A-PLUS CHILDRENS ACADEMY | H13: FRANKLIN | I13: 60163.92 | J13: 3.90896e-05 | K13: =IFERROR(VLOOKUP(E13,Sheet1!$D$2:$E$1226,2,FALSE),"") -> 3901480
... A3993: =K3993 -> 3900444 | B3993: 2023 | C3993: =F3993 -> HORIZON SCI ACAD DOWNTOWN DAYTON | D3993: D248 | E3993: =D3993&F3993 -> D248HORIZON SCI ACAD DOWNTOWN DAYTON | F3993: HORIZON SCI ACAD DOWNTOWN DAYTON | G3993: HORIZON SCI ACAD DOWNTOWN DAYTON | H3993: MONTGOMERY | I3993: 219853.91 | J3993: 0.000116266 | K3993: =IFERROR(VLOOKUP(E3993,Sheet1!$D$2:$E$1226,2,FALSE),"") -> 3900444
A3994: =K3994 -> 3901390 | B3994: 2015 | C3994: =F3994 -> HORIZON SCI ACAD TOLEDO DOWNTOWN | D3994: D235 | E3994: =D3994&F3994 -> D235HORIZON SCI ACAD TOLEDO DOWNTOWN | F3994: HORIZON SCI ACAD TOLEDO DOWNTOWN | G3994: HORIZON SCI ACAD TOLEDO DOWNTOWN | I3994: 11474.86 | J3994: 7.8559e-06 | K3994: =IFERROR(VLOOKUP(E3994,Sheet1!$D$2:$E$1226,2,FALSE),"") -> 3901390
A3995: =K3995 -> 3901322 | B3995: 2015 | C3995: =F3995 -> HORIZON SCIENCE ACAD - COLS MIDDLE SCH | D3995: D179 | E3995: =D3995&F3995 -> D179HORIZON SCIENCE ACAD - COLS MIDDLE SCH | F3995: HORIZON SCIENCE ACAD - COLS MIDDLE SCH | G3995: HORIZON SCIENCE ACAD - COLS MIDDLE SCH | H3995: FRANKLIN | I3995: 204782.84 | J3995: 0.0001401983 | K3995: =IFERROR(VLOOKUP(E3995,Sheet1!$D$2:$E$1226,2,FALSE),"") -> 3901322
A3996: =K3996 -> 3901322 | B3996: 2016 | C3996: =F3996 -> HORIZON SCIENCE ACAD - COLS MIDDLE SCH | D3996: D179 | E3996: =D3996&F3996 -> D179HORIZON SCIENCE ACAD - COLS MIDDLE SCH | F3996: HORIZON SCIENCE ACAD - COLS MIDDLE SCH | G3996: HORIZON SCIENCE ACAD - COLS MIDDLE SCH | H3996: FRANKLIN | I3996: 244360.32 | J3996: 0.0001658852 | K3996: =IFERROR(VLOOKUP(E3996,Sheet1!$D$2:$E$1226,2,FALSE),"") -> 3901322
A3997: =K3997 -> 3901322 | B3997: 2017 | C3997: =F3997 -> HORIZON SCIENCE ACAD - COLS MIDDLE SCH | D3997: D179 | E3997: =D3997&F3997 -> D179HORIZON SCIENCE ACAD - COLS MIDDLE SCH | F3997: HORIZON SCIENCE ACAD - COLS MIDDLE SCH | G3997: HORIZON SCIENCE ACAD - COLS MIDDLE SCH | H3997: FRANKLIN | I3997: 265492.42 | J3997: 0.0001724953 | K3997: =IFERROR(VLOOKUP(E3997,Sheet1!$D$2:$E$1226,2,FALSE),"") -> 3901322
A3998: =K3998 -> 3901322 | B3998: 2018 | C3998: =F3998 -> HORIZON SCIENCE ACAD - COLS MIDDLE SCH | D3998: D179 | E3998: =D3998&F3998 -> D179HORIZON SCIENCE ACAD - COLS MIDDLE SCH | F3998: HORIZON SCIENCE ACAD - COLS MIDDLE SCH | G3998: HORIZON SCIENCE ACAD - COLS MIDDLE SCH | H3998: FRANKLIN | I3998: 281702.18 | J3998: 0.0001769971 | K3998: =IFERROR(VLOOKUP(E3998,Sheet1!$D$2:$E$1226,2,FALSE),"") -> 3901322
A3999: =K3999 -> 3901322 | B3999: 2019 | C3999: =F3999 -> HORIZON SCIENCE ACAD - COLS MIDDLE SCH | D3999: D179 | E3999: =D3999&F3999 -> D179HORIZON SCIENCE ACAD - COLS MIDDLE SCH | F3999: HORIZON SCIENCE ACAD - COLS MIDDLE SCH | G3999: HORIZON SCIENCE ACAD - COLS MIDDLE SCH | H3999: FRANKLIN | I3999: 289361.7 | J3999: 0.0001760478 | K3999: =IFERROR(VLOOKUP(E3999,Sheet1!$D$2:$E$1226,2,FALSE),"") -> 3901322
A4000: =K4000 -> 3901322 | B4000: 2020 | C4000: =F4000 -> HORIZON SCIENCE ACAD - COLS MIDDLE SCH | D4000: D179 | E4000: =D4000&F4000 -> D179HORIZON SCIENCE ACAD - COLS MIDDLE SCH | F4000: HORIZON SCIENCE ACAD - COLS MIDDLE SCH | G4000: HORIZON SCIENCE ACAD - COLS MIDDLE SCH | H4000: FRANKLIN | I4000: 314978.77 | J4000: 0.0001864242 | K4000: =IFERROR(VLOOKUP(E4000,Sheet1!$D$2:$E$1226,2,FALSE),"") -> 3901322
A4001: =K4001 -> 3901322 | B4001: 2021 | C4001: =F4001 -> HORIZON SCIENCE ACAD - COLS MIDDLE SCH | D4001: D179 | E4001: =D4001&F4001 -> D179HORIZON SCIENCE ACAD - COLS MIDDLE SCH | F4001: HORIZON SCIENCE ACAD - COLS MIDDLE SCH | G4001: HORIZON SCIENCE ACAD - COLS MIDDLE SCH | H4001: FRANKLIN | I4001: 306348.18 | J4001: 0.00017733529 | K4001: =IFERROR(VLOOKUP(E4001,Sheet1!$D$2:$E$1226,2,FALSE),"") -> 3901322
A4002: =K4002 -> 3901322 | B4002: 2022 | C4002: =F4002 -> HORIZON SCIENCE ACAD - COLS MIDDLE SCH | D4002: D179 | E4002: =D4002&F4002 -> D179HORIZON SCIENCE ACAD - COLS MIDDLE SCH | F4002: HORIZON SCIENCE ACAD - COLS MIDDLE SCH | G4002: HORIZON SCIENCE ACAD - COLS MIDDLE SCH | H4002: FRANKLIN | I4002: 396139.23 | J4002: 0.0002176509 | K4002: =IFERROR(VLOOKUP(E4002,Sheet1!$D$2:$E$1226,2,FALSE),"") -> 3901322
A4003: =K4003 -> 3901322 | B4003: 2023 | C4003: =F4003 -> HORIZON SCIENCE ACAD - COLS MIDDLE SCH | D4003: D179 | E4003: =D4003&F4003 -> D179HORIZON SCIENCE ACAD - COLS MIDDLE SCH | F4003: HORIZON SCIENCE ACAD - COLS MIDDLE SCH | G4003: HORIZON SCIENCE ACAD - COLS MIDDLE SCH | H4003: FRANKLIN | I4003: 417131.5 | J4003: 0.0002205928 | K4003: =IFERROR(VLOOKUP(E4003,Sheet1!$D$2:$E$1226,2,FALSE),"") -> 3901322
A4004: =K4004 -> 3901353 | B4004: 2015 | C4004: =F4004 -> HORIZON SCIENCE ACAD-ELEMENTARY SCH | D4004: D206 | E4004: =D4004&F4004 -> D206HORIZON SCIENCE ACAD-ELEMENTARY SCH | F4004: HORIZON SCIENCE ACAD-ELEMENTARY SCH | G4004: HORIZON SCIENCE ACAD-ELEMENTARY SCH | H4004: FRANKLIN | I4004: 226865.46 | J4004: 0.0001553165 | K4004: =IFERROR(VLOOKUP(E4004,Sheet1!$D$2:$E$1226,2,FALSE),"") -> 3901353
A4005: =K4005 -> 3901353 | B4005: 2016 | C4005: =F4005 -> HORIZON SCIENCE ACAD-ELEMENTARY SCH | D4005: D206 | E4005: =D4005&F4005 -> D206HORIZON SCIENCE ACAD-ELEMENTARY SCH | F4005: HORIZON SCIENCE ACAD-ELEMENTARY SCH | G4005: HORIZON SCIENCE ACAD-ELEMENTARY SCH | H4005: FRANKLIN | I4005: 271084.89 | J4005: 0.0001840273 | K4005: =IFERROR(VLOOKUP(E4005,Sheet1!$D$2:$E$1226,2,FALSE),"") -> 3901353
A4006: =K4006 -> 3901353 | B4006: 2017 | C4006: =F4006 -> HORIZON SCIENCE ACAD-ELEMENTARY SCH | D4006: D206 | E4006: =D4006&F4006 -> D206HORIZON SCIENCE ACAD-ELEMENTARY SCH | F4006: HORIZON SCIENCE ACAD-ELEMENTARY SCH | G4006: HORIZON SCIENCE ACAD-ELEMENTARY SCH | H4006: FRANKLIN | I4006: 293123.86 | J4006: 0.000190448 | K4006: =IFERROR(VLOOKUP(E4006,Sheet1!$D$2:$E$1226,2,FALSE),"") -> 3901353
... A6659: =K6659 -> 3904457 | B6659: 2023 | C6659: =F6659 -> NORWOOD CITY SCHOOLS | D6659: C179 | E6659: =D6659&F6659 -> C179NORWOOD CITY SCHOOLS | F6659: NORWOOD CITY SCHOOLS | G6659: NORWOOD CITY SCHOOLS | H6659: HAMILTON | I6659: 2055185.1 | J6659: 0.0010868492 | K6659: =IFERROR(VLOOKUP(E6659,Sheet1!$D$2:$E$1226,2,FALSE),"") -> 3904457
A6660: =K6660 -> 3901402 | B6660: 2017 | C6660: =F6660 -> NOTTEN SCHOOL FOR STEM | D6660: D249 | E6660: =D6660&F6660 -> D249NOTTEN SCHOOL FOR STEM | F6660: NOTTEN SCHOOL FOR STEM | G6660: NOTTEN SCHOOL FOR STEM | I6660: 5657.29 | J6660: 3.6756e-06 | K6660: =IFERROR(VLOOKUP(E6660,Sheet1!$D$2:$E$1226,2,FALSE),"") -> 3901402
A6661: =K6661 -> 3904776 | B6661: 2015 | C6661: =F6661 -> OAK HILL UNION LOCAL SCHOOLS | D6661: 4011 | E6661: =D6661&F6661 -> 4011OAK HILL UNION LOCAL SCHOOLS | F6661: OAK HILL UNION LOCAL SCHOOLS | G6661: OAK HILL UNION LOCAL SCHOOLS | H6661: JACKSON | I6661: 696320.65 | J6661: 0.0004767147 | K6661: =IFERROR(VLOOKUP(E6661,Sheet1!$D$2:$E$1226,2,FALSE),"") -> 3904776
A6662: =K6662 -> 3904776 | B6662: 2016 | C6662: =F6662 -> OAK HILL UNION LOCAL SCHOOLS | D6662: 4011 | E6662: =D6662&F6662 -> 4011OAK HILL UNION LOCAL SCHOOLS | F6662: OAK HILL UNION LOCAL SCHOOLS | G6662: OAK HILL UNION LOCAL SCHOOLS | H6662: JACKSON | I6662: 652763.24 | J6662: 0.0004431315 | K6662: =IFERROR(VLOOKUP(E6662,Sheet1!$D$2:$E$1226,2,FALSE),"") -> 3904776
A6663: =K6663 -> 3904776 | B6663: 2017 | C6663: =F6663 -> OAK HILL UNION LOCAL SCHOOLS | D6663: 4011 | E6663: =D6663&F6663 -> 4011OAK HILL UNION LOCAL SCHOOLS | F6663: OAK HILL UNION LOCAL SCHOOLS | G6663: OAK HILL UNION LOCAL SCHOOLS | H6663: JACKSON | I6663: 745607.17 | J6663: 0.0004844347 | K6663: =IFERROR(VLOOKUP(E6663,Sheet1!$D$2:$E$1226,2,FALSE),"") -> 3904776
A6664: =K6664 -> 3904776 | B6664: 2018 | C6664: =F6664 -> OAK HILL UNION LOCAL SCHOOLS | D6664: 4011 | E6664: =D6664&F6664 -> 4011OAK HILL UNION LOCAL SCHOOLS | F6664: OAK HILL UNION LOCAL SCHOOLS | G6664: OAK HILL UNION LOCAL SCHOOLS | H6664: JACKSON | I6664: 772904.09 | J6664: 0.0004856256 | K6664: =IFERROR(VLOOKUP(E6664,Sheet1!$D$2:$E$1226,2,FALSE),"") -> 3904776
A6665: =K6665 -> 3904776 | B6665: 2019 | C6665: =F6665 -> OAK HILL UNION LOCAL SCHOOLS | D6665: 4011 | E6665: =D6665&F6665 -> 4011OAK HILL UNION LOCAL SCHOOLS | F6665: OAK HILL UNION LOCAL SCHOOLS | G6665: OAK HILL UNION LOCAL SCHOOLS | H6665: JACKSON | I6665: 822253.13 | J6665: 0.0005002592 | K6665: =IFERROR(VLOOKUP(E6665,Sheet1!$D$2:$E$1226,2,FALSE),"") -> 3904776
A6666: =K6666 -> 3904776 | B6666: 2020 | C6666: =F6666 -> OAK HILL UNION LOCAL SCHOOLS | D6666: 4011 | E6666: =D6666&F6666 -> 4011OAK HILL UNION LOCAL SCHOOLS | F6666: OAK HILL UNION LOCAL SCHOOLS | G6666: OAK HILL UNION LOCAL SCHOOLS | H6666: JACKSON | I6666: 838757.76 | J6666: 0.0004964294 | K6666: =IFERROR(VLOOKUP(E6666,Sheet1!$D$2:$E$1226,2,FALSE),"") -> 3904776
A6667: =K6667 -> 3904776 | B6667: 2021 | C6667: =F6667 -> OAK HILL UNION LOCAL SCHOOLS | D6667: 4011 | E6667: =D6667&F6667 -> 4011OAK HILL UNION LOCAL SCHOOLS | F6667: OAK HILL UNION LOCAL SCHOOLS | G6667: OAK HILL UNION LOCAL SCHOOLS | H6667: JACKSON | I6667: 879601.21 | J6667: 0.00050917336 | K6667: =IFERROR(VLOOKUP(E6667,Sheet1!$D$2:$E$1226,2,FALSE),"") -> 3904776
A6668: =K6668 -> 3904776 | B6668: 2022 | C6668: =F6668 -> OAK HILL UNION LOCAL SCHOOLS | D6668: 4011 | E6668: =D6668&F6668 -> 4011OAK HILL UNION LOCAL SCHOOLS | F6668: OAK HILL UNION LOCAL SCHOOLS | G6668: OAK HILL UNION LOCAL SCHOOLS | H6668: JACKSON | I6668: 917422.25 | J6668: 0.0005040597 | K6668: =IFERROR(VLOOKUP(E6668,Sheet1!$D$2:$E$1226,2,FALSE),"") -> 3904776
A6669: =K6669 -> 3904776 | B6669: 2023 | C6669: =F6669 -> OAK HILL UNION LOCAL SCHOOLS | D6669: 4011 | E6669: =D6669&F6669 -> 4011OAK HILL UNION LOCAL SCHOOLS | F6669: OAK HILL UNION LOCAL SCHOOLS | G6669: OAK HILL UNION LOCAL SCHOOLS | H6669: JACKSON | I6669: 943539.94 | J6669: 0.0004989748 | K6669: =IFERROR(VLOOKUP(E6669,Sheet1!$D$2:$E$1226,2,FALSE),"") -> 3904776
A6670: =K6670 -> 3904737 | B6670: 2015 | C6670: =F6670 -> OAK HILLS LOCAL SCHOOLS | D6670: 3113 | E6670: =D6670&F6670 -> 3113OAK HILLS LOCAL SCHOOLS | F6670: OAK HILLS LOCAL SCHOOLS | G6670: OAK HILLS LOCAL SCHOOLS | H6670: HAMILTON | I6670: 4955442.1 | J6670: 0.0033925921 | K6670: =IFERROR(VLOOKUP(E6670,Sheet1!$D$2:$E$1226,2,FALSE),"") -> 3904737
A6671: =K6671 -> 3904737 | B6671: 2016 | C6671: =F6671 -> OAK HILLS LOCAL SCHOOLS | D6671: 3113 | E6671: =D6671&F6671 -> 3113OAK HILLS LOCAL SCHOOLS | F6671: OAK HILLS LOCAL SCHOOLS | G6671: OAK HILLS LOCAL SCHOOLS | H6671: HAMILTON | I6671: 4986740.7 | J6671: 0.0033852729 | K6671: =IFERROR(VLOOKUP(E6671,Sheet1!$D$2:$E$1226,2,FALSE),"") -> 3904737
...

Sheet Sheet1
A1: standardized_employer_name | B1: standardized_employer_name | C1: standardized_employer_name | E1: LEAID | F1: count
A2: A PLUS ARTS ACADEMY | B2: =VLOOKUP(A2,'Final Data'!$C$2:$D$10283,2,FALSE) -> D023 | C2: A PLUS ARTS ACADEMY | D2: D023A PLUS ARTS ACADEMY | E2: 3900305 | F2: =COUNTIF($E$2:$E$1226,E2) -> 1
A3: A-PLUS CHILDRENS ACADEMY | B3: =VLOOKUP(A3,'Final Data'!$C$2:$D$10283,2,FALSE) -> D336 | C3: A-PLUS CHILDRENS ACADEMY | D3: D336A-PLUS CHILDRENS ACADEMY | E3: 3901480 | F3: =COUNTIF($E$2:$E$1226,E3) -> 1
A4: ACADEMY FOR URBAN SCHOLARS | B4: =VLOOKUP(A4,'Final Data'!$C$2:$D$10283,2,FALSE) -> D287 | C4: ACADEMY FOR URBAN SCHOLARS | D4: D287ACADEMY FOR URBAN SCHOLARS | F4: =COUNTIF($E$2:$E$1226,E4) -> 0
A5: ACADEMY FOR URBAN SCHOLARS YNGSTWN | B5: =VLOOKUP(A5,'Final Data'!$C$2:$D$10283,2,FALSE) -> D354 | C5: ACADEMY FOR URBAN SCHOLARS YNGSTWN | D5: D354ACADEMY FOR URBAN SCHOLARS YNGSTWN | E5: 3901472 | F5: =COUNTIF($E$2:$E$1226,E5) -> 1
A6: ACCELERATED ACHV ACAD OF CINCINNATI | B6: =VLOOKUP(A6,'Final Data'!$C$2:$D$10283,2,FALSE) -> D292 | C6: ACCELERATED ACHV ACAD OF CINCINNATI | D6: D292ACCELERATED ACHV ACAD OF CINCINNATI | E6: 3901460 | F6: =COUNTIF($E$2:$E$1226,E6) -> 1
A7: ACCLRTD ACHIEV ACAD OF N CINCINNATI | B7: =VLOOKUP(A7,'Final Data'!$C$2:$D$10283,2,FALSE) -> D299 | C7: ACCLRTD ACHIEV ACAD OF N CINCINNATI | D7: D299ACCLRTD ACHIEV ACAD OF N CINCINNATI | E7: 3901440 | F7: =COUNTIF($E$2:$E$1226,E7) -> 1
A8: ACHIEVE CAREER PREP ACADEMY | B8: =VLOOKUP(A8,'Final Data'!$C$2:$D$10283,2,FALSE) -> D217 | C8: ACHIEVE CAREER PREP ACADEMY | D8: D217ACHIEVE CAREER PREP ACADEMY | E8: 3901362 | F8: =COUNTIF($E$2:$E$1226,E8) -> 1
A9: ACHIEVEPOINT CAREER ACADEMY | B9: =VLOOKUP(A9,'Final Data'!$C$2:$D$10283,2,FALSE) -> D443 | C9: ACHIEVEPOINT CAREER ACADEMY | D9: D443ACHIEVEPOINT CAREER ACADEMY | F9: =COUNTIF($E$2:$E$1226,E9) -> 0
A10: ACHIEVEPOINT CAREER ACADEMY CINCINNATI | B10: =VLOOKUP(A10,'Final Data'!$C$2:$D$10283,2,FALSE) -> D444 | C10: ACHIEVEPOINT CAREER ACADEMY CINCINNATI | D10: D444ACHIEVEPOINT CAREER ACADEMY CINCINNATI | E10: 3901602 | F10: =COUNTIF($E$2:$E$1226,E10) -> 1
A11: ADA EXEMPTED VILLAGE SCHOOLS | B11: =VLOOKUP(A11,'Final Data'!$C$2:$D$10283,2,FALSE) -> 9001 | C11: ADA EXEMPTED VILLAGE SCHOOLS | D11: 9001ADA EXEMPTED VILLAGE SCHOOLS | E11: 3904518 | F11: =COUNTIF($E$2:$E$1226,E11) -> 1
A12: ADAMS COUNTY-OHIO VALLEY LOCAL SCH | B12: =VLOOKUP(A12,'Final Data'!$C$2:$D$10283,2,FALSE) -> 0106 | C12: ADAMS COUNTY-OHIO VALLEY LOCAL SCH | D12: 0106ADAMS COUNTY-OHIO VALLEY LOCAL SCH | E12: 3906190 | F12: =COUNTIF($E$2:$E$1226,E12) -> 1
A13: ADENA LOCAL SCHOOLS | B13: =VLOOKUP(A13,'Final Data'!$C$2:$D$10283,2,FALSE) -> 7102 | C13: ADENA LOCAL SCHOOLS | D13: 7102ADENA LOCAL SCHOOLS | E13: 3904949 | F13: =COUNTIF($E$2:$E$1226,E13) -> 1
A14: AKRON CAREER TECH HIGH SCHOOL | B14: =VLOOKUP(A14,'Final Data'!$C$2:$D$10283,2,FALSE) -> D477 | C14: AKRON CAREER TECH HIGH SCHOOL | D14: D477AKRON CAREER TECH HIGH SCHOOL | F14: =COUNTIF($E$2:$E$1226,E14) -> 0
A15: AKRON DIGITAL ACADEMY | B15: =VLOOKUP(A15,'Final Data'!$C$2:$D$10283,2,FALSE) -> 9751 | C15: AKRON DIGITAL ACADEMY | D15: 9751AKRON DIGITAL ACADEMY | E15: 3900152 | F15: =COUNTIF($E$2:$E$1226,E15) -> 1
A16: AKRON PREPARATORY SCHOOL | B16: =VLOOKUP(A16,'Final Data'!$C$2:$D$10283,2,FALSE) -> D344 | C16: AKRON PREPARATORY SCHOOL | D16: D344AKRON PREPARATORY SCHOOL | E16: 3901503 | F16: =COUNTIF($E$2:$E$1226,E16) -> 1
A17: AKRON PUBLIC SCHOOLS | B17: =VLOOKUP(A17,'Final Data'!$C$2:$D$10283,2,FALSE) -> C001 | C17: AKRON PUBLIC SCHOOLS | D17: C001AKRON PUBLIC SCHOOLS | E17: 3904348 | F17: =COUNTIF($E$2:$E$1226,E17) -> 1
A18: AKROS MIDDLE SCHOOL | B18: =VLOOKUP(A18,'Final Data'!$C$2:$D$10283,2,FALSE) -> D264 | C18: AKROS MIDDLE SCHOOL | D18: D264AKROS MIDDLE SCHOOL | E18: 3901428 | F18: =COUNTIF($E$2:$E$1226,E18) -> 1
A19: ALBERT EINSTEIN ACADEMY | B19: =VLOOKUP(A19,'Final Data'!$C$2:$D$10283,2,FALSE) -> D380 | C19: ALBERT EINSTEIN ACADEMY | D19: D380ALBERT EINSTEIN ACADEMY | E19: 3901539 | F19: =COUNTIF($E$2:$E$1226,E19) -> 1
A20: ALEXANDER LOCAL SCHOOLS | B20: =VLOOKUP(A20,'Final Data'!$C$2:$D$10283,2,FALSE) -> 0510 | C20: ALEXANDER LOCAL SCHOOLS | D20: 0510ALEXANDER LOCAL SCHOOLS | E20: 3904590 | F20: =COUNTIF($E$2:$E$1226,E20) -> 1
A21: ALLEN CO BD DEVELOPMENTAL DISABILITIES | B21: =VLOOKUP(A21,'Final Data'!$C$2:$D$10283,2,FALSE) -> 9202 | C21: ALLEN CO BD DEVELOPMENTAL DISABILITIES | D21: 9202ALLEN CO BD DEVELOPMENTAL DISABILITIES | F21: =COUNTIF($E$2:$E$1226,E21) -> 0
A22: ALLEN COUNTY ESC | B22: =VLOOKUP(A22,'Final Data'!$C$2:$D$10283,2,FALSE) -> 0200 | C22: ALLEN COUNTY ESC | D22: 0200ALLEN COUNTY ESC | E22: 3904574 | F22: =COUNTIF($E$2:$E$1226,E22) -> 1
A23: ALLEN EAST LOCAL SCHOOLS | B23: =VLOOKUP(A23,'Final Data'!$C$2:$D$10283,2,FALSE) -> 0207 | C23: ALLEN EAST LOCAL SCHOOLS | D23: 0207ALLEN EAST LOCAL SCHOOLS | E23: 3904575 | F23: =COUNTIF($E$2:$E$1226,E23) -> 1
A24: ALLIANCE ACADEMY | B24: =VLOOKUP(A24,'Final Data'!$C$2:$D$10283,2,FALSE) -> 9766 | C24: ALLIANCE ACADEMY | D24: 9766ALLIANCE ACADEMY | E24: 3900130 | F24: =COUNTIF($E$2:$E$1226,E24) -> 1
A25: ALLIANCE CITY SCHOOLS | B25: =VLOOKUP(A25,'Final Data'!$C$2:$D$10283,2,FALSE) -> C010 | C25: ALLIANCE CITY SCHOOLS | D25: C010ALLIANCE CITY SCHOOLS | E25: 3904349 | F25: =COUNTIF($E$2:$E$1226,E25) -> 1
A26: ALLIANCE COMMUNITY SCHOOLS, INC. | B26: =VLOOKUP(A26,'Final Data'!$C$2:$D$10283,2,FALSE) -> 9678 | C26: ALLIANCE COMMUNITY SCHOOLS, INC. | D26: 9678ALLIANCE COMMUNITY SCHOOLS, INC. | F26: =COUNTIF($E$2:$E$1226,E26) -> 0
A27: ALTERNATIVE ED ACAD DBA OHDELA | B27: =VLOOKUP(A27,'Final Data'!$C$2:$D$10283,2,FALSE) -> 9712 | C27: ALTERNATIVE ED ACAD DBA OHDELA | D27: 9712ALTERNATIVE ED ACAD DBA OHDELA | E27: 3900203 | F27: =COUNTIF($E$2:$E$1226,E27) -> 1
A28: AMANDA-CLEARCREEK LOCAL SCHOOLS | B28: =VLOOKUP(A28,'Final Data'!$C$2:$D$10283,2,FALSE) -> 2301 | C28: AMANDA-CLEARCREEK LOCAL SCHOOLS | D28: 2301AMANDA-CLEARCREEK LOCAL SCHOOLS | E28: 3904684 | F28: =COUNTIF($E$2:$E$1226,E28) -> 1
A29: AMHERST EX VLG SCHOOLS | B29: =VLOOKUP(A29,'Final Data'!$C$2:$D$10283,2,FALSE) -> 9003 | C29: AMHERST EX VLG SCHOOLS | D29: 9003AMHERST EX VLG SCHOOLS | E29: 3904519 | F29: =COUNTIF($E$2:$E$1226,E29) -> 1
A30: ANN JERKINS-HARRIS ACADEMY OF EXCELLENCE | B30: =VLOOKUP(A30,'Final Data'!$C$2:$D$10283,2,FALSE) -> D318 | C30: ANN JERKINS-HARRIS ACADEMY OF EXCELLENCE | D30: D318ANN JERKINS-HARRIS ACADEMY OF EXCELLENCE | F30: =COUNTIF($E$2:$E$1226,E30) -> 0
A31: ANNA LOCAL SCHOOLS | B31: =VLOOKUP(A31,'Final Data'!$C$2:$D$10283,2,FALSE) -> 7501 | C31: ANNA LOCAL SCHOOLS | D31: 7501ANNA LOCAL SCHOOLS | E31: 3910004 | F31: =COUNTIF($E$2:$E$1226,E31) -> 1
A32: ANSONIA LOCAL SCHOOLS | B32: =VLOOKUP(A32,'Final Data'!$C$2:$D$10283,2,FALSE) -> 1902 | C32: ANSONIA LOCAL SCHOOLS | D32: 1902ANSONIA LOCAL SCHOOLS | E32: 3904662 | F32: =COUNTIF($E$2:$E$1226,E32) -> 1
A33: ANTHONY WAYNE LOCAL SCHOOLS | B33: =VLOOKUP(A33,'Final Data'!$C$2:$D$10283,2,FALSE) -> 4814 | C33: ANTHONY WAYNE LOCAL SCHOOLS | D33: 4814ANTHONY WAYNE LOCAL SCHOOLS | E33: 3904820 | F33: =COUNTIF($E$2:$E$1226,E33) -> 1
A34: ANTWERP LOCAL SCHOOLS | B34: =VLOOKUP(A34,'Final Data'!$C$2:$D$10283,2,FALSE) -> 6301 | C34: ANTWERP LOCAL SCHOOLS | D34: 6301ANTWERP LOCAL SCHOOLS | E34: 3904899 | F34: =COUNTIF($E$2:$E$1226,E34) -> 1
A35: APEX CHARTER ACADEMY | B35: =VLOOKUP(A35,'Final Data'!$C$2:$D$10283,2,FALSE) -> D015 | C35: APEX CHARTER ACADEMY | D35: D015APEX CHARTER ACADEMY | E35: 3900309 | F35: =COUNTIF($E$2:$E$1226,E35) -> 1
A36: APOLLO JVS | B36: =VLOOKUP(A36,'Final Data'!$C$2:$D$10283,2,FALSE) -> 9869 | C36: APOLLO JVS | D36: 9869APOLLO JVS | E36: 3905077 | F36: =COUNTIF($E$2:$E$1226,E36) -> 1
A37: ARCADIA LOCAL SCHOOLS | B37: =VLOOKUP(A37,'Final Data'!$C$2:$D$10283,2,FALSE) -> 3201 | C37: ARCADIA LOCAL SCHOOLS | D37: 3201ARCADIA LOCAL SCHOOLS | E37: 3910002 | F37: =COUNTIF($E$2:$E$1226,E37) -> 1
A38: ARCANUM BUTLER LOCAL SCHOOLS | B38: =VLOOKUP(A38,'Final Data'!$C$2:$D$10283,2,FALSE) -> 1928 | C38: ARCANUM BUTLER LOCAL SCHOOLS | D38: 1928ARCANUM BUTLER LOCAL SCHOOLS | E38: 3904663 | F38: =COUNTIF($E$2:$E$1226,E38) -> 1
A39: ARCHBOLD AREA LOCAL SCHOOLS | B39: =VLOOKUP(A39,'Final Data'!$C$2:$D$10283,2,FALSE) -> 2601 | C39: ARCHBOLD AREA LOCAL SCHOOLS | D39: 2601ARCHBOLD AREA LOCAL SCHOOLS | E39: 3904704 | F39: =COUNTIF($E$2:$E$1226,E39) -> 1
A40: ARLINGTON LOCAL SCHOOLS | B40: =VLOOKUP(A40,'Final Data'!$C$2:$D$10283,2,FALSE) -> 3202 | C40: ARLINGTON LOCAL SCHOOLS | D40: 3202ARLINGTON LOCAL SCHOOLS | E40: 3904742 | F40: =COUNTIF($E$2:$E$1226,E40) -> 1
...

Sheet Final Check
A1: Check
A2: Year | B2: Total Reported | C2: Total From Formula | D2: Difference | E2: Proportionate Share Check | F2: Notes
A3: 2015 | B3: 1.4606654e+09 | C3: =SUMIF('Final Data'!B:B,'Final Check'!A3,'Final Data'!I:I) -> 1.4606654e+09 | D3: =B3-C3 -> -1.0000007 | E3: =SUMIF('Final Data'!B:B,'Final Check'!A3,'Final Data'!J:J) -> 1
A4: 2016 | B4: 1.473069e+09 | C4: =SUMIF('Final Data'!B:B,'Final Check'!A4,'Final Data'!I:I) -> 1.473069e+09 | D4: =B4-C4 -> -0.0400002 | E4: =SUMIF('Final Data'!B:B,'Final Check'!A4,'Final Data'!J:J) -> 1
A5: 2017 | B5: 1.5391284e+09 | C5: =SUMIF('Final Data'!B:B,'Final Check'!A5,'Final Data'!I:I) -> 1.5391284e+09 | D5: =B5-C5 -> -2.3841858e-06 | E5: =SUMIF('Final Data'!B:B,'Final Check'!A5,'Final Data'!J:J) -> 1
A6: 2018 | B6: 1.5915638e+09 | C6: =SUMIF('Final Data'!B:B,'Final Check'!A6,'Final Data'!I:I) -> 1.5915638e+09 | D6: =B6-C6 -> 0 | E6: =SUMIF('Final Data'!B:B,'Final Check'!A6,'Final Data'!J:J) -> 1
A7: 2019 | B7: 1.6436542e+09 | C7: =SUMIF('Final Data'!B:B,'Final Check'!A7,'Final Data'!I:I) -> 1.6436542e+09 | D7: =B7-C7 -> 0 | E7: =SUMIF('Final Data'!B:B,'Final Check'!A7,'Final Data'!J:J) -> 1
A8: 2020 | B8: 1.6895812e+09 | C8: =SUMIF('Final Data'!B:B,'Final Check'!A8,'Final Data'!I:I) -> 1.6895812e+09 | D8: =B8-C8 -> 0 | E8: =SUMIF('Final Data'!B:B,'Final Check'!A8,'Final Data'!J:J) -> 1
A9: 2021 | B9: 1.7275083e+09 | C9: =SUMIF('Final Data'!B:B,'Final Check'!A9,'Final Data'!I:I) -> 1.7275083e+09 | D9: =B9-C9 -> 0 | E9: =SUMIF('Final Data'!B:B,'Final Check'!A9,'Final Data'!J:J) -> 1
A10: 2022 | B10: 1.8200667e+09 | C10: =SUMIF('Final Data'!B:B,'Final Check'!A10,'Final Data'!I:I) -> 1.8200667e+09 | D10: =B10-C10 -> 0 | E10: =SUMIF('Final Data'!B:B,'Final Check'!A10,'Final Data'!J:J) -> 1
A11: 2023 | B11: 1.8909569e+09 | C11: =SUMIF('Final Data'!B:B,'Final Check'!A11,'Final Data'!I:I) -> 1.8909569e+09 | D11: =B11-C11 -> 2.8610229e-06 | E11: =SUMIF('Final Data'!B:B,'Final Check'!A11,'Final Data'!J:J) -> 1

Sheet Data
A1: year | B1: employer_code | C1: standardized_employer_name | D1: employer_name | E1: county_name | F1: employer_contributions | G1: proportionate_share
A2: 2015 | B2: 0106 | C2: A | D2: ADAMS COUNTY-OHIO VALLEY LOCAL SCH | E2: ADAMS | F2: 2239432.7 | G2: 0.0015331592
A3: 2015 | B3: 0107 | C3: A | D3: MANCHESTER LOCAL SCHOOL | E3: ADAMS | F3: 611398.47 | G3: 0.0004185753
A4: 2015 | B4: 0200 | C4: A | D4: ALLEN COUNTY ESC | E4: ALLEN | F4: 577175.62 | G4: 0.0003951457
A5: 2015 | B5: 0202 | C5: A | D5: BATH LOCAL SCHOOLS | E5: ALLEN | F5: 946047.39 | G5: 0.0006476825
A6: 2015 | B6: 0205 | C6: A | D6: ELIDA LOCAL SCHOOLS | E6: ALLEN | F6: 1249273.1 | G6: 0.0008552767
A7: 2015 | B7: 0207 | C7: A | D7: ALLEN EAST LOCAL SCHOOLS | E7: ALLEN | F7: 538977.88 | G7: 0.0003689948
A8: 2015 | B8: 0208 | C8: A | D8: PERRY LOCAL SCHOOLS | E8: ALLEN | F8: 441793.01 | G8: 0.0003024601
A9: 2015 | B9: 0209 | C9: A | D9: SHAWNEE LOCAL SCHOOLS | E9: ALLEN | F9: 1408093.1 | G9: 0.0009640079
A10: 2015 | B10: 0210 | C10: A | D10: SPENCERVILLE LOCAL SCHOOLS | E10: ALLEN | F10: 526005.41 | G10: 0.0003601135
A11: 2015 | B11: 0301 | C11: A | D11: HILLSDALE LOCAL SCHOOLS | E11: ASHLAND | F11: 534053.51 | G11: 0.0003656234
A12: 2015 | B12: 0304 | C12: A | D12: MAPLETON LOCAL SCHOOLS | E12: ASHLAND | F12: 510929.94 | G12: 0.0003497926
A13: 2015 | B13: 0400 | C13: A | D13: ASHTABULA COUNTY SCHOOLS | E13: ASHTABULA | F13: 554425.59 | G13: 0.0003795705
... A1061: 2015 | B1061: D233 | C1061: A | D1061: HORIZON SCIENCE ACADEMY YOUNGSTOWN | E1061: MAHONING | F1061: 188506.37 | G1061: 0.0001290551
A1062: 2015 | B1062: D235 | C1062: A | D1062: HORIZON SCI ACAD TOLEDO DOWNTOWN | F1062: 11474.86 | G1062: 7.8559e-06
A1063: 2015 | B1063: D237 | C1063: A | D1063: IMAGINE CLEVELAND ACADEMY | E1063: CUYAHOGA | F1063: 86255.55 | G1063: 5.90522e-05
A1064: 2015 | B1064: D238 | C1064: A | D1064: IMAGINE AKRON ACADEMY | E1064: SUMMIT | F1064: 22848.68 | G1064: 1.56426e-05
A1065: 2015 | B1065: D239 | C1065: A | D1065: RICHLAND ACADEMY SCHOOL OF EXCELLENCE | E1065: RICHLAND | F1065: 84264.74 | G1065: 5.76893e-05
A1066: 2015 | B1066: D240 | C1066: A | D1066: THEODORE ROOSEVELT PUBLIC COMM SCH | E1066: MONTGOMERY | F1066: 5988.77 | G1066: 4.1e-06
A1067: 2015 | B1067: D242 | C1067: A | D1067: CLEVELAND COLLEGE PREPARATORY | E1067: CUYAHOGA | F1067: 214546.13 | G1067: 0.0001468825
A1068: 2015 | B1068: D243 | C1068: A | D1068: NORTHEAST OHIO COLLEGE PREPARATORY | E1068: CUYAHOGA | F1068: 338796.98 | G1068: 0.000231947
A1069: 2015 | B1069: D247 | C1069: A | D1069: EVEREST HIGH SCHOOL | E1069: FRANKLIN | F1069: 21281.77 | G1069: 1.45699e-05
A1070: 2015 | B1070: D248 | C1070: A | D1070: HORIZON SCI ACAD DOWNTOWN DAYTON | E1070: MONTGOMERY | F1070: 119579.75 | G1070: 8.18666e-05
A1071: 2015 | B1071: D251 | C1071: A | D1071: BHA SOUTHSIDE ACADEMY | E1071: MAHONING | F1071: 98184.86 | G1071: 6.72193e-05
A1072: 2015 | B1072: D252 | C1072: A | D1072: ZENITH ACADEMY EAST COMM SCH | E1072: FRANKLIN | F1072: 130503.24 | G1072: 8.93451e-05
A1073: 2015 | B1073: D253 | C1073: A | D1073: COLUMBUS PERFORMANCE ACADEMY | E1073: FRANKLIN | F1073: 112765.77 | G1073: 7.72016e-05
A1074: 2015 | B1074: D255 | C1074: A | D1074: FREDERICK DOUGLASS RECLAMATION ACAD | E1074: CUYAHOGA | F1074: 22067.44 | G1074: 1.51078e-05
... A3381: 2017 | B3381: D248 | C3381: A | D3381: HORIZON SCI ACAD DOWNTOWN DAYTON | E3381: MONTGOMERY | F3381: 144057.88 | G3381: 9.35971e-05
A3382: 2017 | B3382: D249 | C3382: A | D3382: NOTTEN SCHOOL FOR STEM | F3382: 5657.29 | G3382: 3.6756e-06
A3383: 2017 | B3383: D251 | C3383: A | D3383: SOUTHSIDE ACADEMY | E3383: MAHONING | F3383: 107505.57 | G3383: 6.98483e-05
A3384: 2017 | B3384: D252 | C3384: A | D3384: ZENITH ACADEMY EAST COMM SCH | E3384: FRANKLIN | F3384: 134950.57 | G3384: 8.76799e-05
A3385: 2017 | B3385: D253 | C3385: A | D3385: COLUMBUS PERFORMANCE ACADEMY | E3385: FRANKLIN | F3385: 89682.8 | G3385: 5.82686e-05
A3386: 2017 | B3386: D255 | C3386: A | D3386: FREDERICK DOUGLASS RECLAMATION ACAD | E3386: CUYAHOGA | F3386: 24887.16 | G3386: 1.61696e-05
A3387: 2017 | B3387: D256 | C3387: A | D3387: CENTRAL HIGH SCHOOL | E3387: FRANKLIN | F3387: 35888.18 | G3387: 2.33172e-05
A3388: 2017 | B3388: D257 | C3388: A | D3388: GEORGE V VOINOVICH RECLAMATION ACAD | E3388: CUYAHOGA | F3388: 54406.05 | G3388: 3.53486e-05
A3389: 2017 | B3389: D258 | C3389: A | D3389: ROAD TO SUCCESS ACADEMY | E3389: FRANKLIN | F3389: 41436.41 | G3389: 2.6922e-05
A3390: 2017 | B3390: D259 | C3390: A | D3390: MASON RUN HIGH SCHOOL | E3390: FRANKLIN | F3390: 40641.87 | G3390: 2.64058e-05
A3391: 2017 | B3391: D260 | C3391: A | D3391: CAPITAL HIGH SCHOOL | E3391: FRANKLIN | F3391: 58054.73 | G3391: 3.77192e-05
A3392: 2017 | B3392: D261 | C3392: A | D3392: OLD BROOK HIGH SCHOOL | E3392: CUYAHOGA | F3392: 26702.64 | G3392: 1.73492e-05
A3393: 2017 | B3393: D262 | C3393: A | D3393: REGENT HIGH SCHOOL | E3393: CUYAHOGA | F3393: 42149.98 | G3393: 2.73856e-05
...

Sheet Check
A1: Check
A2: Year | B2: Total Reported | C2: Total From Formula | D2: Difference | E2: Notes
A3: 2015 | B3: 1.4606654e+09 | C3: =SUMIF(Data!A:A,Check!A3,Data!F:F) -> 1.4606654e+09 | D3: =B3-C3 -> -1.0000007
A4: 2016 | B4: 1.473069e+09 | C4: =SUMIF(Data!A:A,Check!A4,Data!F:F) -> 1.473069e+09 | D4: =B4-C4 -> -0.040001869
A5: 2017 | B5: 1.5391284e+09 | C5: =SUMIF(Data!A:A,Check!A5,Data!F:F) -> 1.5391284e+09 | D5: =B5-C5 -> 0
A6: 2018 | B6: 1.5915638e+09 | C6: =SUMIF(Data!A:A,Check!A6,Data!F:F) -> 1.5915638e+09 | D6: =B6-C6 -> 0
A7: 2019 | B7: 1.6436542e+09 | C7: =SUMIF(Data!A:A,Check!A7,Data!F:F) -> 1.6436542e+09 | D7: =B7-C7 -> 0
A8: 2020 | B8: 1.6895812e+09 | C8: =SUMIF(Data!A:A,Check!A8,Data!F:F) -> 1.6895812e+09 | D8: =B8-C8 -> 0
A9: 2021 | B9: 1.7275083e+09 | C9: =SUMIF(Data!A:A,Check!A9,Data!F:F) -> 1.7275083e+09 | D9: =B9-C9 -> 0
A10: 2022 | B10: 1.8200667e+09 | C10: =SUMIF(Data!A:A,Check!A10,Data!F:F) -> 1.8200667e+09 | D10: =B10-C10 -> 0
A11: 2023 | B11: 1.8909569e+09 | C11: =SUMIF(Data!A:A,Check!A11,Data!F:F) -> 1.8909569e+09 | D11: =B11-C11 -> 1.9073486e-06

Sheet Name Cleaning
A1: replace | B1: standardized_employer_name | C1: = | D1: =_xlfn.TEXTJOIN(,,J1:L1) -> "ADAMS COUNTY-OHIO VALLEY LOCAL SCH" | E1: if | F1: employer_code | G1: == | H1: =_xlfn.TEXTJOIN(,,L1:N1) -> "0106" | J1: " | K1: ADAMS COUNTY-OHIO VALLEY LOCAL SCH | L1: " | M1: 0106 | N1: "
A2: replace | B2: standardized_employer_name | C2: = | D2: =_xlfn.TEXTJOIN(,,J2:L2) -> "MANCHESTER LOCAL SCHOOL" | E2: if | F2: employer_code | G2: == | H2: =_xlfn.TEXTJOIN(,,L2:N2) -> "0107" | J2: " | K2: MANCHESTER LOCAL SCHOOL | L2: " | M2: 0107 | N2: "
A3: replace | B3: standardized_employer_name | C3: = | D3: =_xlfn.TEXTJOIN(,,J3:L3) -> "ALLEN COUNTY ESC" | E3: if | F3: employer_code | G3: == | H3: =_xlfn.TEXTJOIN(,,L3:N3) -> "0200" | J3: " | K3: ALLEN COUNTY ESC | L3: " | M3: 0200 | N3: "
A4: replace | B4: standardized_employer_name | C4: = | D4: =_xlfn.TEXTJOIN(,,J4:L4) -> "BATH LOCAL SCHOOLS" | E4: if | F4: employer_code | G4: == | H4: =_xlfn.TEXTJOIN(,,L4:N4) -> "0202" | J4: " | K4: BATH LOCAL SCHOOLS | L4: " | M4: 0202 | N4: "
A5: replace | B5: standardized_employer_name | C5: = | D5: =_xlfn.TEXTJOIN(,,J5:L5) -> "ELIDA LOCAL SCHOOLS" | E5: if | F5: employer_code | G5: == | H5: =_xlfn.TEXTJOIN(,,L5:N5) -> "0205" | J5: " | K5: ELIDA LOCAL SCHOOLS | L5: " | M5: 0205 | N5: "
A6: replace | B6: standardized_employer_name | C6: = | D6: =_xlfn.TEXTJOIN(,,J6:L6) -> "ALLEN EAST LOCAL SCHOOLS" | E6: if | F6: employer_code | G6: == | H6: =_xlfn.TEXTJOIN(,,L6:N6) -> "0207" | J6: " | K6: ALLEN EAST LOCAL SCHOOLS | L6: " | M6: 0207 | N6: "
A7: replace | B7: standardized_employer_name | C7: = | D7: =_xlfn.TEXTJOIN(,,J7:L7) -> "PERRY LOCAL SCHOOLS" | E7: if | F7: employer_code | G7: == | H7: =_xlfn.TEXTJOIN(,,L7:N7) -> "0208" | J7: " | K7: PERRY LOCAL SCHOOLS | L7: " | M7: 0208 | N7: "
A8: replace | B8: standardized_employer_name | C8: = | D8: =_xlfn.TEXTJOIN(,,J8:L8) -> "SHAWNEE LOCAL SCHOOLS" | E8: if | F8: employer_code | G8: == | H8: =_xlfn.TEXTJOIN(,,L8:N8) -> "0209" | J8: " | K8: SHAWNEE LOCAL SCHOOLS | L8: " | M8: 0209 | N8: "
A9: replace | B9: standardized_employer_name | C9: = | D9: =_xlfn.TEXTJOIN(,,J9:L9) -> "SPENCERVILLE LOCAL SCHOOLS" | E9: if | F9: employer_code | G9: == | H9: =_xlfn.TEXTJOIN(,,L9:N9) -> "0210" | J9: " | K9: SPENCERVILLE LOCAL SCHOOLS | L9: " | M9: 0210 | N9: "
A10: replace | B10: standardized_employer_name | C10: = | D10: =_xlfn.TEXTJOIN(,,J10:L10) -> "HILLSDALE LOCAL SCHOOLS" | E10: if | F10: employer_code | G10: == | H10: =_xlfn.TEXTJOIN(,,L10:N10) -> "0301" | J10: " | K10: HILLSDALE LOCAL SCHOOLS | L10: " | M10: 0301 | N10: "
A11: replace | B11: standardized_employer_name | C11: = | D11: =_xlfn.TEXTJOIN(,,J11:L11) -> "MAPLETON LOCAL SCHOOLS" | E11: if | F11: employer_code | G11: == | H11: =_xlfn.TEXTJOIN(,,L11:N11) -> "0304" | J11: " | K11: MAPLETON LOCAL SCHOOLS | L11: " | M11: 0304 | N11: "
A12: replace | B12: standardized_employer_name | C12: = | D12: =_xlfn.TEXTJOIN(,,J12:L12) -> "ASHTABULA COUNTY SCHOOLS" | E12: if | F12: employer_code | G12: == | H12: =_xlfn.TEXTJOIN(,,L12:N12) -> "0400" | J12: " | K12: ASHTABULA COUNTY SCHOOLS | L12: " | M12: 0400 | N12: "
... A10282: replace | B10282: standardized_employer_name | C10282: = | D10282: =_xlfn.TEXTJOIN(,,J10282:L10282) -> "THE DAYTON SCHOOL" | E10282: if | F10282: employer_code | G10282: == | H10282: =_xlfn.TEXTJOIN(,,L10282:N10282) -> "D491" | J10282: " | K10282: THE DAYTON SCHOOL | L10282: " | M10282: D491 | N10282: "
