Workbook

Sheet Final
A1: identifier | B1: LEAID | C1: Year | D1: code | E1: State | F1: state_abv | G1: district_name | H1: district_contributions | I1: state_contributions | J1: total_contributions | K1: LEAID
A2: =C2&G2 -> 2015GRANT ELEMENTARY | B2: 3012900 | C2: 2015 | D2: 10071 | E2: Montana | F2: MT | G2: GRANT ELEMENTARY | H2: 4996 | I2: 3840 | J2: 8836 | K2: =IFERROR(VLOOKUP(G2,'GASB Match'!$A$87:$B$363,2,FALSE),"") -> 3012900
A3: =C3&G3 -> 2016GRANT ELEMENTARY | B3: 3012900 | C3: 2016 | D3: 10071 | E3: Montana | F3: MT | G3: GRANT ELEMENTARY | H3: 3325 | I3: 2375 | J3: 5700 | K3: =IFERROR(VLOOKUP(G3,'GASB Match'!$A$87:$B$363,2,FALSE),"") -> 3012900
A4: =C4&G4 -> 2017GRANT ELEMENTARY | B4: 3012900 | C4: 2017 | D4: 10071 | E4: Montana | F4: MT | G4: GRANT ELEMENTARY | H4: 3718 | I4: 2375 | J4: 6093 | K4: =IFERROR(VLOOKUP(G4,'GASB Match'!$A$87:$B$363,2,FALSE),"") -> 3012900
A5: =C5&G5 -> 2018GRANT ELEMENTARY | B5: 3012900 | C5: 2018 | D5: 10071 | E5: Montana | F5: MT | G5: GRANT ELEMENTARY | H5: 3378 | I5: 2432 | J5: 5810 | K5: =IFERROR(VLOOKUP(G5,'GASB Match'!$A$87:$B$363,2,FALSE),"") -> 3012900
A6: =C6&G6 -> 2019GRANT ELEMENTARY | B6: 3012900 | C6: 2019 | D6: 10071 | E6: Montana | F6: MT | G6: GRANT ELEMENTARY | H6: 3448 | I6: 2167 | J6: 5615 | K6: =IFERROR(VLOOKUP(G6,'GASB Match'!$A$87:$B$363,2,FALSE),"") -> 3012900
A7: =C7&G7 -> 2020GRANT ELEMENTARY | B7: 3012900 | C7: 2020 | D7: 10071 | E7: Montana | F7: MT | G7: GRANT ELEMENTARY | H7: 3581 | I7: 2029 | J7: 5610 | K7: =IFERROR(VLOOKUP(G7,'GASB Match'!$A$87:$B$363,2,FALSE),"") -> 3012900
A8: =C8&G8 -> 2021GRANT ELEMENTARY | B8: 3012900 | C8: 2021 | D8: 10071 | E8: Montana | F8: MT | G8: GRANT ELEMENTARY | H8: 3699 | I8: 2061 | J8: 5760 | K8: =IFERROR(VLOOKUP(G8,'GASB Match'!$A$87:$B$363,2,FALSE),"") -> 3012900
A9: =C9&G9 -> 2022GRANT ELEMENTARY | B9: 3012900 | C9: 2022 | D9: 10071 | E9: Montana | F9: MT | G9: GRANT ELEMENTARY | H9: 3827 | I9: 1987 | J9: 5814 | K9: =IFERROR(VLOOKUP(G9,'GASB Match'!$A$87:$B$363,2,FALSE),"") -> 3012900
A10: =C10&G10 -> 2023GRANT ELEMENTARY | B10: 3012900 | C10: 2023 | D10: 10071 | E10: Montana | F10: MT | G10: GRANT ELEMENTARY | H10: 4424 | I10: 2273 | J10: 6697 | K10: =IFERROR(VLOOKUP(G10,'GASB Match'!$A$87:$B$363,2,FALSE),"") -> 3012900
A11: =C11&G11 -> 2015DILLON ELEMENTARY | B11: 3008910 | C11: 2015 | D11: 10101 | E11: Montana | F11: MT | G11: DILLON ELEMENTARY | H11: 290107 | I11: 194686 | J11: 484793 | K11: =IFERROR(VLOOKUP(G11,'GASB Match'!$A$87:$B$363,2,FALSE),"") -> 3008910
A12: =C12&G12 -> 2016DILLON ELEMENTARY | B12: 3008910 | C12: 2016 | D12: 10101 | E12: Montana | F12: MT | G12: DILLON ELEMENTARY | H12: 294875 | I12: 192300 | J12: 487175 | K12: =IFERROR(VLOOKUP(G12,'GASB Match'!$A$87:$B$363,2,FALSE),"") -> 3008910
A13: =C13&G13 -> 2017DILLON ELEMENTARY | B13: 3008910 | C13: 2017 | D13: 10101 | E13: Montana | F13: MT | G13: DILLON ELEMENTARY | H13: 304509 | I13: 193303 | J13: 497812 | K13: =IFERROR(VLOOKUP(G13,'GASB Match'!$A$87:$B$363,2,FALSE),"") -> 3008910
... A100: =C100&G100 -> 2023PRYOR SCHOOL DISTRICT | B100: 3021720 | C100: 2023 | D100: 20021 | E100: Montana | F100: MT | G100: PRYOR SCHOOL DISTRICT | H100: 109725 | I100: 59212 | J100: 168937 | K100: =IFERROR(VLOOKUP(G100,'GASB Match'!$A$87:$B$363,2,FALSE),"") -> 3021720
A101: =C101&G101 -> 2015HARDIN PUBLIC SCHOOL | C101: 2015 | D101: 20171 | E101: Montana | F101: MT | G101: HARDIN PUBLIC SCHOOL | H101: 877877 | I101: 588125 | J101: 1466002 | K101: =IFERROR(VLOOKUP(G101,'GASB Match'!$A$87:$B$363,2,FALSE),"")
A102: =C102&G102 -> 2016HARDIN PUBLIC SCHOOL | C102: 2016 | D102: 20171 | E102: Montana | F102: MT | G102: HARDIN PUBLIC SCHOOL | H102: 907521 | I102: 591398 | J102: 1498919 | K102: =IFERROR(VLOOKUP(G102,'GASB Match'!$A$87:$B$363,2,FALSE),"")
A103: =C103&G103 -> 2017HARDIN PUBLIC SCHOOL | C103: 2017 | D103: 20171 | E103: Montana | F103: MT | G103: HARDIN PUBLIC SCHOOL | H103: 963630 | I103: 611682 | J103: 1575312 | K103: =IFERROR(VLOOKUP(G103,'GASB Match'!$A$87:$B$363,2,FALSE),"")
A104: =C104&G104 -> 2018HARDIN PUBLIC SCHOOL | C104: 2018 | D104: 20171 | E104: Montana | F104: MT | G104: HARDIN PUBLIC SCHOOL | H104: 972266 | I104: 604101 | J104: 1576367 | K104: =IFERROR(VLOOKUP(G104,'GASB Match'!$A$87:$B$363,2,FALSE),"")
A105: =C105&G105 -> 2019HARDIN PUBLIC SCHOOL | C105: 2019 | D105: 20171 | E105: Montana | F105: MT | G105: HARDIN PUBLIC SCHOOL | H105: 986399 | I105: 597223 | J105: 1583622 | K105: =IFERROR(VLOOKUP(G105,'GASB Match'!$A$87:$B$363,2,FALSE),"")
A106: =C106&G106 -> 2020HARDIN PUBLIC SCHOOL | C106: 2020 | D106: 20171 | E106: Montana | F106: MT | G106: HARDIN PUBLIC SCHOOL | H106: 1003435 | I106: 593353 | J106: 1596788 | K106: =IFERROR(VLOOKUP(G106,'GASB Match'!$A$87:$B$363,2,FALSE),"")
A107: =C107&G107 -> 2021HARDIN PUBLIC SCHOOL | C107: 2021 | D107: 20171 | E107: Montana | F107: MT | G107: HARDIN PUBLIC SCHOOL | H107: 1001065 | I107: 571182 | J107: 1572247 | K107: =IFERROR(VLOOKUP(G107,'GASB Match'!$A$87:$B$363,2,FALSE),"")
A108: =C108&G108 -> 2022HARDIN PUBLIC SCHOOL | C108: 2022 | D108: 20171 | E108: Montana | F108: MT | G108: HARDIN PUBLIC SCHOOL | H108: 1061310 | I108: 586201 | J108: 1647511 | K108: =IFERROR(VLOOKUP(G108,'GASB Match'!$A$87:$B$363,2,FALSE),"")
A109: =C109&G109 -> 2023HARDIN PUBLIC SCHOOL | C109: 2023 | D109: 20171 | E109: Montana | F109: MT | G109: HARDIN PUBLIC SCHOOL | H109: 1204687 | I109: 651282 | J109: 1855969 | K109: =IFERROR(VLOOKUP(G109,'GASB Match'!$A$87:$B$363,2,FALSE),"")
A110: =C110&G110 -> 2015LODGE GRASS PUBLIC SCHOOLS | C110: 2015 | D110: 20271 | E110: Montana | F110: MT | G110: LODGE GRASS PUBLIC SCHOOLS | H110: 166801 | I110: 112148 | J110: 278949 | K110: =IFERROR(VLOOKUP(G110,'GASB Match'!$A$87:$B$363,2,FALSE),"")
A111: =C111&G111 -> 2016LODGE GRASS PUBLIC SCHOOLS | C111: 2016 | D111: 20271 | E111: Montana | F111: MT | G111: LODGE GRASS PUBLIC SCHOOLS | H111: 166968 | I111: 108977 | J111: 275945 | K111: =IFERROR(VLOOKUP(G111,'GASB Match'!$A$87:$B$363,2,FALSE),"")
A112: =C112&G112 -> 2017LODGE GRASS PUBLIC SCHOOLS | C112: 2017 | D112: 20271 | E112: Montana | F112: MT | G112: LODGE GRASS PUBLIC SCHOOLS | H112: 174130 | I112: 110544 | J112: 284674 | K112: =IFERROR(VLOOKUP(G112,'GASB Match'!$A$87:$B$363,2,FALSE),"")
... A118: =C118&G118 -> 2023LODGE GRASS PUBLIC SCHOOLS | C118: 2023 | D118: 20271 | E118: Montana | F118: MT | G118: LODGE GRASS PUBLIC SCHOOLS | H118: 261725 | I118: 141401 | J118: 403126 | K118: =IFERROR(VLOOKUP(G118,'GASB Match'!$A$87:$B$363,2,FALSE),"")
A119: =C119&G119 -> 2015WYOLA ELEMENTARY | B119: 3028800 | C119: 2015 | D119: 20291 | E119: Montana | F119: MT | G119: WYOLA ELEMENTARY | H119: 65920 | I119: 44621 | J119: 110541 | K119: =IFERROR(VLOOKUP(G119,'GASB Match'!$A$87:$B$363,2,FALSE),"") -> 3028800
A120: =C120&G120 -> 2016WYOLA ELEMENTARY | B120: 3028800 | C120: 2016 | D120: 20291 | E120: Montana | F120: MT | G120: WYOLA ELEMENTARY | H120: 58653 | I120: 38417 | J120: 97070 | K120: =IFERROR(VLOOKUP(G120,'GASB Match'!$A$87:$B$363,2,FALSE),"") -> 3028800
A121: =C121&G121 -> 2017WYOLA ELEMENTARY | B121: 3028800 | C121: 2017 | D121: 20291 | E121: Montana | F121: MT | G121: WYOLA ELEMENTARY | H121: 62763 | I121: 39854 | J121: 102617 | K121: =IFERROR(VLOOKUP(G121,'GASB Match'!$A$87:$B$363,2,FALSE),"") -> 3028800
A122: =C122&G122 -> 2018WYOLA ELEMENTARY | B122: 3028800 | C122: 2018 | D122: 20291 | E122: Montana | F122: MT | G122: WYOLA ELEMENTARY | H122: 63335 | I122: 39664 | J122: 102999 | K122: =IFERROR(VLOOKUP(G122,'GASB Match'!$A$87:$B$363,2,FALSE),"") -> 3028800
A123: =C123&G123 -> 2019WYOLA ELEMENTARY | B123: 3028800 | C123: 2019 | D123: 20291 | E123: Montana | F123: MT | G123: WYOLA ELEMENTARY | H123: 82822 | I123: 50218 | J123: 133040 | K123: =IFERROR(VLOOKUP(G123,'GASB Match'!$A$87:$B$363,2,FALSE),"") -> 3028800
A124: =C124&G124 -> 2020WYOLA ELEMENTARY | B124: 3028800 | C124: 2020 | D124: 20291 | E124: Montana | F124: MT | G124: WYOLA ELEMENTARY | H124: 91038 | I124: 53752 | J124: 144790 | K124: =IFERROR(VLOOKUP(G124,'GASB Match'!$A$87:$B$363,2,FALSE),"") -> 3028800
A125: =C125&G125 -> 2021WYOLA ELEMENTARY | B125: 3028800 | C125: 2021 | D125: 20291 | E125: Montana | F125: MT | G125: WYOLA ELEMENTARY | H125: 89517 | I125: 51030 | J125: 140547 | K125: =IFERROR(VLOOKUP(G125,'GASB Match'!$A$87:$B$363,2,FALSE),"") -> 3028800
A126: =C126&G126 -> 2022WYOLA ELEMENTARY | B126: 3028800 | C126: 2022 | D126: 20291 | E126: Montana | F126: MT | G126: WYOLA ELEMENTARY | H126: 89342 | I126: 49230 | J126: 138572 | K126: =IFERROR(VLOOKUP(G126,'GASB Match'!$A$87:$B$363,2,FALSE),"") -> 3028800
A127: =C127&G127 -> 2023WYOLA ELEMENTARY | B127: 3028800 | C127: 2023 | D127: 20291 | E127: Montana | F127: MT | G127: WYOLA ELEMENTARY | H127: 79233 | I127: 42724 | J127: 121957 | K127: =IFERROR(VLOOKUP(G127,'GASB Match'!$A$87:$B$363,2,FALSE),"") -> 3028800
A128: =C128&G128 -> 2016BIG HORN COUNTY | B128: 3000010 | C128: 2016 | D128: 29991 | E128: Montana | F128: MT | G128: BIG HORN COUNTY | H128: 2388 | I128: 1765 | J128: 4153 | K128: =IFERROR(VLOOKUP(G128,'GASB Match'!$A$87:$B$363,2,FALSE),"") -> 3000010
A129: =C129&G129 -> 2017BIG HORN COUNTY | B129: 3000010 | C129: 2017 | D129: 29991 | E129: Montana | F129: MT | G129: BIG HORN COUNTY | H129: 140 | I129: 104 | J129: 244 | K129: =IFERROR(VLOOKUP(G129,'GASB Match'!$A$87:$B$363,2,FALSE),"") -> 3000010
A130: =C130&G130 -> 2018BIG HORN COUNTY | B130: 3000010 | C130: 2018 | D130: 29991 | E130: Montana | F130: MT | G130: BIG HORN COUNTY | H130: 0 | I130: 0 | J130: 0 | K130: =IFERROR(VLOOKUP(G130,'GASB Match'!$A$87:$B$363,2,FALSE),"") -> 3000010
A131: =C131&G131 -> 2019BIG HORN COUNTY | B131: 3000010 | C131: 2019 | D131: 29991 | E131: Montana | F131: MT | G131: BIG HORN COUNTY | J131: 0 | K131: =IFERROR(VLOOKUP(G131,'GASB Match'!$A$87:$B$363,2,FALSE),"") -> 3000010
...

Sheet Matching Files -->

Sheet GASB Match
A1: district_name | B1: LEAID | C1: LEAID2
A2: ROCKY BOY PUBLIC SCHOOLS | B2: 3022750 | C2: 3028911
A3: WOLF POINT PUBLIC SCHOOLS | B3: 3028590 | C3: 3028620
A4: WILLOW CREEK PUBLIC SCHOOLS | B4: 3028140 | C4: 3028170
A5: WHITEHALL PUBLIC SCHOOLS | B5: 3027810 | C5: 3027840
A6: WHITEFISH PUBLIC SCHOOLS | B6: 3027740 | C6: 3027790
A7: VALIER PUBLIC SCHOOLS | B7: 3027060 | C7: 3027090
A8: TURNER PUBLIC SCHOOLS | B8: 3026640 | C8: 3026670
A9: TROY PUBLIC SCHOOLS | B9: 3026550 | C9: 3026580
A10: THREE FORKS PUBLIC SCHOOLS | B10: 3026160 | C10: 3026190
A11: THOMPSON FALLS PUBLIC SCHOOLS | B11: 3026070 | C11: 3026100
A12: CENTERVILLE PUBLIC SCHOOLS | B12: 3025130 | C12: 3025140
A13: STEVENSVILLE PUBLIC SCHOOLS | B13: 3025020 | C13: 3025050
... A86: LAME DEER PUBLIC SCHOOLS | B86: 3016050 | C86: 3000095
A87: ALBERTON K-12 SCHOOLS | B87: 3001860
A88: ALDER-UPPER RUBY ELEMENTARY | B88: 3017460
A89: ALLIANCE FOR CURRICULUM ENHANCEMENT
A90: ALZADA ELEMENTARY | B90: 3001950
A91: AMSTERDAM ELEMENTARY | B91: 3001980
A92: ANDERSON ELEMENTARY | B92: 3002070
A93: ARROWHEAD ELEMENTARY | B93: 3002300
A94: ASHLAND PUBLIC SCHOOL | B94: 3000008
A95: AUCHARD CREEK ELEMENTARY | B95: 3002490
A96: AVON ELEMENTARY | B96: 3002550
A97: AYERS ELEMENTARY | B97: 3002570
A98: BAINVILLE K-12 SCHOOLS | B98: 3002640
A99: BAKER K-12 SCHOOLS | B99: 3002730
A100: BASIN ELEMENTARY | B100: 3002820
A101: BEAR PAW COOPERATIVE | B101: 3000012
... A123: BRORSON ELEMENTARY | B123: 3005130
A124: BROWNING PUBLIC SCHOOLS
A125: BYNUM ELEMENTARY | B125: 3005330
A126: CANYON CREEK ELEMENTARY | B126: 3005460
A127: CARBON COUNTY | B127: 3000014
A128: CARDWELL ELEMENTARY | B128: 3005550
A129: CARTER COUNTY | B129: 3000015
A130: CARTER ELEMENTARY | B130: 3005760
A131: CASCADE COUNTY | B131: 3000016
A132: CAYUSE PRAIRIE ELEMENTARY | B132: 3005990
A133: CENTRAL MT LEARNING CENTER | B133: 3000029
...

Sheet GASB-NCES Double LEAIDs
A1: district_name | B1: LEAID | C1: LEAID2
A2: ABSAROKEE PUBLIC SCHOOLS | B2: 3001710 | C2: 3001740
A3: ANACONDA PUBLIC SCHOOLS | B3: 3002010 | C3: 3002030
A4: ARLEE PUBLIC SCHOOLS | B4: 3002220 | C4: 3002250
A5: AUGUSTA PUBLIC SCHOOLS | B5: 3002430 | C5: 3002450
A6: BELGRADE PUBLIC SCHOOL | B6: 3003290 | C6: 3003330
A7: BELT PUBLIC SCHOOLS | B7: 3003420 | C7: 3003450
A8: BIGFORK PUBLIC SCHOOLS | B8: 3003820 | C8: 3003840
A9: BILLINGS PUBLIC SCHOOLS | B9: 3003870 | C9: 3003900
A10: BOZEMAN PUBLIC SCHOOLS | B10: 3004560 | C10: 3004590
A11: BROADVIEW PUBLIC SCHOOLS | B11: 3004890 | C11: 3004920
A12: BROCKTON PUBLIC SCHOOLS | B12: 3005010 | C12: 3005040
A13: BUTTE PUBLIC SCHOOLS | B13: 3005280 | C13: 3005310
... A86: WOLF POINT PUBLIC SCHOOLS | B86: 3028590 | C86: 3028620

Sheet Dealing with Duplicates
A1: LEAID | B1: NAME | C1: STNAME | D1: STABBR | E1: Year | F1: V33 | G1: MEMBERSCH | H1: TOTALEXP | I1: TCURELSC | J1: TCURINST | K1: E13 | L1: TCURSSVC | M1: E17 | N1: E07 | O1: E08 | P1: E09 | Q1: V40 | R1: V45 | S1: V90 | T1: E11 | W1: V33 | X1: MEMBERSCH | Y1: TOTALEXP | Z1: TCURELSC | AA1: TCURINST | AB1: E13 | AC1: TCURSSVC | AD1: E17 | AE1: E07 | AF1: E08 | AG1: E09 | AH1: V40 | AI1: V45 | AJ1: V90 | AK1: E11
A2: 3001710 | B2: Absarokee Elem | C2: Montana | D2: MT | E2: 2015 | F2: 169 | G2: 169 | H2: 2018000 | I2: 1965000 | J2: 1162000 | K2: 1162000 | L2: 677000 | M2: 2000 | N2: 7000 | O2: 78000 | P2: 146000 | Q2: 276000 | R2: 97000 | S2: 71000 | T2: 126000
A3: 3001710 | B3: Absarokee Elem | C3: Montana | D3: MT | E3: 2016 | F3: 155 | G3: 155 | H3: 1852000 | I3: 1806000 | J3: 1042000 | K3: 1042000 | L3: 643000 | M3: 0 | N3: 32000 | O3: 77000 | P3: 134000 | Q3: 247000 | R3: 75000 | S3: 78000 | T3: 121000
A4: 3001710 | B4: Absarokee Elem | C4: Montana | D4: MT | E4: 2017 | F4: 147 | G4: 147 | H4: 1745000 | I4: 1727000 | J4: 1008000 | K4: 1008000 | L4: 602000 | M4: 0 | N4: 27000 | O4: 84000 | P4: 148000 | Q4: 180000 | R4: 80000 | S4: 83000 | T4: 117000
A5: 3001710 | B5: Absarokee Elem | C5: Montana | D5: MT | E5: 2018 | F5: 150 | G5: 150 | H5: 1814000 | I5: 1806000 | J5: 1037000 | K5: 1037000 | L5: 639000 | M5: 0 | N5: 41000 | O5: 93000 | P5: 143000 | Q5: 188000 | R5: 92000 | S5: 82000 | T5: 130000
A6: 3001710 | B6: Absarokee Elem | C6: Montana | D6: MT | E6: 2019 | F6: 144 | G6: 144 | H6: 1757000 | I6: 1749000 | J6: 1025000 | K6: 1025000 | L6: 611000 | M6: 0 | N6: 28000 | O6: 104000 | P6: 72000 | Q6: 238000 | R6: 77000 | S6: 92000 | T6: 113000
A7: 3001710 | B7: Absarokee Elem | C7: Montana | D7: MT | E7: 2020 | F7: 127 | G7: 127 | H7: 1722000 | I7: 1669000 | J7: 1000000 | K7: 1000000 | L7: 579000 | M7: 0 | N7: 16000 | O7: 53000 | P7: 146000 | Q7: 225000 | R7: 65000 | S7: 74000 | T7: 90000
A8: 3001710 | B8: Absarokee Elem | C8: Montana | D8: MT | E8: 2021 | F8: 105 | G8: 105 | H8: 2100000 | I8: 2089000 | J8: 1177000 | K8: 1177000 | L8: 802000 | M8: 72000 | N8: 129000 | O8: 74000 | P8: 147000 | Q8: 239000 | R8: 61000 | S8: 80000 | T8: 110000
A9: 3001710 | B9: Absarokee Elem | C9: Montana | D9: MT | E9: 2022 | F9: 112 | G9: 112 | H9: 2089000 | I9: 1948000 | J9: 999000 | K9: 999000 | L9: 831000 | M9: 166000 | N9: 114000 | O9: 67000 | P9: 124000 | Q9: 211000 | R9: 67000 | S9: 82000 | T9: 118000
A10: 3001740 | B10: Absarokee H S | C10: Montana | D10: MT | E10: 2015 | F10: 81 | G10: 81 | H10: 1597000 | I10: 1560000 | J10: 1031000 | K10: 1031000 | L10: 488000 | M10: 0 | N10: 20000 | O10: 80000 | P10: 38000 | Q10: 184000 | R10: 95000 | S10: 71000 | T10: 41000 | V10: ABSAROKEE PUBLIC SCHOOLS | W10: =SUM(F2,F10) -> 250 | X10: =SUM(G2,G10) -> 250 | Y10: =SUM(H2,H10) -> 3615000 | Z10: =SUM(I2,I10) -> 3525000 | AA10: =SUM(J2,J10) -> 2193000 | AB10: =SUM(K2,K10) -> 2193000 | AC10: =SUM(L2,L10) -> 1165000 | AD10: =SUM(M2,M10) -> 2000 | ... AK10: =SUM(T2,T10) -> 167000
A11: 3001740 | B11: Absarokee H S | C11: Montana | D11: MT | E11: 2016 | F11: 87 | G11: 87 | H11: 1832000 | I11: 1784000 | J11: 1055000 | K11: 1055000 | L11: 684000 | M11: 0 | N11: 21000 | O11: 83000 | P11: 30000 | Q11: 392000 | R11: 82000 | S11: 76000 | T11: 45000 | V11: ABSAROKEE PUBLIC SCHOOLS | W11: =SUM(F3,F11) -> 242 | X11: =SUM(G3,G11) -> 242 | Y11: =SUM(H3,H11) -> 3684000 | Z11: =SUM(I3,I11) -> 3590000 | AA11: =SUM(J3,J11) -> 2097000 | AB11: =SUM(K3,K11) -> 2097000 | AC11: =SUM(L3,L11) -> 1327000 | AD11: =SUM(M3,M11) -> 0 | ... AK11: =SUM(T3,T11) -> 166000
A12: 3001740 | B12: Absarokee H S | C12: Montana | D12: MT | E12: 2017 | F12: 85 | G12: 85 | H12: 1658000 | I12: 1637000 | J12: 1052000 | K12: 1052000 | L12: 537000 | M12: 0 | N12: 21000 | O12: 84000 | P12: 31000 | Q12: 236000 | R12: 84000 | S12: 81000 | T12: 48000 | V12: ABSAROKEE PUBLIC SCHOOLS | W12: =SUM(F4,F12) -> 232 | X12: =SUM(G4,G12) -> 232 | Y12: =SUM(H4,H12) -> 3403000 | Z12: =SUM(I4,I12) -> 3364000 | AA12: =SUM(J4,J12) -> 2060000 | AB12: =SUM(K4,K12) -> 2060000 | AC12: =SUM(L4,L12) -> 1139000 | AD12: =SUM(M4,M12) -> 0 | ... AK12: =SUM(T4,T12) -> 165000
A13: 3001740 | B13: Absarokee H S | C13: Montana | D13: MT | E13: 2018 | F13: 92 | G13: 92 | H13: 1585000 | I13: 1579000 | J13: 1022000 | K13: 1022000 | L13: 511000 | M13: 0 | N13: 23000 | O13: 101000 | P13: 30000 | Q13: 179000 | R13: 95000 | S13: 83000 | T13: 46000 | V13: ABSAROKEE PUBLIC SCHOOLS | W13: =SUM(F5,F13) -> 242 | X13: =SUM(G5,G13) -> 242 | Y13: =SUM(H5,H13) -> 3399000 | Z13: =SUM(I5,I13) -> 3385000 | AA13: =SUM(J5,J13) -> 2059000 | AB13: =SUM(K5,K13) -> 2059000 | AC13: =SUM(L5,L13) -> 1150000 | AD13: =SUM(M5,M13) -> 0 | ... AK13: =SUM(T5,T13) -> 176000
A14: 3001740 | B14: Absarokee H S | C14: Montana | D14: MT | E14: 2019 | F14: 86 | G14: 86 | H14: 1923000 | I14: 1810000 | J14: 1182000 | K14: 1182000 | L14: 584000 | M14: 3000 | N14: 27000 | O14: 91000 | P14: 32000 | Q14: 258000 | R14: 80000 | S14: 93000 | T14: 44000 | V14: ABSAROKEE PUBLIC SCHOOLS | W14: =SUM(F6,F14) -> 230 | X14: =SUM(G6,G14) -> 230 | Y14: =SUM(H6,H14) -> 3680000 | Z14: =SUM(I6,I14) -> 3559000 | AA14: =SUM(J6,J14) -> 2207000 | AB14: =SUM(K6,K14) -> 2207000 | AC14: =SUM(L6,L14) -> 1195000 | AD14: =SUM(M6,M14) -> 3000 | ... AK14: =SUM(T6,T14) -> 157000
A15: 3001740 | B15: Absarokee H S | C15: Montana | D15: MT | E15: 2020 | F15: 80 | G15: 80 | H15: 1655000 | I15: 1608000 | J15: 1054000 | K15: 1054000 | L15: 515000 | M15: 0 | N15: 24000 | O15: 59000 | P15: 83000 | Q15: 209000 | R15: 66000 | S15: 74000 | T15: 39000 | V15: ABSAROKEE PUBLIC SCHOOLS | W15: =SUM(F7,F15) -> 207 | X15: =SUM(G7,G15) -> 207 | Y15: =SUM(H7,H15) -> 3377000 | Z15: =SUM(I7,I15) -> 3277000 | AA15: =SUM(J7,J15) -> 2054000 | AB15: =SUM(K7,K15) -> 2054000 | AC15: =SUM(L7,L15) -> 1094000 | AD15: =SUM(M7,M15) -> 0 | ... AK15: =SUM(T7,T15) -> 129000
A16: 3001740 | B16: Absarokee H S | C16: Montana | D16: MT | E16: 2021 | F16: 74 | G16: 74 | H16: 1511000 | I16: 1504000 | J16: 903000 | K16: 903000 | L16: 584000 | M16: 0 | N16: 5000 | O16: 79000 | P16: 88000 | Q16: 269000 | R16: 62000 | S16: 81000 | T16: 17000 | V16: ABSAROKEE PUBLIC SCHOOLS | W16: =SUM(F8,F16) -> 179 | X16: =SUM(G8,G16) -> 179 | Y16: =SUM(H8,H16) -> 3611000 | Z16: =SUM(I8,I16) -> 3593000 | AA16: =SUM(J8,J16) -> 2080000 | AB16: =SUM(K8,K16) -> 2080000 | AC16: =SUM(L8,L16) -> 1386000 | AD16: =SUM(M8,M16) -> 72000 | ... AK16: =SUM(T8,T16) -> 127000
A17: 3001740 | B17: Absarokee H S | C17: Montana | D17: MT | E17: 2022 | F17: 58 | G17: 58 | H17: 1607000 | I17: 1547000 | J17: 975000 | K17: 975000 | L17: 538000 | M17: 0 | N17: 2000 | O17: 66000 | P17: 151000 | Q17: 169000 | R17: 68000 | S17: 82000 | T17: 34000 | V17: ABSAROKEE PUBLIC SCHOOLS | W17: =SUM(F9,F17) -> 170 | X17: =SUM(G9,G17) -> 170 | Y17: =SUM(H9,H17) -> 3696000 | Z17: =SUM(I9,I17) -> 3495000 | AA17: =SUM(J9,J17) -> 1974000 | AB17: =SUM(K9,K17) -> 1974000 | AC17: =SUM(L9,L17) -> 1369000 | AD17: =SUM(M9,M17) -> 166000 | ... AK17: =SUM(T9,T17) -> 152000
A18: 3002010 | B18: Anaconda Elem | C18: Montana | D18: MT | E18: 2015 | F18: 751 | G18: 751 | H18: 8404000 | I18: 8358000 | J18: 4592000 | K18: 4592000 | L18: 3321000 | M18: 1057000 | N18: 358000 | O18: 157000 | P18: 551000 | Q18: 722000 | R18: 207000 | S18: 269000 | T18: 445000
A19: 3002010 | B19: Anaconda Elem | C19: Montana | D19: MT | E19: 2016 | F19: 745 | G19: 745 | H19: 9224000 | I19: 9117000 | J19: 5202000 | K19: 5202000 | L19: 3499000 | M19: 892000 | N19: 469000 | O19: 184000 | P19: 652000 | Q19: 852000 | R19: 207000 | S19: 243000 | T19: 416000
A20: 3002010 | B20: Anaconda Elem | C20: Montana | D20: MT | E20: 2017 | F20: 740 | G20: 740 | H20: 8825000 | I20: 8569000 | J20: 5058000 | K20: 5058000 | L20: 3084000 | M20: 897000 | N20: 346000 | O20: 186000 | P20: 508000 | Q20: 640000 | R20: 199000 | S20: 308000 | T20: 427000
A21: 3002010 | B21: Anaconda Elem | C21: Montana | D21: MT | E21: 2018 | F21: 787 | G21: 787 | H21: 11128000 | I21: 8962000 | J21: 5175000 | K21: 5175000 | L21: 3313000 | M21: 889000 | N21: 488000 | O21: 185000 | P21: 508000 | Q21: 548000 | R21: 193000 | S21: 502000 | T21: 474000
A22: 3002010 | B22: Anaconda Elem | C22: Montana | D22: MT | E22: 2019 | F22: 764 | G22: 764 | H22: 10016000 | I22: 9229000 | J22: 5303000 | K22: 5303000 | L22: 3410000 | M22: 1067000 | N22: 543000 | O22: 169000 | P22: 525000 | Q22: 557000 | R22: 196000 | S22: 353000 | T22: 516000
A23: 3002010 | B23: Anaconda Elem | C23: Montana | D23: MT | E23: 2020 | F23: 709 | G23: 709 | H23: 10210000 | I23: 9972000 | J23: 5493000 | K23: 5493000 | L23: 4002000 | M23: 1258000 | N23: 473000 | O23: 202000 | P23: 667000 | Q23: 789000 | R23: 244000 | S23: 369000 | T23: 477000
A24: 3002010 | B24: Anaconda Elem | C24: Montana | D24: MT | E24: 2021 | F24: 728 | G24: 728 | H24: 11090000 | I24: 10905000 | J24: 6771000 | K24: 6771000 | L24: 3546000 | M24: 850000 | N24: 351000 | O24: 237000 | P24: 538000 | Q24: 909000 | R24: 220000 | S24: 441000 | T24: 588000
A25: 3002010 | B25: Anaconda Elem | C25: Montana | D25: MT | E25: 2022 | F25: 766 | G25: 766 | H25: 12230000 | I25: 11895000 | J25: 7220000 | K25: 7220000 | L25: 3900000 | M25: 1174000 | N25: 414000 | O25: 200000 | P25: 527000 | Q25: 840000 | R25: 296000 | S25: 449000 | T25: 775000
A26: 3002030 | B26: Anaconda H S | C26: Montana | D26: MT | E26: 2015 | F26: 321 | G26: 321 | H26: 3631000 | I26: 3501000 | J26: 1766000 | K26: 1766000 | L26: 1735000 | M26: 184000 | N26: 85000 | O26: 158000 | P26: 376000 | Q26: 570000 | R26: 173000 | S26: 189000 | T26: 0 | V26: ANACONDA PUBLIC SCHOOLS | W26: =SUM(F18,F26) -> 1072 | X26: =SUM(G18,G26) -> 1072 | Y26: =SUM(H18,H26) -> 12035000 | Z26: =SUM(I18,I26) -> 11859000 | AA26: =SUM(J18,J26) -> 6358000 | AB26: =SUM(K18,K26) -> 6358000 | AC26: =SUM(L18,L26) -> 5056000 | AD26: =SUM(M18,M26) -> 1241000 | ... AK26: =SUM(T18,T26) -> 445000
A27: 3002030 | B27: Anaconda H S | C27: Montana | D27: MT | E27: 2016 | F27: 330 | G27: 330 | H27: 3902000 | I27: 3839000 | J27: 1880000 | K27: 1880000 | L27: 1938000 | M27: 208000 | N27: 92000 | O27: 172000 | P27: 308000 | Q27: 717000 | R27: 176000 | S27: 265000 | T27: 21000 | V27: ANACONDA PUBLIC SCHOOLS | W27: =SUM(F19,F27) -> 1075 | X27: =SUM(G19,G27) -> 1075 | Y27: =SUM(H19,H27) -> 13126000 | Z27: =SUM(I19,I27) -> 12956000 | AA27: =SUM(J19,J27) -> 7082000 | AB27: =SUM(K19,K27) -> 7082000 | AC27: =SUM(L19,L27) -> 5437000 | AD27: =SUM(M19,M27) -> 1100000 | ... AK27: =SUM(T19,T27) -> 437000
A28: 3002030 | B28: Anaconda H S | C28: Montana | D28: MT | E28: 2017 | F28: 327 | G28: 327 | H28: 4337000 | I28: 3784000 | J28: 1870000 | K28: 1870000 | L28: 1904000 | M28: 197000 | N28: 60000 | O28: 174000 | P28: 372000 | Q28: 664000 | R28: 205000 | S28: 232000 | T28: 10000 | V28: ANACONDA PUBLIC SCHOOLS | W28: =SUM(F20,F28) -> 1067 | X28: =SUM(G20,G28) -> 1067 | Y28: =SUM(H20,H28) -> 13162000 | Z28: =SUM(I20,I28) -> 12353000 | AA28: =SUM(J20,J28) -> 6928000 | AB28: =SUM(K20,K28) -> 6928000 | AC28: =SUM(L20,L28) -> 4988000 | AD28: =SUM(M20,M28) -> 1094000 | ... AK28: =SUM(T20,T28) -> 437000
A29: 3002030 | B29: Anaconda H S | C29: Montana | D29: MT | E29: 2018 | F29: 321 | G29: 321 | H29: 4568000 | I29: 3561000 | J29: 1897000 | K29: 1897000 | L29: 1654000 | M29: 179000 | N29: 90000 | O29: 169000 | P29: 324000 | Q29: 507000 | R29: 149000 | S29: 236000 | T29: 10000 | V29: ANACONDA PUBLIC SCHOOLS | W29: =SUM(F21,F29) -> 1108 | X29: =SUM(G21,G29) -> 1108 | Y29: =SUM(H21,H29) -> 15696000 | Z29: =SUM(I21,I29) -> 12523000 | AA29: =SUM(J21,J29) -> 7072000 | AB29: =SUM(K21,K29) -> 7072000 | AC29: =SUM(L21,L29) -> 4967000 | AD29: =SUM(M21,M29) -> 1068000 | ... AK29: =SUM(T21,T29) -> 484000
A30: 3002030 | B30: Anaconda H S | C30: Montana | D30: MT | E30: 2019 | F30: 311 | G30: 311 | H30: 4464000 | I30: 3690000 | J30: 1948000 | K30: 1948000 | L30: 1736000 | M30: 198000 | N30: 62000 | O30: 167000 | P30: 330000 | Q30: 573000 | R30: 140000 | S30: 266000 | T30: 6000 | V30: ANACONDA PUBLIC SCHOOLS | W30: =SUM(F22,F30) -> 1075 | X30: =SUM(G22,G30) -> 1075 | Y30: =SUM(H22,H30) -> 14480000 | Z30: =SUM(I22,I30) -> 12919000 | AA30: =SUM(J22,J30) -> 7251000 | AB30: =SUM(K22,K30) -> 7251000 | AC30: =SUM(L22,L30) -> 5146000 | AD30: =SUM(M22,M30) -> 1265000 | ... AK30: =SUM(T22,T30) -> 522000
A31: 3002030 | B31: Anaconda H S | C31: Montana | D31: MT | E31: 2020 | F31: 313 | G31: 313 | H31: 3675000 | I31: 3573000 | J31: 1910000 | K31: 1910000 | L31: 1660000 | M31: 225000 | N31: 51000 | O31: 237000 | P31: 331000 | Q31: 459000 | R31: 158000 | S31: 199000 | T31: 3000 | V31: ANACONDA PUBLIC SCHOOLS | W31: =SUM(F23,F31) -> 1022 | X31: =SUM(G23,G31) -> 1022 | Y31: =SUM(H23,H31) -> 13885000 | Z31: =SUM(I23,I31) -> 13545000 | AA31: =SUM(J23,J31) -> 7403000 | AB31: =SUM(K23,K31) -> 7403000 | AC31: =SUM(L23,L31) -> 5662000 | AD31: =SUM(M23,M31) -> 1483000 | ... AK31: =SUM(T23,T31) -> 480000
A32: 3002030 | B32: Anaconda H S | C32: Montana | D32: MT | E32: 2021 | F32: 309 | G32: 309 | H32: 3710000 | I32: 3675000 | J32: 2083000 | K32: 2083000 | L32: 1592000 | M32: 285000 | N32: 50000 | O32: 185000 | P32: 332000 | Q32: 360000 | R32: 142000 | S32: 238000 | T32: 0 | V32: ANACONDA PUBLIC SCHOOLS | W32: =SUM(F24,F32) -> 1037 | X32: =SUM(G24,G32) -> 1037 | Y32: =SUM(H24,H32) -> 14800000 | Z32: =SUM(I24,I32) -> 14580000 | AA32: =SUM(J24,J32) -> 8854000 | AB32: =SUM(K24,K32) -> 8854000 | AC32: =SUM(L24,L32) -> 5138000 | AD32: =SUM(M24,M32) -> 1135000 | ... AK32: =SUM(T24,T32) -> 588000
A33: 3002030 | B33: Anaconda H S | C33: Montana | D33: MT | E33: 2022 | F33: 293 | G33: 293 | H33: 3486000 | I33: 3456000 | J33: 2062000 | K33: 2062000 | L33: 1387000 | M33: 148000 | N33: 62000 | O33: 158000 | P33: 356000 | Q33: 327000 | R33: 157000 | S33: 179000 | T33: 7000 | V33: ANACONDA PUBLIC SCHOOLS | W33: =SUM(F25,F33) -> 1059 | X33: =SUM(G25,G33) -> 1059 | Y33: =SUM(H25,H33) -> 15716000 | Z33: =SUM(I25,I33) -> 15351000 | AA33: =SUM(J25,J33) -> 9282000 | AB33: =SUM(K25,K33) -> 9282000 | AC33: =SUM(L25,L33) -> 5287000 | AD33: =SUM(M25,M33) -> 1322000 | ... AK33: =SUM(T25,T33) -> 782000
A34: 3002220 | B34: Arlee Elem | C34: Montana | D34: MT | E34: 2015 | F34: 325 | G34: 325 | H34: 4519000 | I34: 4367000 | J34: 2971000 | K34: 2971000 | L34: 1164000 | M34: 117000 | N34: 140000 | O34: 91000 | P34: 163000 | Q34: 413000 | R34: 149000 | S34: 91000 | T34: 232000
A35: 3002220 | B35: Arlee Elem | C35: Montana | D35: MT | E35: 2016 | F35: 328 | G35: 328 | H35: 4810000 | I35: 4619000 | J35: 3191000 | K35: 3191000 | L35: 1160000 | M35: 105000 | N35: 116000 | O35: 86000 | P35: 158000 | Q35: 454000 | R35: 155000 | S35: 86000 | T35: 268000
A36: 3002220 | B36: Arlee Elem | C36: Montana | D36: MT | E36: 2017 | F36: 323 | G36: 323 | H36: 5030000 | I36: 4732000 | J36: 3204000 | K36: 3204000 | L36: 1255000 | M36: 81000 | N36: 159000 | O36: 92000 | P36: 175000 | Q36: 486000 | R36: 169000 | S36: 93000 | T36: 273000
A37: 3002220 | B37: Arlee Elem | C37: Montana | D37: MT | E37: 2018 | F37: 323 | G37: 323 | H37: 5047000 | I37: 4943000 | J37: 3360000 | K37: 3360000 | L37: 1304000 | M37: 79000 | N37: 133000 | O37: 118000 | P37: 226000 | Q37: 473000 | R37: 186000 | S37: 89000 | T37: 279000
A38: 3002220 | B38: Arlee Elem | C38: Montana | D38: MT | E38: 2019 | F38: 321 | G38: 321 | H38: 5193000 | I38: 4954000 | J38: 3120000 | K38: 3120000 | L38: 1518000 | M38: 90000 | N38: 216000 | O38: 100000 | P38: 255000 | Q38: 511000 | R38: 231000 | S38: 115000 | T38: 316000
A39: 3002220 | B39: Arlee Elem | C39: Montana | D39: MT | E39: 2020 | F39: 302 | G39: 302 | H39: 5204000 | I39: 4904000 | J39: 3131000 | K39: 3131000 | L39: 1469000 | M39: 117000 | N39: 265000 | O39: 123000 | P39: 206000 | Q39: 431000 | R39: 208000 | S39: 119000 | T39: 304000
A40: 3002220 | B40: Arlee Elem | C40: Montana | D40: MT | E40: 2021 | F40: 286 | G40: 286 | H40: 5692000 | I40: 5059000 | J40: 3006000 | K40: 3006000 | L40: 1662000 | M40: 144000 | N40: 295000 | O40: 105000 | P40: 234000 | Q40: 521000 | R40: 226000 | S40: 137000 | T40: 391000
...

Sheet Complete Dup Match NCES Data
A1: identifier | B1: NAME | C1: Year | D1: State | E1: state_abv | F1: district_contributions | G1: state_contributions | H1: total_contributions | I1: V33 | J1: MEMBERSCH | K1: TOTALEXP | L1: TCURELSC | M1: TCURINST | N1: E13 | O1: TCURSSVC | P1: E17 | Q1: E07 | R1: E08 | S1: E09 | T1: V40 | U1: V45 | V1: V90 | W1: E11
A2: =C2&B2 -> 2015ABSAROKEE PUBLIC SCHOOLS | B2: ABSAROKEE PUBLIC SCHOOLS | C2: 2015 | D2: Montana | E2: MT | F2: =VLOOKUP(A2,Final!$A$2:$J$3387,8,FALSE) -> 120631 | G2: =VLOOKUP(A2,Final!$A$2:$J$3387,9,FALSE) -> 81243 | H2: =VLOOKUP(A2,Final!$A$2:$J$3387,10,FALSE) -> 201874 | I2: 250 | J2: 250 | K2: 3615000 | L2: 3525000 | M2: 2193000 | N2: 2193000 | O2: 1165000 | P2: 2000 | Q2: 27000 | R2: 158000 | S2: 184000 | T2: 460000 | U2: 192000 | V2: 142000 | W2: 167000
A3: =C3&B3 -> 2016ABSAROKEE PUBLIC SCHOOLS | B3: ABSAROKEE PUBLIC SCHOOLS | C3: 2016 | D3: Montana | E3: MT | F3: =VLOOKUP(A3,Final!$A$2:$J$3387,8,FALSE) -> 118406 | G3: =VLOOKUP(A3,Final!$A$2:$J$3387,9,FALSE) -> 77343 | H3: =VLOOKUP(A3,Final!$A$2:$J$3387,10,FALSE) -> 195749 | I3: 242 | J3: 242 | K3: 3684000 | L3: 3590000 | M3: 2097000 | N3: 2097000 | O3: 1327000 | P3: 0 | Q3: 53000 | R3: 160000 | S3: 164000 | T3: 639000 | U3: 157000 | V3: 154000 | W3: 166000
A4: =C4&B4 -> 2017ABSAROKEE PUBLIC SCHOOLS | B4: ABSAROKEE PUBLIC SCHOOLS | C4: 2017 | D4: Montana | E4: MT | F4: =VLOOKUP(A4,Final!$A$2:$J$3387,8,FALSE) -> 124122 | G4: =VLOOKUP(A4,Final!$A$2:$J$3387,9,FALSE) -> 78802 | H4: =VLOOKUP(A4,Final!$A$2:$J$3387,10,FALSE) -> 202924 | I4: 232 | J4: 232 | K4: 3403000 | L4: 3364000 | M4: 2060000 | N4: 2060000 | O4: 1139000 | P4: 0 | Q4: 48000 | R4: 168000 | S4: 179000 | T4: 416000 | U4: 164000 | V4: 164000 | W4: 165000
A5: =C5&B5 -> 2018ABSAROKEE PUBLIC SCHOOLS | B5: ABSAROKEE PUBLIC SCHOOLS | C5: 2018 | D5: Montana | E5: MT | F5: =VLOOKUP(A5,Final!$A$2:$J$3387,8,FALSE) -> 124809 | G5: =VLOOKUP(A5,Final!$A$2:$J$3387,9,FALSE) -> 77839 | H5: =VLOOKUP(A5,Final!$A$2:$J$3387,10,FALSE) -> 202648 | I5: 242 | J5: 242 | K5: 3399000 | L5: 3385000 | M5: 2059000 | N5: 2059000 | O5: 1150000 | P5: 0 | Q5: 64000 | R5: 194000 | S5: 173000 | T5: 367000 | U5: 187000 | V5: 165000 | W5: 176000
A6: =C6&B6 -> 2019ABSAROKEE PUBLIC SCHOOLS | B6: ABSAROKEE PUBLIC SCHOOLS | C6: 2019 | D6: Montana | E6: MT | F6: =VLOOKUP(A6,Final!$A$2:$J$3387,8,FALSE) -> 122946 | G6: =VLOOKUP(A6,Final!$A$2:$J$3387,9,FALSE) -> 74508 | H6: =VLOOKUP(A6,Final!$A$2:$J$3387,10,FALSE) -> 197454 | I6: 230 | J6: 230 | K6: 3680000 | L6: 3559000 | M6: 2207000 | N6: 2207000 | O6: 1195000 | P6: 3000 | Q6: 55000 | R6: 195000 | S6: 104000 | T6: 496000 | U6: 157000 | V6: 185000 | W6: 157000
A7: =C7&B7 -> 2020ABSAROKEE PUBLIC SCHOOLS | B7: ABSAROKEE PUBLIC SCHOOLS | C7: 2020 | D7: Montana | E7: MT | F7: =VLOOKUP(A7,Final!$A$2:$J$3387,8,FALSE) -> 122004 | G7: =VLOOKUP(A7,Final!$A$2:$J$3387,9,FALSE) -> 72066 | H7: =VLOOKUP(A7,Final!$A$2:$J$3387,10,FALSE) -> 194070 | I7: 207 | J7: 207 | K7: 3377000 | L7: 3277000 | M7: 2054000 | N7: 2054000 | O7: 1094000 | P7: 0 | Q7: 40000 | R7: 112000 | S7: 229000 | T7: 434000 | U7: 131000 | V7: 148000 | W7: 129000
A8: =C8&B8 -> 2021ABSAROKEE PUBLIC SCHOOLS | B8: ABSAROKEE PUBLIC SCHOOLS | C8: 2021 | D8: Montana | E8: MT | F8: =VLOOKUP(A8,Final!$A$2:$J$3387,8,FALSE) -> 135525 | G8: =VLOOKUP(A8,Final!$A$2:$J$3387,9,FALSE) -> 77284 | H8: =VLOOKUP(A8,Final!$A$2:$J$3387,10,FALSE) -> 212809 | I8: 179 | J8: 179 | K8: 3611000 | L8: 3593000 | M8: 2080000 | N8: 2080000 | O8: 1386000 | P8: 72000 | Q8: 134000 | R8: 153000 | S8: 235000 | T8: 508000 | U8: 123000 | V8: 161000 | W8: 127000
A9: =C9&B9 -> 2022ABSAROKEE PUBLIC SCHOOLS | B9: ABSAROKEE PUBLIC SCHOOLS | C9: 2022 | D9: Montana | E9: MT | F9: =VLOOKUP(A9,Final!$A$2:$J$3387,8,FALSE) -> 128472 | G9: =VLOOKUP(A9,Final!$A$2:$J$3387,9,FALSE) -> 70848 | H9: =VLOOKUP(A9,Final!$A$2:$J$3387,10,FALSE) -> 199320 | I9: 170 | J9: 170 | K9: 3696000 | L9: 3495000 | M9: 1974000 | N9: 1974000 | O9: 1369000 | P9: 166000 | Q9: 116000 | R9: 133000 | S9: 275000 | T9: 380000 | U9: 135000 | V9: 164000 | W9: 152000
A10: =C10&B10 -> 2015ANACONDA PUBLIC SCHOOLS | B10: ANACONDA PUBLIC SCHOOLS | C10: 2015 | D10: Montana | E10: MT | F10: =VLOOKUP(A10,Final!$A$2:$J$3387,8,FALSE) -> 447604 | G10: =VLOOKUP(A10,Final!$A$2:$J$3387,9,FALSE) -> 300111 | H10: =VLOOKUP(A10,Final!$A$2:$J$3387,10,FALSE) -> 747715 | I10: 1072 | J10: 1072 | K10: 12035000 | L10: 11859000 | M10: 6358000 | N10: 6358000 | O10: 5056000 | P10: 1241000 | Q10: 443000 | R10: 315000 | S10: 927000 | T10: 1292000 | U10: 380000 | V10: 458000 | W10: 445000
A11: =C11&B11 -> 2016ANACONDA PUBLIC SCHOOLS | B11: ANACONDA PUBLIC SCHOOLS | C11: 2016 | D11: Montana | E11: MT | F11: =VLOOKUP(A11,Final!$A$2:$J$3387,8,FALSE) -> 472023 | G11: =VLOOKUP(A11,Final!$A$2:$J$3387,9,FALSE) -> 307700 | H11: =VLOOKUP(A11,Final!$A$2:$J$3387,10,FALSE) -> 779723 | I11: 1075 | J11: 1075 | K11: 13126000 | L11: 12956000 | M11: 7082000 | N11: 7082000 | O11: 5437000 | P11: 1100000 | Q11: 561000 | R11: 356000 | S11: 960000 | T11: 1569000 | U11: 383000 | V11: 508000 | W11: 437000
A12: =C12&B12 -> 2017ANACONDA PUBLIC SCHOOLS | B12: ANACONDA PUBLIC SCHOOLS | C12: 2017 | D12: Montana | E12: MT | F12: =VLOOKUP(A12,Final!$A$2:$J$3387,8,FALSE) -> 512744 | G12: =VLOOKUP(A12,Final!$A$2:$J$3387,9,FALSE) -> 325481 | H12: =VLOOKUP(A12,Final!$A$2:$J$3387,10,FALSE) -> 838225 | I12: 1067 | J12: 1067 | K12: 13162000 | L12: 12353000 | M12: 6928000 | N12: 6928000 | O12: 4988000 | P12: 1094000 | Q12: 406000 | R12: 360000 | S12: 880000 | T12: 1304000 | U12: 404000 | V12: 540000 | W12: 437000
A13: =C13&B13 -> 2018ANACONDA PUBLIC SCHOOLS | B13: ANACONDA PUBLIC SCHOOLS | C13: 2018 | D13: Montana | E13: MT | F13: =VLOOKUP(A13,Final!$A$2:$J$3387,8,FALSE) -> 508155 | G13: =VLOOKUP(A13,Final!$A$2:$J$3387,9,FALSE) -> 315893 | H13: =VLOOKUP(A13,Final!$A$2:$J$3387,10,FALSE) -> 824048 | I13: 1108 | J13: 1108 | K13: 15696000 | L13: 12523000 | M13: 7072000 | N13: 7072000 | O13: 4967000 | P13: 1068000 | Q13: 578000 | R13: 354000 | S13: 832000 | T13: 1055000 | U13: 342000 | V13: 738000 | W13: 484000
... A681: =C681&B681 -> 2022WOLF POINT PUBLIC SCHOOLS | B681: WOLF POINT PUBLIC SCHOOLS | C681: 2022 | D681: Montana | E681: MT | F681: =VLOOKUP(A681,Final!$A$2:$J$3387,8,FALSE) -> 435104 | G681: =VLOOKUP(A681,Final!$A$2:$J$3387,9,FALSE) -> 240249 | H681: =VLOOKUP(A681,Final!$A$2:$J$3387,10,FALSE) -> 675353 | I681: 767 | J681: 767 | K681: 13597000 | L681: 12084000 | M681: 6692000 | N681: 6692000 | O681: 4808000 | P681: 1107000 | Q681: 395000 | R681: 458000 | S681: 753000 | T681: 1256000 | U681: 165000 | V681: 674000 | W681: 584000

Sheet Collection -->

Sheet Data As Collected
A1: year | B1: code | C1: employer | D1: contributions
A2: 2015 | B2: 10071 | C2: GRANT ELEMENTARY | D2: 4996
A3: 2015 | B3: 10071 | C3: States Proportionate Share | D3: 3840
A4: 2015 | B4: 10101 | C4: DILLON ELEMENTARY | D4: 290107
A5: 2015 | B5: 10101 | C5: States Proportionate Share | D5: 194686
A6: 2015 | B6: 10111 | C6: WISE RIVER ELEMENTARY | D6: 5906
A7: 2015 | B7: 10111 | C7: States Proportionate Share | D7: 4449
A8: 2015 | B8: 10121 | C8: LIMA K-12 SCHOOL | D8: 41357
A9: 2015 | B9: 10121 | C9: States Proportionate Share | D9: 28179
A10: 2015 | B10: 10161 | C10: WISDOM ELEMENTARY | D10: 5151
A11: 2015 | B11: 10161 | C11: States Proportionate Share | D11: 3944
A12: 2015 | B12: 10211 | C12: POLARIS ELEMENTARY | D12: -
A13: 2015 | B13: 10211 | C13: States Proportionate Share | D13: -
A14: 2015 | B14: 10241 | C14: JACKSON ELEMENTARY | D14: 4259
A15: 2015 | B15: 10241 | C15: States Proportionate Share | D15: 3347
A16: 2015 | B16: 10261 | C16: REICHLE ELEMENTARY | D16: 5925
A17: 2015 | B17: 10261 | C17: States Proportionate Share | D17: 4462
A18: 2015 | B18: 19981 | C18: BEAVERHEAD COUNTY HIGH SCHOOL | D18: 154694
A19: 2015 | B19: 19981 | C19: States Proportionate Share | D19: 104044
A20: 2015 | B20: 20011 | C20: SPRING CREEK ELEMENTARY | D20: 3873
A21: 2015 | B21: 20011 | C21: States Proportionate Share | D21: 3088
A22: 2015 | B22: 20021 | C22: PRYOR SCHOOL DISTRICT | D22: 71088
A23: 2015 | B23: 20021 | C23: States Proportionate Share | D23: 48081
A24: 2015 | B24: 20171 | C24: HARDIN PUBLIC SCHOOL | D24: 877877
A25: 2015 | B25: 20171 | C25: States Proportionate Share | D25: 588125
... A71: 2015 | B71: 60561 | C71: States Proportionate Share | D71: 2102
A72: 2015 | B72: 69991 | C72: CLERK AND RECORDER | D72: -
A73: 2015 | B73: 69991 | C73: States Proportionate Share | D73: -
A74: 2015 | B74: 70011 | C74: GREAT FALLS PUBLIC SCHOOLS | D74: 4286586
A75: 2015 | B75: 70011 | C75: States Proportionate Share | D75: 2869832
A76: 2015 | B76: 70031 | C76: CASCADE PUBLIC SCHOOLS | D76: 125052
A77: 2015 | B77: 70031 | C77: States Proportionate Share | D77: 84203
A78: 2015 | B78: 70051 | C78: CENTERVILLE PUBLIC SCHOOLS | D78: 113827
A79: 2015 | B79: 70051 | C79: States Proportionate Share | D79: 76689
A80: 2015 | B80: 70291 | C80: BELT PUBLIC SCHOOLS | D80: 131726
A81: 2015 | B81: 70291 | C81: States Proportionate Share | D81: 88670
A82: 2015 | B82: 70551 | C82: SUN RIVER VALLEY PUBLIC SCHLS | D82: 121846
A83: 2015 | B83: 70551 | C83: States Proportionate Share | D83: 82057
A84: 2015 | B84: 70741 | C84: VAUGHN ELEMENTARY | D84: 48827
A85: 2015 | B85: 70741 | C85: States Proportionate Share | D85: 33180
...

Sheet Only State
A1: year | B1: code | C1: employer | D1: state_contributions
A2: 2015 | B2: 10071 | C2: States Proportionate Share | D2: 3840
A3: 2015 | B3: 10101 | C3: States Proportionate Share | D3: 194686
A4: 2015 | B4: 10111 | C4: States Proportionate Share | D4: 4449
A5: 2015 | B5: 10121 | C5: States Proportionate Share | D5: 28179
A6: 2015 | B6: 10161 | C6: States Proportionate Share | D6: 3944
A7: 2015 | B7: 10211 | C7: States Proportionate Share | D7: -
A8: 2015 | B8: 10241 | C8: States Proportionate Share | D8: 3347
A9: 2015 | B9: 10261 | C9: States Proportionate Share | D9: 4462
A10: 2015 | B10: 19981 | C10: States Proportionate Share | D10: 104044
A11: 2015 | B11: 20011 | C11: States Proportionate Share | D11: 3088
A12: 2015 | B12: 20021 | C12: States Proportionate Share | D12: 48081
A13: 2015 | B13: 20171 | C13: States Proportionate Share | D13: 588125
A14: 2015 | B14: 20271 | C14: States Proportionate Share | D14: 112148
A15: 2015 | B15: 20291 | C15: States Proportionate Share | D15: 44621
A16: 2015 | B16: 30061 | C16: States Proportionate Share | D16: 2511
A17: 2015 | B17: 30101 | C17: States Proportionate Share | D17: 99648
A18: 2015 | B18: 30121 | C18: States Proportionate Share | D18: 192899
A19: 2015 | B19: 30141 | C19: States Proportionate Share | D19: 2606
... A36: 2015 | B36: 60561 | C36: States Proportionate Share | D36: 2102
A37: 2015 | B37: 69991 | C37: States Proportionate Share | D37: -
A38: 2015 | B38: 70011 | C38: States Proportionate Share | D38: 2869832
A39: 2015 | B39: 70031 | C39: States Proportionate Share | D39: 84203
A40: 2015 | B40: 70051 | C40: States Proportionate Share | D40: 76689
A41: 2015 | B41: 70291 | C41: States Proportionate Share | D41: 88670
A42: 2015 | B42: 70551 | C42: States Proportionate Share | D42: 82057
A43: 2015 | B43: 70741 | C43: States Proportionate Share | D43: 33180
A44: 2015 | B44: 70851 | C44: States Proportionate Share | D44: 25877
A45: 2015 | B45: 79951 | C45: States Proportionate Share | D45: 22739
A46: 2015 | B46: 79991 | C46: States Proportionate Share | D46: 2748
A47: 2015 | B47: 80011 | C47: States Proportionate Share | D47: 84135
A48: 2015 | B48: 80111 | C48: States Proportionate Share | D48: 48623
A49: 2015 | B49: 80281 | C49: States Proportionate Share | D49: 36996
... A107: 2015 | B107: 159951 | C107: States Proportionate Share | D107: 27808
A108: 2015 | B108: 159961 | C108: States Proportionate Share | D108: -
A109: 2015 | B109: 159971 | C109: States Proportionate Share | D109: 309089
A110: 2015 | B110: 159991 | C110: States Proportionate Share | D110: 2543
A111: 2015 | B111: 160031 | C111: States Proportionate Share | D111: 161420
A112: 2015 | B112: 160071 | C112: States Proportionate Share | D112: 1804678
A113: 2015 | B113: 160151 | C113: States Proportionate Share | D113: 26110
...

Sheet Unique Check
A1: 10071 | B1: GRANT ELEMENTARY | C1: =_xlfn.TEXTJOIN("*",TRUE,A1:B1) -> 10071*GRANT ELEMENTARY | E1: {=_xlfn.UNIQUE(C:C)} -> 10071*GRANT ELEMENTARY | H1: 10071 | I1: GRANT ELEMENTARY | K1: {=_xlfn.UNIQUE(A:A)} -> 10071 | L1: {=_xlfn.UNIQUE(B:B)} -> GRANT ELEMENTARY | M1: =H1=K1 -> TRUE | N1: =I1=L1 -> TRUE
A2: 10071 | B2: GRANT ELEMENTARY | C2: =_xlfn.TEXTJOIN("*",TRUE,A2:B2) -> 10071*GRANT ELEMENTARY | E2: 10101*DILLON ELEMENTARY | H2: 10101 | I2: DILLON ELEMENTARY | K2: 10101 | L2: DILLON ELEMENTARY | M2: =H2=K2 -> TRUE | N2: =I2=L2 -> TRUE
A3: 10071 | B3: GRANT ELEMENTARY | C3: =_xlfn.TEXTJOIN("*",TRUE,A3:B3) -> 10071*GRANT ELEMENTARY | E3: 10111*WISE RIVER ELEMENTARY | H3: 10111 | I3: WISE RIVER ELEMENTARY | K3: 10111 | L3: WISE RIVER ELEMENTARY | M3: =H3=K3 -> TRUE | N3: =I3=L3 -> TRUE
A4: 10071 | B4: GRANT ELEMENTARY | C4: =_xlfn.TEXTJOIN("*",TRUE,A4:B4) -> 10071*GRANT ELEMENTARY | E4: 10121*LIMA K-12 SCHOOL | H4: 10121 | I4: LIMA K-12 SCHOOL | K4: 10121 | L4: LIMA K-12 SCHOOL | M4: =H4=K4 -> TRUE | N4: =I4=L4 -> TRUE
A5: 10071 | B5: GRANT ELEMENTARY | C5: =_xlfn.TEXTJOIN("*",TRUE,A5:B5) -> 10071*GRANT ELEMENTARY | E5: 10161*WISDOM ELEMENTARY | H5: 10161 | I5: WISDOM ELEMENTARY | K5: 10161 | L5: WISDOM ELEMENTARY | M5: =H5=K5 -> TRUE | N5: =I5=L5 -> TRUE
A6: 10071 | B6: GRANT ELEMENTARY | C6: =_xlfn.TEXTJOIN("*",TRUE,A6:B6) -> 10071*GRANT ELEMENTARY | E6: 10211*POLARIS ELEMENTARY | H6: 10211 | I6: POLARIS ELEMENTARY | K6: 10211 | L6: POLARIS ELEMENTARY | M6: =H6=K6 -> TRUE | N6: =I6=L6 -> TRUE
A7: 10071 | B7: GRANT ELEMENTARY | C7: =_xlfn.TEXTJOIN("*",TRUE,A7:B7) -> 10071*GRANT ELEMENTARY | E7: 10241*JACKSON ELEMENTARY | H7: 10241 | I7: JACKSON ELEMENTARY | K7: 10241 | L7: JACKSON ELEMENTARY | M7: =H7=K7 -> TRUE | N7: =I7=L7 -> TRUE
A8: 10071 | B8: GRANT ELEMENTARY | C8: =_xlfn.TEXTJOIN("*",TRUE,A8:B8) -> 10071*GRANT ELEMENTARY | E8: 10261*REICHLE ELEMENTARY | H8: 10261 | I8: REICHLE ELEMENTARY | K8: 10261 | L8: REICHLE ELEMENTARY | M8: =H8=K8 -> TRUE | N8: =I8=L8 -> TRUE
A9: 10071 | B9: GRANT ELEMENTARY | C9: =_xlfn.TEXTJOIN("*",TRUE,A9:B9) -> 10071*GRANT ELEMENTARY | E9: 19981*BEAVERHEAD COUNTY HIGH SCHOOL | H9: 19981 | I9: BEAVERHEAD COUNTY HIGH SCHOOL | K9: 19981 | L9: BEAVERHEAD COUNTY HIGH SCHOOL | M9: =H9=K9 -> TRUE | N9: =I9=L9 -> TRUE
A10: 10101 | B10: DILLON ELEMENTARY | C10: =_xlfn.TEXTJOIN("*",TRUE,A10:B10) -> 10101*DILLON ELEMENTARY | E10: 20011*SPRING CREEK ELEMENTARY (20011) | H10: 20011 | I10: SPRING CREEK ELEMENTARY (20011) | K10: 20011 | L10: SPRING CREEK ELEMENTARY (20011) | M10: =H10=K10 -> TRUE | N10: =I10=L10 -> TRUE
A11: 10101 | B11: DILLON ELEMENTARY | C11: =_xlfn.TEXTJOIN("*",TRUE,A11:B11) -> 10101*DILLON ELEMENTARY | E11: 20021*PRYOR SCHOOL DISTRICT | H11: 20021 | I11: PRYOR SCHOOL DISTRICT | K11: 20021 | L11: PRYOR SCHOOL DISTRICT | M11: =H11=K11 -> TRUE | N11: =I11=L11 -> TRUE
A12: 10101 | B12: DILLON ELEMENTARY | C12: =_xlfn.TEXTJOIN("*",TRUE,A12:B12) -> 10101*DILLON ELEMENTARY | E12: 20171*HARDIN PUBLIC SCHOOL | H12: 20171 | I12: HARDIN PUBLIC SCHOOL | K12: 20171 | L12: HARDIN PUBLIC SCHOOL | M12: =H12=K12 -> TRUE | N12: =I12=L12 -> TRUE
A13: 10101 | B13: DILLON ELEMENTARY | C13: =_xlfn.TEXTJOIN("*",TRUE,A13:B13) -> 10101*DILLON ELEMENTARY | E13: 20271*LODGE GRASS PUBLIC SCHOOLS | H13: 20271 | I13: LODGE GRASS PUBLIC SCHOOLS | K13: 20271 | L13: LODGE GRASS PUBLIC SCHOOLS | M13: =H13=K13 -> TRUE | N13: =I13=L13 -> TRUE
... A384: 70741 | B384: VAUGHN ELEMENTARY | C384: =_xlfn.TEXTJOIN("*",TRUE,A384:B384) -> 70741*VAUGHN ELEMENTARY | E384: 729905*RESA REGION 5 | H384: 729905 | I384: RESA REGION 5 | K384: 729905 | L384: RESA REGION 5 | M384: =H384=K384 -> TRUE | N384: =I384=L384 -> TRUE
A385: 70741 | B385: VAUGHN ELEMENTARY | C385: =_xlfn.TEXTJOIN("*",TRUE,A385:B385) -> 70741*VAUGHN ELEMENTARY | E385: 0 | H385: 0 | K385: 0 | L385: 0 | M385: =H385=K385 -> TRUE | N385: =I385=L385 -> TRUE
A386: 70741 | B386: VAUGHN ELEMENTARY | C386: =_xlfn.TEXTJOIN("*",TRUE,A386:B386) -> 70741*VAUGHN ELEMENTARY
A387: 70741 | B387: VAUGHN ELEMENTARY | C387: =_xlfn.TEXTJOIN("*",TRUE,A387:B387) -> 70741*VAUGHN ELEMENTARY
A388: 70741 | B388: VAUGHN ELEMENTARY | C388: =_xlfn.TEXTJOIN("*",TRUE,A388:B388) -> 70741*VAUGHN ELEMENTARY
A389: 70741 | B389: VAUGHN ELEMENTARY | C389: =_xlfn.TEXTJOIN("*",TRUE,A389:B389) -> 70741*VAUGHN ELEMENTARY
A390: 70741 | B390: VAUGHN ELEMENTARY | C390: =_xlfn.TEXTJOIN("*",TRUE,A390:B390) -> 70741*VAUGHN ELEMENTARY
A391: 70741 | B391: VAUGHN ELEMENTARY | C391: =_xlfn.TEXTJOIN("*",TRUE,A391:B391) -> 70741*VAUGHN ELEMENTARY
A392: 70851 | B392: ULM ELEMENTARY | C392: =_xlfn.TEXTJOIN("*",TRUE,A392:B392) -> 70851*ULM ELEMENTARY
A393: 70851 | B393: ULM ELEMENTARY | C393: =_xlfn.TEXTJOIN("*",TRUE,A393:B393) -> 70851*ULM ELEMENTARY
A394: 70851 | B394: ULM ELEMENTARY | C394: =_xlfn.TEXTJOIN("*",TRUE,A394:B394) -> 70851*ULM ELEMENTARY
A395: 70851 | B395: ULM ELEMENTARY | C395: =_xlfn.TEXTJOIN("*",TRUE,A395:B395) -> 70851*ULM ELEMENTARY
A396: 70851 | B396: ULM ELEMENTARY | C396: =_xlfn.TEXTJOIN("*",TRUE,A396:B396) -> 70851*ULM ELEMENTARY
A397: 70851 | B397: ULM ELEMENTARY | C397: =_xlfn.TEXTJOIN("*",TRUE,A397:B397) -> 70851*ULM ELEMENTARY
... A3386: 729905 | B3386: RESA REGION 5 | C3386: =_xlfn.TEXTJOIN("*",TRUE,A3386:B3386) -> 729905*RESA REGION 5
