Workbook

Sheet Full Data
A1: LEAID | B1: Year | C1: Employer | D1: ID | E1: County | F1: Allocation
A2: =IFERROR(VLOOKUP(C2,'GASB Match'!$D$2:$F$6042,3,FALSE),"") | B2: 2015 | C2: 100 Legacy Academy Charter School | D2: 6105 | E2: Essex | F2: 9100
A3: =IFERROR(VLOOKUP(C3,'GASB Match'!$D$2:$F$6042,3,FALSE),"") -> 3400660 | B3: 2015 | C3: Absecon Bd of Ed | D3: 1020 | E3: Atlantic | F3: 282904
A4: =IFERROR(VLOOKUP(C4,'GASB Match'!$D$2:$F$6042,3,FALSE),"") -> 3400660 | B4: 2016 | C4: Absecon Bd of Ed | D4: 1020 | E4: Atlantic | F4: 418086
A5: =IFERROR(VLOOKUP(C5,'GASB Match'!$D$2:$F$6042,3,FALSE),"") -> 3400660 | B5: 2018 | C5: ABSECON BD OF ED | D5: 1020 | E5: ATLANTIC | F5: 791517
A6: =IFERROR(VLOOKUP(C6,'GASB Match'!$D$2:$F$6042,3,FALSE),"") -> 3400660 | B6: 2019 | C6: ABSECON BD OF ED | D6: 1020 | E6: ATLANTIC | F6: 1113713
A7: =IFERROR(VLOOKUP(C7,'GASB Match'!$D$2:$F$6042,3,FALSE),"") -> 3400660 | B7: 2020 | C7: ABSECON BD OF ED | D7: 1020 | E7: ATLANTIC | F7: 1228260
A8: =IFERROR(VLOOKUP(C8,'GASB Match'!$D$2:$F$6042,3,FALSE),"") -> 3400660 | B8: 2021 | C8: ABSECON BD OF ED | D8: 1020 | E8: ATLANTIC | F8: 1670181
A9: =IFERROR(VLOOKUP(C9,'GASB Match'!$D$2:$F$6042,3,FALSE),"") -> 3400660 | B9: 2022 | C9: ABSECON BD OF ED | D9: 1020 | E9: ATLANTIC | F9: 2498460
A10: =IFERROR(VLOOKUP(C10,'GASB Match'!$D$2:$F$6042,3,FALSE),"") -> 3400660 | B10: 2023 | C10: ABSECON BD OF ED | D10: 1020 | E10: ATLANTIC | F10: 2580589
A11: =IFERROR(VLOOKUP(C11,'GASB Match'!$D$2:$F$6042,3,FALSE),"") -> 3400660 | B11: 2017 | C11: Absecon Bd of Ed | D11: 1020 | E11: Atlantic | F11: 606121
A12: =IFERROR(VLOOKUP(C12,'GASB Match'!$D$2:$F$6042,3,FALSE),"") -> 3400048 | B12: 2015 | C12: Academy Charter High School | D12: 311 | E12: Monmouth | F12: 73554
A13: =IFERROR(VLOOKUP(C13,'GASB Match'!$D$2:$F$6042,3,FALSE),"") -> 3400048 | B13: 2016 | C13: Academy Charter High School | D13: 311 | E13: Monmouth | F13: 107688
... A2582: =IFERROR(VLOOKUP(C2582,'GASB Match'!$D$2:$F$6042,3,FALSE),"") -> 3400748 | B2582: 2017 | C2582: John P Holland Charter School | D2582: 662 | E2582: Passaic | F2582: 108886
A2583: =IFERROR(VLOOKUP(C2583,'GASB Match'!$D$2:$F$6042,3,FALSE),"") | B2583: 2015 | C2583: Kean University | D2583: 90412 | F2583: 185803
A2584: =IFERROR(VLOOKUP(C2584,'GASB Match'!$D$2:$F$6042,3,FALSE),"") | B2584: 2016 | C2584: Kean University | D2584: 90412 | F2584: 71938
A2585: =IFERROR(VLOOKUP(C2585,'GASB Match'!$D$2:$F$6042,3,FALSE),"") | B2585: 2018 | C2585: KEAN UNIVERSITY | D2585: 90412 | F2585: 128587
A2586: =IFERROR(VLOOKUP(C2586,'GASB Match'!$D$2:$F$6042,3,FALSE),"") | B2586: 2019 | C2586: KEAN UNIVERSITY | D2586: 90412 | F2586: 164536
A2587: =IFERROR(VLOOKUP(C2587,'GASB Match'!$D$2:$F$6042,3,FALSE),"") | B2587: 2020 | C2587: KEAN UNIVERSITY | D2587: 90412 | F2587: 161198
A2588: =IFERROR(VLOOKUP(C2588,'GASB Match'!$D$2:$F$6042,3,FALSE),"") | B2588: 2021 | C2588: KEAN UNIVERSITY | D2588: 90412 | F2588: 186039
A2589: =IFERROR(VLOOKUP(C2589,'GASB Match'!$D$2:$F$6042,3,FALSE),"") | B2589: 2022 | C2589: KEAN UNIVERSITY | D2589: 90412 | F2589: 261984
A2590: =IFERROR(VLOOKUP(C2590,'GASB Match'!$D$2:$F$6042,3,FALSE),"") | B2590: 2023 | C2590: KEAN UNIVERSITY | D2590: 90412 | F2590: 206187
A2591: =IFERROR(VLOOKUP(C2591,'GASB Match'!$D$2:$F$6042,3,FALSE),"") | B2591: 2017 | C2591: Kean University | D2591: 90412 | F2591: 100504
A2592: =IFERROR(VLOOKUP(C2592,'GASB Match'!$D$2:$F$6042,3,FALSE),"") -> 3407860 | B2592: 2015 | C2592: Keansburg Board of Education | D2592: 336 | E2592: =#REF! -> #REF! | F2592: 903488
A2593: =IFERROR(VLOOKUP(C2593,'GASB Match'!$D$2:$F$6042,3,FALSE),"") -> 3407860 | B2593: 2016 | C2593: Keansburg Board of Education | D2593: 336 | E2593: =#REF! -> #REF! | F2593: 1295339
A2594: =IFERROR(VLOOKUP(C2594,'GASB Match'!$D$2:$F$6042,3,FALSE),"") -> 3407860 | B2594: 2018 | C2594: KEANSBURG BOARD OF EDUCATION | D2594: 336 | E2594: =#REF! -> #REF! | F2594: 2401634
A2595: =IFERROR(VLOOKUP(C2595,'GASB Match'!$D$2:$F$6042,3,FALSE),"") -> 3407860 | B2595: 2019 | C2595: KEANSBURG BOARD OF EDUCATION | D2595: 336 | E2595: =#REF! -> #REF! | F2595: 3249428
A2596: =IFERROR(VLOOKUP(C2596,'GASB Match'!$D$2:$F$6042,3,FALSE),"") -> 3407860 | B2596: 2020 | C2596: KEANSBURG BOARD OF EDUCATION | D2596: 336 | E2596: =#REF! -> #REF! | F2596: 3660371
A2597: =IFERROR(VLOOKUP(C2597,'GASB Match'!$D$2:$F$6042,3,FALSE),"") -> 3407860 | B2597: 2021 | C2597: KEANSBURG BOARD OF EDUCATION | D2597: 336 | E2597: =#REF! -> #REF! | F2597: 4631461
A2598: =IFERROR(VLOOKUP(C2598,'GASB Match'!$D$2:$F$6042,3,FALSE),"") -> 3407860 | B2598: 2022 | C2598: KEANSBURG BOARD OF EDUCATION | D2598: 336 | E2598: =#REF! -> #REF! | F2598: 6288746
A2599: =IFERROR(VLOOKUP(C2599,'GASB Match'!$D$2:$F$6042,3,FALSE),"") -> 3407860 | B2599: 2023 | C2599: KEANSBURG BOARD OF EDUCATION | D2599: 336 | E2599: =#REF! -> #REF! | F2599: 5607968
A2600: =IFERROR(VLOOKUP(C2600,'GASB Match'!$D$2:$F$6042,3,FALSE),"") -> 3407860 | B2600: 2017 | C2600: Keansburg Board of Education | D2600: 336 | E2600: =#REF! -> #REF! | F2600: 1770063
A2601: =IFERROR(VLOOKUP(C2601,'GASB Match'!$D$2:$F$6042,3,FALSE),"") -> 3407890 | B2601: 2015 | C2601: Kearny Town Bd of Ed | D2601: 8030 | E2601: =#REF! -> #REF! | F2601: 2088031
A2602: =IFERROR(VLOOKUP(C2602,'GASB Match'!$D$2:$F$6042,3,FALSE),"") -> 3407890 | B2602: 2016 | C2602: Kearny Town Bd of Ed | D2602: 8030 | E2602: =#REF! -> #REF! | F2602: 3174228
A2603: =IFERROR(VLOOKUP(C2603,'GASB Match'!$D$2:$F$6042,3,FALSE),"") -> 3407890 | B2603: 2018 | C2603: KEARNY TOWN BD OF ED | D2603: 8030 | E2603: =#REF! -> #REF! | F2603: 5695362
... A3493: =IFERROR(VLOOKUP(C3493,'GASB Match'!$D$2:$F$6042,3,FALSE),"") -> 3410560 | B3493: 2017 | C3493: Montclair Bd of Ed | D3493: 6050 | E3493: =#REF! -> #REF! | F3493: 6078033
A3494: =IFERROR(VLOOKUP(C3494,'GASB Match'!$D$2:$F$6042,3,FALSE),"") | B3494: 2015 | C3494: Montclair State University | D3494: 90414 | F3494: 146149
A3495: =IFERROR(VLOOKUP(C3495,'GASB Match'!$D$2:$F$6042,3,FALSE),"") | B3495: 2016 | C3495: Montclair State University | D3495: 90414 | F3495: 43076
A3496: =IFERROR(VLOOKUP(C3496,'GASB Match'!$D$2:$F$6042,3,FALSE),"") | B3496: 2018 | C3496: MONTCLAIR STATE UNIVERSITY | D3496: 90414 | F3496: 75954
A3497: =IFERROR(VLOOKUP(C3497,'GASB Match'!$D$2:$F$6042,3,FALSE),"") | B3497: 2019 | C3497: MONTCLAIR STATE UNIVERSITY | D3497: 90414 | F3497: 96378
...

Sheet Other Data -->

Sheet GASB Match
A1: LEAID | B1: Year | C1: state | D1: district_name | E1: state_contributions | F1: LEAID
A2: 3400004 | B2: 2015 | C2: New Jersey | D2: Chathams School District | E2: 1450464 | F2: 3400004
A3: 3400004 | B3: 2016 | C3: New Jersey | D3: Chathams School District | E3: 2229758 | F3: 3400004
A4: 3400004 | B4: 2017 | C4: New Jersey | D4: Chathams School District | E4: 3144601 | F4: 3400004
A5: 3400004 | B5: 2018 | C5: New Jersey | D5: CHATHAMS SCHOOL DISTRICT | E5: 4235574 | F5: 3400004
A6: 3400004 | B6: 2019 | C6: New Jersey | D6: CHATHAMS SCHOOL DISTRICT | E6: 5770794 | F6: 3400004
A7: 3400004 | B7: 2020 | C7: New Jersey | D7: CHATHAMS SCHOOL DISTRICT | E7: 6507034 | F7: 3400004
A8: 3400004 | B8: 2021 | C8: New Jersey | D8: CHATHAMS SCHOOL DISTRICT | E8: 8568430 | F8: 3400004
A9: 3400004 | B9: 2022 | C9: New Jersey | D9: CHATHAMS SCHOOL DISTRICT | E9: 12411774 | F9: 3400004
A10: 3400004 | B10: 2023 | C10: New Jersey | D10: CHATHAMS SCHOOL DISTRICT | E10: 12250414 | F10: 3400004
A11: 3400005 | B11: 2015 | C11: New Jersey | D11: Morris-Union Jointure Comm | E11: 486545 | F11: 3400005
A12: 3400005 | B12: 2016 | C12: New Jersey | D12: Morris-Union Jointure Comm | E12: 605834 | F12: 3400005
A13: 3400005 | B13: 2017 | C13: New Jersey | D13: Morris-Union Jointure Comm | E13: 806220 | F13: 3400005
... A246: 3400048 | B246: 2016 | C246: New Jersey | D246: Academy Charter High School | E246: 107688 | F246: 3400048
A247: 3400048 | B247: 2017 | C247: New Jersey | D247: Academy Charter High School | E247: =VLOOKUP(A247,#REF!,6,FALSE) -> #REF! | F247: 3400048
A248: 3400048 | B248: 2018 | C248: New Jersey | D248: ACADEMY CHARTER HIGH SCHOOL | E248: 225408 | F248: 3400048
A249: 3400048 | B249: 2019 | C249: New Jersey | D249: ACADEMY CHARTER HIGH SCHOOL | E249: 287048 | F249: 3400048
A250: 3400048 | B250: 2020 | C250: New Jersey | D250: ACADEMY CHARTER HIGH SCHOOL | E250: 336652 | F250: 3400048
A251: 3400048 | B251: 2021 | C251: New Jersey | D251: ACADEMY CHARTER HIGH SCHOOL | E251: 360807 | F251: 3400048
A252: 3400048 | B252: 2022 | C252: New Jersey | D252: ACADEMY CHARTER HIGH SCHOOL | E252: 573976 | F252: 3400048
A253: 3400048 | B253: 2023 | C253: New Jersey | D253: ACADEMY CHARTER HIGH SCHOOL | E253: 553871 | F253: 3400048
A254: 3400049 | B254: 2015 | C254: New Jersey | D254: Red Bank Charter School | E254: 64385 | F254: 3400049
A255: 3400049 | B255: 2016 | C255: New Jersey | D255: Red Bank Charter School | E255: 110793 | F255: 3400049
A256: 3400049 | B256: 2017 | C256: New Jersey | D256: Red Bank Charter School | E256: 141420 | F256: 3400049
A257: 3400049 | B257: 2018 | C257: New Jersey | D257: RED BANK CHARTER SCHOOL | E257: 212628 | F257: 3400049
A258: 3400049 | B258: 2019 | C258: New Jersey | D258: RED BANK CHARTER SCHOOL | E258: 295732 | F258: 3400049
A259: 3400049 | B259: 2020 | C259: New Jersey | D259: RED BANK CHARTER SCHOOL | E259: 321814 | F259: 3400049
... A6042: 3480364 | B6042: 2023 | C6042: New Jersey | D6042: PASSAIC CO. ED SERV COMMISION | E6042: 1739592 | F6042: 3480364
C6044: 2015 | D6044: =SUMIF(B2:B6042,C6044,E2:E6042) -> 536107750
C6045: 2016
C6046: 2017
C6047: 2018
C6048: 2019
C6049: 2020
C6050: 2021
C6051: 2022
